Workbook

Sheet 延安石油化工厂油品动态 
B2: =取值!J1&取值!K1&取值!L1 -> 延安石油化工厂2026-01-07油品动态
B3: 石脑油 | I3: 催化柴油 | P3: 备注
B4: 罐号 | C4: 安全库容(m3) | D4: 安全高度(m) | E4: 油尺 | F4: 油量(吨) | G4: 空量(吨) | I4: 罐号 | J4: 安全库容(m3) | K4: 安全高度(m) | L4: 油尺 | M4: 油量(吨) | N4: 空量(吨) | P4: 0
B5: T-4101 | C5: 5531.1938 | D5: 17.64 | E5: 16.496 | F5: 3697.715 | G5: 173.285 | H5: 3871 | I5: T-4107 | J5: 5529.1387 | K5: 17.64 | L5: 10.194 | M5: 2806.55 | N5: 1862.45 | O5: 4669
B6: T-4102 | C6: 5535.478 | D6: 17.64 | E6: 6.628 | F6: 1481.002 | G6: 2387.998 | H6: 3869 | I6: T-4108 | J6: 5521.9907 | K6: 17.64 | L6: 6.79 | M6: 1863.968 | N6: 2786.032 | O6: 4650
B7: T-4103 | C7: 5531.4097 | D7: 17.64 | E7: 15.998 | F7: 3585.024 | G7: 268.976 | H7: 3854 | I7: T-4109 | J7: 5492.395 | K7: 17.64 | L7: 11.913 | M7: 3259.345 | N7: 1308.655 | O7: 4568
B8: T-4104 | C8: 5537.0762 | D8: 17.64 | E8: 6.519 | F8: 1457.117 | G8: 2412.883 | H8: 3870 | I8: T-4110 | J8: 5520.6787 | K8: 17.64 | N8: 0 | O8: 0
B9: T-4807 | C9: 1974.75 | D9: 12.84 | E9: 0 | F9: -3 | G9: 1393 | H9: 1390
B10: T-4808 | C10: 1974.7561 | D10: 12.84 | E10: 3.614 | F10: 398.823 | G10: 991.177 | H10: 1390
B11: 合计 | F11: =SUM(F5:F10) -> 10616.681 | G11: =SUM(G5:G10) -> 7627.319 | I11: 合计 | M11: =IFERROR(SUM(M5,M6,M7,M8),"error") -> 7929.863 | N11: =IFERROR(SUM(N5,N6,N7,N8),"error") -> 5957.137
B12: 常压柴油 | I12: 催化汽油
B13: T-4904 | C13: 2842.011 | D13: 16.03 | E13: 2.955 | F13: 431.536 | G13: 2069.464 | H13: 2501 | I13: T-4901 | J13: 2845.0591 | K13: 16.03 | L13: 3.934 | M13: 504.24 | N13: 1543.76 | O13: 2048
B14: T-4905 | C14: 2842.3196 | D14: 16.03 | E14: 8.188 | F14: 1191.619 | G14: 1310.381 | H14: 2502 | I14: T-4902 | J14: 2844.8083 | K14: 16.03 | L14: 3.882 | M14: 497.529 | N14: 1550.471 | O14: 2048
B15: T-4906 | C15: 2845.7595 | D15: 16.03 | E15: 3.126 | F15: 457.584 | G15: 2046.416 | H15: 2504 | I15: T-4903 | J15: 2836.3135 | K15: 16.03 | L15: 4.366 | M15: 557.649 | N15: 1485.351 | O15: 2043
B16: T-4809 | C16: 442.65 | D16: 8.84 | E16: 4.242 | F16: 202.879 | G16: 209.121 | H16: 412
B17: T-4810 | C17: 442.03528 | D17: 8.84 | E17: 0.047 | F17: 0.335 | G17: 411.665 | H17: 412
B18: 合计 | F18: =SUM(F13:F17) -> 2283.953 | G18: =SUM(G13:G17) -> 6047.047 | I18: 合计 | M18: =IFERROR(SUM(M13,M14,M15),"error") -> 1559.418 | N18: =IFERROR(SUM(N13,N14,N15),"error") -> 4579.582
B19: 气分原料 | I19: 混合碳四
B20: T-4201 | C20: 1398.8453 | D20: 9.86 | E20: 6.275 | F20: 395.157 | G20: 375.843 | H20: 771 | I20: T-4301 | J20: 1398.8453 | K20: 9.86 | L20: 7.162 | M20: 484.243 | N20: 286.757 | O20: 771
B21: T-4202 | C21: 1394.6259 | D21: 9.86 | E21: 6.797 | F21: 448.214 | G21: 320.786 | H21: 769 | I21: T-4302 | J21: 1394.6259 | K21: 9.86 | L21: 3.956 | M21: 177.359 | N21: 791.641 | O21: 969
B22: T-4203 | C22: 1397.8199 | D22: 9.86 | E22: 8.042 | F22: 580.406 | G22: 190.594 | H22: 771 | I22: T-4303 | J22: 1397.8199 | K22: 9.86 | L22: 7.235 | M22: 492.687 | N22: 278.313 | O22: 771
B23: T-4204 | C23: 1363.22 | D23: 9.86 | E23: 7.835 | F23: 558.238 | G23: 211.762 | H23: 770 | I23: 合计 | M23: =IFERROR(SUM(M20,M21,M22),"error") -> 1154.289 | N23: =IFERROR(SUM(N20,N21,N22),"error") -> 1356.711
B24: 合计 | F24: =IFERROR(SUM(F20,F21,F22,F23),"error") -> 1982.015 | G24: =IFERROR(SUM(G20,G21,G22,G23),"error") -> 1098.985 | I24: 饱和液化气
B25: 丙烯 | I25: T-4304 | J25: 1395.757 | K25: 9.86 | L25: 4.547 | M25: 227.338 | N25: 542.662 | O25: 770
B26: T-4205 | C26: 1396.2042 | D26: 9.86 | E26: 6.286 | F26: 388.646 | G26: 381.354 | H26: 770 | I26: T-4305 | J26: 1396.2042 | K26: 9.86 | L26: 7.048 | M26: 472.15 | N26: 297.85 | O26: 770
B27: T-4206 | C27: 1329.8959 | D27: 9.86 | E27: 8.025 | F27: 539.357 | G27: 193.643 | H27: 733 | I27: 合计 | M27: =IFERROR(SUM(M25,M26),"error") -> 699.488 | N27: =IFERROR(SUM(N25,N26),"error") -> 840.512
B28: T-4207 | C28: 1367.443 | D28: 9.86 | E28: 5.127 | F28: 270.683 | G28: 483.317 | H28: 754 | I28: 碳四原料
B29: T-4208 | C29: 1374.8003 | D29: 9.86 | E29: 3.352 | F29: 128.015 | G29: 629.985 | H29: 758 | I29: T-4306 | J29: 1329.8959 | K29: 9.86 | L29: 6.596 | M29: 428.619 | N29: 304.381 | O29: 733
B30: T-4209 | C30: 1376.869 | D30: 9.86 | E30: 5.826 | F30: 338.395 | G30: 420.605 | H30: 759 | I30: T-4307 | J30: 1367.443 | K30: 9.86 | L30: 2.237 | M30: 64.923 | N30: 689.077 | O30: 754
B31: T-4210 | C31: 1357.7327 | D31: 9.86 | E31: 4.644 | F31: 225.731 | G31: 523.269 | H31: 749 | I31: T-4308 | J31: 1374.8003 | K31: 9.86 | L31: 6.179 | M31: 399.361 | N31: 358.639 | O31: 758
B32: 合计 | F32: =IFERROR(SUM(F26,F27,F28,F29,F30,F31),"error") -> 1890.827 | G32: =IFERROR(SUM(G26,G27,G28,G29,G30,G31),"error") -> 2632.173 | I32: 合计 | M32: =IFERROR(SUM(M29,M30,M31),"error") -> 892.903 | N32: =IFERROR(SUM(N29,N30,N31),"error") -> 1352.097
B33: 精制油 | I33: 丙烷
B34: T-4105 | C34: 5535.0742 | D34: 17.64 | E34: 16.348 | F34: 3692.422 | G34: 229.578 | H34: 3922 | I34: T-4309 | J34: 1376.869 | K34: 9.86 | L34: 6.593 | M34: 418.575 | N34: 271.425 | O34: 690
B35: T-4106 | C35: 5534.1064 | D35: 17.64 | E35: 16.394 | F35: 3702.141 | G35: 206.859 | H35: 3909 | I35: T-4310 | J35: 1357.7327 | K35: 9.86 | L35: 8.423 | M35: 599.054 | N35: 81.946 | O35: 681
B36: 合计 | F36: =IFERROR(SUM(F34,F35),"error") -> 7394.563 | G36: =IFERROR(SUM(G34,G35),"error") -> 436.437 | I36: 合计 | M36: =IFERROR(SUM(M34,M35),"error") -> 1017.629 | N36: =IFERROR(SUM(N34,N35),"error") -> 353.371
B37: 甲醇 | I37: MTBE
B38: T-4801 | C38: 1971.2057 | D38: 12.84 | E38: 12.025 | F38: 1458.18 | G38: 59.82 | H38: 1518 | I38: T-4805 | J38: 1966.9215 | K38: 12.84 | L38: 11.286 | M38: 1313.494 | N38: 98.506 | O38: 1412
B39: T-4802 | C39: 1969.8903 | D39: 12.84 | E39: 7.994 | F39: 966.887 | G39: 542.113 | H39: 1509 | I39: T-4806 | J39: 1975.9862 | K39: 12.84 | L39: 4.766 | M39: 555.456 | N39: 873.544 | O39: 1429
B40: T-41005 | C40: 1841.14 | D40: 13.5 | E40: 10.136 | F40: 1093 | G40: 857 | H40: 1950 | I40: T-41003 | J40: 2585.01 | K40: 15 | L40: 6.699 | M40: 870.287 | N40: 929.713 | O40: 1800
B41: T-41006 | C41: 1844.65 | D41: 13.5 | E41: 8.672 | F41: 936.676 | G41: 1013.324 | H41: 1950 | I41: T-41004 | J41: 2637.86 | K41: 15 | L41: 5.429 | M41: 706.335 | N41: 1093.665 | O41: 1800
...

Sheet 取值
A1: 石脑油 | F1: 催化柴油 | J1: 延安石油化工厂 | K1: 2026-01-07 | L1: 油品动态
A2: 罐号 | B2: 油尺 | C2: 油量(吨) | D2: 空量(吨) | F2: 罐号 | G2: 油尺 | H2: 油量(吨) | I2: 空量(吨)
A3: T-4101 | B3: 16.496 | C3: 3697.715 | E3: 3871.45 | F3: T-4107 | G3: 10.194 | H3: 2806.55 | J3: 0
A4: T-4102 | B4: 6.628 | C4: 1481.002 | E4: 3868.63 | F4: T-4108 | G4: 6.79 | H4: 1863.968 | J4: =J3 -> 0
A5: T-4103 | B5: 15.998 | C5: 3585.024 | E5: 3853.81 | F5: T-4109 | G5: 11.913 | H5: 3259.345
A6: T-4104 | B6: 6.519 | C6: 1457.117 | E6: 3870.04 | F6: T-4110 | G6: 8.142 | H6: 2235.593
A7: T-4807 | B7: 0 | C7: -3
A8: T-4808 | B8: 3.614 | C8: 398.823
A9: 合计 | F9: 合计
A10: 常压柴油 | F10: 催化汽油
A11: T-4904 | B11: 2.955 | C11: 431.536 | E11: 2492.79 | F11: T-4901 | G11: 3.934 | H11: 504.24
A12: T-4905 | B12: 8.188 | C12: 1191.619 | E12: 2492.79 | F12: T-4902 | G12: 3.882 | H12: 497.529
A13: T-4906 | B13: 3.126 | C13: 457.584 | E13: 2492.79 | F13: T-4903 | G13: 4.366 | H13: 557.649
A14: T-4809 | B14: 4.242 | C14: 202.879
A15: T-4810 | B15: 0.047 | C15: 0.335
A16: 合计 | F16: 合计
A17: 气分原料 | F17: 混合碳四
A18: T-4201 | B18: 6.275 | C18: 395.157 | E18: 996 | F18: T-4301 | G18: 7.162 | H18: 484.243
A19: T-4202 | B19: 6.797 | C19: 448.214 | E19: 996 | F19: T-4302 | G19: 3.956 | H19: 177.359
A20: T-4203 | B20: 8.042 | C20: 580.406 | E20: 998 | F20: T-4303 | G20: 7.235 | H20: 492.687
A21: T-4204 | B21: 7.835 | C21: 558.238 | E21: 997 | F21: 合计
A22: 合计 | F22: 饱和液化气
A23: 丙烯 | F23: T-4304 | G23: 4.547 | H23: 227.338
A24: T-4205 | B24: 6.286 | C24: 388.646 | E24: 920 | F24: T-4305 | G24: 7.048 | H24: 472.15
A25: T-4206 | B25: 8.025 | C25: 539.357 | E25: 920 | F25: 合计
A26: T-4207 | B26: 5.127 | C26: 270.683 | E26: 920 | F26: 碳四原料
A27: T-4208 | B27: 3.352 | C27: 128.015 | E27: 920 | F27: T-4306 | G27: 6.596 | H27: 428.619
A28: T-4209 | B28: 5.826 | C28: 338.395 | E28: 920 | F28: T-4307 | G28: 2.237 | H28: 64.923
A29: T-4210 | B29: 4.644 | C29: 225.731 | E29: 920 | F29: T-4308 | G29: 6.179 | H29: 399.361
A30: 合计 | F30: 合计
A31: 精制油 | F31: 丙烷
A32: T-4105 | B32: 16.348 | C32: 3692.422 | E32: 3921.72 | F32: T-4309 | G32: 6.593 | H32: 418.575
A33: T-4106 | B33: 16.394 | C33: 3702.141 | E33: 3909.2 | F33: T-4310 | G33: 8.423 | H33: 599.054
A34: 合计 | F34: 合计
A35: 甲醇 | F35: MTBE
A36: T-4801 | B36: 12.025 | C36: 1458.18 | E36: 1517.82 | F36: T-4805 | G36: 11.286 | H36: 1313.494
A37: T-4802 | B37: 7.994 | C37: 966.887 | E37: 1509.09 | F37: T-4806 | G37: 4.766 | H37: 555.456
A38: T-41005 | B38: 10.136 | C38: 1093 | E38: 1500 | F38: T-41003 | G38: 6.699 | H38: 870.287
A39: T-41006 | B39: 8.672 | C39: 936.676 | E39: 1500 | F39: T-41004 | G39: 5.429 | H39: 706.335
A40: 合计 | F40: 合计
...
