Workbook

Sheet 全年生产任务完成情况统计
B2: =取值!B55 -> 2026年全年生产任务完成情况统计
D4: 日期: | E4: 2026-01-06 | N4: =取值!B50&取值!B51 -> 报表生产时间:2026-01-07 | R4: =取值!B52 -> 0.3333333333333333
B5: 项目 | C5: 月计划 | D5: 当日加工量 | E5: 月累计 | F5: 本月剩余 | G5: 至月底日 | H5: 完成月任务的（%） | I5: 1-12月份 | J5: 去年同期值 （吨） | K5: 增（+） | L5: 全年计划 | M5: 全年剩余加工量 （吨） | N5: 至12月底日处理量 （吨） | O5: 完成全年任务的（%） | P5: 当日收率 | Q5: 月累计 | R5: 年累计
C6: （吨） | D6: （吨） | E6: 生产 (吨) | F6: 加工量 （吨） | G6: 处理量 （吨） | I6: 累计加工量 （吨） | K6: 减（-） | L6: （吨） | P6: （%） | Q6: （%） | R6: （%）
B7: 120万吨/年重整装置加工量 | C7: =计划取值!B5 -> 120000 | D7: =取值!D3 -> 4280 | E7: =取值!E3 -> 29955 | F7: =IF(_xlfn.IFERROR(C7-E7,"error")<0,0,_xlfn.IFERROR(C7-E7,"error")) -> 90045 | G7: =_xlfn.IFERROR(IF($G$23=0,F7,F7/$G$23),0) -> 3751.875 | H7: =_xlfn.IFERROR(E7/C7,"error") -> 0.249625 | I7: =取值!I3 -> 29955 | J7: =取值!J3 -> 27351 | K7: =_xlfn.IFERROR(I7-J7,"error") -> 2604 | L7: =计划取值!D5 -> 0 | M7: =IF(_xlfn.IFERROR(L7-I7,"error")<0,0,_xlfn.IFERROR(L7-I7,"error")) -> 0 | N7: =_xlfn.IFERROR(M7/Q23,"error") -> 0 | O7: =_xlfn.IFERROR(I7/L7,"") | P7: =ROUND(取值!P3/100,4) -> 0.9336 | Q7: =ROUND(取值!R3/100,4) -> 0.9322 | R7: =ROUND(取值!T3/100,4) -> 0.9322
B8: 柴油加氢精制装置加工量 | C8: =SUM(C9,C10) -> 196000 | D8: =_xlfn.IFERROR(SUM(D9,D10),"error") -> 7176 | E8: =_xlfn.IFERROR(SUM(E9,E10),"error") -> 51266 | F8: =IF(_xlfn.IFERROR(C8-E8,"error")<0,0,_xlfn.IFERROR(C8-E8,"error")) -> 144734 | G8: =_xlfn.IFERROR(IF($G$23=0,F8,F8/$G$23),0) -> 6030.5835 | H8: =_xlfn.IFERROR(E8/C8,"error") -> 0.26156122 | I8: =_xlfn.IFERROR(SUM(I9,I10),"error") -> 51266 | J8: =_xlfn.IFERROR(SUM(J9,J10),"error") -> 58114 | K8: =_xlfn.IFERROR(I8-J8,"error") -> -6848 | L8: =SUM(L9,L10) -> 0 | M8: =IF(_xlfn.IFERROR(L8-I8,"error")<0,0,_xlfn.IFERROR(L8-I8,"error")) -> 0 | N8: =_xlfn.IFERROR(M8/Q23,"error") -> 0 | O8: =_xlfn.IFERROR(I8/L8,"") | P8: =ROUND(取值!P6/100,4) -> 0.9944 | Q8: =ROUND(取值!R6/100,4) -> 0.9934 | R8: =ROUND(取值!T6/100,4) -> 0.9934
B9: 其中:140万吨/年柴油加氢装置 | C9: =计划取值!B7 -> 68000.003 | D9: =取值!D7 -> 2295 | E9: =_xlfn.IFERROR(SUM(取值!E7,取值!E8,取值!E9),"error") -> 16921 | F9: =IF(_xlfn.IFERROR(C9-E9,"error")<0,0,_xlfn.IFERROR(C9-E9,"error")) -> 51079.003 | G9: =_xlfn.IFERROR(IF($G$23=0,F9,F9/$G$23),0) -> 2128.2918 | H9: =_xlfn.IFERROR(E9/C9,"error") -> 0.24883822 | I9: =_xlfn.IFERROR(SUM(取值!I7,取值!I8,取值!I9),"error") -> 16921 | J9: =_xlfn.IFERROR(SUM(取值!J7,取值!J8,取值!J9),"error") -> 21303 | K9: =_xlfn.IFERROR(I9-J9,"error") -> -4382 | L9: =计划取值!D7 -> 0 | M9: =IF(_xlfn.IFERROR(L9-I9,"error")<0,0,_xlfn.IFERROR(L9-I9,"error")) -> 0 | N9: =_xlfn.IFERROR(M9/Q23,"error") -> 0 | O9: =_xlfn.IFERROR(I9/L9,"") | P9: =ROUND(取值!P7/100,4) -> 0.9974 | Q9: =ROUND(取值!R7/100,4) -> 0.9973 | R9: =ROUND(取值!T7/100,4) -> 0.9973
B10: 240万吨/年柴油加氢精制装置 | C10: =计划取值!B8 -> 128000 | D10: =_xlfn.IFERROR(SUM(取值!D11,取值!D12),"error") -> 4881 | E10: =_xlfn.IFERROR(SUM(取值!E11,取值!E12),"error") -> 34345 | F10: =IF(_xlfn.IFERROR(C10-E10,"error")<0,0,_xlfn.IFERROR(C10-E10,"error")) -> 93655 | G10: =_xlfn.IFERROR(IF($G$23=0,F10,F10/$G$23),0) -> 3902.2917 | H10: =_xlfn.IFERROR(E10/C10,"error") -> 0.26832031 | I10: =_xlfn.IFERROR(SUM(取值!I11,取值!I12),"error") -> 34345 | J10: =_xlfn.IFERROR(SUM(取值!J11,取值!J12),"error") -> 36811 | K10: =_xlfn.IFERROR(I10-J10,"error") -> -2466 | L10: =计划取值!D8 -> 0 | M10: =IF(_xlfn.IFERROR(L10-I10,"error")<0,0,_xlfn.IFERROR(L10-I10,"error")) -> 0 | N10: =_xlfn.IFERROR(M10/Q23,"error") -> 0 | O10: =_xlfn.IFERROR(I10/L10,"") | P10: =ROUND(取值!P11/100,4) -> 0.993 | Q10: =ROUND(取值!R11/100,4) -> 0.9914 | R10: =ROUND(取值!T11/100,4) -> 0.9914
B11: 180万吨/年汽油精制装置加工量 | C11: =计划取值!B9 -> 117000 | D11: =_xlfn.IFERROR(SUM(取值!D13,取值!D14,取值!D15),"error") -> 4149 | E11: =_xlfn.IFERROR(SUM(取值!E13,取值!E14,取值!E15),"error") -> 29145 | F11: =IF(_xlfn.IFERROR(C11-E11,"error")<0,0,_xlfn.IFERROR(C11-E11,"error")) -> 87855 | G11: =_xlfn.IFERROR(IF($G$23=0,F11,F11/$G$23),0) -> 3660.625 | H11: =_xlfn.IFERROR(E11/C11,"error") -> 0.24910256 | I11: =_xlfn.IFERROR(SUM(取值!I13,取值!I14,取值!I15),"error") -> 29145 | J11: =_xlfn.IFERROR(SUM(取值!J13,取值!J14,取值!J15),"error") -> 28625 | K11: =_xlfn.IFERROR(I11-J11,"error") -> 520 | L11: =计划取值!D9 -> 0 | M11: =IF(_xlfn.IFERROR(L11-I11,"error")<0,0,_xlfn.IFERROR(L11-I11,"error")) -> 0 | N11: =_xlfn.IFERROR(M11/Q23,"error") -> 0 | O11: =_xlfn.IFERROR(I11/L11,"") | P11: =ROUND(取值!P13/100,4) -> 0.9896 | Q11: =ROUND(取值!R13/100,4) -> 0.9901 | R11: =ROUND(取值!T13/100,4) -> 0.9901
B12: 60万吨/年气体分馏装置加工量 | C12: =计划取值!B10 -> 56000.005 | D12: =_xlfn.IFERROR(SUM(取值!D18,取值!D19),"error") -> 1730 | E12: =_xlfn.IFERROR(SUM(取值!E18,取值!E19),"error") -> 12354 | F12: =IF(_xlfn.IFERROR(C12-E12,"error")<0,0,_xlfn.IFERROR(C12-E12,"error")) -> 43646.005 | G12: =_xlfn.IFERROR(IF($G$23=0,F12,F12/$G$23),0) -> 1818.5835 | H12: =_xlfn.IFERROR(E12/C12,"error") -> 0.22060712 | I12: =_xlfn.IFERROR(SUM(取值!I18,取值!I19),"error") -> 12354 | J12: =_xlfn.IFERROR(SUM(取值!J18,取值!J19),"error") -> 12963 | K12: =_xlfn.IFERROR(I12-J12,"error") -> -609 | L12: =计划取值!D10 -> 0 | M12: =IF(_xlfn.IFERROR(L12-I12,"error")<0,0,_xlfn.IFERROR(L12-I12,"error")) -> 0 | N12: =_xlfn.IFERROR(M12/Q23,"error") -> 0 | O12: =_xlfn.IFERROR(I12/L12,"") | P12: =ROUND(取值!P16/100,4) -> 0.978 | Q12: =ROUND(取值!R16/100,4) -> 0.9795 | R12: =ROUND(取值!T16/100,4) -> 0.9795
B13: MTBE产量 | C13: =SUM(C14,C15) -> 24052.651 | D13: =SUM(D14,D15) -> 835 | E13: =SUM(E14,E15) -> 6006 | F13: =IF(_xlfn.IFERROR(C13-E13,"error")<0,0,_xlfn.IFERROR(C13-E13,"error")) -> 18046.651 | G13: =IF(_xlfn.IFERROR(IF($G$23=0,C13-E13,(C13-E13)/$G$23),"error")<0,0,_xlfn.IFERROR(IF($G$23=0,C13-E13,(C13-E13)/$G$23),"error")) -> 751.94379 | H13: =_xlfn.IFERROR(E13/C13,"error") -> 0.24970221 | I13: =SUM(I14,I15) -> 6006 | J13: =SUM(J14,J15) -> 2828 | K13: =SUM(K14:K15) -> 3178 | L13: =SUM(L14,L15) -> 0 | M13: =SUM(M14,M15) -> 0 | N13: =SUM(N14,N15) -> 0 | O13: =_xlfn.IFERROR(I13/L13,"")
B14: 其中:12万吨装置 | C14: =_xlfn.IFERROR(计划取值!B12,"") -> 6411.3901 | D14: =取值!D20 -> 164 | E14: =取值!E20 -> 1166 | F14: =IF(_xlfn.IFERROR(C14-E14,"error")<0,0,_xlfn.IFERROR(C14-E14,"error")) -> 5245.3901 | G14: =_xlfn.IFERROR(IF($G$23=0,F14,F14/$G$23),0) -> 218.55792 | H14: =_xlfn.IFERROR(E14/C14,"error") -> 0.18186384 | I14: =取值!I20 -> 1166 | J14: =取值!J20 -> 1410 | K14: =_xlfn.IFERROR(I14-J14,"error") -> -244 | L14: =_xlfn.IFERROR(计划取值!D12*计划取值!E12/100,"") -> 0 | M14: =IF(_xlfn.IFERROR(L14-I14,"error")<0,0,_xlfn.IFERROR(L14-I14,"error")) -> 0 | N14: =_xlfn.IFERROR(M14/Q23,"error") -> 0 | O14: =_xlfn.IFERROR(I14/L14,"") | P14: =取值!P20 -> 0.1572 | Q14: =取值!R20 -> 0.1567 | R14: =ROUND(取值!T20/100,4) -> 0.1567
B15: 25万吨装置 | C15: =_xlfn.IFERROR(计划取值!B13,"") -> 17641.261 | D15: =取值!D41 -> 671 | E15: =取值!E41 -> 4840 | F15: =IF(_xlfn.IFERROR(C15-E15,"error")<0,0,_xlfn.IFERROR(C15-E15,"error")) -> 12801.261 | G15: =_xlfn.IFERROR(IF($G$23=0,F15,F15/$G$23),0) -> 533.38587 | H15: =_xlfn.IFERROR(E15/C15,"error") -> 0.27435681 | I15: =取值!I41 -> 4840 | J15: =取值!J41 -> 1418 | K15: =_xlfn.IFERROR(I15-J15,"error") -> 3422 | L15: =_xlfn.IFERROR(计划取值!D13*计划取值!E13/100,"") -> 0 | M15: =IF(_xlfn.IFERROR(L15-I15,"error")<0,0,_xlfn.IFERROR(L15-I15,"error")) -> 0 | N15: =_xlfn.IFERROR(M15/Q23,"error") -> 0 | O15: =_xlfn.IFERROR(I15/L15,"") | P15: =取值!P41 -> 0.4855 | Q15: =取值!R41 -> 0.4888 | R15: =ROUND(取值!T41/100,4) -> 0.4888
B16: 苯产量 | C16: =_xlfn.IFERROR(计划取值!B14*计划取值!C14/100,"") -> 4350 | D16: =取值!D23 -> 183 | E16: =取值!E23 -> 1308 | F16: =IF(_xlfn.IFERROR(C16-E16,"error")<0,0,_xlfn.IFERROR(C16-E16,"error")) -> 3042 | G16: =_xlfn.IFERROR(IF($G$23=0,F16,F16/$G$23),0) -> 126.75 | H16: =_xlfn.IFERROR(E16/C16,"error") -> 0.30068965 | I16: =取值!I23 -> 1308 | J16: =取值!J23 -> 1011 | K16: =_xlfn.IFERROR(I16-J16,"error") -> 297 | L16: =_xlfn.IFERROR(计划取值!D14*计划取值!E14/100,"") -> 0 | M16: =IF(_xlfn.IFERROR(L16-I16,"error")<0,0,_xlfn.IFERROR(L16-I16,"error")) -> 0 | N16: =_xlfn.IFERROR(M16/Q23,"error") -> 0 | O16: =_xlfn.IFERROR(I16/L16,"") | P16: =取值!P23 -> 0.3274 | Q16: =取值!R23 -> 0.329 | R16: =ROUND(取值!T23/100,4) -> 0.329
B17: 聚丙烯产量 | C17: =_xlfn.IFERROR(计划取值!B15*计划取值!C15/100,"") -> 17499.996 | D17: =取值!D24 -> 609.56 | E17: =取值!E24 -> 4269.06 | F17: =IF(_xlfn.IFERROR(C17-E17,"error")<0,0,_xlfn.IFERROR(C17-E17,"error")) -> 13230.936 | G17: =_xlfn.IFERROR(IF($G$23=0,F17,F17/$G$23),0) -> 551.28901 | H17: =_xlfn.IFERROR(E17/C17,"error") -> 0.24394634 | I17: =取值!I24 -> 4269 | J17: =取值!J24 -> 4198.58 | K17: =_xlfn.IFERROR(I17-J17,"error") -> 70.42 | L17: =_xlfn.IFERROR(计划取值!D15*计划取值!E15/100,"") -> 0 | M17: =IF(_xlfn.IFERROR(L17-I17,"error")<0,0,_xlfn.IFERROR(L17-I17,"error")) -> 0 | N17: =_xlfn.IFERROR(M17/Q23,"error") -> 0 | O17: =_xlfn.IFERROR(I17/L17,"") | P17: =取值!P24 -> 0.9722 | Q17: =取值!R24 -> 0.97 | R17: =ROUND(取值!T24/100,4) -> 0.97
B18: 异辛烷组分产量 | C18: =_xlfn.IFERROR(计划取值!B16*计划取值!C16/100,"") -> 18000.001 | D18: =取值!D33 -> 604 | E18: =取值!E33 -> 4379 | F18: =IF(_xlfn.IFERROR(C18-E18,"error")<0,0,_xlfn.IFERROR(C18-E18,"error")) -> 13621.002 | G18: =_xlfn.IFERROR(IF($G$23=0,F18,F18/$G$23),0) -> 567.54173 | H18: =_xlfn.IFERROR(E18/C18,"error") -> 0.24327776 | I18: =取值!I33 -> 4379 | J18: =取值!J33 -> 4638 | K18: =_xlfn.IFERROR(I18-J18,"error") -> -259 | L18: =_xlfn.IFERROR(计划取值!D16*计划取值!E16/100,"") -> 0 | M18: =IF(_xlfn.IFERROR(L18-I18,"error")<0,0,_xlfn.IFERROR(L18-I18,"error")) -> 0 | N18: =_xlfn.IFERROR(M18/Q23,"error") -> 0 | O18: =_xlfn.IFERROR(I18/L18,"") | P18: =取值!P33 -> 0.6069 | Q18: =取值!R33 -> 0.6168 | R18: =取值!T33 -> 0.6168
B19: 油品名称 | C19: 常压石脑油 | D19: 催化柴油 | E19: 丙烯 | F19: 气分碳四 | G19: 饱和液化气 | H19: 丙烷 | I19: 醚（酯）后C4 | J19: 聚丙烯 | K19: MTBE | L19: 异辛烷组分
B20: 库存 | C20: =取值!A59 -> 10616.681 | D20: =取值!B59 -> 7929.863 | E20: =取值!C59 -> 1890.827 | F20: =取值!D59 -> 892.903 | G20: =取值!E59 -> 699.488 | H20: =取值!F59 -> 1017.629 | I20: =取值!G59 -> 1154.289 | J20: =取值!H59 -> 597 | K20: =ROUND(取值!I59,0)+ROUND(取值!I58,0) -> 3446 | L20: =取值!J59 -> 5770.289
B21: 空量 | K21: =取值!B65 -> 2995.428 | L21: =取值!A65 -> 729.711
B22: 备 注
D23: 距 | E23: =取值!B48 -> 2026-01-30 | F23: 还有 | G23: =取值!B46 -> 24 | H23: 天 | N23: 距 | O23: =取值!B49 -> 2026-12-30 | P23: 还有 | Q23: =取值!B47 -> 358 | R23: 天

Sheet 取值
B1: 项目 | C1: 月计划 | D1: 当日加工量 | E1: 月累计 | F1: 本月剩余 | G1: 至月底日 | H1: 完成月任务的（%） | I1: 1-12月份 | J1: 去年同期值（万吨） | K1: 增（+） | L1: 全年计划 | M1: 全年剩余加工量（万吨） | N1: 至12月底日处理量（吨） | O1: 完成全年任务的（%） | P1: 当日收率 | Q1: 当日原料 | R1: 月累计收率 | S1: 当月原料 | T1: 年累计 | U1: 年累计加工 | V1: 当年原料
C2: （万吨） | E2: 生产(万吨) | F2: 加工量（万吨） | G2: 处理量（吨） | I2: 累计加工量（万吨） | K2: 减（-） | L2: （万吨）
A3: 120万吨/年重整装置 | B3: 120万吨/年重整装置 | D3: 4280 | E3: 29955 | I3: 29955 | J3: 27351 | P3: 93.364486 | R3: 93.216491 | T3: 93.216491
A5: 柴油加氢精制装置加工量
A6: 其中:140万吨/年柴油加氢装置 | B6: 140万吨、240万吨/柴油加氢精制装置加工量 | P6: 99.442586 | R6: 99.336792 | T6: 99.336792
A7: 240万吨/年柴油加氢精制装置 | B7: 其中:140万吨/年柴油加氢装置 | D7: =_xlfn.IFERROR(SUM(D8:D10),0) -> 2295 | E7: 15902 | I7: 15902 | J7: 20605 | P7: 99.738562 | R7: 99.728148 | T7: 99.728148
D8: 2156 | E8: 486 | I8: 486 | J8: 276
D9: 60 | E9: 533 | I9: 533 | J9: 422
D10: 79
B11: 240万吨/年柴油加氢精制装置 | D11: 4871 | E11: 34284 | I11: 34284 | J11: 36758 | P11: 99.303421 | R11: 99.14398 | T11: 99.14398
D12: 10 | E12: 61 | I12: 61 | J12: 53
A13: 180万吨/年汽油精制装置 | B13: 180万吨/年汽油精制装置 | D13: 4135 | E13: 29053 | I13: 29145 | J13: 28553 | P13: 98.963606 | R13: 99.008406 | T13: 99.008406
D14: 14 | E14: 92 | J14: 46
D15: 0 | E15: 0 | J15: 26
A16: 60万吨/年气体分馏装置 | B16: 60万吨/年液化气精制装置 | E16: 10912 | I16: 10912 | J16: 12156 | P16: 97.803468 | R16: 97.95208 | T16: 97.95208
E17: 840 | I17: 840 | J17: 702
B18: 60万吨/年气体分馏装置 | D18: 1730 | E18: 12354 | I18: 12354 | J18: 12963
D19: 0 | E19: 0 | I19: 0 | J19: 0 | P19: =ROUND(SUM(D20,D41)/SUM(Q20,Q41),4) -> 0.3443 | R19: =ROUND(SUM(E20,E41)/SUM(S20,S41),4) -> 0.3463 | T19: =ROUND(SUM(U20,U41)/SUM(V20,V41),4)
A20: MTBE产量 | B20: 12万吨/年MTBE产量 | D20: 164 | E20: 1166 | I20: 1166 | J20: 1410 | P20: =ROUND(D20/Q20,4) -> 0.1572 | Q20: =SUM(Q21:Q22) -> 1043 | R20: =ROUND(E20/S20,4) -> 0.1567 | S20: =SUM(S21:S22) -> 7442 | T20: 15.667831 | V20: =SUM(V21:V22) -> 0
A21: 其中:12万吨装置 | Q21: 981 | S21: 7012
Q22: 62 | S22: 430
A23: 苯产量 | B23: 20万吨/年苯抽提产量 | D23: 183 | E23: 1308 | I23: 1308 | J23: 1011 | P23: =ROUND(D23/Q23,4) -> 0.3274 | Q23: 559 | R23: =ROUND(E23/S23,4) -> 0.329 | S23: 3976 | T23: 32.897384
A24: 聚丙烯产量 | B24: 20万吨/年聚丙烯产量 | D24: 609.56 | E24: 4269.06 | I24: =ROUND(SUM(H25:H32),0) -> 4269 | J24: 4198.58 | P24: =ROUND(D24/Q24,4) -> 0.9722 | Q24: 627 | R24: =ROUND(E24/S24,4) -> 0.97 | S24: 4401 | T24: 97.002045
H25: =ROUND(I25,0) -> 4232 | I25: 4232
H26: =ROUND(I26,0) -> 0 | I26: 0
H27: =ROUND(I27,0) -> 37 | I27: 37.06
H28: =ROUND(I28,0) -> 0 | I28: 0
H29: =ROUND(I29,0) -> 0 | I29: 0
H30: =ROUND(I30,0) -> 0 | I30: 0
H31: =ROUND(I31,0) -> 0 | I31: 0
H32: =ROUND(I32,0) -> 0 | I32: 0
A33: 烷基化油产量 | B33: 20万吨/年烷基化装置加工量 | D33: 604 | E33: 4379 | I33: 4379 | J33: 4638 | P33: =ROUND(D33/Q33,4) -> 0.6069 | Q33: =SUM(Q34:Q37) -> 995.2 | R33: =ROUND(E33/S33,4) -> 0.6168 | S33: =SUM(S34:S37) -> 7099.4 | T33: =ROUND(U33/V33,4) -> 0.6168 | U33: 4379 | V33: =SUM(V34:V37) -> 7099.4
Q34: 995 | S34: 7098 | V34: 7098
Q35: 0.2 | S35: 1.4 | V35: 1.4
Q36: 0 | S36: 0 | V36: 0
A37: 30万吨/年混合脱氢装置加工量 | B37: 30万吨/年混合脱氢装置加工量 | E37: 1997 | I37: 1997 | J37: 818 | Q37: 0 | S37: 0 | V37: 0
E38: 2658 | I38: 2658 | J38: 1004
E39: 3347 | I39: 3347 | J39: 893
E40: 4663 | I40: 4663 | J40: 2057
A41: 25万吨装置 | B41: 25万吨/年MTBE装置加工量 | D41: 671 | E41: 4840 | I41: 4840 | J41: 1418 | P41: =ROUND(D41/Q41,4) -> 0.4855 | Q41: =SUM(Q42:Q45) -> 1382 | R41: =ROUND(E41/S41,4) -> 0.4888 | S41: =SUM(S42:S45) -> 9901 | T41: 48.883951 | V41: =SUM(V42:V45) -> 0
...

Sheet 计划取值
A3: 项目 | B3: 月计划
B4: （万吨）
A5: 120万吨/年重整装置加工量 | B5: 120000
A6: 柴油加氢精制装置加工量
A7: 其中:140万吨/年柴油加氢装置 | B7: 68000.003
A8: 240万吨/年柴油加氢精制装置 | B8: 128000
A9: 180万吨/年汽油精制装置加工量 | B9: 117000
A10: 60万吨/年气体分馏装置加工量 | B10: 56000.005
A11: MTBE产量
A12: 其中:12万吨装置 | B12: 6411.3901 | C12: 18.5
A13: 25万吨装置 | B13: 17641.261 | C13: 46.4
A14: 苯产量 | B14: 15000 | C14: 29
A15: 聚丙烯产量 | B15: 18134.711 | C15: 96.5
A16: 烷基化油产量 | B16: 27692.31 | C16: 65
