Workbook

Sheet 全年生产任务情况统计
B1: 全年生产任务情况统计
B2: 编辑单位：生产计划部 | J2: =取值!A1&取值!B1&取值!C1 -> 报表生成时间：2026-01-07 8:00:00
A3: 项目 | C3: 月计划 | D3: 本日 | E3: 本月 | F3: 本月 | G3: 至本月底 | H3: 年计划 (t) | I3: 全年累计加工量 (t) | J3: 全年剩余加工量 (t) | K3: 至12月底日处理量 (t) | L3: 完成全年任务的 (%)
C4: t | D4: t | E4: 累计生产(t) | F4: 剩余加工量(t) | G4: 日处理量(t)
A5: BDO产量 | C5: =取值!B10 -> 5000 | D5: =取值!C11 -> 201 | E5: =_xlfn.IFERROR(SUM(D5,取值!D11),"") -> 1403.2 | F5: =_xlfn.IFERROR(C5-E5,"") -> 3596.8 | G5: =_xlfn.IFERROR(F5/取值!F5,"") -> 149.86667 | H5: =取值!G10 -> 0 | I5: =_xlfn.IFERROR(SUM(取值!H11,E5),"") -> 1403.2 | J5: =_xlfn.IFERROR(H5-I5,"") -> -1403.2 | K5: =_xlfn.IFERROR(J5/取值!F6,"") -> -3.9195531 | L5: =_xlfn.IFERROR(I5/H5*100,"")
A6: PTMEG产量 | C6: =取值!B13 -> 0 | D6: =取值!C13 -> 0 | E6: =_xlfn.IFERROR(SUM(E7:E10),"") -> 0 | F6: =_xlfn.IFERROR(C6-E6,"") -> 0 | G6: =_xlfn.IFERROR(F6/取值!F5,"") -> 0 | H6: =取值!G13 -> 0 | I6: =_xlfn.IFERROR(SUM(I7:I10),"") -> 0 | J6: =_xlfn.IFERROR(H6-I6,"") -> 0 | K6: =_xlfn.IFERROR(J6/取值!F6,"") -> 0 | L6: =_xlfn.IFERROR(I6/H6*100,"")
A7: PTMEG1800 | B7: 国标 | D7: =取值!C14 -> 0 | E7: =_xlfn.IFERROR(SUM(D7,取值!D14),"") -> 0 | I7: =SUM(取值!H14,E7) -> 0
B8: 行标 | D8: =取值!C15 -> 0 | E8: =_xlfn.IFERROR(SUM(D8,取值!D15),"") -> 0 | I8: =SUM(取值!H15,E8) -> 0
A9: PTMEG2000 | B9: 国标 | D9: =取值!C16 -> 0 | E9: =_xlfn.IFERROR(SUM(D9,取值!D16),"") -> 0 | I9: =SUM(取值!H16,E9) -> 0
B10: 行标 | D10: =取值!C17 -> 0 | E10: =_xlfn.IFERROR(SUM(D10,取值!D17),"") -> 0 | I10: =SUM(取值!H17,E10) -> 0
A11: 乙二醇产量 | C11: =取值!B19 -> 5000 | D11: =SUM(D12,D13,D14,D15) -> 246 | E11: =SUM(E12,E13,E14,E15) -> 1551.9 | F11: =_xlfn.IFERROR(C11-E11,"") -> 3448.1 | G11: =_xlfn.IFERROR(F11/取值!F5,"") -> 143.67083 | H11: =取值!G19 -> 0 | I11: =_xlfn.IFERROR(SUM(I12,I13,I14,I15),"") -> 1551.9 | J11: =_xlfn.IFERROR(H11-I11,"") -> -1551.9 | K11: =_xlfn.IFERROR(J11/取值!F6,"") -> -4.3349162 | L11: =_xlfn.IFERROR(I11/H11*100,"")
A12: 聚酯级乙二醇 | D12: =取值!C20 -> 246 | E12: =_xlfn.IFERROR(SUM(D12,取值!D20),"") -> 1356 | I12: =SUM(取值!H20,E12) -> 1356
A13: 工业级乙二醇 | D13: =取值!C21 -> 0 | E13: =_xlfn.IFERROR(SUM(D13,取值!D21),"") -> 0 | I13: =SUM(取值!H21,E13) -> 0
A14: 轻质多元醇 | D14: =取值!C22 -> 0 | E14: =_xlfn.IFERROR(SUM(D14,取值!D22),"") -> 88.9 | I14: =SUM(取值!H22,E14) -> 88.9
A15: 重质多元醇 | D15: =取值!C35 -> 0 | E15: =_xlfn.IFERROR(SUM(D15,取值!D35),"") -> 107 | I15: =SUM(取值!H35,E15) -> 107
A16: =取值!C33 -> 0
A18: 审核人： | C18: =_xlfn.IFERROR(IF(取值!C32=0,"",取值!C32),"") | K18: 填报人： | L18: =_xlfn.IFERROR(IF(取值!D32=0,"",取值!D32),"")
A20: 产品名称 | B20: 产量
B21: 本月 | D21: 累计
A22: BDO（销售） | B22: =取值!B45 -> 1824.14 | D22: =取值!D45 -> 1824.14
A23: PTMEG | B23: =取值!B46 -> 0 | D23: =取值!D46 -> 0
A24: 副产油 | B24: =取值!B47 -> 0 | D24: =取值!D47 -> 0
A25: 聚脂级乙二醇 | B25: =取值!B48 -> 1356 | D25: =取值!D48 -> 1356
A26: 轻质多元醇 | B26: =取值!B49 -> 88.9 | D26: =取值!D49 -> 88.9
A27: 重质多元醇 | B27: =取值!B50 -> 107 | D27: =取值!D50 -> 107
A28: 混合醇 | B28: =取值!B51 -> 84.8 | D28: =取值!D51 -> 84.8

Sheet 取值
A1: 报表生成时间： | B1: 2026-01-07 | C1: 8:00:00
A3: 项目 | B3: 月计划 | C3: 本日 | D3: 本月 | G3: 年计划 (万吨) | H3: 全年累计加工量 (万吨) | L3: 单耗
B4: t | C4: t | D4: 累计生产(t)
A5: 天然气加工量 | C5: 575296 | D5: 3529880 | F5: 24
A6: 乙炔产量 | C6: 81.5 | D6: 500.5 | F6: 358 | L6: 乙炔单耗 | M6: 7200 | O6: =_xlfn.IFERROR(O16/O18,"") -> 7058.8466 | P6: =_xlfn.IFERROR(P16/P18,"") | Q6: =_xlfn.IFERROR(Q16/Q18,"")
A7: 甲醇加工量 | C7: 174.5 | D7: 1273.7 | L7: 甲醛单耗 | M7: 0.42 | O7: =_xlfn.IFERROR(O19/O20,"") -> 0.41380128 | P7: =_xlfn.IFERROR(P19/P20,"") | Q7: =_xlfn.IFERROR(Q19/Q20,"")
A8: 甲醛产量 | C8: 421.7 | D8: 3114.14 | L8: BDO单耗 | M8: 0.43 | O8: =_xlfn.IFERROR(O21/O22,"") -> 0.40346535 | P8: =_xlfn.IFERROR(P21/P22,"") | Q8: =_xlfn.IFERROR(Q21/Q22,"")
A9: 乙炔加工量 | C9: 81.5 | D9: 500.5 | L9: PT单耗 | M9: 0 | O9: =_xlfn.IFERROR(O23/SUM(O24,O27),"") | P9: =_xlfn.IFERROR(P23/SUM(P24,P27),"") | Q9: =_xlfn.IFERROR(Q23/SUM(Q24,Q27),"")
A10: BDO产量（二部） | B10: 5000 | C10: 202 | D10: 1256.48 | L10: EG单耗 | O10: =_xlfn.IFERROR(O28/SUM(O29,O30,O31),"") -> 189.83158 | P10: =_xlfn.IFERROR(P28/SUM(P29,P30,P31),"") | Q10: =_xlfn.IFERROR(Q28/SUM(Q29,Q30,Q31),"")
A11: BDO产量（转储运） | C11: 201 | D11: 1202.2
A12: BDO加工量 | C12: 0 | D12: 0 | L12: 综合能耗 | M12: 2750 | O12: =O32 -> 0
A13: PTMEG产量 | B13: 0 | C13: =_xlfn.IFERROR(SUM(C14,C16),"") -> 0 | D13: =_xlfn.IFERROR(SUM(D14,D16),"") -> 0
A14: PT1800国标 | C14: 0 | D14: 0 | O14: 收率本日 | P14: 收率本月 | Q14: 收率本年
A15: PT1800客标
A16: PT2000国标 | C16: 0 | D16: 0 | N16: 乙炔单耗 | O16: 575296
A17: PT2000客标
A18: CO加工量 | C18: 149920 | D18: 1054072 | O18: 81.5
A19: 乙二醇产量 | B19: 5000 | C19: =_xlfn.IFERROR(SUM(C20,C21,C22,C25),"") -> 246 | D19: =_xlfn.IFERROR(SUM(D20,D21,D22),"") -> 1198.9 | N19: 甲醛单耗 | O19: 174.5
A20: 聚酯级乙二醇 | C20: 246 | D20: 1110 | O20: 421.7
A21: 工业级乙二醇 | N21: BDO单耗 | O21: 81.5
A22: 轻质多元醇 | C22: 0 | D22: 88.9 | O22: 202
A23: BDO销售量 | C23: 226.98 | D23: 1597.16 | N23: PT单耗 | O23: 0
A24: PT销售量 | C24: =_xlfn.IFERROR(SUM(#REF!,#REF!),"") | D24: =_xlfn.IFERROR(SUM(C24,D25,D26),"") -> 62.64 | H24: =_xlfn.IFERROR(SUM(H25,H26),"") -> 0 | O24: 0
A25: PT1800 | C25: 0 | D25: 62.64
A26: PT2000 | C26: 0 | D26: 0
A27: 聚酯级乙二醇销售量 | C27: 223.72 | D27: 1073.66 | O27: 0
A28: 工业级乙二醇销售量 | C28: 0 | D28: 0 | N28: EG单耗 | O28: 36068
A29: 轻质多元醇销售量 | C29: 32.68 | D29: 130.78 | O29: 178
A30: 混合醇销售量 | C30: 32.64 | D30: 65.24 | O30: 0
A31: 副产油销售量 | C31: 0 | D31: 0 | O31: 12
N32: 综合能耗
C35: 0 | D35: 107
G40: qn_cl_lj
A43: 产品名称 | B43: 产量
B44: 本月 | D44: 累计
A45: BDO（销售） | B45: 1824.14 | D45: 1824.14
A46: PTMEG | B46: =H46+H47+H48+H49 -> 0 | D46: =J46+J47+J48+J49 -> 0 | H46: 0 | J46: 0
A47: 副产油 | B47: 0 | D47: 0
A48: 聚脂级乙二醇 | B48: 1356 | D48: 1356 | H48: 0 | J48: 0
A49: 轻质多元醇 | B49: 88.9 | D49: 88.9
...
