Workbook

Sheet 全年生产任务情况统计
B2: 全年生产任务情况统计
B3: 编制单位：生产计划部 | C3: 编制单位：生产计划部 | G3: 日期： | H3: 2025-12-31 | L3: 内部数据 | O3: =取值!A1&取值!B1&取值!C1 -> 报表生成时间：2026-01-01 8:00:00
B4: 项 目 | C4: 本月完成情况 | H4: 全年目标任务完成情况 | M4: 收率（催化收率含回炼油） | S4: 部分指标手动录入
B5: 项 目 | C5: 计划 （万吨） | D5: 本日 （吨） | E5: 累计生产 （万吨） | F5: 剩余加工量 (万吨) | G5: 日处理量 (吨) | H5: 年计划 （万吨） | I5: 完成情况 （万吨） | J5: 剩余加工量 （万吨） | K5: 剩余日处理量（吨） | L5: 完成任务比 （%） | M5: 年计划 | N5: 月计划 | O5: 本日 | P5: 本月 | Q5: 本年 | R5: 本月 + - | S5: 本月余 | T5: 本年余 | U5: 本月天数 | V5: 本年天数
B6: 原油加工量 | C6: =_xlfn.IFERROR(SUM(C7,C8),"") -> 48 | D6: =_xlfn.IFERROR(SUM(D7,D8),"") -> 16822 | E6: =_xlfn.IFERROR(SUM(E7,E8),"") -> 1.6822 | F6: =_xlfn.IFERROR(C6-E6,"") -> 46.3178 | G6: =_xlfn.IFERROR(F6*10000/取值!B4,"") -> 15439.267 | H6: =_xlfn.IFERROR(SUM(H7,H8,Y6),"") -> 0 | I6: =_xlfn.IFERROR(SUM(I7,I8,Z6),"") -> 1.6822 | J6: =_xlfn.IFERROR(H6-I6,"") -> -1.6822 | K6: =_xlfn.IFERROR(J6*10000/取值!C4,"") -> -46.214286 | L6: =_xlfn.IFERROR(I6/H6*100,"") | O6: =取值!O154 -> 49.078588 | P6: =取值!P154 -> 49.078588 | Q6: =取值!Q154 -> 49.078588 | R6: =_xlfn.IFERROR(P6-N6,"") -> 49.078588 | S6: =取值!B4 -> 30 | T6: =取值!C4 -> 364 | Z6: 0
B7: 其中：300万常压 | C7: 27.3 | D7: =取值!B7 -> 9496 | E7: =_xlfn.IFERROR(取值!B56/10000,"") -> 0.9496 | F7: =_xlfn.IFERROR(C7-E7,"") -> 26.3504 | G7: =_xlfn.IFERROR(F7*10000/取值!B4,"") -> 8783.4667 | H7: 0 | I7: =_xlfn.IFERROR(取值!B105/10000,"") -> 0.9496 | J7: =_xlfn.IFERROR(H7-I7,"") -> -0.9496 | K7: =_xlfn.IFERROR(J7*10000/取值!C4,"") -> -26.087912 | L7: =_xlfn.IFERROR(I7/H7*100,"") | O7: =取值!O155 -> 48.557287 | P7: =取值!P155 -> 48.557287 | Q7: =取值!Q155 -> 48.557287 | R7: =_xlfn.IFERROR(P7-N7,"") -> 48.557287 | X7: 0
B8: 260万常压 | C8: 20.7 | D8: =取值!B8 -> 7326 | E8: =_xlfn.IFERROR(取值!B57/10000,"") -> 0.7326 | F8: =_xlfn.IFERROR(C8-E8,"") -> 19.9674 | G8: =_xlfn.IFERROR(F8*10000/取值!B4,"") -> 6655.8 | H8: 0 | I8: =_xlfn.IFERROR(取值!B106/10000,"") -> 0.7326 | J8: =_xlfn.IFERROR(H8-I8,"") -> -0.7326 | K8: =_xlfn.IFERROR(J8*10000/取值!C4,"") -> -20.126374 | L8: =_xlfn.IFERROR(I8/H8*100,"") | O8: =取值!O156 -> 49.7543 | P8: =取值!P156 -> 49.7543 | Q8: =取值!Q156 -> 49.7543 | R8: =_xlfn.IFERROR(P8-N8,"") -> 49.7543 | X8: 0
B9: 催化渣油加工量 | C9: =_xlfn.IFERROR(SUM(C10,C11),"") -> 25.5 | D9: =_xlfn.IFERROR(SUM(D10,D11),"") -> 8807 | E9: =_xlfn.IFERROR(SUM(E10,E11),"") -> 0.8807 | F9: =_xlfn.IFERROR(C9-E9,"") -> 24.6193 | G9: =_xlfn.IFERROR(F9*10000/取值!B4,"") -> 8206.4333 | H9: =_xlfn.IFERROR(SUM(H10,H11),"") -> 0 | I9: =_xlfn.IFERROR(SUM(I10,I11),"") -> 0.8807 | J9: =_xlfn.IFERROR(H9-I9,"") -> -0.8807 | K9: =_xlfn.IFERROR(J9*10000/取值!C4,"") -> -24.195055 | L9: =_xlfn.IFERROR(I9/H9*100,"") | O9: =取值!O157 -> 87.944062 | P9: =取值!P157 -> 87.944062 | Q9: =取值!Q157 -> 87.944062 | R9: =_xlfn.IFERROR(P9-N9,"") -> 87.944062
B10: 其中：200万催化 | C10: 17.6 | D10: =取值!B9 -> 5996 | E10: =_xlfn.IFERROR(取值!B58/10000,"") -> 0.5996 | F10: =_xlfn.IFERROR(C10-E10,"") -> 17.0004 | G10: =_xlfn.IFERROR(F10*10000/取值!B4,"") -> 5666.8 | H10: 0 | I10: =_xlfn.IFERROR(取值!B107/10000,"") -> 0.5996 | J10: =_xlfn.IFERROR(H10-I10,"") -> -0.5996 | K10: =_xlfn.IFERROR(J10*10000/取值!C4,"") -> -16.472527 | L10: =_xlfn.IFERROR(I10/H10*100,"") | O10: =取值!O158 -> 87.758506 | P10: =取值!P158 -> 87.758506 | Q10: =取值!Q158 -> 87.758506 | R10: =_xlfn.IFERROR(P10-N10,"") -> 87.758506 | X10: 0
B11: 100万催化 | C11: 7.9 | D11: =取值!B10 -> 2811 | E11: =_xlfn.IFERROR(取值!B59/10000,"") -> 0.2811 | F11: =_xlfn.IFERROR(C11-E11,"") -> 7.6189 | G11: =_xlfn.IFERROR(F11*10000/取值!B4,"") -> 2539.6333 | H11: 0 | I11: =_xlfn.IFERROR(取值!B108/10000,"") -> 0.2811 | J11: =_xlfn.IFERROR(H11-I11,"") -> -0.2811 | K11: =_xlfn.IFERROR(J11*10000/取值!C4,"") -> -7.7225275 | L11: =_xlfn.IFERROR(I11/H11*100,"") | O11: =取值!O159 -> 88.331592 | P11: =取值!P159 -> 88.331592 | Q11: =取值!Q159 -> 88.331592 | R11: =_xlfn.IFERROR(P11-N11,"") -> 88.331592 | X11: 0
B12: 苯乙烯产量 | C12: 0.46 | D12: =取值!B21 -> 155 | E12: =_xlfn.IFERROR(取值!B70/10000,"") -> 0.0155 | F12: =_xlfn.IFERROR(C12-E12,"") -> 0.4445 | G12: =_xlfn.IFERROR(F12*10000/取值!B4,"") -> 148.16667 | H12: 0 | I12: =_xlfn.IFERROR(取值!B119/10000,"") -> 0.0155 | J12: =_xlfn.IFERROR(H12-I12,"") -> -0.0155 | K12: =_xlfn.IFERROR(J12*10000/取值!C4,"") -> -0.42582418 | L12: =_xlfn.IFERROR(I12/H12*100,"") | O12: =取值!O160 -> 94.512195 | P12: =取值!P160 -> 94.512195 | Q12: =取值!Q160 -> 94.512195 | R12: =_xlfn.IFERROR(P12-N12,"") -> 94.512195 | U12: 11920 | X12: 0
B13: 气分装置加工量 | C13: 2.77 | D13: =取值!B11 -> 945 | E13: =_xlfn.IFERROR(取值!B60/10000,"") -> 0.0945 | F13: =_xlfn.IFERROR(C13-E13,"") -> 2.6755 | G13: =_xlfn.IFERROR(F13*10000/取值!B4,"") -> 891.83333 | H13: 0 | I13: =_xlfn.IFERROR(取值!B109/10000,"") -> 0.0945 | J13: =_xlfn.IFERROR(H13-I13,"") -> -0.0945 | K13: =_xlfn.IFERROR(J13*10000/取值!C4,"") -> -2.5961538 | L13: =_xlfn.IFERROR(I13/H13*100,"") | U13: 每月初输入以下两指标 | V13: 每日输入以下两指标 | X13: 0
B14: 聚丙烯产量 | C14: 0.9 | D14: =取值!A18 -> 296 | E14: =_xlfn.IFERROR(取值!A67/10000,"") -> 0.0296 | F14: =_xlfn.IFERROR(C14-E14,"") -> 0.8704 | G14: =_xlfn.IFERROR(F14*10000/取值!B4,"") -> 290.13333 | H14: 0 | I14: =_xlfn.IFERROR(取值!A116/10000,"") -> 0.0296 | J14: =_xlfn.IFERROR(H14-I14,"") -> -0.0296 | K14: =_xlfn.IFERROR(J14*10000/取值!C4,"") -> -0.81318681 | L14: =_xlfn.IFERROR(I14/H14*100,"") | M14: 项目名称 | N14: 单位 | O14: 本日 | P14: 月累计 | Q14: 年累计 | X14: 0
B15: MTBE产量 | C15: 0.31 | D15: =取值!B19 -> 104 | E15: =_xlfn.IFERROR(取值!B68/10000,"") -> 0.0104 | F15: =_xlfn.IFERROR(C15-E15,"") -> 0.2996 | G15: =_xlfn.IFERROR(F15*10000/取值!B4,"") -> 99.866667 | H15: 0 | I15: =_xlfn.IFERROR(取值!B117/10000,"") -> 0.0104 | J15: =_xlfn.IFERROR(H15-I15,"") -> -0.0104 | K15: =_xlfn.IFERROR(J15*10000/取值!C4,"") -> -0.28571429 | L15: =_xlfn.IFERROR(I15/H15*100,"") | M15: 3号喷气燃料销售 | N15: 吨 | O15: =取值!L48 -> 0 | P15: =取值!L97 -> 0 | Q15: =取值!L146 -> 0 | U15: 10941 | X15: 0
B16: SBA产量 | C16: 0.51 | D16: =取值!B20 -> 159 | E16: =_xlfn.IFERROR(取值!B69/10000,"") -> 0.0159 | F16: =_xlfn.IFERROR(C16-E16,"") -> 0.4941 | G16: =_xlfn.IFERROR(F16*10000/取值!B4,"") -> 164.7 | H16: 0 | I16: =_xlfn.IFERROR(取值!B118/10000,"") -> 0.0159 | J16: =_xlfn.IFERROR(H16-I16,"") -> -0.0159 | K16: =_xlfn.IFERROR(J16*10000/取值!C4,"") -> -0.43681319 | L16: =_xlfn.IFERROR(I16/H16*100,"") | N16: 车 | O16: =取值!L49 -> 0 | P16: =取值!L98 -> 0 | Q16: =取值!L147 -> 0 | X16: 0
B17: 92#汽油调合量 | C17: 14 | D17: =取值!B24 -> 0 | E17: =_xlfn.IFERROR(取值!B73/10000,"") -> 0 | F17: =_xlfn.IFERROR(C17-E17,"") -> 14 | G17: =_xlfn.IFERROR(F17*10000/取值!B4,"") -> 4666.6667 | H17: 0 | I17: =_xlfn.IFERROR(取值!B122/10000+Z17,"") -> 0 | J17: =_xlfn.IFERROR(H17-I17,"") -> 0 | K17: =_xlfn.IFERROR(J17*10000/取值!C4,"") -> 0 | L17: =_xlfn.IFERROR(I17/H17*100,"") | X17: 0
B18: 92#汽油销售量 | D18: =取值!A29 -> 7627 | E18: =_xlfn.IFERROR(取值!A78/10000,"") -> 0.7627 | I18: =_xlfn.IFERROR(取值!A127/10000,"") -> 0.7627
B19: 95#汽油调合量 | C19: 11 | D19: =取值!B32 -> 6710 | E19: =_xlfn.IFERROR(取值!B81/10000,"") -> 0.671 | F19: =_xlfn.IFERROR(C19-E19,"") -> 10.329 | G19: =_xlfn.IFERROR(F19*10000/取值!B4,"") -> 3443 | H19: 0 | I19: =_xlfn.IFERROR(取值!B130/10000,"") -> 0.671 | J19: =_xlfn.IFERROR(H19-I19,"") -> -0.671 | K19: =_xlfn.IFERROR(J19*10000/取值!C4,"") -> -18.434066 | L19: =_xlfn.IFERROR(I19/H19*100,"") | X19: 0
B20: 95#汽油销售量 | D20: =取值!A37 -> 4189 | E20: =_xlfn.IFERROR(取值!A86/10000,"") -> 0.4189 | I20: =_xlfn.IFERROR(取值!A135/10000,"") -> 0.4189
B21: 98#汽油调合量 | C21: 0 | D21: =取值!L32 -> 0 | E21: =_xlfn.IFERROR(取值!N81/10000,"") -> 0 | F21: =_xlfn.IFERROR(C21-E21,"") -> 0 | G21: =_xlfn.IFERROR(F21*10000/取值!B4,"") -> 0 | H21: 0 | I21: =_xlfn.IFERROR(取值!O130/10000,"") -> 0 | J21: =_xlfn.IFERROR(H21-I21,"") -> 0 | K21: =_xlfn.IFERROR(J21*10000/取值!C4,"") -> 0 | L21: =_xlfn.IFERROR(I21/H21*100,"") | X21: 0
B22: 98#汽油销售量 | D22: =取值!L37 -> 0 | E22: =_xlfn.IFERROR(取值!N86/10000,"") -> 0 | I22: =_xlfn.IFERROR(取值!O135/10000,"") -> 0
B23: 汽油总调合量 | C23: 25 | D23: =_xlfn.IFERROR(SUM(D17,D19,D21),"") -> 6710 | E23: =_xlfn.IFERROR(SUM(E17,E19,E21),"") -> 0.671 | F23: =_xlfn.IFERROR(C23-E23,"") -> 24.329 | G23: =_xlfn.IFERROR(F23*10000/取值!B4,"") -> 8109.6667 | H23: 0 | I23: =_xlfn.IFERROR(SUM(I17,I19,I21),"") -> 0.671 | J23: =_xlfn.IFERROR(H23-I23,"") -> -0.671 | K23: =_xlfn.IFERROR(J23*10000/取值!C4,"") -> -18.434066 | L23: =_xlfn.IFERROR(I23/H23*100,"")
B24: 汽油总销售量 | D24: =_xlfn.IFERROR(SUM(D18,D20,D22),"") -> 11816 | E24: =_xlfn.IFERROR(SUM(E18,E20,E22),"") -> 1.1816 | I24: =_xlfn.IFERROR(SUM(I18,I20,I22),"") -> 1.1816 | M24: 项目名称 | N24: 单位 | O24: 本日 | P24: 月累计 | Q24: 年累计
B25: 0#柴油调合量 | C25: 18 | D25: =取值!B40 -> 11925 | E25: =_xlfn.IFERROR(取值!B89/10000,"") -> 1.1925 | F25: =_xlfn.IFERROR(C25-E25,"") -> 16.8075 | G25: =_xlfn.IFERROR(F25*10000/取值!B4,"") -> 5602.5 | H25: 0 | I25: =_xlfn.IFERROR(取值!B138/10000+Z25,"") -> 1.1925 | J25: =_xlfn.IFERROR(H25-I25,"") -> -1.1925 | K25: =_xlfn.IFERROR(J25*10000/取值!C4,"") -> -32.760989 | L25: =_xlfn.IFERROR(I25/H25*100,"") | M25: 榆炼氨水 | N25: 吨 | O25: =取值!M51 -> 0 | P25: =取值!M100 -> 0 | Q25: =取值!M149 -> 0 | X25: 0
B26: 0#柴油销售量 | D26: =取值!A45 -> 40 | E26: =_xlfn.IFERROR(取值!A94/10000,"") -> 0.004 | I26: =_xlfn.IFERROR(取值!A143/10000,"") -> 0.004 | N26: 车 | O26: =_xlfn.IFERROR(ROUND(O25/30,0),"") -> 0 | P26: =_xlfn.IFERROR(ROUND(P25/30,0),"") -> 0 | Q26: =_xlfn.IFERROR(ROUND(Q25/30,0),"") -> 0
B27: 3号喷气燃料产量 | C27: 1.92 | D27: =取值!B181 -> 0 | E27: =_xlfn.IFERROR(取值!C181/10000,"") -> 0 | F27: =_xlfn.IFERROR(C27-E27,"") -> 1.92 | G27: =_xlfn.IFERROR(F27*10000/取值!B4,"") -> 640 | H27: 0 | I27: =_xlfn.IFERROR(取值!E181/10000,"") -> 0 | J27: =_xlfn.IFERROR(H27-I27,"") -> 0 | K27: =_xlfn.IFERROR(J27*10000/取值!C4,"") -> 0 | L27: =_xlfn.IFERROR(I27/H27*100,"") | X27: 0
B28: 3号喷气燃料销售量 | D28: =取值!B182 -> 0 | E28: =_xlfn.IFERROR(取值!C182/10000,"") -> 0 | I28: =_xlfn.IFERROR(取值!E182/10000,"") -> 0
B29: 备注 | C29: 本月接收原油1.63万吨，其中接收长庆原油0万吨；全年接收原油1.63万吨，其中接收长庆原油0万吨。
B30: 备注 | C30: 距离12月底还有364天。
B31: 单位负责人： | C31: 王静 | I31: 审核人： | J31: 李小军 | P31: 制表人： | Q31: 韩卫玲

Sheet 取值
A1: 报表生成时间： | B1: 2026-01-01 | C1: 8:00:00 | E1: 王静 | O1: 本月累计 | P1: 本年累计
E2: 李小军 | N2: 1.原 油 | O2: =_xlfn.IFERROR(ROUND(SUM(O3,O6,O7)/10000,2),0) -> 1.63 | P2: =_xlfn.IFERROR(ROUND(SUM(P3,P6,P7)/10000,2),0) -> 1.63 | Q2: =_xlfn.IFERROR(ROUND(O4/10000,2),0) -> 0 | R2: =_xlfn.IFERROR(ROUND(P4/10000,2),0) -> 0
B3: 当日-本月 | C3: 当月-本年 | E3: 韩卫玲 | N3: ①.管 输 | O3: =SUM(O4:O5) -> 16310 | P3: =SUM(P4:P5) -> 16310
B4: 30 | C4: 364 | N4: 其中:长 庆 | O4: 0 | P4: 0
N5: 管道公司 | O5: 16310 | P5: 16310
B6: 本日（吨） | N6: ②.长庆长东 | O6: 0 | P6: 0
B7: 9496 | N7: ③.钻采公司 | O7: =SUM(O8:O11) -> 0 | P7: =SUM(P8:P11) -> 0
B8: 7326 | N8: 其中： 英 旺 | O8: 0 | P8: 0
B9: 5996 | N9: 油气勘探 | O9: 0 | P9: 0
B10: 2811 | N10: 旬 邑 | O10: 0 | P10: 0
B11: 945 | N11: 黄陵指挥部 | O11: 0 | P11: 0
B12: 296
B13: 0 | N13: 本月接收原油
B14: 0 | N14: 万吨，
B15: 0 | N15: 其中接收长庆原油
B16: 0 | N16: 万吨；
B17: 0 | N17: 全年接收原油
A18: =_xlfn.IFERROR(SUM(B12,B13,B14,B15,B16,B17,B18),"") -> 296 | B18: 0 | N18: 万吨，
B19: 104 | N19: 其中接收长庆原油
B20: 159 | N20: 万吨。
B21: 155 | N21: 距离12月底还有
N22: 天。
B23: 92#汽油调合量 | N23: =SUM(C4) -> 364
N25: =N13&O2&N14&N15&Q2&N16&N17&P2&N18&N19&R2&N20 -> 本月接收原油1.63万吨，其中接收长庆原油0万吨；全年接收原油1.63万吨，其中接收长庆原油0万吨。
B26: 92#汽油销售量 | N26: =N21&N23&N22 -> 距离12月底还有364天。
B27: 0
B28: 0
A29: =_xlfn.IFERROR(SUM(B27,B28,B29),"") -> 7627 | B29: 7627
B31: 95#汽油调合量 | L31: 98#汽油调合量
B32: 6710
B34: 95#汽油销售量 | M34: 98#汽油销售量
B35: 32 | M35: 0
B36: 1679 | M36: 0
A37: =_xlfn.IFERROR(SUM(B35,B36,B37),"") -> 4189 | B37: 2478 | L37: =_xlfn.IFERROR(SUM(M35,M36,M37),"") -> 0 | M37: 0
B39: 0#柴油调合量
B40: 11925
B42: 0#柴油销售量
B43: 40
B44: 0
A45: =_xlfn.IFERROR(SUM(B43,B44,B45),"") -> 40 | B45: 0
...

Sheet 计划取值
F4: YL_SCJHBTHHZ_Day | K4: YL_SCJHBTHHZ_Day
C5: 月计划 | F5: 月计划调整量 | H5: 年计划 | K5: 年计划调整量
B6: 原油加工量
B7: 其中：300万常压 | C7: 27.3 | F7: 0 | K7: 355
B8: 260万常压 | C8: 20.7 | F8: 0 | K8: 275
B9: 催化渣油加工量 | K9: 0
B10: 其中：200万催化 | C10: 17.6 | F10: 0 | K10: 213
B11: 100万催化 | C11: 7.9 | F11: 0 | K11: 95
B12: 苯乙烯产量 | C12: =_xlfn.IFERROR(D12/10000,0) -> 0.46 | D12: 4600 | F12: 0 | H12: =_xlfn.IFERROR(I12/10000,0) -> 0 | K12: 5
B13: 气分装置加工量 | C13: 2.77 | F13: 0 | K13: 30
B14: 聚丙烯产量 | C14: =_xlfn.IFERROR(ROUND(D14,0)/10000,0) -> 0.9 | D14: 9000 | F14: 0 | H14: =_xlfn.IFERROR(ROUND(I14,0)/10000,0) -> 0 | K14: 10
B15: MTBE产量 | C15: =_xlfn.IFERROR(ROUND(D15,0)/10000,0) -> 0.31 | D15: 3100 | F15: 0 | H15: =_xlfn.IFERROR(ROUND(I15,0)/10000,0) -> 0 | K15: 3.7
B16: SBA产量 | C16: =_xlfn.IFERROR(ROUND(D16,0)/10000,0) -> 0.51 | D16: 5100 | F16: 0 | H16: =_xlfn.IFERROR(ROUND(I16,0)/10000,0) -> 0 | K16: 5.6
B17: 92#汽油调合量 | C17: =_xlfn.IFERROR(D17/10000,0) -> 14 | D17: 140000 | F17: 0 | H17: =_xlfn.IFERROR(I17/10000,0) -> 0 | K17: 201.26
B18: 92#汽油销售量
B19: 95#汽油调合量 | C19: =_xlfn.IFERROR(D19/10000,0) -> 11 | D19: 110000 | F19: 0 | H19: =_xlfn.IFERROR(I19/10000,0) -> 0 | K19: 106.27
B20: 95#汽油销售量
B21: 98#汽油调合量 | C21: =_xlfn.IFERROR(D21/10000,0) -> 0 | D21: 0 | H21: =_xlfn.IFERROR(I21/10000,0) -> 0 | K21: 4
B22: 98#汽油销售量
B23: 0#柴油调合量 | C23: =_xlfn.IFERROR(D23/10000,0) -> 18 | D23: 180000 | F23: 0 | H23: =_xlfn.IFERROR(I23/10000,0) -> 0 | K23: 257.75
B24: 0#柴油销售量
B25: 3号喷气燃料产量 | C25: 19200 | F25: 0 | K25: 15
B26: 3号喷气燃料销售量
C28: 收率（催化收率含回炼油）
C29: 年计划 | D29: 月计划
C30: 48.06 | D30: 48.06
C31: 48.5 | D31: 48.1
C32: 47.6 | D32: 48.1
C33: 87.64 | D33: 87.64
C34: 87.6 | D34: 87.6
C35: 87.7 | D35: 87.7
C36: 94 | D36: 94.4
