Workbook

Sheet 榆炼全年生产任务情况统计表
B1: 全年生产任务情况统计
B2: 编制单位：生产计划部 | G2: 日期： | H2: 2025-12-31 | L2: =取值!A1&取值!B1&取值!C1 -> 报表生成时间：2026-01-01 8:00:00
B3: 项目 | C3: 月计划 | D3: 本日 | E3: 本月 | F3: 本月 | G3: 至本月底 | H3: 年计划 （万吨） | I3: 全年累计 加工量 （万吨） | J3: 全年剩余 加工量 （万吨） | K3: 至12月底 日处理量 （吨） | L3: 完成全年任 务的（%） | M3: 装置收率
C4: （万吨） | D4: （吨） | E4: 累计生产 （万吨） | F4: 剩余加工量(万吨) | G4: 日处理量 (吨) | M4: 年计划 | N4: 月计划 | O4: 本日 | P4: 本月 | Q4: 本年 | R4: 本月（+-）
B5: 500万常压加工量 | C5: 54.2 | D5: =取值!C6 -> 10329 | E5: =_xlfn.IFERROR((取值!C6+取值!D6)/10000,"") -> 1.0329 | F5: =_xlfn.IFERROR(C5-E5,"") -> 53.1671 | G5: =_xlfn.IFERROR(F5*10000/取值!R2,"") -> 17722.367 | H5: 510 | I5: =_xlfn.IFERROR((取值!C6+取值!H6)/10000,"") -> 398.2604 | J5: =_xlfn.IFERROR(H5-I5,"") -> 111.7396 | K5: =_xlfn.IFERROR(J5*10000/取值!S2,"") -> 3069.7692 | L5: =_xlfn.IFERROR(I5/H5*100,"") -> 78.090275 | M5: 51 | N5: 50 | O5: =取值!N6 -> 53.13693 | P5: =取值!O6 -> 53.13693 | Q5: =取值!P6 -> 53.13693 | R5: =_xlfn.IFERROR(P5-N5,"") -> 3.1369301
B6: 180万催化加工量 | C6: 9.5 | D6: =取值!C7 -> 4334 | E6: =_xlfn.IFERROR((取值!C7+取值!D7)/10000,"") -> 0.4334 | F6: =_xlfn.IFERROR(C6-E6,"") -> 9.0666 | G6: =_xlfn.IFERROR(F6*10000/取值!R2,"") -> 3022.2 | H6: 178 | I6: =_xlfn.IFERROR((取值!C7+取值!H7)/10000,"") -> 147.6279 | J6: =_xlfn.IFERROR(H6-I6,"") -> 30.3721 | K6: =_xlfn.IFERROR(J6*10000/取值!S2,"") -> 834.39835 | M6: 84.65 | N6: 84.5 | O6: =取值!N7+取值!S18 -> 85.002307 | P6: =取值!O7+取值!T18 -> 85.002307 | Q6: =取值!P7+取值!U18 -> 85.002307 | R6: =_xlfn.IFERROR(P6-N6,"") -> 0.50230734
B7: 100万连续重整加工量 | C7: 8.8 | D7: =取值!C8 -> 3324 | E7: =_xlfn.IFERROR((取值!C8+取值!D8)/10000,"") -> 0.3324 | F7: =_xlfn.IFERROR(C7-E7,"") -> 8.4676 | G7: =_xlfn.IFERROR(F7*10000/取值!R2,"") -> 2822.5333 | H7: 95 | I7: =_xlfn.IFERROR((取值!C8+取值!H8)/10000,"") -> 100.56385 | J7: =_xlfn.IFERROR(H7-I7,"") -> -5.56385 | K7: =_xlfn.IFERROR(J7*10000/取值!S2,"") -> -152.85302 | M7: 92.9 | N7: 92.3 | O7: =取值!N8 -> 93.351384 | P7: =取值!O8 -> 93.351384 | Q7: =取值!P8 -> 93.351384 | R7: =_xlfn.IFERROR(P7-N7,"") -> 1.0513839
B8: 90万汽油精制加工量 | C8: 6.4 | D8: =取值!C9 -> 2053 | E8: =_xlfn.IFERROR((取值!C9+取值!D9)/10000,"") -> 0.2053 | F8: =_xlfn.IFERROR(C8-E8,"") -> 6.1947 | G8: =_xlfn.IFERROR(F8*10000/取值!R2,"") -> 2064.9 | H8: 88 | I8: =_xlfn.IFERROR((取值!C9+取值!H9)/10000,"") -> 84.210543 | J8: =_xlfn.IFERROR(H8-I8,"") -> 3.789457 | K8: =_xlfn.IFERROR(J8*10000/取值!S2,"") -> 104.10596 | M8: 99 | N8: 98.5 | O8: =取值!N9 -> 99.36678 | P8: =取值!O9 -> 99.36678 | Q8: =取值!P9 -> 99.36678 | R8: =_xlfn.IFERROR(P8-N8,"") -> 0.86678032
B9: 200万柴油精制加工量 | C9: 17.5 | D9: =取值!C10 -> 4749 | E9: =_xlfn.IFERROR((取值!C10+取值!D10)/10000,"") -> 0.4749 | F9: =_xlfn.IFERROR(C9-E9,"") -> 17.0251 | G9: =_xlfn.IFERROR(F9*10000/取值!R2,"") -> 5675.0333 | H9: 180 | I9: =_xlfn.IFERROR((取值!C10+取值!H10)/10000,"") -> 191.51994 | J9: =_xlfn.IFERROR(H9-I9,"") -> -11.519943 | K9: =_xlfn.IFERROR(J9*10000/取值!S2,"") -> -316.48195 | M9: 98.9 | N9: 98.5 | O9: =取值!N10 -> 99.305117 | P9: =取值!O10 -> 99.305117 | Q9: =取值!P10 -> 99.305117 | R9: =_xlfn.IFERROR(P9-N9,"") -> 0.80511687
B10: 20万DCC石脑油加工量 | C10: 0 | D10: =取值!C11 -> 0 | E10: =_xlfn.IFERROR((取值!C11+取值!D11)/10000,"") -> 0 | F10: =_xlfn.IFERROR(C10-E10,"") -> 0 | G10: =_xlfn.IFERROR(F10*10000/取值!R2,"") -> 0 | H10: 0 | I10: =_xlfn.IFERROR((取值!C11+取值!H11)/10000,"") -> 0 | J10: =_xlfn.IFERROR(H10-I10,"") -> 0 | K10: =_xlfn.IFERROR(J10*10000/取值!S2,"") -> 0 | M10: 0 | N10: 0 | O10: =取值!N11 -> 0 | P10: =取值!O11 -> 0 | Q10: =取值!P11 -> 0 | R10: =_xlfn.IFERROR(P10-N10,"") -> 0
B11: 进口原油加工量 | C11: 0 | D11: =取值!C12 -> 3554 | E11: =_xlfn.IFERROR((取值!C12+取值!D12)/10000,"") -> 0.3554 | F11: =_xlfn.IFERROR(C11-E11,"") -> -0.3554 | G11: =_xlfn.IFERROR(F11*10000/取值!R2,"") -> -118.46667 | H11: 0 | I11: =_xlfn.IFERROR((取值!C12+取值!H12)/10000,"") -> 135.7292 | J11: =_xlfn.IFERROR(H11-I11,"") -> -135.7292 | K11: =_xlfn.IFERROR(J11*10000/取值!S2,"") -> -3728.8242 | M11: 0 | N11: 0 | R11: =_xlfn.IFERROR(P11-N11,"") -> 0
B12: 航煤产量 | C12: 0 | D12: =取值!C13 -> 898 | E12: =_xlfn.IFERROR((取值!C13+取值!D13)/10000,"") -> 0.0898 | F12: =_xlfn.IFERROR(C12-E12,"") -> -0.0898 | G12: =_xlfn.IFERROR(F12*10000/取值!R2,"") -> -29.933333 | I12: =_xlfn.IFERROR((取值!C13+取值!H13)/10000,"") -> 27.3614
B13: 液化气产量 | C13: 2.15 | D13: =取值!C14 -> 654 | E13: =_xlfn.IFERROR((取值!C14+取值!D14)/10000,"") -> 0.0654 | F13: =_xlfn.IFERROR(C13-E13,"") -> 2.0846 | G13: =_xlfn.IFERROR(F13*10000/取值!R2,"") -> 694.86667 | H13: 23.2 | I13: =_xlfn.IFERROR((取值!C14+取值!H14)/10000,"") -> 22.743 | J13: =_xlfn.IFERROR(H13-I13,"") -> 0.457 | K13: =_xlfn.IFERROR(J13*10000/取值!S2,"") -> 12.554945
B14: 苯产量 | C14: 0.42 | D14: =取值!C15 -> 139 | E14: =_xlfn.IFERROR((取值!C15+取值!D15)/10000,"") -> 0.0139 | F14: =_xlfn.IFERROR(C14-E14,"") -> 0.4061 | G14: =_xlfn.IFERROR(F14*10000/取值!R2,"") -> 135.36667 | H14: 2.9726 | I14: =_xlfn.IFERROR((取值!C15+取值!H15)/10000,"") -> 4.152924 | J14: =_xlfn.IFERROR(H14-I14,"") -> -1.180324 | K14: =_xlfn.IFERROR(J14*10000/取值!S2,"") -> -32.426484
B15: 混合二甲苯产量 | C15: 0 | D15: =取值!C16 -> 455 | E15: =_xlfn.IFERROR((取值!C16+取值!D16)/10000,"") -> 0.0455 | F15: =_xlfn.IFERROR(C15-E15,"") -> -0.0455 | G15: =_xlfn.IFERROR(F15*10000/取值!R2,"") -> -15.166667 | H15: 6.65 | I15: =_xlfn.IFERROR((取值!C16+取值!H16)/10000,"") -> 9.57811 | J15: =_xlfn.IFERROR(H15-I15,"") -> -2.92811 | K15: =_xlfn.IFERROR(J15*10000/取值!S2,"") -> -80.442582
B16: 2#渣油产量 | C16: 0.31 | D16: =取值!C17 -> 196 | E16: =_xlfn.IFERROR((取值!C17+取值!D17)/10000,"") -> 0.0196 | F16: =_xlfn.IFERROR(C16-E16,"") -> 0.2904 | G16: =_xlfn.IFERROR(F16*10000/取值!R2,"") -> 96.8 | H16: 5.874 | I16: =_xlfn.IFERROR((取值!C17+取值!H17)/10000,"") -> 5.5515 | J16: =_xlfn.IFERROR(H16-I16,"") -> 0.3225 | K16: =_xlfn.IFERROR(J16*10000/取值!S2,"") -> 8.8598901
B17: 92#汽油产量 | C17: 0 | D17: =取值!C18 -> 0 | E17: =_xlfn.IFERROR((取值!C18+取值!D18)/10000,"") -> 0 | F17: =_xlfn.IFERROR(C17-E17,"") -> 0 | G17: =_xlfn.IFERROR(F17*10000/取值!R2,"") -> 0 | H17: 130.54 | I17: =_xlfn.IFERROR((取值!C18+取值!H18)/10000,"") -> 147.9586 | J17: =_xlfn.IFERROR(H17-I17,"") -> -17.4186 | K17: =_xlfn.IFERROR(J17*10000/取值!S2,"") -> -478.53297
B18: 92#汽油销售量（公路+铁路） | D18: =取值!C19 -> 1408.515 | I18: =_xlfn.IFERROR((取值!C19+取值!H19)/10000,"") -> 99.752895
B19: 95#汽油产量 | C19: 0 | D19: =取值!C20 -> 0 | E19: =_xlfn.IFERROR((取值!C20+取值!D20)/10000,"") -> 0 | F19: =_xlfn.IFERROR(C19-E19,"") -> 0 | G19: =_xlfn.IFERROR(F19*10000/取值!R2,"") -> 0 | H19: 19.46 | I19: =_xlfn.IFERROR((取值!C20+取值!H20)/10000,"") -> 17.9565 | J19: =_xlfn.IFERROR(H19-I19,"") -> 1.5035 | K19: =_xlfn.IFERROR(J19*10000/取值!S2,"") -> 41.304945
B20: 95#汽油销售量 | D20: =取值!C21 -> 223.14 | I20: =_xlfn.IFERROR((取值!C21+取值!H21)/10000,"") -> 19.934632
B21: 汽油总产量 | C21: 0 | D21: =取值!C22 -> 0 | E21: =_xlfn.IFERROR((取值!C22+取值!D22)/10000,"") -> 0 | F21: =_xlfn.IFERROR(C21-E21,"") -> 0 | G21: =_xlfn.IFERROR(F21*10000/取值!R2,"") -> 0 | H21: 150 | I21: =_xlfn.IFERROR((取值!C22+取值!H22)/10000,"") -> 165.9151 | J21: =_xlfn.IFERROR(H21-I21,"") -> -15.9151 | K21: =_xlfn.IFERROR(J21*10000/取值!S2,"") -> -437.22802
B22: 汽油总销售量（公路+铁路） | D22: =取值!C23 -> 1631.655 | I22: =_xlfn.IFERROR((取值!C23+取值!H23)/10000,"") -> 119.68753 | M22: 项目名称 | N22: 单位 | O22: 本日 | P22: 月累计 | Q22: 年累计
B23: 0#柴油产量 | D23: =取值!C24 -> 0 | I23: =_xlfn.IFERROR((取值!C24+取值!H24)/10000,"") -> 155.9802 | M23: 进口原油收购量 | N23: 吨 | O23: 8541.29 | P23: 8541.29 | Q23: 8541.29
B24: 0#柴油销售量（公路+铁路） | D24: =取值!C25 -> 504.768 | I24: =_xlfn.IFERROR((取值!C25+取值!H25)/10000,"") -> 113.14692
B25: 备注
B26: 单位负责人： | C26: 0 | G26: 统计负责人： | H26: 0 | O26: 填报人： | P26: 0

Sheet 取值
A1: 报表生成时间： | B1: 2026-01-01 | C1: 8:00:00 | R1: 当日-本月 | S1: 当月-本年
A2: 日 | B2: 月 | C2: 年 | R2: 30 | S2: 364
A4: 项？？？？目 | B4: 月计划 | C4: 本日 | D4: 本月 | E4: 本月 | F4: 至本月底 | G4: 年计划 （万吨） | H4: 全年累计 加工量 （万吨） | I4: 全年剩余 加工量 （万吨） | J4: 至12月底 日处理量 （吨） | K4: 完成全年任 务的（%） | L4: 装置收率
B5: （万吨） | C5: （吨） | D5: 累计生产 （万吨） | E5: 剩余加工量 ？(万吨) | F5: 日处理量 (吨) | L5: 年计划 | M5: 月计划 | N5: 本日 | O5: 本月 | P5: 本年 | Q5: 本月 +？-？？？？ | R5: 0
A6: 500万常压加工量 | B6: 542000 | C6: 10329 | E6: =_xlfn.IFERROR(B6-D6,"") -> 542000 | F6: =_xlfn.IFERROR(E6*10000/取值!Q3,"") | G6: 5100000 | H6: 3972275 | L6: 51 | M6: 50 | N6: 53.13693 | O6: 53.13693 | P6: 53.13693 | R6: 0
A7: 180万催化加工量 | B7: 95000 | C7: 4334 | G7: 1780000 | H7: 1471945 | L7: 84.65 | M7: 68.6 | N7: 69.912321 | O7: 69.912321 | P7: 69.912321
A8: 100万连续重整加工量 | B8: 88000 | C8: 3324 | G8: 950000 | H8: 1002314.5 | L8: 92.9 | M8: 92.3 | N8: 93.351384 | O8: 93.351384 | P8: 93.351384
A9: 90万汽油精制加工量 | B9: 64000 | C9: =_xlfn.IFERROR(C26+C27,"") -> 2053 | D9: =_xlfn.IFERROR(D26+D27,"") -> 0 | G9: 880000 | H9: =_xlfn.IFERROR(H26+H27,"") -> 840052.43 | L9: 99 | M9: 98.5 | N9: 99.36678 | O9: 99.36678 | P9: 99.36678 | R9: 0
A10: 200万柴油精制加工量 | B10: 175000 | C10: =_xlfn.IFERROR(A27+A28,"") -> 4749 | D10: =_xlfn.IFERROR(A30+A31,"") -> 0 | G10: 1800000 | H10: =_xlfn.IFERROR(A33+A34,"") -> 1910450.4 | L10: 98.9 | M10: 98.5 | N10: 99.305117 | O10: 99.305117 | P10: 99.305117 | R10: 0
A11: 20万DCC石脑油加工量 | B11: 0 | C11: =_xlfn.IFERROR(R5+R6,"") -> 0 | D11: =_xlfn.IFERROR(R7+R8,"") -> 0 | H11: =_xlfn.IFERROR(R9+R10,"") -> 0
A12: 进口原油加工量 | B12: 0 | C12: 3554 | G12: 0 | H12: 1353738
A13: 航煤产量 | C13: 898 | G13: 250000 | H13: 272716
A14: 液化气产量 | B14: 21500 | C14: =_xlfn.IFERROR(C28+C29+C30,"") -> 654 | D14: =_xlfn.IFERROR(D28+D29+D30,"") -> 0 | G14: 232000 | H14: =_xlfn.IFERROR(H28+H29+H30,"") -> 226776
A15: 苯产量 | B15: 4200 | C15: =_xlfn.IFERROR(C32+C33,"") -> 139 | D15: =_xlfn.IFERROR(D32+D33,"") -> 0 | G15: 29726 | H15: =_xlfn.IFERROR(H32+H33,"") -> 41390.24
A16: 混合二甲苯产量 | C16: 455 | G16: 66500 | H16: 95326.1
A17: 2#渣油产量 | B17: 3100 | C17: =_xlfn.IFERROR(C35+C36,"") -> 196 | D17: =_xlfn.IFERROR(D35+D36,"") -> 0 | G17: 58740 | H17: =_xlfn.IFERROR(H35+H36,"") -> 55319
A18: 92#汽油产量 | G18: 1305400 | H18: 1479586 | S18: 15.089986 | T18: 15.089986 | U18: 15.089986
A19: 92#汽油销售量（公路+铁路） | C19: 1408.515 | H19: 996120.43 | T19: 15.9
A20: 95#汽油产量 | G20: 194600 | H20: 179565
A21: 95#汽油销售量 | C21: 223.14 | H21: 199123.18
A22: 汽油总产量 | B22: =B18+B20 -> 0 | C22: =_xlfn.IFERROR(C20+C18,"") -> 0 | D22: =_xlfn.IFERROR(D20+D18,"") -> 0 | G22: 1500000 | H22: =_xlfn.IFERROR(H20+H18,"") -> 1659151
A23: 汽油总销售量（公路+铁路） | B23: =B19+B21 -> 0 | C23: =_xlfn.IFERROR(C19+C21,"") -> 1631.655 | D23: =_xlfn.IFERROR(D19+D21,"") -> 0 | G23: =G19+G21 -> 0 | H23: =_xlfn.IFERROR(H19+H21,"") -> 1195243.6 | L23: 项目名称 | M23: 单位 | N23: 本日 | O23: 月累计 | P23: 年累计
A24: 0#柴油产量 | G24: 1641452 | H24: 1559802 | L24: 进口原油收购量 | M24: 吨 | N24: 8541.29 | O24: 8541.29 | P24: 8541.29
A25: 0#柴油销售量（公路+铁路） | C25: 504.768 | H25: 1130964.4
C26: 2053 | H26: 840052
A27: 4705 | C27: 0 | H27: 0.43
A28: 44 | C28: 654 | H28: 192327
C29: 0 | H29: 34449
C30: 0 | H30: 0
C32: 0 | H32: 0
A33: 1899817 | C33: 139 | H33: 41390.24
A34: 10633.43
C35: 196 | H35: 48920
C36: 0 | H36: 6399
A38: 10329 | C38: 3972275 | D38: =_xlfn.IFERROR(B38+A38,"") -> 10329 | E38: =_xlfn.IFERROR(C38+A38,"") -> 3982604 | F38: 500万常压加工量
A39: 4334 | C39: 1471945 | D39: =_xlfn.IFERROR(B39+A39,"") -> 4334 | E39: =_xlfn.IFERROR(C39+A39,"") -> 1476279 | F39: 180万催化加工量
A40: 3324 | C40: 1002314.5 | D40: =_xlfn.IFERROR(B40+A40,"") -> 3324 | E40: =_xlfn.IFERROR(C40+A40,"") -> 1005638.5 | F40: 100万连续重整加工量
A41: 2053 | C41: 840052 | D41: =_xlfn.IFERROR(B41+A41,"") -> 2053 | E41: =_xlfn.IFERROR(C41+A41,"") -> 842105 | F41: 90万汽油精制加工量
A42: 4705 | C42: 1899817 | D42: =_xlfn.IFERROR(B42+A42,"") -> 4705 | E42: =_xlfn.IFERROR(C42+A42,"") -> 1904522 | F42: 200万柴油精制加工量
A43: 0 | C43: 0 | D43: =_xlfn.IFERROR(B43+A43,"") -> 0 | E43: =_xlfn.IFERROR(C43+A43,"") -> 0 | F43: 20万DCC石脑油加工量
...
