Workbook

Sheet 生产信息简表
B1: 炼化公司生产信息简表
B2: 填报单位：炼化公司 | D2: 统计日期： | E2: =J2 -> 2026-01-06 | G2: 填报日期： | H2: =K2 -> 2026-01-07 | J2: 2026-01-06 | K2: 2026-01-07
C3: 延炼 | D3: 永炼 | E3: 榆炼 | F3: 合计 | G3: 年累 | H3: 交口区域化工物料平衡
B4: 原油来量： | C4: =SUM(C5:C7) -> 15115 | D4: =IF(取值!A289=0,"",取值!A289) -> 9800 | E4: =SUM(E5:E7) -> 13048.1 | F4: =SUM(C4:E4) -> 37963.1 | H4: 原料气总产量 | I4: =_xlfn.IFERROR(SUM(I5:I6),"") -> 2776
B5: 长庆 | C5: =IF(取值!A128=0,"",取值!A128) | D5: =IF(取值!A290=0,"",取值!A290) | E5: =IF(取值!A186=0,"",取值!A186) | F5: =SUM(C5:E5) -> 0 | H5: 永炼、榆炼产量 | I5: =_xlfn.IFERROR(SUM(取值!A335,取值!A245),"") -> 1340
B6: 管输 | C6: =IF(取值!A129=0,"",取值!A129) -> 14688 | D6: =IF(取值!A291=0,"",取值!A291) -> 9800 | E6: =IF(取值!A187=0,"",取值!A187) -> 7259.453 | F6: =SUM(C6:E6) -> 31747.453 | H6: 延炼自产 | I6: =IF(取值!A178=0,"",取值!A178) -> 1436
B7: 进口 | C7: =IF(取值!A130=0,"",取值!A130) -> 427 | D7: =IF(取值!A292=0,"",取值!A292) | E7: =IF(SUM(取值!A188:A190)=0,"",SUM(取值!A188:A190)) -> 5788.647 | F7: =_xlfn.IFERROR(SUM(取值!B188:B190),"") -> 42482.56 | G7: =_xlfn.IFERROR(SUM(取值!A3,取值!A4,取值!A5,取值!A130),"") -> 42909.56 | H7: 原料气库存 | I7: =_xlfn.IFERROR(SUM(I8:I10),"") -> 7890.1693
B8: 原油库存 | C8: =IF(取值!A131=0,"",取值!A131) -> 42674 | D8: =IF(取值!A296=0,"",取值!A296) -> 12261 | E8: =IF(取值!A191=0,"",取值!A191) -> 80285.6 | F8: =SUM(C8:E8) -> 135220.6 | H8: 延炼 | I8: =IF(取值!A179=0,"",取值!A179) -> 4528 | N8: 底库量 | O8: 延炼 | P8: 永炼 | Q8: 榆炼 | R8: =C8 -> 42674 | S8: =D8 -> 12261 | T8: =E8 -> 80285.6
B9: 可付量 | C9: =_xlfn.IFERROR(C8-O9,"") -> 20674 | D9: =_xlfn.IFERROR(D8-P9,"") -> 2261 | E9: =_xlfn.IFERROR(E8-Q9,"") -> 55285.6 | F9: =_xlfn.IFERROR(SUM(C9:E9),"") -> 78220.6 | H9: 永炼 | I9: =IF(取值!A336=0,"",取值!A336) -> 2360 | O9: 22000 | P9: 10000 | Q9: 25000 | R9: =C9 -> 20674 | S9: =D9 -> 2261 | T9: =E9 -> 55285.6
B10: 管输末站库存 | C10: =IF(取值!A133=0,"",取值!A133) -> 99188 | E10: =IF(取值!A193=0,"",取值!A193) -> 29520 | F10: =SUM(C10:E10) -> 128708 | H10: 榆炼 | I10: =IF(取值!A244=0,"",取值!A244) -> 1002.1693
B11: 原油加工量 | C11: =IF(取值!A134=0,"",取值!A134) -> 16826 | D11: =IF(取值!A297=0,"",取值!A297) -> 8574 | E11: =IF(取值!A194=0,"",取值!A194) -> 13511 | F11: =SUM(C11:E11) -> 38911 | G11: =_xlfn.IFERROR(SUM(取值!A350:A353),"") -> 274136 | H11: 原料气总加工 | I11: =_xlfn.IFERROR(SUM(I12:I13),"") -> 2706 | R11: =C11 -> 16826 | S11: =D11 -> 8574 | T11: =E11 -> 13511
B12: 渣油加工量 | C12: =IF(取值!A135=0,"",取值!A135) -> 8809 | D12: =IF(取值!A348=0,"",取值!A348) -> 3431 | E12: =IF(取值!A195=0,"",取值!A195) -> 4677.44 | F12: =SUM(C12:E12) -> 16917.44 | G12: =_xlfn.IFERROR(SUM(取值!A354:A356),"") -> 116440 | H12: 延炼 | I12: =IF(取值!A180=0,"",取值!A180) -> 949
B13: 渣油库存 | C13: =IF(取值!A136=0,"",取值!A136) -> 39858 | D13: =IF(取值!A302=0,"",取值!A302) -> 14605 | E13: =IF(取值!A196=0,"",取值!A196) -> 30663 | F13: =SUM(C13:E13) -> 85126 | H13: 石化厂 | I13: =IF(取值!A248=0,"",取值!A248) -> 1757
B14: 空量 | C14: =IF(取值!A137=0,"",取值!A137) -> 35569 | D14: =_xlfn.IFERROR(取值!A303-取值!A302,"") -> 24395 | E14: =IF(取值!A197=0,"",取值!A197) -> 19337 | F14: =SUM(C14:E14) -> 79301 | H14: 丙烯总产量 | I14: =_xlfn.IFERROR(SUM(I15:I17),"") -> 1055
B15: 汽油产量 | C15: =IF(取值!A138=0,"",取值!A138) -> 7612 | D15: =IF(取值!A305=0,"",取值!A305) -> 2596 | E15: =IF(取值!A198=0,"",取值!A198) -> 4039 | F15: =SUM(C15:E15) -> 14247 | H15: 延炼气分 | I15: =IF(取值!A181=0,"",取值!A181) -> 238
B16: 92#汽油销量 | C16: =IF(取值!A139=0,"",取值!A139) -> 9857 | D16: =IF(取值!A306=0,"",取值!A306) -> 1996.86 | E16: =IF(取值!A199=0,"",取值!A199) -> 2766 | F16: =SUM(C16:E16) -> 14619.86 | H16: 石化厂气分 | I16: =IF(取值!A249=0,"",取值!A249) -> 465
B17: 库存 | C17: =IF(取值!A140=0,"",取值!A140) -> 27750 | D17: =IF(取值!A307=0,"",取值!A307) -> 19899 | E17: =IF(取值!A200=0,"",取值!A200) -> 74515.76 | F17: =SUM(C17:E17) -> 122164.76 | H17: 石化厂混脱 | I17: =IF(取值!A250=0,"",取值!A250) -> 352
B18: 空量 | C18: =IF(取值!A141=0,"",取值!A141) -> 31235 | D18: =_xlfn.IFERROR(取值!A309-取值!A307,"") -> 2301 | E18: =IF(取值!A201=0,"",取值!A201) -> 4484.24 | F18: =SUM(C18:E18) -> 38020.24 | H18: 丙烯总加工 | I18: =_xlfn.IFERROR(SUM(I19:I20),"") -> 943
B19: 95#汽油销量 | C19: =IF(取值!A142=0,"",取值!A142) -> 3322 | E19: =IF(取值!A202=0,"",取值!A202) -> 416 | F19: =SUM(C19:E19) -> 3738 | H19: 延炼 | I19: =IF(取值!A182=0,"",取值!A182) -> 316
B20: 库存 | C20: =IF(取值!A143=0,"",取值!A143) -> 24353 | E20: =IF(取值!A203=0,"",取值!A203) -> 4814.4 | F20: =SUM(C20:E20) -> 29167.4 | H20: 石化厂 | I20: =IF(取值!A251=0,"",取值!A251) -> 627
B21: 空量 | C21: =IF(取值!A144=0,"",取值!A144) -> 19779 | E21: =IF(取值!A204=0,"",取值!A204) -> 1185.6 | F21: =SUM(C21:E21) -> 20964.6 | H21: 丙烯总库存 | I21: =_xlfn.IFERROR(SUM(I22:I23),"") -> 2623.827
B22: 98#汽油销量 | C22: =IF(取值!A145=0,"",取值!A145) | F22: =SUM(C22:E22) -> 0 | H22: 延炼 | I22: =IF(取值!A183=0,"",取值!A183) -> 733
B23: 库存 | C23: =IF(取值!A146=0,"",取值!A146) | F23: =SUM(C23:E23) -> 0 | H23: 石化厂 | I23: =IF(取值!A252=0,"",取值!A252) -> 1890.827
B24: 空量 | C24: =IF(取值!A147=0,"",取值!A147) | F24: =SUM(C24:E24) -> 0 | H24: 烷基化油产量 | I24: =IF(取值!A253=0,"",取值!A253) -> 604
B25: 柴油产量 | C25: =IF(取值!A148=0,"",取值!A148) -> 6405 | D25: =IF(取值!A311=0,"",取值!A311) -> 2495 | E25: =IF(取值!A205=0,"",取值!A205) -> 4096 | F25: =SUM(C25:E25) -> 12996 | H25: MTBE总产量 | I25: =_xlfn.IFERROR(SUM(I26:I28),"") -> 943
B26: 0#柴油销量 | C26: =IF(取值!A149=0,"",取值!A149) -> 3452 | D26: =IF(取值!A313=0,"",取值!A313) -> 1641.94 | E26: =IF(取值!A206=0,"",取值!A206) -> 5346 | F26: =SUM(C26:E26) -> 10439.94 | H26: 6万吨/MTBE | I26: =IF(取值!A184=0,"",取值!A184) -> 108
B27: 库存 | C27: =IF(取值!A150=0,"",取值!A150) -> 52469 | D27: =IF(取值!A315=0,"",取值!A315) -> 22712 | E27: =IF(取值!A207=0,"",取值!A207) -> 86181.65 | F27: =SUM(C27:E27) -> 161362.65 | H27: 12万吨/MTBE | I27: =IF(取值!A254=0,"",取值!A254) -> 164
B28: 空量 | C28: =IF(取值!A151=0,"",取值!A151) -> 34322 | D28: =_xlfn.IFERROR(取值!A317-取值!A315,"") -> 1288 | E28: =IF(取值!A208=0,"",取值!A208) | F28: =SUM(C28:E28) -> 35610 | H28: 25万吨/MTBE | I28: =IF(取值!A255=0,"",取值!A255) -> 671
B29: -10#柴油销量 | C29: =IF(取值!A152=0,"",取值!A152) | E29: =IF(取值!A209=0,"",取值!A209) -> 192.9 | F29: =SUM(C29:E29) -> 192.9 | H29: 油田气科技公司
B30: 库存 | C30: =IF(取值!A153=0,"",取值!A153) | E30: =IF(取值!A210=0,"",取值!A210) -> 6959 | F30: =SUM(C30:E30) -> 6959 | H30: 天然气用量 | I30: =IF(取值!A344=0,"",取值!A344) -> 644000
B31: 空量 | C31: =IF(取值!A154=0,"",取值!A154) | E31: =IF(取值!A211=0,"",取值!A211) -> 8041 | F31: =SUM(C31:E31) -> 8041 | H31: BDO产量 | I31: =IF(取值!A220=0,"",取值!A220) -> 236.55
B32: -20#柴油销量 | C32: =IF(取值!A155=0,"",取值!A155) | D32: =IF(取值!A322=0,"",取值!A322) -> 892.12 | E32: =IF(取值!A212=0,"",取值!A212) | F32: =SUM(C32:E32) -> 892.12 | H32: BDO库存 | I32: =IF(取值!A223=0,"",取值!A223) -> 2158.86
B33: 库存 | C33: =IF(取值!A156=0,"",取值!A156) | D33: =IF(取值!A324=0,"",取值!A324) -> 5434 | E33: =IF(取值!A213=0,"",取值!A213) -> 1220 | F33: =SUM(C33:E33) -> 6654 | H33: BDO销量 | I33: =IF(取值!A222=0,"",取值!A222) -> 226.98
B34: 空量 | C34: =IF(取值!A157=0,"",取值!A157) | D34: =_xlfn.IFERROR(取值!A326-取值!A324,"") -> 5066 | E34: =IF(取值!A214=0,"",取值!A214) | F34: =SUM(C34:E34) -> 5066 | H34: 聚酯级乙二醇产量 | I34: =IF(取值!A225=0,"",取值!A225) -> 178
B35: 航煤产量 | C35: =IF(取值!B158=0,"",取值!B158) | D35: =IF(取值!B328=0,"",取值!B328) -> 473 | E35: =IF(取值!B215=0,"",取值!B215) -> 731 | F35: =SUM(C35:E35) -> 1204 | G35: =_xlfn.IFERROR(SUM(取值!B112:B114),"") -> 9331 | H35: 轻质多元醇产量 | I35: =IF(取值!A228=0,"",取值!A228) -> 19.4
B36: 销量 | C36: =IF(取值!B159=0,"",取值!B159) -> 65.42 | D36: =IF(取值!B330=0,"",取值!B330) | E36: =IF(取值!B216=0,"",取值!B216) -> 958 | F36: =SUM(C36:E36) -> 1023.42 | G36: =_xlfn.IFERROR(SUM(取值!B116:B118),"") -> 4653.58 | H36: 乙二醇库存 | I36: =IF(取值!A231=0,"",取值!A231) -> 2645.42
B37: 库存 | C37: =IF(取值!B160=0,"",取值!B160) -> 37517 | D37: =IF(取值!B332=0,"",取值!B332) -> 10795 | E37: =IF(取值!B217=0,"",取值!B217) -> 6723 | F37: =SUM(C37:E37) -> 55035 | H37: 聚酯级乙二醇销量 | I37: =IF(取值!A234=0,"",取值!A234) -> 223.72
B38: 空量 | C38: =IF(取值!A161=0,"",取值!A161) -> 3300 | D38: =_xlfn.IFERROR(取值!A333-取值!A332,"") -> 1815 | E38: =IF(取值!A218=0,"",取值!A218) -> 4276.01 | F38: =SUM(C38:E38) -> 9391.01 | H38: 轻质多元醇销量 | I38: =IF(取值!A235=0,"",取值!A235) -> 32.68
B39: 天然气公司 | C39: 进气量 | D39: 产量 | E39: 销售量 | F39: 库存 | G39: 空量 | H39: PTMEG产量 | I39: =IF(取值!A236=0,"",取值!A236)
B40: 临镇站 | C40: =IF(取值!A257=0,"",取值!A257) -> 1.4 | D40: =IF(取值!A258=0,"",取值!A258) | E40: =IF(取值!A259=0,"",取值!A259) | F40: =IF(取值!A260=0,"",取值!A260) -> 587 | G40: =1800-F40 -> 1213 | H40: PTMEG库存 | I40: =IF(取值!A239=0,"",取值!A239) -> 5569.14
...

Sheet 取值
A1: 0
A3: 42482.56
A4: 0
A5: 0
A6: 117313
A8: 50993.84
A14: 292745
A16: 580672.5
A22: 828148
A24: 260416
A26: 117720
A29: 103906
... A110: 0
A112: 6803 | B112: 0
A113: 3395 | B113: 3395
A114: 5936 | B114: 5936
A116: 390 | B116: 390.58
A117: 331.66 | B117: 332
A118: 4882 | B118: 3931
A120: 265639
A122: 48009.78
A124: 24707
A126: 28990.22
A127: 延炼
A128: 0
A129: 14688
A130: 427
A131: 42674
A132: 27887
A133: 99188
A134: 16826
A135: 8809
A136: 39858
A137: 35569
A138: 7612
A139: 9857
... A151: 34322
B157: 2023/10/03 炼化调度要求取值替换为 航煤日报表
A158: 959 | B158: 0
A159: 65 | B159: 65.42
...
