Workbook

Sheet 全年生产任务完成情况统计
B1: 全年生产任务完成情况统计
B2: 填报单位：炼化公司 | N2: 统计日期： | P2: =T2 -> 2026-01-06 | T2: 2026-01-06
B3: 指标名称 | C3: 月计划 | D3: 本日 | E3: 本月 | F3: 本月 | G3: 至本月底 | H3: 年计划 （万吨） | I3: 全年累计 加工量 （万吨） | J3: 全年剩余 加工量 （万吨） | K3: 至12月底 日处理量 （吨） | L3: 完成全年任 务的（%） | M3: 收率（催化收率含回炼油）
C4: （万吨） | D4: （吨） | E4: 累计生产 （万吨） | F4: 剩余加工量 (万吨) | G4: 日处理量 (吨) | M4: 年计划 | N4: 月计划 | O4: 本日 | P4: 本月 | Q4: 本年 | R4: 本月 + -
B5: 原油加工量 | C5: =取值!C5 -> 1180000 | D5: =IF(取值!D5=0,"",取值!D5) -> 39021 | E5: =IF(取值!E5=0,"",取值!E5) -> 274136 | F5: =_xlfn.IFERROR(IF(取值!F5<0,"",取值!F5),"") -> 905864 | G5: =IF(取值!G5<0,"",取值!G5) -> 37744.333 | H5: =14970000 -> 14970000 | I5: =IF(取值!I5=0,"",取值!I5) -> 274136 | J5: =_xlfn.IFERROR(IF(取值!J5<0,"",取值!J5),"") | K5: =IF(取值!K5<0,"",取值!K5) | L5: =IF(取值!L5=0,"",取值!L5) | M5: =IF(取值!M5=0,"",取值!M5) | N5: =IF(取值!N5=0,"",取值!N5) -> 48.454237 | O5: =IF(取值!O5=0,"",取值!O5) -> 49.663002 | P5: =IF(取值!P5=0,"",取值!P5) -> 50.153938 | Q5: =IF(取值!Q5=0,"",取值!Q5) -> 50.153938
B6: 渣油加工量 | C6: =取值!C6 -> 486000 | D6: =IF(取值!D6=0,"",取值!D6) -> 16887 | E6: =IF(取值!E6=0,"",取值!E6) -> 116440 | F6: =_xlfn.IFERROR(IF(取值!F6<0,"",取值!F6),"") -> 369560 | G6: =IF(取值!G6<0,"",取值!G6) -> 15398.333 | H6: =取值!H6 -> 0 | I6: =IF(取值!I6=0,"",取值!I6) -> 116440 | J6: =_xlfn.IFERROR(IF(取值!J6<0,"",取值!J6),"") | K6: =IF(取值!K6<0,"",取值!K6) | L6: =IF(取值!L6=0,"",取值!L6) | M6: =IF(取值!M6=0,"",取值!M6) | N6: =IF(取值!N6=0,"",取值!N6) -> 86.324691 | O6: =IF(取值!O6=0,"",取值!O6) -> 65.425873 | P6: =IF(取值!P6=0,"",取值!P6) -> 86.980519 | Q6: =IF(取值!Q6=0,"",取值!Q6) -> 86.980519
B7: 重整装置加工量 | C7: =取值!C7 -> 223000 | D7: =IF(取值!D7=0,"",取值!D7) -> 8237 | E7: =IF(取值!E7=0,"",取值!E7) -> 57560 | F7: =_xlfn.IFERROR(IF(取值!F7<0,"",取值!F7),"") -> 165440 | G7: =IF(取值!G7<0,"",取值!G7) -> 6893.3333 | H7: =取值!H7 -> 0 | I7: =IF(取值!I7=0,"",取值!I7) -> 57560 | J7: =_xlfn.IFERROR(IF(取值!J7<0,"",取值!J7),"") | K7: =IF(取值!K7<0,"",取值!K7) | L7: =IF(取值!L7=0,"",取值!L7) | M7: =IF(取值!M7=0,"",取值!M7) | N7: =IF(取值!N7=0,"",取值!N7) -> 92.456054 | O7: =IF(取值!O7=0,"",取值!O7) -> 93.225689 | P7: =IF(取值!P7=0,"",取值!P7) -> 93.231411 | Q7: =IF(取值!Q7=0,"",取值!Q7) -> 93.231411
B8: 汽油加氢精制加工量 | C8: =取值!C8 -> 228000 | D8: =IF(取值!D8=0,"",取值!D8) -> 8016 | E8: =IF(取值!E8=0,"",取值!E8) -> 56420 | F8: =_xlfn.IFERROR(IF(取值!F8<0,"",取值!F8),"") -> 171580 | G8: =IF(取值!G8<0,"",取值!G8) -> 7149.1667 | H8: =取值!H8 -> 0 | I8: =IF(取值!I8=0,"",取值!I8) -> 56420 | J8: =_xlfn.IFERROR(IF(取值!J8<0,"",取值!J8),"") | K8: =IF(取值!K8<0,"",取值!K8) | L8: =IF(取值!L8=0,"",取值!L8) | M8: =IF(取值!M8=0,"",取值!M8) | N8: =IF(取值!N8=0,"",取值!N8) -> 98.243421 | O8: =IF(取值!O8=0,"",取值!O8) -> 99.014471 | P8: =IF(取值!P8=0,"",取值!P8) -> 99.035803 | Q8: =IF(取值!Q8=0,"",取值!Q8) -> 99.035803
B9: 柴油加氢精制加工量 | C9: =取值!C9 -> 446000 | D9: =IF(取值!D9=0,"",取值!D9) -> 12136 | E9: =IF(取值!E9=0,"",取值!E9) -> 91838 | F9: =_xlfn.IFERROR(IF(取值!F9<0,"",取值!F9),"") -> 354162 | G9: =IF(取值!G9<0,"",取值!G9) -> 14756.75 | H9: =取值!H9 -> 0 | I9: =IF(取值!I9=0,"",取值!I9) -> 91838 | J9: =_xlfn.IFERROR(IF(取值!J9<0,"",取值!J9),"") | K9: =IF(取值!K9<0,"",取值!K9) | L9: =IF(取值!L9=0,"",取值!L9) | M9: =IF(取值!M9=0,"",取值!M9) | N9: =IF(取值!N9=0,"",取值!N9) -> 98.587892 | O9: =IF(取值!O9=0,"",取值!O9) -> 99.151285 | P9: =IF(取值!P9=0,"",取值!P9) -> 99.169189 | Q9: =IF(取值!Q9=0,"",取值!Q9) -> 99.169189
B10: 烷基化装置加工量 | C10: =取值!C10 -> 27600 | D10: =IF(取值!D10=0,"",取值!D10) -> 995.2 | E10: =IF(取值!E10=0,"",取值!E10) -> 7099.4 | F10: =_xlfn.IFERROR(IF(取值!F10<0,"",取值!F10),"") -> 20500.6 | G10: =IF(取值!G10<0,"",取值!G10) -> 854.19167 | H10: =取值!H10 -> 0 | I10: =IF(取值!I10=0,"",取值!I10) -> 7099.4 | J10: =_xlfn.IFERROR(IF(取值!J10<0,"",取值!J10),"") | K10: =IF(取值!K10<0,"",取值!K10) | L10: =IF(取值!L10=0,"",取值!L10) | M10: =IF(取值!M10=0,"",取值!M10) | N10: =IF(取值!N10=0,"",取值!N10) | O10: =IF(取值!O10=0,"",取值!O10) | P10: =IF(取值!P10=0,"",取值!P10) | Q10: =IF(取值!Q10=0,"",取值!Q10)
B11: 汽油产量 | C11: =取值!C11 -> 458000 | D11: =IF(取值!D11=0,"",取值!D11) -> 7399 | E11: =IF(取值!E11=0,"",取值!E11) -> 74561 | F11: =_xlfn.IFERROR(IF(取值!F11<0,"",取值!F11),"") -> 383439 | G11: =IF(取值!G11<0,"",取值!G11) -> 15976.625 | H11: =取值!H11 -> 0 | I11: =IF(取值!I11=0,"",取值!I11) -> 74561 | J11: =_xlfn.IFERROR(IF(取值!J11<0,"",取值!J11),"") | K11: =IF(取值!K11<0,"",取值!K11) | L11: =IF(取值!L11=0,"",取值!L11) | M11: =IF(取值!M11=0,"",取值!M11) | N11: =IF(取值!N11=0,"",取值!N11) | O11: =IF(取值!O11=0,"",取值!O11) | P11: =IF(取值!P11=0,"",取值!P11) | Q11: =IF(取值!Q11=0,"",取值!Q11)
B12: 其中：92# | C12: =取值!C12 -> 328000 | D12: =IF(取值!D12=0,"",取值!D12) -> 6565 | E12: =IF(取值!E12=0,"",取值!E12) -> 47524 | F12: =_xlfn.IFERROR(IF(取值!F12<0,"",取值!F12),"") -> 280476 | G12: =IF(取值!G12<0,"",取值!G12) -> 11686.5 | H12: =取值!H12 -> 0 | I12: =IF(取值!I12=0,"",取值!I12) -> 47524 | J12: =_xlfn.IFERROR(IF(取值!J12<0,"",取值!J12),"") | K12: =IF(取值!K12<0,"",取值!K12) | L12: =IF(取值!L12=0,"",取值!L12) | M12: =IF(取值!M12=0,"",取值!M12) | N12: =IF(取值!N12=0,"",取值!N12) | O12: =IF(取值!O12=0,"",取值!O12) | P12: =IF(取值!P12=0,"",取值!P12) | Q12: =IF(取值!Q12=0,"",取值!Q12)
B13: 95# | C13: =取值!C13 -> 130000 | D13: =IF(取值!D13=0,"",取值!D13) -> 834 | E13: =IF(取值!E13=0,"",取值!E13) -> 27037 | F13: =_xlfn.IFERROR(IF(取值!F13<0,"",取值!F13),"") -> 102963 | G13: =IF(取值!G13<0,"",取值!G13) -> 4290.125 | H13: =取值!H13 -> 0 | I13: =IF(取值!I13=0,"",取值!I13) -> 27037 | J13: =_xlfn.IFERROR(IF(取值!J13<0,"",取值!J13),"") | K13: =IF(取值!K13<0,"",取值!K13) | L13: =IF(取值!L13=0,"",取值!L13) | M13: =IF(取值!M13=0,"",取值!M13) | N13: =IF(取值!N13=0,"",取值!N13) | O13: =IF(取值!O13=0,"",取值!O13) | P13: =IF(取值!P13=0,"",取值!P13) | Q13: =IF(取值!Q13=0,"",取值!Q13)
B14: 柴油产量 | C14: =取值!C14 -> 408000 | D14: =IF(取值!D14=0,"",取值!D14) -> 15469 | E14: =IF(取值!E14=0,"",取值!E14) -> 83308 | F14: =_xlfn.IFERROR(IF(取值!F14<0,"",取值!F14),"") -> 324692 | G14: =IF(取值!G14<0,"",取值!G14) -> 13528.833 | H14: =取值!H14 -> 0 | I14: =IF(取值!I14=0,"",取值!I14) -> 83308 | J14: =_xlfn.IFERROR(IF(取值!J14<0,"",取值!J14),"") | K14: =IF(取值!K14<0,"",取值!K14) | L14: =IF(取值!L14=0,"",取值!L14) | M14: =IF(取值!M14=0,"",取值!M14) | N14: =IF(取值!N14=0,"",取值!N14) | O14: =IF(取值!O14=0,"",取值!O14) | P14: =IF(取值!P14=0,"",取值!P14) | Q14: =IF(取值!Q14=0,"",取值!Q14)
B15: 其中：军用柴油 | C15: =取值!C15 -> 0 | D15: =IF(取值!D15=0,"",取值!D15) | E15: =IF(取值!E15=0,"",取值!E15) | F15: =_xlfn.IFERROR(IF(取值!F15<0,"",取值!F15),"") | G15: =IF(取值!G15<0,"",取值!G15) | H15: =取值!H15 -> 0 | I15: =IF(取值!I15=0,"",取值!I15) | J15: =_xlfn.IFERROR(IF(取值!J15<0,"",取值!J15),"") -> 0 | K15: =IF(取值!K15<0,"",取值!K15) -> 0 | L15: =IF(取值!L15=0,"",取值!L15) | M15: =IF(取值!M15=0,"",取值!M15) | N15: =IF(取值!N15=0,"",取值!N15) | O15: =IF(取值!O15=0,"",取值!O15) | P15: =IF(取值!P15=0,"",取值!P15) | Q15: =IF(取值!Q15=0,"",取值!Q15)
B16: 0# | C16: =取值!C16 -> 0 | D16: =IF(取值!D16=0,"",取值!D16) -> 2075 | E16: =IF(取值!E16=0,"",取值!E16) -> 28295 | F16: =_xlfn.IFERROR(IF(取值!F16<0,"",取值!F16),"") | G16: =IF(取值!G16<0,"",取值!G16) | I16: =IF(取值!I16=0,"",取值!I16) -> 28295 | J16: =_xlfn.IFERROR(IF(取值!J16<0,"",取值!J16),"") -> 4871705 | K16: =IF(取值!K16<0,"",取值!K16) -> 13608.115 | L16: =IF(取值!L16=0,"",取值!L16) -> 0.57744898 | M16: =IF(取值!M16=0,"",取值!M16) | N16: =IF(取值!N16=0,"",取值!N16) | O16: =IF(取值!O16=0,"",取值!O16) | P16: =IF(取值!P16=0,"",取值!P16) | Q16: =IF(取值!Q16=0,"",取值!Q16)
B17: -10# | C17: =取值!C17 -> 30000 | D17: =IF(取值!D17=0,"",取值!D17) -> 3500 | E17: =IF(取值!E17=0,"",取值!E17) -> 3500 | F17: =_xlfn.IFERROR(IF(取值!F17<0,"",取值!F17),"") -> 26500 | G17: =IF(取值!G17<0,"",取值!G17) | I17: =IF(取值!I17=0,"",取值!I17) -> 3500 | J17: =_xlfn.IFERROR(IF(取值!J17<0,"",取值!J17),"") -> 76500 | K17: =IF(取值!K17<0,"",取值!K17) -> 213.68715 | L17: =IF(取值!L17=0,"",取值!L17) -> 4.375 | M17: =IF(取值!M17=0,"",取值!M17) | N17: =IF(取值!N17=0,"",取值!N17) | O17: =IF(取值!O17=0,"",取值!O17) | P17: =IF(取值!P17=0,"",取值!P17) | Q17: =IF(取值!Q17=0,"",取值!Q17)
B18: -20# | C18: =取值!C18 -> 30000 | D18: =IF(取值!D18=0,"",取值!D18) -> 1352 | E18: =IF(取值!E18=0,"",取值!E18) -> 1352 | F18: =_xlfn.IFERROR(IF(取值!F18<0,"",取值!F18),"") -> 28648 | G18: =IF(取值!G18<0,"",取值!G18) | I18: =IF(取值!I18=0,"",取值!I18) -> 1352 | J18: =_xlfn.IFERROR(IF(取值!J18<0,"",取值!J18),"") -> 48648 | K18: =IF(取值!K18<0,"",取值!K18) -> 135.88827 | L18: =IF(取值!L18=0,"",取值!L18) -> 2.704 | M18: =IF(取值!M18=0,"",取值!M18) | N18: =IF(取值!N18=0,"",取值!N18) | O18: =IF(取值!O18=0,"",取值!O18) | P18: =IF(取值!P18=0,"",取值!P18) | Q18: =IF(取值!Q18=0,"",取值!Q18)
B19: 航煤产量 | C19: =取值!C19 -> 43899.604 | D19: =IF(取值!D19=0,"",取值!D19) -> 1204 | E19: =IF(取值!E19=0,"",取值!E19) -> 9331 | F19: =_xlfn.IFERROR(IF(取值!F19<0,"",取值!F19),"") -> 34568.604 | G19: =IF(取值!G19<0,"",取值!G19) | H19: =取值!H19 -> 0 | I19: =IF(取值!I19=0,"",取值!I19) -> 9331 | J19: =_xlfn.IFERROR(IF(取值!J19<0,"",取值!J19),"") | K19: =IF(取值!K19<0,"",取值!K19) | L19: =IF(取值!L19=0,"",取值!L19) | M19: =IF(取值!M19=0,"",取值!M19) | N19: =IF(取值!N19=0,"",取值!N19) | O19: =IF(取值!O19=0,"",取值!O19) | P19: =IF(取值!P19=0,"",取值!P19) | Q19: =IF(取值!Q19=0,"",取值!Q19)
B20: LNG产量 | C20: =取值!C20 -> 120000 | D20: =IF(取值!D20=0,"",取值!D20) -> 2119 | E20: =IF(取值!E20=0,"",取值!E20) -> 15226 | F20: =_xlfn.IFERROR(IF(取值!F20<0,"",取值!F20),"") -> 104774 | G20: =IF(取值!G20<0,"",取值!G20) -> 4365.5833 | H20: =取值!H20 -> 0 | I20: =IF(取值!I20=0,"",取值!I20) -> 15226 | J20: =_xlfn.IFERROR(IF(取值!J20<0,"",取值!J20),"") | K20: =IF(取值!K20<0,"",取值!K20) | L20: =IF(取值!L20=0,"",取值!L20) | M20: =IF(取值!M20=0,"",取值!M20) | N20: =IF(取值!N20=0,"",取值!N20) | O20: =IF(取值!O20=0,"",取值!O20) | P20: =IF(取值!P20=0,"",取值!P20) | Q20: =IF(取值!Q20=0,"",取值!Q20)
B21: 苯乙烯产量 | C21: =取值!C21 -> 4600.36 | D21: =IF(取值!D21=0,"",取值!D21) -> 151 | E21: =IF(取值!E21=0,"",取值!E21) -> 1075 | F21: =_xlfn.IFERROR(IF(取值!F21<0,"",取值!F21),"") -> 3525.36 | G21: =IF(取值!G21<0,"",取值!G21) -> 146.89 | H21: =取值!H21 -> 0 | I21: =IF(取值!I21=0,"",取值!I21) -> 1075 | J21: =_xlfn.IFERROR(IF(取值!J21<0,"",取值!J21),"") | K21: =IF(取值!K21<0,"",取值!K21) | L21: =IF(取值!L21=0,"",取值!L21) | M21: =IF(取值!M21=0,"",取值!M21) | N21: =IF(取值!N21=0,"",取值!N21) | O21: =IF(取值!O21=0,"",取值!O21) | P21: =IF(取值!P21=0,"",取值!P21) | Q21: =IF(取值!Q21=0,"",取值!Q21)
B22: 聚丙烯产量 | C22: =取值!C22 -> 26499.939 | D22: =IF(取值!D22=0,"",取值!D22) -> 914.56 | E22: =IF(取值!E22=0,"",取值!E22) -> 6369.06 | F22: =_xlfn.IFERROR(IF(取值!F22<0,"",取值!F22),"") -> 20130.879 | G22: =IF(取值!G22<0,"",取值!G22) -> 838.78662 | H22: =取值!H22 -> 0 | I22: =IF(取值!I22=0,"",取值!I22) -> 6369.06 | J22: =_xlfn.IFERROR(IF(取值!J22<0,"",取值!J22),"") | K22: =IF(取值!K22<0,"",取值!K22) | L22: =IF(取值!L22=0,"",取值!L22) | M22: =IF(取值!M22=0,"",取值!M22) | N22: =IF(取值!N22=0,"",取值!N22) | O22: =IF(取值!O22=0,"",取值!O22) | P22: =IF(取值!P22=0,"",取值!P22) | Q22: =IF(取值!Q22=0,"",取值!Q22)
B23: MTBE产量 | C23: =取值!C23 -> 26800 | D23: =IF(取值!D23=0,"",取值!D23) -> 943 | E23: =IF(取值!E23=0,"",取值!E23) -> 6694 | F23: =_xlfn.IFERROR(IF(取值!F23<0,"",取值!F23),"") -> 20106 | G23: =IF(取值!G23<0,"",取值!G23) -> 837.75 | H23: =取值!H23 -> 0 | I23: =IF(取值!I23=0,"",取值!I23) -> 6694 | J23: =_xlfn.IFERROR(IF(取值!J23<0,"",取值!J23),"") | K23: =IF(取值!K23<0,"",取值!K23) | L23: =IF(取值!L23=0,"",取值!L23) | M23: =IF(取值!M23=0,"",取值!M23) | N23: =IF(取值!N23=0,"",取值!N23) | O23: =IF(取值!O23=0,"",取值!O23) | P23: =IF(取值!P23=0,"",取值!P23) | Q23: =IF(取值!Q23=0,"",取值!Q23)
B24: SBA产量 | C24: =取值!C24 -> 5100.027 | D24: =IF(取值!D24=0,"",取值!D24) -> 169 | E24: =IF(取值!E24=0,"",取值!E24) -> 1128 | F24: =_xlfn.IFERROR(IF(取值!F24<0,"",取值!F24),"") -> 3972.027 | G24: =IF(取值!G24<0,"",取值!G24) -> 165.50113 | H24: =取值!H24 -> 0 | I24: =IF(取值!I24=0,"",取值!I24) -> 1128 | J24: =_xlfn.IFERROR(IF(取值!J24<0,"",取值!J24),"") | K24: =IF(取值!K24<0,"",取值!K24) | L24: =IF(取值!L24=0,"",取值!L24) | M24: =IF(取值!M24=0,"",取值!M24) | N24: =IF(取值!N24=0,"",取值!N24) | O24: =IF(取值!O24=0,"",取值!O24) | P24: =IF(取值!P24=0,"",取值!P24) | Q24: =IF(取值!Q24=0,"",取值!Q24)
B25: 烷基化油产量 | C25: =取值!C25 -> 18000.055 | D25: =IF(取值!D25=0,"",取值!D25) -> 604 | E25: =IF(取值!E25=0,"",取值!E25) -> 4379 | F25: =_xlfn.IFERROR(IF(取值!F25<0,"",取值!F25),"") -> 13621.055 | G25: =IF(取值!G25<0,"",取值!G25) -> 567.54396 | H25: =取值!H25 -> 0 | I25: =IF(取值!I25=0,"",取值!I25) -> 4379 | J25: =_xlfn.IFERROR(IF(取值!J25<0,"",取值!J25),"") | K25: =IF(取值!K25<0,"",取值!K25) | L25: =IF(取值!L25=0,"",取值!L25) | M25: =IF(取值!M25=0,"",取值!M25) | N25: =IF(取值!N25=0,"",取值!N25) | O25: =IF(取值!O25=0,"",取值!O25) | P25: =IF(取值!P25=0,"",取值!P25) | Q25: =IF(取值!Q25=0,"",取值!Q25)
B26: 石脑油销量 | C26: =取值!C26 -> 0 | D26: =IF(取值!D26=0,"",取值!D26) | E26: =IF(取值!E26=0,"",取值!E26) | F26: =_xlfn.IFERROR(IF(取值!F26<0,"",取值!F26),"") | G26: =IF(取值!G26<0,"",取值!G26) | H26: =取值!H26 -> 0 | I26: =IF(取值!I26=0,"",取值!I26) | J26: =_xlfn.IFERROR(IF(取值!J26<0,"",取值!J26),"") | K26: =IF(取值!K26<0,"",取值!K26) | L26: =IF(取值!L26=0,"",取值!L26) | M26: =IF(取值!M26=0,"",取值!M26) | N26: =IF(取值!N26=0,"",取值!N26) | O26: =IF(取值!O26=0,"",取值!O26) | P26: =IF(取值!P26=0,"",取值!P26) | Q26: =IF(取值!Q26=0,"",取值!Q26)
B27: 液化气销量 | C27: =取值!C27 -> 0 | D27: =IF(取值!D27=0,"",取值!D27) -> 1917.48 | E27: =IF(取值!E27=0,"",取值!E27) -> 10122.14 | F27: =_xlfn.IFERROR(IF(取值!F27<0,"",取值!F27),"") | G27: =IF(取值!G27<0,"",取值!G27) | H27: =取值!H27 -> 0 | I27: =IF(取值!I27=0,"",取值!I27) -> 10122.14 | J27: =_xlfn.IFERROR(IF(取值!J27<0,"",取值!J27),"") | K27: =IF(取值!K27<0,"",取值!K27) | L27: =IF(取值!L27=0,"",取值!L27) | M27: =IF(取值!M27=0,"",取值!M27) | N27: =IF(取值!N27=0,"",取值!N27) | O27: =IF(取值!O27=0,"",取值!O27) | P27: =IF(取值!P27=0,"",取值!P27) | Q27: =IF(取值!Q27=0,"",取值!Q27)
B28: 1#渣油销售量 | C28: =取值!C28 -> 120000 | D28: =IF(取值!D28=0,"",取值!D28) -> 3906 | E28: =IF(取值!E28=0,"",取值!E28) -> 25627 | F28: =_xlfn.IFERROR(IF(取值!F28<0,"",取值!F28),"") -> 94373 | G28: =IF(取值!G28<0,"",取值!G28) -> 3932.2083 | H28: =取值!H28 -> 0 | I28: =IF(取值!I28=0,"",取值!I28) -> 25627 | J28: =_xlfn.IFERROR(IF(取值!J28<0,"",取值!J28),"") | K28: =IF(取值!K28<0,"",取值!K28) | L28: =IF(取值!L28=0,"",取值!L28) | M28: =IF(取值!M28=0,"",取值!M28) | N28: =IF(取值!N28=0,"",取值!N28) | O28: =IF(取值!O28=0,"",取值!O28) | P28: =IF(取值!P28=0,"",取值!P28) | Q28: =IF(取值!Q28=0,"",取值!Q28)
B29: 乙二醇产量 | C29: =取值!C29 -> 5000 | D29: =IF(取值!D29=0,"",取值!D29) -> 190 | E29: =IF(取值!E29=0,"",取值!E29) -> 1488 | F29: =_xlfn.IFERROR(IF(取值!F29<0,"",取值!F29),"") -> 3512 | G29: =IF(取值!G29<0,"",取值!G29) -> 146.33333 | H29: =取值!H29 -> 0 | I29: =IF(取值!I29=0,"",取值!I29) -> 1488 | J29: =_xlfn.IFERROR(IF(取值!J29<0,"",取值!J29),"") | K29: =IF(取值!K29<0,"",取值!K29) | L29: =IF(取值!L29=0,"",取值!L29) | M29: =IF(取值!M29=0,"",取值!M29) | N29: =IF(取值!N29=0,"",取值!N29) | O29: =IF(取值!O29=0,"",取值!O29) | P29: =IF(取值!P29=0,"",取值!P29) | Q29: =IF(取值!Q29=0,"",取值!Q29)
B30: BDO产量 | C30: =取值!C30 -> 5000 | D30: =IF(取值!D30=0,"",取值!D30) -> 202 | E30: =IF(取值!E30=0,"",取值!E30) -> 1461.2782 | F30: =_xlfn.IFERROR(IF(取值!F30<0,"",取值!F30),"") -> 3538.7218 | G30: =IF(取值!G30<0,"",取值!G30) -> 147.44674 | H30: =取值!H30 -> 0 | I30: =IF(取值!I30=0,"",取值!I30) -> 1461.2782 | J30: =_xlfn.IFERROR(IF(取值!J30<0,"",取值!J30),"") | K30: =IF(取值!K30<0,"",取值!K30) | L30: =IF(取值!L30=0,"",取值!L30) | M30: =IF(取值!M30=0,"",取值!M30) | N30: =IF(取值!N30=0,"",取值!N30) | O30: =IF(取值!O30=0,"",取值!O30) | P30: =IF(取值!P30=0,"",取值!P30) | Q30: =IF(取值!Q30=0,"",取值!Q30)
B31: PT产量 | C31: =取值!C31 -> 0 | D31: =IF(取值!D31=0,"",取值!D31) | E31: =IF(取值!E31=0,"",取值!E31) | F31: =_xlfn.IFERROR(IF(取值!F31<0,"",取值!F31),"") -> 0 | G31: =IF(取值!G31<0,"",取值!G31) -> 0 | H31: =取值!H31 -> 0 | I31: =IF(取值!I31=0,"",取值!I31) | J31: =_xlfn.IFERROR(IF(取值!J31<0,"",取值!J31),"") -> 0 | K31: =IF(取值!K31<0,"",取值!K31) -> 0 | L31: =IF(取值!L31=0,"",取值!L31) | M31: =IF(取值!M31=0,"",取值!M31) | N31: =IF(取值!N31=0,"",取值!N31) | O31: =IF(取值!O31=0,"",取值!O31) | P31: =IF(取值!P31=0,"",取值!P31) | Q31: =IF(取值!Q31=0,"",取值!Q31)
B32: 备注
B34: 主管领导： | C34: =C36 -> 曹培宽 | D34: 部门负责人： | F34: =F36 -> 郝新宇 | H34: 审核人： | I34: =H36 -> 陈雄伟 | K34: 编制： | L34: =K36 -> 王宇辉
C36: 曹培宽 | F36: 郝新宇 | H36: 陈雄伟 | K36: 王宇辉

Sheet 取值
B1: ？？？？？？？全年生产任务情况统计
B2: ？？编制单位：生产计划部 | G2: 日期： | H2: 2026-01-06 | L2: 内部数据 | O2: 2026-01-07
B3: 项？？？？目 | C3: 月计划 | D3: 本日 | E3: 本月 | F3: 本月 | G3: 至本月底 | H3: 年计划 （万吨） | I3: 全年累计 加工量 （万吨） | J3: 全年剩余 加工量 （万吨） | K3: 至12月底 日处理量 （吨） | L3: 完成全年任 务的（%） | M3: 收率（催化收率含回炼油）
C4: （万吨） | D4: （吨） | E4: 累计生产 （万吨） | F4: 剩余加工量 ？(万吨) | G4: 日处理量 (吨) | M4: 年计划 | N4: 月计划 | O4: 本日 | P4: 本月 | Q4: 本年 | R4: 本月 +？-？？？？
B5: 原油加工量 | C5: 1180000 | D5: =_xlfn.IFERROR(SUM(D48:D50),"") -> 39021 | E5: =_xlfn.IFERROR(SUM(E48:E50),"") -> 274136 | F5: =C5-E5 -> 905864 | G5: =_xlfn.IFERROR(F5/S5,"") -> 37744.333 | I5: =_xlfn.IFERROR(SUM(I48:I50),"") -> 274136 | J5: =H5-I5 -> -274136 | K5: =_xlfn.IFERROR(J5/T13,"") -> -765.74302 | L5: =_xlfn.IFERROR(I5/H5*100,"") | N5: 48.454237 | O5: =_xlfn.IFERROR((O36*D48+O37*D49+O38*D50)/(D48+D49+D50),"") -> 49.663002 | P5: =_xlfn.IFERROR((P36*E48+P37*E49+P38*E50)/(E48+E49+E50),"") -> 50.153938 | Q5: =_xlfn.IFERROR((Q36*I48+Q37*I49+Q38*I50)/(I48+I49+I50),"") -> 50.153938 | R5: =P5-N5 -> 1.6997009 | S5: =T5-U5 -> 24 | T5: =DAY(EOMONTH(H2,0)) -> 31 | U5: =DAY(O2) -> 7
B6: 渣油加工量 | C6: 486000 | D6: =_xlfn.IFERROR(SUM(D52:D54),"") -> 16887 | E6: =_xlfn.IFERROR(SUM(E52:E54),"") -> 116440 | F6: =C6-E6 -> 369560 | G6: =_xlfn.IFERROR(F6/S5,"") -> 15398.333 | I6: =_xlfn.IFERROR(SUM(I52:I54),"") -> 116440 | J6: =H6-I6 -> -116440 | K6: =_xlfn.IFERROR(J6/T13,"") -> -325.2514 | L6: =_xlfn.IFERROR(I6/H6*100,"") | N6: =N35+N36 -> 86.324691 | O6: =_xlfn.IFERROR(((O56+O59)*O63+(O57+O61)*O64+(O58+O60)*O65)/(O63+O64+O65),"") -> 65.425873 | P6: =_xlfn.IFERROR(((P56+P59)*P63+(P57+P60)*P64+(P58+P61)*P65)/(P63+P64+P65),"") -> 86.980519 | Q6: =_xlfn.IFERROR(((Q56+Q59)*Q63+(Q57+Q60)*Q64+(Q58+Q61)*Q65)/(Q63+Q64+Q65),"") -> 86.980519 | R6: =P6-N6 -> 0.65582785
B7: 重整装置处理量 | C7: =B35 -> 223000 | D7: =_xlfn.IFERROR(SUM(D36:D38),"") -> 8237 | E7: =_xlfn.IFERROR(SUM(E36:E38),"") -> 57560 | F7: =IF(C7-E7=0,"",C7-E7) -> 165440 | G7: =_xlfn.IFERROR(F7/S5,"") -> 6893.3333 | I7: =_xlfn.IFERROR(SUM(I36:I38),"") -> 57560 | J7: =H7-I7 -> -57560 | K7: =_xlfn.IFERROR(J7/T13,"") -> -160.78212 | L7: =_xlfn.IFERROR(I7/H7*100,"") | N7: 92.456054 | O7: =_xlfn.IFERROR((O48*D36+O49*D37+O50*D38)/(D36+D37+D38),"") -> 93.225689 | P7: =_xlfn.IFERROR((P48*E36+P49*E37+P50*E38)/(E36+E37+E38),"") -> 93.231411 | Q7: =_xlfn.IFERROR((Q48*I36+Q49*I37+Q50*I38)/(I36+I37+I38),"") -> 93.231411 | R7: =P7-N7 -> 0.77535689
B8: 汽油加氢精制处理量 | C8: 228000 | D8: =_xlfn.IFERROR(SUM(D40:D42),"") -> 8016 | E8: =_xlfn.IFERROR(SUM(E40:E42),"") -> 56420 | F8: =C8-E8 -> 171580 | G8: =_xlfn.IFERROR(F8/S5,"") -> 7149.1667 | I8: =_xlfn.IFERROR(SUM(I40:I42),"") -> 56420 | J8: =H8-I8 -> -56420 | K8: =_xlfn.IFERROR(J8/T13,"") -> -157.59777 | L8: =_xlfn.IFERROR(I8/H8*100,"") | N8: 98.243421 | O8: =_xlfn.IFERROR((O44*D40+O45*D41+O46*D42)/(D40+D41+D42),"") -> 99.014471 | P8: =_xlfn.IFERROR((P44*E40+P45*E41+P46*E42)/(E40+E41+E42),"") -> 99.035803 | Q8: =_xlfn.IFERROR((Q44*I40+Q45*I41+Q46*I42)/(I40+I41+I42),"") -> 99.035803 | R8: =P8-N8 -> 0.79238185
B9: 柴油加氢精制处理量 | C9: 446000 | D9: =_xlfn.IFERROR(SUM(D44:D46),"") -> 12136 | E9: =_xlfn.IFERROR(SUM(E44:E46),"") -> 91838 | F9: =C9-E9 -> 354162 | G9: =_xlfn.IFERROR(F9/S5,"") -> 14756.75 | I9: =_xlfn.IFERROR(SUM(I44:I46),"") -> 91838 | J9: =H9-I9 -> -91838 | K9: =_xlfn.IFERROR(J9/T13,"") -> -256.53073 | L9: =_xlfn.IFERROR(I9/H9*100,"") | N9: 98.587892 | O9: =_xlfn.IFERROR((O52*D44+O53*D45+O54*D46)/(D44+D45+D46),"") -> 99.151285 | P9: =_xlfn.IFERROR((P52*E44+P53*E45+P54*E46)/(E44+E45+E46),"") -> 99.169189 | Q9: =_xlfn.IFERROR((Q52*I44+Q53*I45+Q54*I46)/(I44+I45+I46),"") -> 99.169189 | R9: =P9-N9 -> 0.58129685
B10: 烷基化装置处理量 | C10: 27600 | D10: =_xlfn.IFERROR(D56,"") -> 995.2 | E10: =_xlfn.IFERROR(E56,"") -> 7099.4 | F10: =C10-E10 -> 20500.6 | G10: =_xlfn.IFERROR(F10/S5,"") -> 854.19167 | I10: =_xlfn.IFERROR(I56,"") -> 7099.4 | J10: =H10-I10 -> -7099.4 | K10: =_xlfn.IFERROR(J10/T13,"") -> -19.830726 | L10: =_xlfn.IFERROR(I10/H10*100,"")
B11: 汽油产量 | C11: 458000 | D11: =_xlfn.IFERROR(SUM(D59:D64),"") -> 7399 | E11: =_xlfn.IFERROR(SUM(E59:E64),"") -> 74561 | F11: =C11-E11 -> 383439 | G11: =_xlfn.IFERROR(F11/S5,"") -> 15976.625 | I11: =_xlfn.IFERROR(SUM(I59:I64),"") -> 74561 | J11: =H11-I11 -> -74561 | K11: =_xlfn.IFERROR(J11/T13,"") -> -208.27095 | L11: =_xlfn.IFERROR(I11/H11*100,"")
B12: 其中：92# | C12: 328000 | D12: =_xlfn.IFERROR(SUM(D73:D75),"") -> 6565 | E12: =_xlfn.IFERROR(SUM(E73:E75),"") -> 47524 | F12: =C12-E12 -> 280476 | G12: =_xlfn.IFERROR(F12/S5,"") -> 11686.5 | I12: =_xlfn.IFERROR(SUM(I73:I75),"") -> 47524 | J12: =H12-I12 -> -47524 | K12: =_xlfn.IFERROR(J12/T13,"") -> -132.7486 | L12: =_xlfn.IFERROR(I12/H12*100,"")
B13: 95# | C13: 130000 | D13: =_xlfn.IFERROR(SUM(D77:D78),"") -> 834 | E13: =_xlfn.IFERROR(SUM(E77:E78),"") -> 27037 | F13: =C13-E13 -> 102963 | G13: =_xlfn.IFERROR(F13/S5,"") -> 4290.125 | I13: =_xlfn.IFERROR(SUM(I77:I78),"") -> 27037 | J13: =H13-I13 -> -27037 | K13: =_xlfn.IFERROR(J13/T13,"") -> -75.522346 | L13: =_xlfn.IFERROR(I13/H13*100,"") | S13: =DATE(YEAR(H2),12,31) -> 46387 | T13: =DATEDIF(O2,S13,"d") -> 358
B14: 柴油产量 | C14: 408000 | D14: =_xlfn.IFERROR(SUM(D80:D87),"") -> 15469 | E14: =_xlfn.IFERROR(SUM(E80:E87),"") -> 83308 | F14: =C14-E14 -> 324692 | G14: =_xlfn.IFERROR(F14/S5,"") -> 13528.833 | I14: =_xlfn.IFERROR(SUM(I80:I87),"") -> 83308 | J14: =H14-I14 -> -83308 | K14: =_xlfn.IFERROR(J14/T13,"") -> -232.70391 | L14: =_xlfn.IFERROR(I14/H14*100,"")
B15: 其中：军用柴油 | F15: =IF(C15-E15=0,"",C15-E15) | G15: =_xlfn.IFERROR(IF(F15/S5=0,"",F15/S5),"") | J15: =H15-I15 -> 0 | K15: =_xlfn.IFERROR(J15/T13,"") -> 0 | L15: =_xlfn.IFERROR(I15/H15*100,"")
B16: 0# | D16: =_xlfn.IFERROR(SUM(D91:D93),"") -> 2075 | E16: =_xlfn.IFERROR(SUM(E91:E93),"") -> 28295 | F16: =C16-E16 -> -28295 | G16: =_xlfn.IFERROR(F16/S5,"") -> -1178.9583 | H16: 4900000 | I16: =_xlfn.IFERROR(SUM(I91:I93),"") -> 28295 | J16: =H16-I16 -> 4871705 | K16: =_xlfn.IFERROR(J16/T13,"") -> 13608.115 | L16: =_xlfn.IFERROR(I16/H16*100,"") -> 0.57744898
B17: -10# | C17: 30000 | D17: =_xlfn.IFERROR(SUM(D95:D97),"") -> 3500 | E17: =_xlfn.IFERROR(SUM(E95:E97),"") -> 3500 | F17: =IF(C17-E17=0,"",C17-E17) -> 26500 | G17: =_xlfn.IFERROR(IF(F17/S7=0,"",F17/S7),"") | H17: 80000 | I17: =_xlfn.IFERROR(SUM(I95:I97),"") -> 3500 | J17: =H17-I17 -> 76500 | K17: =_xlfn.IFERROR(J17/T13,"") -> 213.68715 | L17: =_xlfn.IFERROR(I17/H17*100,"") -> 4.375
B18: -20# | C18: 30000 | D18: =_xlfn.IFERROR(SUM(D99:D100),"") -> 1352 | E18: =_xlfn.IFERROR(SUM(E99:E100),"") -> 1352 | F18: =IF(C18-E18=0,"",C18-E18) -> 28648 | G18: =_xlfn.IFERROR(IF(F18/S8=0,"",F18/S8),"") | H18: 50000 | I18: =_xlfn.IFERROR(SUM(I99:I100),"") -> 1352 | J18: =H18-I18 -> 48648 | K18: =_xlfn.IFERROR(J18/T13,"") -> 135.88827 | L18: =_xlfn.IFERROR(I18/H18*100,"") -> 2.704
B19: 航煤产量 | C19: 43899.604 | D19: =SUM(D155:D157) -> 1204 | E19: =SUM(E155:E157) -> 9331 | F19: =C19-E19 -> 34568.604 | G19: =_xlfn.IFERROR(F19/S19,"") | I19: =SUM(I155:I157) -> 9331 | J19: =H19-I19 -> -9331 | K19: =_xlfn.IFERROR(J19/T13,"") -> -26.064246 | L19: =_xlfn.IFERROR(I19/H19*100,"")
B20: LNG产量 | C20: =_xlfn.IFERROR(C38,"") -> 120000 | D20: =_xlfn.IFERROR(SUM(D144:D148),"") -> 2119 | E20: =_xlfn.IFERROR(SUM(E144:E148),"") -> 15226 | F20: =C20-E20 -> 104774 | G20: =_xlfn.IFERROR(F20/S5,"") -> 4365.5833 | H20: =_xlfn.IFERROR(H35,"") -> 0 | I20: =_xlfn.IFERROR(SUM(I144:I148),"") -> 15226 | J20: =H20-I20 -> -15226 | K20: =_xlfn.IFERROR(J20/T13,"") -> -42.530726 | L20: =_xlfn.IFERROR(I20/H20*100,"")
B21: 苯乙烯产量 | C21: 4600.36 | D21: =_xlfn.IFERROR(D104,"") -> 151 | E21: =_xlfn.IFERROR(E104,"") -> 1075 | F21: =C21-E21 -> 3525.36 | G21: =_xlfn.IFERROR(F21/S5,"") -> 146.89 | I21: =_xlfn.IFERROR(I104,"") -> 1075 | J21: =H21-I21 -> -1075 | K21: =_xlfn.IFERROR(J21/T13,"") -> -3.0027933 | L21: =_xlfn.IFERROR(I21/H21*100,"")
B22: 聚丙烯产量 | C22: 26499.939 | D22: =_xlfn.IFERROR(SUM(D106:D107),"") -> 914.56 | E22: =_xlfn.IFERROR(SUM(E106:E107),"") -> 6369.06 | F22: =C22-E22 -> 20130.879 | G22: =_xlfn.IFERROR(F22/S5,"") -> 838.78662 | I22: =_xlfn.IFERROR(SUM(I106:I107),"") -> 6369.06 | J22: =H22-I22 -> -6369.06 | K22: =_xlfn.IFERROR(J22/T13,"") -> -17.79067 | L22: =_xlfn.IFERROR(I22/H22*100,"")
B23: MTBE产量 | C23: 26800 | D23: =_xlfn.IFERROR(SUM(D109:D111),"") -> 943 | E23: =_xlfn.IFERROR(SUM(E109:E111),"") -> 6694 | F23: =C23-E23 -> 20106 | G23: =_xlfn.IFERROR(F23/S5,"") -> 837.75 | I23: =_xlfn.IFERROR(SUM(I109:I111),"") -> 6694 | J23: =H23-I23 -> -6694 | K23: =_xlfn.IFERROR(J23/T13,"") -> -18.698324 | L23: =_xlfn.IFERROR(I23/H23*100,"")
B24: SBA产量 | C24: 5100.027 | D24: =_xlfn.IFERROR(D113,"") -> 169 | E24: =_xlfn.IFERROR(E113,"") -> 1128 | F24: =C24-E24 -> 3972.027 | G24: =_xlfn.IFERROR(F24/S5,"") -> 165.50113 | I24: =_xlfn.IFERROR(I113,"") -> 1128 | J24: =H24-I24 -> -1128 | K24: =_xlfn.IFERROR(J24/T13,"") -> -3.150838 | L24: =_xlfn.IFERROR(I24/H24*100,"")
B25: 烷基化油产量 | C25: 18000.055 | D25: =_xlfn.IFERROR(D115,"") -> 604 | E25: =_xlfn.IFERROR(E115,"") -> 4379 | F25: =C25-E25 -> 13621.055 | G25: =_xlfn.IFERROR(F25/S5,"") -> 567.54396 | I25: =_xlfn.IFERROR(I115,"") -> 4379 | J25: =H25-I25 -> -4379 | K25: =_xlfn.IFERROR(J25/T13,"") -> -12.231844 | L25: =_xlfn.IFERROR(I25/H25*100,"")
B26: 石脑油销量 | F26: =IF(C26-E26=0,"",C26-E26) | G26: =_xlfn.IFERROR(IF(F26/S16=0,"",F26/S16),"") | J26: =IF(H26-I26=0,"",H26-I26) | K26: =_xlfn.IFERROR(IF(J26/T16=0,"",J26/T16),"") | L26: =_xlfn.IFERROR(I26/H26*100,"")
B27: 液化气销量 | C27: =SUM(C35:C36) -> 0 | D27: =_xlfn.IFERROR(SUM(D117:D130),"") -> 1917.48 | E27: =_xlfn.IFERROR(SUM(E117:E130),"") -> 10122.14 | F27: =C27-E27 -> -10122.14 | G27: =_xlfn.IFERROR(F27/S5,"") -> -421.75583 | I27: =_xlfn.IFERROR(SUM(I117:I130),"") -> 10122.14 | J27: =H27-I27 -> -10122.14 | K27: =_xlfn.IFERROR(J27/T13,"") -> -28.274134 | L27: =_xlfn.IFERROR(I27/H27*100,"")
B28: 1#渣油销售量 | C28: 120000 | D28: =_xlfn.IFERROR(SUM(D132:D134),"") -> 3906 | E28: =_xlfn.IFERROR(SUM(E132:E134),"") -> 25627 | F28: =C28-E28 -> 94373 | G28: =_xlfn.IFERROR(F28/S5,"") -> 3932.2083 | I28: =_xlfn.IFERROR(SUM(I132:I134),"") -> 25627 | J28: =H28-I28 -> -25627 | K28: =_xlfn.IFERROR(J28/T13,"") -> -71.583799 | L28: =_xlfn.IFERROR(I28/H28*100,"")
B29: 乙二醇产量 | C29: 5000 | D29: =_xlfn.IFERROR(SUM(D151:D153),"") -> 190 | E29: =_xlfn.IFERROR(SUM(E151:E153),"") -> 1488 | F29: =C29-E29 -> 3512 | G29: =_xlfn.IFERROR(F29/S5,"") -> 146.33333 | I29: =_xlfn.IFERROR(SUM(I151:I153),"") -> 1488 | J29: =H29-I29 -> -1488 | K29: =_xlfn.IFERROR(J29/T13,"") -> -4.1564246 | L29: =_xlfn.IFERROR(I29/H29*100,"")
B30: BDO产量 | C30: 5000 | D30: =_xlfn.IFERROR(D138,"") -> 202 | E30: =_xlfn.IFERROR(E138,"") -> 1461.2782 | F30: =C30-E30 -> 3538.7218 | G30: =_xlfn.IFERROR(F30/S5,"") -> 147.44674 | I30: =_xlfn.IFERROR(I138,"") -> 1461.2782 | J30: =H30-I30 -> -1461.2782 | K30: =_xlfn.IFERROR(J30/T13,"") -> -4.0817828 | L30: =_xlfn.IFERROR(I30/H30*100,"")
B31: PT产量 | C31: 0 | D31: =_xlfn.IFERROR(SUM(D140:D141),"") -> 0 | E31: =_xlfn.IFERROR(SUM(E140:E141),"") -> 0 | F31: =C31-E31 -> 0 | G31: =_xlfn.IFERROR(F31/S5,"") -> 0 | I31: =_xlfn.IFERROR(SUM(I140:I141),"") -> 0 | J31: =H31-I31 -> 0 | K31: =_xlfn.IFERROR(J31/T13,"") -> 0 | L31: =_xlfn.IFERROR(I31/H31*100,"")
B32: 备注
B35: 223000 | D35: 重整装置处理量 | E35: 重整装置处理量 | I35: 重整装置处理量 | N35: 69.224074 | O35: 原油加工量 | P35: 原油加工量 | Q35: 原油加工量
D36: 617 | E36: 4266 | I36: 4266 | N36: 17.100617 | O36: 48.30025 | P36: 48.547401 | Q36: 48.547401
D37: 3340 | E37: 23339 | I37: 23339 | O37: 49.042854 | P37: 49.121111 | Q37: 49.121111
C38: 120000 | D38: 4280 | E38: 29955 | I38: 29955 | O38: 51.865241 | P38: 52.837868 | Q38: 52.837868
D39: 汽油加氢精制处理量 | E39: 汽油加氢精制处理量 | I39: 汽油加氢精制处理量 | O39: 渣油加工量 | P39: 渣油加工量 | Q39: 渣油加工量
D40: 1806 | E40: 12962 | I40: 12962
D41: 2061 | E41: 14313 | I41: 14313
D42: 4149 | E42: 29145 | I42: 29145
...
