Workbook

Sheet 早八点信息简表
B1: 炼化公司早八点生产信息简表
B3: 填报单位：炼化公司 | E3: 统计日期： | G3: =S3 -> 2026-01-06 | J3: 填报日期： | K3: =取值!A1 -> 2026-01-07 | M3: 2022-01-26 | N3: 8:00:00 | S3: 2026-01-06
B4: 销售信息
D5: 延炼_x0009__x0009_ | G5: 永炼 | J5: 榆炼
D6: 公路 | E6: 铁路 | F6: 管输 | G6: 公路 | H6: 铁路 | I6: 管输 | J6: 公路 | K6: 铁路 | L6: 管输
B7: 92# | D7: =_xlfn.IFERROR(IF(取值!A108=0,"",取值!A108),"") -> 20 | E7: =_xlfn.IFERROR(IF(取值!A115=0,"",取值!A115),"") | F7: =_xlfn.IFERROR(IF(取值!A122=0,"",取值!A122),"") -> 9837 | G7: =_xlfn.IFERROR(IF(取值!A29=0,"",取值!A29),"") -> 187 | I7: =_xlfn.IFERROR(取值!A33,"") -> 1810 | J7: =_xlfn.IFERROR(取值!A160,"") -> 573.44 | K7: =_xlfn.IFERROR(IF(取值!A166=0,"",取值!A166),"") -> 2289 | L7: =_xlfn.IFERROR(IF(取值!A172=0,"",取值!A172),"")
B8: 95# | D8: =_xlfn.IFERROR(IF(取值!A109=0,"",取值!A109),"") -> 162 | E8: =_xlfn.IFERROR(IF(取值!A116=0,"",取值!A116),"") -> 3169 | F8: =_xlfn.IFERROR(IF(取值!A123=0,"",取值!A123),"") | J8: =_xlfn.IFERROR(取值!A161,"") -> 416 | K8: =_xlfn.IFERROR(IF(取值!A167=0,"",取值!A167),"") | L8: =_xlfn.IFERROR(IF(取值!A173=0,"",取值!A173),"")
B9: 98# | D9: =_xlfn.IFERROR(IF(取值!A110=0,"",取值!A110),"") | E9: =_xlfn.IFERROR(IF(取值!A117=0,"",取值!A117),"") | F9: =_xlfn.IFERROR(IF(取值!A124=0,"",取值!A124),"")
B10: 0# | D10: =_xlfn.IFERROR(IF(取值!A111=0,"",取值!A111),"") -> 21 | E10: =_xlfn.IFERROR(IF(取值!A118=0,"",取值!A118),"") -> 3442 | F10: =_xlfn.IFERROR(IF(取值!A125=0,"",取值!A125),"") | G10: =_xlfn.IFERROR(IF(取值!A30=0,"",取值!A30),"") -> 60 | I10: =_xlfn.IFERROR(取值!A34,"") -> 1582 | J10: =_xlfn.IFERROR(取值!A162,"") -> 94.76 | K10: =_xlfn.IFERROR(IF(取值!A168=0,"",取值!A168),"") -> 5251 | L10: =_xlfn.IFERROR(IF(取值!A174=0,"",取值!A174),"")
B11: -10# | D11: =_xlfn.IFERROR(IF(取值!A112=0,"",取值!A112),"") | E11: =_xlfn.IFERROR(IF(取值!A119=0,"",取值!A119),"") | F11: =_xlfn.IFERROR(IF(取值!A126=0,"",取值!A126),"") | J11: =_xlfn.IFERROR(取值!A163,"") -> 192.9 | K11: =_xlfn.IFERROR(IF(取值!A169=0,"",取值!A169),"") | L11: =_xlfn.IFERROR(IF(取值!A175=0,"",取值!A175),"") -> 1480
B12: -20# | D12: =_xlfn.IFERROR(IF(取值!A113=0,"",取值!A113),"") | E12: =_xlfn.IFERROR(IF(取值!A120=0,"",取值!A120),"") | F12: =_xlfn.IFERROR(IF(取值!A127=0,"",取值!A127),"") | G12: =_xlfn.IFERROR(IF(取值!A31=0,"",取值!A31),"") -> 892 | I12: =_xlfn.IFERROR(IF(取值!A35=0,"",取值!A35),"") | J12: =_xlfn.IFERROR(IF(取值!A164=0,"",取值!A164),"") | K12: =_xlfn.IFERROR(IF(取值!A170=0,"",取值!A170),"") | L12: =_xlfn.IFERROR(IF(取值!A176=0,"",取值!A176),"")
B13: 航煤 | D13: =_xlfn.IFERROR(IF(取值!A114=0,"",取值!A114),"") -> 65 | E13: =_xlfn.IFERROR(IF(取值!A121=0,"",取值!A121),"") | F13: =_xlfn.IFERROR(IF(取值!A128=0,"",取值!A128),"") | G13: =_xlfn.IFERROR(IF(取值!A32=0,"",取值!A32),"") | I13: =_xlfn.IFERROR(IF(取值!A36=0,"",取值!A36),"") | J13: =_xlfn.IFERROR(IF(取值!A165=0,"",取值!A165),"") | K13: =_xlfn.IFERROR(IF(取值!A171=0,"",取值!A171),"") | L13: =_xlfn.IFERROR(IF(取值!A177=0,"",取值!A177),"") -> 1905
B14: LNG产销量信息 | I14: 原油价格信息
D15: 临镇 | E15: 杨家湾 | F15: 延川 | G15: 志丹 | H15: 安塞 | J15: 当日价格 | K15: 前日价格 | L15: 涨跌
B16: 产量 | D16: =_xlfn.IFERROR(取值!A216,"") -> 0 | E16: =_xlfn.IFERROR(取值!A219,"") -> 369.34 | F16: =_xlfn.IFERROR(取值!A222,"") -> 467.36 | G16: =_xlfn.IFERROR(取值!A225,"") -> 761.73 | H16: =_xlfn.IFERROR(取值!A228,"") -> 521.44 | I16: WTI | J16: 57.13 | K16: 58.32 | L16: =_xlfn.IFERROR(J16-K16,"") -> -1.19
B17: 销量 | D17: =_xlfn.IFERROR(取值!A217,"") -> 0 | E17: =_xlfn.IFERROR(取值!A220,"") -> 873.08 | F17: =_xlfn.IFERROR(取值!A223,"") -> 749.9 | G17: =_xlfn.IFERROR(取值!A226,"") -> 1829.96 | H17: =_xlfn.IFERROR(取值!A229,"") -> 645.54 | I17: BRENT | J17: 60.7 | K17: 61.74 | L17: =_xlfn.IFERROR(J17-K17,"") -> -1.04
B18: 价格 | D18: =_xlfn.IFERROR(取值!A231,"") -> 3310 | E18: =_xlfn.IFERROR(取值!A232,"") -> 3300 | F18: =_xlfn.IFERROR(取值!A233,"") -> 3290 | G18: =_xlfn.IFERROR(取值!A234,"") -> 3250 | H18: =_xlfn.IFERROR(取值!A235,"") -> 3280 | I18: 沪油 | J18: 427.3 | K18: 426.8 | L18: =_xlfn.IFERROR(J18-K18,"") -> 0.5
B19: 调运信息_x0009__x0009__x0009__x0009__x0009__x0009__x0009__x0009__x0009_
B20: 延炼 | E20: 永炼 | H20: 榆炼 | K20: 石化厂
B21: 卸原料气 | D21: =_xlfn.IFERROR(IF(取值!A129=0,"",取值!A129),"") -> 1056 | E21: 石脑油调石化厂 | G21: =_xlfn.IFERROR(IF(取值!A37=0,"",取值!A37),"") -> 764 | H21: 原料气调延炼 | J21: =_xlfn.IFERROR(IF(取值!A178=0,"",取值!A178),"") -> 536 | K21: 卸永炼石脑油 | L21: =_xlfn.IFERROR(IF(取值!A67=0,"",取值!A67),"") -> 667.36
B22: 卸饱和气 | D22: =_xlfn.IFERROR(IF(取值!A130=0,"",取值!A130),"") -> 225 | E22: 1#渣油调榆能化 | G22: =_xlfn.IFERROR(IF(取值!A38=0,"",取值!A38),"") -> 1476 | H22: 饱和气调延炼 | J22: =_xlfn.IFERROR(IF(取值!A179=0,"",取值!A179),"") -> 250 | K22: 烷基化油调永炼 | L22: =_xlfn.IFERROR(IF(取值!A68=0,"",取值!A68),"") -> 219.1
B23: 回炼油 | D23: =_xlfn.IFERROR(IF(取值!A131=0,"",取值!A131),"") -> 64 | E23: 原料气调延炼 | G23: =_xlfn.IFERROR(IF(取值!A39=0,"",取值!A39),"") -> 709 | H23: 二甲苯调永炼 | J23: =_xlfn.IFERROR(IF(取值!A180=0,"",取值!A180),"") -> 129 | K23: 烷基化油调榆炼 | L23: =_xlfn.IFERROR(IF(取值!A69=0,"",取值!A69),"") -> 219.2
B24: 卸永炼渣油 | D24: =_xlfn.IFERROR(IF(取值!A132=0,"",取值!A132),"") | E24: 卸烷基化油 | G24: =_xlfn.IFERROR(IF(取值!A40=0,"",取值!A40),"") -> 219 | H24: 卸烷基化油 | J24: =_xlfn.IFERROR(IF(取值!A181=0,"",取值!A181),"") -> 314 | K24: MTBE调永炼 | L24: =_xlfn.IFERROR(IF(取值!A70=0,"",取值!A70),"") -> 313.46
B25: 卸二甲苯 | D25: =_xlfn.IFERROR(IF(取值!A133=0,"",取值!A133),"") | E25: 卸二甲苯 | G25: =_xlfn.IFERROR(IF(取值!A41=0,"",取值!A41),"") -> 32 | H25: 卸MTBE | J25: =_xlfn.IFERROR(IF(取值!A182=0,"",取值!A182),"") | K25: MTBE调榆炼 | L25: =_xlfn.IFERROR(IF(取值!A22=0,"",取值!A22),"")
B26: 2#渣油 | D26: =_xlfn.IFERROR(IF(取值!A134=0,"",取值!A134),"") | E26: 卸MTBE | G26: =_xlfn.IFERROR(IF(取值!A42=0,"",取值!A42),"") -> 314 | H26: 卸减压渣油 | J26: =_xlfn.IFERROR(IF(取值!A183=0,"",取值!A183),"") | K26: 异丁烷外购量 | L26: =_xlfn.IFERROR(IF(取值!A257=0,"",取值!A257),"") -> 224.72
E27: 2#渣油 | G27: =_xlfn.IFERROR(IF(取值!A43=0,"",取值!A43),"") | H27: 2#渣油 | J27: =_xlfn.IFERROR(IF(取值!A184=0,"",取值!A184),"")
B28: 化工品销售信息
B29: 产品名称 | D29: 产量 | E29: 销量 | F29: 单价 | G29: 装置负荷 | H29: 产品名称 | J29: 销量 | K29: 单价 | L29: 备注
B30: BDO | D30: =_xlfn.IFERROR(IF(取值!A139=0,"",取值!A139),"") -> 236.55 | E30: =_xlfn.IFERROR(IF(取值!A149=0,"",取值!A149),"") -> 226.98 | F30: =_xlfn.IFERROR(IF(取值!A154=0,"",取值!A154),"") -> 7400 | G30: =_xlfn.IFERROR(IF(取值!A140=0,"",取值!A140),"") -> 0.7885 | H30: 延炼民用气 | J30: =_xlfn.IFERROR(IF(取值!A247=0,"",取值!A247),"") -> 603 | K30: =_xlfn.IFERROR(IF(取值!A250=0,"",取值!A250),"") | L30: =_xlfn.IFERROR(IF(取值!A253=0,"",取值!A253),"") -> 内销
B31: 乙二醇 | C31: 聚酯级乙二醇 | D31: =_xlfn.IFERROR(IF(取值!A142=0,"",取值!A142),"") -> 178 | E31: =_xlfn.IFERROR(IF(取值!A150=0,"",取值!A150),"") -> 223.72 | F31: =_xlfn.IFERROR(IF(取值!A155=0,"",取值!A155),"") -> 3215 | G31: =_xlfn.IFERROR(IF(取值!A144=0,"",取值!A144),"") -> 0.658 | H31: 延炼丙烯 | J31: =_xlfn.IFERROR(IF(取值!A135=0,"",取值!A135),"") -> 95 | K31: =_xlfn.IFERROR(IF(取值!A136=0,"",取值!A136),"") | L31: =_xlfn.IFERROR(IF(取值!A137=0,“”,取值!A137),"") -> 内销
C32: 轻质多元醇 | D32: =_xlfn.IFERROR(IF(取值!A143=0,"",取值!A143),"") -> 19.4 | E32: =_xlfn.IFERROR(IF(取值!A151=0,"",取值!A151),"") -> 32.68 | F32: =_xlfn.IFERROR(IF(取值!A156=0,"",取值!A156),"") -> 2655 | H32: 延炼醚后碳四 | J32: =_xlfn.IFERROR(IF(取值!A248=0,"",取值!A248),"") -> 25/50 | K32: =_xlfn.IFERROR(IF(取值!A251=0,"",取值!A251),"") | L32: =_xlfn.IFERROR(IF(取值!A254=0,"",取值!A254),"") -> 外销/内销
B33: PTMEG | D33: =_xlfn.IFERROR(IF(取值!A146=0,"",取值!A146),"") | E33: =_xlfn.IFERROR(IF(取值!A152=0,"",取值!A152),"") | F33: =_xlfn.IFERROR(IF(取值!A157=0,"",取值!A157),"") | G33: =_xlfn.IFERROR(IF(取值!A147=0,"",取值!A147),"") | H33: 榆炼二甲苯 | J33: =_xlfn.IFERROR(IF(取值!A212=0,"",取值!A212),"") -> 430 | K33: =_xlfn.IFERROR(IF(取值!A213=0,"",取值!A213),"") | L33: =_xlfn.IFERROR(IF(取值!A214=0,“”,取值!A214),"")
B34: 混合醇 | D34: =_xlfn.IFERROR(IF(取值!A148=0,"",取值!A148),"") | E34: =_xlfn.IFERROR(IF(取值!A153=0,"",取值!A153),"") -> 32.64 | F34: =_xlfn.IFERROR(IF(取值!A158=0,"",取值!A158),"") -> 1690 | H34: 榆炼原料气 | J34: =_xlfn.IFERROR(IF(取值!A72=0,"",取值!A72),"") -> 316 | K34: =_xlfn.IFERROR(IF(取值!A73=0,"",取值!A73),"") | L34: =_xlfn.IFERROR(IF(取值!A74=0,“”,取值!A74),"")
B35: 天然气公司氦气产品 | D35: 产量 | E35: 677.02 | F35: 年累计销量 | G35: 4731.32 | H35: 价格 | I35: 71 | J35: 库存 | K35: 8929.7
B36: 天气情况 | D36: 交口区域 | F36: 延安区域 | H36: 永坪区域 | J36: 靖边区域 | K36: 定边区域 | L36: 江苏泰兴
D37: 晴天 | F37: 晴天 | H37: 晴天 | J37: 晴天 | K37: 晴天 | L37: 晴天
B38: 生产运行情况 | D38: 各单位生产运行正常。
D39: 审核人： | E39: 罗先波 | I39: 一审人： | J39: 胡连鹏 李阿君

Sheet 取值
A1: 2026-01-07 | B1: 8:00:00
A22: 0
A28: 永练
A29: 187
A30: 60
A31: 892
A33: 1810
A34: 1582
A37: 764
A38: 1476
A39: 709
A40: 219
A41: 32
A42: 314
A45: 187
... A58: 314
A59: 石化
A67: 667.36
A68: 219.1
A69: 219.2
A70: 313.46
A71: 0
A72: 316
A78: 延炼
A79: 20
A80: 162
A81: 21
A84: 65
A86: 3169
A87: 3442
A91: 9837
A97: 1056
A98: 225
A99: 64
A102: 95
A106: 内销
A108: 20
A109: 162
A111: 21
A114: 65
...

Sheet Sheet1
A1: 油田气_生产计划部_调度部门_信息简表_BDO库存量
A2: 油田气_生产计划部_调度部门_信息简表_BDO产量
A3: 油田气_生产计划部_调度部门_信息简表_BDO销量
A4: 油田气_生产计划部_调度部门_信息简表_BDO单价
A5: 油田气_生产计划部_调度部门_信息简表_BDO装置负荷
A6: 油田气_生产计划部_调度部门_信息简表_BDO备注
A7: 油田气_生产计划部_调度部门_信息简表_聚酯级乙二醇库存量
A8: 油田气_生产计划部_调度部门_信息简表_聚酯级乙二醇产量
A9: 油田气_生产计划部_调度部门_信息简表_聚酯级乙二醇销量
A10: 油田气_生产计划部_调度部门_信息简表_聚酯级乙二醇单价
A11: 油田气_生产计划部_调度部门_信息简表_乙二醇装置负荷
A12: 油田气_生产计划部_调度部门_信息简表_乙二醇备注
... A28: 油田气_生产计划部_调度部门_信息简表_混合醇备注
