Workbook

Sheet 生产计划指标完成情况
A1: 油田气生产计划指标完成情况表
A2: 编制单位：油田气科技公司 | F2: 日期： | G2: 2025-12 | J2: =取值!O1&取值!P1&取值!Q1 -> 报表生成时间：2026-01-01 8:00:00
A3: 指标名称 | C3: 计量 | D3: 本月 | G3: 年累计 | J3: 历史数据
C4: 单位 | D4: 月度计划 | E4: 实际完成 | F4: 完成情况（%） | G4: 年度计划 | H4: 实际完成 | I4: 完成情况（%） | J4: 上月完成 | K4: 环比增长（%） | L4: 去年同期 | M4: 同比增长（%）
A5: 一、加工量及主要产品产量
A6: BDO | C6: t | D6: 5000 | E6: =取值!E6 -> 6490.02 | F6: =_xlfn.IFERROR(SUM(E6/D6)*100,"") -> 129.8004 | G6: 83000 | H6: =取值!H6 -> 89597.99 | I6: =_xlfn.IFERROR(SUM(H6/G6)*100,"") -> 107.94939 | J6: 6116.41 | K6: =_xlfn.IFERROR(IF(SUM(SUM(E6-J6)/J6)*100=0,"",SUM(SUM(E6-J6)/J6))*100,"") -> 6.1083217 | L6: 8238.38 | M6: =_xlfn.IFERROR(IF(SUM(SUM(E6-L6)/L6=0)*100,"",SUM(SUM(E6-L6)/L6))*100,"") -> -21.222133
A7: PTMEG1800 | B7: 国标 | C7: t | D7: 0 | E7: =取值!E7 -> 0 | F7: =_xlfn.IFERROR(SUM(E7,E9)/D7*100,"") | G7: 26300 | H7: =取值!H7 -> 2857.9 | I7: =_xlfn.IFERROR(SUM(H7,H9)/G7*100,"") -> 10.86654 | J7: =取值!J7 -> 0 | K7: =_xlfn.IFERROR(IF(E7=0,"",SUM(SUM(E7-J7)/J7))*100,"") | L7: 2248 | M7: =_xlfn.IFERROR(IF(SUM(SUM(E7-L7)/L7=0)*100,"",SUM(SUM(E7-L7)/L7))*100,"") -> -100
B8: 行标 | C8: t | E8: =取值!E8 -> 0 | H8: =取值!H8 -> 0 | J8: =取值!J8 -> 0 | K8: =_xlfn.IFERROR(IF(E8=0,"",SUM(SUM(E8-J8)/J8))*100,"") | L8: 0 | M8: =_xlfn.IFERROR(IF(SUM(SUM(E8-L8)/L8=0)*100,"",SUM(SUM(E8-L8)/L8))*100,"")
A9: PTMEG2000 | B9: 国标 | C9: t | E9: =取值!E9 -> 0 | H9: =取值!H9 -> 0 | J9: =取值!J9 -> 0 | K9: =_xlfn.IFERROR(IF(SUM(SUM(E9-J9)/J9)*100=0,"",SUM(SUM(E9-J9)/J9))*100,"") | L9: 0 | M9: =_xlfn.IFERROR(IF(SUM(SUM(E9-L9)/L9=0)*100,"",SUM(SUM(E9-L9)/L9))*100,"")
B10: 行标 | C10: t | E10: =取值!E10 -> 0 | H10: =取值!H10 -> 0 | J10: =取值!J10 -> 0 | K10: =_xlfn.IFERROR(IF(SUM(SUM(E10-J10)/J10)*100=0,"",SUM(SUM(E10-J10)/J10))*100,"") | L10: 0 | M10: =_xlfn.IFERROR(IF(SUM(SUM(E10-L10)/L10=0)*100,"",SUM(SUM(E10-L10)/L10))*100,"")
A11: 聚酯级乙二醇 | C11: t | D11: 5000 | E11: =取值!E11 -> 4813 | F11: =_xlfn.IFERROR(SUM(SUM(E11,E12,E13,E14)/D11)*100,"") -> 116.942 | G11: 74000 | H11: =取值!H11 -> 63696 | I11: =_xlfn.IFERROR(SUM(SUM(H11,H12,H13,H14)/G11)*100,"") -> 114.25059 | J11: =取值!J11 -> 5605 | K11: =_xlfn.IFERROR(IF(E11=0,"",SUM(SUM(E11-J11)/J11))*100,"") -> -14.130241 | L11: 6106 | M11: =_xlfn.IFERROR(IF(SUM(SUM(E11-L11)/L11=0)*100,"",SUM(SUM(E11-L11)/L11))*100,"") -> -21.175893
A12: 工业级乙二醇 | C12: t | E12: =取值!E12 -> 0 | H12: =取值!H12 -> 0 | J12: =取值!J12 -> 0 | K12: =_xlfn.IFERROR(IF(SUM(SUM(E12-J12)/J12)*100=0,"",SUM(SUM(E12-J12)/J12))*100,"") | L12: 0 | M12: =_xlfn.IFERROR(IF(SUM(SUM(E12-L12)/L12=0)*100,"",SUM(SUM(E12-L12)/L12))*100,"")
A13: 轻质多元醇 | C13: t | E13: =取值!E13 -> 473.2 | H13: =取值!H13 -> 13767.94 | J13: =取值!J13 -> 780.8 | K13: =_xlfn.IFERROR(IF(SUM(SUM(E13-J13)/J13)*100=0,"",SUM(SUM(E13-J13)/J13))*100,"") -> -39.395492 | L13: 1295.9 | M13: =_xlfn.IFERROR(IF(SUM(SUM(E13-L13)/L13=0)*100,"",SUM(SUM(E13-L13)/L13))*100,"") -> -63.484837
A14: 重质多元醇 | C14: t | E14: =取值!E14 -> 560.9 | H14: =取值!H14 -> 7081.5 | J14: =取值!J14 -> 493.7 | K14: =_xlfn.IFERROR(IF(SUM(SUM(E14-J14)/J14)*100=0,"",SUM(SUM(E14-J14)/J14))*100,"") -> 13.611505 | L14: 531.5 | M14: =_xlfn.IFERROR(IF(SUM(SUM(E14-L14)/L14=0)*100,"",SUM(SUM(E14-L14)/L14))*100,"") -> 5.5315146
A15: 二、技术经济指标 | E15: =E11+E12+E13+E14 -> 5847.1 | F15: =E11/E15*100 -> 82.31431
A16: 1、生产吨乙炔耗原料天然气 | C16: Nm3/t | D16: 7250 | E16: 6964.0332 | F16: =_xlfn.IFERROR(E16-D16,"") -> -285.96677 | G16: 7450 | H16: 7061.3301 | I16: =_xlfn.IFERROR(SUM(H16-G16),"") -> -388.66992 | J16: =取值!J16 -> 7075.3657 | K16: =_xlfn.IFERROR(E16-J16,"") -> -111.33247 | L16: 7211.4942 | M16: =_xlfn.IFERROR(E16-L16,"") -> -247.46095
A17: 2、生产吨甲醛耗原料甲醇 | C17: t/t | D17: 0.42 | E17: =取值!E17 -> 0.42098553 | F17: =_xlfn.IFERROR(E17-D17,"") -> 0.00098552893 | G17: 0.43 | H17: =取值!H17 -> 0.41756396 | I17: =_xlfn.IFERROR(SUM(H17-G17),"") -> -0.012436042 | J17: =取值!J17 -> 0.42350725 | K17: =_xlfn.IFERROR(E17-J17,"") -> -0.0025217202 | L17: 0.3944946 | M17: =_xlfn.IFERROR(E17-L17,"") -> 0.026490924
A18: 3、生产吨BDO耗原料乙炔 | C18: t/t | D18: 0.42 | E18: =取值!E18 -> 0.41390518 | F18: =_xlfn.IFERROR(E18-D18,"") -> -0.0060948192 | G18: 0.4 | H18: =取值!H18 -> 0.380971 | I18: =_xlfn.IFERROR(SUM(H18-G18),"") -> -0.019028999 | J18: =取值!J18 -> 0.39499598 | K18: =_xlfn.IFERROR(E18-J18,"") -> 0.018909197 | L18: 0.36580868 | M18: =_xlfn.IFERROR(E18-L18,"") -> 0.048096496
A19: 4、生产吨PTMEG耗BDO | C19: t/t | D19: 0 | E19: =取值!E19 | F19: =_xlfn.IFERROR(E19-D19,"") | G19: 1.38 | H19: 1.7162498 | I19: =_xlfn.IFERROR(SUM(H19-G19),"") -> 0.33624981 | J19: =取值!J19 | K19: =_xlfn.IFERROR(E19-J19,"") | L19: 1.0652873 | M19: =_xlfn.IFERROR(E19-L19,"")
A20: 5、生产吨乙二醇耗CO | C20: Nm3/t | D20: 1100 | E20: =_xlfn.IFERROR(ROUND(取值!E20,2),"") -> 862.52 | F20: =_xlfn.IFERROR(E20-D20,"") -> -237.48 | G20: 1020 | H20: 935.04772 | I20: =_xlfn.IFERROR(SUM(H20-G20),"") -> -84.952279 | J20: =_xlfn.IFERROR(ROUND(取值!J20,2),"") -> 965.92 | K20: =_xlfn.IFERROR(E20-J20,"") -> -103.4 | L20: 1095.7204 | M20: =_xlfn.IFERROR(E20-L20,"") -> -233.20038
A21: 6、全厂综合能耗 | C21: kgce/t | D21: 2980 | E21: =取值!E38 -> 2724.02 | F21: =_xlfn.IFERROR(E21-D21,"") -> -255.98 | G21: 3400 | H21: =取值!H38 -> 2485.28 | I21: =_xlfn.IFERROR(SUM(H21-G21),"") -> -914.72 | J21: =_xlfn.IFERROR(ROUND(取值!J21,2),"") -> 2598 | K21: =_xlfn.IFERROR(E21-J21,"") -> 126.02 | L21: 2612.62 | M21: =_xlfn.IFERROR(E21-L21,"") -> 111.4
A22: 单位负责人： | C22: 李刚 | K22: 填报人： | L22: 霍宇

Sheet 取值
A1: 油田气生产计划指标完成情况表 | O1: 报表生成时间： | P1: 2026-01-01 | Q1: 8:00:00
A2: 编制单位：油田气科技公司 | F2: 日期： | G2: 2025-12
A3: 指标名称 | C3: 计量 | D3: 本月 | G3: 年累计 | J3: 历史数据
C4: 单位 | D4: 月度计划 | E4: 实际完成 | F4: 完成情况 | G4: 年度计划 | H4: 实际完成 | I4: 完成情况 | J4: 上月完成 | K4: 环比% ( + -) | L4: 去年同期 | M4: ·
A5: 一、加工量及主要产品产量 | F5: % | I5: % | K5: % | M5: %
A6: BDO | C6: t | D6: =D24 -> 5000 | E6: =_xlfn.IFERROR(SUM(E24,E61),"") -> 6490.02 | F6: =_xlfn.IFERROR(E6/D6,"") -> 1.298004 | G6: =G24 -> 83000 | H6: =_xlfn.IFERROR(SUM(H24,H61),"") -> 89597.99 | I6: =_xlfn.IFERROR(H6/G6,"") -> 1.0794939 | J6: =_xlfn.IFERROR(SUM(J24),"") -> 6116.41 | L6: =_xlfn.IFERROR(SUM(L24,L61),"") -> 8238.38
A7: PTMEG1800 | B7: 国标 | C7: t | D7: =D27 -> 0 | E7: =E25 -> 0 | F7: =_xlfn.IFERROR(E7/D7,"") | G7: =G25 -> 26300 | H7: =H25 -> 2857.9 | I7: =_xlfn.IFERROR(H7/G7,"") -> 0.1086654 | J7: =J25 -> 0 | L7: =L25 -> 2248
B8: 行标 | C8: t | E8: =E26 -> 0 | H8: =H26 -> 0 | J8: =J26 -> 0 | L8: =L26 -> 0
A9: PTMEG2000 | B9: 国标 | C9: t | E9: =E27 -> 0 | F9: =_xlfn.IFERROR(E9/D9,"") | H9: =H27 -> 0 | I9: =_xlfn.IFERROR(H9/G9,"") | J9: =J27 -> 0 | L9: =L27 -> 0
B10: 行标 | C10: t | E10: =E28 -> 0 | H10: =H28 -> 0 | J10: =J28 -> 0 | L10: =L28 -> 0
A11: 聚酯级乙二醇 | C11: t | D11: =D29 -> 5000 | E11: =E29 -> 4813 | F11: =_xlfn.IFERROR(E11/D11,"") -> 0.9626 | G11: =G29 -> 74000 | H11: =H29 -> 63696 | I11: =_xlfn.IFERROR(H11/G11,"") -> 0.86075676 | J11: =J29 -> 5605 | L11: =L29 -> 6106
A12: 工业级乙二醇 | C12: t | E12: =E30 -> 0 | F12: =_xlfn.IFERROR(E12/D12,"") | H12: =H30 -> 0 | I12: =_xlfn.IFERROR(H12/G12,"") | J12: =J30 -> 0 | L12: =L30 -> 0
A13: 轻质多元醇 | C13: t | E13: =E31 -> 473.2 | F13: =_xlfn.IFERROR(E13/D13,"") | H13: =H31 -> 13767.94 | I13: =_xlfn.IFERROR(H13/G13,"") | J13: =J31 -> 780.8 | L13: =L31 -> 1295.9
A14: 重质多元醇 | E14: =E32 -> 560.9 | F14: =_xlfn.IFERROR(E14/D14,"") | H14: =H32 -> 7081.5 | I14: =_xlfn.IFERROR(H14/G14,"") | J14: =J32 -> 493.7 | L14: =L32 -> 531.5
A15: 二、技术经济指标
A16: 1、生产吨乙炔耗原料天然气 | C16: Nm3/t | D16: =D33 -> 7250 | E16: =E33 -> 6964.0332 | F16: =_xlfn.IFERROR(D16-E16,"") -> 285.96677 | G16: =G33 -> 7450 | H16: =H33 -> 7061.3301 | I16: =_xlfn.IFERROR(G16-H16,"") -> 388.66992 | J16: =J33 -> 7075.3657 | L16: =L33 -> 7211.4942
A17: 2、生产吨甲醛耗原料甲醇 | C17: t/t | D17: =D34 -> 0.42 | E17: =E34 -> 0.42098553 | F17: =_xlfn.IFERROR(D17-E17,"") -> -0.00098552893 | G17: =G34 -> 0.43 | H17: =H34 -> 0.41756396 | I17: =_xlfn.IFERROR(G17-H17,"") -> 0.012436042 | J17: =J34 -> 0.42350725 | L17: =L34 -> 0.3944946
A18: 3、生产吨BDO耗原料乙炔 | C18: t/t | D18: =D35 -> 0.42 | E18: =E35 -> 0.41390518 | F18: =_xlfn.IFERROR(D18-E18,"") -> 0.0060948192 | G18: =G35 -> 0.4 | H18: =H35 -> 0.380971 | I18: =_xlfn.IFERROR(G18-H18,"") -> 0.019028999 | J18: =J35 -> 0.39499598 | L18: =L35 -> 0.36580868
A19: 4、生产吨PTMEG耗BDO | C19: t/t | D19: =D36 -> 0 | E19: =E36 | F19: =_xlfn.IFERROR(D19-E19,"") | G19: =G36 -> 1.38 | H19: =H36 -> 1.7162498 | I19: =_xlfn.IFERROR(G19-H19,"") -> -0.33624981 | J19: =J36 | L19: =L36 -> 1.0652873
A20: 5、生产吨乙二醇耗CO | C20: Nm3/t | D20: =D37 -> 1100 | E20: =E37 -> 862.51989 | F20: =_xlfn.IFERROR(D20-E20,"") -> 237.48011 | G20: =G37 -> 1020 | H20: =H37 -> 935.04772 | I20: =_xlfn.IFERROR(G20-H20,"") -> 84.952279 | J20: =J37 -> 965.91749 | L20: =L37 -> 1095.7204
A21: 6、全厂综合能耗 | C21: kgce/t | D21: =D38 -> 2980 | E21: =E38 -> 2724.02 | G21: =G38 -> 3400 | H21: =H38 -> 2485.28 | J21: =J38 -> 2598 | L21: =L38 -> 2612.62
A22: 单位负责人： | K22: 填报人：
D24: 5000 | E24: 6490.02 | G24: 83000 | H24: 89597.99 | J24: 6116.41 | L24: 8238.38
E25: 0 | G25: 26300 | H25: 2857.9 | J25: 0 | L25: 2248
E26: 0 | H26: 0 | J26: 0 | L26: 0
D27: 0 | E27: 0 | H27: 0 | J27: 0 | L27: 0
E28: 0 | H28: 0 | J28: 0 | L28: 0
D29: 5000 | E29: 4813 | G29: 74000 | H29: 63696 | J29: 5605 | L29: 6106
E30: 0 | H30: 0 | J30: 0 | L30: 0
E31: 473.2 | H31: 13767.94 | J31: 780.8 | L31: 1295.9
E32: 560.9 | H32: 7081.5 | J32: 493.7 | L32: 531.5
D33: 7250 | E33: =_xlfn.IFERROR(SUM(E40)/E41,"") -> 6964.0332 | G33: 7450 | H33: =_xlfn.IFERROR(H40/H41,"") -> 7061.3301 | J33: =_xlfn.IFERROR(J40/J41,"") -> 7075.3657 | L33: =_xlfn.IFERROR(SUM(L40)/L41,"") -> 7211.4942
D34: 0.42 | E34: =_xlfn.IFERROR(E43/E44,"") -> 0.42098553 | G34: 0.43 | H34: =_xlfn.IFERROR(H43/H44,"") -> 0.41756396 | J34: =_xlfn.IFERROR(J43/J44,"") -> 0.42350725 | K34: =_xlfn.IFERROR(SUM(J34/E34),"") -> 1.00599 | L34: =_xlfn.IFERROR(L43/L44,"") -> 0.3944946
D35: 0.42 | E35: =_xlfn.IFERROR(E46/E47,"") -> 0.41390518 | G35: 0.4 | H35: =_xlfn.IFERROR(H46/H47,"") -> 0.380971 | J35: =_xlfn.IFERROR(J46/J47,"") -> 0.39499598 | L35: =_xlfn.IFERROR(L46/L47,"") -> 0.36580868
D36: 0 | E36: =_xlfn.IFERROR(E49/SUM(E50,E51),"") | G36: 1.38 | H36: =_xlfn.IFERROR(H49/SUM(H50,H51),"") -> 1.7162498 | J36: =_xlfn.IFERROR(J49/SUM(J50,J51),"") | L36: =_xlfn.IFERROR(L49/SUM(L50,L51),"") -> 1.0652873
D37: 1100 | E37: =_xlfn.IFERROR(E53/SUM(E54,E55,E56,E32),"") -> 862.51989 | G37: 1020 | H37: =_xlfn.IFERROR(H53/SUM(H54,H55,H56,H57),"") -> 935.04772 | J37: =_xlfn.IFERROR(J53/SUM(J54,J55,J56,J57),"") -> 965.91749 | L37: =_xlfn.IFERROR(L53/SUM(L54,L55,L56,L57),"") -> 1095.7204
D38: 2980 | E38: 2724.02 | G38: 3400 | H38: 2485.28 | J38: 2598 | L38: 2612.62
E40: 19279926 | H40: 245564815 | J40: 17780394 | L40: 24464994
E41: 2768.5 | H41: 34776 | J41: 2513 | L41: 3392.5
E43: 5514.3 | H43: 79666.99 | J43: 6216.07 | L43: 7883.02
...
