Workbook

Sheet 装置生产流程表
B2: 装置生产流程表
B3: 填报单位：榆林炼油厂 | F3: 日期： | G3: 2025-12 | P3: =Sheet2!A1&Sheet2!B1&Sheet2!C1 -> 报表生成时间：2025-12 8:00:00 | T3: 陕油炼计统B202表
B4: 装置 名称 | C4: 指标名称 | D4: 产量 t | F4: 收率 % | H4: 去年同期 | J4: 收率 % | L4: 装置 名称 | M4: 指标名称 | N4: 产量 t | P4: 收率 % | R4: 去年同期 | T4: 收率 %
D5: 本月 | E5: 累计 | F5: 本月 | G5: 累计 | H5: 本月 | I5: 累计 | J5: 本月 | K5: 累计 | N5: 本月 | O5: 累计 | P5: 本月 | Q5: 累计 | R5: 本月 | S5: 累计 | T5: 本月 | U5: 累计
B6: 500万 吨 常 压 装 置 | C6: 原油加工量 | D6: 379023 | E6: =_xlfn.IFERROR(取值!A73+D6,"") -> 3972275 | L6: 100万 吨 重 整 装 置 | M6: 加工量 | N6: 94368 | O6: =_xlfn.IFERROR(取值!A113+N6,"") -> 1002315
C7: 石脑油Ⅰ | D7: 48401 | E7: =_xlfn.IFERROR(取值!A74+D7,"") -> 493722 | F7: =_xlfn.IFERROR(D7/D6*100,"") -> 12.769937 | G7: =_xlfn.IFERROR(E7/E6*100,"") -> 12.4292 | J7: =_xlfn.IFERROR(H7/H6*100,"") | K7: =_xlfn.IFERROR(I7/I6*100,"") | M7: 重整汽油 | N7: 51101 | O7: =_xlfn.IFERROR(取值!A114+N7,"") -> 634833 | P7: =_xlfn.IFERROR(N7/N6*100,"") -> 54.150771 | Q7: =_xlfn.IFERROR(O7/O6*100,"") -> 63.336676 | T7: =_xlfn.IFERROR(R7/R6*100,"") | U7: =_xlfn.IFERROR(S7/S6*100,"")
C8: 常一线 | D8: 29173 | E8: =_xlfn.IFERROR(取值!A75+D8,"") -> 281248 | F8: =_xlfn.IFERROR(D8/D6*100,"") -> 7.6968944 | G8: =_xlfn.IFERROR(E8/E6*100,"") -> 7.0802752 | J8: =_xlfn.IFERROR(H8/H6*100,"") | K8: =_xlfn.IFERROR(I8/I6*100,"") | M8: 二甲苯塔底油 | N8: 4696 | O8: =_xlfn.IFERROR(取值!A115+N8,"") -> 21166 | P8: =_xlfn.IFERROR(N8/N6*100,"") -> 4.9762631 | Q8: =_xlfn.IFERROR(O8/O6*100,"") -> 2.1117114 | T8: =_xlfn.IFERROR(R8/R6*100,"") | U8: =_xlfn.IFERROR(S8/S6*100,"")
C9: 常二线 | D9: 0 | E9: =_xlfn.IFERROR(取值!A76+D9,"") -> 0 | F9: =_xlfn.IFERROR(D9/D6*100,"") -> 0 | G9: =_xlfn.IFERROR(E9/E6*100,"") -> 0 | J9: =_xlfn.IFERROR(H9/H6*100,"") | K9: =_xlfn.IFERROR(I9/I6*100,"") | M9: C6馏分油 | N9: 13694 | O9: =_xlfn.IFERROR(取值!A116+N9,"") -> 136054 | P9: =_xlfn.IFERROR(N9/N6*100,"") -> 14.511275 | Q9: =_xlfn.IFERROR(O9/O6*100,"") -> 13.573976 | T9: =_xlfn.IFERROR(R9/R6*100,"") | U9: =_xlfn.IFERROR(S9/S6*100,"")
C10: 常三线 | D10: 0 | E10: =_xlfn.IFERROR(取值!A77+D10,"") -> 0 | F10: =_xlfn.IFERROR(D10/D6*100,"") -> 0 | G10: =_xlfn.IFERROR(E10/E6*100,"") -> 0 | J10: =_xlfn.IFERROR(H10/H6*100,"") | K10: =_xlfn.IFERROR(I10/I6*100,"") | M10: 饱和液化气 | N10: 4516 | O10: =_xlfn.IFERROR(取值!A117+N10,"") -> 47162 | P10: =_xlfn.IFERROR(N10/N6*100,"") -> 4.7855205 | Q10: =_xlfn.IFERROR(O10/O6*100,"") -> 4.7053072 | T10: =_xlfn.IFERROR(R10/R6*100,"") | U10: =_xlfn.IFERROR(S10/S6*100,"")
C11: 混柴 | D11: 102803 | E11: =_xlfn.IFERROR(取值!A78+D11,"") -> 1099979 | F11: =_xlfn.IFERROR(D11/D6*100,"") -> 27.123156 | G11: =_xlfn.IFERROR(E11/E6*100,"") -> 27.691411 | J11: =_xlfn.IFERROR(H11/H6*100,"") | K11: =_xlfn.IFERROR(I11/I6*100,"") | M11: 二甲苯 | N11: 14133 | O11: =_xlfn.IFERROR(取值!A118+N11,"") -> 95326 | P11: =_xlfn.IFERROR(N11/N6*100,"") -> 14.976475 | Q11: =_xlfn.IFERROR(O11/O6*100,"") -> 9.510583 | T11: =_xlfn.IFERROR(R11/R6*100,"") | U11: =_xlfn.IFERROR(S11/S6*100,"")
C12: 饱和液化气 | D12: 2661 | E12: =_xlfn.IFERROR(取值!A79+D12,"") -> 44852 | F12: =_xlfn.IFERROR(D12/D6*100,"") -> 0.70206821 | G12: =_xlfn.IFERROR(E12/E6*100,"") -> 1.1291263 | J12: =_xlfn.IFERROR(H12/H6*100,"") | K12: =_xlfn.IFERROR(I12/I6*100,"") | M12: 燃 料 气 | N12: 5675 | O12: =_xlfn.IFERROR(取值!A119+N12,"") -> 63128 | P12: =_xlfn.IFERROR(N12/N6*100,"") -> 6.0136911 | Q12: =_xlfn.IFERROR(O12/O6*100,"") -> 6.2982196 | T12: =_xlfn.IFERROR(R12/R6*100,"") | U12: =_xlfn.IFERROR(S12/S6*100,"")
C13: 渣油 | D13: 192035 | E13: =_xlfn.IFERROR(取值!A80+D13,"") -> 2017109 | F13: =_xlfn.IFERROR(D13/D6*100,"") -> 50.665791 | G13: =_xlfn.IFERROR(E13/E6*100,"") -> 50.779692 | J13: =_xlfn.IFERROR(H13/H6*100,"") | K13: =_xlfn.IFERROR(I13/I6*100,"") | M13: 精制石脑油 | O13: =_xlfn.IFERROR(取值!A120+N13,"") -> 0
C14: 压缩富气 | D14: 187 | E14: =_xlfn.IFERROR(取值!A81+D14,"") -> 6674 | F14: =_xlfn.IFERROR(D14/D6*100,"") -> 0.049337375 | G14: =_xlfn.IFERROR(E14/E6*100,"") -> 0.16801455 | J14: =_xlfn.IFERROR(H14/H6*100,"") | K14: =_xlfn.IFERROR(I14/I6*100,"") | M14: 加工损失 | N14: =_xlfn.IFERROR(N6-N7-N8-N9-N10-N11-N12-N13,"") -> 553 | O14: =_xlfn.IFERROR(取值!A155+N14,"") -> 4646 | P14: =_xlfn.IFERROR(100-P7-P8-P9-P10-P11-P12-P13,"") -> 0.58600373 | Q14: =_xlfn.IFERROR(100-Q7-Q8-Q9-Q10-Q11-Q12-Q13,"") -> 0.46352694 | R14: =_xlfn.IFERROR(R6-R7-R8-R9-R10-R11-R12-R13,"") -> 0 | S14: =_xlfn.IFERROR(S6-S7-S8-S9-S10-S11-S12-S13,"") -> 0 | T14: =_xlfn.IFERROR(100-T7-T8-T9-T10-T11-T12-T13,"") | U14: =_xlfn.IFERROR(100-U7-U8-U9-U10-U11-U12-U13,"")
C15: 加工损失 | D15: =_xlfn.IFERROR(D6-D7-D8-D9-D10-D11-D12-D13-D14,"") -> 3763 | E15: =_xlfn.IFERROR(取值!A143+D15,"") -> 28691 | F15: =_xlfn.IFERROR(100-F7-F8-F9-F10-F11-F12-F13-F14,"") -> 0.99281574 | G15: =_xlfn.IFERROR(100-G7-G8-G9-G10-G11-G12-G13-G14,"") -> 0.72228131 | H15: =_xlfn.IFERROR(H6-H7-H8-H9-H10-H11-H12-H13,"") -> 0 | I15: =_xlfn.IFERROR(I6-I7-I8-I9-I10-I11-I12-I13,"") -> 0 | J15: =_xlfn.IFERROR(100-J7-J8-J9-J10-J11-J12-J13-J14,"") | K15: =_xlfn.IFERROR(100-K7-K8-K9-K10-K11-K12-K13-K14,"")
B16: 60万 吨 催 化 装 置 | C16: 催化加工 | D16: 0 | E16: =_xlfn.IFERROR(取值!A83+D16,"") -> 249205
C17: 催化汽油 | D17: 0 | E17: =_xlfn.IFERROR(取值!A84+D17,"") -> 116064 | F17: =_xlfn.IFERROR(D17/D16*100,"") | G17: =_xlfn.IFERROR(E17/E16*100,"") -> 46.573704 | J17: =_xlfn.IFERROR(H17/H16*100,"") | K17: =_xlfn.IFERROR(I17/I16*100,"") | L17: 20万 吨 苯 抽 提 装 置 | M17: 处理量 | N17: 13559 | O17: =_xlfn.IFERROR(取值!A122+N17,"") -> 132304
C18: 催化柴油 | D18: 0 | E18: =_xlfn.IFERROR(取值!A85+D18,"") -> 55392 | F18: =_xlfn.IFERROR(D18/D16*100,"") | G18: =_xlfn.IFERROR(E18/E16*100,"") -> 22.227483 | J18: =_xlfn.IFERROR(H18/H16*100,"") | K18: =_xlfn.IFERROR(I18/I16*100,"") | M18: 非芳烃 | N18: 8306 | O18: =_xlfn.IFERROR(取值!A123+N18,"") -> 80598 | P18: =_xlfn.IFERROR(N18/N17*100,"") -> 61.258205 | Q18: =_xlfn.IFERROR(O18/O17*100,"") -> 60.918793 | T18: =_xlfn.IFERROR(R18/R17*100,"") | U18: =_xlfn.IFERROR(S18/S17*100,"")
C19: 原料液化气 | D19: 0 | E19: =_xlfn.IFERROR(取值!A86+D19,"") -> 34449 | F19: =_xlfn.IFERROR(D19/D16*100,"") | G19: =_xlfn.IFERROR(E19/E16*100,"") -> 13.823559 | J19: =_xlfn.IFERROR(H19/H16*100,"") | K19: =_xlfn.IFERROR(I19/I16*100,"") | M19: 苯 | N19: 4064 | O19: =_xlfn.IFERROR(取值!A124+N19,"") -> 41528 | P19: =_xlfn.IFERROR(N19/N17*100,"") -> 29.972712 | Q19: =_xlfn.IFERROR(O19/O17*100,"") -> 31.388318 | T19: =_xlfn.IFERROR(R19/R17*100,"") | U19: =_xlfn.IFERROR(S19/S17*100,"")
C20: 2#渣油 | D20: 0 | E20: =_xlfn.IFERROR(取值!A87+D20,"") -> 6399 | F20: =_xlfn.IFERROR(D20/D16*100,"") | G20: =_xlfn.IFERROR(E20/E16*100,"") -> 2.5677655 | J20: =_xlfn.IFERROR(H20/H16*100,"") | K20: =_xlfn.IFERROR(I20/I16*100,"") | M20: 燃料气 | N20: 1117 | O20: =_xlfn.IFERROR(取值!A125+N20,"") -> 9622 | P20: =_xlfn.IFERROR(N20/N17*100,"") -> 8.2380707 | Q20: =_xlfn.IFERROR(O20/O17*100,"") -> 7.2726448 | T20: =_xlfn.IFERROR(R20/R17*100,"") | U20: =_xlfn.IFERROR(S20/S17*100,"")
C21: 干 气 | D21: 0 | E21: =_xlfn.IFERROR(取值!A88+D21,"") -> 7620 | F21: =_xlfn.IFERROR(D21/D16*100,"") | G21: =_xlfn.IFERROR(E21/E16*100,"") -> 3.0577236 | J21: =_xlfn.IFERROR(H21/H16*100,"") | K21: =_xlfn.IFERROR(I21/I16*100,"") | M21: 加工损失 | N21: =_xlfn.IFERROR(N17-N18-N19-N20,"") -> 72 | O21: =_xlfn.IFERROR(取值!A158+N21,"") -> 556 | P21: =_xlfn.IFERROR(100-P18-P19-P20,"") -> 0.53101261 | Q21: =_xlfn.IFERROR(100-Q18-Q19-Q20,"") -> 0.42024429 | R21: =_xlfn.IFERROR(R17-R18-R19-R20,"") -> 0 | S21: =_xlfn.IFERROR(S17-S18-S19-S20,"") -> 0 | T21: =_xlfn.IFERROR(100-T18-T19-T20,"") | U21: =_xlfn.IFERROR(100-U18-U19-U20,"")
C22: 生焦量 | D22: 0 | E22: =_xlfn.IFERROR(取值!A89+D22,"") -> 28156 | F22: =_xlfn.IFERROR(D22/D16*100,"") | G22: =_xlfn.IFERROR(E22/E16*100,"") -> 11.298329 | J22: =_xlfn.IFERROR(H22/H16*100,"") | K22: =_xlfn.IFERROR(I22/I16*100,"") | L22: 20万 DCC石脑油装置 | M22: 裂解石脑油 | N22: 0 | O22: =_xlfn.IFERROR(取值!A127+N22,"") -> 0
C23: 加工损失 | D23: =_xlfn.IFERROR(D16-D17-D18-D19-D20-D21-D22,"") -> 0 | E23: =_xlfn.IFERROR(取值!A146+D23,"") -> 1125 | F23: =_xlfn.IFERROR(100-F17-F18-F19-F20-F21-F22,"") | G23: =_xlfn.IFERROR(100-G17-G18-G19-G20-G21-G22,"") -> 0.45143557 | H23: =_xlfn.IFERROR(H16-H17-H18-H19-H20-H21-H22,"") -> 0 | I23: =_xlfn.IFERROR(I16-I17-I18-I19-I20-I21-I22,"") -> 0 | J23: =_xlfn.IFERROR(100-J17-J18-J19-J20-J21-J22,"") | K23: =_xlfn.IFERROR(100-K17-K18-K19-K20-K21-K22,"") | M23: 氢气处理量 | N23: 0 | O23: =_xlfn.IFERROR(取值!A128+N23,"") -> 0
B24: 180万 吨 催 化 装 置 | C24: 催化加工 | D24: 129635 | E24: =_xlfn.IFERROR(取值!A91+D24,"") -> 1471946 | M24: 脱戊烷油 | N24: 0 | O24: =_xlfn.IFERROR(取值!A129+N24,"") -> 0 | P24: =_xlfn.IFERROR(N24/(N22+N23)*100,"") | Q24: =_xlfn.IFERROR(O24/(O22+O23)*100,"") | T24: =_xlfn.IFERROR(S24/(S22+S23)*100,"") | U24: =_xlfn.IFERROR(S24/(S22+S23)*100,"")
C25: 催化汽油 | D25: 69784 | E25: =_xlfn.IFERROR(取值!A92+D25,"") -> 725290 | F25: =_xlfn.IFERROR(D25/D24*100,"") -> 53.831141 | G25: =_xlfn.IFERROR(E25/E24*100,"") -> 49.274226 | J25: =_xlfn.IFERROR(H25/H24*100,"") | K25: =_xlfn.IFERROR(I25/I24*100,"") | M25: C5 | N25: 0 | O25: =_xlfn.IFERROR(取值!A130+N25,"") -> 0 | P25: =_xlfn.IFERROR(N25/(N23+N22)*100,"") | Q25: =_xlfn.IFERROR(O25/(O22+O23)*100,"") | T25: =_xlfn.IFERROR(S25/(S23+S22)*100,"") | U25: =_xlfn.IFERROR(S25/(S22+S23)*100,"")
C26: 催化柴油 | D26: 24870 | E26: =_xlfn.IFERROR(取值!A93+D26,"") -> 334125 | F26: =_xlfn.IFERROR(D26/D24*100,"") -> 19.184634 | G26: =_xlfn.IFERROR(E26/E24*100,"") -> 22.699542 | J26: =_xlfn.IFERROR(H26/H24*100,"") | K26: =_xlfn.IFERROR(I26/I24*100,"") | M26: 气体产量 | N26: 0 | O26: =_xlfn.IFERROR(取值!A131+N26,"") -> 0 | P26: =_xlfn.IFERROR(N26/(N23+N22)*100,"") | Q26: =_xlfn.IFERROR(O26/(O22+O23)*100,"") | T26: =_xlfn.IFERROR(S26/(S22+S23)*100,"") | U26: =_xlfn.IFERROR(S26/(S22+S23)*100,"")
C27: 原料液化气 | D27: 16092 | E27: =_xlfn.IFERROR(取值!A94+D27,"") -> 192327 | F27: =_xlfn.IFERROR(D27/D24*100,"") -> 12.413314 | G27: =_xlfn.IFERROR(E27/E24*100,"") -> 13.066172 | J27: =_xlfn.IFERROR(H27/H24*100,"") | K27: =_xlfn.IFERROR(I27/I24*100,"") | M27: 加工损失 | N27: =_xlfn.IFERROR(N22+N23-N24-N25-N26,"") -> 0 | O27: =_xlfn.IFERROR(取值!A161+N27,"") -> 0 | P27: =_xlfn.IFERROR(100-P24-P25-P26,"") | Q27: =_xlfn.IFERROR(100-Q24-Q25-Q26,"") | R27: =_xlfn.IFERROR(R22+R23-R24-R25-R26,"") -> 0 | S27: =_xlfn.IFERROR(S22+S23-S24-S25-S26,"") -> 0 | T27: =_xlfn.IFERROR(100-T24-T25-T26,"") | U27: =_xlfn.IFERROR(100-U24-U25-U26,"")
C28: 2#渣油 | D28: 3972 | E28: =_xlfn.IFERROR(取值!A95+D28,"") -> 48950 | F28: =_xlfn.IFERROR(D28/D24*100,"") -> 3.0639873 | G28: =_xlfn.IFERROR(E28/E24*100,"") -> 3.3255296 | J28: =_xlfn.IFERROR(H28/H24*100,"") | K28: =_xlfn.IFERROR(I28/I24*100,"") | L28: 30万吨/年航煤装置 | M28: 处理量 | N28: 29173 | O28: =_xlfn.IFERROR(取值!A133+N28,"") -> 281248
C29: 干 气 | D29: 3024 | E29: =_xlfn.IFERROR(取值!A96+D29,"") -> 34330 | F29: =_xlfn.IFERROR(D29/D24*100,"") -> 2.3327034 | G29: =_xlfn.IFERROR(E29/E24*100,"") -> 2.3322866 | J29: =_xlfn.IFERROR(H29/H24*100,"") | K29: =_xlfn.IFERROR(I29/I24*100,"") | M29: 氢气处理量 | N29: 62 | O29: =_xlfn.IFERROR(取值!A134+N29,"") -> 630
C30: 生焦量 | D30: 10911 | E30: =_xlfn.IFERROR(取值!A97+D30,"") -> 129776 | F30: =_xlfn.IFERROR(D30/D24*100,"") -> 8.4167085 | G30: =_xlfn.IFERROR(E30/E24*100,"") -> 8.8166278 | J30: =_xlfn.IFERROR(H30/H24*100,"") | K30: =_xlfn.IFERROR(I30/I24*100,"") | M30: 3#喷气燃料 | N30: 28268 | O30: =_xlfn.IFERROR(取值!A135+N30,"") -> 272723 | P30: =_xlfn.IFERROR(N30/(N28+N29)*100,"") -> 96.692321 | Q30: =_xlfn.IFERROR(O30/(O28+O29)*100,"") -> 96.752141 | T30: =_xlfn.IFERROR(R30/(R28+R29)*100,"") | U30: =_xlfn.IFERROR(S30/(S28+S29)*100,"")
C31: 加工损失 | D31: =_xlfn.IFERROR(D24-D25-D26-D27-D28-D29-D30,"") -> 982 | E31: =_xlfn.IFERROR(取值!A140+D31,"") -> 7148 | F31: =_xlfn.IFERROR(100-F25-F26-F27-F28-F29-F30,"") -> 0.75751147 | G31: =_xlfn.IFERROR(100-G25-G26-G27-G28-G29-G30,"") -> 0.48561564 | H31: =_xlfn.IFERROR(H24-H25-H26-H27-H28-H29-H30,"") -> 0 | I31: =_xlfn.IFERROR(I24-I25-I26-I27-I28-I29-I30,"") -> 0 | J31: =_xlfn.IFERROR(100-J25-J26-J27-J28-J29-J30,"") | K31: =_xlfn.IFERROR(100-K25-K26-K27-K28-K29-K30,"") | M31: 航煤石脑油Ⅱ | N31: 575 | O31: =_xlfn.IFERROR(取值!A136+N31,"") -> 4382 | P31: =_xlfn.IFERROR(N31/(N29+N28)*100,"") -> 1.9668206 | Q31: =_xlfn.IFERROR(O31/(O28+O68)*100,"") -> 1.5580555 | T31: =_xlfn.IFERROR(R31/(R28+R29)*100,"") | U31: =_xlfn.IFERROR(S31/(S28+S29)*100,"")
B32: 200万 柴 油 加 氢 装 置 | C32: 混合柴油处理量 | D32: 172170 | E32: =_xlfn.IFERROR(取值!A99+D32,"") -> 1899817 | M32: 气体产量 | N32: 123 | O32: =_xlfn.IFERROR(取值!A137+N32,"") -> 2255 | P32: =_xlfn.IFERROR(N32/(N28+N29)*100,"") -> 0.42072858 | Q32: =_xlfn.IFERROR(O32/(O28+O29)*100,"") -> 0.79999149 | T32: =_xlfn.IFERROR(R32/(R28+R29)*100,"") | U32: =_xlfn.IFERROR(S32/(S28+S29)*100,"")
C33: 氢气处理量 | D33: 1314 | E33: =_xlfn.IFERROR(取值!A100+D33,"") -> 10633 | M33: 加工损失 | N33: =_xlfn.IFERROR(N28+N29-N30-N31-N32,"") -> 269 | O33: =_xlfn.IFERROR(取值!A164+N33,"") -> 2518 | P33: =_xlfn.IFERROR(100-P32-P31-P30,"") -> 0.92012998 | Q33: =_xlfn.IFERROR(100-Q32-Q31-Q30,"") -> 0.88981199 | R33: =_xlfn.IFERROR(R28+R29-R30-R31-R32,"") -> 0 | S33: =_xlfn.IFERROR(S28+S29-S30-S31-S32,"") -> 0 | T33: =_xlfn.IFERROR(R33/(R28+R29)*100,"") | U33: =_xlfn.IFERROR(S33/(S28+S29)*100,"")
C34: 精制柴油 | D34: 142188 | E34: =_xlfn.IFERROR(取值!A101+D34,"") -> 1674381 | F34: =_xlfn.IFERROR(D34/(D32+D33)*100,"") -> 81.960296 | G34: =_xlfn.IFERROR(E34/(E32+E33)*100,"") -> 87.643278 | J34: =_xlfn.IFERROR(H34/(H32+H33)*100,"") | K34: =_xlfn.IFERROR(I34/(I32+I33)*100,"") | L34: 220万吨常压装置 | M34: 原油 | N34: 122294 | O34: =_xlfn.IFERROR(取值!A184+N34,"") -> 1082894
C35: 石脑油Ⅰ | D35: 22862 | E35: =_xlfn.IFERROR(取值!A102+D35,"") -> 153080 | F35: =_xlfn.IFERROR(D35/(D33+D32)*100,"") -> 13.178161 | G35: =_xlfn.IFERROR(E35/(E33+E32)*100,"") -> 8.0127719 | J35: =_xlfn.IFERROR(H35/(H33+H32)*100,"") | K35: =_xlfn.IFERROR(I35/(I33+I32)*100,"") | M35: 石脑油 | N35: 29947 | O35: =_xlfn.IFERROR(取值!A185+N35,"") -> 272429 | P35: =_xlfn.IFERROR(N35/N34*100,"") -> 24.48771 | Q35: =_xlfn.IFERROR(O35/O34*100,"") -> 25.157495
C36: 原料液化气 | D36: 0 | E36: =_xlfn.IFERROR(取值!A103+D36,"") -> 0 | F36: =_xlfn.IFERROR(D36/(D32+D33)*100,"") -> 0 | G36: =_xlfn.IFERROR(E36/(E32+E33)*100,"") -> 0 | J36: =_xlfn.IFERROR(H36/(H32+H33)*100,"") | K36: =_xlfn.IFERROR(I36/(I32+I33)*100,"") | M36: 柴油 | N36: 50168 | O36: =_xlfn.IFERROR(取值!A186+N36,"") -> 426627 | P36: =_xlfn.IFERROR(N36/N34*100,"") -> 41.022454 | Q36: =_xlfn.IFERROR(O36/O34*100,"") -> 39.396931
C37: 加氢粗气油 | D37: 7258 | E37: =_xlfn.IFERROR(取值!A104+D37,"") -> 68318 | F37: =_xlfn.IFERROR(D37/(D32+D33)*100,"") -> 4.1836711 | G37: =_xlfn.IFERROR(E37/(E32+E33)*100,"") -> 3.5760161 | J37: =_xlfn.IFERROR(H37/(H32+H33)*100,"") | K37: =_xlfn.IFERROR(I37/(I32+I33)*100,"") | M37: 常压渣油 | N37: 41240 | O37: =_xlfn.IFERROR(取值!A187+N37,"") -> 376812 | P37: =_xlfn.IFERROR(N37/N34*100,"") -> 33.722014 | Q37: =_xlfn.IFERROR(O37/O34*100,"") -> 34.796758
C38: 燃料气 | D38: 255 | E38: =_xlfn.IFERROR(取值!A105+D38,"") -> 6471 | F38: =_xlfn.IFERROR(D38/(D33+D32)*100,"") -> 0.14698762 | G38: =_xlfn.IFERROR(E38/(E33+E32)*100,"") -> 0.33871601 | J38: =_xlfn.IFERROR(H38/(H33+H32)*100,"") | K38: =_xlfn.IFERROR(I38/(I33+I32)*100,"") | M38: 腊油 | N38: 0 | O38: =_xlfn.IFERROR(取值!A188+N38,"") -> 0 | P38: =_xlfn.IFERROR(N38/N34*100,"") -> 0 | Q38: =_xlfn.IFERROR(O38/O34*100,"") -> 0
C39: 加工损失 | D39: =_xlfn.IFERROR(D32+D33-D34-D35-D36-D37-D38,"") -> 921 | E39: =_xlfn.IFERROR(取值!A149+D39,"") -> 8200 | F39: =_xlfn.IFERROR(100-F34-F35-F36-F37-F38,"") -> 0.53088469 | G39: =_xlfn.IFERROR(100-G34-G35-G36-G37-G38,"") -> 0.42921825 | H39: =_xlfn.IFERROR(H32+H33-H34-H35-H36-H37-H38,"") -> 0 | I39: =_xlfn.IFERROR(I32+I33-I34-I35-I36-I37-I38,"") -> 0 | J39: =_xlfn.IFERROR(100-J34-J35-J36-J37-J38,"") | K39: =_xlfn.IFERROR(100-K34-K35-K36-K37-K38,"") | M39: 减二线油 | N39: 0 | O39: =_xlfn.IFERROR(取值!A189+N39,"") -> 0 | P39: =_xlfn.IFERROR(N39/N34*100,"") -> 0 | Q39: =_xlfn.IFERROR(O39/O34*100,"") -> 0
B40: 90万吨汽油精制 | C40: 催化汽油 | D40: 70525 | E40: =_xlfn.IFERROR(取值!A107+D40,"") -> 840052 | M40: 减压渣油 | N40: 0 | O40: =_xlfn.IFERROR(取值!A190+N40,"") -> 0 | P40: =_xlfn.IFERROR(N40/N34*100,"") -> 0 | Q40: =_xlfn.IFERROR(O40/O34*100,"") -> 0
C41: 氢气 | D41: 0 | E41: =_xlfn.IFERROR(取值!A108+D41,"") -> 0 | M41: 燃料气 | N41: 235 | O41: =_xlfn.IFERROR(取值!A191+N41,"") -> 1716 | P41: =_xlfn.IFERROR(N41/N34*100,"") -> 0.19215988 | Q41: =_xlfn.IFERROR(O41/O34*100,"") -> 0.15846426
...

Sheet 公式
A1: 公式类型 | C1: 数据源 | E1: 取值 | G1: 计量点名称 | I1: 取值条件
A2: 产量部分
A3: 500万常压
A4: #SQL | B4: (" | C4: Yul_PM_ALL_ByMonth | D4: "," | E4: VALUE | F4: ",":where{NAME= | G4: 榆炼_生产_联合一车间_500万吨/年常压装置_进_原油 | H4: }") | I4: =A4&B4&C4&D4&E4&F4&G4&H4 -> #SQL("Yul_PM_ALL_ByMonth","VALUE",":where{NAME=榆炼_生产_联合一车间_500万吨/年常压装置_进_原油}")
A5: #SQL | B5: (" | C5: Yul_PM_ALL_ByMonth | D5: "," | E5: VALUE | F5: ",":where{NAME= | G5: 榆炼_生产_联合一车间_500万吨/年常压装置_出_石脑油（常压） | H5: }") | I5: =A5&B5&C5&D5&E5&F5&G5&H5 -> #SQL("Yul_PM_ALL_ByMonth","VALUE",":where{NAME=榆炼_生产_联合一车间_500万吨/年常压装置_出_石脑油（常压）}")
A6: #SQL | B6: (" | C6: Yul_PM_ALL_ByMonth | D6: "," | E6: VALUE | F6: ",":where{NAME= | G6: 榆炼_生产_联合一车间_500万吨/年常压装置_出_终止剂 | H6: }") | I6: =A6&B6&C6&D6&E6&F6&G6&H6 -> #SQL("Yul_PM_ALL_ByMonth","VALUE",":where{NAME=榆炼_生产_联合一车间_500万吨/年常压装置_出_终止剂}")
A7: #SQL | B7: (" | C7: Yul_PM_ALL_ByMonth | D7: "," | E7: VALUE | F7: ",":where{NAME= | G7: 榆炼_生产_联合一车间_500万吨/年常压装置_出_常三线柴油 | H7: }") | I7: =A7&B7&C7&D7&E7&F7&G7&H7 -> #SQL("Yul_PM_ALL_ByMonth","VALUE",":where{NAME=榆炼_生产_联合一车间_500万吨/年常压装置_出_常三线柴油}")
A8: #SQL | B8: (" | C8: Yul_PM_ALL_ByMonth | D8: "," | E8: VALUE | F8: ",":where{NAME= | G8: 榆炼_生产_联合一车间_500万吨/年常压装置_出_混合柴油 | H8: }") | I8: =A8&B8&C8&D8&E8&F8&G8&H8 -> #SQL("Yul_PM_ALL_ByMonth","VALUE",":where{NAME=榆炼_生产_联合一车间_500万吨/年常压装置_出_混合柴油}")
A9: #SQL | B9: (" | C9: Yul_PM_ALL_ByMonth | D9: "," | E9: VALUE | F9: ",":where{NAME= | G9: 榆炼_生产_联合一车间_500万吨/年常压装置_出_常三线单出产量 | H9: }") | I9: =A9&B9&C9&D9&E9&F9&G9&H9 -> #SQL("Yul_PM_ALL_ByMonth","VALUE",":where{NAME=榆炼_生产_联合一车间_500万吨/年常压装置_出_常三线单出产量}")
A10: #SQL | B10: (" | C10: Yul_PM_ALL_ByMonth | D10: "," | E10: VALUE | F10: ",":where{NAME= | G10: 榆炼_生产_联合一车间_500万吨/年常压装置_出_饱和液化气 | H10: }") | I10: =A10&B10&C10&D10&E10&F10&G10&H10 -> #SQL("Yul_PM_ALL_ByMonth","VALUE",":where{NAME=榆炼_生产_联合一车间_500万吨/年常压装置_出_饱和液化气}")
A11: #SQL | B11: (" | C11: Yul_PM_ALL_ByMonth | D11: "," | E11: VALUE | F11: ",":where{NAME= | G11: 榆炼_生产_联合一车间_500万吨/年常压装置_出_1#渣油 （常压） | H11: }") | I11: =A11&B11&C11&D11&E11&F11&G11&H11 -> #SQL("Yul_PM_ALL_ByMonth","VALUE",":where{NAME=榆炼_生产_联合一车间_500万吨/年常压装置_出_1#渣油 （常压）}")
A12: #SQL | B12: (" | C12: Yul_PM_ALL_ByMonth | D12: "," | E12: VALUE | F12: ",":where{NAME= | G12: 榆炼_生产_联合一车间_500万吨/年常压装置_出_压缩富气 | H12: }") | I12: =A12&B12&C12&D12&E12&F12&G12&H12 -> #SQL("Yul_PM_ALL_ByMonth","VALUE",":where{NAME=榆炼_生产_联合一车间_500万吨/年常压装置_出_压缩富气}")
A13: 60万催化
A14: #SQL | B14: (" | C14: Yul_PM_ALL_ByMonth | D14: "," | E14: VALUE | F14: ",":where{NAME= | G14: 榆炼_生产_联合二车间_60万吨/年催化装置_进_渣油 | H14: }") | I14: =A14&B14&C14&D14&E14&F14&G14&H14 -> #SQL("Yul_PM_ALL_ByMonth","VALUE",":where{NAME=榆炼_生产_联合二车间_60万吨/年催化装置_进_渣油}")
A15: #SQL | B15: (" | C15: Yul_PM_ALL_ByMonth | D15: "," | E15: VALUE | F15: ",":where{NAME= | G15: 榆炼_生产_联合二车间_60万吨/年催化装置_出_汽油 | H15: }") | I15: =A15&B15&C15&D15&E15&F15&G15&H15 -> #SQL("Yul_PM_ALL_ByMonth","VALUE",":where{NAME=榆炼_生产_联合二车间_60万吨/年催化装置_出_汽油}")
A16: #SQL | B16: (" | C16: Yul_PM_ALL_ByMonth | D16: "," | E16: VALUE | F16: ",":where{NAME= | G16: 榆炼_生产_联合二车间_60万吨/年催化装置_出_柴油 | H16: }") | I16: =A16&B16&C16&D16&E16&F16&G16&H16 -> #SQL("Yul_PM_ALL_ByMonth","VALUE",":where{NAME=榆炼_生产_联合二车间_60万吨/年催化装置_出_柴油}")
A17: #SQL | B17: (" | C17: Yul_PM_ALL_ByMonth | D17: "," | E17: VALUE | F17: ",":where{NAME= | G17: 榆炼_生产_联合二车间_60万吨/年催化装置_出_液化气 | H17: }") | I17: =A17&B17&C17&D17&E17&F17&G17&H17 -> #SQL("Yul_PM_ALL_ByMonth","VALUE",":where{NAME=榆炼_生产_联合二车间_60万吨/年催化装置_出_液化气}")
A18: #SQL | B18: (" | C18: Yul_PM_ALL_ByMonth | D18: "," | E18: VALUE | F18: ",":where{NAME= | G18: 榆炼_生产_联合二车间_60万吨/年催化装置_出_油浆 | H18: }") | I18: =A18&B18&C18&D18&E18&F18&G18&H18 -> #SQL("Yul_PM_ALL_ByMonth","VALUE",":where{NAME=榆炼_生产_联合二车间_60万吨/年催化装置_出_油浆}")
A19: #SQL | B19: (" | C19: Yul_PM_ALL_ByMonth | D19: "," | E19: VALUE | F19: ",":where{NAME= | G19: 榆炼_生产_联合二车间_60万吨/年催化装置_出_干气 | H19: }") | I19: =A19&B19&C19&D19&E19&F19&G19&H19 -> #SQL("Yul_PM_ALL_ByMonth","VALUE",":where{NAME=榆炼_生产_联合二车间_60万吨/年催化装置_出_干气}")
A20: #SQL | B20: (" | C20: Yul_PM_ALL_ByMonth | D20: "," | E20: VALUE | F20: ",":where{NAME= | G20: 榆炼_生产_联合二车间_60万吨/年催化装置_出_生焦 | H20: }") | I20: =A20&B20&C20&D20&E20&F20&G20&H20 -> #SQL("Yul_PM_ALL_ByMonth","VALUE",":where{NAME=榆炼_生产_联合二车间_60万吨/年催化装置_出_生焦}")
A21: #SQL | B21: (" | C21: Yul_PM_ALL_ByMonth | D21: "," | E21: VALUE | F21: ",":where{NAME= | H21: }") | I21: =A21&B21&C21&D21&E21&F21&G21&H21 -> #SQL("Yul_PM_ALL_ByMonth","VALUE",":where{NAME=}")
A22: 180催化
A23: #SQL | B23: (" | C23: Yul_PM_ALL_ByMonth | D23: "," | E23: VALUE | F23: ",":where{NAME= | G23: 榆炼_生产_联合二车间_180万吨/年催化装置_进_常压渣油 | H23: }") | I23: =A23&B23&C23&D23&E23&F23&G23&H23 -> #SQL("Yul_PM_ALL_ByMonth","VALUE",":where{NAME=榆炼_生产_联合二车间_180万吨/年催化装置_进_常压渣油}")
A24: #SQL | B24: (" | C24: Yul_PM_ALL_ByMonth | D24: "," | E24: VALUE | F24: ",":where{NAME= | G24: 榆炼_生产_联合二车间_180万吨/年催化装置_出_催化汽油 | H24: }") | I24: =A24&B24&C24&D24&E24&F24&G24&H24 -> #SQL("Yul_PM_ALL_ByMonth","VALUE",":where{NAME=榆炼_生产_联合二车间_180万吨/年催化装置_出_催化汽油}")
A25: #SQL | B25: (" | C25: Yul_PM_ALL_ByMonth | D25: "," | E25: VALUE | F25: ",":where{NAME= | G25: 榆炼_生产_联合二车间_180万吨/年催化装置_出_催化柴油 | H25: }") | I25: =A25&B25&C25&D25&E25&F25&G25&H25 -> #SQL("Yul_PM_ALL_ByMonth","VALUE",":where{NAME=榆炼_生产_联合二车间_180万吨/年催化装置_出_催化柴油}")
A26: #SQL | B26: (" | C26: Yul_PM_ALL_ByMonth | D26: "," | E26: VALUE | F26: ",":where{NAME= | G26: 榆炼_生产_联合二车间_180万吨/年催化装置_出_原料液化气 | H26: }") | I26: =A26&B26&C26&D26&E26&F26&G26&H26 -> #SQL("Yul_PM_ALL_ByMonth","VALUE",":where{NAME=榆炼_生产_联合二车间_180万吨/年催化装置_出_原料液化气}")
A27: #SQL | B27: (" | C27: Yul_PM_ALL_ByMonth | D27: "," | E27: VALUE | F27: ",":where{NAME= | G27: 榆炼_生产_联合二车间_180万吨/年催化装置_出_2#渣油(催化渣油、催化澄清油、油浆、罐区回炼油浆） | H27: }") | I27: =A27&B27&C27&D27&E27&F27&G27&H27 -> #SQL("Yul_PM_ALL_ByMonth","VALUE",":where{NAME=榆炼_生产_联合二车间_180万吨/年催化装置_出_2#渣油(催化渣油、催化澄清油、油浆、罐区回炼油浆）}")
A28: #SQL | B28: (" | C28: Yul_PM_ALL_ByMonth | D28: "," | E28: VALUE | F28: ",":where{NAME= | G28: 榆炼_生产_联合二车间_180万吨/年催化装置_出_干气 | H28: }") | I28: =A28&B28&C28&D28&E28&F28&G28&H28 -> #SQL("Yul_PM_ALL_ByMonth","VALUE",":where{NAME=榆炼_生产_联合二车间_180万吨/年催化装置_出_干气}")
A29: #SQL | B29: (" | C29: Yul_PM_ALL_ByMonth | D29: "," | E29: VALUE | F29: ",":where{NAME= | G29: 榆炼_生产_联合二车间_180万吨/年催化装置_出_生焦 | H29: }") | I29: =A29&B29&C29&D29&E29&F29&G29&H29 -> #SQL("Yul_PM_ALL_ByMonth","VALUE",":where{NAME=榆炼_生产_联合二车间_180万吨/年催化装置_出_生焦}")
A30: #SQL | B30: (" | C30: Yul_PM_ALL_ByMonth | D30: "," | E30: VALUE | F30: ",":where{NAME= | H30: }") | I30: =A30&B30&C30&D30&E30&F30&G30&H30 -> #SQL("Yul_PM_ALL_ByMonth","VALUE",":where{NAME=}")
A31: 200万柴油加氢
A32: #SQL | B32: (" | C32: Yul_PM_ALL_ByMonth | D32: "," | E32: VALUE | F32: ",":where{NAME= | G32: 榆炼_生产_联合四车间_200万吨/年柴油精制装置_进_加氢加工量 | H32: }") | I32: =A32&B32&C32&D32&E32&F32&G32&H32 -> #SQL("Yul_PM_ALL_ByMonth","VALUE",":where{NAME=榆炼_生产_联合四车间_200万吨/年柴油精制装置_进_加氢加工量}")
A33: #SQL | B33: (" | C33: Yul_PM_ALL_ByMonth | D33: "," | E33: VALUE | F33: ",":where{NAME= | G33: 榆炼_生产_联合四车间_200万吨/年柴油精制装置_进_氢气 | H33: }") | I33: =A33&B33&C33&D33&E33&F33&G33&H33 -> #SQL("Yul_PM_ALL_ByMonth","VALUE",":where{NAME=榆炼_生产_联合四车间_200万吨/年柴油精制装置_进_氢气}")
A34: #SQL | B34: (" | C34: Yul_PM_ALL_ByMonth | D34: "," | E34: VALUE | F34: ",":where{NAME= | G34: 榆炼_生产_联合四车间_200万吨/年柴油精制装置_出_精制柴油 | H34: }") | I34: =A34&B34&C34&D34&E34&F34&G34&H34 -> #SQL("Yul_PM_ALL_ByMonth","VALUE",":where{NAME=榆炼_生产_联合四车间_200万吨/年柴油精制装置_出_精制柴油}")
A35: #SQL | B35: (" | C35: Yul_PM_ALL_ByMonth | D35: "," | E35: VALUE | F35: ",":where{NAME= | G35: 榆炼_生产_联合四车间_200万吨/年柴油精制装置_出_石脑油Ⅱ (拨头油、重整轻汽油、轻石脑油、重整轻石脑油) | H35: }") | I35: =A35&B35&C35&D35&E35&F35&G35&H35 -> #SQL("Yul_PM_ALL_ByMonth","VALUE",":where{NAME=榆炼_生产_联合四车间_200万吨/年柴油精制装置_出_石脑油Ⅱ (拨头油、重整轻汽油、轻石脑油、重整轻石脑油)}")
A36: #SQL | B36: (" | C36: Yul_PM_ALL_ByMonth | D36: "," | E36: VALUE | F36: ",":where{NAME= | G36: 榆炼_生产_联合四车间_200万吨/年柴油精制装置_出_轻烃气 | H36: }") | I36: =A36&B36&C36&D36&E36&F36&G36&H36 -> #SQL("Yul_PM_ALL_ByMonth","VALUE",":where{NAME=榆炼_生产_联合四车间_200万吨/年柴油精制装置_出_轻烃气}")
A37: #SQL | B37: (" | C37: Yul_PM_ALL_ByMonth | D37: "," | E37: VALUE | F37: ",":where{NAME= | G37: 榆炼_生产_联合四车间_200万吨/年柴油精制装置_出_轻烃液 | H37: }") | I37: =A37&B37&C37&D37&E37&F37&G37&H37 -> #SQL("Yul_PM_ALL_ByMonth","VALUE",":where{NAME=榆炼_生产_联合四车间_200万吨/年柴油精制装置_出_轻烃液}")
A38: #SQL | B38: (" | C38: Yul_PM_ALL_ByMonth | D38: "," | E38: VALUE | F38: ",":where{NAME= | G38: 榆炼_生产_联合四车间_200万吨/年柴油精制装置_出_低分气 | H38: }") | I38: =A38&B38&C38&D38&E38&F38&G38&H38 -> #SQL("Yul_PM_ALL_ByMonth","VALUE",":where{NAME=榆炼_生产_联合四车间_200万吨/年柴油精制装置_出_低分气}")
A39: 90万汽油精制
A40: #SQL | B40: (" | C40: Yul_PM_ALL_ByMonth | D40: "," | E40: VALUE | F40: ",":where{NAME= | G40: 榆炼_生产_联合四车间_90万吨/年汽油加氢装置_进_催化汽油 | H40: }") | I40: =A40&B40&C40&D40&E40&F40&G40&H40 -> #SQL("Yul_PM_ALL_ByMonth","VALUE",":where{NAME=榆炼_生产_联合四车间_90万吨/年汽油加氢装置_进_催化汽油}")
...

Sheet 取值
A1: 产量部分 | N1: 0
A2: 500万常压 | N2: 0
A3: 379023 | N3: 0
A4: 48401
A5: 0
A6: 29173
A7: 102803
A8: 0
A9: 2661
A10: 192035
A11: 187
A12: 60万催化
A21: 180催化
A22: 129635
A23: 69784
A24: 24870
A25: 16092
A26: 3972
A27: 3024
A28: 10911
A30: 200万柴油加氢
A31: 172170
A32: 1314
A33: 142188
A34: 22862
A35: 0
A36: 7258
A37: 255
A38: 90万汽油精制
A39: 70525
A40: 0
A41: 61999
A42: 8072
A43: 153
A44: 100万连续重整
A45: 94368
A46: 51101 | M46: 0
A47: 4696
A48: 13694
A49: 4516
...

Sheet Sheet2
A1: 报表生成时间： | B1: 2025-12 | C1: 8:00:00
