Workbook

Sheet 调度工艺台账
B2: 调 度 工 艺 台 账
B3: 填报单位： | C3: 永坪炼油厂 | D3: 统计日期： | F3: 2026-01-06 | L3: =取值!N1&取值!O1&取值!P1 -> 报表生成时间：2026-01-07 8:00:00
B4: 装置 | C4: 参数 | D4: DCS位号 | E4: 0 | F4: 2 | G4: 4 | H4: 6 | I4: 8 | J4: 10 | K4: 12 | L4: 14 | M4: 16 | N4: 18 | O4: 20 | P4: 22
B5: 210万吨/年常压装置 | C5: 加热炉出口温度 | D5: TIC1010 | E5: =_xlfn.IFERROR(SUM(取值!E5),"") -> 367.3615 | F5: =_xlfn.IFERROR(SUM(取值!F5),"") -> 367.3615 | G5: =_xlfn.IFERROR(SUM(取值!G5),"") -> 367.3615 | H5: =_xlfn.IFERROR(SUM(取值!H5),"") -> 367.3615 | I5: =_xlfn.IFERROR(SUM(取值!I5),"") -> 367.3615 | J5: =_xlfn.IFERROR(SUM(取值!J5),"") -> 367.3615 | K5: =_xlfn.IFERROR(SUM(取值!K5),"") -> 367.3615 | L5: =_xlfn.IFERROR(SUM(取值!L5),"") -> 367.3615 | ... P5: =_xlfn.IFERROR(SUM(取值!P5),"") -> 364.6256
C6: 原油瞬时流量 | D6: FIQ1024 | E6: =_xlfn.IFERROR(SUM(取值!E6),"") -> 170.3692 | F6: =_xlfn.IFERROR(SUM(取值!F6),"") -> 170.3692 | G6: =_xlfn.IFERROR(SUM(取值!G6),"") -> 170.3692 | H6: =_xlfn.IFERROR(SUM(取值!H6),"") -> 170.3692 | I6: =_xlfn.IFERROR(SUM(取值!I6),"") -> 170.3692 | J6: =_xlfn.IFERROR(SUM(取值!J6),"") -> 170.3692 | K6: =_xlfn.IFERROR(SUM(取值!K6),"") -> 170.3692 | L6: =_xlfn.IFERROR(SUM(取值!L6),"") -> 170.3692 | ... P6: =_xlfn.IFERROR(SUM(取值!P6),"") -> 175.9752
B7: 250万吨/年常压装置 | C7: 加热炉出口温度 | D7: TRCA21123 | E7: =_xlfn.IFERROR(SUM(取值!E7),"") -> 362.366 | F7: =_xlfn.IFERROR(SUM(取值!F7),"") -> 365.0036 | G7: =_xlfn.IFERROR(SUM(取值!G7),"") -> 364.0148 | H7: =_xlfn.IFERROR(SUM(取值!H7),"") -> 364.0032 | I7: =_xlfn.IFERROR(SUM(取值!I7),"") -> 363.8995 | J7: =_xlfn.IFERROR(SUM(取值!J7),"") -> 356.3947 | K7: =_xlfn.IFERROR(SUM(取值!K7),"") -> 355.3049 | L7: =_xlfn.IFERROR(SUM(取值!L7),"") -> 364.0594 | ... P7: =_xlfn.IFERROR(SUM(取值!P7),"") -> 363.7659
C8: 原油瞬时流量 | D8: FRQ21101 | E8: =_xlfn.IFERROR(SUM(取值!E8),"") -> 210.2112 | F8: =_xlfn.IFERROR(SUM(取值!F8),"") -> 216.0037 | G8: =_xlfn.IFERROR(SUM(取值!G8),"") -> 207.1064 | H8: =_xlfn.IFERROR(SUM(取值!H8),"") -> 186.6396 | I8: =_xlfn.IFERROR(SUM(取值!I8),"") -> 206.3136 | J8: =_xlfn.IFERROR(SUM(取值!J8),"") -> 211.7121 | K8: =_xlfn.IFERROR(SUM(取值!K8),"") -> 213.4746 | L8: =_xlfn.IFERROR(SUM(取值!L8),"") -> 187.4312 | ... P8: =_xlfn.IFERROR(SUM(取值!P8),"") -> 202.6841
B9: 120万吨/年催化装置 | C9: 进料量 | D9: FRC11201A | E9: =_xlfn.IFERROR(SUM(取值!E9),"") -> 148.0433 | F9: =_xlfn.IFERROR(SUM(取值!F9),"") -> 148.9989 | G9: =_xlfn.IFERROR(SUM(取值!G9),"") -> 150.4255 | H9: =_xlfn.IFERROR(SUM(取值!H9),"") -> 148.5032 | I9: =_xlfn.IFERROR(SUM(取值!I9),"") -> 140.8297 | J9: =_xlfn.IFERROR(SUM(取值!J9),"") -> 143.4034 | K9: =_xlfn.IFERROR(SUM(取值!K9),"") -> 144.6214 | L9: =_xlfn.IFERROR(SUM(取值!L9),"") -> 146.8824 | ... P9: =_xlfn.IFERROR(SUM(取值!P9),"") -> 144.1833
C10: 进料量 | D10: FRC11201B | E10: =_xlfn.IFERROR(SUM(取值!E10),"") -> 147.9782 | F10: =_xlfn.IFERROR(SUM(取值!F10),"") -> 148.9989 | G10: =_xlfn.IFERROR(SUM(取值!G10),"") -> 149.9882 | H10: =_xlfn.IFERROR(SUM(取值!H10),"") -> 148.1376 | I10: =_xlfn.IFERROR(SUM(取值!I10),"") -> 140.5216 | J10: =_xlfn.IFERROR(SUM(取值!J10),"") -> 143.4034 | K10: =_xlfn.IFERROR(SUM(取值!K10),"") -> 144.6214 | L10: =_xlfn.IFERROR(SUM(取值!L10),"") -> 146.8824 | ... P10: =_xlfn.IFERROR(SUM(取值!P10),"") -> 143.8969
C11: 反应温度 | D11: TRCA11101 | E11: =_xlfn.IFERROR(SUM(取值!E11),"") -> 511.0833 | F11: =_xlfn.IFERROR(SUM(取值!F11),"") -> 508.165 | G11: =_xlfn.IFERROR(SUM(取值!G11),"") -> 508.1021 | H11: =_xlfn.IFERROR(SUM(取值!H11),"") -> 509.1055 | I11: =_xlfn.IFERROR(SUM(取值!I11),"") -> 508.7383 | J11: =_xlfn.IFERROR(SUM(取值!J11),"") -> 509.4075 | K11: =_xlfn.IFERROR(SUM(取值!K11),"") -> 510.95 | L11: =_xlfn.IFERROR(SUM(取值!L11),"") -> 510.8574 | ... P11: =_xlfn.IFERROR(SUM(取值!P11),"") -> 508.5659
C12: 床层温度 | D12: TRCA11102 | E12: =_xlfn.IFERROR(SUM(取值!E12),"") -> 669.0388 | F12: =_xlfn.IFERROR(SUM(取值!F12),"") -> 671.5338 | G12: =_xlfn.IFERROR(SUM(取值!G12),"") -> 671.593 | H12: =_xlfn.IFERROR(SUM(取值!H12),"") -> 673.1566 | I12: =_xlfn.IFERROR(SUM(取值!I12),"") -> 670.1186 | J12: =_xlfn.IFERROR(SUM(取值!J12),"") -> 670.2256 | K12: =_xlfn.IFERROR(SUM(取值!K12),"") -> 670.884 | L12: =_xlfn.IFERROR(SUM(取值!L12),"") -> 670.1187 | ... P12: =_xlfn.IFERROR(SUM(取值!P12),"") -> 672.0531
C13: 外取热产汽量 | D13: FR11802 | E13: =_xlfn.IFERROR(SUM(取值!E13),"") -> 78.02948 | F13: =_xlfn.IFERROR(SUM(取值!F13),"") -> 78.76244 | G13: =_xlfn.IFERROR(SUM(取值!G13),"") -> 77.74912 | H13: =_xlfn.IFERROR(SUM(取值!H13),"") -> 78.7143 | I13: =_xlfn.IFERROR(SUM(取值!I13),"") -> 78.00824 | J13: =_xlfn.IFERROR(SUM(取值!J13),"") -> 78.38966 | K13: =_xlfn.IFERROR(SUM(取值!K13),"") -> 79.66066 | L13: =_xlfn.IFERROR(SUM(取值!L13),"") -> 79.35944 | ... P13: =_xlfn.IFERROR(SUM(取值!P13),"") -> 79.70379
C14: 3.2MPa蒸汽压力 | D14: PIC11804A | E14: =_xlfn.IFERROR(SUM(取值!E14),"") -> 3.285997 | F14: =_xlfn.IFERROR(SUM(取值!F14),"") -> 3.273058 | G14: =_xlfn.IFERROR(SUM(取值!G14),"") -> 3.280875 | H14: =_xlfn.IFERROR(SUM(取值!H14),"") -> 3.273886 | I14: =_xlfn.IFERROR(SUM(取值!I14),"") -> 3.272886 | J14: =_xlfn.IFERROR(SUM(取值!J14),"") -> 3.281966 | K14: =_xlfn.IFERROR(SUM(取值!K14),"") -> 3.271701 | L14: =_xlfn.IFERROR(SUM(取值!L14),"") -> 3.286853 | ... P14: =_xlfn.IFERROR(SUM(取值!P14),"") -> 3.282131
C15: 1.0MPa蒸汽压力 | D15: PI11804B | E15: =_xlfn.IFERROR(SUM(取值!E15),"") -> 0.9096271 | F15: =_xlfn.IFERROR(SUM(取值!F15),"") -> 0.9232986 | G15: =_xlfn.IFERROR(SUM(取值!G15),"") -> 0.9033581 | H15: =_xlfn.IFERROR(SUM(取值!H15),"") -> 0.9112934 | I15: =_xlfn.IFERROR(SUM(取值!I15),"") -> 0.9006488 | J15: =_xlfn.IFERROR(SUM(取值!J15),"") -> 0.8649458 | K15: =_xlfn.IFERROR(SUM(取值!K15),"") -> 0.8940718 | L15: =_xlfn.IFERROR(SUM(取值!L15),"") -> 0.8641422 | ... P15: =_xlfn.IFERROR(SUM(取值!P15),"") -> 0.9255369
C16: 1.0MPa蒸汽放空开度 | D16: PIC11909 | E16: =_xlfn.IFERROR(SUM(取值!E16),"") -> 0 | F16: =_xlfn.IFERROR(SUM(取值!F16),"") -> 0 | G16: =_xlfn.IFERROR(SUM(取值!G16),"") -> 0 | H16: =_xlfn.IFERROR(SUM(取值!H16),"") -> 0 | I16: =_xlfn.IFERROR(SUM(取值!I16),"") -> 0 | J16: =_xlfn.IFERROR(SUM(取值!J16),"") -> 0 | K16: =_xlfn.IFERROR(SUM(取值!K16),"") -> 0 | L16: =_xlfn.IFERROR(SUM(取值!L16),"") -> 0 | ... P16: =_xlfn.IFERROR(SUM(取值!P16),"") -> 0
C17: 中压锅炉负荷 | D17: VH3101ABC | E17: =_xlfn.IFERROR(SUM(取值!E17),"") -> 35 | F17: =_xlfn.IFERROR(SUM(取值!F17),"") -> 35 | G17: =_xlfn.IFERROR(SUM(取值!G17),"") -> 35 | H17: =_xlfn.IFERROR(SUM(取值!H17),"") -> 35 | I17: =_xlfn.IFERROR(SUM(取值!I17),"") -> 35 | J17: =_xlfn.IFERROR(SUM(取值!J17),"") -> 35 | K17: =_xlfn.IFERROR(SUM(取值!K17),"") -> 35 | L17: =_xlfn.IFERROR(SUM(取值!L17),"") -> 35 | ... P17: =_xlfn.IFERROR(SUM(取值!P17),"") -> 35
C18: 中压锅炉产汽量 | D18: FRCQ11641 | E18: =_xlfn.IFERROR(SUM(取值!E18),"") -> 13.83241 | F18: =_xlfn.IFERROR(SUM(取值!F18),"") -> 15.29463 | G18: =_xlfn.IFERROR(SUM(取值!G18),"") -> 14.64806 | H18: =_xlfn.IFERROR(SUM(取值!H18),"") -> 15.11002 | I18: =_xlfn.IFERROR(SUM(取值!I18),"") -> 14.89532 | J18: =_xlfn.IFERROR(SUM(取值!J18),"") -> 13.30201 | K18: =_xlfn.IFERROR(SUM(取值!K18),"") -> 12.72012 | L18: =_xlfn.IFERROR(SUM(取值!L18),"") -> 11.43863 | ... P18: =_xlfn.IFERROR(SUM(取值!P18),"") -> 13.35449
B19: 15万吨/年重整装置 | C19: 原料量 | D19: FIQ7509B | E19: =_xlfn.IFERROR(SUM(取值!E19),"") -> 17.79634 | F19: =_xlfn.IFERROR(SUM(取值!F19),"") -> 18.2812 | G19: =_xlfn.IFERROR(SUM(取值!G19),"") -> 17.60827 | H19: =_xlfn.IFERROR(SUM(取值!H19),"") -> 17.51852 | I19: =_xlfn.IFERROR(SUM(取值!I19),"") -> 24.99651 | J19: =_xlfn.IFERROR(SUM(取值!J19),"") -> 16.72508 | K19: =_xlfn.IFERROR(SUM(取值!K19),"") -> 19.19778 | L19: =_xlfn.IFERROR(SUM(取值!L19),"") -> 16.70713 | ... P19: =_xlfn.IFERROR(SUM(取值!P19),"") -> 17.2769
C20: 重整反应进料量 | D20: FRCQ7601 | E20: =_xlfn.IFERROR(SUM(取值!E20),"") -> 16.97565 | F20: =_xlfn.IFERROR(SUM(取值!F20),"") -> 16.99318 | G20: =_xlfn.IFERROR(SUM(取值!G20),"") -> 16.98606 | H20: =_xlfn.IFERROR(SUM(取值!H20),"") -> 16.98517 | I20: =_xlfn.IFERROR(SUM(取值!I20),"") -> 16.93231 | J20: =_xlfn.IFERROR(SUM(取值!J20),"") -> 17.0403 | K20: =_xlfn.IFERROR(SUM(取值!K20),"") -> 17.0421 | L20: =_xlfn.IFERROR(SUM(取值!L20),"") -> 17.00335 | ... P20: =_xlfn.IFERROR(SUM(取值!P20),"") -> 16.96708
C21: 预加氢反应温度 | D21: TI7524 | E21: =_xlfn.IFERROR(SUM(取值!E21),"") -> 284.7057 | F21: =_xlfn.IFERROR(SUM(取值!F21),"") -> 282.8596 | G21: =_xlfn.IFERROR(SUM(取值!G21),"") -> 284.6616 | H21: =_xlfn.IFERROR(SUM(取值!H21),"") -> 283.2304 | I21: =_xlfn.IFERROR(SUM(取值!I21),"") -> 284.2923 | J21: =_xlfn.IFERROR(SUM(取值!J21),"") -> 284.644 | K21: =_xlfn.IFERROR(SUM(取值!K21),"") -> 285.4602 | L21: =_xlfn.IFERROR(SUM(取值!L21),"") -> 284.0402 | ... P21: =_xlfn.IFERROR(SUM(取值!P21),"") -> 283.3869
C22: 预加氢压差 | D22: PDR7509 | E22: =_xlfn.IFERROR(SUM(取值!E22),"") -> 38.64854 | F22: =_xlfn.IFERROR(SUM(取值!F22),"") -> 40.28741 | G22: =_xlfn.IFERROR(SUM(取值!G22),"") -> 40.0263 | H22: =_xlfn.IFERROR(SUM(取值!H22),"") -> 40.36453 | I22: =_xlfn.IFERROR(SUM(取值!I22),"") -> 38.7252 | J22: =_xlfn.IFERROR(SUM(取值!J22),"") -> 38.13836 | K22: =_xlfn.IFERROR(SUM(取值!K22),"") -> 40.21678 | L22: =_xlfn.IFERROR(SUM(取值!L22),"") -> 40.41374 | ... P22: =_xlfn.IFERROR(SUM(取值!P22),"") -> 42.54858
C23: 重整一反温度 | D23: TRC7601 | E23: =_xlfn.IFERROR(SUM(取值!E23),"") -> 472.4089 | F23: =_xlfn.IFERROR(SUM(取值!F23),"") -> 472.1727 | G23: =_xlfn.IFERROR(SUM(取值!G23),"") -> 472.1069 | H23: =_xlfn.IFERROR(SUM(取值!H23),"") -> 472.4383 | I23: =_xlfn.IFERROR(SUM(取值!I23),"") -> 472.0801 | J23: =_xlfn.IFERROR(SUM(取值!J23),"") -> 471.861 | K23: =_xlfn.IFERROR(SUM(取值!K23),"") -> 471.1911 | L23: =_xlfn.IFERROR(SUM(取值!L23),"") -> 471.908 | ... P23: =_xlfn.IFERROR(SUM(取值!P23),"") -> 471.6697
C24: 重整三反温度 | D24: TRC7603 | E24: =_xlfn.IFERROR(SUM(取值!E24),"") -> 477.3494 | F24: =_xlfn.IFERROR(SUM(取值!F24),"") -> 476.7776 | G24: =_xlfn.IFERROR(SUM(取值!G24),"") -> 477.1104 | H24: =_xlfn.IFERROR(SUM(取值!H24),"") -> 477.247 | I24: =_xlfn.IFERROR(SUM(取值!I24),"") -> 477.5986 | J24: =_xlfn.IFERROR(SUM(取值!J24),"") -> 477.5952 | K24: =_xlfn.IFERROR(SUM(取值!K24),"") -> 476.3401 | L24: =_xlfn.IFERROR(SUM(取值!L24),"") -> 476.2952 | ... P24: =_xlfn.IFERROR(SUM(取值!P24),"") -> 476.8367
C25: 一段氢气流量 | D25: FRA7610 | E25: =_xlfn.IFERROR(SUM(取值!E25),"") -> 16740.03 | F25: =_xlfn.IFERROR(SUM(取值!F25),"") -> 16684.21 | G25: =_xlfn.IFERROR(SUM(取值!G25),"") -> 16643.92 | H25: =_xlfn.IFERROR(SUM(取值!H25),"") -> 16634.79 | I25: =_xlfn.IFERROR(SUM(取值!I25),"") -> 16617.82 | J25: =_xlfn.IFERROR(SUM(取值!J25),"") -> 16553.53 | K25: =_xlfn.IFERROR(SUM(取值!K25),"") -> 16680.29 | L25: =_xlfn.IFERROR(SUM(取值!L25),"") -> 16660.47 | ... P25: =_xlfn.IFERROR(SUM(取值!P25),"") -> 17035.12
C26: 二段氢气流量 | D26: FRA7616 | E26: =_xlfn.IFERROR(SUM(取值!E26),"") -> 15904.26 | F26: =_xlfn.IFERROR(SUM(取值!F26),"") -> 15872.3 | G26: =_xlfn.IFERROR(SUM(取值!G26),"") -> 15831.81 | H26: =_xlfn.IFERROR(SUM(取值!H26),"") -> 15789.04 | I26: =_xlfn.IFERROR(SUM(取值!I26),"") -> 15802.98 | J26: =_xlfn.IFERROR(SUM(取值!J26),"") -> 15746.13 | K26: =_xlfn.IFERROR(SUM(取值!K26),"") -> 15903.06 | L26: =_xlfn.IFERROR(SUM(取值!L26),"") -> 15858.16 | ... P26: =_xlfn.IFERROR(SUM(取值!P26),"") -> 16242.75
C27: 重整汽油产量 | D27: FIQ7615B | E27: =_xlfn.IFERROR(SUM(取值!E27),"") -> 15.09963 | F27: =_xlfn.IFERROR(SUM(取值!F27),"") -> 13.84164 | G27: =_xlfn.IFERROR(SUM(取值!G27),"") -> 16.63508 | H27: =_xlfn.IFERROR(SUM(取值!H27),"") -> 15.41624 | I27: =_xlfn.IFERROR(SUM(取值!I27),"") -> 14.72824 | J27: =_xlfn.IFERROR(SUM(取值!J27),"") -> 14.25276 | K27: =_xlfn.IFERROR(SUM(取值!K27),"") -> 14.70266 | L27: =_xlfn.IFERROR(SUM(取值!L27),"") -> 14.08172 | ... P27: =_xlfn.IFERROR(SUM(取值!P27),"") -> 14.94411
B28: 20万吨/年航煤装置 | C28: 航煤反应进料量 | D28: FRC7101A | E28: =_xlfn.IFERROR(SUM(取值!E28),"") -> 19.96645 | F28: =_xlfn.IFERROR(SUM(取值!F28),"") -> 19.99748 | G28: =_xlfn.IFERROR(SUM(取值!G28),"") -> 19.96302 | H28: =_xlfn.IFERROR(SUM(取值!H28),"") -> 20.00477 | I28: =_xlfn.IFERROR(SUM(取值!I28),"") -> 19.90705 | J28: =_xlfn.IFERROR(SUM(取值!J28),"") -> 19.92171 | K28: =_xlfn.IFERROR(SUM(取值!K28),"") -> 19.99587 | L28: =_xlfn.IFERROR(SUM(取值!L28),"") -> 19.79097 | ... P28: =_xlfn.IFERROR(SUM(取值!P28),"") -> 20.07153
C29: 反应温度 | D29: TIC7101 | E29: =_xlfn.IFERROR(SUM(取值!E29),"") -> 0 | F29: =_xlfn.IFERROR(SUM(取值!F29),"") -> 0 | G29: =_xlfn.IFERROR(SUM(取值!G29),"") -> 0 | H29: =_xlfn.IFERROR(SUM(取值!H29),"") -> 0 | I29: =_xlfn.IFERROR(SUM(取值!I29),"") -> 0 | J29: =_xlfn.IFERROR(SUM(取值!J29),"") -> 0 | K29: =_xlfn.IFERROR(SUM(取值!K29),"") -> 0 | L29: =_xlfn.IFERROR(SUM(取值!L29),"") -> 0 | ... P29: =_xlfn.IFERROR(SUM(取值!P29),"") -> 0
C30: 高分压力 | D30: PRC7103 | E30: =_xlfn.IFERROR(SUM(取值!E30),"") -> 1.73473 | F30: =_xlfn.IFERROR(SUM(取值!F30),"") -> 1.733075 | G30: =_xlfn.IFERROR(SUM(取值!G30),"") -> 1.736275 | H30: =_xlfn.IFERROR(SUM(取值!H30),"") -> 1.737021 | I30: =_xlfn.IFERROR(SUM(取值!I30),"") -> 1.714893 | J30: =_xlfn.IFERROR(SUM(取值!J30),"") -> 1.724872 | K30: =_xlfn.IFERROR(SUM(取值!K30),"") -> 1.724222 | L30: =_xlfn.IFERROR(SUM(取值!L30),"") -> 1.739725 | ... P30: =_xlfn.IFERROR(SUM(取值!P30),"") -> 1.731572
C31: 汽提塔顶温 | D31: TIC7201 | E31: =_xlfn.IFERROR(SUM(取值!E31),"") -> 151.2305 | F31: =_xlfn.IFERROR(SUM(取值!F31),"") -> 152.261 | G31: =_xlfn.IFERROR(SUM(取值!G31),"") -> 153.0492 | H31: =_xlfn.IFERROR(SUM(取值!H31),"") -> 152.1515 | I31: =_xlfn.IFERROR(SUM(取值!I31),"") -> 150.9187 | J31: =_xlfn.IFERROR(SUM(取值!J31),"") -> 152.0392 | K31: =_xlfn.IFERROR(SUM(取值!K31),"") -> 152.7689 | L31: =_xlfn.IFERROR(SUM(取值!L31),"") -> 152.4096 | ... P31: =_xlfn.IFERROR(SUM(取值!P31),"") -> 150.955
C32: 汽提塔底温 | D32: TR7205 | E32: =_xlfn.IFERROR(SUM(取值!E32),"") -> 229.9201 | F32: =_xlfn.IFERROR(SUM(取值!F32),"") -> 229.9142 | G32: =_xlfn.IFERROR(SUM(取值!G32),"") -> 230.084 | H32: =_xlfn.IFERROR(SUM(取值!H32),"") -> 229.9445 | I32: =_xlfn.IFERROR(SUM(取值!I32),"") -> 230.2732 | J32: =_xlfn.IFERROR(SUM(取值!J32),"") -> 229.912 | K32: =_xlfn.IFERROR(SUM(取值!K32),"") -> 229.9166 | L32: =_xlfn.IFERROR(SUM(取值!L32),"") -> 229.5526 | ... P32: =_xlfn.IFERROR(SUM(取值!P32),"") -> 230.9865
C33: 精制航煤产量 | D33: FIQ7204B | E33: =_xlfn.IFERROR(SUM(取值!E33),"") -> 21.75922 | F33: =_xlfn.IFERROR(SUM(取值!F33),"") -> 21.3431 | G33: =_xlfn.IFERROR(SUM(取值!G33),"") -> 20.2494 | H33: =_xlfn.IFERROR(SUM(取值!H33),"") -> 20.51443 | I33: =_xlfn.IFERROR(SUM(取值!I33),"") -> 21.1531 | J33: =_xlfn.IFERROR(SUM(取值!J33),"") -> 20.93544 | K33: =_xlfn.IFERROR(SUM(取值!K33),"") -> 20.35954 | L33: =_xlfn.IFERROR(SUM(取值!L33),"") -> 20.54657 | ... P33: =_xlfn.IFERROR(SUM(取值!P33),"") -> 21.4762
B34: 2万标立/时制氢装置 | C34: 催化干气进料 | D34: 2FIQ10101 | E34: =_xlfn.IFERROR(SUM(取值!E34),"") -> 0 | F34: =_xlfn.IFERROR(SUM(取值!F34),"") -> 0 | G34: =_xlfn.IFERROR(SUM(取值!G34),"") -> 0 | H34: =_xlfn.IFERROR(SUM(取值!H34),"") -> 0 | I34: =_xlfn.IFERROR(SUM(取值!I34),"") -> 0 | J34: =_xlfn.IFERROR(SUM(取值!J34),"") -> 0 | K34: =_xlfn.IFERROR(SUM(取值!K34),"") -> 0 | L34: =_xlfn.IFERROR(SUM(取值!L34),"") -> 0 | ... P34: =_xlfn.IFERROR(SUM(取值!P34),"") -> 0
C35: 天然气进料 | D35: 2FIQ21002 | E35: =_xlfn.IFERROR(SUM(取值!E35),"") -> 4572.345 | F35: =_xlfn.IFERROR(SUM(取值!F35),"") -> 4418.345 | G35: =_xlfn.IFERROR(SUM(取值!G35),"") -> 4561.872 | H35: =_xlfn.IFERROR(SUM(取值!H35),"") -> 4622.612 | I35: =_xlfn.IFERROR(SUM(取值!I35),"") -> 4607.598 | J35: =_xlfn.IFERROR(SUM(取值!J35),"") -> 4591.213 | K35: =_xlfn.IFERROR(SUM(取值!K35),"") -> 4552.431 | L35: =_xlfn.IFERROR(SUM(取值!L35),"") -> 4536.6 | ... P35: =_xlfn.IFERROR(SUM(取值!P35),"") -> 4227.256
C36: 加氢反应温度 | D36: 2TIA10401D | E36: =_xlfn.IFERROR(SUM(取值!E36),"") -> 335.212 | F36: =_xlfn.IFERROR(SUM(取值!F36),"") -> 333.9731 | G36: =_xlfn.IFERROR(SUM(取值!G36),"") -> 332.2179 | H36: =_xlfn.IFERROR(SUM(取值!H36),"") -> 332.9783 | I36: =_xlfn.IFERROR(SUM(取值!I36),"") -> 333.2394 | J36: =_xlfn.IFERROR(SUM(取值!J36),"") -> 332.6369 | K36: =_xlfn.IFERROR(SUM(取值!K36),"") -> 335.2573 | L36: =_xlfn.IFERROR(SUM(取值!L36),"") -> 335.2245 | ... P36: =_xlfn.IFERROR(SUM(取值!P36),"") -> 336.1243
C37: 转化进料量 | D37: 2FICQ10501 | E37: =_xlfn.IFERROR(SUM(取值!E37),"") -> 4886.056 | F37: =_xlfn.IFERROR(SUM(取值!F37),"") -> 4894.98 | G37: =_xlfn.IFERROR(SUM(取值!G37),"") -> 4909.336 | H37: =_xlfn.IFERROR(SUM(取值!H37),"") -> 4911.719 | I37: =_xlfn.IFERROR(SUM(取值!I37),"") -> 4905.127 | J37: =_xlfn.IFERROR(SUM(取值!J37),"") -> 4915.269 | K37: =_xlfn.IFERROR(SUM(取值!K37),"") -> 4879.065 | L37: =_xlfn.IFERROR(SUM(取值!L37),"") -> 4934.285 | ... P37: =_xlfn.IFERROR(SUM(取值!P37),"") -> 4986.615
C38: 配汽量 | D38: 2FICQ10502 | E38: =_xlfn.IFERROR(SUM(取值!E38),"") -> 16.02656 | F38: =_xlfn.IFERROR(SUM(取值!F38),"") -> 16.01279 | G38: =_xlfn.IFERROR(SUM(取值!G38),"") -> 16.05494 | H38: =_xlfn.IFERROR(SUM(取值!H38),"") -> 16.06004 | I38: =_xlfn.IFERROR(SUM(取值!I38),"") -> 16.00188 | J38: =_xlfn.IFERROR(SUM(取值!J38),"") -> 16.07828 | K38: =_xlfn.IFERROR(SUM(取值!K38),"") -> 16.05605 | L38: =_xlfn.IFERROR(SUM(取值!L38),"") -> 16.09891 | ... P38: =_xlfn.IFERROR(SUM(取值!P38),"") -> 16.04389
C39: 转化进口温度 | D39: 2TI10602 | E39: =_xlfn.IFERROR(SUM(取值!E39),"") -> 457.4214 | F39: =_xlfn.IFERROR(SUM(取值!F39),"") -> 457.4409 | G39: =_xlfn.IFERROR(SUM(取值!G39),"") -> 456.1681 | H39: =_xlfn.IFERROR(SUM(取值!H39),"") -> 456.2197 | I39: =_xlfn.IFERROR(SUM(取值!I39),"") -> 456.4231 | J39: =_xlfn.IFERROR(SUM(取值!J39),"") -> 456.1841 | K39: =_xlfn.IFERROR(SUM(取值!K39),"") -> 458.6392 | L39: =_xlfn.IFERROR(SUM(取值!L39),"") -> 453.2147 | ... P39: =_xlfn.IFERROR(SUM(取值!P39),"") -> 457.1262
C40: 转化出口温度 | D40: 2TICA10604 | E40: =_xlfn.IFERROR(SUM(取值!E40),"") -> 730.493 | F40: =_xlfn.IFERROR(SUM(取值!F40),"") -> 730.7803 | G40: =_xlfn.IFERROR(SUM(取值!G40),"") -> 730.0059 | H40: =_xlfn.IFERROR(SUM(取值!H40),"") -> 730.3513 | I40: =_xlfn.IFERROR(SUM(取值!I40),"") -> 730.5482 | J40: =_xlfn.IFERROR(SUM(取值!J40),"") -> 730.3562 | K40: =_xlfn.IFERROR(SUM(取值!K40),"") -> 730.8309 | L40: =_xlfn.IFERROR(SUM(取值!L40),"") -> 729.6143 | ... P40: =_xlfn.IFERROR(SUM(取值!P40),"") -> 726.2589
C41: 转化炉压差 | D41: 2PDI10607 | E41: =_xlfn.IFERROR(SUM(取值!E41),"") -> 99.47729 | F41: =_xlfn.IFERROR(SUM(取值!F41),"") -> 99.25842 | G41: =_xlfn.IFERROR(SUM(取值!G41),"") -> 99.39027 | H41: =_xlfn.IFERROR(SUM(取值!H41),"") -> 99.09201 | I41: =_xlfn.IFERROR(SUM(取值!I41),"") -> 99.00618 | J41: =_xlfn.IFERROR(SUM(取值!J41),"") -> 99.84875 | K41: =_xlfn.IFERROR(SUM(取值!K41),"") -> 99.67923 | L41: =_xlfn.IFERROR(SUM(取值!L41),"") -> 99.9763 | ... P41: =_xlfn.IFERROR(SUM(取值!P41),"") -> 99.72835
...

Sheet 取值
A1: 4053 | N1: 报表生成时间： | O1: 2026-01-07 | P1: 8:00:00
B3: 调 度 工 艺 台 账
B4: 装置 | C4: 参数 | D4: DCS位号 | E4: 0 | F4: 2 | G4: 4 | H4: 6 | I4: 8 | J4: 10 | K4: 12 | L4: 14 | M4: 16 | N4: 18 | O4: 20 | P4: 22
B5: 210万吨/年常压装置 | C5: 加热炉出口温度 | D5: CY1.TIC1010.PV | E5: 367.3615 | F5: 367.3615 | G5: 367.3615 | H5: 367.3615 | I5: 367.3615 | J5: 367.3615 | K5: 367.3615 | L5: 367.3615 | M5: 366.4898 | N5: 364.6256 | O5: 364.6256 | P5: 364.6256
C6: 原油瞬时流量 | D6: CY1.FIQ1024.PV | E6: 170.3692 | F6: 170.3692 | G6: 170.3692 | H6: 170.3692 | I6: 170.3692 | J6: 170.3692 | K6: 170.3692 | L6: 170.3692 | M6: 173.028 | N6: 175.9752 | O6: 175.9752 | P6: 175.9752
B7: 250万吨/年常压装置 | C7: 加热炉出口温度 | D7: CY2.TRCA21123.PV | E7: 362.366 | F7: 365.0036 | G7: 364.0148 | H7: 364.0032 | I7: 363.8995 | J7: 356.3947 | K7: 355.3049 | L7: 364.0594 | M7: 363.9439 | N7: 363.6012 | O7: 363.0798 | P7: 363.7659
C8: 原油瞬时流量 | D8: CY2.FRQ21101.PV | E8: 210.2112 | F8: 216.0037 | G8: 207.1064 | H8: 186.6396 | I8: 206.3136 | J8: 211.7121 | K8: 213.4746 | L8: 187.4312 | M8: 212.063 | N8: 210.6971 | O8: 206.5491 | P8: 202.6841
B9: 120万吨/年催化装置 | C9: 进料量 | D9: CH2.FRC11201A.PV | E9: 148.0433 | F9: 148.9989 | G9: 150.4255 | H9: 148.5032 | I9: 140.8297 | J9: 143.4034 | K9: 144.6214 | L9: 146.8824 | M9: 148.7398 | N9: 153.1131 | O9: 142.1313 | P9: 144.1833
C10: 进料量 | D10: CH2.FRC11201B.PV | E10: 147.9782 | F10: 148.9989 | G10: 149.9882 | H10: 148.1376 | I10: 140.5216 | J10: 143.4034 | K10: 144.6214 | L10: 146.8824 | M10: 148.4001 | N10: 152.6674 | O10: 141.2875 | P10: 143.8969
C11: 反应温度 | D11: CH2.TRCA11101.PV | E11: 511.0833 | F11: 508.165 | G11: 508.1021 | H11: 509.1055 | I11: 508.7383 | J11: 509.4075 | K11: 510.95 | L11: 510.8574 | M11: 509.3898 | N11: 508.4846 | O11: 510.7469 | P11: 508.5659
C12: 床层温度 | D12: CH2.TRCA11102.PV | E12: 669.0388 | F12: 671.5338 | G12: 671.593 | H12: 673.1566 | I12: 670.1186 | J12: 670.2256 | K12: 670.884 | L12: 670.1187 | M12: 669.4556 | N12: 670.2274 | O12: 671.7142 | P12: 672.0531
C13: 外取热产汽量 | D13: CH2.FR11802.PV | E13: 78.02948 | F13: 78.76244 | G13: 77.74912 | H13: 78.7143 | I13: 78.00824 | J13: 78.38966 | K13: 79.66066 | L13: 79.35944 | M13: 80.31715 | N13: 80.61673 | O13: 78.99202 | P13: 79.70379
C14: 3.2MPa蒸汽压力 | D14: CH2.PIC11804A.PV | E14: 3.285997 | F14: 3.273058 | G14: 3.280875 | H14: 3.273886 | I14: 3.272886 | J14: 3.281966 | K14: 3.271701 | L14: 3.286853 | M14: 3.260506 | N14: 3.259532 | O14: 3.279675 | P14: 3.282131
C15: 1.0MPa蒸汽压力 | D15: CH2.PI11804B.PV | E15: 0.9096271 | F15: 0.9232986 | G15: 0.9033581 | H15: 0.9112934 | I15: 0.9006488 | J15: 0.8649458 | K15: 0.8940718 | L15: 0.8641422 | M15: 0.8925709 | N15: 0.9002503 | O15: 0.9077369 | P15: 0.9255369
C16: 1.0MPa蒸汽放空开度 | D16: CH2.PIC11909.MV | E16: 0 | F16: 0 | G16: 0 | H16: 0 | I16: 0 | J16: 0 | K16: 0 | L16: 0 | M16: 0 | N16: 0 | O16: 0 | P16: 0
C17: 中压锅炉负荷 | D17: CH2.VH3101ABCD.PV | E17: 35 | F17: 35 | G17: 35 | H17: 35 | I17: 35 | J17: 35 | K17: 35 | L17: 35 | M17: 35 | N17: 35 | O17: 35 | P17: 35
C18: 中压锅炉产汽量 | D18: CH2.FRCQ11641.PV | E18: 13.83241 | F18: 15.29463 | G18: 14.64806 | H18: 15.11002 | I18: 14.89532 | J18: 13.30201 | K18: 12.72012 | L18: 11.43863 | M18: 13.24226 | N18: 13.48892 | O18: 12.56484 | P18: 13.35449
B19: 15万吨/年重整装置 | C19: 原料量 | D19: CZ.FIQ7509B.PV | E19: 17.79634 | F19: 18.2812 | G19: 17.60827 | H19: 17.51852 | I19: 24.99651 | J19: 16.72508 | K19: 19.19778 | L19: 16.70713 | M19: 16.569 | N19: 18.29433 | O19: 17.99195 | P19: 17.2769
C20: 重整反应进料量 | D20: YPCZ.FRCQ7601.PV | E20: 16.97565 | F20: 16.99318 | G20: 16.98606 | H20: 16.98517 | I20: 16.93231 | J20: 17.0403 | K20: 17.0421 | L20: 17.00335 | M20: 16.98937 | N20: 16.97254 | O20: 17.00001 | P20: 16.96708
C21: 预加氢反应温度 | D21: YPCZ.TI7524.PV | E21: 284.7057 | F21: 282.8596 | G21: 284.6616 | H21: 283.2304 | I21: 284.2923 | J21: 284.644 | K21: 285.4602 | L21: 284.0402 | M21: 283.9051 | N21: 283.226 | O21: 283.456 | P21: 283.3869
C22: 预加氢压差 | D22: YPCZ.PDR7509.PV | E22: 38.64854 | F22: 40.28741 | G22: 40.0263 | H22: 40.36453 | I22: 38.7252 | J22: 38.13836 | K22: 40.21678 | L22: 40.41374 | M22: 41.6483 | N22: 41.87342 | O22: 39.22972 | P22: 42.54858
C23: 重整一反温度 | D23: YPCZ.TRC7601.PV | E23: 472.4089 | F23: 472.1727 | G23: 472.1069 | H23: 472.4383 | I23: 472.0801 | J23: 471.861 | K23: 471.1911 | L23: 471.908 | M23: 471.3738 | N23: 471.8661 | O23: 472.8426 | P23: 471.6697
C24: 重整三反温度 | D24: YPCZ.TRC7603.PV | E24: 477.3494 | F24: 476.7776 | G24: 477.1104 | H24: 477.247 | I24: 477.5986 | J24: 477.5952 | K24: 476.3401 | L24: 476.2952 | M24: 477.1053 | N24: 476.9018 | O24: 476.6307 | P24: 476.8367
C25: 一段氢气流量 | D25: YPCZ.FRA7610.PV | E25: 16740.03 | F25: 16684.21 | G25: 16643.92 | H25: 16634.79 | I25: 16617.82 | J25: 16553.53 | K25: 16680.29 | L25: 16660.47 | M25: 16729.08 | N25: 16973.28 | O25: 17049.93 | P25: 17035.12
C26: 二段氢气流量 | D26: YPCZ.FRA7616.PV | E26: 15904.26 | F26: 15872.3 | G26: 15831.81 | H26: 15789.04 | I26: 15802.98 | J26: 15746.13 | K26: 15903.06 | L26: 15858.16 | M26: 15959.3 | N26: 16196.96 | O26: 16267.51 | P26: 16242.75
C27: 重整汽油产量 | D27: CZ.FIQ7615B.PV | E27: 15.09963 | F27: 13.84164 | G27: 16.63508 | H27: 15.41624 | I27: 14.72824 | J27: 14.25276 | K27: 14.70266 | L27: 14.08172 | M27: 15.13702 | N27: 14.94569 | O27: 15.2856 | P27: 14.94411
B28: 20万吨/年航煤装置 | C28: 航煤反应进料量 | D28: YPCZ.FRC7101A.PV | E28: 19.96645 | F28: 19.99748 | G28: 19.96302 | H28: 20.00477 | I28: 19.90705 | J28: 19.92171 | K28: 19.99587 | L28: 19.79097 | M28: 20.05231 | N28: 20.03573 | O28: 20.10132 | P28: 20.07153
C29: 反应温度 | D29: YPCZ.TIC7101.PV
C30: 高分压力 | D30: YPCZ.PRC7103.PV | E30: 1.73473 | F30: 1.733075 | G30: 1.736275 | H30: 1.737021 | I30: 1.714893 | J30: 1.724872 | K30: 1.724222 | L30: 1.739725 | M30: 1.729104 | N30: 1.721812 | O30: 1.72956 | P30: 1.731572
C31: 汽提塔顶温 | D31: YPCZ.TIC7201.PV | E31: 151.2305 | F31: 152.261 | G31: 153.0492 | H31: 152.1515 | I31: 150.9187 | J31: 152.0392 | K31: 152.7689 | L31: 152.4096 | M31: 153.1664 | N31: 150.9076 | O31: 149.8868 | P31: 150.955
C32: 汽提塔底温 | D32: YPCZ.TR7205.PV | E32: 229.9201 | F32: 229.9142 | G32: 230.084 | H32: 229.9445 | I32: 230.2732 | J32: 229.912 | K32: 229.9166 | L32: 229.5526 | M32: 229.764 | N32: 230.6621 | O32: 231.0779 | P32: 230.9865
C33: 精制航煤产量 | D33: CZ.FIQ7204B.PV | E33: 21.75922 | F33: 21.3431 | G33: 20.2494 | H33: 20.51443 | I33: 21.1531 | J33: 20.93544 | K33: 20.35954 | L33: 20.54657 | M33: 19.90054 | N33: 20.24636 | O33: 21.24424 | P33: 21.4762
B34: 2万标立/时制氢装置 | C34: 催化干气进料 | D34: 2FIQ10101.PV | E34: 0 | F34: 0 | G34: 0 | H34: 0 | I34: 0 | J34: 0 | K34: 0 | L34: 0 | M34: 0 | N34: 0 | O34: 0 | P34: 0
C35: 天然气进料 | D35: 2FIQ21002.PV | E35: 4572.345 | F35: 4418.345 | G35: 4561.872 | H35: 4622.612 | I35: 4607.598 | J35: 4591.213 | K35: 4552.431 | L35: 4536.6 | M35: 4411.366 | N35: 4360.901 | O35: 4476.547 | P35: 4227.256
C36: 加氢反应温度 | D36: 2TIA10401D.PV | E36: 335.212 | F36: 333.9731 | G36: 332.2179 | H36: 332.9783 | I36: 333.2394 | J36: 332.6369 | K36: 335.2573 | L36: 335.2245 | M36: 338.3408 | N36: 338.7721 | O36: 337.7673 | P36: 336.1243
C37: 转化进料量 | D37: 2FICQ10501.PV | E37: 4886.056 | F37: 4894.98 | G37: 4909.336 | H37: 4911.719 | I37: 4905.127 | J37: 4915.269 | K37: 4879.065 | L37: 4934.285 | M37: 4890.448 | N37: 4986.16 | O37: 5026.828 | P37: 4986.615
C38: 配汽量 | D38: 2FICQ10502.PV | E38: 16.02656 | F38: 16.01279 | G38: 16.05494 | H38: 16.06004 | I38: 16.00188 | J38: 16.07828 | K38: 16.05605 | L38: 16.09891 | M38: 16.06186 | N38: 16.06139 | O38: 16.0167 | P38: 16.04389
C39: 转化进口温度 | D39: 2TI10602.PV | E39: 457.4214 | F39: 457.4409 | G39: 456.1681 | H39: 456.2197 | I39: 456.4231 | J39: 456.1841 | K39: 458.6392 | L39: 453.2147 | M39: 456.2177 | N39: 456.3517 | O39: 457.2298 | P39: 457.1262
C40: 转化出口温度 | D40: 2TICA10604.PV | E40: 730.493 | F40: 730.7803 | G40: 730.0059 | H40: 730.3513 | I40: 730.5482 | J40: 730.3562 | K40: 730.8309 | L40: 729.6143 | M40: 727.0994 | N40: 726.3113 | O40: 727.5468 | P40: 726.2589
C41: 转化炉压差 | D41: 2PDI10607.PV | E41: 99.47729 | F41: 99.25842 | G41: 99.39027 | H41: 99.09201 | I41: 99.00618 | J41: 99.84875 | K41: 99.67923 | L41: 99.9763 | M41: 99.27106 | N41: 100.112 | O41: 99.72072 | P41: 99.72835
...
