Workbook

Sheet Sheet2
B1: 炼化公司调运信息简表
B2: 填报单位：炼化公司 | D2: 统计日期： | E2: =I2 -> 2026-01-06 | F2: 填报日期： | G2: =取值!A1 -> 2026-01-07 | I2: 2026-01-06
B3: 单位 名称 | D3: 延炼 | E3: 永炼 | F3: 榆炼 | G3: 石化厂 | H3: 榆能化 | L3: 库容 | M3: 延炼 | N3: 永炼 | O3: 榆炼 | P3: 石化厂
B4: 原料气 | C4: 调运量 | D4: =_xlfn.IFERROR(取值!A130,"") -> 1056 | E4: =_xlfn.IFERROR(SUM(取值!A2),"") -> 709 | F4: =_xlfn.IFERROR(取值!A158,"") -> 536.32 | L4: 原料气 | M4: 5600 | N4: 3700 | O4: 3000 | P4: 3680
C5: 库存 | D5: =_xlfn.IFERROR(取值!A131,"") -> 4528 | E5: =_xlfn.IFERROR(SUM(取值!A3),"") -> 2360 | F5: =_xlfn.IFERROR(取值!A159,"") -> 1002.1693 | Q5: 5600 | R5: 3700 | S5: 3000 | T5: 3680
C6: 空量 | D6: =M4-D5 -> 1072 | E6: =N4-E5 -> 1340 | F6: =O4-F5 -> 1997.8307
B7: 饱和气 | C7: 调运量 | D7: =_xlfn.IFERROR(取值!A133,"") -> 225 | F7: =_xlfn.IFERROR(取值!A161,"") -> 250.12 | G7: =_xlfn.IFERROR(取值!A68,"") -> 174 | L7: 饱和气 | M7: 1600 | O7: 2200 | P7: 1840
C8: 库存 | D8: =_xlfn.IFERROR(取值!A134,"") -> 292 | F8: =_xlfn.IFERROR(取值!A162,"") -> 686.43624 | G8: =_xlfn.IFERROR(取值!A69,"") -> 699.488 | Q8: 1600 | S8: 2200 | T8: 1840
C9: 空量 | D9: =M7-D8 -> 1308 | F9: =O7-F8 -> 1513.5638 | G9: =P7-G8 -> 1140.512
B10: 常压石脑油 | C10: 调运量 | D10: =_xlfn.IFERROR(取值!A136,"") -> 2963 | E10: =_xlfn.IFERROR(SUM(取值!A6),"") -> 763.58 | F10: =_xlfn.IFERROR(取值!A164,"") -> 353 | G10: =_xlfn.IFERROR(取值!A71,"") -> 667.36 | L10: 常压 石脑油 | M10: 15000 | N10: 9500 | O10: 23000 | P10: 14360
C11: 库存 | D11: =_xlfn.IFERROR(取值!A137,"") -> 11849 | E11: =_xlfn.IFERROR(SUM(取值!A7),"") -> 9264 | F11: =_xlfn.IFERROR(取值!A165,"") -> 22050.6 | G11: =_xlfn.IFERROR(取值!A72,"") -> 10616.681 | Q11: 15000 | R11: 9500 | S11: 18000 | T11: 14360
C12: 空量 | D12: =M10-D11 -> 3151 | E12: =N10-E11 -> 236 | F12: =O10-F11 -> 949.4 | G12: =P10-G11 -> 3743.319
B13: 石脑油（供延能化） | C13: 调运量 | D13: =_xlfn.IFERROR(取值!A139,"") -> 64 | E13: =_xlfn.IFERROR(SUM(取值!A10),"") -> 324.78 | L13: 石脑油（供延能化） | M13: 1600 | N13: 1200
C14: 库存 | D14: =_xlfn.IFERROR(取值!A140,"") -> 1156 | E14: =_xlfn.IFERROR(SUM(取值!A11),"") -> 562 | Q14: 1600 | R14: 1200
C15: 空量 | E15: =N13-E14 -> 638
B16: 1#渣油 | C16: 调运量 | D16: =_xlfn.IFERROR(取值!A141,"") -> 0 | E16: {=_xlfn.IFERROR(SUM(取值!A14:取值!A15),"")} -> 1475.72 | F16: =_xlfn.IFERROR(取值!A167,"") -> 2432 | H16: =F16+E16 -> 3907.72 | L16: 1#渣油 | M16: 75800 | N16: 35000 | O16: 50000
C17: 库存 | D17: =_xlfn.IFERROR(取值!A142,"") -> 39858 | E17: =_xlfn.IFERROR(SUM(取值!A16),"") -> 14605 | F17: =_xlfn.IFERROR(取值!A168,"") -> 30663 | Q17: 75800 | R17: 35000 | S17: 50000
C18: 空量 | D18: =M16-D17 -> 35942 | E18: =N16-E17 -> 20395 | F18: =O16-F17 -> 19337
B19: MTBE | C19: 调运量 | D19: =_xlfn.IFERROR(取值!A144,"") -> 850 | E19: =_xlfn.IFERROR(SUM(取值!A19),"") -> 313.76 | F19: =_xlfn.IFERROR(取值!A170,"") -> 0 | G19: =_xlfn.IFERROR(取值!A80,"") -> 1163.46 | L19: MTBE | M19: 6500 | N19: 3000 | O19: 3000 | P19: 6440
C20: 使用量 | D20: =_xlfn.IFERROR(取值!A146,"") -> 930 | E20: =_xlfn.IFERROR(SUM(取值!A21),"") -> 213 | F20: =_xlfn.IFERROR(取值!A172,"") -> 293 | Q20: 6500 | R20: 700 | S20: 3000 | T20: 6440
C21: 库存 | D21: =_xlfn.IFERROR(取值!A145,"") -> 3472 | E21: =_xlfn.IFERROR(SUM(取值!A20),"") -> 2825 | F21: =_xlfn.IFERROR(取值!A171,"") -> 1917.6 | G21: =_xlfn.IFERROR(取值!A81,"") -> 3445.572
C22: 空量 | D22: =M19-D21 -> 3028 | E22: =N19-E21 -> 175 | F22: =O19-F21 -> 1082.4 | G22: =P19-G21 -> 2994.428
B23: 烷基化油 | C23: 调运量 | D23: =_xlfn.IFERROR(取值!A147,"") -> 371 | E23: =_xlfn.IFERROR(SUM(取值!A23),"") -> 219.4 | F23: =_xlfn.IFERROR(取值!A173,"") -> 213.54 | G23: =_xlfn.IFERROR(取值!A83,"") -> 809.3 | L23: 烷基 化油 | M23: 5300 | N23: 2800 | O23: 2950 | P23: 6500
C24: 使用量 | D24: =_xlfn.IFERROR(取值!A149,"") -> 371 | E24: =_xlfn.IFERROR(SUM(取值!A25),"") -> 136 | F24: =_xlfn.IFERROR(取值!A175,"") -> 133 | Q24: 5200 | R24: 2800 | S24: 2950 | T24: 6500
C25: 库存 | D25: =_xlfn.IFERROR(取值!A148,"") -> 5270 | E25: =_xlfn.IFERROR(SUM(取值!A24),"") -> 2083 | F25: =_xlfn.IFERROR(取值!A174,"") -> 2512.8 | G25: =_xlfn.IFERROR(取值!A84,"") -> 5770.289
C26: 空量 | D26: =M23-D25 -> 30 | E26: =N23-E25 -> 717 | F26: =O23-F25 -> 437.2 | G26: =P23-G25 -> 729.711
B27: 二甲苯 | C27: 调运量 | D27: =_xlfn.IFERROR(取值!A150,"") -> 0 | E27: =_xlfn.IFERROR(SUM(取值!A27),"") -> 32.16 | F27: =_xlfn.IFERROR(取值!A176,"") -> 128.68 | L27: 二甲苯 | M27: 0 | N27: 3200 | O27: 7000 | P27: 0
C28: 使用量 | D28: =_xlfn.IFERROR(取值!A152,"") -> 28 | E28: =_xlfn.IFERROR(SUM(取值!A29),"") -> 91 | F28: =_xlfn.IFERROR(取值!A178,"") -> 0 | R28: 3200 | S28: 7000
C29: 库存 | D29: =_xlfn.IFERROR(取值!A151,"") -> 3222 | E29: =_xlfn.IFERROR(SUM(取值!A28),"") -> 2670 | F29: =_xlfn.IFERROR(取值!A177,"") -> 3565.92
C30: 空量 | E30: =N27-E29 -> 530 | F30: =O27-F29 -> 3434.08
B31: 丙烯 | C31: 库存 | D31: =_xlfn.IFERROR(取值!A153,"") -> 733 | F31: =_xlfn.IFERROR(取值!A179,"") -> 0 | G31: =_xlfn.IFERROR(取值!A89,"") -> 1890.827 | L31: 丙烯 | M31: 2200 | N31: =R32 -> 0 | O31: 0 | P31: 4512
C32: 空量 | D32: =M31-D31 -> 1467 | F32: =_xlfn.IFERROR(取值!A180,"") -> 0 | G32: =P31-G31 -> 2621.173 | Q32: 2200 | T32: 4512
B33: 油浆 | C33: 库存 | D33: =_xlfn.IFERROR(取值!A155,"") -> 1627 | E33: =_xlfn.IFERROR(SUM(取值!A31),"") -> 904 | F33: =_xlfn.IFERROR(取值!A181,"") -> 4493.02 | L33: 油浆 | M33: 1700 | N33: =R34 -> 1200 | O33: 20500 | P33: 0
C34: 空量 | D34: =M33-D33 -> 73 | E34: =N33-E33 -> 296 | F34: =O33-F33 -> 16006.98 | Q34: 1600 | R34: 1200 | S34: 20500
B35: 审核人： | D35: 罗先波 | G35: 一审人： | H35: 李阿君
E38: 198
E39: 736 | G39: 0
E40: 61
E41: 0 | G41: 9885.421
E42: 262
...

Sheet 取值
A1: 2026-01-07 | B1: 8:00:00 | F1: 原料气
A2: 709
A3: 2360
A4: 3430
A5: 石脑油
A6: 763.58
A7: 9264
A8: 12000
A9: 轻石脑油
A10: 324.78
A11: 562
A12: 1600
A13: 1#渣油
A14: 0
A15: 1475.72
A16: 14605
A17: 39000
A18: MTBE
A19: 313.76
A20: 2825
A21: 213
A22: 烷基化油
A23: 219.4
A24: 2083
A25: 136
A26: 二甲苯
A27: 32.16
A28: 2670
A29: 91
A30: 油浆
A31: 904
A32: 1200
D33: =A33&B33&C33
D34: =A34&B34&C34
D35: =A35&B35&C35
A66: 1982.015
A68: 174
A69: 699.488
A71: 667.36
A72: 10616.681
...
