Workbook

Sheet 炼化公司月报表
B1: 炼化公司生产月报表
B2: 填报单位：炼化公司 | C2: 2025-11 | J2: 陕油统 炼化B-401
B3: 指标名称 | C3: 单位 | D3: 本月生产 | G3: 本年生产 | J3: 去年同期 | L3: 同比 增长
D4: 月计划 | E4: 月完成 | F4: 完成率% | G4: 年计划 | H4: 年完成 | I4: 完成率% | J4: 本月 | K4: 本年
B5: 一、装置加工量
B6: 1、原料油（气）加工量 | C6: 吨 | D6: =_xlfn.IFERROR(IF(取值!C34=0,"",取值!C34),"") | E6: =_xlfn.IFERROR(SUM(E7:E15),"") -> 1319643 | F6: =_xlfn.IFERROR(E6/D6*100,"") | G6: =_xlfn.IFERROR(IF(取值!D34=0,"",取值!D34),"") | H6: =_xlfn.IFERROR(SUM(H7:H15),"") -> 14158321 | I6: =_xlfn.IFERROR(H6/G6*100,"") | J6: 0 | K6: 0 | L6: =_xlfn.IFERROR(H6-K6,"") -> 14158321 | M6: =E6 -> 1319643 | N6: =H6 -> 14158321
B7: 其中：原油 | C7: 吨 | D7: 1280000 | E7: =_xlfn.IFERROR(SUM(延炼月报表!E7,永炼月报表!E7,榆炼月报表!E7,石化厂月报表!E7),"") -> 1291340 | F7: =_xlfn.IFERROR(E7/D7*100,"") -> 100.88594 | G7: 15100000 | H7: =_xlfn.IFERROR(SUM(延炼月报表!H7,永炼月报表!H7,榆炼月报表!H7,石化厂月报表!H7),"") -> 13869932 | I7: =_xlfn.IFERROR(H7/G7*100,"") -> 91.853854 | J7: 0 | K7: 0 | L7: =_xlfn.IFERROR(H7-K7,"") -> 13869932 | M7: =E7 -> 1291340 | N7: =H7 -> 13869932
B8: 甲醇 | C8: 吨 | D8: 10300 | E8: =_xlfn.IFERROR(SUM(延炼月报表!E8,永炼月报表!E8,榆炼月报表!E8,石化厂月报表!E8),"") -> 11889.68 | F8: =_xlfn.IFERROR(E8/D8*100,"") -> 115.43379 | G8: 129528 | H8: =_xlfn.IFERROR(SUM(延炼月报表!H8,永炼月报表!H8,榆炼月报表!H8,石化厂月报表!H8),"") -> 94061.28 | I8: =_xlfn.IFERROR(H8/G8*100,"") -> 72.618492 | J8: 0 | K8: 0 | L8: =_xlfn.IFERROR(H8-K8,"") -> 94061.28 | M8: =E8 -> 11889.68 | N8: =H8 -> 94061.28
B9: MTBE | C9: 吨 | D9: =_xlfn.IFERROR(IF(取值!C37=0,"",取值!C37),"") | E9: =_xlfn.IFERROR(SUM(延炼月报表!E9,永炼月报表!E9,榆炼月报表!E9,石化厂月报表!E9),"") -> 6400 | F9: =_xlfn.IFERROR(E9/D9*100,"") | G9: =_xlfn.IFERROR(IF(取值!D37=0,"",取值!D37),"") | H9: =_xlfn.IFERROR(SUM(延炼月报表!H9,永炼月报表!H9,榆炼月报表!H9,石化厂月报表!H9),"") -> 104521.16 | I9: =_xlfn.IFERROR(H9/G9*100,"") | J9: 0 | K9: 0 | L9: =_xlfn.IFERROR(H9-K9,"") -> 104521.16 | M9: =E9 -> 6400 | N9: =H9 -> 104521.16
B10: 1#渣油 | C10: 吨 | D10: =_xlfn.IFERROR(IF(取值!C38=0,"",取值!C38),"") | E10: =_xlfn.IFERROR(SUM(延炼月报表!E10,永炼月报表!E10,榆炼月报表!E10,石化厂月报表!E10),"") -> 0 | F10: =_xlfn.IFERROR(E10/D10*100,"") | G10: =_xlfn.IFERROR(IF(取值!D38=0,"",取值!D38),"") | H10: =_xlfn.IFERROR(SUM(延炼月报表!H10,永炼月报表!H10,榆炼月报表!H10,石化厂月报表!H10),"") -> 0 | I10: =_xlfn.IFERROR(H10/G10*100,"") | J10: 0 | K10: 0 | L10: =_xlfn.IFERROR(H10-K10,"") -> 0 | M10: =E10 -> 0 | N10: =H10 -> 0
B11: 裂解石脑油 | C11: 吨 | D11: =_xlfn.IFERROR(IF(取值!C39=0,"",取值!C39),"") | E11: =_xlfn.IFERROR(SUM(延炼月报表!E11,永炼月报表!E11,榆炼月报表!E11,石化厂月报表!E11),"") -> 481 | F11: =_xlfn.IFERROR(E11/D11*100,"") | G11: =_xlfn.IFERROR(IF(取值!D39=0,"",取值!D39),"") | H11: =_xlfn.IFERROR(SUM(延炼月报表!H11,永炼月报表!H11,榆炼月报表!H11,石化厂月报表!H11),"") -> 481 | I11: =_xlfn.IFERROR(H11/G11*100,"") | J11: 0 | K11: 0 | L11: =_xlfn.IFERROR(H11-K11,"") -> 481 | M11: =E11 -> 481 | N11: =H11 -> 481
B12: 上古液化气 | C12: 吨 | D12: =_xlfn.IFERROR(IF(取值!C40=0,"",取值!C40),"") | E12: =_xlfn.IFERROR(SUM(延炼月报表!E12,永炼月报表!E12,榆炼月报表!E12,石化厂月报表!E12),"") -> 0 | F12: =_xlfn.IFERROR(E12/D12*100,"") | G12: =_xlfn.IFERROR(IF(取值!D40=0,"",取值!D40),"") | H12: =_xlfn.IFERROR(SUM(延炼月报表!H12,永炼月报表!H12,榆炼月报表!H12,石化厂月报表!H12),"") -> 0 | I12: =_xlfn.IFERROR(H12/G12*100,"") | J12: 0 | K12: 0 | L12: =_xlfn.IFERROR(H12-K12,"") -> 0 | M12: =E12 -> 0 | N12: =H12 -> 0
B13: 醋酸 | C13: 吨 | D13: 2200 | E13: =_xlfn.IFERROR(SUM(延炼月报表!E13,永炼月报表!E13,榆炼月报表!E13,石化厂月报表!E13),"") -> 2787 | F13: =_xlfn.IFERROR(E13/D13*100,"") -> 126.68182 | G13: 30625 | H13: =_xlfn.IFERROR(SUM(延炼月报表!H13,永炼月报表!H13,榆炼月报表!H13,石化厂月报表!H13),"") -> 25213 | I13: =_xlfn.IFERROR(H13/G13*100,"") -> 82.328163 | J13: 0 | K13: 0 | L13: =_xlfn.IFERROR(H13-K13,"") -> 25213 | M13: =E13 -> 2787 | N13: =H13 -> 25213
B14: 异辛烷组分 | C14: 吨 | D14: =_xlfn.IFERROR(IF(取值!C42=0,"",取值!C42),"") | E14: =_xlfn.IFERROR(SUM(延炼月报表!E14,永炼月报表!E14,榆炼月报表!E14,石化厂月报表!E14),"") -> 0 | F14: =_xlfn.IFERROR(E14/D14*100,"") | G14: =_xlfn.IFERROR(IF(取值!D42=0,"",取值!D42),"") | H14: =_xlfn.IFERROR(SUM(延炼月报表!H14,永炼月报表!H14,榆炼月报表!H14,石化厂月报表!H14),"") -> 0 | I14: =_xlfn.IFERROR(H14/G14*100,"") | J14: 0 | K14: 0 | L14: =_xlfn.IFERROR(H14-K14,"") -> 0 | M14: =E14 -> 0 | N14: =H14 -> 0
B15: 异丁烷 | C15: 吨 | D15: =_xlfn.IFERROR(IF(取值!C43=0,"",取值!C43),"") | E15: =_xlfn.IFERROR(SUM(延炼月报表!E15,永炼月报表!E15,榆炼月报表!E15,石化厂月报表!E15),"") -> 6745.3 | F15: =_xlfn.IFERROR(E15/D15*100,"") | G15: 50000 | H15: =_xlfn.IFERROR(SUM(延炼月报表!H15,永炼月报表!H15,榆炼月报表!H15,石化厂月报表!H15),"") -> 64112.6 | I15: =_xlfn.IFERROR(H15/G15*100,"") -> 128.2252 | J15: 0 | K15: 0 | L15: =_xlfn.IFERROR(H15-K15,"") -> 64112.6 | M15: =E15 -> 6745.3 | N15: =H15 -> 64112.6
B16: 2、常压装置加工量 | C16: 吨 | D16: =_xlfn.IFERROR(IF(取值!C44=0,"",取值!C44),"") | E16: =_xlfn.IFERROR(SUM(延炼月报表!E16,永炼月报表!E16,榆炼月报表!E16,石化厂月报表!E16),"") -> 1291340 | F16: =_xlfn.IFERROR(E16/D16*100,"") | G16: =_xlfn.IFERROR(IF(取值!D44=0,"",取值!D44),"") | H16: =_xlfn.IFERROR(SUM(延炼月报表!H16,永炼月报表!H16,榆炼月报表!H16,石化厂月报表!H16),"") -> 13869932 | I16: =_xlfn.IFERROR(H16/G16*100,"") | J16: 0 | K16: 0 | L16: =_xlfn.IFERROR(H16-K16,"") -> 13869932 | M16: =E16 -> 1291340 | N16: =H16 -> 13869932
B17: 原油加工量 | C17: 吨 | D17: 1280000 | E17: =_xlfn.IFERROR(SUM(延炼月报表!E17,永炼月报表!E17,榆炼月报表!E17,石化厂月报表!E17),"") -> 1291340 | F17: =_xlfn.IFERROR(E17/D17*100,"") -> 100.88594 | G17: 15100000 | H17: =_xlfn.IFERROR(SUM(延炼月报表!H17,永炼月报表!H17,榆炼月报表!H17,石化厂月报表!H17),"") -> 13869932 | I17: =_xlfn.IFERROR(H17/G17*100,"") -> 91.853854 | J17: 0 | K17: 0 | L17: =_xlfn.IFERROR(H17-K17,"") -> 13869932 | M17: =E17 -> 1291340 | N17: =H17 -> 13869932
B18: 其中：进口原油加工量 | C18: 吨 | D18: =_xlfn.IFERROR(IF(取值!C46=0,"",取值!C46),"") | E18: 0 | F18: =_xlfn.IFERROR(E18/D18*100,"") | G18: =_xlfn.IFERROR(IF(取值!D46=0,"",取值!D46),"") | H18: 0 | I18: =_xlfn.IFERROR(H18/G18*100,"") | J18: 0 | K18: 0 | L18: =_xlfn.IFERROR(H18-K18,"") -> 0
B19: 3、催化装置加工量 | C19: 吨 | D19: =_xlfn.IFERROR(IF(取值!C46=0,"",取值!C46),"") | E19: =_xlfn.IFERROR(SUM(延炼月报表!E19,永炼月报表!E19,榆炼月报表!E19,石化厂月报表!E19),"") -> 531507 | F19: =_xlfn.IFERROR(E19/D19*100,"") | G19: =_xlfn.IFERROR(IF(取值!D46=0,"",取值!D46),"") | H19: =_xlfn.IFERROR(SUM(延炼月报表!H19,永炼月报表!H19,榆炼月报表!H19,石化厂月报表!H19),"") -> 5798572 | I19: =_xlfn.IFERROR(H19/G19*100,"") | J19: 0 | K19: 0 | L19: =_xlfn.IFERROR(H19-K19,"") -> 5798572 | M19: =E19 -> 531507 | N19: =H19 -> 5798572
B20: 其中：1#渣油加工量 | C20: 吨 | D20: 497000 | E20: =_xlfn.IFERROR(SUM(延炼月报表!E20,永炼月报表!E20,榆炼月报表!E20,石化厂月报表!E20),"") -> 519099 | F20: =_xlfn.IFERROR(E20/D20*100,"") -> 104.44648 | G20: 5980000 | H20: =_xlfn.IFERROR(SUM(延炼月报表!H20,永炼月报表!H20,榆炼月报表!H20,石化厂月报表!H20),"") -> 5690089 | I20: =_xlfn.IFERROR(H20/G20*100,"") -> 95.15199 | J20: 0 | K20: 0 | L20: =_xlfn.IFERROR(H20-K20,"") -> 5690089 | M20: =E20 -> 519099 | N20: =H20 -> 5690089
B21: 4、重整装置处理量 | C21: 吨 | D21: 220500 | E21: =_xlfn.IFERROR(SUM(延炼月报表!E21,永炼月报表!E21,榆炼月报表!E21,石化厂月报表!E21),"") -> 249055 | F21: =_xlfn.IFERROR(E21/D21*100,"") -> 112.95011 | G21: 2570000 | H21: =_xlfn.IFERROR(SUM(延炼月报表!H21,永炼月报表!H21,榆炼月报表!H21,石化厂月报表!H21),"") -> 2480546 | I21: =_xlfn.IFERROR(H21/G21*100,"") -> 96.5193 | J21: 0 | K21: 0 | L21: =_xlfn.IFERROR(H21-K21,"") -> 2480546 | M21: =E21 -> 249055 | N21: =H21 -> 2480546
B22: 5、DCC石脑油加氢处理量 | C22: 吨 | D22: =_xlfn.IFERROR(IF(取值!C49=0,"",取值!C49),"") | E22: =_xlfn.IFERROR(SUM(延炼月报表!E22,永炼月报表!E22,榆炼月报表!E22,石化厂月报表!E22),"") -> 0 | F22: =_xlfn.IFERROR(E22/D22*100,"") | G22: =_xlfn.IFERROR(IF(取值!D49=0,"",取值!D49),"") | H22: =_xlfn.IFERROR(SUM(延炼月报表!H22,永炼月报表!H22,榆炼月报表!H22,石化厂月报表!H22),"") -> 0 | I22: =_xlfn.IFERROR(H22/G22*100,"") | J22: 0 | K22: 0 | L22: =_xlfn.IFERROR(H22-K22,"") -> 0 | M22: =E22 -> 0 | N22: =H22 -> 0
B23: 6、DCC裂解轻油加氢处理量 | C23: 吨 | D23: =_xlfn.IFERROR(IF(取值!C50=0,"",取值!C50),"") | E23: =_xlfn.IFERROR(SUM(延炼月报表!E23,永炼月报表!E23,榆炼月报表!E23,石化厂月报表!E23),"") -> 0 | F23: =_xlfn.IFERROR(E23/D23*100,"") | G23: =_xlfn.IFERROR(IF(取值!D50=0,"",取值!D50),"") | H23: =_xlfn.IFERROR(SUM(延炼月报表!H23,永炼月报表!H23,榆炼月报表!H23,石化厂月报表!H23),"") -> 0 | I23: =_xlfn.IFERROR(H23/G23*100,"") | J23: 0 | K23: 0 | L23: =_xlfn.IFERROR(H23-K23,"") -> 0 | M23: =E23 -> 0 | N23: =H23 -> 0
B24: 7、汽油加氢精制处理量 | C24: 吨 | D24: 233000 | E24: =_xlfn.IFERROR(SUM(延炼月报表!E24,永炼月报表!E24,榆炼月报表!E24,石化厂月报表!E24),"") -> 274854 | F24: =_xlfn.IFERROR(E24/D24*100,"") -> 117.96309 | G24: 2890000 | H24: =_xlfn.IFERROR(SUM(延炼月报表!H24,永炼月报表!H24,榆炼月报表!H24,石化厂月报表!H24),"") -> 2669899 | I24: =_xlfn.IFERROR(H24/G24*100,"") -> 92.384048 | J24: 0 | K24: 0 | L24: =_xlfn.IFERROR(H24-K24,"") -> 2669899 | M24: =E24 -> 274854 | N24: =H24 -> 2669899
B25: 8、柴油加氢精制处理量 | C25: 吨 | D25: 476000 | E25: =_xlfn.IFERROR(SUM(延炼月报表!E25,永炼月报表!E25,榆炼月报表!E25,石化厂月报表!E25),"") -> 527019 | F25: =_xlfn.IFERROR(E25/D25*100,"") -> 110.71828 | G25: 5890000 | H25: =_xlfn.IFERROR(SUM(延炼月报表!H25,永炼月报表!H25,榆炼月报表!H25,石化厂月报表!H25),"") -> 5741404 | I25: =_xlfn.IFERROR(H25/G25*100,"") -> 97.477148 | J25: 0 | K25: 0 | L25: =_xlfn.IFERROR(H25-K25,"") -> 5741404 | M25: =E25 -> 527019 | N25: =H25 -> 5741404
B26: 9、气分装置加工量 | C26: 吨 | D26: 82600 | E26: =_xlfn.IFERROR(SUM(延炼月报表!E26,永炼月报表!E26,榆炼月报表!E26,石化厂月报表!E26),"") -> 82180 | F26: =_xlfn.IFERROR(E26/D26*100,"") -> 99.491525 | G26: 900000 | H26: =_xlfn.IFERROR(SUM(延炼月报表!H26,永炼月报表!H26,榆炼月报表!H26,石化厂月报表!H26),"") -> 907074 | I26: =_xlfn.IFERROR(H26/G26*100,"") -> 100.786 | J26: 0 | K26: 0 | L26: =_xlfn.IFERROR(H26-K26,"") -> 907074 | M26: =E26 -> 82180 | N26: =H26 -> 907074
B27: 10、航煤装置处理量 | C27: 吨 | D27: =_xlfn.IFERROR(IF(取值!C54=0,"",取值!C54),"") | E27: =_xlfn.IFERROR(SUM(延炼月报表!E27,永炼月报表!E27,榆炼月报表!E27,石化厂月报表!E27),"") -> 70759 | F27: =_xlfn.IFERROR(E27/D27*100,"") | G27: 525843 | H27: =_xlfn.IFERROR(SUM(延炼月报表!H27,永炼月报表!H27,榆炼月报表!H27,石化厂月报表!H27),"") -> 612876 | I27: =_xlfn.IFERROR(H27/G27*100,"") -> 116.55114 | J27: 0 | K27: 0 | L27: =_xlfn.IFERROR(H27-K27,"") -> 612876 | M27: =E27 -> 70759 | N27: =H27 -> 612876
B28: 11、烷基化装置处理量 | C28: 吨 | D28: =_xlfn.IFERROR(IF(取值!C55=0,"",取值!C55),"") | E28: =_xlfn.IFERROR(SUM(延炼月报表!E28,永炼月报表!E28,榆炼月报表!E28,石化厂月报表!E28),"") -> 29971 | F28: =_xlfn.IFERROR(E28/D28*100,"") | G28: =_xlfn.IFERROR(IF(取值!D55=0,"",取值!D55),"") | H28: =_xlfn.IFERROR(SUM(延炼月报表!H28,永炼月报表!H28,榆炼月报表!H28,石化厂月报表!H28),"") -> 317896.8 | I28: =_xlfn.IFERROR(H28/G28*100,"") | J28: 0 | K28: 0 | L28: =_xlfn.IFERROR(H28-K28,"") -> 317896.8 | M28: =E28 -> 29971 | N28: =H28 -> 317896.8
B29: 12、混合脱氢装置处理量 | C29: 吨 | D29: =_xlfn.IFERROR(IF(取值!C56=0,"",取值!C56),"") | E29: =_xlfn.IFERROR(SUM(延炼月报表!E29,永炼月报表!E29,榆炼月报表!E29,石化厂月报表!E29),"") -> 56218 | F29: =_xlfn.IFERROR(E29/D29*100,"") | G29: =_xlfn.IFERROR(IF(取值!D56=0,"",取值!D56),"") | H29: =_xlfn.IFERROR(SUM(延炼月报表!H29,永炼月报表!H29,榆炼月报表!H29,石化厂月报表!H29),"") -> 486669 | I29: =_xlfn.IFERROR(H29/G29*100,"") | J29: 0 | K29: 0 | L29: =_xlfn.IFERROR(H29-K29,"") -> 486669 | M29: =E29 -> 56218 | N29: =H29 -> 486669
B30: 二、油气产品产销量 | D30: =_xlfn.IFERROR(IF(取值!C57=0,"",取值!C57),"") | F30: =_xlfn.IFERROR(E30/D30*100,"") | G30: =_xlfn.IFERROR(IF(取值!D57=0,"",取值!D57),"") | I30: =_xlfn.IFERROR(H30/G30*100,"")
B31: 1、汽油产量 | C31: 吨 | D31: 499000 | E31: =_xlfn.IFERROR(SUM(延炼月报表!E31,永炼月报表!E31,榆炼月报表!E31,石化厂月报表!E31),"") -> 496793 | F31: =_xlfn.IFERROR(E31/D31*100,"") -> 99.557715 | G31: 4817524 | H31: =_xlfn.IFERROR(SUM(延炼月报表!H31,永炼月报表!H31,榆炼月报表!H31,石化厂月报表!H31),"") -> 5284966 | I31: =_xlfn.IFERROR(H31/G31*100,"") -> 109.70295 | J31: 0 | K31: 0 | L31: =_xlfn.IFERROR(H31-K31,"") -> 5284966 | M31: =E31 -> 496793 | N31: =H31 -> 5284966
B32: ⑴ 92#VI | C32: 吨 | D32: =_xlfn.IFERROR(IF(取值!C59=0,"",取值!C59),"") | E32: =_xlfn.IFERROR(SUM(延炼月报表!E32,永炼月报表!E32,榆炼月报表!E32,石化厂月报表!E32),"") -> 380685 | F32: =_xlfn.IFERROR(E32/D32*100,"") | G32: 3736408 | H32: =_xlfn.IFERROR(SUM(延炼月报表!H32,永炼月报表!H32,榆炼月报表!H32,石化厂月报表!H32),"") -> 3900258 | I32: =_xlfn.IFERROR(H32/G32*100,"") -> 104.38523 | J32: 0 | K32: 0 | L32: =_xlfn.IFERROR(H32-K32,"") -> 3900258 | M32: =E32 -> 380685 | N32: =H32 -> 3900258
B33: ⑵ 95#VI | C33: 吨 | D33: =_xlfn.IFERROR(IF(取值!C60=0,"",取值!C60),"") | E33: =_xlfn.IFERROR(SUM(延炼月报表!E33,永炼月报表!E33,榆炼月报表!E33,石化厂月报表!E33),"") -> 116108 | F33: =_xlfn.IFERROR(E33/D33*100,"") | G33: 1058800 | H33: =_xlfn.IFERROR(SUM(延炼月报表!H33,永炼月报表!H33,榆炼月报表!H33,石化厂月报表!H33),"") -> 1361746 | I33: =_xlfn.IFERROR(H33/G33*100,"") -> 128.6122 | J33: 0 | K33: 0 | L33: =_xlfn.IFERROR(H33-K33,"") -> 1361746 | M33: =E33 -> 116108 | N33: =H33 -> 1361746
B34: ⑶ 98#Ⅵ | C34: 吨 | D34: =_xlfn.IFERROR(IF(取值!C61=0,"",取值!C61),"") | E34: =_xlfn.IFERROR(SUM(延炼月报表!E34,永炼月报表!E34,榆炼月报表!E34,石化厂月报表!E34),"") -> 0 | F34: =_xlfn.IFERROR(E34/D34*100,"") | G34: =_xlfn.IFERROR(IF(取值!D61=0,"",取值!D61),"") | H34: =_xlfn.IFERROR(SUM(延炼月报表!H34,永炼月报表!H34,榆炼月报表!H34,石化厂月报表!H34),"") -> 22962 | I34: =_xlfn.IFERROR(H34/G34*100,"") | J34: 0 | K34: 0 | L34: =_xlfn.IFERROR(H34-K34,"") -> 22962 | M34: =E34 -> 0 | N34: =H34 -> 22962
B35: 2、柴油产量 | C35: 吨 | D35: 441000 | E35: =_xlfn.IFERROR(SUM(延炼月报表!E35,永炼月报表!E35,榆炼月报表!E35,石化厂月报表!E35),"") -> 459042 | F35: =_xlfn.IFERROR(E35/D35*100,"") -> 104.09116 | G35: 5489343 | H35: =_xlfn.IFERROR(SUM(延炼月报表!H35,永炼月报表!H35,榆炼月报表!H35,石化厂月报表!H35),"") -> 5170950 | I35: =_xlfn.IFERROR(H35/G35*100,"") -> 94.199798 | J35: 0 | K35: 0 | L35: =_xlfn.IFERROR(H35-K35,"") -> 5170950 | M35: =E35 -> 459042 | N35: =H35 -> 5170950
B36: ⑴ 军用柴油 | C36: 吨 | D36: =_xlfn.IFERROR(IF(取值!C63=0,"",取值!C63),"") | E36: =_xlfn.IFERROR(SUM(延炼月报表!E36,永炼月报表!E36,榆炼月报表!E36,石化厂月报表!E36),"") -> 0 | F36: =_xlfn.IFERROR(E36/D36*100,"") | G36: =_xlfn.IFERROR(IF(取值!D63=0,"",取值!D63),"") | H36: =_xlfn.IFERROR(SUM(延炼月报表!H36,永炼月报表!H36,榆炼月报表!H36,石化厂月报表!H36),"") -> 0 | I36: =_xlfn.IFERROR(H36/G36*100,"") | J36: 0 | K36: 0 | L36: =_xlfn.IFERROR(H36-K36,"") -> 0 | M36: =E36 -> 0 | N36: =H36 -> 0
B37: ⑵ 0#VI | C37: 吨 | D37: =_xlfn.IFERROR(IF(取值!C64=0,"",取值!C64),"") | E37: =_xlfn.IFERROR(SUM(延炼月报表!E37,永炼月报表!E37,榆炼月报表!E37,石化厂月报表!E37),"") -> 389812 | F37: =_xlfn.IFERROR(E37/D37*100,"") | G37: =_xlfn.IFERROR(IF(取值!D64=0,"",取值!D64),"") | H37: =_xlfn.IFERROR(SUM(延炼月报表!H37,永炼月报表!H37,榆炼月报表!H37,石化厂月报表!H37),"") -> 5023311 | I37: =_xlfn.IFERROR(H37/G37*100,"") | J37: 0 | K37: 0 | L37: =_xlfn.IFERROR(H37-K37,"") -> 5023311 | M37: =E37 -> 389812 | N37: =H37 -> 5023311
B38: ⑶ -10#VI | C38: 吨 | D38: 30000 | E38: =_xlfn.IFERROR(SUM(延炼月报表!E38,永炼月报表!E38,榆炼月报表!E38,石化厂月报表!E38),"") -> 35700 | F38: =_xlfn.IFERROR(E38/D38*100,"") -> 119 | G38: =_xlfn.IFERROR(IF(取值!D65=0,"",取值!D65),"") | H38: =_xlfn.IFERROR(SUM(延炼月报表!H38,永炼月报表!H38,榆炼月报表!H38,石化厂月报表!H38),"") -> 76700 | I38: =_xlfn.IFERROR(H38/G38*100,"") | J38: 0 | K38: 0 | L38: =_xlfn.IFERROR(H38-K38,"") -> 76700 | M38: =E38 -> 35700 | N38: =H38 -> 76700
B39: ⑷ -20#VI | C39: 吨 | D39: 20000 | E39: =_xlfn.IFERROR(SUM(延炼月报表!E39,永炼月报表!E39,榆炼月报表!E39,石化厂月报表!E39),"") -> 33530 | F39: =_xlfn.IFERROR(E39/D39*100,"") -> 167.65 | G39: =_xlfn.IFERROR(IF(取值!D66=0,"",取值!D66),"") | H39: =_xlfn.IFERROR(SUM(延炼月报表!H39,永炼月报表!H39,榆炼月报表!H39,石化厂月报表!H39),"") -> 70939 | I39: =_xlfn.IFERROR(H39/G39*100,"") | J39: 0 | K39: 0 | L39: =_xlfn.IFERROR(H39-K39,"") -> 70939 | M39: =E39 -> 33530 | N39: =H39 -> 70939
B40: ⑸ -35#VI | C40: 吨 | D40: =_xlfn.IFERROR(IF(取值!C67=0,"",取值!C67),"") | E40: =_xlfn.IFERROR(SUM(延炼月报表!E40,永炼月报表!E40,榆炼月报表!E40,石化厂月报表!E40),"") -> 0 | F40: =_xlfn.IFERROR(E40/D40*100,"") | G40: =_xlfn.IFERROR(IF(取值!D67=0,"",取值!D67),"") | H40: =_xlfn.IFERROR(SUM(延炼月报表!H40,永炼月报表!H40,榆炼月报表!H40,石化厂月报表!H40),"") -> 0 | I40: =_xlfn.IFERROR(H40/G40*100,"") | J40: 0 | K40: 0 | L40: =_xlfn.IFERROR(H40-K40,"") -> 0 | M40: =E40 -> 0 | N40: =H40 -> 0
...

Sheet 取值
B2: 月 | M2: 年
C3: 延炼 | E3: 永炼 | G3: 榆炼 | I3: 石化 | K3: 合计 | N3: 延炼 | P3: 永炼 | R3: 榆炼 | T3: 石化 | V3: 合计
B4: 自用率 | C4: =_xlfn.IFERROR(C7/C8*100,"") -> 2.5205124 | E4: =_xlfn.IFERROR(E7/E8*100,"") -> 4.7096725 | G4: =_xlfn.IFERROR(G7/G8*100,"") -> 4.5853858 | I4: =_xlfn.IFERROR(I7/I8*100,"") -> 3.961531 | K4: =_xlfn.IFERROR(C7+E7+G7+I7,"") -> 84777 | N4: =_xlfn.IFERROR(N7/N8*100,"") -> 2.5062749 | P4: =_xlfn.IFERROR(P7/P8*100,"") -> 4.4504288 | R4: =_xlfn.IFERROR(R7/R8*100,"") -> 5.3445032 | T4: =_xlfn.IFERROR(T7/T8*100,"") -> 2.0420753 | V4: =_xlfn.IFERROR(N7+P7+R7+T7,"") -> 820867
B5: 损失率 | C5: =_xlfn.IFERROR(C10/C11*100,"") -> 0.76595358 | E5: =_xlfn.IFERROR(E10/E11*100,"") -> 0.7349151 | G5: =_xlfn.IFERROR(G10/G11*100,"") -> 1.5241037 | I5: =_xlfn.IFERROR(I10/I11*100,"") -> 1.0300608 | K5: =_xlfn.IFERROR(C10+E10+G10+I10,"") -> 23723.56 | N5: =_xlfn.IFERROR(N10/N11*100,"") -> 0.75773225 | P5: =_xlfn.IFERROR(P10/P11*100,"") -> 0.73497371 | R5: =_xlfn.IFERROR(R10/R11*100,"") -> 1.1341718 | T5: =_xlfn.IFERROR(T10/T11*100,"") -> 1.0400295 | V5: =_xlfn.IFERROR(N10+P10+R10+T10,"") -> 226352.82
C7: 24938 | E7: 12426 | G7: 25952 | I7: 21461 | N7: 287320 | P7: 162286 | R7: 257157 | T7: 114104
C8: 989402 | E8: 263840 | G8: 565972 | I8: 541735 | N8: 11464026 | P8: 3646525 | R8: 4811616.6 | T8: 5587649
C10: 7578.36 | E10: 1939 | G10: 8626 | I10: 5580.2 | N10: 86866.62 | P10: 26801 | R10: 54572 | T10: 58113.2
C11: 989402 | E11: 263840 | G11: 565972 | I11: 541735 | N11: 11464026 | P11: 3646525 | R11: 4811616.6 | T11: 5587649
B20: 炼油综合能耗 | C20: 24552.64 | E20: 14043.47 | G20: 26881.22 | I20: 42.21 | N20: 271660.8 | P20: 165580.77 | R20: 278184 | T20: 42.6
C21: 524629 | E21: 252343 | G21: 550368 | N21: 5905379 | P21: 3486701 | R21: 4553852
C22: =C20/C21*1000 -> 46.800005 | E22: =E20/E21*1000 -> 55.652307 | G22: =G20/G21*1000 -> 48.842266 | I22: =I20 -> 42.21 | K22: =(C22*C23+E22*E23+G22*G23+I22*I23)/K23 -> 66.557148 | N22: =N20/N21*1000 -> 46.002263 | P22: =P20/P21*1000 -> 47.489237 | R22: =R20/R21*1000 -> 61.087624 | T22: =T20 -> 42.6 | V22: =(N22*N23+P22*P23+R22*R23+T22*T23)/V23 -> 69.994849
C23: 524629 | E23: 252343 | G23: 550368 | I23: 541735 | K23: =C23+E23+G23 -> 1327340 | N23: 5905379 | P23: 3486701 | R23: 4553852 | T23: 6120137 | V23: =N23+P23+R23 -> 13945932
C33: 月计划 | D33: 年计划
B35: 7 | C35: 1280000 | D35: 15100000
B36: 8 | C36: 10300 | D36: 129528
B37: 9
B38: 10 | D38: =_xlfn.IFERROR(SUM('延炼取值 '!G10,永炼取值!G10,榆炼取值!G10,石化取值!G10),"") -> 0
B39: 11 | C39: 0
B40: 12 | D40: =_xlfn.IFERROR(SUM('延炼取值 '!G12,永炼取值!G12,榆炼取值!G12,石化取值!G12),"") -> 0
B41: 13 | C41: 2200 | D41: 30625
B42: 14 | D42: =_xlfn.IFERROR(SUM('延炼取值 '!G14,永炼取值!G14,榆炼取值!G14,石化取值!G14),"") -> 0
B43: 15 | D43: =_xlfn.IFERROR(SUM('延炼取值 '!G15,永炼取值!G15,榆炼取值!G15,石化取值!G15),"") -> 50000
B44: 16 | D44: =_xlfn.IFERROR(SUM('延炼取值 '!G16,永炼取值!G16,榆炼取值!G16,石化取值!G16),"") -> 0
B45: 17 | C45: 1280000 | D45: 15100000
B46: 18
B47: 19 | C47: 497000 | D47: 5980000
B48: 20 | C48: 220500 | D48: 2570000
B49: 21 | C49: 0
B50: 22
B51: 23 | C51: 233000 | D51: 2890000
B52: 24 | C52: 476000 | D52: 5890000
B53: 25 | C53: 82600 | D53: 900000
B54: 26 | D54: 525843
B55: 27
B56: 28
B57: 29
B58: 30 | C58: 499000 | D58: 4817524
B59: 31 | D59: 3736408
B60: 32 | D60: 1058800
B61: 33
...

Sheet 延炼月报表
B1: 炼化公司生产月报表（延炼）
B2: 填报单位：炼化公司 | C2: 2025-11 | J2: 陕油统 炼化B-401
B3: 指标名称 | C3: 单位 | D3: 本月生产 | G3: 本年生产 | J3: 去年同期 | L3: 同比 增长
D4: 月计划 | E4: 月完成 | F4: 完成率% | G4: 年计划 | H4: 年完成 | I4: 完成率% | J4: 本月 | K4: 本年
B5: 一、装置加工量
B6: 1、原料油（气）加工量 | C6: 吨 | D6: =_xlfn.IFERROR(IF('延炼取值 '!D6=0,"",'延炼取值 '!D6),"") | E6: =_xlfn.IFERROR(SUM(E7:E15),"") -> 492908.96 | G6: =_xlfn.IFERROR(IF('延炼取值 '!G6=0,"",'延炼取值 '!G6),"") | H6: =_xlfn.IFERROR(SUM(H7:H15),"") -> 5877567.4 | J6: 470841.46 | K6: 5819161.2 | L6: =_xlfn.IFERROR(H6-K6,"") -> 58406.18
B7: 其中：原油 | C7: 吨 | D7: 525000 | E7: =_xlfn.IFERROR('延炼取值 '!E7,"") -> 488629 | F7: =_xlfn.IFERROR(E7/'延炼取值 '!D7*100,"") -> 93.07219 | G7: 6300000 | H7: =_xlfn.IFERROR('延炼取值 '!H7,"") -> 5829379 | I7: =_xlfn.IFERROR(H7/'延炼取值 '!G7*100,"") -> 92.529825 | J7: 466526 | K7: 5775191 | L7: =_xlfn.IFERROR(H7-K7,"") -> 54188
B8: 甲醇 | C8: 吨 | D8: 1300 | E8: =_xlfn.IFERROR('延炼取值 '!E8,"") -> 1492.96 | F8: =_xlfn.IFERROR(E8/'延炼取值 '!D8*100,"") -> 114.84308 | G8: 15256 | H8: =_xlfn.IFERROR('延炼取值 '!H8,"") -> 13575.24 | I8: =_xlfn.IFERROR(H8/'延炼取值 '!G8*100,"") -> 88.982958 | J8: 1418.46 | K8: 14243.22 | L8: =_xlfn.IFERROR(H8-K8,"") -> -667.98
B9: MTBE | C9: 吨 | D9: 3000 | E9: =_xlfn.IFERROR('延炼取值 '!E9,"") -> 0 | F9: =_xlfn.IFERROR(E9/'延炼取值 '!D9*100,"") -> 0 | G9: =_xlfn.IFERROR(IF('延炼取值 '!G9=0,"",'延炼取值 '!G9),"") | H9: =_xlfn.IFERROR('延炼取值 '!H9,"") -> 9400.16 | I9: =_xlfn.IFERROR(H9/'延炼取值 '!G9*100,"") | J9: 0 | K9: 0 | L9: =_xlfn.IFERROR(H9-K9,"") -> 9400.16
B10: 1#渣油 | C10: 吨 | D10: =_xlfn.IFERROR(IF('延炼取值 '!D10=0,"",'延炼取值 '!D10),"") | F10: =_xlfn.IFERROR(E10/'延炼取值 '!D10*100,"") | G10: =_xlfn.IFERROR(IF('延炼取值 '!G10=0,"",'延炼取值 '!G10),"") | I10: =_xlfn.IFERROR(H10/'延炼取值 '!G10*100,"") | L10: =_xlfn.IFERROR(H10-K10,"") -> 0
B11: 裂解石脑油 | C11: 吨 | D11: =_xlfn.IFERROR(IF('延炼取值 '!D11=0,"",'延炼取值 '!D11),"") | F11: =_xlfn.IFERROR(E11/'延炼取值 '!D11*100,"") | G11: =_xlfn.IFERROR(IF('延炼取值 '!G11=0,"",'延炼取值 '!G11),"") | I11: =_xlfn.IFERROR(H11/'延炼取值 '!G11*100,"") | L11: =_xlfn.IFERROR(H11-K11,"") -> 0
B12: 上古液化气 | C12: 吨 | D12: =_xlfn.IFERROR(IF('延炼取值 '!D12=0,"",'延炼取值 '!D12),"") | E12: =_xlfn.IFERROR('延炼取值 '!E12,"") -> 0 | F12: =_xlfn.IFERROR(E12/'延炼取值 '!D12*100,"") | G12: =_xlfn.IFERROR(IF('延炼取值 '!G12=0,"",'延炼取值 '!G12),"") | H12: =_xlfn.IFERROR('延炼取值 '!H12,"") -> 0 | I12: =_xlfn.IFERROR(H12/'延炼取值 '!G12*100,"") | J12: 0 | K12: 0 | L12: =_xlfn.IFERROR(H12-K12,"") -> 0
B13: 醋酸 | C13: 吨 | D13: 2200 | E13: =_xlfn.IFERROR('延炼取值 '!E13,"") -> 2787 | F13: =_xlfn.IFERROR(E13/'延炼取值 '!D13*100,"") -> 126.68182 | G13: 30625 | H13: =_xlfn.IFERROR('延炼取值 '!H13,"") -> 25213 | I13: =_xlfn.IFERROR(H13/'延炼取值 '!G13*100,"") -> 82.328163 | J13: 2897 | K13: 29727 | L13: =_xlfn.IFERROR(H13-K13,"") -> -4514
B14: 异辛烷组分 | C14: 吨 | D14: =_xlfn.IFERROR(IF('延炼取值 '!D14=0,"",'延炼取值 '!D14),"") | F14: =_xlfn.IFERROR(E14/'延炼取值 '!D14*100,"") | G14: =_xlfn.IFERROR(IF('延炼取值 '!G14=0,"",'延炼取值 '!G14),"") | I14: =_xlfn.IFERROR(H14/'延炼取值 '!G14*100,"") | L14: =_xlfn.IFERROR(H14-K14,"") -> 0
B15: 异丁烷 | C15: 吨 | D15: =_xlfn.IFERROR(IF('延炼取值 '!D15=0,"",'延炼取值 '!D15),"") | F15: =_xlfn.IFERROR(E15/'延炼取值 '!D15*100,"") | G15: =_xlfn.IFERROR(IF('延炼取值 '!G15=0,"",'延炼取值 '!G15),"") | I15: =_xlfn.IFERROR(H15/'延炼取值 '!G15*100,"") | L15: =_xlfn.IFERROR(H15-K15,"") -> 0
B16: 2、常压装置加工量 | C16: 吨 | D16: =_xlfn.IFERROR(IF('延炼取值 '!D16=0,"",'延炼取值 '!D16),"") | E16: =_xlfn.IFERROR('延炼取值 '!E16,"") -> 488629 | F16: =_xlfn.IFERROR(E16/'延炼取值 '!D16*100,"") | G16: =_xlfn.IFERROR(IF('延炼取值 '!G16=0,"",'延炼取值 '!G16),"") | H16: =_xlfn.IFERROR('延炼取值 '!H16,"") -> 5829379 | I16: =_xlfn.IFERROR(H16/'延炼取值 '!G16*100,"") | J16: 466526 | K16: 5775191 | L16: =_xlfn.IFERROR(H16-K16,"") -> 54188 | M16: 月 | N16: 年
B17: 原油加工量 | C17: 吨 | D17: 525000 | E17: =_xlfn.IFERROR('延炼取值 '!E17,"") -> 488629 | F17: =_xlfn.IFERROR(E17/'延炼取值 '!D17*100,"") -> 93.07219 | G17: 6300000 | H17: =_xlfn.IFERROR('延炼取值 '!H17,"") -> 5829379 | I17: =_xlfn.IFERROR(H17/'延炼取值 '!G17*100,"") -> 92.529825 | J17: 466526 | K17: 5775191 | L17: =_xlfn.IFERROR(H17-K17,"") -> 54188 | M17: =E17 -> 488629 | N17: =H17 -> 5829379
B18: 其中：进口原油加工量 | C18: 吨 | D18: =_xlfn.IFERROR(IF('延炼取值 '!D18=0,"",'延炼取值 '!D18),"") | E18: 0 | F18: =_xlfn.IFERROR(E18/'延炼取值 '!D18*100,"") | G18: =_xlfn.IFERROR(IF('延炼取值 '!G18=0,"",'延炼取值 '!G18),"") | H18: 0 | I18: =_xlfn.IFERROR(H18/'延炼取值 '!G18*100,"") | J18: 0 | K18: 0 | L18: =_xlfn.IFERROR(H18-K18,"") -> 0
B19: 3、催化装置加工量 | C19: 吨 | D19: =_xlfn.IFERROR(IF('延炼取值 '!D19=0,"",'延炼取值 '!D19),"") | E19: =_xlfn.IFERROR('延炼取值 '!E19,"") -> 252896 | F19: =_xlfn.IFERROR(E19/'延炼取值 '!D19*100,"") | G19: =_xlfn.IFERROR(IF('延炼取值 '!G19=0,"",'延炼取值 '!G19),"") | H19: =_xlfn.IFERROR('延炼取值 '!H19,"") -> 2967443 | I19: =_xlfn.IFERROR(H19/'延炼取值 '!G19*100,"") | J19: 261377 | K19: 2949656 | L19: =_xlfn.IFERROR(H19-K19,"") -> 17787
B20: 其中：1#渣油加工量 | C20: 吨 | D20: 260000 | E20: =_xlfn.IFERROR('延炼取值 '!E20,"") -> 251400 | F20: =_xlfn.IFERROR(E20/'延炼取值 '!D20*100,"") -> 96.692308 | G20: 3080000 | H20: =_xlfn.IFERROR('延炼取值 '!H20,"") -> 2974069 | I20: =_xlfn.IFERROR(H20/'延炼取值 '!G20*100,"") -> 96.560682 | J20: 260435 | K20: 2936284 | L20: =_xlfn.IFERROR(H20-K20,"") -> 37785 | M20: =E20 -> 251400 | N20: =H20 -> 2974069
B21: 4、重整装置处理量 | C21: 吨 | D21: =_xlfn.IFERROR(IF('延炼取值 '!D21=0,"",'延炼取值 '!D21),"") | F21: =_xlfn.IFERROR(E21/'延炼取值 '!D21*100,"") | G21: =_xlfn.IFERROR(IF('延炼取值 '!G21=0,"",'延炼取值 '!G21),"") | I21: =_xlfn.IFERROR(H21/'延炼取值 '!G21*100,"") | L21: =_xlfn.IFERROR(H21-K21,"") -> 0
B22: 5、DCC石脑油加氢处理量 | C22: 吨 | D22: =_xlfn.IFERROR(IF('延炼取值 '!D22=0,"",'延炼取值 '!D22),"") | F22: =_xlfn.IFERROR(E22/'延炼取值 '!D22*100,"") | G22: =_xlfn.IFERROR(IF('延炼取值 '!G22=0,"",'延炼取值 '!G22),"") | I22: =_xlfn.IFERROR(H22/'延炼取值 '!G22*100,"") | L22: =_xlfn.IFERROR(H22-K22,"") -> 0
B23: 6、DCC裂解轻油加氢处理量 | C23: 吨 | D23: =_xlfn.IFERROR(IF('延炼取值 '!D23=0,"",'延炼取值 '!D23),"") | F23: =_xlfn.IFERROR(E23/'延炼取值 '!D23*100,"") | G23: =_xlfn.IFERROR(IF('延炼取值 '!G23=0,"",'延炼取值 '!G23),"") | I23: =_xlfn.IFERROR(H23/'延炼取值 '!G23*100,"") | L23: =_xlfn.IFERROR(H23-K23,"") -> 0
B24: 7、汽油加氢精制处理量 | C24: 吨 | D24: =_xlfn.IFERROR(IF('延炼取值 '!D24=0,"",'延炼取值 '!D24),"") | F24: =_xlfn.IFERROR(E24/'延炼取值 '!D24*100,"") | G24: =_xlfn.IFERROR(IF('延炼取值 '!G24=0,"",'延炼取值 '!G24),"") | I24: =_xlfn.IFERROR(H24/'延炼取值 '!G24*100,"") | L24: =_xlfn.IFERROR(H24-K24,"") -> 0
B25: 8、柴油加氢精制处理量 | C25: 吨 | D25: =_xlfn.IFERROR(IF('延炼取值 '!D25=0,"",'延炼取值 '!D25),"") | F25: =_xlfn.IFERROR(E25/'延炼取值 '!D25*100,"") | G25: =_xlfn.IFERROR(IF('延炼取值 '!G25=0,"",'延炼取值 '!G25),"") | I25: =_xlfn.IFERROR(H25/'延炼取值 '!G25*100,"") | L25: =_xlfn.IFERROR(H25-K25,"") -> 0
B26: 9、气分装置加工量 | C26: 吨 | D26: 26800 | E26: =_xlfn.IFERROR('延炼取值 '!E26,"") -> 28307 | F26: =_xlfn.IFERROR(E26/'延炼取值 '!D26*100,"") -> 105.62313 | G26: 300000 | H26: =_xlfn.IFERROR('延炼取值 '!H26,"") -> 303202 | I26: =_xlfn.IFERROR(H26/'延炼取值 '!G26*100,"") -> 101.06733 | J26: 29206 | K26: 311265 | L26: =_xlfn.IFERROR(H26-K26,"") -> -8063
B27: 10、航煤装置处理量 | C27: 吨 | D27: =_xlfn.IFERROR(IF('延炼取值 '!D27=0,"",'延炼取值 '!D27),"") | E27: =_xlfn.IFERROR('延炼取值 '!E27,"") -> 29036 | F27: =_xlfn.IFERROR(E27/'延炼取值 '!D27*100,"") | G27: 157422 | H27: =_xlfn.IFERROR('延炼取值 '!H27,"") -> 193268 | I27: =_xlfn.IFERROR(H27/'延炼取值 '!G27*100,"") -> 122.77064 | J27: 8195 | K27: 238896 | L27: =_xlfn.IFERROR(H27-K27,"") -> -45628
B28: 11、烷基化装置处理量 | C28: 吨 | D28: =_xlfn.IFERROR(IF('延炼取值 '!D28=0,"",'延炼取值 '!D28),"") | F28: =_xlfn.IFERROR(E28/'延炼取值 '!D28*100,"") | G28: =_xlfn.IFERROR(IF('延炼取值 '!G28=0,"",'延炼取值 '!G28),"") | I28: =_xlfn.IFERROR(H28/'延炼取值 '!G28*100,"") | L28: =_xlfn.IFERROR(H28-K28,"") -> 0
B29: 12、混合脱氢装置处理量 | C29: 吨 | D29: =_xlfn.IFERROR(IF('延炼取值 '!D29=0,"",'延炼取值 '!D29),"") | F29: =_xlfn.IFERROR(E29/'延炼取值 '!D29*100,"") | G29: =_xlfn.IFERROR(IF('延炼取值 '!G29=0,"",'延炼取值 '!G29),"") | I29: =_xlfn.IFERROR(H29/'延炼取值 '!G29*100,"") | L29: =_xlfn.IFERROR(H29-K29,"") -> 0
B30: 二、油气产品产销量 | M30: 汽油
B31: 1、汽油产量 | C31: 吨 | D31: 253000 | E31: =_xlfn.IFERROR('延炼取值 '!E31,"") -> 239897 | F31: =_xlfn.IFERROR(E31/'延炼取值 '!D31*100,"") -> 94.820949 | G31: 2656714 | H31: =_xlfn.IFERROR('延炼取值 '!H31,"") -> 2874458 | I31: =_xlfn.IFERROR(H31/'延炼取值 '!G31*100,"") -> 108.19599 | J31: 252437 | K31: 2814746 | L31: =_xlfn.IFERROR(H31-K31,"") -> 59712 | M31: =E31 -> 239897 | N31: =H31 -> 2874458
B32: ⑴ 92#VI | C32: 吨 | D32: =_xlfn.IFERROR(IF('延炼取值 '!D32=0,"",'延炼取值 '!D32),"") | E32: =_xlfn.IFERROR('延炼取值 '!E32,"") -> 135789 | F32: =_xlfn.IFERROR(E32/'延炼取值 '!D32*100,"") | G32: 1770198 | H32: =_xlfn.IFERROR('延炼取值 '!H32,"") -> 1660222 | I32: =_xlfn.IFERROR(H32/'延炼取值 '!G32*100,"") -> 93.787362 | J32: 152029 | K32: 1766975 | L32: =_xlfn.IFERROR(H32-K32,"") -> -106753
B33: ⑵ 95#VI | C33: 吨 | D33: =_xlfn.IFERROR(IF('延炼取值 '!D33=0,"",'延炼取值 '!D33),"") | E33: =_xlfn.IFERROR('延炼取值 '!E33,"") -> 104108 | F33: =_xlfn.IFERROR(E33/'延炼取值 '!D33*100,"") | G33: 864200 | H33: =_xlfn.IFERROR('延炼取值 '!H33,"") -> 1191274 | I33: =_xlfn.IFERROR(H33/'延炼取值 '!G33*100,"") -> 137.84703 | J33: 98185 | K33: 1026709 | L33: =_xlfn.IFERROR(H33-K33,"") -> 164565
B34: ⑶ 98#Ⅵ | C34: 吨 | D34: =_xlfn.IFERROR(IF('延炼取值 '!D34=0,"",'延炼取值 '!D34),"") | E34: =_xlfn.IFERROR('延炼取值 '!E34,"") -> 0 | F34: =_xlfn.IFERROR(E34/'延炼取值 '!D34*100,"") | G34: =_xlfn.IFERROR(IF('延炼取值 '!G34=0,"",'延炼取值 '!G34),"") | H34: =_xlfn.IFERROR('延炼取值 '!H34,"") -> 22962 | I34: =_xlfn.IFERROR(H34/'延炼取值 '!G34*100,"") | J34: 2223 | K34: 21062 | L34: =_xlfn.IFERROR(H34-K34,"") -> 1900 | M34: 柴油
B35: 2、柴油产量 | C35: 吨 | D35: 200000 | E35: =_xlfn.IFERROR('延炼取值 '!E35,"") -> 194670 | F35: =_xlfn.IFERROR(E35/'延炼取值 '!D35*100,"") -> 97.335 | G35: 2577462 | H35: =_xlfn.IFERROR('延炼取值 '!H35,"") -> 2388739 | I35: =_xlfn.IFERROR(H35/'延炼取值 '!G35*100,"") -> 92.677952 | J35: 158779 | K35: 2366904 | L35: =_xlfn.IFERROR(H35-K35,"") -> 21835 | M35: =E35 -> 194670 | N35: =H35 -> 2388739
B36: ⑴ 军用柴油 | C36: 吨 | D36: =_xlfn.IFERROR(IF('延炼取值 '!D36=0,"",'延炼取值 '!D36),"") | F36: =_xlfn.IFERROR(E36/'延炼取值 '!D36*100,"") | G36: =_xlfn.IFERROR(IF('延炼取值 '!G36=0,"",'延炼取值 '!G36),"") | I36: =_xlfn.IFERROR(H36/'延炼取值 '!G36*100,"") | L36: =_xlfn.IFERROR(H36-K36,"") -> 0
B37: ⑵ 0#VI | C37: 吨 | D37: =_xlfn.IFERROR(IF('延炼取值 '!D37=0,"",'延炼取值 '!D37),"") | E37: =_xlfn.IFERROR('延炼取值 '!E37,"") -> 194670 | F37: =_xlfn.IFERROR(E37/'延炼取值 '!D37*100,"") | G37: =_xlfn.IFERROR(IF('延炼取值 '!G37=0,"",'延炼取值 '!G37),"") | H37: =_xlfn.IFERROR('延炼取值 '!H37,"") -> 2388739 | I37: =_xlfn.IFERROR(H37/'延炼取值 '!G37*100,"") | J37: 158779 | K37: 2366904 | L37: =_xlfn.IFERROR(H37-K37,"") -> 21835
B38: ⑶ -10#VI | C38: 吨 | D38: =_xlfn.IFERROR(IF('延炼取值 '!D38=0,"",'延炼取值 '!D38),"") | E38: =_xlfn.IFERROR('延炼取值 '!E38,"") -> 0 | F38: =_xlfn.IFERROR(E38/'延炼取值 '!D38*100,"") | G38: =_xlfn.IFERROR(IF('延炼取值 '!G38=0,"",'延炼取值 '!G38),"") | H38: =_xlfn.IFERROR('延炼取值 '!H38,"") -> 0 | I38: =_xlfn.IFERROR(H38/'延炼取值 '!G38*100,"") | J38: 0 | K38: 0 | L38: =_xlfn.IFERROR(H38-K38,"") -> 0
B39: ⑷ -20#VI | C39: 吨 | D39: =_xlfn.IFERROR(IF('延炼取值 '!D39=0,"",'延炼取值 '!D39),"") | F39: =_xlfn.IFERROR(E39/'延炼取值 '!D39*100,"") | G39: =_xlfn.IFERROR(IF('延炼取值 '!G39=0,"",'延炼取值 '!G39),"") | I39: =_xlfn.IFERROR(H39/'延炼取值 '!G39*100,"") | L39: =_xlfn.IFERROR(H39-K39,"") -> 0
B40: ⑸ -35#VI | C40: 吨 | D40: =_xlfn.IFERROR(IF('延炼取值 '!D40=0,"",'延炼取值 '!D40),"") | F40: =_xlfn.IFERROR(E40/'延炼取值 '!D40*100,"") | G40: =_xlfn.IFERROR(IF('延炼取值 '!G40=0,"",'延炼取值 '!G40),"") | I40: =_xlfn.IFERROR(H40/'延炼取值 '!G40*100,"") | L40: =_xlfn.IFERROR(H40-K40,"") -> 0
...

Sheet 延炼取值 
B1: 炼化公司生产月报表（延炼）
B2: 填报单位：炼化公司 | J2: 陕油统 炼化B-401
B3: 指标名称 | C3: 单位 | D3: 本月生产 | G3: 本年生产 | J3: 去年同期 | L3: 同比 增长
D4: 月计划 | E4: 月完成 | F4: 完成率% | G4: 年计划 | H4: 年完成 | I4: 完成率% | J4: 本月 | K4: 本年
B5: 一、装置加工量
B6: 1、原料油（气）加工量 | C6: 吨
B7: 其中：原油 | C7: 吨 | D7: 525000 | E7: =E98 -> 488629 | F7: =E7/#REF!*100 | G7: 6300000 | H7: =H98 -> 5829379 | I7: =H7/#REF!*100 | J7: =J16 -> 466526 | K7: =K16 -> 5775191 | L7: =H7-K7 -> 54188
B8: 甲醇 | C8: 吨 | D8: 1300 | E8: =E100 -> 1492.96 | F8: =E8/#REF!*100 | G8: 15256 | H8: =H100 -> 13575.24 | I8: =H8/#REF!*100 | J8: =J100 -> 1418.46 | K8: =K100 -> 14243.22 | L8: =H8-K8 -> -667.98
B9: MTBE | C9: 吨 | D9: 3000 | E9: =E102 -> 0 | H9: =H102 -> 9400.16 | J9: =J102 -> 0 | K9: =K102 -> 0 | L9: =H9-K9 -> 9400.16
B10: 1#渣油 | C10: 吨
B11: 裂解石脑油 | C11: 吨
B12: 上古液化气 | C12: 吨 | E12: =E104 -> 0 | H12: =H104 -> 0 | J12: =J104 -> 0 | K12: =K104 -> 0
B13: 醋酸 | C13: 吨 | D13: 2200 | E13: =E106 -> 2787 | F13: =E13/#REF!*100 | G13: 30625 | H13: =H106 -> 25213 | I13: =H13/#REF!*100 | J13: =J106 -> 2897 | K13: =K106 -> 29727 | L13: =H13-K13 -> -4514
B14: 异辛烷组分 | C14: 吨 | L14: =H14-K14 -> 0
B15: 异丁烷 | C15: 吨
B16: 2、常压装置加工量 | C16: 吨 | E16: =E96 -> 488629 | H16: =H96 -> 5829379 | J16: =J96 -> 466526 | K16: =K96 -> 5775191
B17: 原油加工量 | C17: 吨 | D17: 525000 | E17: =E7 -> 488629 | F17: =E17/#REF!*100 | G17: 6300000 | H17: =H7 -> 5829379 | I17: =H17/#REF!*100 | J17: =J16 -> 466526 | K17: =K16 -> 5775191 | L17: =H17-K17 -> 54188
B18: 其中：进口原油加工量 | C18: 吨 | H18: =H223 -> 0 | J18: =J223 -> 0 | K18: =K223 -> 0
B19: 3、催化装置加工量 | C19: 吨 | E19: =_xlfn.IFERROR(E108,"") -> 252896 | H19: =_xlfn.IFERROR(H108,"") -> 2967443 | J19: =_xlfn.IFERROR(J108,"") -> 261377 | K19: =_xlfn.IFERROR(K108,"") -> 2949656 | L19: =H19-K19 -> 17787
B20: 其中：1#渣油加工量 | C20: 吨 | D20: 260000 | E20: =_xlfn.IFERROR(E110,"") -> 251400 | F20: =E20/#REF!*100 | G20: 3080000 | H20: =_xlfn.IFERROR(H110,"") -> 2974069 | I20: =H20/#REF!*100 | J20: =_xlfn.IFERROR(J110,"") -> 260435 | K20: =_xlfn.IFERROR(K110,"") -> 2936284 | L20: =H20-K20 -> 37785
B21: 4、重整装置处理量 | C21: 吨
B22: 5、DCC石脑油加氢处理量 | C22: 吨
B23: 6、DCC裂解轻油加氢处理量 | C23: 吨
B24: 7、汽油加氢精制处理量 | C24: 吨
B25: 8、柴油加氢精制处理量 | C25: 吨
B26: 9、气分装置加工量 | C26: 吨 | D26: 26800 | E26: =E113 -> 28307 | F26: =E26/#REF!*100 | G26: 300000 | H26: =H113 -> 303202 | I26: =H26/#REF!*100 | J26: =J113 -> 29206 | K26: =K113 -> 311265 | L26: =H26-K26 -> -8063
B27: 10、航煤装置处理量 | C27: 吨 | E27: =E115 -> 29036 | G27: 157422 | H27: =H115 -> 193268 | J27: =J115 -> 8195 | K27: =K115 -> 238896
B28: 11、烷基化装置处理量 | C28: 吨
B29: 12、混合脱氢装置处理量 | C29: 吨
B30: 二、油气产品产销量
B31: 1、汽油产量 | C31: 吨 | D31: 253000 | E31: =E32+E33+E34 -> 239897 | F31: =E31/#REF!*100 | G31: 2656714 | H31: =H32+H33+H34 -> 2874458 | I31: =H31/#REF!*100 | J31: =J32+J33+J34 -> 252437 | K31: =K32+K33+K34 -> 2814746 | L31: =H31-K31 -> 59712
B32: ⑴ 92#VI | C32: 吨 | E32: =E118 -> 135789 | F32: =E32/#REF!*100 | G32: 1770198 | H32: =H118 -> 1660222 | I32: =H32/#REF!*100 | J32: =J118 -> 152029 | K32: =K118 -> 1766975 | L32: =H32-K32 -> -106753
B33: ⑵ 95#VI | C33: 吨 | E33: =E119 -> 104108 | F33: =E33/#REF!*100 | G33: 864200 | H33: =H119 -> 1191274 | I33: =H33/#REF!*100 | J33: =J119 -> 98185 | K33: =K119 -> 1026709 | L33: =H33-K33 -> 164565
B34: ⑶ 98#Ⅵ | C34: 吨 | E34: =E117 -> 0 | H34: =H117 -> 22962 | J34: =J117 -> 2223 | K34: =K117 -> 21062 | L34: =H34-K34 -> 1900
B35: 2、柴油产量 | C35: 吨 | D35: 200000 | E35: =E36+E37+E38+E39+E40 -> 194670 | F35: =E35/#REF!*100 | G35: 2577462 | H35: =H36+H37+H38+H39+H40 -> 2388739 | I35: =H35/#REF!*100 | J35: =J36+J37+J38+J39+J40 -> 158779 | K35: =K36+K37+K38+K39+K40 -> 2366904 | L35: =H35-K35 -> 21835
B36: ⑴ 军用柴油 | C36: 吨 | L36: =H36-K36 -> 0
B37: ⑵ 0#VI | C37: 吨 | E37: =E121 -> 194670 | H37: =H121 -> 2388739 | J37: =SUM(J121:J122) -> 158779 | K37: =SUM(K121:K122) -> 2366904 | L37: =H37-K37 -> 21835
B38: ⑶ -10#VI | C38: 吨 | E38: =E123 -> 0 | H38: =H123 -> 0 | J38: =J123 -> 0 | K38: =K123 -> 0 | L38: =H38-K38 -> 0
B39: ⑷ -20#VI | C39: 吨
B40: ⑸ -35#VI | C40: 吨
...

Sheet 永炼月报表
B1: 炼化公司生产月报表（永炼）
B2: 填报单位：炼化公司 | C2: 2025-11 | J2: 陕油统 炼化B-401
B3: 指标名称 | C3: 单位 | D3: 本月生产 | G3: 本年生产 | J3: 去年同期 | L3: 同比 增长
D4: 月计划 | E4: 月完成 | F4: 完成率% | G4: 年计划 | H4: 年完成 | I4: 完成率% | J4: 本月 | K4: 本年
B5: 一、装置加工量
B6: 1、原料油（气）加工量 | C6: 吨 | D6: =_xlfn.IFERROR(IF(永炼取值!D6=0,"",永炼取值!D6),"") | E6: =_xlfn.IFERROR(SUM(E7:E15),"") -> 252702 | G6: =_xlfn.IFERROR(IF(永炼取值!G6=0,"",永炼取值!G6),"") | H6: =_xlfn.IFERROR(SUM(H7:H15),"") -> 3509085 | J6: 330770 | K6: 2978885 | L6: =_xlfn.IFERROR(H6-K6,"") -> 530200
B7: 其中：原油 | C7: 吨 | D7: 240000 | E7: =_xlfn.IFERROR(永炼取值!E7,"") -> 252343 | F7: =_xlfn.IFERROR(E7/永炼取值!D7*100,"") -> 105.14292 | G7: 3700000 | H7: =_xlfn.IFERROR(永炼取值!H7,"") -> 3486701 | I7: =_xlfn.IFERROR(H7/永炼取值!G7*100,"") -> 94.235162 | J7: 330378 | K7: 2974894 | L7: =_xlfn.IFERROR(H7-K7,"") -> 511807
B8: 甲醇 | C8: 吨 | D8: =_xlfn.IFERROR(IF(永炼取值!D8=0,"",永炼取值!D8),"") | F8: =_xlfn.IFERROR(E8/永炼取值!D8*100,"") | G8: =_xlfn.IFERROR(IF(永炼取值!G8=0,"",永炼取值!G8),"") | I8: =_xlfn.IFERROR(H8/永炼取值!G8*100,"") | L8: =_xlfn.IFERROR(H8-K8,"") -> 0
B9: MTBE | C9: 吨 | D9: =_xlfn.IFERROR(IF(永炼取值!D9=0,"",永炼取值!D9),"") | E9: =_xlfn.IFERROR(永炼取值!E9,"") -> 359 | F9: =_xlfn.IFERROR(E9/永炼取值!D9*100,"") | G9: 20000 | H9: =_xlfn.IFERROR(永炼取值!H9,"") -> 22384 | I9: =_xlfn.IFERROR(H9/永炼取值!G9*100,"") -> 111.92 | J9: 392 | K9: 3991 | L9: =_xlfn.IFERROR(H9-K9,"") -> 18393
B10: 1#渣油 | C10: 吨 | D10: =_xlfn.IFERROR(IF(永炼取值!D10=0,"",永炼取值!D10),"") | F10: =_xlfn.IFERROR(E10/永炼取值!D10*100,"") | G10: =_xlfn.IFERROR(IF(永炼取值!G10=0,"",永炼取值!G10),"") | I10: =_xlfn.IFERROR(H10/永炼取值!G10*100,"") | L10: =_xlfn.IFERROR(H10-K10,"") -> 0
B11: 裂解石脑油 | C11: 吨 | D11: =_xlfn.IFERROR(IF(永炼取值!D11=0,"",永炼取值!D11),"") | F11: =_xlfn.IFERROR(E11/永炼取值!D11*100,"") | G11: =_xlfn.IFERROR(IF(永炼取值!G11=0,"",永炼取值!G11),"") | I11: =_xlfn.IFERROR(H11/永炼取值!G11*100,"") | L11: =_xlfn.IFERROR(H11-K11,"") -> 0
B12: 上古液化气 | C12: 吨 | D12: =_xlfn.IFERROR(IF(永炼取值!D12=0,"",永炼取值!D12),"") | E12: =_xlfn.IFERROR(永炼取值!E12,"") -> 0 | F12: =_xlfn.IFERROR(E12/永炼取值!D12*100,"") | G12: =_xlfn.IFERROR(IF(永炼取值!G12=0,"",永炼取值!G12),"") | H12: =_xlfn.IFERROR(永炼取值!H12,"") -> 0 | I12: =_xlfn.IFERROR(H12/永炼取值!G12*100,"") | J12: 0 | K12: 0 | L12: =_xlfn.IFERROR(H12-K12,"") -> 0
B13: 醋酸 | C13: 吨 | D13: =_xlfn.IFERROR(IF(永炼取值!D13=0,"",永炼取值!D13),"") | E13: =_xlfn.IFERROR(永炼取值!E13,"") -> 0 | F13: =_xlfn.IFERROR(E13/永炼取值!D13*100,"") | G13: =_xlfn.IFERROR(IF(永炼取值!G13=0,"",永炼取值!G13),"") | I13: =_xlfn.IFERROR(H13/永炼取值!G13*100,"") | J13: 0 | L13: =_xlfn.IFERROR(H13-K13,"") -> 0
B14: 异辛烷组分 | C14: 吨 | D14: =_xlfn.IFERROR(IF(永炼取值!D14=0,"",永炼取值!D14),"") | E14: =_xlfn.IFERROR(永炼取值!E14,"") -> 0 | F14: =_xlfn.IFERROR(E14/永炼取值!D14*100,"") | G14: =_xlfn.IFERROR(IF(永炼取值!G14=0,"",永炼取值!G14),"") | H14: =_xlfn.IFERROR(永炼取值!H14,"") -> 0 | I14: =_xlfn.IFERROR(H14/永炼取值!G14*100,"") | J14: 0 | K14: 0 | L14: =_xlfn.IFERROR(H14-K14,"") -> 0
B15: 异丁烷 | C15: 吨 | D15: =_xlfn.IFERROR(IF(永炼取值!D15=0,"",永炼取值!D15),"") | F15: =_xlfn.IFERROR(E15/永炼取值!D15*100,"") | G15: =_xlfn.IFERROR(IF(永炼取值!G15=0,"",永炼取值!G15),"") | I15: =_xlfn.IFERROR(H15/永炼取值!G15*100,"") | L15: =_xlfn.IFERROR(H15-K15,"") -> 0
B16: 2、常压装置加工量 | C16: 吨 | D16: =_xlfn.IFERROR(IF(永炼取值!D16=0,"",永炼取值!D16),"") | E16: =_xlfn.IFERROR(永炼取值!E16,"") -> 252343 | F16: =_xlfn.IFERROR(E16/永炼取值!D16*100,"") | G16: =_xlfn.IFERROR(IF(永炼取值!G16=0,"",永炼取值!G16),"") | H16: =_xlfn.IFERROR(永炼取值!H16,"") -> 3486701 | I16: =_xlfn.IFERROR(H16/永炼取值!G16*100,"") | J16: 330378 | K16: 2974894 | L16: =_xlfn.IFERROR(H16-K16,"") -> 511807 | M16: 原油
B17: 原油加工量 | C17: 吨 | D17: 240000 | E17: =_xlfn.IFERROR(永炼取值!E17,"") -> 252343 | F17: =_xlfn.IFERROR(E17/永炼取值!D17*100,"") -> 105.14292 | G17: 3700000 | H17: =_xlfn.IFERROR(永炼取值!H17,"") -> 3486701 | I17: =_xlfn.IFERROR(H17/永炼取值!G17*100,"") -> 94.235162 | J17: 330378 | K17: 2974894 | L17: =_xlfn.IFERROR(H17-K17,"") -> 511807 | M17: =E17 -> 252343 | N17: =H17 -> 3486701
B18: 其中：进口原油加工量 | C18: 吨 | D18: =_xlfn.IFERROR(IF(永炼取值!D18=0,"",永炼取值!D18),"") | E18: =_xlfn.IFERROR(永炼取值!E18,"") -> 0 | F18: =_xlfn.IFERROR(E18/永炼取值!D18*100,"") | G18: =_xlfn.IFERROR(IF(永炼取值!G18=0,"",永炼取值!G18),"") | H18: =_xlfn.IFERROR(永炼取值!H18,"") -> 0 | I18: =_xlfn.IFERROR(H18/永炼取值!G18*100,"") | J18: 0 | K18: 0 | L18: =_xlfn.IFERROR(H18-K18,"") -> 0
B19: 3、催化装置加工量 | C19: 吨 | D19: =_xlfn.IFERROR(IF(永炼取值!D19=0,"",永炼取值!D19),"") | E19: =_xlfn.IFERROR(永炼取值!E19,"") -> 103741 | F19: =_xlfn.IFERROR(E19/永炼取值!D19*100,"") | G19: =_xlfn.IFERROR(IF(永炼取值!G19=0,"",永炼取值!G19),"") | H19: =_xlfn.IFERROR(永炼取值!H19,"") -> 1239613 | I19: =_xlfn.IFERROR(H19/永炼取值!G19*100,"") | J19: 115149 | K19: 953245 | L19: =_xlfn.IFERROR(H19-K19,"") -> 286368
B20: 其中：1#渣油加工量 | C20: 吨 | D20: 96000 | E20: =_xlfn.IFERROR(永炼取值!E20,"") -> 96093 | F20: =_xlfn.IFERROR(E20/永炼取值!D20*100,"") -> 100.09687 | G20: 1120000 | H20: =_xlfn.IFERROR(永炼取值!H20,"") -> 1140974 | I20: =_xlfn.IFERROR(H20/永炼取值!G20*100,"") -> 101.87268 | J20: 109008 | K20: 899933 | L20: =_xlfn.IFERROR(H20-K20,"") -> 241041 | M20: =E20 -> 96093 | N20: =H20 -> 1140974
B21: 4、重整装置处理量 | C21: 吨 | D21: 16500 | E21: =_xlfn.IFERROR(永炼取值!E21,"") -> 18360 | F21: =_xlfn.IFERROR(E21/永炼取值!D21*100,"") -> 111.27273 | G21: 190000 | H21: =_xlfn.IFERROR(永炼取值!H21,"") -> 208122 | I21: =_xlfn.IFERROR(H21/永炼取值!G21*100,"") -> 109.53789 | J21: 18222 | K21: 168339 | L21: =_xlfn.IFERROR(H21-K21,"") -> 39783
B22: 5、DCC石脑油加氢处理量 | C22: 吨 | D22: =_xlfn.IFERROR(IF(永炼取值!D22=0,"",永炼取值!D22),"") | E22: =_xlfn.IFERROR(永炼取值!E22,"") -> 0 | F22: =_xlfn.IFERROR(E22/永炼取值!D22*100,"") | G22: =_xlfn.IFERROR(IF(永炼取值!G22=0,"",永炼取值!G22),"") | H22: =_xlfn.IFERROR(永炼取值!H22,"") -> 0 | I22: =_xlfn.IFERROR(H22/永炼取值!G22*100,"") | J22: 0 | K22: 0 | L22: =_xlfn.IFERROR(H22-K22,"") -> 0
B23: 6、DCC裂解轻油加氢处理量 | C23: 吨 | D23: =_xlfn.IFERROR(IF(永炼取值!D23=0,"",永炼取值!D23),"") | E23: =_xlfn.IFERROR(永炼取值!E23,"") -> 0 | F23: =_xlfn.IFERROR(E23/永炼取值!D23*100,"") | G23: =_xlfn.IFERROR(IF(永炼取值!G23=0,"",永炼取值!G23),"") | H23: =_xlfn.IFERROR(永炼取值!H23,"") -> 0 | I23: =_xlfn.IFERROR(H23/永炼取值!G23*100,"") | J23: 0 | K23: 0 | L23: =_xlfn.IFERROR(H23-K23,"") -> 0
B24: 7、汽油加氢精制处理量 | C24: 吨 | D24: 47000 | E24: =_xlfn.IFERROR(永炼取值!E24,"") -> 50846 | F24: =_xlfn.IFERROR(E24/永炼取值!D24*100,"") -> 108.18298 | G24: 550000 | H24: =_xlfn.IFERROR(永炼取值!H24,"") -> 610823 | I24: =_xlfn.IFERROR(H24/永炼取值!G24*100,"") -> 111.05873 | J24: 55968 | K24: 478921 | L24: =_xlfn.IFERROR(H24-K24,"") -> 131902
B25: 8、柴油加氢精制处理量 | C25: 吨 | D25: 90000 | E25: =_xlfn.IFERROR(永炼取值!E25,"") -> 101000 | F25: =_xlfn.IFERROR(E25/永炼取值!D25*100,"") -> 112.22222 | G25: 1330000 | H25: =_xlfn.IFERROR(永炼取值!H25,"") -> 1302390 | I25: =_xlfn.IFERROR(H25/永炼取值!G25*100,"") -> 97.92406 | J25: 123978 | K25: 1079507 | L25: =_xlfn.IFERROR(H25-K25,"") -> 222883
B26: 9、气分装置加工量 | C26: 吨 | D26: =_xlfn.IFERROR(IF(永炼取值!D26=0,"",永炼取值!D26),"") | E26: =_xlfn.IFERROR(永炼取值!E26,"") -> 0 | F26: =_xlfn.IFERROR(E26/永炼取值!D26*100,"") | G26: =_xlfn.IFERROR(IF(永炼取值!G26=0,"",永炼取值!G26),"") | H26: =_xlfn.IFERROR(永炼取值!H26,"") -> 0 | I26: =_xlfn.IFERROR(H26/永炼取值!G26*100,"") | J26: 0 | K26: 0 | L26: =_xlfn.IFERROR(H26-K26,"") -> 0
B27: 10、航煤装置处理量 | C27: 吨 | D27: =_xlfn.IFERROR(IF(永炼取值!D27=0,"",永炼取值!D27),"") | E27: =_xlfn.IFERROR(永炼取值!E27,"") -> 13271 | F27: =_xlfn.IFERROR(E27/永炼取值!D27*100,"") | G27: 105263 | H27: =_xlfn.IFERROR(永炼取值!H27,"") -> 166965 | I27: =_xlfn.IFERROR(H27/永炼取值!G27*100,"") -> 158.61699 | J27: 12597 | K27: 127693 | L27: =_xlfn.IFERROR(H27-K27,"") -> 39272
B28: 11、烷基化装置处理量 | C28: 吨 | D28: =_xlfn.IFERROR(IF(永炼取值!D28=0,"",永炼取值!D28),"") | E28: =_xlfn.IFERROR(永炼取值!E28,"") -> 0 | F28: =_xlfn.IFERROR(E28/永炼取值!D28*100,"") | G28: =_xlfn.IFERROR(IF(永炼取值!G28=0,"",永炼取值!G28),"") | H28: =_xlfn.IFERROR(永炼取值!H28,"") -> 0 | I28: =_xlfn.IFERROR(H28/永炼取值!G28*100,"") | J28: 0 | K28: 0 | L28: =_xlfn.IFERROR(H28-K28,"") -> 0
B29: 12、混合脱氢装置处理量 | C29: 吨 | D29: =_xlfn.IFERROR(IF(永炼取值!D29=0,"",永炼取值!D29),"") | E29: =_xlfn.IFERROR(永炼取值!E29,"") -> 0 | F29: =_xlfn.IFERROR(E29/永炼取值!D29*100,"") | G29: =_xlfn.IFERROR(IF(永炼取值!G29=0,"",永炼取值!G29),"") | H29: =_xlfn.IFERROR(永炼取值!H29,"") -> 0 | I29: =_xlfn.IFERROR(H29/永炼取值!G29*100,"") | J29: 0 | K29: 0 | L29: =_xlfn.IFERROR(H29-K29,"") -> 0
B30: 二、油气产品产销量 | M30: 汽油
B31: 1、汽油产量 | C31: 吨 | D31: 76000 | E31: =_xlfn.IFERROR(永炼取值!E31,"") -> 76027 | F31: =_xlfn.IFERROR(E31/永炼取值!D31*100,"") -> 100.03553 | G31: 660810 | H31: =_xlfn.IFERROR(永炼取值!H31,"") -> 889792 | I31: =_xlfn.IFERROR(H31/永炼取值!G31*100,"") -> 134.65172 | J31: 79776 | K31: 695518 | L31: =_xlfn.IFERROR(H31-K31,"") -> 194274 | M31: =E31 -> 76027 | N31: =H31 -> 889792
B32: ⑴ 92#VI | C32: 吨 | D32: =_xlfn.IFERROR(IF(永炼取值!D32=0,"",永炼取值!D32),"") | E32: =_xlfn.IFERROR(永炼取值!E32,"") -> 76027 | F32: =_xlfn.IFERROR(E32/永炼取值!D32*100,"") | G32: 660810 | H32: =_xlfn.IFERROR(永炼取值!H32,"") -> 889792 | I32: =_xlfn.IFERROR(H32/永炼取值!G32*100,"") -> 134.65172 | J32: 79776 | K32: 695518 | L32: =_xlfn.IFERROR(H32-K32,"") -> 194274
B33: ⑵ 95#VI | C33: 吨 | D33: =_xlfn.IFERROR(IF(永炼取值!D33=0,"",永炼取值!D33),"") | E33: =_xlfn.IFERROR(永炼取值!E33,"") -> 0 | F33: =_xlfn.IFERROR(E33/永炼取值!D33*100,"") | G33: =_xlfn.IFERROR(IF(永炼取值!G33=0,"",永炼取值!G33),"") | H33: =_xlfn.IFERROR(永炼取值!H33,"") -> 0 | I33: =_xlfn.IFERROR(H33/永炼取值!G33*100,"") | J33: 0 | K33: 0 | L33: =_xlfn.IFERROR(H33-K33,"") -> 0
B34: ⑶ 98#Ⅵ | C34: 吨 | D34: =_xlfn.IFERROR(IF(永炼取值!D34=0,"",永炼取值!D34),"") | E34: =_xlfn.IFERROR(永炼取值!E34,"") -> 0 | F34: =_xlfn.IFERROR(E34/永炼取值!D34*100,"") | G34: =_xlfn.IFERROR(IF(永炼取值!G34=0,"",永炼取值!G34),"") | H34: =_xlfn.IFERROR(永炼取值!H34,"") -> 0 | I34: =_xlfn.IFERROR(H34/永炼取值!G34*100,"") | J34: 0 | K34: 0 | L34: =_xlfn.IFERROR(H34-K34,"") -> 0 | M34: 柴油
B35: 2、柴油产量 | C35: 吨 | D35: 81000 | E35: =_xlfn.IFERROR(永炼取值!E35,"") -> 94831 | F35: =_xlfn.IFERROR(E35/永炼取值!D35*100,"") -> 117.07531 | G35: 1270429 | H35: =_xlfn.IFERROR(永炼取值!H35,"") -> 1242223 | I35: =_xlfn.IFERROR(H35/永炼取值!G35*100,"") -> 97.779805 | J35: 112486 | K35: 999335 | L35: =_xlfn.IFERROR(H35-K35,"") -> 242888 | M35: =E35 -> 94831 | N35: =H35 -> 1242223
B36: ⑴ 军用柴油 | C36: 吨 | D36: =_xlfn.IFERROR(IF(永炼取值!D36=0,"",永炼取值!D36),"") | E36: =_xlfn.IFERROR(永炼取值!E36,"") -> 0 | F36: =_xlfn.IFERROR(E36/永炼取值!D36*100,"") | G36: =_xlfn.IFERROR(IF(永炼取值!G36=0,"",永炼取值!G36),"") | H36: =_xlfn.IFERROR(永炼取值!H36,"") -> 0 | I36: =_xlfn.IFERROR(H36/永炼取值!G36*100,"") | J36: 0 | K36: 0 | L36: =_xlfn.IFERROR(H36-K36,"") -> 0
B37: ⑵ 0#VI | C37: 吨 | D37: =_xlfn.IFERROR(IF(永炼取值!D37=0,"",永炼取值!D37),"") | E37: =_xlfn.IFERROR(永炼取值!E37,"") -> 69912 | F37: =_xlfn.IFERROR(E37/永炼取值!D37*100,"") | G37: =_xlfn.IFERROR(IF(永炼取值!G37=0,"",永炼取值!G37),"") | H37: =_xlfn.IFERROR(永炼取值!H37,"") -> 1179895 | I37: =_xlfn.IFERROR(H37/永炼取值!G37*100,"") | J37: 92630 | K37: 946077 | L37: =_xlfn.IFERROR(H37-K37,"") -> 233818
B38: ⑶ -10#VI | C38: 吨 | D38: =_xlfn.IFERROR(IF(永炼取值!D38=0,"",永炼取值!D38),"") | E38: =_xlfn.IFERROR(永炼取值!E38,"") -> 0 | F38: =_xlfn.IFERROR(E38/永炼取值!D38*100,"") | G38: =_xlfn.IFERROR(IF(永炼取值!G38=0,"",永炼取值!G38),"") | H38: =_xlfn.IFERROR(永炼取值!H38,"") -> 0 | I38: =_xlfn.IFERROR(H38/永炼取值!G38*100,"") | J38: 0 | K38: 0 | L38: =_xlfn.IFERROR(H38-K38,"") -> 0
B39: ⑷ -20#VI | C39: 吨 | D39: 20000 | E39: =_xlfn.IFERROR(永炼取值!E39,"") -> 24919 | F39: =_xlfn.IFERROR(E39/永炼取值!D39*100,"") -> 124.595 | G39: =_xlfn.IFERROR(IF(永炼取值!G39=0,"",永炼取值!G39),"") | H39: =_xlfn.IFERROR(永炼取值!H39,"") -> 62328 | I39: =_xlfn.IFERROR(H39/永炼取值!G39*100,"") | J39: 19856 | K39: 53258 | L39: =_xlfn.IFERROR(H39-K39,"") -> 9070
B40: ⑸ -35#VI | C40: 吨 | D40: =_xlfn.IFERROR(IF(永炼取值!D40=0,"",永炼取值!D40),"") | E40: =_xlfn.IFERROR(永炼取值!E40,"") -> 0 | F40: =_xlfn.IFERROR(E40/永炼取值!D40*100,"") | G40: =_xlfn.IFERROR(IF(永炼取值!G40=0,"",永炼取值!G40),"") | H40: =_xlfn.IFERROR(永炼取值!H40,"") -> 0 | I40: =_xlfn.IFERROR(H40/永炼取值!G40*100,"") | J40: 0 | K40: 0 | L40: =_xlfn.IFERROR(H40-K40,"") -> 0
...

Sheet 永炼取值
B1: 炼化公司生产月报表（永炼）
B2: 填报单位：炼化公司 | C2: =#REF! | J2: 陕油统 炼化B-401
B3: 指标名称 | C3: 单位 | D3: 本月生产 | G3: 本年生产 | J3: 去年同期 | L3: 同比 增长
D4: 月计划 | E4: 月完成 | F4: 完成率% | G4: 年计划 | H4: 年完成 | I4: 完成率% | J4: 本月 | K4: 本年
B5: 一、装置加工量
B6: 1、原料油（气）加工量 | C6: 吨
B7: 其中：原油 | C7: 吨 | D7: 240000 | E7: =E96 -> 252343 | F7: =E7/#REF!*100 | G7: 3700000 | H7: =H96 -> 3486701 | I7: =H7/#REF!*100 | J7: =J96 -> 330378 | K7: =K96 -> 2974894 | L7: =H7-K7 -> 511807
B8: 甲醇 | C8: 吨
B9: MTBE | C9: 吨 | E9: =E100 -> 359 | G9: 20000 | H9: =H100 -> 22384 | J9: =J100 -> 392 | K9: =K100 -> 3991 | L9: =H9-K9 -> 18393
B10: 1#渣油 | C10: 吨
B11: 裂解石脑油 | C11: 吨
B12: 上古液化气 | C12: 吨 | E12: =E102 -> 0 | H12: =H102 -> 0 | J12: =J102 -> 0 | K12: =K102 -> 0
B13: 醋酸 | C13: 吨
B14: 异辛烷组分 | C14: 吨 | E14: =E104 -> 0 | H14: =H104 -> 0 | J14: =J104 -> 0 | K14: =K104 -> 0
B15: 异丁烷 | C15: 吨
B16: 2、常压装置加工量 | C16: 吨 | E16: =E98 -> 252343 | H16: =SUM(H98:H99) -> 3486701 | J16: =SUM(J98:J99) -> 330378 | K16: =SUM(K98:K99) -> 2974894
B17: 原油加工量 | C17: 吨 | D17: 240000 | E17: =E16 -> 252343 | F17: =E17/#REF!*100 | G17: 3700000 | H17: =H16 -> 3486701 | I17: =H17/#REF!*100 | J17: =J16 -> 330378 | K17: =K16 -> 2974894 | L17: =H17-K17 -> 511807
B18: 其中：进口原油加工量 | C18: 吨 | H18: =H207 -> 0 | J18: =J207 -> 0 | K18: =K207 -> 0
B19: 3、催化装置加工量 | C19: 吨 | E19: =E106 -> 103741 | H19: =SUM(H106:H107) -> 1239613 | J19: =SUM(J106:J107) -> 115149 | K19: =SUM(K106:K107) -> 953245 | L19: =H19-K19 -> 286368
B20: 其中：1#渣油加工量 | C20: 吨 | D20: 96000 | E20: =E109 -> 96093 | F20: =E20/#REF!*100 | G20: 1120000 | H20: =H109 -> 1140974 | I20: =H20/#REF!*100 | J20: =J109 -> 109008 | K20: =K109 -> 899933 | L20: =H20-K20 -> 241041
B21: 4、重整装置处理量 | C21: 吨 | D21: 16500 | E21: =E111 -> 18360 | F21: =E21/#REF!*100 | G21: 190000 | H21: =H111 -> 208122 | I21: =H21/#REF!*100 | J21: =J111 -> 18222 | K21: =K111 -> 168339 | L21: =H21-K21 -> 39783
B22: 5、DCC石脑油加氢处理量 | C22: 吨
B23: 6、DCC裂解轻油加氢处理量 | C23: 吨
B24: 7、汽油加氢精制处理量 | C24: 吨 | D24: 47000 | E24: =E113 -> 50846 | F24: =E24/#REF!*100 | G24: 550000 | H24: =_xlfn.IFERROR(H113,"") -> 610823 | I24: =H24/#REF!*100 | J24: =J113 -> 55968 | K24: =K113 -> 478921 | L24: =H24-K24 -> 131902
B25: 8、柴油加氢精制处理量 | C25: 吨 | D25: 90000 | E25: =E115 -> 101000 | F25: =E25/#REF!*100 | G25: 1330000 | H25: =SUM(H115:H116) -> 1302390 | I25: =H25/#REF!*100 | J25: =SUM(J115:J116) -> 123978 | K25: =SUM(K115:K116) -> 1079507 | L25: =H25-K25 -> 222883
B26: 9、气分装置加工量 | C26: 吨
B27: 10、航煤装置处理量 | C27: 吨 | E27: =E117 -> 13271 | G27: 105263 | H27: =H117 -> 166965 | I27: =H27/#REF!*100 | J27: =J117 -> 12597 | K27: =K117 -> 127693
B28: 11、烷基化装置处理量 | C28: 吨
B29: 12、混合脱氢装置处理量 | C29: 吨
B30: 二、油气产品产销量
B31: 1、汽油产量 | C31: 吨 | D31: 76000 | E31: =E32+E33+E34 -> 76027 | F31: =E31/#REF!*100 | G31: 660810 | H31: =H32+H33+H34 -> 889792 | I31: =H31/#REF!*100 | J31: =J32+J33+J34 -> 79776 | K31: =K32+K33+K34 -> 695518 | L31: =H31-K31 -> 194274
B32: ⑴ 92#VI | C32: 吨 | E32: =E119 -> 76027 | F32: =E32/#REF!*100 | G32: 660810 | H32: =H119 -> 889792 | I32: =H32/#REF!*100 | J32: =J119 -> 79776 | K32: =K119 -> 695518 | L32: =H32-K32 -> 194274
B33: ⑵ 95#VI | C33: 吨
B34: ⑶ 98#Ⅵ | C34: 吨
B35: 2、柴油产量 | C35: 吨 | D35: 81000 | E35: =E36+E37+E38+E39+E40 -> 94831 | F35: =E35/#REF!*100 | G35: 1270429 | H35: =H36+H37+H38+H39+H40 -> 1242223 | I35: =H35/#REF!*100 | J35: =J36+J37+J38+J39+J40 -> 112486 | K35: =K36+K37+K38+K39+K40 -> 999335 | L35: =H35-K35 -> 242888
B36: ⑴ 军用柴油 | C36: 吨
B37: ⑵ 0#VI | C37: 吨 | E37: =E121 -> 69912 | H37: =SUM(H121:H122) -> 1179895 | I37: =H37/#REF!*100 | J37: =J121 -> 92630 | K37: =K121 -> 946077 | L37: =H37-K37 -> 233818
B38: ⑶ -10#VI | C38: 吨
B39: ⑷ -20#VI | C39: 吨 | D39: 20000 | E39: =E124 -> 24919 | H39: =SUM(H124:H125) -> 62328 | I39: =H39/#REF!*100 | J39: =SUM(J124:J125) -> 19856 | K39: =SUM(K124:K125) -> 53258 | L39: =H39-K39 -> 9070
B40: ⑸ -35#VI | C40: 吨
...

Sheet 榆炼月报表
B1: 炼化公司生产月报表（榆炼）
B2: 填报单位：炼化公司 | C2: 2025-11 | J2: 陕油统 炼化B-401
B3: 指标名称 | C3: 单位 | D3: 本月生产 | G3: 本年生产 | J3: 去年同期 | L3: 同比 增长
D4: 月计划 | E4: 月完成 | F4: 完成率% | G4: 年计划 | H4: 年完成 | I4: 完成率% | J4: 本月 | K4: 本年
B5: 一、装置加工量
B6: 1、原料油（气）加工量 | C6: 吨 | D6: =_xlfn.IFERROR(IF(榆炼取值!D6=0,"",榆炼取值!D6),"") | E6: =_xlfn.IFERROR(SUM(E7:E15),"") -> 556890 | G6: =_xlfn.IFERROR(IF(榆炼取值!G6=0,"",榆炼取值!G6),"") | H6: =_xlfn.IFERROR(SUM(H7:H15),"") -> 4627070 | J6: 438402 | K6: 5230269 | L6: =_xlfn.IFERROR(H6-K6,"") -> -603199
B7: 其中：原油 | C7: 吨 | D7: 515000 | E7: =_xlfn.IFERROR(榆炼取值!E7,"") -> 550368 | F7: =_xlfn.IFERROR(E7/榆炼取值!D7*100,"") -> 106.86757 | G7: 5100000 | H7: =_xlfn.IFERROR(榆炼取值!H7,"") -> 4553852 | I7: =_xlfn.IFERROR(H7/榆炼取值!G7*100,"") -> 89.291216 | J7: 433198 | K7: 5100900 | L7: =_xlfn.IFERROR(H7-K7,"") -> -547048
B8: 甲醇 | C8: 吨 | D8: =_xlfn.IFERROR(IF(榆炼取值!D8=0,"",榆炼取值!D8),"") | E8: =_xlfn.IFERROR(榆炼取值!E8,"") -> 0 | F8: =_xlfn.IFERROR(E8/榆炼取值!D8*100,"") | G8: =_xlfn.IFERROR(IF(榆炼取值!G8=0,"",榆炼取值!G8),"") | H8: =_xlfn.IFERROR(榆炼取值!H8,"") -> 0 | I8: =_xlfn.IFERROR(H8/榆炼取值!G8*100,"") | J8: 0 | K8: 0 | L8: =_xlfn.IFERROR(H8-K8,"") -> 0
B9: MTBE | C9: 吨 | D9: =_xlfn.IFERROR(IF(榆炼取值!D9=0,"",榆炼取值!D9),"") | E9: =_xlfn.IFERROR(榆炼取值!E9,"") -> 6041 | F9: =_xlfn.IFERROR(E9/榆炼取值!D9*100,"") | G9: 40000 | H9: =_xlfn.IFERROR(榆炼取值!H9,"") -> 72737 | I9: =_xlfn.IFERROR(H9/榆炼取值!G9*100,"") -> 181.8425 | J9: 5204 | K9: 63651 | L9: =_xlfn.IFERROR(H9-K9,"") -> 9086
B10: 1#渣油 | C10: 吨 | D10: =_xlfn.IFERROR(IF(榆炼取值!D10=0,"",榆炼取值!D10),"") | E10: =_xlfn.IFERROR(榆炼取值!E10,"") -> 0 | F10: =_xlfn.IFERROR(E10/榆炼取值!D10*100,"") | G10: =_xlfn.IFERROR(IF(榆炼取值!G10=0,"",榆炼取值!G10),"") | H10: =_xlfn.IFERROR(榆炼取值!H10,"") -> 0 | I10: =_xlfn.IFERROR(H10/榆炼取值!G10*100,"") | J10: 0 | K10: 0 | L10: =_xlfn.IFERROR(H10-K10,"") -> 0
B11: 裂解石脑油 | C11: 吨 | D11: =_xlfn.IFERROR(IF(榆炼取值!D11=0,"",榆炼取值!D11),"") | E11: =_xlfn.IFERROR(榆炼取值!E11,"") -> 481 | F11: =_xlfn.IFERROR(E11/榆炼取值!D11*100,"") | G11: =_xlfn.IFERROR(IF(榆炼取值!G11=0,"",榆炼取值!G11),"") | H11: =_xlfn.IFERROR(榆炼取值!H11,"") -> 481 | I11: =_xlfn.IFERROR(H11/榆炼取值!G11*100,"") | J11: 0 | K11: 65718 | L11: =_xlfn.IFERROR(H11-K11,"") -> -65237
B12: 上古液化气 | C12: 吨 | D12: =_xlfn.IFERROR(IF(榆炼取值!D12=0,"",榆炼取值!D12),"") | E12: =_xlfn.IFERROR(榆炼取值!E12,"") -> 0 | F12: =_xlfn.IFERROR(E12/榆炼取值!D12*100,"") | G12: =_xlfn.IFERROR(IF(榆炼取值!G12=0,"",榆炼取值!G12),"") | H12: =_xlfn.IFERROR(榆炼取值!H12,"") -> 0 | I12: =_xlfn.IFERROR(H12/榆炼取值!G12*100,"") | J12: 0 | K12: 0 | L12: =_xlfn.IFERROR(H12-K12,"") -> 0
B13: 醋酸 | C13: 吨 | D13: =_xlfn.IFERROR(IF(榆炼取值!D13=0,"",榆炼取值!D13),"") | E13: =_xlfn.IFERROR(榆炼取值!E13,"") -> 0 | F13: =_xlfn.IFERROR(E13/榆炼取值!D13*100,"") | G13: =_xlfn.IFERROR(IF(榆炼取值!G13=0,"",榆炼取值!G13),"") | H13: =_xlfn.IFERROR(榆炼取值!H13,"") -> 0 | I13: =_xlfn.IFERROR(H13/榆炼取值!G13*100,"") | J13: 0 | K13: 0 | L13: =_xlfn.IFERROR(H13-K13,"") -> 0
B14: 异辛烷组分 | C14: 吨 | D14: =_xlfn.IFERROR(IF(榆炼取值!D14=0,"",榆炼取值!D14),"") | E14: =_xlfn.IFERROR(榆炼取值!E14,"") -> 0 | F14: =_xlfn.IFERROR(E14/榆炼取值!D14*100,"") | G14: =_xlfn.IFERROR(IF(榆炼取值!G14=0,"",榆炼取值!G14),"") | H14: =_xlfn.IFERROR(榆炼取值!H14,"") -> 0 | I14: =_xlfn.IFERROR(H14/榆炼取值!G14*100,"") | J14: 0 | K14: 0 | L14: =_xlfn.IFERROR(H14-K14,"") -> 0
B15: 异丁烷 | C15: 吨 | D15: =_xlfn.IFERROR(IF(榆炼取值!D15=0,"",榆炼取值!D15),"") | E15: =_xlfn.IFERROR(榆炼取值!E15,"") -> 0 | F15: =_xlfn.IFERROR(E15/榆炼取值!D15*100,"") | G15: =_xlfn.IFERROR(IF(榆炼取值!G15=0,"",榆炼取值!G15),"") | H15: =_xlfn.IFERROR(榆炼取值!H15,"") -> 0 | I15: =_xlfn.IFERROR(H15/榆炼取值!G15*100,"") | J15: 0 | K15: 0 | L15: =_xlfn.IFERROR(H15-K15,"") -> 0
B16: 2、常压装置加工量 | C16: 吨 | D16: =_xlfn.IFERROR(IF(榆炼取值!D16=0,"",榆炼取值!D16),"") | E16: =_xlfn.IFERROR(榆炼取值!E16,"") -> 550368 | F16: =_xlfn.IFERROR(E16/榆炼取值!D16*100,"") | G16: =_xlfn.IFERROR(IF(榆炼取值!G16=0,"",榆炼取值!G16),"") | H16: =_xlfn.IFERROR(榆炼取值!H16,"") -> 4553852 | I16: =_xlfn.IFERROR(H16/榆炼取值!G16*100,"") | J16: 433198 | K16: 5100900 | L16: =_xlfn.IFERROR(H16-K16,"") -> -547048 | M16: 原油
B17: 原油加工量 | C17: 吨 | D17: 515000 | E17: =_xlfn.IFERROR(榆炼取值!E17,"") -> 550368 | F17: =_xlfn.IFERROR(E17/榆炼取值!D17*100,"") -> 106.86757 | G17: 5100000 | H17: =_xlfn.IFERROR(榆炼取值!H17,"") -> 4553852 | I17: =_xlfn.IFERROR(H17/榆炼取值!G17*100,"") -> 89.291216 | J17: 433198 | K17: 5100900 | L17: =_xlfn.IFERROR(H17-K17,"") -> -547048 | M17: =E17 -> 550368 | N17: =H17 -> 4553852
B18: 其中：进口原油加工量 | C18: 吨 | D18: =_xlfn.IFERROR(IF(榆炼取值!D18=0,"",榆炼取值!D18),"") | E18: 0 | F18: =_xlfn.IFERROR(E18/榆炼取值!D18*100,"") | G18: =_xlfn.IFERROR(IF(榆炼取值!G18=0,"",榆炼取值!G18),"") | H18: 0 | I18: =_xlfn.IFERROR(H18/榆炼取值!G18*100,"") | J18: 0 | K18: 0 | L18: =_xlfn.IFERROR(H18-K18,"") -> 0
B19: 3、催化装置加工量 | C19: 吨 | D19: =_xlfn.IFERROR(IF(榆炼取值!D19=0,"",榆炼取值!D19),"") | E19: =_xlfn.IFERROR(榆炼取值!E19,"") -> 174870 | F19: =_xlfn.IFERROR(E19/榆炼取值!D19*100,"") | G19: =_xlfn.IFERROR(IF(榆炼取值!G19=0,"",榆炼取值!G19),"") | H19: =_xlfn.IFERROR(榆炼取值!H19,"") -> 1591516 | I19: =_xlfn.IFERROR(H19/榆炼取值!G19*100,"") | J19: 153134 | K19: 1667450 | L19: =_xlfn.IFERROR(H19-K19,"") -> -75934
B20: 其中：1#渣油加工量 | C20: 吨 | D20: 141000 | E20: =_xlfn.IFERROR(榆炼取值!E20,"") -> 171606 | F20: =_xlfn.IFERROR(E20/榆炼取值!D20*100,"") -> 121.70638 | G20: 1780000 | H20: =_xlfn.IFERROR(榆炼取值!H20,"") -> 1575046 | I20: =_xlfn.IFERROR(H20/榆炼取值!G20*100,"") -> 88.48573 | J20: 149057 | K20: 1626265 | L20: =_xlfn.IFERROR(H20-K20,"") -> -51219 | M20: =E20 -> 171606 | N20: =H20 -> 1575046
B21: 4、重整装置处理量 | C21: 吨 | D21: 84000 | E21: =_xlfn.IFERROR(榆炼取值!E21,"") -> 110093 | F21: =_xlfn.IFERROR(E21/榆炼取值!D21*100,"") -> 131.0631 | G21: 950000 | H21: =_xlfn.IFERROR(榆炼取值!H21,"") -> 907947 | I21: =_xlfn.IFERROR(H21/榆炼取值!G21*100,"") -> 95.573368 | J21: 93966 | K21: 1019022 | L21: =_xlfn.IFERROR(H21-K21,"") -> -111075
B22: 5、DCC石脑油加氢处理量 | C22: 吨 | D22: =_xlfn.IFERROR(IF(榆炼取值!D22=0,"",榆炼取值!D22),"") | E22: =_xlfn.IFERROR(榆炼取值!E22,"") -> 0 | F22: =_xlfn.IFERROR(E22/榆炼取值!D22*100,"") | G22: =_xlfn.IFERROR(IF(榆炼取值!G22=0,"",榆炼取值!G22),"") | H22: =_xlfn.IFERROR(榆炼取值!H22,"") -> 0 | I22: =_xlfn.IFERROR(H22/榆炼取值!G22*100,"") | J22: 0 | K22: 80968 | L22: =_xlfn.IFERROR(H22-K22,"") -> -80968
B23: 6、DCC裂解轻油加氢处理量 | C23: 吨 | D23: =_xlfn.IFERROR(IF(榆炼取值!D23=0,"",榆炼取值!D23),"") | E23: =_xlfn.IFERROR(榆炼取值!E23,"") -> 0 | F23: =_xlfn.IFERROR(E23/榆炼取值!D23*100,"") | G23: =_xlfn.IFERROR(IF(榆炼取值!G23=0,"",榆炼取值!G23),"") | H23: =_xlfn.IFERROR(榆炼取值!H23,"") -> 0 | I23: =_xlfn.IFERROR(H23/榆炼取值!G23*100,"") | J23: 0 | K23: 0 | L23: =_xlfn.IFERROR(H23-K23,"") -> 0
B24: 7、汽油加氢精制处理量 | C24: 吨 | D24: 67000 | E24: =_xlfn.IFERROR(榆炼取值!E24,"") -> 99150 | F24: =_xlfn.IFERROR(E24/榆炼取值!D24*100,"") -> 147.98507 | G24: 880000 | H24: =_xlfn.IFERROR(榆炼取值!H24,"") -> 769527 | I24: =_xlfn.IFERROR(H24/榆炼取值!G24*100,"") -> 87.44625 | J24: 75564 | K24: 823073 | L24: =_xlfn.IFERROR(H24-K24,"") -> -53546
B25: 8、柴油加氢精制处理量 | C25: 吨 | D25: 177000 | E25: =_xlfn.IFERROR(榆炼取值!E25,"") -> 202494 | F25: =_xlfn.IFERROR(E25/榆炼取值!D25*100,"") -> 114.40339 | G25: 1800000 | H25: =_xlfn.IFERROR(榆炼取值!H25,"") -> 1736966 | I25: =_xlfn.IFERROR(H25/榆炼取值!G25*100,"") -> 96.498111 | J25: 172264 | K25: 1933004 | L25: =_xlfn.IFERROR(H25-K25,"") -> -196038
B26: 9、气分装置加工量 | C26: 吨 | D26: =_xlfn.IFERROR(IF(榆炼取值!D26=0,"",榆炼取值!D26),"") | E26: =_xlfn.IFERROR(榆炼取值!E26,"") -> 0 | F26: =_xlfn.IFERROR(E26/榆炼取值!D26*100,"") | G26: =_xlfn.IFERROR(IF(榆炼取值!G26=0,"",榆炼取值!G26),"") | H26: =_xlfn.IFERROR(榆炼取值!H26,"") -> 0 | I26: =_xlfn.IFERROR(H26/榆炼取值!G26*100,"") | J26: 0 | K26: 0 | L26: =_xlfn.IFERROR(H26-K26,"") -> 0
B27: 10、航煤装置处理量 | C27: 吨 | D27: =_xlfn.IFERROR(IF(榆炼取值!D27=0,"",榆炼取值!D27),"") | E27: =_xlfn.IFERROR(榆炼取值!E27,"") -> 28452 | F27: =_xlfn.IFERROR(E27/榆炼取值!D27*100,"") | G27: 263158 | H27: =_xlfn.IFERROR(榆炼取值!H27,"") -> 252643 | I27: =_xlfn.IFERROR(H27/榆炼取值!G27*100,"") -> 96.004302 | J27: =_xlfn.IFERROR(榆炼取值!J27,"") -> 24702 | K27: =_xlfn.IFERROR(榆炼取值!K27,"") -> 289635 | L27: =_xlfn.IFERROR(H27-K27,"") -> -36992
B28: 11、烷基化装置处理量 | C28: 吨 | D28: =_xlfn.IFERROR(IF(榆炼取值!D28=0,"",榆炼取值!D28),"") | E28: =_xlfn.IFERROR(榆炼取值!E28,"") -> 0 | F28: =_xlfn.IFERROR(E28/榆炼取值!D28*100,"") | G28: =_xlfn.IFERROR(IF(榆炼取值!G28=0,"",榆炼取值!G28),"") | H28: =_xlfn.IFERROR(榆炼取值!H28,"") -> 0 | I28: =_xlfn.IFERROR(H28/榆炼取值!G28*100,"") | J28: 0 | K28: 0 | L28: =_xlfn.IFERROR(H28-K28,"") -> 0
B29: 12、混合脱氢装置处理量 | C29: 吨 | D29: =_xlfn.IFERROR(IF(榆炼取值!D29=0,"",榆炼取值!D29),"") | E29: =_xlfn.IFERROR(榆炼取值!E29,"") -> 0 | F29: =_xlfn.IFERROR(E29/榆炼取值!D29*100,"") | G29: =_xlfn.IFERROR(IF(榆炼取值!G29=0,"",榆炼取值!G29),"") | H29: =_xlfn.IFERROR(榆炼取值!H29,"") -> 0 | I29: =_xlfn.IFERROR(H29/榆炼取值!G29*100,"") | J29: 0 | K29: 0 | L29: =_xlfn.IFERROR(H29-K29,"") -> 0
B30: 二、油气产品产销量
B31: 1、汽油产量 | C31: 吨 | D31: 170000 | E31: =_xlfn.IFERROR(榆炼取值!E31,"") -> 180869 | F31: =_xlfn.IFERROR(E31/榆炼取值!D31*100,"") -> 106.39353 | G31: 1500000 | H31: =_xlfn.IFERROR(榆炼取值!H31,"") -> 1520716 | I31: =_xlfn.IFERROR(H31/榆炼取值!G31*100,"") -> 101.38107 | J31: 142767 | K31: 1623821 | L31: =_xlfn.IFERROR(H31-K31,"") -> -103105 | M31: =E31 -> 180869 | N31: =H31 -> 1520716
B32: ⑴ 92#VI | C32: 吨 | D32: =_xlfn.IFERROR(IF(榆炼取值!D32=0,"",榆炼取值!D32),"") | E32: =_xlfn.IFERROR(榆炼取值!E32,"") -> 168869 | F32: =_xlfn.IFERROR(E32/榆炼取值!D32*100,"") | G32: 1305400 | H32: =_xlfn.IFERROR(榆炼取值!H32,"") -> 1350244 | I32: =_xlfn.IFERROR(H32/榆炼取值!G32*100,"") -> 103.43527 | J32: 122717 | K32: 1422443 | L32: =_xlfn.IFERROR(H32-K32,"") -> -72199
B33: ⑵ 95#VI | C33: 吨 | D33: =_xlfn.IFERROR(IF(榆炼取值!D33=0,"",榆炼取值!D33),"") | E33: =_xlfn.IFERROR(榆炼取值!E33,"") -> 12000 | F33: =_xlfn.IFERROR(E33/榆炼取值!D33*100,"") | G33: 194600 | H33: =_xlfn.IFERROR(榆炼取值!H33,"") -> 170472 | I33: =_xlfn.IFERROR(H33/榆炼取值!G33*100,"") -> 87.601233 | J33: 20050 | K33: 201378 | L33: =_xlfn.IFERROR(H33-K33,"") -> -30906
B34: ⑶ 98#Ⅵ | D34: =_xlfn.IFERROR(IF(榆炼取值!D34=0,"",榆炼取值!D34),"") | E34: =_xlfn.IFERROR(榆炼取值!E34,"") -> 0 | F34: =_xlfn.IFERROR(E34/榆炼取值!D34*100,"") | G34: =_xlfn.IFERROR(IF(榆炼取值!G34=0,"",榆炼取值!G34),"") | H34: =_xlfn.IFERROR(榆炼取值!H34,"") -> 0 | I34: =_xlfn.IFERROR(H34/榆炼取值!G34*100,"") | J34: 0 | K34: 0 | L34: =_xlfn.IFERROR(H34-K34,"") -> 0
B35: 2、柴油产量 | C35: 吨 | D35: 160000 | E35: =_xlfn.IFERROR(榆炼取值!E35,"") -> 169541 | F35: =_xlfn.IFERROR(E35/榆炼取值!D35*100,"") -> 105.96313 | G35: 1641452 | H35: =_xlfn.IFERROR(榆炼取值!H35,"") -> 1539988 | I35: =_xlfn.IFERROR(H35/榆炼取值!G35*100,"") -> 93.818643 | J35: 152928 | K35: 1736786 | L35: =_xlfn.IFERROR(H35-K35,"") -> -196798 | M35: =E35 -> 169541 | N35: =H35 -> 1539988
B36: ⑴ 军用柴油 | C36: 吨 | D36: =_xlfn.IFERROR(IF(榆炼取值!D36=0,"",榆炼取值!D36),"") | E36: =_xlfn.IFERROR(榆炼取值!E36,"") -> 0 | F36: =_xlfn.IFERROR(E36/榆炼取值!D36*100,"") | G36: =_xlfn.IFERROR(IF(榆炼取值!G36=0,"",榆炼取值!G36),"") | H36: =_xlfn.IFERROR(榆炼取值!H36,"") -> 0 | I36: =_xlfn.IFERROR(H36/榆炼取值!G36*100,"") | J36: 0 | K36: 0 | L36: =_xlfn.IFERROR(H36-K36,"") -> 0
