Workbook

Sheet 生产日报1
B1: 炼化公司生产日报表
B2: 填报单位：生产计划部 | D2: 统计日期： | F2: 2026-01-06 | H2: 填报日期： | J2: 2026-01-07 | N2: 陕油炼计统B900-1表
B3: 指标名称 | D3: 月计划 | E3: 延安炼油厂 | G3: 永坪炼油厂 | I3: 榆林炼油厂 | K3: 延安石化厂 | M3: 公司合计 | N3: 本月累计 | O3: 月完成率
E4: 日累 | F4: 月累 | G4: 日累 | H4: 月累 | I4: 日累 | J4: 月累 | K4: 日累 | L4: 月累
B5: 一、生产加工量
B6: 1.常压装置加工量 | D6: =IF(生产日报1取值!D6=0,"",生产日报1取值!D6) -> 1180000 | E6: =IF(生产日报1取值!E6=0,"",生产日报1取值!E6) -> 16826 | F6: =IF(生产日报1取值!F6=0,"",生产日报1取值!F6) -> 117720 | G6: =IF(生产日报1取值!G6=0,"",生产日报1取值!G6) -> 9194 | H6: =IF(生产日报1取值!H6=0,"",生产日报1取值!H6) -> 62067 | I6: =IF(生产日报1取值!I6=0,"",生产日报1取值!I6) -> 13001 | J6: =IF(生产日报1取值!J6=0,"",生产日报1取值!J6) -> 94349 | K6: =IF(生产日报1取值!K6=0,"",生产日报1取值!K6) | ... O6: =IF(生产日报1取值!O6=0,"",生产日报1取值!O6) -> 23.231864
B7: 2.催化装置加工量 | D7: =IF(生产日报1取值!D7=0,"",生产日报1取值!D7) -> 486000 | E7: =IF(生产日报1取值!E7=0,"",生产日报1取值!E7) -> 8867 | F7: =IF(生产日报1取值!F7=0,"",生产日报1取值!F7) -> 62050 | G7: =IF(生产日报1取值!G7=0,"",生产日报1取值!G7) -> 3733 | H7: =IF(生产日报1取值!H7=0,"",生产日报1取值!H7) -> 26723 | I7: =IF(生产日报1取值!I7=0,"",生产日报1取值!I7) -> 4763 | J7: =IF(生产日报1取值!J7=0,"",生产日报1取值!J7) -> 30986 | K7: =IF(生产日报1取值!K7=0,"",生产日报1取值!K7) | ... O7: =IF(生产日报1取值!O7=0,"",生产日报1取值!O7) -> 24.64177
B8: 1#渣油加工量 | D8: =IF(生产日报1取值!D8=0,"",生产日报1取值!D8) -> 486000 | E8: =IF(生产日报1取值!E8=0,"",生产日报1取值!E8) -> 8809 | F8: =IF(生产日报1取值!F8=0,"",生产日报1取值!F8) -> 61644 | G8: =IF(生产日报1取值!G8=0,"",生产日报1取值!G8) -> 3431 | H8: =IF(生产日报1取值!H8=0,"",生产日报1取值!H8) -> 24621 | I8: =IF(生产日报1取值!I8=0,"",生产日报1取值!I8) -> 4647 | J8: =IF(生产日报1取值!J8=0,"",生产日报1取值!J8) -> 30175 | K8: =IF(生产日报1取值!K8=0,"",生产日报1取值!K8) | ... O8: =IF(生产日报1取值!O8=0,"",生产日报1取值!O8) -> 23.958848
B9: 3.重整装置加工量 | D9: =IF(生产日报1取值!D9=0,"",生产日报1取值!D9) -> 223000 | E9: =IF(生产日报1取值!E9=0,"",生产日报1取值!E9) | F9: =IF(生产日报1取值!F9=0,"",生产日报1取值!F9) | G9: =IF(生产日报1取值!G9=0,"",生产日报1取值!G9) -> 617 | H9: =IF(生产日报1取值!H9=0,"",生产日报1取值!H9) -> 4266 | I9: =IF(生产日报1取值!I9=0,"",生产日报1取值!I9) -> 3340 | J9: =IF(生产日报1取值!J9=0,"",生产日报1取值!J9) -> 23339 | K9: =IF(生产日报1取值!K9=0,"",生产日报1取值!K9) -> 4280 | ... O9: =IF(生产日报1取值!O9=0,"",生产日报1取值!O9) -> 25.811659
B10: 4.加氢装置加工量 | D10: =IF(生产日报1取值!D10=0,"",生产日报1取值!D10) | E10: =IF(生产日报1取值!E10=0,"",生产日报1取值!E10) | F10: =IF(生产日报1取值!F10=0,"",生产日报1取值!F10) | G10: =IF(生产日报1取值!G10=0,"",生产日报1取值!G10) | H10: =IF(生产日报1取值!H10=0,"",生产日报1取值!H10) | I10: =IF(生产日报1取值!I10=0,"",生产日报1取值!I10) | J10: =IF(生产日报1取值!J10=0,"",生产日报1取值!J10) | K10: =IF(生产日报1取值!K10=0,"",生产日报1取值!K10) -> 2295 | ... O10: =IF(生产日报1取值!O10=0,"",生产日报1取值!O10)
B11: 5.液化气精制量 | D11: =IF(生产日报1取值!D11=0,"",生产日报1取值!D11) | E11: =IF(生产日报1取值!E11=0,"",生产日报1取值!E11) -> 949 | F11: =IF(生产日报1取值!F11=0,"",生产日报1取值!F11) -> 6156 | G11: =IF(生产日报1取值!G11=0,"",生产日报1取值!G11) | H11: =IF(生产日报1取值!H11=0,"",生产日报1取值!H11) | I11: =IF(生产日报1取值!I11=0,"",生产日报1取值!I11) | J11: =IF(生产日报1取值!J11=0,"",生产日报1取值!J11) | K11: =IF(生产日报1取值!K11=0,"",生产日报1取值!K11) -> 1757 | ... O11: =IF(生产日报1取值!O11=0,"",生产日报1取值!O11)
B12: 6.气体分馏加工量 | D12: =IF(生产日报1取值!D12=0,"",生产日报1取值!D12) -> 83600 | E12: =IF(生产日报1取值!E12=0,"",生产日报1取值!E12) -> 946 | F12: =IF(生产日报1取值!F12=0,"",生产日报1取值!F12) -> 6135 | G12: =IF(生产日报1取值!G12=0,"",生产日报1取值!G12) | H12: =IF(生产日报1取值!H12=0,"",生产日报1取值!H12) | I12: =IF(生产日报1取值!I12=0,"",生产日报1取值!I12) | J12: =IF(生产日报1取值!J12=0,"",生产日报1取值!J12) | K12: =IF(生产日报1取值!K12=0,"",生产日报1取值!K12) -> 1730 | ... O12: =IF(生产日报1取值!O12=0,"",生产日报1取值!O12) -> 22.116029
B13: 7.聚丙烯加工量 | D13: =IF(生产日报1取值!D13=0,"",生产日报1取值!D13) | E13: =IF(生产日报1取值!E13=0,"",生产日报1取值!E13) -> 316 | F13: =IF(生产日报1取值!F13=0,"",生产日报1取值!F13) -> 2187 | G13: =IF(生产日报1取值!G13=0,"",生产日报1取值!G13) | H13: =IF(生产日报1取值!H13=0,"",生产日报1取值!H13) | I13: =IF(生产日报1取值!I13=0,"",生产日报1取值!I13) | J13: =IF(生产日报1取值!J13=0,"",生产日报1取值!J13) | K13: =IF(生产日报1取值!K13=0,"",生产日报1取值!K13) -> 627 | ... O13: =IF(生产日报1取值!O13=0,"",生产日报1取值!O13)
B14: 8.MTBE加工量 | D14: =IF(生产日报1取值!D14=0,"",生产日报1取值!D14) | E14: =IF(生产日报1取值!E14=0,"",生产日报1取值!E14) -> 582 | F14: =IF(生产日报1取值!F14=0,"",生产日报1取值!F14) -> 3756 | G14: =IF(生产日报1取值!G14=0,"",生产日报1取值!G14) | H14: =IF(生产日报1取值!H14=0,"",生产日报1取值!H14) | I14: =IF(生产日报1取值!I14=0,"",生产日报1取值!I14) | J14: =IF(生产日报1取值!J14=0,"",生产日报1取值!J14) | K14: =IF(生产日报1取值!K14=0,"",生产日报1取值!K14) -> 1043 | ... O14: =IF(生产日报1取值!O14=0,"",生产日报1取值!O14)
B15: 9.苯抽提加工量 | D15: =IF(生产日报1取值!D15=0,"",生产日报1取值!D15) | E15: =IF(生产日报1取值!E15=0,"",生产日报1取值!E15) | F15: =IF(生产日报1取值!F15=0,"",生产日报1取值!F15) | G15: =IF(生产日报1取值!G15=0,"",生产日报1取值!G15) | H15: =IF(生产日报1取值!H15=0,"",生产日报1取值!H15) | I15: =IF(生产日报1取值!I15=0,"",生产日报1取值!I15) -> 471 | J15: =IF(生产日报1取值!J15=0,"",生产日报1取值!J15) -> 3189 | K15: =IF(生产日报1取值!K15=0,"",生产日报1取值!K15) -> 559 | ... O15: =IF(生产日报1取值!O15=0,"",生产日报1取值!O15)
B16: 10.干气精制加工量 | D16: =IF(生产日报1取值!D16=0,"",生产日报1取值!D16) | E16: =IF(生产日报1取值!E16=0,"",生产日报1取值!E16) -> 300 | F16: =IF(生产日报1取值!F16=0,"",生产日报1取值!F16) -> 2164 | G16: =IF(生产日报1取值!G16=0,"",生产日报1取值!G16) | H16: =IF(生产日报1取值!H16=0,"",生产日报1取值!H16) | I16: =IF(生产日报1取值!I16=0,"",生产日报1取值!I16) | J16: =IF(生产日报1取值!J16=0,"",生产日报1取值!J16) | K16: =IF(生产日报1取值!K16=0,"",生产日报1取值!K16) | ... O16: =IF(生产日报1取值!O16=0,"",生产日报1取值!O16)
B17: 11.乙苯加工量 | D17: =IF(生产日报1取值!D17=0,"",生产日报1取值!D17) | E17: =IF(生产日报1取值!E17=0,"",生产日报1取值!E17) -> 356 | F17: =IF(生产日报1取值!F17=0,"",生产日报1取值!F17) -> 2564 | G17: =IF(生产日报1取值!G17=0,"",生产日报1取值!G17) | H17: =IF(生产日报1取值!H17=0,"",生产日报1取值!H17) | I17: =IF(生产日报1取值!I17=0,"",生产日报1取值!I17) | J17: =IF(生产日报1取值!J17=0,"",生产日报1取值!J17) | K17: =IF(生产日报1取值!K17=0,"",生产日报1取值!K17) | ... O17: =IF(生产日报1取值!O17=0,"",生产日报1取值!O17)
... B22: 15.柴油精制加工量 | D22: =IF(生产日报1取值!D22=0,"",生产日报1取值!D22) -> 446000 | E22: =IF(生产日报1取值!E22=0,"",生产日报1取值!E22) | F22: =IF(生产日报1取值!F22=0,"",生产日报1取值!F22) | G22: =IF(生产日报1取值!G22=0,"",生产日报1取值!G22) -> 2830 | H22: =IF(生产日报1取值!H22=0,"",生产日报1取值!H22) -> 23859 | I22: =IF(生产日报1取值!I22=0,"",生产日报1取值!I22) -> 4425 | J22: =IF(生产日报1取值!J22=0,"",生产日报1取值!J22) -> 33634 | K22: =IF(生产日报1取值!K22=0,"",生产日报1取值!K22) -> 4881 | ... O22: =IF(生产日报1取值!O22=0,"",生产日报1取值!O22) -> 20.59148
B23: 二、装置收率 | D23: =IF(生产日报1取值!D23=0,"",生产日报1取值!D23)
B24: 1.常压轻质油收率 | D24: =IF(生产日报1取值!D24=0,"",生产日报1取值!D24) -> 48.454237 | E24: =IF(生产日报1取值!E24=0,"",生产日报1取值!E24) -> 48.30025 | F24: =IF(生产日报1取值!F24=0,"",生产日报1取值!F24) -> 48.547401 | G24: =IF(生产日报1取值!G24=0,"",生产日报1取值!G24) -> 49.042854 | H24: =IF(生产日报1取值!H24=0,"",生产日报1取值!H24) -> 49.121111 | I24: =IF(生产日报1取值!I24=0,"",生产日报1取值!I24) -> 51.865241 | J24: =IF(生产日报1取值!J24=0,"",生产日报1取值!J24) -> 52.837868 | K24: =IF(生产日报1取值!K24=0,"",生产日报1取值!K24) | ... N24: =IF(生产日报1取值!N24=0,"",生产日报1取值!N24) -> 50.153938 | P24: =M24 -> 49.663002 | Q24: =N24 -> 50.153938
B25: 2.催化轻质油收率 | D25: =IF(生产日报1取值!D25=0,"",生产日报1取值!D25) -> 69.224074 | E25: =IF(生产日报1取值!E25=0,"",生产日报1取值!E25) -> 71.771738 | F25: =IF(生产日报1取值!F25=0,"",生产日报1取值!F25) -> 71.452055 | G25: =IF(生产日报1取值!G25=0,"",生产日报1取值!G25) -> 70.559871 | H25: =IF(生产日报1取值!H25=0,"",生产日报1取值!H25) -> 71.197096 | I25: =IF(生产日报1取值!I25=0,"",生产日报1取值!I25) -> 69.850934 | J25: =IF(生产日报1取值!J25=0,"",生产日报1取值!J25) -> 70.180081 | K25: =IF(生产日报1取值!K25=0,"",生产日报1取值!K25) | ... N25: =IF(生产日报1取值!N25=0,"",生产日报1取值!N25) -> 71.066058 | P25: =M25 -> 70.984277 | Q25: =N25 -> 71.066058
B26: 液化气收率 | D26: =IF(生产日报1取值!D26=0,"",生产日报1取值!D26) -> 17.100617 | E26: =IF(生产日报1取值!E26=0,"",生产日报1取值!E26) -> 16.19488 | F26: =IF(生产日报1取值!F26=0,"",生产日报1取值!F26) -> 16.446414 | G26: =IF(生产日报1取值!G26=0,"",生产日报1取值!G26) -> 16.662202 | H26: =IF(生产日报1取值!H26=0,"",生产日报1取值!H26) -> 16.02365 | I26: =IF(生产日报1取值!I26=0,"",生产日报1取值!I26) -> 15.074533 | J26: =IF(生产日报1取值!J26=0,"",生产日报1取值!J26) -> 14.755051 | K26: =IF(生产日报1取值!K26=0,"",生产日报1取值!K26) | ... N26: =IF(生产日报1取值!N26=0,"",生产日报1取值!N26) -> 15.918711
B27: 3.重整装置总收率 | D27: =IF(生产日报1取值!D27=0,"",生产日报1取值!D27) -> 92.456054 | E27: =IF(生产日报1取值!E27=0,"",生产日报1取值!E27) | F27: =IF(生产日报1取值!F27=0,"",生产日报1取值!F27) | G27: =IF(生产日报1取值!G27=0,"",生产日报1取值!G27) -> 93.354943 | H27: =IF(生产日报1取值!H27=0,"",生产日报1取值!H27) -> 93.459916 | I27: =IF(生产日报1取值!I27=0,"",生产日报1取值!I27) -> 93.023952 | J27: =IF(生产日报1取值!J27=0,"",生产日报1取值!J27) -> 93.208792 | K27: =IF(生产日报1取值!K27=0,"",生产日报1取值!K27) -> 93.364486 | ... N27: =IF(生产日报1取值!N27=0,"",生产日报1取值!N27) -> 93.231411 | P27: =M27 -> 93.225689 | Q27: =N27 -> 93.231411
B28: 4.加氢装置总收率 | D28: =IF(生产日报1取值!D28=0,"",生产日报1取值!D28) | E28: =IF(生产日报1取值!E28=0,"",生产日报1取值!E28) | F28: =IF(生产日报1取值!F28=0,"",生产日报1取值!F28) | G28: =IF(生产日报1取值!G28=0,"",生产日报1取值!G28) | H28: =IF(生产日报1取值!H28=0,"",生产日报1取值!H28) | I28: =IF(生产日报1取值!I28=0,"",生产日报1取值!I28) | J28: =IF(生产日报1取值!J28=0,"",生产日报1取值!J28) | K28: =IF(生产日报1取值!K28=0,"",生产日报1取值!K28) -> 99.738562 | ... N28: =IF(生产日报1取值!N28=0,"",生产日报1取值!N28) -> 99.728148
B29: 5.气分装置收率 | D29: =IF(生产日报1取值!D29=0,"",生产日报1取值!D29) | E29: =IF(生产日报1取值!E29=0,"",生产日报1取值!E29) -> 99.682875 | F29: =IF(生产日报1取值!F29=0,"",生产日报1取值!F29) -> 99.657702 | G29: =IF(生产日报1取值!G29=0,"",生产日报1取值!G29) | H29: =IF(生产日报1取值!H29=0,"",生产日报1取值!H29) | I29: =IF(生产日报1取值!I29=0,"",生产日报1取值!I29) | J29: =IF(生产日报1取值!J29=0,"",生产日报1取值!J29) | K29: =IF(生产日报1取值!K29=0,"",生产日报1取值!K29) -> 97.803468 | ... N29: =IF(生产日报1取值!N29=0,"",生产日报1取值!N29) -> 98.518038
B30: 丙烯收率 | D30: =IF(生产日报1取值!D30=0,"",生产日报1取值!D30) -> 25.557925 | E30: =IF(生产日报1取值!E30=0,"",生产日报1取值!E30) -> 25.158562 | F30: =IF(生产日报1取值!F30=0,"",生产日报1取值!F30) -> 27.628362 | G30: =IF(生产日报1取值!G30=0,"",生产日报1取值!G30) | H30: =IF(生产日报1取值!H30=0,"",生产日报1取值!H30) | I30: =IF(生产日报1取值!I30=0,"",生产日报1取值!I30) | J30: =IF(生产日报1取值!J30=0,"",生产日报1取值!J30) | K30: =IF(生产日报1取值!K30=0,"",生产日报1取值!K30) -> 26.878613 | ... N30: =IF(生产日报1取值!N30=0,"",生产日报1取值!N30) -> 27.037698
B31: 6.聚丙烯装置收率 | D31: =IF(生产日报1取值!D31=0,"",生产日报1取值!D31) | E31: =IF(生产日报1取值!E31=0,"",生产日报1取值!E31) -> 96.518987 | F31: =IF(生产日报1取值!F31=0,"",生产日报1取值!F31) -> 96.021948 | G31: =IF(生产日报1取值!G31=0,"",生产日报1取值!G31) | H31: =IF(生产日报1取值!H31=0,"",生产日报1取值!H31) | I31: =IF(生产日报1取值!I31=0,"",生产日报1取值!I31) | J31: =IF(生产日报1取值!J31=0,"",生产日报1取值!J31) | K31: =IF(生产日报1取值!K31=0,"",生产日报1取值!K31) -> 97.218501 | ... N31: =IF(生产日报1取值!N31=0,"",生产日报1取值!N31) -> 96.676685
B32: 7.MTBE收率 | D32: =IF(生产日报1取值!D32=0,"",生产日报1取值!D32) | E32: =IF(生产日报1取值!E32=0,"",生产日报1取值!E32) -> 18.556701 | F32: =IF(生产日报1取值!F32=0,"",生产日报1取值!F32) -> 18.317359 | G32: =IF(生产日报1取值!G32=0,"",生产日报1取值!G32) | H32: =IF(生产日报1取值!H32=0,"",生产日报1取值!H32) | I32: =IF(生产日报1取值!I32=0,"",生产日报1取值!I32) | J32: =IF(生产日报1取值!J32=0,"",生产日报1取值!J32) | K32: =IF(生产日报1取值!K32=0,"",生产日报1取值!K32) -> 15.723873 | ... N32: =IF(生产日报1取值!N32=0,"",生产日报1取值!N32) -> 16.556528
B33: 8.MTBE转化率 | D33: =IF(生产日报1取值!D33=0,"",生产日报1取值!D33) | E33: =IF(生产日报1取值!E33=0,"",生产日报1取值!E33) -> 99.3 | F33: =IF(生产日报1取值!F33=0,"",生产日报1取值!F33) -> 99.07 | G33: =IF(生产日报1取值!G33=0,"",生产日报1取值!G33) | H33: =IF(生产日报1取值!H33=0,"",生产日报1取值!H33) | I33: =IF(生产日报1取值!I33=0,"",生产日报1取值!I33) | J33: =IF(生产日报1取值!J33=0,"",生产日报1取值!J33) | K33: =_xlfn.IFERROR(IF(生产日报1取值!K33=0,"",生产日报1取值!K33),"") -> 99.769849 | L33: =_xlfn.IFERROR(IF(生产日报1取值!L33=0,"",生产日报1取值!L33),"") -> 99.802218 | M33: =IF(生产日报1取值!M33=0,"",生产日报1取值!M33) -> 99.601571 | N33: =IF(生产日报1取值!N33=0,"",生产日报1取值!N33) -> 99.556619
B34: 9.苯抽提装置收率 | D34: =IF(生产日报1取值!D34=0,"",生产日报1取值!D34) | E34: =IF(生产日报1取值!E34=0,"",生产日报1取值!E34) | F34: =IF(生产日报1取值!F34=0,"",生产日报1取值!F34) | G34: =IF(生产日报1取值!G34=0,"",生产日报1取值!G34) | H34: =IF(生产日报1取值!H34=0,"",生产日报1取值!H34) | I34: =IF(生产日报1取值!I34=0,"",生产日报1取值!I34) -> 95.329087 | J34: =IF(生产日报1取值!J34=0,"",生产日报1取值!J34) -> 94.042019 | K34: =IF(生产日报1取值!K34=0,"",生产日报1取值!K34) -> 99.463327 | ... N34: =IF(生产日报1取值!N34=0,"",生产日报1取值!N34) -> 97.055129
B35: 10.乙苯收率 | D35: =IF(生产日报1取值!D35=0,"",生产日报1取值!D35) | E35: =IF(生产日报1取值!E35=0,"",生产日报1取值!E35) -> 43.539326 | F35: =IF(生产日报1取值!F35=0,"",生产日报1取值!F35) -> 43.876755 | G35: =IF(生产日报1取值!G35=0,"",生产日报1取值!G35) | H35: =IF(生产日报1取值!H35=0,"",生产日报1取值!H35) | I35: =IF(生产日报1取值!I35=0,"",生产日报1取值!I35) | J35: =IF(生产日报1取值!J35=0,"",生产日报1取值!J35) | K35: =IF(生产日报1取值!K35=0,"",生产日报1取值!K35) | ... N35: =IF(生产日报1取值!N35=0,"",生产日报1取值!N35) -> 43.876755
B36: 11.苯乙烯收率 | D36: =IF(生产日报1取值!D36=0,"",生产日报1取值!D36) | E36: =IF(生产日报1取值!E36=0,"",生产日报1取值!E36) -> 94.968553 | F36: =IF(生产日报1取值!F36=0,"",生产日报1取值!F36) -> 94.630282 | G36: =IF(生产日报1取值!G36=0,"",生产日报1取值!G36) | H36: =IF(生产日报1取值!H36=0,"",生产日报1取值!H36) | I36: =IF(生产日报1取值!I36=0,"",生产日报1取值!I36) | J36: =IF(生产日报1取值!J36=0,"",生产日报1取值!J36) | K36: =IF(生产日报1取值!K36=0,"",生产日报1取值!K36) | ... N36: =IF(生产日报1取值!N36=0,"",生产日报1取值!N36) -> 94.630282
B37: 12.醋酸仲丁酯收率 | D37: =IF(生产日报1取值!D37=0,"",生产日报1取值!D37) -> 43.5 | E37: =IF(生产日报1取值!E37=0,"",生产日报1取值!E37) -> 38.940092 | F37: =IF(生产日报1取值!F37=0,"",生产日报1取值!F37) -> 37.928716 | G37: =IF(生产日报1取值!G37=0,"",生产日报1取值!G37) | H37: =IF(生产日报1取值!H37=0,"",生产日报1取值!H37) | I37: =IF(生产日报1取值!I37=0,"",生产日报1取值!I37) | J37: =IF(生产日报1取值!J37=0,"",生产日报1取值!J37) | K37: =IF(生产日报1取值!K37=0,"",生产日报1取值!K37) | ... N37: =IF(生产日报1取值!N37=0,"",生产日报1取值!N37) -> 37.928716
B38: 13.汽油精制总收率 | D38: =IF(生产日报1取值!D38=0,"",生产日报1取值!D38) -> 98.243421 | E38: =IF(生产日报1取值!E38=0,"",生产日报1取值!E38) | F38: =IF(生产日报1取值!F38=0,"",生产日报1取值!F38) | G38: =IF(生产日报1取值!G38=0,"",生产日报1取值!G38) -> 98.89258 | H38: =IF(生产日报1取值!H38=0,"",生产日报1取值!H38) -> 98.88906 | I38: =IF(生产日报1取值!I38=0,"",生产日报1取值!I38) -> 99.223678 | J38: =IF(生产日报1取值!J38=0,"",生产日报1取值!J38) -> 99.224481 | K38: =IF(生产日报1取值!K38=0,"",生产日报1取值!K38) -> 98.963606 | ... N38: =IF(生产日报1取值!N38=0,"",生产日报1取值!N38) -> 99.035803
B39: 14.柴油精制总收率 | D39: =IF(生产日报1取值!D39=0,"",生产日报1取值!D39) -> 98.587892 | E39: =IF(生产日报1取值!E39=0,"",生产日报1取值!E39) | F39: =IF(生产日报1取值!F39=0,"",生产日报1取值!F39) | G39: =IF(生产日报1取值!G39=0,"",生产日报1取值!G39) -> 99.081272 | H39: =IF(生产日报1取值!H39=0,"",生产日报1取值!H39) -> 99.207846 | I39: =IF(生产日报1取值!I39=0,"",生产日报1取值!I39) -> 99.028249 | J39: =IF(生产日报1取值!J39=0,"",生产日报1取值!J39) -> 99.167509 | K39: =IF(生产日报1取值!K39=0,"",生产日报1取值!K39) -> 99.303421 | ... N39: =IF(生产日报1取值!N39=0,"",生产日报1取值!N39) -> 99.169189
B40: 15.汽柴液总收率 | D40: =IF(生产日报1取值!D40=0,"",生产日报1取值!D40) | E40: =IF(生产日报1取值!E40=0,"",生产日报1取值!E40) -> 94.657078 | F40: =IF(生产日报1取值!F40=0,"",生产日报1取值!F40) -> 94.878525 | G40: =IF(生产日报1取值!G40=0,"",生产日报1取值!G40) -> 81.194257 | H40: =IF(生产日报1取值!H40=0,"",生产日报1取值!H40) -> 83.332528 | I40: =IF(生产日报1取值!I40=0,"",生产日报1取值!I40) -> 77.155603 | J40: =IF(生产日报1取值!J40=0,"",生产日报1取值!J40) -> 75.822281 | K40: =IF(生产日报1取值!K40=0,"",生产日报1取值!K40) | ... N40: =IF(生产日报1取值!N40=0,"",生产日报1取值!N40) -> 85.705841
B41: 三、原料调运 | D41: =IF(生产日报1取值!D41=0,"",生产日报1取值!D41)
B42: 1.渣油调出量 | D42: =IF(生产日报1取值!D42=0,"",生产日报1取值!D42) | E42: =IF(生产日报1取值!E42=0,"",生产日报1取值!E42) | F42: =IF(生产日报1取值!F42=0,"",生产日报1取值!F42) | G42: =IF(生产日报1取值!G42=0,"",生产日报1取值!G42) -> 1475.72 | H42: =IF(生产日报1取值!H42=0,"",生产日报1取值!H42) -> 8741.1 | I42: =IF(生产日报1取值!I42=0,"",生产日报1取值!I42) | J42: =IF(生产日报1取值!J42=0,"",生产日报1取值!J42) | K42: =IF(生产日报1取值!K42=0,"",生产日报1取值!K42) | ... O42: =IF(生产日报1取值!O42=0,"",生产日报1取值!O42)
B43: 渣油调入量 | D43: =IF(生产日报1取值!D43=0,"",生产日报1取值!D43) | E43: =IF(生产日报1取值!E43=0,"",生产日报1取值!E43) | F43: =IF(生产日报1取值!F43=0,"",生产日报1取值!F43) | G43: =IF(生产日报1取值!G43=0,"",生产日报1取值!G43) | H43: =IF(生产日报1取值!H43=0,"",生产日报1取值!H43) | I43: =IF(生产日报1取值!I43=0,"",生产日报1取值!I43) | J43: =IF(生产日报1取值!J43=0,"",生产日报1取值!J43) | K43: =IF(生产日报1取值!K43=0,"",生产日报1取值!K43) | ... O43: =IF(生产日报1取值!O43=0,"",生产日报1取值!O43)
B44: 2.石脑油调出量(常) | D44: =IF(生产日报1取值!D44=0,"",生产日报1取值!D44) | E44: =IF(生产日报1取值!E44=0,"",生产日报1取值!E44) -> 2963 | F44: =IF(生产日报1取值!F44=0,"",生产日报1取值!F44) -> 19355 | G44: =IF(生产日报1取值!G44=0,"",生产日报1取值!G44) -> 763.58 | H44: =IF(生产日报1取值!H44=0,"",生产日报1取值!H44) -> 3925.46 | I44: =IF(生产日报1取值!I44=0,"",生产日报1取值!I44) -> 352.74 | J44: =IF(生产日报1取值!J44=0,"",生产日报1取值!J44) -> 1369.42 | K44: =IF(生产日报1取值!K44=0,"",生产日报1取值!K44) | ... O44: =IF(生产日报1取值!O44=0,"",生产日报1取值!O44)
...

Sheet 生产日报1取值
B1: 炼化公司生产日报表
B2: 填报单位： | C2: 生产计划部 | F2: 日期： | G2: 2026-01-06 | I2: 单位：吨 | J2: 报表生成时间： | L2: =#REF! | N2: 陕油炼计统B900-1表
B3: 指标名称 | D3: 月计划 | E3: 延安炼油厂 | G3: 永坪炼油厂 | I3: 榆林炼油厂 | K3: 延安石化厂 | M3: 公司合计 | N3: 本月累计 | O3: 月完成率
E4: 日累 | F4: 月累 | G4: 日累 | H4: 月累 | I4: 日累 | J4: 月累 | K4: 日累 | L4: 月累
B5: 一、生产加工量
B6: 1.常压装置加工量 | D6: 1180000 | E6: =E48 -> 16826 | F6: =F48 -> 117720 | G6: =G48 -> 9194 | H6: =H48 -> 62067 | I6: =I48 -> 13001 | J6: =J48 -> 94349 | M6: =SUM(E6,G6,I6,K6) -> 39021 | N6: =SUM(F6,H6,J6,L6) -> 274136 | O6: =_xlfn.IFERROR(N6/D6*100,"") -> 23.231864
B7: 2.催化装置加工量 | D7: 486000 | E7: =E49 -> 8867 | F7: =F49 -> 62050 | G7: =G49 -> 3733 | H7: =H49 -> 26723 | I7: =I49 -> 4763 | J7: =J49 -> 30986 | M7: =SUM(E7,G7,I7,K7) -> 17363 | N7: =SUM(F7,H7,J7,L7) -> 119759 | O7: =_xlfn.IFERROR(N7/D7*100,"") -> 24.64177
B8: 1#渣油加工量 | D8: 486000 | E8: =E50 -> 8809 | F8: =F50 -> 61644 | G8: =G50 -> 3431 | H8: =H50 -> 24621 | I8: =I50 -> 4647 | J8: =J50 -> 30175 | M8: =SUM(E8,G8,I8,K8) -> 16887 | N8: =SUM(F8,H8,J8,L8) -> 116440 | O8: =_xlfn.IFERROR(N8/D8*100,"") -> 23.958848
B9: 3.重整装置加工量 | D9: =D47 -> 223000 | G9: =G51 -> 617 | H9: =H51 -> 4266 | I9: =I51 -> 3340 | J9: =J51 -> 23339 | K9: =K48 -> 4280 | L9: =L48 -> 29955 | M9: =SUM(E9,G9,I9,K9) -> 8237 | N9: =SUM(F9,H9,J9,L9) -> 57560 | O9: =_xlfn.IFERROR(N9/D9*100,"") -> 25.811659
B10: 4.加氢装置加工量 | I10: =I52 -> 0 | J10: =J52 -> 0 | K10: =K49 -> 2295 | L10: =L49 -> 16921 | M10: =SUM(E10,G10,I10,K10) -> 2295 | N10: =SUM(F10,H10,J10,L10) -> 16921 | O10: =_xlfn.IFERROR(N10/D10*100,"")
B11: 5.液化气精制量 | E11: =E52 -> 949 | F11: =F52 -> 6156 | K11: =K50 -> 1757 | L11: =L50 -> 11752 | M11: =SUM(E11,G11,I11,K11) -> 2706 | N11: =SUM(F11,H11,J11,L11) -> 17908 | O11: =_xlfn.IFERROR(N11/D11*100,"")
B12: 6.气体分馏加工量 | D12: 83600 | E12: =E53 -> 946 | F12: =F53 -> 6135 | K12: =K51 -> 1730 | L12: =L51 -> 12354 | M12: =SUM(E12,G12,I12,K12) -> 2676 | N12: =SUM(F12,H12,J12,L12) -> 18489 | O12: =_xlfn.IFERROR(N12/D12*100,"") -> 22.116029
B13: 7.聚丙烯加工量 | E13: =E54 -> 316 | F13: =F54 -> 2187 | K13: =K52 -> 627 | L13: =L52 -> 4401 | M13: =SUM(E13,G13,I13,K13) -> 943 | N13: =SUM(F13,H13,J13,L13) -> 6588 | O13: =_xlfn.IFERROR(N13/D13*100,"")
B14: 8.MTBE加工量 | E14: =E55 -> 582 | F14: =F55 -> 3756 | K14: =K53 -> 1043 | L14: =L53 -> 7442 | M14: =SUM(E14,G14,I14,K14) -> 1625 | N14: =SUM(F14,H14,J14,L14) -> 11198 | O14: =_xlfn.IFERROR(N14/D14*100,"")
B15: 9.苯抽提加工量 | I15: =I54 -> 471 | J15: =J54 -> 3189 | K15: =K54 -> 559 | L15: =L54 -> 3976 | M15: =SUM(E15,G15,I15,K15) -> 1030 | N15: =SUM(F15,H15,J15,L15) -> 7165 | O15: =_xlfn.IFERROR(N15/D15*100,"")
B16: 10.干气精制加工量 | E16: =E57 -> 300 | F16: =F57 -> 2164 | M16: =SUM(E16,G16,I16,K16) -> 300 | N16: =SUM(F16,H16,J16,L16) -> 2164 | O16: =_xlfn.IFERROR(N16/D16*100,"")
B17: 11.乙苯加工量 | E17: =E58 -> 356 | F17: =F58 -> 2564 | M17: =SUM(E17,G17,I17,K17) -> 356 | N17: =SUM(F17,H17,J17,L17) -> 2564 | O17: =_xlfn.IFERROR(N17/D17*100,"")
B18: 12.苯乙烯加工量 | E18: =E59 -> 171 | F18: =F59 -> 1155 | M18: =SUM(E18,G18,I18,K18) -> 171 | N18: =SUM(F18,H18,J18,L18) -> 1155 | O18: =_xlfn.IFERROR(N18/D18*100,"")
B19: 13.醋酸仲丁酯装置加工量 | E19: =E60 -> 434 | F19: =F60 -> 2974 | M19: =SUM(E19,G19,I19,K19) -> 434 | N19: =SUM(F19,H19,J19,L19) -> 2974 | O19: =_xlfn.IFERROR(N19/D19*100,"")
B20: 其中：醋酸原料 | E20: =E61 -> 91 | F20: =F61 -> 611 | M20: =SUM(E20,G20,I20,K20) -> 91 | N20: =SUM(F20,H20,J20,L20) -> 611 | O20: =_xlfn.IFERROR(N20/D20*100,"")
B21: 14.汽油精制加工量 | D21: 228000 | G21: =G53 -> 1806 | H21: =H53 -> 12962 | I21: =I56 -> 2061 | J21: =J56 -> 14313 | K21: =K56 -> 4149 | L21: =L56 -> 29145 | M21: =SUM(E21,G21,I21,K21) -> 8016 | N21: =SUM(F21,H21,J21,L21) -> 56420 | O21: =_xlfn.IFERROR(N21/D21*100,"") -> 24.745614
B22: 15.柴油精制加工量 | D22: 446000 | G22: =G54 -> 2830 | H22: =H54 -> 23859 | I22: =I57 -> 4425 | J22: =J57 -> 33634 | K22: =K57 -> 4881 | L22: =L57 -> 34345 | M22: =SUM(E22,G22,I22,K22) -> 12136 | N22: =SUM(F22,H22,J22,L22) -> 91838 | O22: =_xlfn.IFERROR(N22/D22*100,"") -> 20.59148
B23: 二、装置收率
B24: 1.常压轻质油收率 | D24: 48.454237 | E24: =E63 -> 48.30025 | F24: =F63 -> 48.547401 | G24: =G56 -> 49.042854 | H24: =H56 -> 49.121111 | I24: =I59 -> 51.865241 | J24: =J59 -> 52.837868 | M24: =_xlfn.IFERROR((E24*E6+G24*G6+I24*I6+K24*K6)/(E6+G6+I6+K6),"") -> 49.663002 | N24: =_xlfn.IFERROR((F24*F6+H24*H6+J24*J6+L24*L6)/(F6+H6+J6+L6),"") -> 50.153938
B25: 2.催化轻质油收率 | D25: 69.224074 | E25: =E64 -> 71.771738 | F25: =F64 -> 71.452055 | G25: =G57 -> 70.559871 | H25: =H57 -> 71.197096 | I25: =I60 -> 69.850934 | J25: =J60 -> 70.180081 | M25: =_xlfn.IFERROR((E25*E7+G25*G7+I25*I7+K25*K7)/(E7+G7+I7+K7),"") -> 70.984277 | N25: =_xlfn.IFERROR((F25*F7+H25*H7+J25*J7+L25*L7)/(F7+H7+J7+L7),"") -> 71.066058
B26: 液化气收率 | D26: 17.100617 | E26: =E65 -> 16.19488 | F26: =F65 -> 16.446414 | G26: =G58 -> 16.662202 | H26: =H58 -> 16.02365 | I26: =I61 -> 15.074533 | J26: =J61 -> 14.755051 | M26: =_xlfn.IFERROR((E26*E8+G26*G8+I26*I8+K26*K8)/(E8+G8+I8+K8),"") -> 15.981528 | N26: =_xlfn.IFERROR((F26*F8+H26*H8+J26*J8+L26*L8)/(F8+H8+J8+L8),"") -> 15.918711
B27: 3.重整装置总收率 | D27: 92.456054 | G27: =G59 -> 93.354943 | H27: =H59 -> 93.459916 | I27: =I62 -> 93.023952 | J27: =J62 -> 93.208792 | K27: =K59 -> 93.364486 | L27: =L59 -> 93.216491 | M27: =_xlfn.IFERROR((E27*E9+G27*G9+I27*I9+K27*K9)/(E9+G9+I9+K9),"") -> 93.225689 | N27: =_xlfn.IFERROR((F27*F9+H27*H9+J27*J9+L27*L9)/(F9+H9+J9+L9),"") -> 93.231411
B28: 4.加氢装置总收率 | I28: =I64 -> 0 | J28: =J64 -> 0 | K28: =K60 -> 99.738562 | L28: =L60 -> 99.728148 | M28: =_xlfn.IFERROR((E28*E10+G28*G10+K28*K10)/(E10+G10+K10),"") -> 99.738562 | N28: =_xlfn.IFERROR((F28*F10+H28*H10+L28*L10)/(F10+H10+L10),"") -> 99.728148
B29: 5.气分装置收率 | E29: =E67 -> 99.682875 | F29: =F67 -> 99.657702 | K29: =K61 -> 97.803468 | L29: =L61 -> 97.95208 | M29: =_xlfn.IFERROR((E29*E12+G29*G12+I29*I12+K29*K12)/(E12+G12+I12+K12),"") -> 98.467862 | N29: =_xlfn.IFERROR((F29*F12+H29*H12+J29*J12+L29*L12)/(F12+H12+J12+L12),"") -> 98.518038
B30: 丙烯收率 | D30: 25.557925 | E30: =E68 -> 25.158562 | F30: =F68 -> 27.628362 | K30: =K62 -> 26.878613 | L30: =L62 -> 26.744374 | M30: =_xlfn.IFERROR((E30*E12+G30*G12+I30*I12+K30*K12)/(E12+G12+I12+K12),"") -> 26.270553 | N30: =_xlfn.IFERROR((F30*F12+H30*H12+J30*J12+L30*L12)/(F12+H12+J12+L12),"") -> 27.037698
B31: 6.聚丙烯装置收率 | E31: =E69 -> 96.518987 | F31: =F69 -> 96.021948 | K31: =K63 -> 97.218501 | L31: =L63 -> 97.002045 | M31: =_xlfn.IFERROR((E31*E13+G31*G13+I31*I13+K31*K13)/(E13+G13+I13+K13),"") -> 96.984093 | N31: =_xlfn.IFERROR((F31*F13+H31*H13+J31*J13+L31*L13)/(F13+H13+J13+L13),"") -> 96.676685
B32: 7.MTBE收率 | E32: =E70 -> 18.556701 | F32: =F70 -> 18.317359 | K32: =K64 -> 15.723873 | L32: =L64 -> 15.667831 | M32: =_xlfn.IFERROR((E32*E14+G32*G14+I32*I14+K32*K14)/(E14+G14+I14+K14),"") -> 16.738462 | N32: =_xlfn.IFERROR((F32*F14+H32*H14+J32*J14+L32*L14)/(F14+H14+J14+L14),"") -> 16.556528
B33: 8.MTBE转化率 | E33: =E71 -> 99.3 | F33: =F71 -> 99.07 | K33: =K85 -> 99.769849 | L33: =L85 -> 99.802218 | M33: =_xlfn.IFERROR((E33*E14+G33*G14+I33*I14+K33*K14)/(E14+G14+I14+K14),"") -> 99.601571 | N33: =_xlfn.IFERROR((F33*F14+H33*H14+J33*J14+L33*L14)/(F14+H14+J14+L14),"") -> 99.556619
B34: 9.苯抽提装置收率 | I34: =I65 -> 95.329087 | J34: =J65 -> 94.042019 | K34: =K66 -> 99.463327 | L34: =L66 -> 99.471831 | M34: =_xlfn.IFERROR((E34*E15+G34*G15+I34*I15+K34*K15)/(E15+G15+I15+K15),"") -> 97.572816 | N34: =_xlfn.IFERROR((F34*F15+H34*H15+J34*J15+L34*L15)/(F15+H15+J15+L15),"") -> 97.055129
B35: 10.乙苯收率 | E35: =E73 -> 43.539326 | F35: =F73 -> 43.876755 | M35: =_xlfn.IFERROR((E35*E17+G35*G17+I35*I17+K35*K17)/(E17+G17+I17+K17),"") -> 43.539326 | N35: =_xlfn.IFERROR((F35*F17+H35*H17+J35*J17+L35*L17)/(F17+H17+J17+L17),"") -> 43.876755
B36: 11.苯乙烯收率 | E36: =E74 -> 94.968553 | F36: =F74 -> 94.630282 | M36: =_xlfn.IFERROR((E36*E18+G36*G18+I36*I18+K36*K18)/(E18+G18+I18+K18),"") -> 94.968553 | N36: =_xlfn.IFERROR((F36*F18+H36*H18+J36*J18+L36*L18)/(F18+H18+J18+L18),"") -> 94.630282
B37: 12.醋酸仲丁酯收率 | D37: 43.5 | E37: =E75 -> 38.940092 | F37: =F75 -> 37.928716 | M37: =E37 -> 38.940092 | N37: =F37 -> 37.928716
B38: 13.汽油精制总收率 | D38: 98.243421 | G38: =G60 -> 98.89258 | H38: =H60 -> 98.88906 | I38: =I67 -> 99.223678 | J38: =J67 -> 99.224481 | K38: =K68 -> 98.963606 | L38: =L68 -> 99.008406 | M38: =_xlfn.IFERROR((E38*E21+G38*G21+I38*I21+K38*K21)/(E21+G21+I21+K21),"") -> 99.014471 | N38: =_xlfn.IFERROR((F38*F21+H38*H21+J38*J21+L38*L21)/(F21+H21+J21+L21),"") -> 99.035803
B39: 14.柴油精制总收率 | D39: 98.587892 | G39: =G61 -> 99.081272 | H39: =H61 -> 99.207846 | I39: =I68 -> 99.028249 | J39: =J68 -> 99.167509 | K39: =K69 -> 99.303421 | L39: =L69 -> 99.14398 | M39: =_xlfn.IFERROR((E39*E22+G39*G22+I39*I22+K39*K22)/(E22+G22+I22+K22),"") -> 99.151285 | N39: =_xlfn.IFERROR((F39*F22+H39*H22+J39*J22+L39*L22)/(F22+H22+J22+L22),"") -> 99.169189
B40: 15.汽柴液总收率 | E40: =E77 -> 94.657078 | F40: =F77 -> 94.878525 | G40: =G64 -> 81.194257 | H40: =H64 -> 83.332528 | I40: =I69 -> 77.155603 | J40: =J69 -> 75.822281 | M40: =_xlfn.IFERROR((E40*E6+G40*G6+I40*I6)/(E6+G6+I6),"") -> 85.653879 | N40: =_xlfn.IFERROR((F40*F6+H40*H6+J40*J6)/(F6+H6+J6),"") -> 85.705841
...

Sheet 生产日报2
B1: 炼化公司生产日报表
B2: 填报单位：生产计划部 | D2: 统计日期： | F2: =O2 -> 2026-01-06 | H2: 填报日期： | J2: =P2 -> 2026-01-07 | M2: 陕油炼计统B900-1表 | O2: 2026-01-06 | P2: 2026-01-07
B3: 指标名称 | D3: 年计划 | E3: 延安炼油厂 | G3: 永坪炼油厂 | I3: 榆林炼油厂 | K3: 延安石化厂 | M3: 本年合计 | N3: 年完成率
E4: 年累 | G4: 年累 | I4: 年累 | K4: 年累
B5: 一、生产加工量
B6: 1.常压装置加工量 | D6: =IF(生产日报2取值!D6=0,"",生产日报2取值!D6) | E6: =IF(生产日报2取值!E6=0,"",生产日报2取值!E6) -> 117720 | G6: =IF(生产日报2取值!F6=0,"",生产日报2取值!F6) -> 62067 | I6: =IF(生产日报2取值!G6=0,"",生产日报2取值!G6) -> 94349 | M6: =_xlfn.IFERROR(生产日报2取值!I6,"") -> 274136 | N6: =IF(生产日报2取值!J6=0,"",生产日报2取值!J6)
B7: 2.催化装置加工量 | D7: =IF(生产日报2取值!D7=0,"",生产日报2取值!D7) | E7: =IF(生产日报2取值!E7=0,"",生产日报2取值!E7) -> 62050 | G7: =IF(生产日报2取值!F7=0,"",生产日报2取值!F7) -> 26723 | I7: =IF(生产日报2取值!G7=0,"",生产日报2取值!G7) -> 30986 | M7: =_xlfn.IFERROR(生产日报2取值!I7,"") -> 119759 | N7: =IF(生产日报2取值!J7=0,"",生产日报2取值!J7)
B8: 1#渣油加工量 | D8: =IF(生产日报2取值!D8=0,"",生产日报2取值!D8) | E8: =IF(生产日报2取值!E8=0,"",生产日报2取值!E8) -> 61644 | G8: =IF(生产日报2取值!F8=0,"",生产日报2取值!F8) -> 24621 | I8: =IF(生产日报2取值!G8=0,"",生产日报2取值!G8) -> 30175 | M8: =_xlfn.IFERROR(生产日报2取值!I8,"") -> 116440 | N8: =IF(生产日报2取值!J8=0,"",生产日报2取值!J8)
B9: 3.重整装置加工量 | D9: =IF(生产日报2取值!D9=0,"",生产日报2取值!D9) | E9: =IF(生产日报2取值!E9=0,"",生产日报2取值!E9) | G9: =IF(生产日报2取值!F9=0,"",生产日报2取值!F9) -> 4266 | I9: =IF(生产日报2取值!G9=0,"",生产日报2取值!G9) -> 23339 | K9: =IF(生产日报2取值!H9=0,"",生产日报2取值!H9) -> 29955 | M9: =_xlfn.IFERROR(生产日报2取值!I9,"") -> 57560 | N9: =IF(生产日报2取值!J9=0,"",生产日报2取值!J9)
B10: 4.加氢装置加工量 | D10: =IF(生产日报2取值!D10=0,"",生产日报2取值!D10) | E10: =IF(生产日报2取值!E10=0,"",生产日报2取值!E10) | G10: =IF(生产日报2取值!F10=0,"",生产日报2取值!F10) | I10: =IF(生产日报2取值!G10=0,"",生产日报2取值!G10) | K10: =IF(生产日报2取值!H10=0,"",生产日报2取值!H10) -> 16921 | M10: =_xlfn.IFERROR(生产日报2取值!I10,"") -> 16921 | N10: =IF(生产日报2取值!J10=0,"",生产日报2取值!J10)
B11: 5.液化气精制量 | D11: =IF(生产日报2取值!D11=0,"",生产日报2取值!D11) | E11: =IF(生产日报2取值!E11=0,"",生产日报2取值!E11) -> 6156 | G11: =IF(生产日报2取值!F11=0,"",生产日报2取值!F11) | I11: =IF(生产日报2取值!G11=0,"",生产日报2取值!G11) | K11: =IF(生产日报2取值!H11=0,"",生产日报2取值!H11) -> 11752 | M11: =_xlfn.IFERROR(生产日报2取值!I11,"") -> 17908 | N11: =IF(生产日报2取值!J11=0,"",生产日报2取值!J11)
B12: 6.气体分馏加工量 | D12: =IF(生产日报2取值!D12=0,"",生产日报2取值!D12) | E12: =IF(生产日报2取值!E12=0,"",生产日报2取值!E12) -> 6135 | G12: =IF(生产日报2取值!F12=0,"",生产日报2取值!F12) | I12: =IF(生产日报2取值!G12=0,"",生产日报2取值!G12) | K12: =IF(生产日报2取值!H12=0,"",生产日报2取值!H12) -> 12354 | M12: =_xlfn.IFERROR(生产日报2取值!I12,"") -> 18489 | N12: =IF(生产日报2取值!J12=0,"",生产日报2取值!J12)
B13: 7.聚丙烯加工量 | D13: =IF(生产日报2取值!D13=0,"",生产日报2取值!D13) | E13: =IF(生产日报2取值!E13=0,"",生产日报2取值!E13) -> 2187 | G13: =IF(生产日报2取值!F13=0,"",生产日报2取值!F13) | I13: =IF(生产日报2取值!G13=0,"",生产日报2取值!G13) | K13: =IF(生产日报2取值!H13=0,"",生产日报2取值!H13) -> 4401 | M13: =_xlfn.IFERROR(生产日报2取值!I13,"") -> 6588 | N13: =IF(生产日报2取值!J13=0,"",生产日报2取值!J13)
B14: 8.MTBE加工量 | D14: =IF(生产日报2取值!D14=0,"",生产日报2取值!D14) | E14: =IF(生产日报2取值!E14=0,"",生产日报2取值!E14) -> 3756 | G14: =IF(生产日报2取值!F14=0,"",生产日报2取值!F14) | I14: =IF(生产日报2取值!G14=0,"",生产日报2取值!G14) | K14: =IF(生产日报2取值!H14=0,"",生产日报2取值!H14) -> 7442 | M14: =_xlfn.IFERROR(生产日报2取值!I14,"") -> 11198 | N14: =IF(生产日报2取值!J14=0,"",生产日报2取值!J14)
B15: 9.苯抽提加工量 | D15: =IF(生产日报2取值!D15=0,"",生产日报2取值!D15) | E15: =IF(生产日报2取值!E15=0,"",生产日报2取值!E15) | G15: =IF(生产日报2取值!F15=0,"",生产日报2取值!F15) | I15: =IF(生产日报2取值!G15=0,"",生产日报2取值!G15) -> 3189 | K15: =IF(生产日报2取值!H15=0,"",生产日报2取值!H15) -> 3976 | M15: =_xlfn.IFERROR(生产日报2取值!I15,"") -> 7165 | N15: =IF(生产日报2取值!J15=0,"",生产日报2取值!J15)
B16: 10.干气精制加工量 | D16: =IF(生产日报2取值!D16=0,"",生产日报2取值!D16) | E16: =IF(生产日报2取值!E16=0,"",生产日报2取值!E16) -> 2164 | G16: =IF(生产日报2取值!F16=0,"",生产日报2取值!F16) | I16: =IF(生产日报2取值!G16=0,"",生产日报2取值!G16) | K16: =IF(生产日报2取值!H16=0,"",生产日报2取值!H16) | M16: =_xlfn.IFERROR(生产日报2取值!I16,"") -> 2164 | N16: =IF(生产日报2取值!J16=0,"",生产日报2取值!J16)
B17: 11.乙苯加工量 | D17: =IF(生产日报2取值!D17=0,"",生产日报2取值!D17) | E17: =IF(生产日报2取值!E17=0,"",生产日报2取值!E17) -> 2564 | G17: =IF(生产日报2取值!F17=0,"",生产日报2取值!F17) | I17: =IF(生产日报2取值!G17=0,"",生产日报2取值!G17) | K17: =IF(生产日报2取值!H17=0,"",生产日报2取值!H17) | M17: =_xlfn.IFERROR(生产日报2取值!I17,"") -> 2564 | N17: =IF(生产日报2取值!J17=0,"",生产日报2取值!J17)
B18: 12.苯乙烯加工量 | D18: =IF(生产日报2取值!D18=0,"",生产日报2取值!D18) | E18: =IF(生产日报2取值!E18=0,"",生产日报2取值!E18) -> 1155 | G18: =IF(生产日报2取值!F18=0,"",生产日报2取值!F18) | I18: =IF(生产日报2取值!G18=0,"",生产日报2取值!G18) | K18: =IF(生产日报2取值!H18=0,"",生产日报2取值!H18) | M18: =_xlfn.IFERROR(生产日报2取值!I18,"") -> 1155 | N18: =IF(生产日报2取值!J18=0,"",生产日报2取值!J18)
B19: 13.醋酸仲丁酯装置加工量 | D19: =IF(生产日报2取值!D19=0,"",生产日报2取值!D19) | E19: =IF(生产日报2取值!E19=0,"",生产日报2取值!E19) -> 2974 | G19: =IF(生产日报2取值!F19=0,"",生产日报2取值!F19) | I19: =IF(生产日报2取值!G19=0,"",生产日报2取值!G19) | K19: =IF(生产日报2取值!H19=0,"",生产日报2取值!H19) | M19: =_xlfn.IFERROR(生产日报2取值!I19,"") -> 2974 | N19: =IF(生产日报2取值!J19=0,"",生产日报2取值!J19)
B20: 其中：醋酸原料 | D20: =IF(生产日报2取值!D20=0,"",生产日报2取值!D20) | E20: =IF(生产日报2取值!E20=0,"",生产日报2取值!E20) -> 611 | G20: =IF(生产日报2取值!F20=0,"",生产日报2取值!F20) | I20: =IF(生产日报2取值!G20=0,"",生产日报2取值!G20) | K20: =IF(生产日报2取值!H20=0,"",生产日报2取值!H20) | M20: =_xlfn.IFERROR(生产日报2取值!I20,"") -> 611 | N20: =IF(生产日报2取值!J20=0,"",生产日报2取值!J20)
... B22: 15.柴油精制加工量 | D22: =IF(生产日报2取值!D22=0,"",生产日报2取值!D22) | E22: =IF(生产日报2取值!E22=0,"",生产日报2取值!E22) | G22: =IF(生产日报2取值!F22=0,"",生产日报2取值!F22) -> 23859 | I22: =IF(生产日报2取值!G22=0,"",生产日报2取值!G22) -> 33634 | K22: =IF(生产日报2取值!H22=0,"",生产日报2取值!H22) -> 34345 | M22: =_xlfn.IFERROR(生产日报2取值!I22,"") -> 91838 | N22: =IF(生产日报2取值!J22=0,"",生产日报2取值!J22)
B23: 二、装置收率 | E23: =IF(生产日报2取值!E23=0,"",生产日报2取值!E23) | G23: =IF(生产日报2取值!F23=0,"",生产日报2取值!F23) | I23: =IF(生产日报2取值!G23=0,"",生产日报2取值!G23) | K23: =IF(生产日报2取值!H23=0,"",生产日报2取值!H23) | N23: =IF(生产日报2取值!J23=0,"",生产日报2取值!J23)
B24: 1.常压轻质油收率 | D24: =IF(生产日报2取值!D24=0,"",生产日报2取值!D24) | E24: =IF(生产日报2取值!E24=0,"",生产日报2取值!E24) -> 48.547401 | G24: =IF(生产日报2取值!F24=0,"",生产日报2取值!F24) -> 49.121111 | I24: =IF(生产日报2取值!G24=0,"",生产日报2取值!G24) -> 52.837868 | K24: =IF(生产日报2取值!H24=0,"",生产日报2取值!H24) | M24: =IF(生产日报2取值!I24=0,"",生产日报2取值!I24) -> 50.153938
B25: 2.催化轻质油收率 | D25: =IF(生产日报2取值!D25=0,"",生产日报2取值!D25) | E25: =IF(生产日报2取值!E25=0,"",生产日报2取值!E25) -> 71.452055 | G25: =IF(生产日报2取值!F25=0,"",生产日报2取值!F25) -> 71.197096 | I25: =IF(生产日报2取值!G25=0,"",生产日报2取值!G25) -> 70.180081 | K25: =IF(生产日报2取值!H25=0,"",生产日报2取值!H25) | M25: =IF(生产日报2取值!I25=0,"",生产日报2取值!I25) -> 71.066058
B26: 液化气收率 | D26: =IF(生产日报2取值!D26=0,"",生产日报2取值!D26) | E26: =IF(生产日报2取值!E26=0,"",生产日报2取值!E26) -> 16.446414 | G26: =IF(生产日报2取值!F26=0,"",生产日报2取值!F26) -> 16.02365 | I26: =IF(生产日报2取值!G26=0,"",生产日报2取值!G26) -> 14.755051 | K26: =IF(生产日报2取值!H26=0,"",生产日报2取值!H26) | M26: =IF(生产日报2取值!I26=0,"",生产日报2取值!I26) -> 15.918711
B27: 3.重整装置总收率 | D27: =IF(生产日报2取值!D27=0,"",生产日报2取值!D27) | E27: =IF(生产日报2取值!E27=0,"",生产日报2取值!E27) | G27: =IF(生产日报2取值!F27=0,"",生产日报2取值!F27) -> 93.459916 | I27: =IF(生产日报2取值!G27=0,"",生产日报2取值!G27) -> 93.208792 | K27: =IF(生产日报2取值!H27=0,"",生产日报2取值!H27) -> 93.216491 | M27: =IF(生产日报2取值!I27=0,"",生产日报2取值!I27) -> 93.231411
B28: 4.加氢装置总收率 | D28: =IF(生产日报2取值!D28=0,"",生产日报2取值!D28) | E28: =IF(生产日报2取值!E28=0,"",生产日报2取值!E28) | G28: =IF(生产日报2取值!F28=0,"",生产日报2取值!F28) | I28: =IF(生产日报2取值!G28=0,"",生产日报2取值!G28) | K28: =IF(生产日报2取值!H28=0,"",生产日报2取值!H28) -> 99.728148 | M28: =IF(生产日报2取值!I28=0,"",生产日报2取值!I28) -> 99.728148
B29: 5.气分装置收率 | D29: =IF(生产日报2取值!D29=0,"",生产日报2取值!D29) | E29: =IF(生产日报2取值!E29=0,"",生产日报2取值!E29) -> 99.657702 | G29: =IF(生产日报2取值!F29=0,"",生产日报2取值!F29) | I29: =IF(生产日报2取值!G29=0,"",生产日报2取值!G29) | K29: =IF(生产日报2取值!H29=0,"",生产日报2取值!H29) -> 97.95208 | M29: =IF(生产日报2取值!I29=0,"",生产日报2取值!I29) -> 98.518038
B30: 丙烯收率 | D30: =IF(生产日报2取值!D30=0,"",生产日报2取值!D30) | E30: =IF(生产日报2取值!E30=0,"",生产日报2取值!E30) -> 27.628362 | G30: =IF(生产日报2取值!F30=0,"",生产日报2取值!F30) | I30: =IF(生产日报2取值!G30=0,"",生产日报2取值!G30) | K30: =IF(生产日报2取值!H30=0,"",生产日报2取值!H30) -> 26.744374 | M30: =IF(生产日报2取值!I30=0,"",生产日报2取值!I30) -> 27.037698
B31: 6.聚丙烯装置收率 | D31: =IF(生产日报2取值!D31=0,"",生产日报2取值!D31) | E31: =IF(生产日报2取值!E31=0,"",生产日报2取值!E31) -> 96.021948 | G31: =IF(生产日报2取值!F31=0,"",生产日报2取值!F31) | I31: =IF(生产日报2取值!G31=0,"",生产日报2取值!G31) | K31: =IF(生产日报2取值!H31=0,"",生产日报2取值!H31) -> 97.002045 | M31: =IF(生产日报2取值!I31=0,"",生产日报2取值!I31) -> 96.676685
B32: 7.MTBE收率 | D32: =IF(生产日报2取值!D32=0,"",生产日报2取值!D32) | E32: =IF(生产日报2取值!E32=0,"",生产日报2取值!E32) -> 18.317359 | G32: =IF(生产日报2取值!F32=0,"",生产日报2取值!F32) | I32: =IF(生产日报2取值!G32=0,"",生产日报2取值!G32) | K32: =IF(生产日报2取值!H32=0,"",生产日报2取值!H32) -> 15.667831 | M32: =IF(生产日报2取值!I32=0,"",生产日报2取值!I32) -> 16.556528
B33: 8.MTBE转化率 | D33: =IF(生产日报2取值!D33=0,"",生产日报2取值!D33) | E33: =IF(生产日报2取值!E33=0,"",生产日报2取值!E33) | G33: =IF(生产日报2取值!F33=0,"",生产日报2取值!F33) | I33: =IF(生产日报2取值!G33=0,"",生产日报2取值!G33) | K33: =_xlfn.IFERROR(IF(生产日报2取值!H33=0,"",生产日报2取值!H33),"") -> 99.802218 | M33: =IF(生产日报2取值!I33=0,"",生产日报2取值!I33) -> 66.326853
B34: 9.苯抽提装置收率 | D34: =IF(生产日报2取值!D34=0,"",生产日报2取值!D34) | E34: =IF(生产日报2取值!E34=0,"",生产日报2取值!E34) | G34: =IF(生产日报2取值!F34=0,"",生产日报2取值!F34) | I34: =IF(生产日报2取值!G34=0,"",生产日报2取值!G34) -> 94.042019 | K34: =IF(生产日报2取值!H34=0,"",生产日报2取值!H34) -> 99.471831 | M34: =IF(生产日报2取值!I34=0,"",生产日报2取值!I34) -> 97.055129
B35: 10.乙苯收率 | D35: =IF(生产日报2取值!D35=0,"",生产日报2取值!D35) | E35: =IF(生产日报2取值!E35=0,"",生产日报2取值!E35) -> 43.876755 | G35: =IF(生产日报2取值!F35=0,"",生产日报2取值!F35) | I35: =IF(生产日报2取值!G35=0,"",生产日报2取值!G35) | K35: =IF(生产日报2取值!H35=0,"",生产日报2取值!H35) | M35: =IF(生产日报2取值!I35=0,"",生产日报2取值!I35) -> 43.876755
B36: 11.苯乙烯收率 | D36: =IF(生产日报2取值!D36=0,"",生产日报2取值!D36) | E36: =IF(生产日报2取值!E36=0,"",生产日报2取值!E36) -> 94.630282 | G36: =IF(生产日报2取值!F36=0,"",生产日报2取值!F36) | I36: =IF(生产日报2取值!G36=0,"",生产日报2取值!G36) | K36: =IF(生产日报2取值!H36=0,"",生产日报2取值!H36) | M36: =IF(生产日报2取值!I36=0,"",生产日报2取值!I36) -> 94.630282
B37: 12.醋酸仲丁酯收率 | D37: =IF(生产日报2取值!D37=0,"",生产日报2取值!D37) | E37: =IF(生产日报2取值!E37=0,"",生产日报2取值!E37) -> 37.928716 | G37: =IF(生产日报2取值!F37=0,"",生产日报2取值!F37) | I37: =IF(生产日报2取值!G37=0,"",生产日报2取值!G37) | K37: =IF(生产日报2取值!H37=0,"",生产日报2取值!H37) | M37: =IF(生产日报2取值!I37=0,"",生产日报2取值!I37) -> 37.928716
B38: 13.汽油精制总收率 | D38: =IF(生产日报2取值!D38=0,"",生产日报2取值!D38) | E38: =IF(生产日报2取值!E38=0,"",生产日报2取值!E38) | G38: =IF(生产日报2取值!F38=0,"",生产日报2取值!F38) -> 98.88906 | I38: =IF(生产日报2取值!G38=0,"",生产日报2取值!G38) -> 99.224481 | K38: =IF(生产日报2取值!H38=0,"",生产日报2取值!H38) -> 99.008406 | M38: =IF(生产日报2取值!I38=0,"",生产日报2取值!I38) -> 99.035803
B39: 14.柴油精制总收率 | D39: =IF(生产日报2取值!D39=0,"",生产日报2取值!D39) | E39: =IF(生产日报2取值!E39=0,"",生产日报2取值!E39) | G39: =IF(生产日报2取值!F39=0,"",生产日报2取值!F39) -> 99.207846 | I39: =IF(生产日报2取值!G39=0,"",生产日报2取值!G39) -> 99.167509 | K39: =IF(生产日报2取值!H39=0,"",生产日报2取值!H39) -> 99.14398 | M39: =IF(生产日报2取值!I39=0,"",生产日报2取值!I39) -> 99.169189
B40: 15.汽柴液总收率 | D40: =IF(生产日报2取值!D40=0,"",生产日报2取值!D40) | E40: =IF(生产日报2取值!E40=0,"",生产日报2取值!E40) -> 94.878525 | G40: =IF(生产日报2取值!F40=0,"",生产日报2取值!F40) -> 83.332528 | I40: =IF(生产日报2取值!G40=0,"",生产日报2取值!G40) -> 75.822743 | K40: =IF(生产日报2取值!H40=0,"",生产日报2取值!H40) | M40: =IF(生产日报2取值!I40=0,"",生产日报2取值!I40) -> 85.706
B41: 三、原料调运 | D41: =IF(生产日报2取值!D41=0,"",生产日报2取值!D41) | E41: =IF(生产日报2取值!E41=0,"",生产日报2取值!E41) | G41: =IF(生产日报2取值!F41=0,"",生产日报2取值!F41) | I41: =IF(生产日报2取值!G41=0,"",生产日报2取值!G41) | K41: =IF(生产日报2取值!H41=0,"",生产日报2取值!H41)
...

Sheet 生产日报2取值
B1: 炼化公司生产日报表
B2: 填报单位： | C2: 生产计划部 | F2: 2026-01-06 | G2: 8:00:00 | H2: 2026-01-07 | I2: 陕油炼计统B900-1表
B3: 指标名称 | D3: 年计划 | I3: 本年合计 | J3: 年完成率%
E4: 年累 | F4: 年累 | G4: 年累 | H4: 年累
B5: 一、生产加工量
B6: 1.常压装置加工量 | E6: =_xlfn.IFERROR(E54,"") -> 117720 | F6: =_xlfn.IFERROR(F54,"") -> 62067 | G6: =_xlfn.IFERROR(G112,"") -> 94349 | I6: =E6+F6+G6+H6 -> 274136 | J6: =_xlfn.IFERROR(I6/生产日报2取值!D6*100,"")
B7: 2.催化装置加工量 | E7: =_xlfn.IFERROR(E57,"") -> 62050 | F7: =_xlfn.IFERROR(F55,"") -> 26723 | G7: =_xlfn.IFERROR(G113,"") -> 30986 | I7: =E7+F7+G7+H7 -> 119759 | J7: =_xlfn.IFERROR(I7/生产日报2取值!D7*100,"")
B8: 1#渣油加工量 | E8: =_xlfn.IFERROR(E60,"") -> 61644 | F8: =_xlfn.IFERROR(F56,"") -> 24621 | G8: =_xlfn.IFERROR(G114,"") -> 30175 | I8: =E8+F8+G8+H8 -> 116440 | J8: =_xlfn.IFERROR(I8/生产日报2取值!D8*100,"")
B9: 3.重整装置加工量 | F9: =_xlfn.IFERROR(F57,"") -> 4266 | G9: =_xlfn.IFERROR(G115,"") -> 23339 | H9: =_xlfn.IFERROR(H57,"") -> 29955 | I9: =E9+F9+G9+H9 -> 57560 | J9: =_xlfn.IFERROR(I9/生产日报2取值!D9*100,"")
B10: 4.加氢装置加工量 | G10: =_xlfn.IFERROR(G140,"") -> 0 | H10: =_xlfn.IFERROR(H59,"") -> 16921 | I10: =E10+F10+G10+H10 -> 16921 | J10: =_xlfn.IFERROR(I10/生产日报2取值!D10*100,"")
B11: 5.液化气精制量 | E11: =_xlfn.IFERROR(E65,"") -> 6156 | H11: =_xlfn.IFERROR(H63,"") -> 11752 | I11: =E11+F11+G11+H11 -> 17908 | J11: =_xlfn.IFERROR(I11/生产日报2取值!D11*100,"")
B12: 6.气体分馏加工量 | E12: =_xlfn.IFERROR(E67,"") -> 6135 | H12: =_xlfn.IFERROR(H66,"") -> 12354 | I12: =E12+F12+G12+H12 -> 18489 | J12: =_xlfn.IFERROR(I12/生产日报2取值!D12*100,"")
B13: 7.聚丙烯加工量 | E13: =_xlfn.IFERROR(E69,"") -> 2187 | H13: =_xlfn.IFERROR(H70,"") -> 4401 | I13: =E13+F13+G13+H13 -> 6588 | J13: =_xlfn.IFERROR(I13/生产日报2取值!D13*100,"")
B14: 8.MTBE加工量 | E14: =_xlfn.IFERROR(E71,"") -> 3756 | H14: =_xlfn.IFERROR(H72,"") -> 7442 | I14: =E14+F14+G14+H14 -> 11198 | J14: =_xlfn.IFERROR(I14/生产日报2取值!D14*100,"")
B15: 9.苯抽提加工量 | G15: =_xlfn.IFERROR(G117,"") -> 3189 | H15: =_xlfn.IFERROR(H79,"") -> 3976 | I15: =E15+F15+G15+H15 -> 7165 | J15: =_xlfn.IFERROR(I15/生产日报2取值!D15*100,"")
B16: 10.干气精制加工量 | E16: =_xlfn.IFERROR(E75,"") -> 2164 | I16: =E16+F16+G16+H16 -> 2164 | J16: =_xlfn.IFERROR(I16/生产日报2取值!D16*100,"")
B17: 11.乙苯加工量 | E17: =_xlfn.IFERROR(E77,"") -> 2564 | I17: =E17+F17+G17+H17 -> 2564 | J17: =_xlfn.IFERROR(I17/生产日报2取值!D17*100,"")
B18: 12.苯乙烯加工量 | E18: =_xlfn.IFERROR(E86,"") -> 1155 | I18: =E18+F18+G18+H18 -> 1155 | J18: =_xlfn.IFERROR(I18/生产日报2取值!D18*100,"")
B19: 13.醋酸装置加工量 | E19: =_xlfn.IFERROR(E81,"") -> 2974 | I19: =E19+F19+G19+H19 -> 2974 | J19: =_xlfn.IFERROR(I19/生产日报2取值!D19*100,"")
B20: 其中：醋酸原料 | E20: =_xlfn.IFERROR(E84,"") -> 611 | I20: =E20+F20+G20+H20 -> 611 | J20: =_xlfn.IFERROR(I20/生产日报2取值!D20*100,"")
B21: 14.汽油精制加工量 | F21: =_xlfn.IFERROR(F58,"") -> 12962 | G21: =_xlfn.IFERROR(G118,"") -> 14313 | H21: =_xlfn.IFERROR(H56,"") -> 29145 | I21: =E21+F21+G21+H21 -> 56420 | J21: =_xlfn.IFERROR(I21/生产日报2取值!D21*100,"")
B22: 15.柴油精制加工量 | F22: =_xlfn.IFERROR(F59,"") -> 23859 | G22: =_xlfn.IFERROR(G119,"") -> 33634 | H22: =_xlfn.IFERROR(H58,"") -> 34345 | I22: =E22+F22+G22+H22 -> 91838 | J22: =_xlfn.IFERROR(I22/生产日报2取值!D22*100,"")
B23: 二、装置收率
B24: 1.常压轻质油收率 | E24: =_xlfn.IFERROR(E103,"") -> 48.547401 | F24: =F71 -> 49.121111 | G24: =G142 -> 52.837868 | I24: =_xlfn.IFERROR((E24*E6+F24*F6+G24*G6+H24*H6)/(E6+F6+G6+H6),"") -> 50.153938 | J24: =_xlfn.IFERROR(I24/D24*100,"")
B25: 2.催化轻质油收率 | E25: =_xlfn.IFERROR(E92,"") -> 71.452055 | F25: =F72 -> 71.197096 | G25: =G143 -> 70.180081 | I25: =_xlfn.IFERROR((E25*E7+F25*F7+G25*G7+H25*H7)/(E7+F7+G7+H7),"") -> 71.066058 | J25: =_xlfn.IFERROR(I25/D25*100,"")
B26: 液化气收率 | E26: =_xlfn.IFERROR(E89,"") -> 16.446414 | F26: =F73 -> 16.02365 | G26: =G144 -> 14.755051 | I26: =_xlfn.IFERROR((E26*E8+F26*F8+G26*G8+H26*H8)/(E8+F8+G8+H8),"") -> 15.918711 | J26: =_xlfn.IFERROR(I26/D26*100,"")
B27: 3.重整装置总收率 | F27: =F74 -> 93.459916 | G27: =G145 -> 93.208792 | H27: =_xlfn.IFERROR(H164,"") -> 93.216491 | I27: =_xlfn.IFERROR((E27*E9+F27*F9+G27*G9+H27*H9)/(E9+F9+G9+H9),"") -> 93.231411 | J27: =_xlfn.IFERROR(I27/D27*100,"")
B28: 4.加氢装置总收率 | G28: =G146 -> 0 | H28: =_xlfn.IFERROR(H165,"") -> 99.728148 | I28: =_xlfn.IFERROR((E28*E10+F28*F10+H28*H10)/(E10+F10+H10),"") -> 99.728148 | J28: =_xlfn.IFERROR(I28/D28*100,"")
B29: 5.气分装置收率 | E29: =_xlfn.IFERROR(E98,"") -> 99.657702 | H29: =_xlfn.IFERROR(H166,"") -> 97.95208 | I29: =_xlfn.IFERROR((E29*E12+F29*F12+G29*G12+H29*H12)/(E12+F12+G12+H12),"") -> 98.518038 | J29: =_xlfn.IFERROR(I29/D29*100,"")
B30: 丙烯收率 | E30: =_xlfn.IFERROR(E131,"") -> 27.628362 | H30: =_xlfn.IFERROR(H167,"") -> 26.744374 | I30: =_xlfn.IFERROR((E30*E12+F30*F12+G30*G12+H30*H12)/(E12+F12+G12+H12),"") -> 27.037698 | J30: =_xlfn.IFERROR(I30/D30*100,"")
B31: 6.聚丙烯装置收率 | E31: =_xlfn.IFERROR(E114,"") -> 96.021948 | H31: =_xlfn.IFERROR(H168,"") -> 97.002045 | I31: =_xlfn.IFERROR((E31*E13+F31*F13+G31*G13+H31*H13)/(E13+F13+G13+H13),"") -> 96.676685 | J31: =_xlfn.IFERROR(I31/D31*100,"")
B32: 7.MTBE收率 | E32: =_xlfn.IFERROR(E112,"") -> 18.317359 | H32: =_xlfn.IFERROR(H169,"") -> 15.667831 | I32: =_xlfn.IFERROR((E32*E14+F32*F14+G32*G14+H32*H14)/(E14+F14+G14+H14),"") -> 16.556528 | J32: =_xlfn.IFERROR(I32/D32*100,"")
B33: 8.MTBE转化率 | E33: =_xlfn.IFERROR(E109,"") -> 0 | H33: =H194 -> 99.802218 | I33: =_xlfn.IFERROR((E33*E14+F33*F14+G33*G14+H33*H14)/(E14+F14+G14+H14),"") -> 66.326853 | J33: =_xlfn.IFERROR(I33/D33*100,"")
B34: 9.苯抽提装置收率 | G34: =G152 -> 94.042019 | H34: =_xlfn.IFERROR(H171,"") -> 99.471831 | I34: =_xlfn.IFERROR((E34*E15+F34*F15+G34*G15+H34*H15)/(E15+F15+G15+H15),"") -> 97.055129 | J34: =_xlfn.IFERROR(I34/D34*100,"")
B35: 10.乙苯收率 | E35: =_xlfn.IFERROR(E121,"") -> 43.876755 | I35: =E35 -> 43.876755 | J35: =_xlfn.IFERROR(I35/D35*100,"")
B36: 11.苯乙烯收率 | E36: =_xlfn.IFERROR(E62,"") -> 94.630282 | I36: =E36 -> 94.630282 | J36: =_xlfn.IFERROR(I36/D36*100,"")
B37: 12.醋酸仲丁酯收率 | E37: =_xlfn.IFERROR(E134,"") -> 37.928716 | I37: =E37 -> 37.928716 | J37: =_xlfn.IFERROR(I37/D37*100,"")
B38: 13.汽油精制总收率 | F38: =F85 -> 98.88906 | G38: =G156 -> 99.224481 | H38: =_xlfn.IFERROR(H175,"") -> 99.008406 | I38: =_xlfn.IFERROR((E38*E21+F38*F21+G38*G21+H38*H21)/(E21+F21+G21+H21),"") -> 99.035803 | J38: =_xlfn.IFERROR(I38/D38*100,"")
B39: 14.柴油精制总收率 | F39: =F86 -> 99.207846 | G39: =G157 -> 99.167509 | H39: =_xlfn.IFERROR(H176,"") -> 99.14398 | I39: =_xlfn.IFERROR((E39*E22+F39*F22+G39*G22+H39*H22)/(E22+F22+G22+H22),"") -> 99.169189 | J39: =_xlfn.IFERROR(I39/D39*100,"")
B40: 15.汽柴液总收率 | E40: =_xlfn.IFERROR(E136,"") -> 94.878525 | F40: =F87 -> 83.332528 | G40: =G158 -> 75.822743 | I40: =_xlfn.IFERROR((E40*E6+F40*F6+G40*G6+H40*H6)/(E6+F6+G6+H6),"") -> 85.706 | J40: =_xlfn.IFERROR(I40/D40*100,"")
...

Sheet 生产日报3
B1: 炼化公司生产日报表
B2: 填报单位：生产计划部 | D2: 统计日期： | F2: =P2 -> 2026-01-06 | H2: 填报日期： | J2: =Q2 -> 2026-01-07 | M2: 陕油炼计统B900-1表 | P2: 2026-01-06 | Q2: 2026-01-07
B3: 指标名称 | D3: 月计划 | E3: 延安炼油厂 | G3: 永坪炼油厂 | I3: 榆林炼油厂 | K3: 延安石化厂 | M3: 公司合计 | N3: 本月累计 | O3: 月完成率%
E4: 当日 | F4: 月累 | G4: 当日 | H4: 月累 | I4: 当日 | J4: 月累 | K4: 当日 | L4: 月累
B5: 3.催化柴油调出量 | D5: =IF(生产日报3取值!D5=0,"",生产日报3取值!D5) | E5: =IF(生产日报3取值!E5=0,"",生产日报3取值!E5) -> 2447 | F5: =IF(生产日报3取值!F5=0,"",生产日报3取值!F5) -> 15104 | G5: =IF(生产日报3取值!G5=0,"",生产日报3取值!G5) | H5: =IF(生产日报3取值!H5=0,"",生产日报3取值!H5) | I5: =IF(生产日报3取值!I5=0,"",生产日报3取值!I5) | J5: =IF(生产日报3取值!J5=0,"",生产日报3取值!J5) | K5: =IF(生产日报3取值!K5=0,"",生产日报3取值!K5) | ... N5: =IF(生产日报3取值!N5=0,"",生产日报3取值!N5) -> 15104
B6: 催化柴油调入量 | D6: =IF(生产日报3取值!D6=0,"",生产日报3取值!D6) | E6: =IF(生产日报3取值!E6=0,"",生产日报3取值!E6) | F6: =IF(生产日报3取值!F6=0,"",生产日报3取值!F6) | G6: =IF(生产日报3取值!G6=0,"",生产日报3取值!G6) | H6: =IF(生产日报3取值!H6=0,"",生产日报3取值!H6) | I6: =IF(生产日报3取值!I6=0,"",生产日报3取值!I6) | J6: =IF(生产日报3取值!J6=0,"",生产日报3取值!J6) | K6: =IF(生产日报3取值!K6=0,"",生产日报3取值!K6) -> 2447 | ... N6: =IF(生产日报3取值!N6=0,"",生产日报3取值!N6) -> 15427.98
B7: 4.液化气调出量 | D7: =IF(生产日报3取值!D7=0,"",生产日报3取值!D7) | E7: =IF(生产日报3取值!E7=0,"",生产日报3取值!E7) -> 1632 | F7: =IF(生产日报3取值!F7=0,"",生产日报3取值!F7) -> 10912 | G7: =IF(生产日报3取值!G7=0,"",生产日报3取值!G7) -> 709 | H7: =IF(生产日报3取值!H7=0,"",生产日报3取值!H7) -> 3190 | I7: =IF(生产日报3取值!I7=0,"",生产日报3取值!I7) -> 536.32 | J7: =IF(生产日报3取值!J7=0,"",生产日报3取值!J7) -> 3055.94 | K7: =IF(生产日报3取值!K7=0,"",生产日报3取值!K7) | ... N7: =IF(生产日报3取值!N7=0,"",生产日报3取值!N7) -> 17157.94
B8: 液化气调入量 | D8: =IF(生产日报3取值!D8=0,"",生产日报3取值!D8) | E8: =IF(生产日报3取值!E8=0,"",生产日报3取值!E8) -> 1056.16 | F8: =IF(生产日报3取值!F8=0,"",生产日报3取值!F8) -> 6778.44 | G8: =IF(生产日报3取值!G8=0,"",生产日报3取值!G8) | H8: =IF(生产日报3取值!H8=0,"",生产日报3取值!H8) | I8: =IF(生产日报3取值!I8=0,"",生产日报3取值!I8) | J8: =IF(生产日报3取值!J8=0,"",生产日报3取值!J8) | K8: =IF(生产日报3取值!K8=0,"",生产日报3取值!K8) -> 1632 | ... N8: =IF(生产日报3取值!N8=0,"",生产日报3取值!N8) -> 17690.44
B9: 5.丙烯转出量 | D9: =IF(生产日报3取值!D9=0,"",生产日报3取值!D9) | E9: =IF(生产日报3取值!E9=0,"",生产日报3取值!E9) -> 95.22 | F9: =IF(生产日报3取值!F9=0,"",生产日报3取值!F9) -> 571.28 | G9: =IF(生产日报3取值!G9=0,"",生产日报3取值!G9) | H9: =IF(生产日报3取值!H9=0,"",生产日报3取值!H9) | I9: =IF(生产日报3取值!I9=0,"",生产日报3取值!I9) | J9: =IF(生产日报3取值!J9=0,"",生产日报3取值!J9) | K9: =IF(生产日报3取值!K9=0,"",生产日报3取值!K9) | ... N9: =IF(生产日报3取值!N9=0,"",生产日报3取值!N9) -> 571.28
B10: 丙烯转入量 | D10: =IF(生产日报3取值!D10=0,"",生产日报3取值!D10) | E10: =IF(生产日报3取值!E10=0,"",生产日报3取值!E10) -> 296 | F10: =IF(生产日报3取值!F10=0,"",生产日报3取值!F10) -> 1527 | G10: =IF(生产日报3取值!G10=0,"",生产日报3取值!G10) | H10: =IF(生产日报3取值!H10=0,"",生产日报3取值!H10) | I10: =IF(生产日报3取值!I10=0,"",生产日报3取值!I10) | J10: =IF(生产日报3取值!J10=0,"",生产日报3取值!J10) | K10: =IF(生产日报3取值!K10=0,"",生产日报3取值!K10) | ... N10: =IF(生产日报3取值!N10=0,"",生产日报3取值!N10) -> 1527
B11: 6.汽油精制原料转出 | D11: =IF(生产日报3取值!D11=0,"",生产日报3取值!D11) | E11: =IF(生产日报3取值!E11=0,"",生产日报3取值!E11) -> 4106 | F11: =IF(生产日报3取值!F11=0,"",生产日报3取值!F11) -> 29162 | G11: =IF(生产日报3取值!G11=0,"",生产日报3取值!G11) | H11: =IF(生产日报3取值!H11=0,"",生产日报3取值!H11) | I11: =IF(生产日报3取值!I11=0,"",生产日报3取值!I11) | J11: =IF(生产日报3取值!J11=0,"",生产日报3取值!J11) | K11: =IF(生产日报3取值!K11=0,"",生产日报3取值!K11) | ... N11: =IF(生产日报3取值!N11=0,"",生产日报3取值!N11) -> 29162
B12: 汽油精制原料转入 | D12: =IF(生产日报3取值!D12=0,"",生产日报3取值!D12) | E12: =IF(生产日报3取值!E12=0,"",生产日报3取值!E12) | F12: =IF(生产日报3取值!F12=0,"",生产日报3取值!F12) | G12: =IF(生产日报3取值!G12=0,"",生产日报3取值!G12) | H12: =IF(生产日报3取值!H12=0,"",生产日报3取值!H12) | I12: =IF(生产日报3取值!I12=0,"",生产日报3取值!I12) | J12: =IF(生产日报3取值!J12=0,"",生产日报3取值!J12) | K12: =IF(生产日报3取值!K12=0,"",生产日报3取值!K12) -> 4106 | ... N12: =IF(生产日报3取值!N12=0,"",生产日报3取值!N12) -> 29162
B13: 7.柴油精制原料转出 | D13: =IF(生产日报3取值!D13=0,"",生产日报3取值!D13) | E13: =IF(生产日报3取值!E13=0,"",生产日报3取值!E13) -> 4870 | F13: =IF(生产日报3取值!F13=0,"",生产日报3取值!F13) -> 34344 | G13: =IF(生产日报3取值!G13=0,"",生产日报3取值!G13) | H13: =IF(生产日报3取值!H13=0,"",生产日报3取值!H13) | I13: =IF(生产日报3取值!I13=0,"",生产日报3取值!I13) | J13: =IF(生产日报3取值!J13=0,"",生产日报3取值!J13) | K13: =IF(生产日报3取值!K13=0,"",生产日报3取值!K13) | ... N13: =IF(生产日报3取值!N13=0,"",生产日报3取值!N13) -> 34344
B14: 柴油精制原料转入 | D14: =IF(生产日报3取值!D14=0,"",生产日报3取值!D14) | E14: =IF(生产日报3取值!E14=0,"",生产日报3取值!E14) | F14: =IF(生产日报3取值!F14=0,"",生产日报3取值!F14) | G14: =IF(生产日报3取值!G14=0,"",生产日报3取值!G14) | H14: =IF(生产日报3取值!H14=0,"",生产日报3取值!H14) | I14: =IF(生产日报3取值!I14=0,"",生产日报3取值!I14) | J14: =IF(生产日报3取值!J14=0,"",生产日报3取值!J14) | K14: =IF(生产日报3取值!K14=0,"",生产日报3取值!K14) -> 4870 | ... N14: =IF(生产日报3取值!N14=0,"",生产日报3取值!N14) -> 34344
B15: 四、产品产量 | D15: =IF(生产日报3取值!D15=0,"",生产日报3取值!D15) | M15: =IF(生产日报3取值!M15=0,"",生产日报3取值!M15) | N15: =IF(生产日报3取值!N15=0,"",生产日报3取值!N15)
B16: 1.汽油产量 | D16: =IF(生产日报3取值!D16=0,"",生产日报3取值!D16) -> 458000 | E16: =IF(生产日报3取值!E16=0,"",生产日报3取值!E16) -> 834 | F16: =IF(生产日报3取值!F16=0,"",生产日报3取值!F16) -> 43275 | G16: =IF(生产日报3取值!G16=0,"",生产日报3取值!G16) -> 3565 | H16: =IF(生产日报3取值!H16=0,"",生产日报3取值!H16) -> 17294 | I16: =IF(生产日报3取值!I16=0,"",生产日报3取值!I16) -> 3000 | J16: =IF(生产日报3取值!J16=0,"",生产日报3取值!J16) -> 13992 | K16: =IF(生产日报3取值!K16=0,"",生产日报3取值!K16) -> 9155 | ... N16: =IF(生产日报3取值!N16=0,"",生产日报3取值!N16) -> 74561 | O16: =_xlfn.IFERROR(N16/D16*100,"") -> 16.279694
B17: 2.柴油产量 | D17: =IF(生产日报3取值!D17=0,"",生产日报3取值!D17) -> 408000 | E17: =IF(生产日报3取值!E17=0,"",生产日报3取值!E17) -> 8542 | F17: =IF(生产日报3取值!F17=0,"",生产日报3取值!F17) -> 50161 | G17: =IF(生产日报3取值!G17=0,"",生产日报3取值!G17) -> 3427 | H17: =IF(生产日报3取值!H17=0,"",生产日报3取值!H17) -> 19647 | I17: =IF(生产日报3取值!I17=0,"",生产日报3取值!I17) -> 3500 | J17: =IF(生产日报3取值!J17=0,"",生产日报3取值!J17) -> 13500 | K17: =IF(生产日报3取值!K17=0,"",生产日报3取值!K17) -> 6405 | ... N17: =IF(生产日报3取值!N17=0,"",生产日报3取值!N17) -> 83308 | O17: =_xlfn.IFERROR(N17/D17*100,"") -> 20.418627
B18: 3.原料液化气产量 | D18: =IF(生产日报3取值!D18=0,"",生产日报3取值!D18) -> 87000 | E18: =IF(生产日报3取值!E18=0,"",生产日报3取值!E18) -> 1436 | F18: =IF(生产日报3取值!F18=0,"",生产日报3取值!F18) -> 10205 | G18: =IF(生产日报3取值!G18=0,"",生产日报3取值!G18) -> 622 | H18: =IF(生产日报3取值!H18=0,"",生产日报3取值!H18) -> 4282 | I18: =IF(生产日报3取值!I18=0,"",生产日报3取值!I18) -> 718 | J18: =IF(生产日报3取值!J18=0,"",生产日报3取值!J18) -> 4572 | K18: =IF(生产日报3取值!K18=0,"",生产日报3取值!K18) | ... N18: =IF(生产日报3取值!N18=0,"",生产日报3取值!N18) -> 19059 | O18: =_xlfn.IFERROR(N18/D18*100,"") -> 21.906897
B19: 4.民用液化气产量 | D19: =IF(生产日报3取值!D19=0,"",生产日报3取值!D19) | E19: =IF(生产日报3取值!E19=0,"",生产日报3取值!E19) -> 738 | F19: =IF(生产日报3取值!F19=0,"",生产日报3取值!F19) -> 3397 | G19: =IF(生产日报3取值!G19=0,"",生产日报3取值!G19) | H19: =IF(生产日报3取值!H19=0,"",生产日报3取值!H19) | I19: =IF(生产日报3取值!I19=0,"",生产日报3取值!I19) | J19: =IF(生产日报3取值!J19=0,"",生产日报3取值!J19) | K19: =IF(生产日报3取值!K19=0,"",生产日报3取值!K19) | ... N19: =IF(生产日报3取值!N19=0,"",生产日报3取值!N19) -> 3397 | O19: =_xlfn.IFERROR(N19/D19*100,"")
B20: 5.丙烷产量 | D20: =IF(生产日报3取值!D20=0,"",生产日报3取值!D20) | E20: =IF(生产日报3取值!E20=0,"",生产日报3取值!E20) -> 94 | F20: =IF(生产日报3取值!F20=0,"",生产日报3取值!F20) -> 561 | G20: =IF(生产日报3取值!G20=0,"",生产日报3取值!G20) | H20: =IF(生产日报3取值!H20=0,"",生产日报3取值!H20) | I20: =IF(生产日报3取值!I20=0,"",生产日报3取值!I20) | J20: =IF(生产日报3取值!J20=0,"",生产日报3取值!J20) | K20: =IF(生产日报3取值!K20=0,"",生产日报3取值!K20) -> 217 | ... N20: =IF(生产日报3取值!N20=0,"",生产日报3取值!N20) -> 2208 | O20: =_xlfn.IFERROR(N20/D20*100,"")
B21: 6.丁烷产量 | D21: =IF(生产日报3取值!D21=0,"",生产日报3取值!D21) | E21: =IF(生产日报3取值!E21=0,"",生产日报3取值!E21) | F21: =IF(生产日报3取值!F21=0,"",生产日报3取值!F21) | G21: =IF(生产日报3取值!G21=0,"",生产日报3取值!G21) | H21: =IF(生产日报3取值!H21=0,"",生产日报3取值!H21) | I21: =IF(生产日报3取值!I21=0,"",生产日报3取值!I21) | J21: =IF(生产日报3取值!J21=0,"",生产日报3取值!J21) | K21: =IF(生产日报3取值!K21=0,"",生产日报3取值!K21) -> 305 | ... N21: =IF(生产日报3取值!N21=0,"",生产日报3取值!N21) -> 2327 | O21: =_xlfn.IFERROR(N21/D21*100,"")
B22: 7.聚丙烯产量 | D22: =IF(生产日报3取值!D22=0,"",生产日报3取值!D22) -> 26499.939 | E22: =IF(生产日报3取值!E22=0,"",生产日报3取值!E22) -> 305 | F22: =IF(生产日报3取值!F22=0,"",生产日报3取值!F22) -> 2100 | G22: =IF(生产日报3取值!G22=0,"",生产日报3取值!G22) | H22: =IF(生产日报3取值!H22=0,"",生产日报3取值!H22) | I22: =IF(生产日报3取值!I22=0,"",生产日报3取值!I22) | J22: =IF(生产日报3取值!J22=0,"",生产日报3取值!J22) | K22: =IF(生产日报3取值!K22=0,"",生产日报3取值!K22) -> 609.56 | ... N22: =IF(生产日报3取值!N22=0,"",生产日报3取值!N22) -> 6369.06 | O22: =_xlfn.IFERROR(N22/D22*100,"") -> 24.034244
B23: 8.MTBE产量 | D23: =IF(生产日报3取值!D23=0,"",生产日报3取值!D23) -> 26800 | E23: =IF(生产日报3取值!E23=0,"",生产日报3取值!E23) -> 108 | F23: =IF(生产日报3取值!F23=0,"",生产日报3取值!F23) -> 688 | G23: =IF(生产日报3取值!G23=0,"",生产日报3取值!G23) | H23: =IF(生产日报3取值!H23=0,"",生产日报3取值!H23) | I23: =IF(生产日报3取值!I23=0,"",生产日报3取值!I23) | J23: =IF(生产日报3取值!J23=0,"",生产日报3取值!J23) | K23: =IF(生产日报3取值!K23=0,"",生产日报3取值!K23) -> 835 | ... N23: =IF(生产日报3取值!N23=0,"",生产日报3取值!N23) -> 6694 | O23: =_xlfn.IFERROR(N23/D23*100,"") -> 24.977612
B24: 9.苯产量 | D24: =IF(生产日报3取值!D24=0,"",生产日报3取值!D24) -> 8300 | E24: =IF(生产日报3取值!E24=0,"",生产日报3取值!E24) | F24: =IF(生产日报3取值!F24=0,"",生产日报3取值!F24) | G24: =IF(生产日报3取值!G24=0,"",生产日报3取值!G24) | H24: =IF(生产日报3取值!H24=0,"",生产日报3取值!H24) | I24: =IF(生产日报3取值!I24=0,"",生产日报3取值!I24) -> 163 | J24: =IF(生产日报3取值!J24=0,"",生产日报3取值!J24) -> 1002 | K24: =IF(生产日报3取值!K24=0,"",生产日报3取值!K24) -> 183 | ... N24: =IF(生产日报3取值!N24=0,"",生产日报3取值!N24) -> 2310 | O24: =_xlfn.IFERROR(N24/D24*100,"") -> 27.831325
B25: 10.苯乙烯 | D25: =IF(生产日报3取值!D25=0,"",生产日报3取值!D25) | E25: =IF(生产日报3取值!E25=0,"",生产日报3取值!E25) -> 151 | F25: =IF(生产日报3取值!F25=0,"",生产日报3取值!F25) -> 1075 | G25: =IF(生产日报3取值!G25=0,"",生产日报3取值!G25) | H25: =IF(生产日报3取值!H25=0,"",生产日报3取值!H25) | I25: =IF(生产日报3取值!I25=0,"",生产日报3取值!I25) | J25: =IF(生产日报3取值!J25=0,"",生产日报3取值!J25) | K25: =IF(生产日报3取值!K25=0,"",生产日报3取值!K25) | ... N25: =IF(生产日报3取值!N25=0,"",生产日报3取值!N25) -> 1075 | O25: =_xlfn.IFERROR(N25/D25*100,"")
B26: 11.醋酸仲丁酯产量 | D26: =IF(生产日报3取值!D26=0,"",生产日报3取值!D26) -> 5100.027 | E26: =IF(生产日报3取值!E26=0,"",生产日报3取值!E26) -> 169 | F26: =IF(生产日报3取值!F26=0,"",生产日报3取值!F26) -> 1128 | G26: =IF(生产日报3取值!G26=0,"",生产日报3取值!G26) | H26: =IF(生产日报3取值!H26=0,"",生产日报3取值!H26) | I26: =IF(生产日报3取值!I26=0,"",生产日报3取值!I26) | J26: =IF(生产日报3取值!J26=0,"",生产日报3取值!J26) | K26: =IF(生产日报3取值!K26=0,"",生产日报3取值!K26) | ... N26: =IF(生产日报3取值!N26=0,"",生产日报3取值!N26) -> 1128 | O26: =_xlfn.IFERROR(N26/D26*100,"") -> 22.11753
B27: 12.粗硫磺产量 | D27: =IF(生产日报3取值!D27=0,"",生产日报3取值!D27) | E27: =IF(生产日报3取值!E27=0,"",生产日报3取值!E27) -> 13 | F27: =IF(生产日报3取值!F27=0,"",生产日报3取值!F27) -> 100 | G27: =IF(生产日报3取值!G27=0,"",生产日报3取值!G27) -> 8 | H27: =IF(生产日报3取值!H27=0,"",生产日报3取值!H27) -> 54 | I27: =IF(生产日报3取值!I27=0,"",生产日报3取值!I27) -> 28.5 | J27: =IF(生产日报3取值!J27=0,"",生产日报3取值!J27) -> 111 | K27: =IF(生产日报3取值!K27=0,"",生产日报3取值!K27) | ... N27: =IF(生产日报3取值!N27=0,"",生产日报3取值!N27) -> 266 | O27: =_xlfn.IFERROR(N27/D27*100,"")
B28: 13.精制硫磺产量 | D28: =IF(生产日报3取值!D28=0,"",生产日报3取值!D28) | E28: =IF(生产日报3取值!E28=0,"",生产日报3取值!E28) | F28: =IF(生产日报3取值!F28=0,"",生产日报3取值!F28) | G28: =IF(生产日报3取值!G28=0,"",生产日报3取值!G28) | H28: =IF(生产日报3取值!H28=0,"",生产日报3取值!H28) | I28: =IF(生产日报3取值!I28=0,"",生产日报3取值!I28) | J28: =IF(生产日报3取值!J28=0,"",生产日报3取值!J28) | K28: =IF(生产日报3取值!K28=0,"",生产日报3取值!K28) | ... N28: =IF(生产日报3取值!N28=0,"",生产日报3取值!N28) | O28: =_xlfn.IFERROR(N28/D28*100,"")
B29: 五、产品销售 | D29: =IF(生产日报3取值!D29=0,"",生产日报3取值!D29) | M29: =IF(生产日报3取值!M29=0,"",生产日报3取值!M29) | N29: =IF(生产日报3取值!N29=0,"",生产日报3取值!N29)
B30: 1.汽油 | D30: =IF(生产日报3取值!D30=0,"",生产日报3取值!D30) | E30: =IF(生产日报3取值!E30=0,"",生产日报3取值!E30) -> 13179 | F30: =IF(生产日报3取值!F30=0,"",生产日报3取值!F30) -> 57060 | G30: =IF(生产日报3取值!G30=0,"",生产日报3取值!G30) -> 1997 | H30: =IF(生产日报3取值!H30=0,"",生产日报3取值!H30) -> 17226 | I30: =IF(生产日报3取值!I30=0,"",生产日报3取值!I30) -> 3200 | J30: =IF(生产日报3取值!J30=0,"",生产日报3取值!J30) -> 19096 | M30: =IF(生产日报3取值!M30=0,"",生产日报3取值!M30) -> 18376 | N30: =IF(生产日报3取值!N30=0,"",生产日报3取值!N30) -> 93382
B31: 乙醇汽油组分油 | D31: =IF(生产日报3取值!D31=0,"",生产日报3取值!D31) | E31: =IF(生产日报3取值!E31=0,"",生产日报3取值!E31) | F31: =IF(生产日报3取值!F31=0,"",生产日报3取值!F31) | G31: =IF(生产日报3取值!G31=0,"",生产日报3取值!G31) | H31: =IF(生产日报3取值!H31=0,"",生产日报3取值!H31) | I31: =IF(生产日报3取值!I31=0,"",生产日报3取值!I31) | J31: =IF(生产日报3取值!J31=0,"",生产日报3取值!J31) | M31: =IF(生产日报3取值!M31=0,"",生产日报3取值!M31) | N31: =IF(生产日报3取值!N31=0,"",生产日报3取值!N31)
B32: 92# | D32: =IF(生产日报3取值!D32=0,"",生产日报3取值!D32) | E32: =IF(生产日报3取值!E32=0,"",生产日报3取值!E32) -> 9857 | F32: =IF(生产日报3取值!F32=0,"",生产日报3取值!F32) -> 32478 | G32: =IF(生产日报3取值!G32=0,"",生产日报3取值!G32) -> 1997 | H32: =IF(生产日报3取值!H32=0,"",生产日报3取值!H32) -> 17226 | I32: =IF(生产日报3取值!I32=0,"",生产日报3取值!I32) -> 2784 | J32: =IF(生产日报3取值!J32=0,"",生产日报3取值!J32) -> 16566 | M32: =IF(生产日报3取值!M32=0,"",生产日报3取值!M32) -> 14638 | N32: =IF(生产日报3取值!N32=0,"",生产日报3取值!N32) -> 66270
B33: 93# | D33: =IF(生产日报3取值!D33=0,"",生产日报3取值!D33) | E33: =IF(生产日报3取值!E33=0,"",生产日报3取值!E33) | F33: =IF(生产日报3取值!F33=0,"",生产日报3取值!F33) | G33: =IF(生产日报3取值!G33=0,"",生产日报3取值!G33) | H33: =IF(生产日报3取值!H33=0,"",生产日报3取值!H33) | I33: =IF(生产日报3取值!I33=0,"",生产日报3取值!I33) | J33: =IF(生产日报3取值!J33=0,"",生产日报3取值!J33) | M33: =IF(生产日报3取值!M33=0,"",生产日报3取值!M33) | N33: =IF(生产日报3取值!N33=0,"",生产日报3取值!N33)
B34: 95# | D34: =IF(生产日报3取值!D34=0,"",生产日报3取值!D34) | E34: =IF(生产日报3取值!E34=0,"",生产日报3取值!E34) -> 3322 | F34: =IF(生产日报3取值!F34=0,"",生产日报3取值!F34) -> 24582 | G34: =IF(生产日报3取值!G34=0,"",生产日报3取值!G34) | H34: =IF(生产日报3取值!H34=0,"",生产日报3取值!H34) | I34: =IF(生产日报3取值!I34=0,"",生产日报3取值!I34) -> 416 | J34: =IF(生产日报3取值!J34=0,"",生产日报3取值!J34) -> 2530 | M34: =IF(生产日报3取值!M34=0,"",生产日报3取值!M34) -> 3738 | N34: =IF(生产日报3取值!N34=0,"",生产日报3取值!N34) -> 27112
B35: 2.柴油 | D35: =IF(生产日报3取值!D35=0,"",生产日报3取值!D35) | E35: =IF(生产日报3取值!E35=0,"",生产日报3取值!E35) -> 3452 | F35: =IF(生产日报3取值!F35=0,"",生产日报3取值!F35) -> 43190 | G35: =IF(生产日报3取值!G35=0,"",生产日报3取值!G35) -> 2534 | H35: =IF(生产日报3取值!H35=0,"",生产日报3取值!H35) -> 17769 | I35: =IF(生产日报3取值!I35=0,"",生产日报3取值!I35) -> 8270 | J35: =IF(生产日报3取值!J35=0,"",生产日报3取值!J35) -> 22878 | M35: =IF(生产日报3取值!M35=0,"",生产日报3取值!M35) -> 14256 | N35: =IF(生产日报3取值!N35=0,"",生产日报3取值!N35) -> 83837
B36: 0#（国ⅤI） | D36: =IF(生产日报3取值!D36=0,"",生产日报3取值!D36) | E36: =IF(生产日报3取值!E36=0,"",生产日报3取值!E36) -> 3452 | F36: =IF(生产日报3取值!F36=0,"",生产日报3取值!F36) -> 43190 | G36: =IF(生产日报3取值!G36=0,"",生产日报3取值!G36) -> 1642 | H36: =IF(生产日报3取值!H36=0,"",生产日报3取值!H36) -> 14410 | I36: =IF(生产日报3取值!I36=0,"",生产日报3取值!I36) -> 5338 | J36: =IF(生产日报3取值!J36=0,"",生产日报3取值!J36) -> 17922 | M36: =IF(生产日报3取值!M36=0,"",生产日报3取值!M36) -> 10432 | N36: =IF(生产日报3取值!N36=0,"",生产日报3取值!N36) -> 75522
B37: -10# | D37: =IF(生产日报3取值!D37=0,"",生产日报3取值!D37) | E37: =IF(生产日报3取值!E37=0,"",生产日报3取值!E37) | F37: =IF(生产日报3取值!F37=0,"",生产日报3取值!F37) | G37: =IF(生产日报3取值!G37=0,"",生产日报3取值!G37) | H37: =IF(生产日报3取值!H37=0,"",生产日报3取值!H37) | I37: =IF(生产日报3取值!I37=0,"",生产日报3取值!I37) -> 2932 | J37: =IF(生产日报3取值!J37=0,"",生产日报3取值!J37) -> 3792 | M37: =IF(生产日报3取值!M37=0,"",生产日报3取值!M37) -> 2932 | N37: =IF(生产日报3取值!N37=0,"",生产日报3取值!N37) -> 3792
B38: -20# | D38: =IF(生产日报3取值!D38=0,"",生产日报3取值!D38) | E38: =IF(生产日报3取值!E38=0,"",生产日报3取值!E38) | F38: =IF(生产日报3取值!F38=0,"",生产日报3取值!F38) | G38: =IF(生产日报3取值!G38=0,"",生产日报3取值!G38) -> 892 | H38: =IF(生产日报3取值!H38=0,"",生产日报3取值!H38) -> 3359 | I38: =IF(生产日报3取值!I38=0,"",生产日报3取值!I38) | J38: =IF(生产日报3取值!J38=0,"",生产日报3取值!J38) -> 1164 | M38: =IF(生产日报3取值!M38=0,"",生产日报3取值!M38) -> 892 | N38: =IF(生产日报3取值!N38=0,"",生产日报3取值!N38) -> 4523
B39: 3.民用液化气 | D39: =IF(生产日报3取值!D39=0,"",生产日报3取值!D39) | E39: =IF(生产日报3取值!E39=0,"",生产日报3取值!E39) -> 603.42 | F39: =IF(生产日报3取值!F39=0,"",生产日报3取值!F39) -> 3562.92 | G39: =IF(生产日报3取值!G39=0,"",生产日报3取值!G39) | H39: =IF(生产日报3取值!H39=0,"",生产日报3取值!H39) | I39: =IF(生产日报3取值!I39=0,"",生产日报3取值!I39) | J39: =IF(生产日报3取值!J39=0,"",生产日报3取值!J39) | K39: =IF(生产日报3取值!K39=0,"",生产日报3取值!K39) | ... N39: =IF(生产日报3取值!N39=0,"",生产日报3取值!N39) -> 3562.92 | O39: =_xlfn.IFERROR(N39/D39*100,"")
B40: 4.丙烯 | D40: =IF(生产日报3取值!D40=0,"",生产日报3取值!D40) | E40: =IF(生产日报3取值!E40=0,"",生产日报3取值!E40) -> 95.22 | F40: =IF(生产日报3取值!F40=0,"",生产日报3取值!F40) -> 765.34 | G40: =IF(生产日报3取值!G40=0,"",生产日报3取值!G40) | H40: =IF(生产日报3取值!H40=0,"",生产日报3取值!H40) | I40: =IF(生产日报3取值!I40=0,"",生产日报3取值!I40) | J40: =IF(生产日报3取值!J40=0,"",生产日报3取值!J40) | M40: =IF(生产日报3取值!M40=0,"",生产日报3取值!M40) -> 95.22 | N40: =IF(生产日报3取值!N40=0,"",生产日报3取值!N40) -> 765.34
...

Sheet 生产日报3取值
B1: 炼化公司生产日报表
B2: 填报单位： | C2: 生产计划部 | H2: 2026-01-07 | L2: 2026-01-07 | N2: 陕油炼计统B900-1表
B3: 指标名称 | D3: 月计划 | E3: 延安炼油厂 | G3: 永坪炼油厂 | I3: 榆林炼油厂 | K3: 延安石化厂 | M3: 公司合计 | N3: 本月累计 | O3: 月完成率%
E4: 当日 | F4: 月累 | G4: 当日 | H4: 月累 | I4: 当日 | J4: 月累 | K4: 当日 | L4: 月累
B5: 3.催化柴油调出量 | E5: =_xlfn.IFERROR(E51,"") -> 2447 | F5: =_xlfn.IFERROR(F51,"") -> 15104 | M5: =E5+G5+I5+K5 -> 2447 | N5: =F5+H5+J5+L5 -> 15104 | O5: =_xlfn.IFERROR(N5/D5,"")
B6: 催化柴油调入量 | I6: =_xlfn.IFERROR(SUM(I51:I53),"") -> 0 | J6: =_xlfn.IFERROR(SUM(J51:J53),"") -> 0 | K6: =_xlfn.IFERROR(SUM(K52:K55),"") -> 2447 | L6: =_xlfn.IFERROR(SUM(L52:L55),"") -> 15427.98 | M6: =E6+G6+I6+K6 -> 2447 | N6: =F6+H6+J6+L6 -> 15427.98 | O6: =_xlfn.IFERROR(N6/D6,"")
B7: 4.液化气调出量 | E7: =_xlfn.IFERROR(E158,"") -> 1632 | F7: =_xlfn.IFERROR(F158,"") -> 10912 | G7: =_xlfn.IFERROR(SUM(G83),"") -> 709 | H7: =_xlfn.IFERROR(SUM(H83),"") -> 3190 | I7: =_xlfn.IFERROR(I77,"") -> 536.32 | J7: =_xlfn.IFERROR(J77,"") -> 3055.94 | M7: =E7+G7+I7+K7 -> 2877.32 | N7: =F7+H7+J7+L7 -> 17157.94 | O7: =_xlfn.IFERROR(N7/D7,"")
B8: 液化气调入量 | E8: =_xlfn.IFERROR(E59,"") -> 1056.16 | F8: =_xlfn.IFERROR(F59,"") -> 6778.44 | K8: =_xlfn.IFERROR(K128,"") -> 1632 | L8: =_xlfn.IFERROR(L128,"") -> 10912 | M8: =E8+G8+I8+K8 -> 2688.16 | N8: =F8+H8+J8+L8 -> 17690.44 | O8: =_xlfn.IFERROR(N8/D8,"")
B9: 5.丙烯转出量 | E9: =_xlfn.IFERROR(E57,"") -> 95.22 | F9: =_xlfn.IFERROR(F57,"") -> 571.28 | M9: =E9+G9+I9+K9 -> 95.22 | N9: =F9+H9+J9+L9 -> 571.28 | O9: =_xlfn.IFERROR(N9/D9,"")
B10: 丙烯转入量 | E10: =_xlfn.IFERROR(E67,"") -> 296 | F10: =_xlfn.IFERROR(F67,"") -> 1527 | M10: =E10+G10+I10+K10 -> 296 | N10: =F10+H10+J10+L10 -> 1527 | O10: =_xlfn.IFERROR(N10/D10,"")
B11: 6.汽油精制原料转出 | E11: =_xlfn.IFERROR(E160,"") -> 4106 | F11: =_xlfn.IFERROR(F160,"") -> 29162 | M11: =E11+G11+I11+K11 -> 4106 | N11: =F11+H11+J11+L11 -> 29162 | O11: =_xlfn.IFERROR(N11/D11,"")
B12: 汽油精制原料转入 | K12: =K122 -> 4106 | L12: =L122 -> 29162 | M12: =E12+G12+I12+K12 -> 4106 | N12: =F12+H12+J12+L12 -> 29162 | O12: =_xlfn.IFERROR(N12/D12,"")
B13: 7.柴油精制原料转出 | E13: =_xlfn.IFERROR(E162,"") -> 4870 | F13: =_xlfn.IFERROR(F162,"") -> 34344 | M13: =E13+G13+I13+K13 -> 4870 | N13: =F13+H13+J13+L13 -> 34344 | O13: =_xlfn.IFERROR(N13/D13,"")
B14: 柴油精制原料转入 | K14: =SUM(K130:K132) -> 4870 | L14: =SUM(L123:L125) -> 34344 | M14: =E14+G14+I14+K14 -> 4870 | N14: =F14+H14+J14+L14 -> 34344 | O14: =_xlfn.IFERROR(N14/D14,"")
B15: 四、产品产量
