Workbook

Sheet 油田气物料动态台账
A1: 油田气化工科技公司物料动态台账
K3: 日期： | L3: 2026-01-07
A4: 储罐库存信息 | B4: 罐区 | C4: 罐号 | D4: 液位（米） | E4: 液位（%） | F4: 储量(吨) | G4: 空量(吨) | H4: 罐区 | I4: 罐号 | J4: 液位（米） | K4: 液位（%） | L4: 储量(吨) | M4: 空量(吨)
B5: 原料成品罐区 | C5: 甲醇 | H5: 原料成品罐区 | I5: 聚四氢呋喃
C6: V-001A | D6: =_xlfn.IFERROR(ROUND(取值!D6,2),"") -> 7.96 | E6: =_xlfn.IFERROR(ROUND(取值!F6,4),"") -> 0.496 | F6: =取值!E6 -> 1429.0258 | G6: =_xlfn.IFERROR(2316.08-F6,"") -> 887.05415 | I6: V-008A | J6: =_xlfn.IFERROR(ROUND(取值!I6,2),"") -> 8.48 | K6: =_xlfn.IFERROR(ROUND(取值!K6,4),"") -> 0.7745 | L6: =取值!J6 -> 854.17456 | M6: =_xlfn.IFERROR(846.32-L6,"") -> -7.8545583
C7: V-001B | D7: =_xlfn.IFERROR(ROUND(取值!D7,2),"") -> 4.27 | E7: =_xlfn.IFERROR(ROUND(取值!F7,4),"") -> 0.269 | F7: =取值!E7 -> 767.05077 | G7: =_xlfn.IFERROR(2316.08-F7,"") -> 1549.0292 | I7: V-008B | J7: =_xlfn.IFERROR(ROUND(取值!I7,2),"") -> 7.19 | K7: =_xlfn.IFERROR(ROUND(取值!K7,4),"") -> 0.6495 | L7: =取值!J7 -> 723.86302 | M7: =_xlfn.IFERROR(846.32-L7,"") -> 122.45698
C8: 合计 | D8: / | E8: / | F8: =SUM(F6:F7) -> 2196.0766 | G8: =SUM(G6:G7) -> 2436.0834 | I8: V-008C | J8: =_xlfn.IFERROR(ROUND(取值!I8,2),"") -> 8.5 | K8: =_xlfn.IFERROR(ROUND(取值!K8,4),"") -> 0.7705 | L8: =取值!J8 -> 855.47379 | M8: =_xlfn.IFERROR(846.32-L8,"") -> -9.1537897
C9: 碳酸二甲酯 | I9: V-008D | J9: =_xlfn.IFERROR(ROUND(取值!I95,2),"") -> 8.39 | K9: =_xlfn.IFERROR(ROUND(取值!K95,4),"") -> 0.7619 | L9: =取值!J95 -> 844.66999 | M9: =_xlfn.IFERROR(846.32-L9,"") -> 1.6500112
C10: V-002 | D10: =_xlfn.IFERROR(ROUND(取值!D10,2),"") -> 4.71 | E10: =_xlfn.IFERROR(ROUND(取值!F10,4),"") -> 0.4479 | F10: =取值!E10 -> 226.3 | G10: =_xlfn.IFERROR(464.01-F10,"") -> 237.71 | I10: V-008E | J10: =_xlfn.IFERROR(ROUND(取值!I96,2),"") -> 1.27 | K10: =_xlfn.IFERROR(ROUND(取值!K96,4),"") -> 0.1064 | L10: =取值!J96 -> 127.44572 | M10: =_xlfn.IFERROR(846.32-L10,"") -> 718.87428
C11: 四氢呋喃 | I11: V-008F | J11: =_xlfn.IFERROR(ROUND(取值!I97,2),"") -> 2.18 | K11: =_xlfn.IFERROR(ROUND(取值!K97,4),"") -> 0.1897 | L11: =取值!J97 -> 219.50777 | M11: =_xlfn.IFERROR(846.32-L11,"") -> 626.81223
C12: V-003A | D12: =_xlfn.IFERROR(ROUND(取值!D12,2),"") -> 8.99 | E12: =_xlfn.IFERROR(ROUND(取值!F12,4),"") -> 0.721 | F12: =取值!E12 -> 531.81351 | G12: =_xlfn.IFERROR(585.72-F12,"") -> 53.906495 | I12: V-008G | J12: =_xlfn.IFERROR(ROUND(取值!I98,2),"") -> 5.76 | K12: =_xlfn.IFERROR(ROUND(取值!K98,4),"") -> 0.5167 | L12: =取值!J98 -> 580.43168 | M12: =_xlfn.IFERROR(846.32-L12,"") -> 265.88832
C13: V-003B | D13: =_xlfn.IFERROR(ROUND(取值!D13,2),"") -> 9.12 | E13: =_xlfn.IFERROR(ROUND(取值!F13,4),"") -> 0.728 | F13: =取值!E13 -> 539.34614 | G13: =_xlfn.IFERROR(585.72-F13,"") -> 46.373865 | I13: V-008H | J13: =_xlfn.IFERROR(ROUND(取值!I99,2),"") -> 5.88 | K13: =_xlfn.IFERROR(ROUND(取值!K99,4),"") -> 0.5277 | L13: =取值!J99 -> 591.95659 | M13: =_xlfn.IFERROR(846.32-L13,"") -> 254.36341
C14: 合计 | D14: / | E14: / | F14: =SUM(F12:F13) -> 1071.1596 | G14: =SUM(G12:G13) -> 100.28036 | I14: V-008I | J14: =_xlfn.IFERROR(ROUND(取值!I100,2),"") -> 7.66 | K14: =_xlfn.IFERROR(ROUND(取值!K100,4),"") -> 0.6864 | L14: =取值!J100 -> 771.61204 | M14: =_xlfn.IFERROR(846.32-L14,"") -> 74.707962
C15: 正丁醇 | I15: 合计 | J15: / | K15: / | L15: =SUM(L6:L14) -> 5569.1352 | M15: =SUM(M6:M14) -> 2047.7448
C16: V-004 | D16: =_xlfn.IFERROR(ROUND(取值!D16,2),"") -> 4.6 | E16: =_xlfn.IFERROR(ROUND(取值!F16,4),"") -> 0.423 | F16: =取值!E16 -> 196.66672 | G16: =_xlfn.IFERROR(359.32-F16,"") -> 162.65328 | I16: 1,4-丁二醇
C17: 醋酐 | I17: V-009A | J17: =_xlfn.IFERROR(ROUND(取值!I11,2),"") -> 1.66 | K17: =_xlfn.IFERROR(ROUND(取值!K11,4),"") -> 0.1422 | L17: =取值!J11 -> 471.53963 | M17: =_xlfn.IFERROR(2676.75-L17,"") -> 2205.2104
C18: V-005A | D18: =_xlfn.IFERROR(ROUND(取值!D18,2),"") -> 2.98 | E18: =_xlfn.IFERROR(ROUND(取值!F18,4),"") -> 0.6122 | F18: =取值!E18 -> 68.254408 | G18: =_xlfn.IFERROR(89.45-F18,"") -> 21.195592 | I18: V-009B | J18: =_xlfn.IFERROR(ROUND(取值!I12,2),"") -> 3.33 | K18: =_xlfn.IFERROR(ROUND(取值!K12,4),"") -> 0.2684 | L18: =取值!J12 -> 947.3386 | M18: =_xlfn.IFERROR(2676.75-L18,"") -> 1729.4114
C19: V-005B | D19: =_xlfn.IFERROR(ROUND(取值!D19,2),"") -> 3.21 | E19: =_xlfn.IFERROR(ROUND(取值!F19,4),"") -> 0.61 | F19: =取值!E19 -> 73.5 | G19: =_xlfn.IFERROR(89.45-F19,"") -> 15.95 | I19: V-009C | J19: =_xlfn.IFERROR(ROUND(取值!I13,2),"") -> 2.6 | K19: =_xlfn.IFERROR(ROUND(取值!K13,4),"") -> 0.1761 | L19: =取值!J13 -> 739.9787 | M19: =_xlfn.IFERROR(2676.75-L19,"") -> 1936.7713
C20: 合计 | D20: / | E20: / | F20: =SUM(F18:F19) -> 141.75441 | G20: =SUM(G18:G19) -> 37.145592 | I20: 合计 | J20: / | K20: / | L20: =SUM(L17:L19) -> 2158.8569 | M20: =SUM(M17:M19) -> 5871.3931
C21: 聚酯级乙二醇 | I21: 粗乙醇
C22: V-006A | D22: =_xlfn.IFERROR(ROUND(取值!D20,2),"") -> 5.04 | E22: =_xlfn.IFERROR(ROUND(取值!F20,4),"") -> 0.4133 | F22: =取值!E20 -> 1350.0736 | G22: =_xlfn.IFERROR(2465.13-F22,"") -> 1115.0564 | I22: V-010 | J22: =_xlfn.IFERROR(ROUND(取值!I15,2),"") -> 4.48 | K22: =_xlfn.IFERROR(ROUND(取值!K15,4),"") -> 0.4299 | L22: =取值!J15 -> 234.5 | M22: =_xlfn.IFERROR(350.45-L22,"") -> 115.95
C23: V-006B | D23: =_xlfn.IFERROR(ROUND(取值!D21,2),"") -> 4.84 | E23: =_xlfn.IFERROR(ROUND(取值!F21,4),"") -> 0.3909 | F23: =取值!E21 -> 1295.3485 | G23: =_xlfn.IFERROR(2465.13-F23,"") -> 1169.7815 | I23: 混合醇
C24: 合计 | D24: / | E24: / | F24: =SUM(F22:F23) -> 2645.4221 | G24: =SUM(G22:G23) -> 2284.8379 | I24: V-011 | J24: =_xlfn.IFERROR(ROUND(取值!I17,2),"") -> 1.93 | K24: =_xlfn.IFERROR(ROUND(取值!K17,4),"") -> 0.2934 | L24: =取值!J17 -> 57.014188 | M24: =_xlfn.IFERROR(139.2-L24,"") -> 82.185812
C25: 轻质多元醇 | I25: 副产油
C26: V-007 | D26: =_xlfn.IFERROR(ROUND(取值!D24,2),"") -> 2.85 | E26: =_xlfn.IFERROR(ROUND(取值!F24,4),"") -> 0.3448 | F26: =取值!E24 -> 198.52226 | G26: =_xlfn.IFERROR(480.78-F26,"") -> 282.25774 | I26: V-012 | J26: =_xlfn.IFERROR(ROUND(取值!I19,2),"") -> 3.62 | K26: =_xlfn.IFERROR(ROUND(取值!K19,4),"") -> 0.3443 | L26: =取值!J19 -> 174.5849 | M26: =_xlfn.IFERROR(405.46-L26,"") -> 230.8751
C27: 焦油 | H27: 原料煤 | I27: 筒仓A | J27: / | K27: / | L27: =取值!J22 -> 4161.79 | M27: =_xlfn.IFERROR(6000-L27,"") -> 1838.21
C28: V-013 | D28: =_xlfn.IFERROR(ROUND(取值!I14,2),"") -> 1.46 | E28: =_xlfn.IFERROR(ROUND(取值!K14,4),"") -> 0.2809 | F28: =取值!J14 -> 44.291699 | G28: =_xlfn.IFERROR(148.88-F28,"") -> 104.5883 | I28: 筒仓B | J28: / | K28: / | L28: =取值!J23 -> 1694.53 | M28: =_xlfn.IFERROR(6000-L28,"") -> 4305.47
B29: 乙二醇中间罐区 | C29: 聚酯级乙二醇 | I29: 合计 | J29: / | K29: / | L29: =_xlfn.IFERROR(L27+L28,"") -> 5856.32 | M29: =_xlfn.IFERROR(M27+M28,"") -> 6143.68
C30: TK-001A | D30: =_xlfn.IFERROR(E30*5.8,"") -> 2.726 | E30: =_xlfn.IFERROR(ROUND(取值!E26,4),"") -> 0.47 | F30: =_xlfn.IFERROR(E30*1.74*100,"") -> 81.78 | G30: =_xlfn.IFERROR(174-F30,"") -> 92.22 | H30: BDO中间罐区 | I30: 循环BYD储罐
C31: TK-001B | D31: =_xlfn.IFERROR(E31*5.8,"") -> 0.0058 | E31: =_xlfn.IFERROR(ROUND(取值!E27,4),"") -> 0.001 | F31: =_xlfn.IFERROR(E31*1.74*100,"") -> 0.174 | G31: =_xlfn.IFERROR(174-F31,"") -> 173.826 | I31: V-401 | J31: =_xlfn.IFERROR(K31*8.5+0.3,"") -> 2.4505 | K31: =_xlfn.IFERROR(ROUND(取值!J26,4),"") -> 0.253 | L31: =_xlfn.IFERROR(K31*500*1.1*0.4,"") -> 55.66 | M31: =_xlfn.IFERROR(500-L31,"") -> 444.34
C32: 合计 | D32: / | E32: / | F32: =SUM(F30:F31) -> 81.954 | G32: =SUM(G30:G31) -> 266.046 | I32: 粗BYD储罐
C33: 轻质多元醇 | I33: V-402 | J33: =_xlfn.IFERROR(K33*8.5+0.3,"") -> 2.629 | K33: =_xlfn.IFERROR(ROUND(取值!J28,4),"") -> 0.274 | L33: =_xlfn.IFERROR(K33*500*1.1*0.4,"") -> 60.28 | M33: =_xlfn.IFERROR(500-L33,"") -> 439.72
C34: TK-002 | D34: =_xlfn.IFERROR(E34*4.5,"") -> 1.69875 | E34: =_xlfn.IFERROR(ROUND(取值!E30,4),"") -> 0.3775 | F34: =_xlfn.IFERROR(E34*0.81*100,"") -> 30.5775 | G34: =_xlfn.IFERROR(81-F34,"") -> 50.4225 | I34: BYD产品储罐
C35: 混合醇 | I35: V-403A | J35: =_xlfn.IFERROR(K35*8.5+0.3,"") -> 5.944 | K35: =_xlfn.IFERROR(ROUND(取值!J30,4),"") -> 0.664 | L35: =_xlfn.IFERROR(K35*500*1.1*0.4,"") -> 146.08 | M35: =_xlfn.IFERROR(500-L35,"") -> 353.92
C36: TK-005 | D36: =_xlfn.IFERROR(E36*3,"") -> 0.0786 | E36: =_xlfn.IFERROR(ROUND(取值!E32,4),"") -> 0.0262 | F36: =_xlfn.IFERROR(E36*0.094*100,"") -> 0.24628 | G36: =_xlfn.IFERROR(9.354-F36,"") -> 9.10772 | I36: V-403B | J36: =_xlfn.IFERROR(K36*8.5+0.3,"") -> 5.944 | K36: =_xlfn.IFERROR(ROUND(取值!J31,4),"") -> 0.664 | L36: =_xlfn.IFERROR(K36*500*1.1*0.4,"") -> 146.08 | M36: =_xlfn.IFERROR(500-L36,"") -> 353.92
C37: 粗乙醇 | I37: 合计 | J37: / | K37: / | L37: =SUM(L35:L36) -> 292.16 | M37: =SUM(M35:M36) -> 707.84
C38: TK-006 | D38: =_xlfn.IFERROR(E38*3.4,"") -> 1.33926 | E38: =_xlfn.IFERROR(ROUND(取值!E34,4),"") -> 0.3939 | F38: =_xlfn.IFERROR(E38*0.136*100,"") -> 5.35704 | G38: =_xlfn.IFERROR(13.6-F38,"") -> 8.24296 | I38: 粗BDO储罐
C39: 甲醇 | I39: V-404A | J39: =_xlfn.IFERROR(K39*8.5+0.3,"") -> 4.805 | K39: =_xlfn.IFERROR(ROUND(取值!J38,4),"") -> 0.53 | L39: =_xlfn.IFERROR(K39*550,"") -> 291.5 | M39: =_xlfn.IFERROR(550-L39,"") -> 258.5
C40: TK-009 | D40: =_xlfn.IFERROR(E40*5.8,"") -> 3.7729 | E40: =_xlfn.IFERROR(ROUND(取值!E36,4),"") -> 0.6505 | F40: =_xlfn.IFERROR(E40*0.75*100,"") -> 48.7875 | G40: =_xlfn.IFERROR(75.4-F40,"") -> 26.6125 | I40: V-404B | J40: =_xlfn.IFERROR(K40*8.5+0.3,"") -> 4.9155 | K40: =_xlfn.IFERROR(ROUND(取值!J39,4),"") -> 0.543 | L40: =_xlfn.IFERROR(K40*550,"") -> 298.65 | M40: =_xlfn.IFERROR(550-L40,"") -> 251.35
C41: 多元醇 | I41: 合计 | J41: / | K41: / | L41: =SUM(L39:L40) -> 590.15 | M41: =SUM(M39:M40) -> 509.85
...

Sheet 取值
C6: V-001A | D6: 7.963365 | E6: 1429.0258 | F6: 0.4959999 | H6: V-008A | I6: 8.482369 | J6: 854.17456 | K6: 0.7745393
C7: V-001B | D7: 4.274454 | E7: 767.05077 | F7: 0.269 | H7: V-008B | I7: 7.188312 | J7: 723.86302 | K7: 0.6495383
C8: 合计 | H8: V-008C | I8: 8.495271 | J8: 855.47379 | K8: 0.7705435
C10: V-002 | D10: 4.710176 | E10: 226.3 | F10: 0.447888
H11: V-009A | I11: 1.656734 | J11: 471.53963 | K11: 0.1422495
C12: V-003A | D12: 8.993971 | E12: 531.81351 | F12: 0.721 | H12: V-009B | I12: 3.328433 | J12: 947.3386 | K12: 0.2683797
C13: V-003B | D13: 9.121362 | E13: 539.34614 | F13: 0.728 | I13: 2.599883 | J13: 739.9787 | K13: 0.1761465
C14: 合计 | I14: 1.458403 | J14: 44.291699 | K14: 0.2808748
H15: V-010 | I15: 4.481348 | J15: 234.5 | K15: 0.4299367
C16: V-004 | D16: 4.600391 | E16: 196.66672 | F16: 0.423
H17: V-011 | I17: 1.926155 | J17: 57.014188 | K17: 0.2933841
C18: V-005 | D18: 2.977941 | E18: 68.254408 | F18: 0.6121968
D19: 3.206043 | E19: 73.5 | F19: 0.61 | H19: V-012 | I19: 3.61909 | J19: 174.5849 | K19: 0.3442585
C20: V-006A | D20: 5.041162 | E20: 1350.0736 | F20: 0.4132661
C21: V-006B | D21: 4.836819 | E21: 1295.3485 | F21: 0.3909142 | H21: V-013 | I21: 1.458403 | J21: 44.291699 | K21: 0.2808748
C22: 合计 | H22: 筒仓A | J22: 4161.79
H23: 筒仓B | J23: 1694.53
C24: V-007 | D24: 2.850693 | E24: 198.52226 | F24: 0.3448228
C26: TK-001A | E26: 0.4699766 | F26: 81.775928 | H26: V-401 | J26: 0.253 | K26: 55.66
C27: TK-001B | E27: 0.001 | F27: 0.174
C28: 合计 | H28: V-402 | J28: 0.274 | K28: 60.28
C30: TK-002 | E30: 0.3775072 | F30: 30.578083 | H30: V-403A | J30: 0.664 | K30: 146.08
H31: V-403B | J31: 0.664 | K31: 146.08
C32: TK-005 | E32: 0.02621675 | F32: 0.24643745 | H32: 合计
C34: TK-006 | E34: 0.3938565 | F34: 5.3564484 | H34: V-408A | J34: 0.723 | K34: 397.65
H35: V-408B | J35: 0.715 | K35: 393.25
C36: TK-009 | E36: 0.650498 | F36: 48.78735 | H36: 合计
C38: TK-013 | E38: 0.1178876 | F38: 16.091657 | H38: V-404A | J38: 0.53 | K38: 291.5
H39: V-404B | J39: 0.543 | K39: 298.65
C40: TK-800 | D40: 0 | H40: 合计
C42: TK-102 | D42: 0 | H42: V-407A | J42: 0.41 | K42: 67.96611
H43: V-407B | J43: 0.107 | K43: 17.737497
C44: TK-202 | D44: 29.96479 | E44: 0.2996479 | H44: 合计
C46: TK-880A | D46: 62.05003 | E46: 0.6205003 | H46: TK-001 | I46: 0.756
C47: TK-880B | D47: 72.4225 | E47: 0.724225
H48: TK-002 | I48: 0.389
C50: TK-760 | D50: 40.14898 | E50: 0.4014898 | H50: V-001A | J50: 0.39 | K50: 376.82432
H51: V-001B | J51: 0.13 | K51: 125.60811
C52: TK-330A | D52: 7.140135E-17 | E52: 7.140135e-19 | H52: V-001C | J52: 0.15 | K52: 144.93243
C53: TK-330B | D53: 1.177014E-19 | E53: 1.177014e-21 | H53: V-001D | J53: 0.67 | K53: 647.36486
...
