Workbook

Sheet 延安石油化工厂生产调度工艺台帐(物料平衡） 
B2: 陕西延长石油（集团）有限责任公司延安石油化工厂调度工艺物料平衡台账
L4: 日期 | N4: 2026-01-06 | AO4: =取值!A57&取值!B57 -> 报出日期:2026-01-07 | AT4: 0.33333333
B5: 时间 项目 | I5: 0.66666667 | K5: 0.041666667 | M5: 0.29166667 | O5: 时间 项目 | S5: 0.66666667 | U5: 0.041666667 | V5: 0.29166667 | W5: 时间 项目 | Z5: 0.66666667 | AA5: 0.041666667 | AB5: 0.29166667 | AC5: 时间 项目 | AG5: 0.66666667 | AH5: 0.041666667 | AI5: 0.29166667 | AJ5: 时间 项目 | AL5: 0.66666667 | AM5: 0.041666667 | AN5: 0.29166667 | AO5: 时间 项目 | AR5: 0.66666667 | AS5: 0.041666667 | AT5: 0.29166667
B6: 120万吨/年重整装置 | C6: 预加氢系统压降Mpa | I6: 0.05172424 | K6: 0.05067567 | M6: 0.04694378 | O6: 20万吨/年苯抽提装置 | P6: 抽提塔(C-101)顶温度℃ | S6: 80.1851 | U6: 80.88347 | V6: 79.3567 | W6: 12万吨/年MTBE装置 | X6: 反应器床层温度℃ | Z6: =IF(取值1!C38=0,"",取值1!C38) | AA6: =IF(取值1!D38=0,"",取值1!D38) | AB6: =IF(取值1!E38=0,"",取值1!E38) | AC6: 20万吨/年烷基化装置 | AD6: 加氢反应器(R-101)压力Mpa | AG6: 1.753871 | AH6: 1.754921 | AI6: 1.751447 | AJ6: 30万吨/年丙烷/异丁烷混合脱氢装置 | AK6: 脱氢反应器R-101入口压力Mpa | AL6: 0.123104 | AM6: 0.1245977 | AN6: 0.123893 | AP6: 75吨/小时1#锅炉 | AQ6: 炉膛温度℃ | AR6: 882.5236 | AS6: 868.1421 | AT6: 859.6019
C7: 蒸发塔(C-101)顶压力Mpa | I7: 1.099557 | K7: 1.098998 | M7: 1.093176 | P7: 抽提塔(C-101)底温度℃ | S7: 168.4544 | U7: 168.6084 | V7: 168.2898 | X7: 反应器操作压力Mpa | Z7: 0.5605221 | AA7: 0.5465196 | AB7: 0.5579426 | AD7: 加氢反应器(R-101)入口温度℃ | AG7: 64.18044 | AH7: 63.68192 | AI7: 62.99017 | AK7: 脱氢反应器R-102温度℃ | AL7: 621.8397 | AM7: 621.9496 | AN7: 622.2856 | AQ7: 蒸汽压力MPa | AR7: 3.243888 | AS7: 3.362279 | AT7: 3.353634
C8: 一反(R-201)入口温度℃ | I8: 512.3381 | K8: 512.531 | M8: 512.3973 | P8: 抽提塔(C-101)顶压力Mpa | S8: 0.06589691 | U8: 0.06800033 | V8: 0.06085174 | X8: 催化蒸馏塔顶温度℃ | Z8: 51.85713 | AA8: 52.61676 | AB8: 51.62971 | AD8: 反应器（R-201）顶压力Mpa | AG8: 0.1504894 | AH8: 0.1482544 | AI8: 0.1481637 | AK8: 脱氢反应器R-103温度℃ | AL8: 625.3337 | AM8: 626.1934 | AN8: 626.015 | AQ8: 蒸汽温度℃ | AR8: 404.8797 | AS8: 416.5627 | AT8: 420.5431
C9: 四反(R-204)入口温度℃ | I9: 512.1147 | K9: 512.0168 | M9: 512.1044 | P9: 溶剂回收塔(C-102)顶温度℃ | S9: 62.81561 | U9: 62.40968 | V9: 62.33079 | X9: 催化蒸馏塔底温度℃ | Z9: 126.0645 | AA9: 126.4014 | AB9: 126.3348 | AD9: 反应器（R-201）下部Q点压力Mpa | AG9: 0.02320197 | AH9: 0.02013851 | AI9: 0.01940982 | AK9: 再生器R-401温度℃ | AL9: 503.4558 | AM9: 503.4438 | AN9: 503.4558 | AQ9: 蒸汽流量M3/H | AR9: 71.82957 | AS9: 71.02824 | AT9: 70.37158
C10: 产物分离罐（D-201)压力Mpa | I10: 0.2419407 | K10: 0.2416959 | M10: 0.2416148 | P10: 溶剂回收塔(C-102)底温度℃ | S10: 165.8763 | U10: 166.1332 | V10: 165.4944 | X10: 催化蒸馏塔顶压力Mpa | Z10: 0.5263219 | AA10: 0.5395958 | AB10: 0.535611 | AD10: 反应器（R-201）进料温度℃ | AG10: 5.491353 | AH10: 4.439972 | AI10: 4.254805 | AK10: T-201丙/丙分离塔压力Mpa | AL10: 65.07428 | AM10: 64.60234 | AN10: 64.44135 | AP10: 75吨/小时2#锅炉 | AQ10: 炉膛温度℃ | AR10: 886.3918 | AS10: 900.5479 | AT10: 909.5413
C11: 烧焦区(R-301)入口温度℃ | I11: 480.0383 | K11: 480.0271 | M11: 479.9764 | P11: 溶剂回收塔(C-102)顶压力Mpa | S11: -41.69657 | U11: -42.53204 | V11: -42.72856 | X11: 萃取塔操作温度℃ | Z11: 50.82442 | AA11: 50.82543 | AB11: 50.23771 | AD11: 反应器（R-201）压差Mpa | AG11: 0.1371 | AH11: 0.1377688 | AI11: 0.1376447 | AQ11: 蒸汽压力MPa | AR11: 5.620328 | AS11: 5.197007 | AT11: 5.206415
C12: 干燥区(R-301)入口温度℃ | I12: 570.467 | K12: 569.3619 | M12: 569.8109 | O12: 60万吨/年气体分馏装置 | P12: 脱丙烷塔(C-101)顶温度℃ | S12: 48.47912 | U12: 48.35229 | V12: 48.62885 | X12: 萃取塔顶压力Mpa | Z12: 0.5531757 | AA12: 0.5672817 | AB12: 0.5599515 | AD12: 压缩机（C-301）一段吸气压力Mpa | AG12: 0.01958309 | AH12: 0.01669374 | AI12: 0.01615489 | AQ12: 蒸汽温度℃ | AR12: 412.791 | AS12: 404.7139 | AT12: 416.8038
C13: 再生器(R-301)压力Mpa | I13: 0.2652831 | K13: 0.2651369 | M13: 0.2643673 | P13: 脱丙烷塔(C-101)顶压力Mpa | S13: 1.879918 | U13: 1.880965 | V13: 1.880938 | W13: 240万吨/年柴油精制装置 | X13: 反应器（R-101）入口温度℃ | Z13: 352.2697 | AA13: 351.9589 | AB13: 351.8729 | AD13: 压缩机（C-301）一段入口流量m3/h | AG13: 46653.15 | AH13: 46281.51 | AI13: 46332.73 | AQ13: 蒸汽流量M3/H | AR13: 68.62093 | AS13: 69.88447 | AT13: 71.13879
B14: 140万吨/年柴油加氢装置 | C14: 加氢反应器(R-101)温度℃ | I14: 298.0436 | K14: 297.7819 | M14: 297.5555 | P14: 脱乙烷塔(C-102)顶温度℃ | S14: 57.01244 | U14: 55.95622 | V14: 55.67295 | X14: 反应器（R-101）压力Mpa | Z14: 6.853453 | AA14: 6.879702 | AB14: 6.906269 | AD14: 汽轮机（ST-301）进气流量kg/h | AG14: 50662.62 | AH14: 50345 | AI14: 49927.76 | AP14: 75吨/小时3#锅炉 | AQ14: 炉膛温度℃ | AR14: 915.306 | AS14: 907.2817 | AT14: 921.6283
C15: 高压分离罐(D-103)压力Mpa | I15: 6.477001 | K15: 6.489275 | M15: 6.456166 | P15: 脱乙烷塔(C-102)顶压力Mpa | S15: 2.853419 | U15: 2.850089 | V15: 2.84925 | X15: 冷高分罐（D-105）压力Mpa | Z15: 6.453642 | AA15: 6.480742 | AB15: 6.508387 | AC15: 25万吨/年MTBE装置物料平衡 | AD15: 第一醚化反应器操作温度℃ | AG15: 58.44726 | AH15: 57.08833 | AI15: 57.81035 | AQ15: 蒸汽压力MPa | AR15: 3.272814 | AS15: 3.39237 | AT15: 3.385144
C16: 汽提塔(C-201)顶温度℃ | I16: 87.3282 | K16: 86.43716 | M16: 88.66401 | P16: 丙烯塔(C-104)顶温度℃ | S16: 27.90551 | U16: 26.925 | V16: 27.59036 | X16: 脱硫化氢汽提塔（C-201）顶温度℃ | Z16: 137.0691 | AA16: 136.7636 | AB16: 137.6186 | AD16: 第一醚化反应器操作压力Mpa | AG16: 1.11828 | AH16: 1.117362 | AI16: 1.117325 | AQ16: 蒸汽温度℃ | AR16: 413.4008 | AS16: 413.8743 | AT16: 407.3294
C17: 分馏塔(C-202)顶温度℃ | I17: 146.5144 | K17: 145.7637 | M17: 146.1001 | O17: 20万吨/年聚丙烯装置 | P17: 预聚合反应器（R-200）温度℃ | S17: 18.9928 | U17: 19.01192 | V17: 19.0054 | X17: 脱硫化氢汽提塔（C-201）底温度℃ | Z17: 182.3604 | AA17: 182.0957 | AB17: 181.7542 | AD17: 第二醚化反应器操作温度℃ | AG17: 51.95076 | AH17: 50.82618 | AI17: 51.5266 | AQ17: 蒸汽流量M3/H | AR17: 68.52834 | AS17: 67.63504 | AT17: 68.83044
C18: 分馏塔(C-202)底温度℃ | I18: 292.7516 | K18: 292.2554 | M18: 291.6619 | P18: 预聚合反应器（R-200）压力Mpa | S18: 3.546564 | U18: 3.541105 | V18: 3.538326 | X18: 脱硫化氢汽提塔（C-201）压力Mpa | Z18: 0.8018434 | AA18: 0.7938417 | AB18: 0.8018432 | AD18: 第二醚化反应器操作压力Mpa | AG18: 1.035991 | AH18: 1.034592 | AI18: 1.034655 | AP18: 75吨/小时4#锅炉 | AQ18: 炉膛温度℃ | AR18: 117.518 | AS18: 114.7667 | AT18: 115.0448
B19: 180万吨/年汽油精制装置 | C19: 反应器（R-101）进口温度℃ | I19: 410.1113 | K19: 407.5627 | M19: 408.8253 | P19: 第一环管反应器（R-201）温度℃ | S19: 70.00957 | U19: 69.99118 | V19: 70.0092 | Z19: =IF(取值1!C51=0,"",取值1!C51) | AA19: =IF(取值1!D51=0,"",取值1!D51) | AB19: =IF(取值1!E51=0,"",取值1!E51) | AD19: 第三醚化反应器操作温度℃ | AG19: 49.9668 | AH19: 48.6977 | AI19: 49.24726 | AQ19: 蒸汽压力MPa | AR19: 0.1722002 | AS19: 0.116975 | AT19: 0.185427
C20: 反应器（R-101）压力Mpa | I20: 2.356201 | K20: 2.358328 | M20: 2.352422 | P20: 第一环管反应器（R-201）压力Mpa | S20: 3.562305 | U20: 3.537084 | V20: 3.531636 | Z20: =IF(取值1!C52=0,"",取值1!C52) | AA20: =IF(取值1!D52=0,"",取值1!D52) | AB20: =IF(取值1!E52=0,"",取值1!E52) | AD20: 第三醚化反应器操作压力Mpa | AG20: 1.02095 | AH20: 1.020291 | AI20: 1.020147 | AQ20: 蒸汽温度℃ | AR20: 338.8067 | AS20: 327.2264 | AT20: 335.0783
C21: 再生器（R-102）温度℃ | I21: 524.8091 | K21: 522.1177 | M21: 523.14 | P21: 第二环管反应器（R-202）温度℃ | S21: 70.01047 | U21: 70.00228 | V21: 69.97826 | Z21: =IF(取值1!C53=0,"",取值1!C53) | AA21: =IF(取值1!D53=0,"",取值1!D53) | AB21: =IF(取值1!E53=0,"",取值1!E53) | AD21: 催化蒸馏塔温度℃ | AG21: 141.5255 | AH21: 142.2014 | AI21: 142.1775 | AQ21: 蒸汽流量M3/H | AR21: 80.02592 | AS21: 82.50062 | AT21: 76.49224
C22: 再生器（R-102）压力Mpa | I22: 0.1185762 | K22: 0.1199141 | M22: 0.1219955 | P22: 第二环管反应器（R-202）压力mpa | S22: 3.508369 | U22: 3.503385 | V22: 3.502784 | Z22: =IF(取值1!C54=0,"",取值1!C54) | AA22: =IF(取值1!D54=0,"",取值1!D54) | AB22: =IF(取值1!E54=0,"",取值1!E54) | AD22: 催化蒸馏塔压力Mpa | AG22: 0.8024743 | AH22: 0.8075014 | AI22: 0.8103261 | AP22: 110吨/小时1#锅炉 | AQ22: 炉膛温度℃ | AR22: =IF(取值1!C95=0,"",取值1!C95) | AS22: =IF(取值1!D95=0,"",取值1!D95) | AT22: =IF(取值1!E95=0,"",取值1!E95)
C23: 稳定塔（C-201）底温℃ | I23: 145.8097 | K23: 143.8167 | M23: 144.3297 | P23: 预接触罐（D-201)压力Mpa | S23: 3.582441 | U23: 3.570594 | V23: 3.564552 | Z23: =IF(取值1!C55=0,"",取值1!C55) | AA23: =IF(取值1!D55=0,"",取值1!D55) | AB23: =IF(取值1!E55=0,"",取值1!E55) | AD23: 甲醇萃取塔顶温度℃ | AG23: 29.08229 | AH23: 27.88723 | AI23: 27.28493 | AQ23: 蒸汽压力MPa | AR23: =IF(取值1!C96=0,"",取值1!C96) | AS23: =IF(取值1!D96=0,"",取值1!D96) | AT23: =IF(取值1!E96=0,"",取值1!E96)
B24: 项目 时间 | C24: 120万吨∕年重整装置物料平衡 | AB24: 140万吨∕年柴油加氢装置物料平衡 | AQ24: 蒸汽温度℃ | AR24: =IF(取值1!C97=0,"",取值1!C97) | AS24: =IF(取值1!D97=0,"",取值1!D97) | AT24: =IF(取值1!E97=0,"",取值1!E97)
AQ25: 蒸汽流量M3/H | AR25: =IF(取值1!C98=0,"",取值1!C98) | AS25: =IF(取值1!D98=0,"",取值1!D98) | AT25: =IF(取值1!E98=0,"",取值1!E98)
C26: 原料 | D26: 重整汽油 | H26: C6-馏分 | L26: 轻汽油 | P26: 液化气 | T26: 轻 油 | X26: 燃料气+损失 | AB26: 原料 | AD26: 加氢柴油 | AG26: 粗汽油 | AI26: 液化气 | AK26: 轻 油 | AM26: 燃料气+损失 | AP26: 110吨/小时2#锅炉 | AQ26: 炉膛温度℃ | AR26: =IF(取值1!C99=0,"",取值1!C99) | AS26: =IF(取值1!D99=0,"",取值1!D99) | AT26: =IF(取值1!E99=0,"",取值1!E99)
C27: T | D27: T | F27: % | G27: % | H27: T | J27: % | L27: T | N27: % | P27: T | R27: % | T27: T | V27: % | X27: T | Z27: % | AB27: T | AD27: T | AF27: % | AG27: T | AH27: % | AI27: T | AJ27: % | AK27: T | AL27: % | AM27: T | AN27: % | AQ27: 蒸汽压力MPa | AR27: =IF(取值1!C100=0,"",取值1!C100) | AS27: =IF(取值1!D100=0,"",取值1!D100) | AT27: =IF(取值1!E100=0,"",取值1!E100)
B28: 8—16 | C28: 1604 | D28: 923 | F28: =_xlfn.IFERROR(D28/C28,"error") -> 0.57543641 | H28: 213 | J28: =_xlfn.IFERROR(H28/C28,"error") -> 0.13279302 | L28: 288 | N28: =_xlfn.IFERROR(L28/C28,"error") -> 0.17955112 | P28: 78 | R28: =_xlfn.IFERROR(P28/C28,"error") -> 0.048628429 | T28: =_xlfn.IFERROR(SUM(D28,H28,L28),"error") -> 1424 | V28: =_xlfn.IFERROR(T28/C28,"error") -> 0.88778055 | X28: =_xlfn.IFERROR(C28-P28-T28,"error") -> 102 | Z28: =_xlfn.IFERROR(X28/C28,"error") -> 0.063591022 | AB28: 801 | AD28: 672 | AF28: =_xlfn.IFERROR(AD28/AB28,"error") -> 0.83895131 | AG28: 138 | AH28: =_xlfn.IFERROR(AG28/AB28,"error") -> 0.17228464 | AI28: 46 | AJ28: =_xlfn.IFERROR(AI28/AB28,"error") -> 0.057428215 | AK28: =_xlfn.IFERROR(SUM(AD28,AG28),"error") -> 810 | AL28: =_xlfn.IFERROR(AK28/AB28,"error") -> 1.011236 | AM28: =_xlfn.IFERROR(AB28-AI28-AK28,"error") -> -55 | AN28: =_xlfn.IFERROR(AM28/AB28,"error") -> -0.06866417 | AQ28: 蒸汽温度℃ | AR28: =IF(取值1!C101=0,"",取值1!C101) | AS28: =IF(取值1!D101=0,"",取值1!D101) | AT28: =IF(取值1!E101=0,"",取值1!E101)
B29: 16—1 | C29: 1606 | D29: 909 | F29: =_xlfn.IFERROR(D29/C29,"error") -> 0.56600249 | H29: 208 | J29: =_xlfn.IFERROR(H29/C29,"error") -> 0.12951432 | L29: 289 | N29: =_xlfn.IFERROR(L29/C29,"error") -> 0.17995019 | P29: 80 | R29: =_xlfn.IFERROR(P29/C29,"error") -> 0.0498132 | T29: =_xlfn.IFERROR(SUM(D29,H29,L29),"error") -> 1406 | V29: =_xlfn.IFERROR(T29/C29,"error") -> 0.875467 | X29: =_xlfn.IFERROR(C29-P29-T29,"error") -> 120 | Z29: =_xlfn.IFERROR(X29/C29,"error") -> 0.074719801 | AB29: 812 | AD29: 663 | AF29: =_xlfn.IFERROR(AD29/AB29,"error") -> 0.81650246 | AG29: 142 | AH29: =_xlfn.IFERROR(AG29/AB29,"error") -> 0.17487685 | AI29: 48 | AJ29: =_xlfn.IFERROR(AI29/AB29,"error") -> 0.0591133 | AK29: =_xlfn.IFERROR(SUM(AD29,AG29),"error") -> 805 | AL29: =_xlfn.IFERROR(AK29/AB29,"error") -> 0.99137931 | AM29: =_xlfn.IFERROR(AB29-AI29-AK29,"error") -> -41 | AN29: =_xlfn.IFERROR(AM29/AB29,"error") -> -0.050492611 | AQ29: 蒸汽流量M3/H | AR29: =IF(取值1!C102=0,"",取值1!C102) | AS29: =IF(取值1!D102=0,"",取值1!D102) | AT29: =IF(取值1!E102=0,"",取值1!E102)
B30: 1—8 | C30: 1070 | D30: 603 | F30: =_xlfn.IFERROR(D30/C30,"error") -> 0.5635514 | H30: 138 | J30: =_xlfn.IFERROR(H30/C30,"error") -> 0.12897196 | L30: 208 | N30: =_xlfn.IFERROR(L30/C30,"error") -> 0.19439252 | P30: 54 | R30: =_xlfn.IFERROR(P30/C30,"error") -> 0.05046729 | T30: =_xlfn.IFERROR(SUM(D30,H30,L30),"error") -> 949 | V30: =_xlfn.IFERROR(T30/C30,"error") -> 0.88691589 | X30: =_xlfn.IFERROR(C30-P30-T30,"error") -> 67 | Z30: =_xlfn.IFERROR(X30/C30,"error") -> 0.062616822 | AB30: 543 | AD30: 450 | AF30: =_xlfn.IFERROR(AD30/AB30,"error") -> 0.82872928 | AG30: 99 | AH30: =_xlfn.IFERROR(AG30/AB30,"error") -> 0.18232044 | AI30: 31 | AJ30: =_xlfn.IFERROR(AI30/AB30,"error") -> 0.057090239 | AK30: =_xlfn.IFERROR(SUM(AD30,AG30),"error") -> 549 | AL30: =_xlfn.IFERROR(AK30/AB30,"error") -> 1.0110497 | AM30: =_xlfn.IFERROR(AB30-AI30-AK30,"error") -> -37 | AN30: =_xlfn.IFERROR(AM30/AB30,"error") -> -0.068139963 | AP30: 110吨/小时3#锅炉 | AQ30: 炉膛温度℃ | AR30: =IF(取值1!C103=0,"",取值1!C103) | AS30: =IF(取值1!D103=0,"",取值1!D103) | AT30: =IF(取值1!E103=0,"",取值1!E103)
B31: 合计 | C31: =_xlfn.IFERROR(SUM(C28,C29,C30),"error") -> 4280 | D31: =_xlfn.IFERROR(SUM(D28,D29,D30),"error") -> 2435 | F31: =_xlfn.IFERROR(D31/C31,"error") -> 0.56892523 | H31: =_xlfn.IFERROR(SUM(H28,H29,H30),"error") -> 559 | J31: =_xlfn.IFERROR(H31/C31,"error") -> 0.13060748 | L31: =_xlfn.IFERROR(SUM(L28,L29,L30),"error") -> 785 | N31: =_xlfn.IFERROR(L31/C31,"error") -> 0.18341121 | P31: =_xlfn.IFERROR(SUM(P28,P29,P30),"error") -> 212 | R31: =_xlfn.IFERROR(P31/C31,"error") -> 0.04953271 | T31: =_xlfn.IFERROR(SUM(T28,T29,T30),"error") -> 3779 | V31: =_xlfn.IFERROR(T31/C31,"error") -> 0.88294393 | X31: =_xlfn.IFERROR(SUM(X28,X29,X30),"error") -> 289 | Z31: =_xlfn.IFERROR(X31/C31,"error") -> 0.067523364 | AB31: =_xlfn.IFERROR(SUM(AB28,AB29,AB30),"error") -> 2156 | AD31: =_xlfn.IFERROR(SUM(AD28,AD29,AD30),"error") -> 1785 | AF31: =_xlfn.IFERROR(AD31/AB31,"error") -> 0.82792208 | AG31: =_xlfn.IFERROR(SUM(AG28,AG29,AG30),"error") -> 379 | AH31: =_xlfn.IFERROR(AG31/AB31,"error") -> 0.1757885 | AI31: =_xlfn.IFERROR(SUM(AI28,AI29,AI30),"error") -> 125 | AJ31: =_xlfn.IFERROR(AI31/AB31,"error") -> 0.057977737 | AK31: =_xlfn.IFERROR(SUM(AK28,AK29,AK30),"error") -> 2164 | AL31: =_xlfn.IFERROR(AK31/AB31,"error") -> 1.0037106 | AM31: =_xlfn.IFERROR(SUM(AM28,AM29,AM30),"error") -> -133 | AN31: =_xlfn.IFERROR(AM31/AB31,"error") -> -0.061688312 | AQ31: 蒸汽压力MPa | AR31: =IF(取值1!C104=0,"",取值1!C104) | AS31: =IF(取值1!D104=0,"",取值1!D104) | AT31: =IF(取值1!E104=0,"",取值1!E104)
B32: 累计 | C32: =SUM(C31,取值!B9,取值!B10,取值!B11) -> 25678 | D32: =SUM(D31,取值!C9,取值!C10,取值!C11) -> 14566 | F32: =_xlfn.IFERROR(D32/C32,"error") -> 0.56725602 | H32: =SUM(H31,取值!G9,取值!G10,取值!G11) -> 3407 | J32: =_xlfn.IFERROR(H32/C32,"error") -> 0.13268167 | L32: =SUM(L31,取值!K9,取值!K10,取值!K11) -> 4699 | N32: =_xlfn.IFERROR(L32/C32,"error") -> 0.18299712 | P32: =SUM(P31,取值!O10,取值!O9,取值!O11) -> 1262 | R32: =_xlfn.IFERROR(P32/C32,"error") -> 0.04914713 | T32: =_xlfn.IFERROR(SUM(D32,H32,L32),"error") -> 22672 | V32: =_xlfn.IFERROR(T32/C32,"error") -> 0.88293481 | X32: =_xlfn.IFERROR(C32-P32-T32,"error") -> 1744 | Z32: =_xlfn.IFERROR(X32/C32,"error") -> 0.067918062 | AB32: =SUM(AB31,取值!AA9,取值!AA10,取值!AA11) -> 13671 | AD32: =SUM(AD31,取值!AC9,取值!AC10,取值!AC11) -> 11545 | AF32: =_xlfn.IFERROR(AD32/AB32,"error") -> 0.84448833 | AG32: =SUM(AG31,取值!AF9,取值!AF10,取值!AF11) -> 2232 | AH32: =_xlfn.IFERROR(AG32/AB32,"error") -> 0.16326531 | AI32: =SUM(AI31,取值!AH9,取值!AH10,取值!AH11) -> 722 | AJ32: =_xlfn.IFERROR(AI32/AB32,"error") -> 0.052812523 | AK32: =_xlfn.IFERROR(SUM(AD32,AG32),"error") -> 13777 | AL32: =_xlfn.IFERROR(AK32/AB32,"error") -> 1.0077536 | AM32: =_xlfn.IFERROR(AB32-AI32-AK32,"error") -> -828 | AN32: =_xlfn.IFERROR(AM32/AB32,"error") -> -0.060566162 | AQ32: 蒸汽温度℃ | AR32: =IF(取值1!C105=0,"",取值1!C105) | AS32: =IF(取值1!D105=0,"",取值1!D105) | AT32: =IF(取值1!E105=0,"",取值1!E105)
B33: 项目 时间 | C33: 60万吨∕年气分装置物料平衡 | AB33: 20万吨∕年苯抽提装置物料平衡 | AQ33: 蒸汽流量M3/H | AR33: =IF(取值1!C106=0,"",取值1!C106) | AS33: =IF(取值1!D106=0,"",取值1!D106) | AT33: =IF(取值1!E106=0,"",取值1!E106)
AP34: 本部空分空压 | AQ34: 工业风压力MPa | AR34: =_xlfn.IFERROR(IF(取值1!C107=0,"",取值1!C107)/1000,"") | AS34: =_xlfn.IFERROR(IF(取值1!D107=0,"",取值1!D107)/1000,"") | AT34: =_xlfn.IFERROR(IF(取值1!E107=0,"",取值1!E107)/1000,"")
C35: 原料 | D35: 丙烯 | H35: 丙烷 | L35: C4馏分 | P35: 戊烷 | T35: 产品 | X35: 燃料气+损失 | AB35: 原料 | AD35: 苯 | AG35: 抽余油 | AI35: 产 品 | AK35: 损失 | AQ35: 仪表风压力MPa | AR35: 0.7194629 | AS35: 0.7272444 | AT35: 0.7187581
C36: T | D36: T | F36: % | G36: % | H36: T | J36: % | L36: T | N36: % | O36: % | P36: T | R36: % | S36: % | T36: T | V36: % | W36: % | X36: T | Z36: % | AA36: % | AB36: T | AD36: T | AF36: % | AG36: T | AH36: % | AI36: T | AJ36: % | AK36: T | AM36: % | AQ36: 0.7MPa氮气压力MPa | AR36: 0.709919 | AS36: 0.7079126 | AT36: 0.6994255
B37: 8—16 | C37: 619 | D37: 188 | F37: =_xlfn.IFERROR(D37/C37,"error") -> 0.30371567 | H37: 76 | J37: =_xlfn.IFERROR(H37/C37,"error") -> 0.12277868 | L37: 338 | N37: =_xlfn.IFERROR(L37/C37,"error") -> 0.546042 | P37: 7 | R37: =_xlfn.IFERROR(P37/C37,"error") -> 0.011308562 | T37: =_xlfn.IFERROR(SUM(D37,H37,L37,P37),"error") -> 609 | V37: =_xlfn.IFERROR(T37/C37,"error") -> 0.98384491 | X37: =_xlfn.IFERROR(C37-T37,"error") -> 10 | Z37: =_xlfn.IFERROR(X37/C37,"error") -> 0.016155089 | AB37: 213 | AD37: 71 | AF37: =_xlfn.IFERROR(AD37/AB37,"error") -> 0.33333333 | AG37: 142 | AH37: =_xlfn.IFERROR(AG37/AB37,"error") -> 0.66666667 | AI37: =_xlfn.IFERROR(SUM(AD37,AG37),"error") -> 213 | AJ37: =_xlfn.IFERROR(AI37/AB37,"error") -> 1 | AK37: =_xlfn.IFERROR(AB37-AI37,"error") -> 0 | AM37: =_xlfn.IFERROR(AK37/AB37,"error") -> 0 | AQ37: 0.85MPa氮气压力MPa | AR37: 0.8407592 | AS37: 0.8401034 | AT37: 0.8396519
B38: 16—1 | C38: 657 | D38: 170 | F38: =_xlfn.IFERROR(D38/C38,"error") -> 0.2587519 | H38: 87 | J38: =_xlfn.IFERROR(H38/C38,"error") -> 0.13242009 | L38: 377 | N38: =_xlfn.IFERROR(L38/C38,"error") -> 0.5738204 | P38: 6 | R38: =_xlfn.IFERROR(P38/C38,"error") -> 0.0091324201 | T38: =_xlfn.IFERROR(SUM(D38,H38,L38,P38),"error") -> 640 | V38: =_xlfn.IFERROR(T38/C38,"error") -> 0.97412481 | X38: =_xlfn.IFERROR(C38-T38,"error") -> 17 | Z38: =_xlfn.IFERROR(X38/C38,"error") -> 0.02587519 | AB38: 208 | AD38: 63 | AF38: =_xlfn.IFERROR(AD38/AB38,"error") -> 0.30288462 | AG38: 145 | AH38: =_xlfn.IFERROR(AG38/AB38,"error") -> 0.69711538 | AI38: =_xlfn.IFERROR(SUM(AD38,AG38),"error") -> 208 | AJ38: =_xlfn.IFERROR(AI38/AB38,"error") -> 1 | AK38: =_xlfn.IFERROR(AB38-AI38,"error") -> 0 | AM38: =_xlfn.IFERROR(AK38/AB38,"error") -> 0 | AQ38: 2.5MPa氮气压力MPa | AR38: 2.399581 | AS38: 2.414061 | AT38: 2.099747
B39: 1—8 | C39: 454 | D39: 107 | F39: =_xlfn.IFERROR(D39/C39,"error") -> 0.23568282 | H39: 54 | J39: =_xlfn.IFERROR(H39/C39,"error") -> 0.11894273 | L39: 278 | N39: =_xlfn.IFERROR(L39/C39,"error") -> 0.6123348 | P39: 4 | R39: =_xlfn.IFERROR(P39/C39,"error") -> 0.0088105727 | T39: =_xlfn.IFERROR(SUM(D39,H39,L39,P39),"error") -> 443 | V39: =_xlfn.IFERROR(T39/C39,"error") -> 0.97577093 | X39: =_xlfn.IFERROR(C39-T39,"error") -> 11 | Z39: =_xlfn.IFERROR(X39/C39,"error") -> 0.024229075 | AB39: 138 | AD39: 49 | AF39: =_xlfn.IFERROR(AD39/AB39,"error") -> 0.35507246 | AG39: 86 | AH39: =_xlfn.IFERROR(AG39/AB39,"error") -> 0.62318841 | AI39: =_xlfn.IFERROR(SUM(AD39,AG39),"error") -> 135 | AJ39: =_xlfn.IFERROR(AI39/AB39,"error") -> 0.97826087 | AK39: =_xlfn.IFERROR(AB39-AI39,"error") -> 3 | AM39: =_xlfn.IFERROR(AK39/AB39,"error") -> 0.02173913 | AQ39: 净化风事故储罐压力MPa | AR39: 2.120536 | AS39: 2.05733 | AT39: 2.017047
B40: 合计 | C40: =_xlfn.IFERROR(SUM(C37,C38,C39),"error") -> 1730 | D40: =_xlfn.IFERROR(SUM(D37,D38,D39),"error") -> 465 | F40: =_xlfn.IFERROR(D40/C40,"error") -> 0.26878613 | H40: =_xlfn.IFERROR(SUM(H37,H38,H39),"error") -> 217 | J40: =_xlfn.IFERROR(H40/C40,"error") -> 0.12543353 | L40: =_xlfn.IFERROR(SUM(L37,L38,L39),"error") -> 993 | N40: =_xlfn.IFERROR(L40/C40,"error") -> 0.57398844 | P40: =_xlfn.IFERROR(SUM(P37,P38,P39),"error") -> 17 | R40: =_xlfn.IFERROR(P40/C40,"error") -> 0.0098265896 | T40: =_xlfn.IFERROR(SUM(T37,T38,T39),"error") -> 1692 | V40: =_xlfn.IFERROR(T40/C40,"error") -> 0.97803468 | X40: =_xlfn.IFERROR(SUM(X37,X38,X39),"error") -> 38 | Z40: =_xlfn.IFERROR(X40/C40,"error") -> 0.021965318 | AB40: =_xlfn.IFERROR(SUM(AB37,AB38,AB39),"error") -> 559 | AD40: =_xlfn.IFERROR(SUM(AD37,AD38,AD39),"error") -> 183 | AF40: =_xlfn.IFERROR(AD40/AB40,"error") -> 0.3273703 | AG40: =_xlfn.IFERROR(SUM(AG37,AG38,AG39),"error") -> 373 | AH40: =_xlfn.IFERROR(AG40/AB40,"error") -> 0.66726297 | AI40: =_xlfn.IFERROR(SUM(AI37,AI38,AI39),"error") -> 556 | AJ40: =_xlfn.IFERROR(AI40/AB40,"error") -> 0.99463327 | AK40: =_xlfn.IFERROR(SUM(AK37,AK38,AK39),"error") -> 3 | AM40: =_xlfn.IFERROR(AK40/AB40,"error") -> 0.0053667263 | AQ40: 氮气事故储罐压力MPa | AR40: 2.398019 | AS40: 2.4124 | AT40: 2.289315
B41: 累计 | C41: =SUM(C40,取值!B20,取值!B21,取值!B22) -> 10664 | D41: =SUM(D40,取值!C20,取值!C21,取值!C22) -> 2894 | F41: =_xlfn.IFERROR(D41/C41,"error") -> 0.27138035 | H41: =SUM(H40,取值!G20,取值!G21,取值!G22) -> 1406 | J41: =_xlfn.IFERROR(H41/C41,"error") -> 0.13184546 | L41: =SUM('延安石油化工厂生产调度工艺台帐(物料平衡） '!L40:M40,取值!K20,取值!K21,取值!K22) -> 5988 | N41: =_xlfn.IFERROR(L41/C41,"error") -> 0.56151538 | P41: =SUM(P40,取值!O20,取值!O21,取值!O22) -> 98 | R41: =_xlfn.IFERROR(P41/C41,"error") -> 0.0091897974 | T41: =_xlfn.IFERROR(SUM(D41,H41,L41,P41),"error") -> 10386 | V41: =_xlfn.IFERROR(T41/C41,"error") -> 0.97393098 | X41: =_xlfn.IFERROR(C41-T41,"error") -> 278 | Z41: =_xlfn.IFERROR(X41/C41,"error") -> 0.026069017 | AB41: =SUM(AB40,取值!AA20,取值!AA21,取值!AA22) -> 3407 | AD41: =SUM(AD40,取值!AC20,取值!AC21,取值!AC22) -> 1120 | AF41: =_xlfn.IFERROR(AD41/AB41,"error") -> 0.32873496 | AG41: =SUM(AG40,取值!AF20,取值!AF21,取值!AF22) -> 2269 | AH41: =_xlfn.IFERROR(AG41/AB41,"error") -> 0.6659818 | AI41: =_xlfn.IFERROR(SUM(AD41,AG41),"error") -> 3389 | AJ41: =_xlfn.IFERROR(AI41/AB41,"error") -> 0.99471676 | AK41: =_xlfn.IFERROR(AB41-AI41,"error") -> 18 | AM41: =_xlfn.IFERROR(AK41/AB41,"error") -> 0.0052832404 | AQ41: 0.7MPa氮气流量NM3/h | AR41: 5527.41 | AS41: 5753.479 | AT41: 5869.393
B42: 项目 时间 | C42: 20万吨∕年聚丙烯装置物料平衡 | H42: 12万吨∕年MTBE装置物料平衡 | X42: 双脱装置物料平衡 | AF42: 2万标方/小时制氢 | AI42: 180万吨∕年汽油精制装置物料平衡 | AQ42: 0.85MPa氮气流量NM3/h | AR42: 365.0865 | AS42: 376.98 | AT42: 388.8808
...

Sheet 取值
A1: 项目 时间 | B1: 120万吨∕年重整装置物料平衡 | AA1: 140万吨∕年柴油加氢装置物料平衡
B3: 原料 | C3: 重整汽油 | G3: C6-馏分 | K3: 轻汽油 | O3: 液化气 | S3: 轻 油 | W3: 燃料气+损失 | AA3: 原料 | AC3: 加氢柴油 | AF3: 粗汽油 | AH3: 液化气 | AJ3: 轻 油 | AL3: 燃料气+损失
B4: T | C4: T | E4: % | F4: % | G4: T | I4: % | K4: T | M4: % | O4: T | Q4: % | S4: T | U4: % | W4: T | Y4: % | AA4: T | AC4: T | AE4: % | AF4: T | AG4: % | AH4: T | AI4: % | AJ4: T | AK4: % | AL4: T | AM4: %
A5: 8—16 | B5: 1604 | C5: 1065 | D5: =SUM(C5,E5)-SUM(AF16) -> 923 | G5: 213 | K5: 288 | O5: 78 | AA5: 801 | AC5: 672 | AF5: 138 | AH5: 46
A6: 16—1 | B6: 1606 | C6: 1054 | D6: =SUM(C6,E6)-SUM(AF17) -> 909 | G6: 208 | K6: 289 | O6: 80 | AA6: 812 | AC6: 663 | AF6: 142 | AH6: 48
A7: 16—8 | B7: 1070 | C7: 689 | D7: =SUM(C7,E7)-SUM(AF18) -> 603 | G7: 138 | K7: 208 | O7: 54 | AA7: 543 | AC7: 450 | AF7: 99 | AH7: 31
A8: 合计
A9: 累计 | B9: 8026 | C9: 4558 | G9: 1073 | K9: 1460 | O9: 391 | AA9: 4314 | AC9: 3666 | AF9: 694 | AH9: 226
B10: 5350 | C10: 4513 | G10: 1063 | K10: 1477 | O10: 398 | AA10: 4323 | AC10: 3652 | AF10: 691 | AH10: 218
B11: 8022 | C11: 3060 | G11: 712 | K11: 977 | O11: 261 | AA11: 2878 | AC11: 2442 | AF11: 468 | AH11: 153
A12: 项目 时间 | B12: 60万吨∕年气分装置物料平衡 | AA12: 20万吨∕年苯抽提装置物料平衡
B14: 原料 | C14: 丙烯 | G14: 丙烷 | K14: C4馏分 | O14: 戊烷 | S14: 产品 | W14: 燃料气+损失 | AA14: 原料 | AC14: 苯 | AF14: 抽余油 | AH14: 产 品 | AJ14: 损失
B15: T | C15: T | E15: % | F15: % | G15: T | I15: % | K15: T | M15: % | N15: % | O15: T | Q15: % | R15: % | S15: T | U15: % | V15: % | W15: T | Y15: % | Z15: % | AA15: T | AC15: T | AE15: % | AF15: T | AG15: % | AH15: T | AI15: % | AJ15: T | AL15: %
A16: 8—16 | B16: 619 | C16: 188 | G16: 76 | K16: 338 | O16: 7 | AA16: 213 | AC16: 71 | AF16: 142
A17: 16—1 | B17: 657 | C17: 170 | G17: 87 | K17: 377 | O17: 6 | AA17: 208 | AC17: 63 | AF17: 145
A18: 16—8 | B18: 454 | C18: 107 | G18: 54 | K18: 278 | O18: 4 | AA18: 138 | AC18: 49 | AF18: 86
A19: 合计
B20: 3436 | C20: 956 | G20: 473 | K20: 1966 | O20: 31 | AA20: 1073 | AC20: 357 | AF20: 716
B21: 3305 | C21: 883 | G21: 281 | K21: 1158 | O21: 30 | AA21: 1063 | AC21: 331 | AF21: 732
A22: 累计 | B22: 2193 | C22: 590 | G22: 435 | K22: 1871 | O22: 20 | AA22: 712 | AC22: 249 | AF22: 448
A23: 项目 时间 | B23: 20万吨∕年聚丙烯装置物料平衡 | G23: 12万吨∕年MTBE装置物料平衡 | W23: 双脱装置物料平衡 | AE23: 2万标方/小时制氢 | AH23: 180万吨∕年汽油精制装置物料平衡
B25: 原料 | C25: 聚丙烯 | G25: C4原料 | I25: 甲醇 | K25: MTBE产品 | O25: 剩余C4 | S25: 损失 | W25: 原 料 | AA25: 精制液化气 | AE25: 原 料 | AF25: 产品氢 | AH25: 原料 | AI25: 精制汽油 | AK25: 燃料气+损失
B26: T | C26: T | E26: % | F26: % | G26: T | I26: T | K26: T | M26: % | N26: % | O26: T | Q26: % | R26: % | S26: T | U26: % | V26: % | W26: T | AA26: T | AC26: % | AE26: T | AF26: T | AG26: % | AH26: T | AI26: T | AJ26: % | AK26: T | AL26: %
A27: 8—16 | B27: 234 | G27: 327 | I27: 20 | K27: 54 | O27: 294 | W27: 583 | X27: 46 | Y27: =SUM(W27,X27) -> 629 | AA27: 619 | AH27: 1552 | AI27: 1523
A28: 16—1 | B28: 236 | G28: 390 | I28: 25 | K28: 65 | O28: 336 | W28: 626 | X28: 48 | Y28: =SUM(W28,X28) -> 674 | AA28: 668 | AH28: 1544 | AI28: 1559
A29: 16—8 | B29: 157 | G29: 264 | I29: 17 | K29: 45 | O29: 240 | W29: 423 | X29: 31 | Y29: =SUM(W29,X29) -> 454 | AA29: 449 | AH29: 1039 | AI29: 1024
A30: 合计
B31: 1176 | E31: 592 | G31: 1936 | I31: 115 | K31: 322 | O31: 1748 | W31: 3205 | AA31: 3160 | AH31: 7827 | AI31: 7777
B32: 1183 | E32: 3640 | G32: 1885 | I32: 119 | K32: 316 | O32: 1679 | W32: 3178 | AA32: 3132 | AH32: 7789 | AI32: 7713
A33: 累计 | B33: 787 | G33: 1238 | I33: 74 | K33: 204 | O33: 1090 | W33: 2081 | AA33: 2064 | AH33: 5162 | AI33: 5152
A34: 项目 时间 | B34: 240万吨/年柴油加氢装置物料平衡 | Y34: 20万吨∕年烷基化装置物料平衡
B36: 原料 | D36: 精制柴油 | H36: 粗汽油 | L36: 富 气 | P36: 轻 烃 | T36: 轻 油 | W36: 燃料气+损失 | Y36: 原料 | AA36: 烷基化C4 | AE36: 烷基化油 | AH36: 正丁烷 | AK36: 干气
B37: T | D37: T | F37: % | H37: T | J37: % | L37: T | N37: % | P37: T | R37: % | T37: T | V37: % | W37: T | X37: % | Y37: T | AA37: T | AC37: % | AE37: T | AG37: % | AH37: T | AJ37: % | AK37: T | AL37: %
A38: 8—16 | B38: 1822 | D38: 1737 | H38: 50 | L38: 18 | P38: 28 | X38: =SUM(Y38,Z38) -> 377.0001 | Y38: 377 | Z38: 0.0001 | AA38: 86 | AE38: 229 | AH38: 53 | AJ38: 0
A39: 16—1 | B39: 1824 | D39: 1723 | H39: 52 | L39: 18 | P39: 30 | X39: =SUM(Y39,Z39) -> 364 | Y39: 364 | Z39: 0 | AA39: 80 | AE39: 223 | AH39: 52 | AJ39: 0
A40: 16—8 | B40: 1225 | D40: 1160 | H40: 36 | L40: 12 | P40: 21 | X40: =SUM(Y40,Z40) -> 254 | Y40: 254 | Z40: 0 | AA40: 60 | AE40: 152 | AH40: 36 | AJ40: 0
A41: 合计
B42: 9202 | D42: 8677 | H42: 254 | L42: 90 | P42: 140 | Y42: 1917 | AA42: 420 | AE42: 1195 | AH42: 255 | AJ42: 0
B43: 9178 | D43: 8658 | H43: 253 | L43: 91 | P43: 144 | Y43: 1852.0002 | AA43: 379 | AE43: 1171 | AH43: 257 | AJ43: 0
A44: 累计 | B44: 6128 | D44: 5783 | H44: 166 | L44: 60 | P44: 96 | Y44: 1314 | AA44: 304 | AE44: 780 | AH44: 170 | AJ44: 0
...

Sheet 取值1
A2: 120万吨/年重整装置 | B2: 预加氢系统压降Mpa | C2: 0.05172424 | D2: 0.05067567 | E2: 0.04694378
B3: 蒸发塔(C-101)顶压力Mpa | C3: 1.099557 | D3: 1.098998 | E3: 1.093176
B4: 一反(R-201)入口温度℃ | C4: 512.3381 | D4: 512.531 | E4: 512.3973
B5: 四反(R-204)入口温度℃ | C5: 512.1147 | D5: 512.0168 | E5: 512.1044
B6: 产物分离罐（D-201)压力Mpa | C6: 0.2419407 | D6: 0.2416959 | E6: 0.2416148
B7: 烧焦区(R-301)入口温度℃ | C7: 480.0383 | D7: 480.0271 | E7: 479.9764
B8: 干燥区(R-301)入口温度℃ | C8: 570.467 | D8: 569.3619 | E8: 569.8109
B9: 再生器(R-301)压力Mpa | C9: 0.2652831 | D9: 0.2651369 | E9: 0.2643673
A10: 140万吨/年柴油加氢装置 | B10: 加氢反应器(R-101)温度℃ | C10: 298.0436 | D10: 297.7819 | E10: 297.5555
B11: 高压分离罐(D-103)压力Mpa | C11: 6.477001 | D11: 6.489275 | E11: 6.456166
B12: 汽提塔(C-201)顶温度℃ | C12: 87.3282 | D12: 86.43716 | E12: 88.66401
B13: 分馏塔(C-202)顶温度℃ | C13: 146.5144 | D13: 145.7637 | E13: 146.1001
B14: 分馏塔(C-202)底温度℃ | C14: 292.7516 | D14: 292.2554 | E14: 291.6619
A15: 180万吨/年汽油精制装置 | B15: 吸收脱吸塔(C-203)顶温度℃ | C15: 410.1113 | D15: 407.5627 | E15: 408.8253
B16: 吸收脱吸塔(C-203)底温度℃ | C16: 2.356201 | D16: 2.358328 | E16: 2.352422
B17: 吸收脱吸塔(C-203)顶压力Mpa | C17: 524.8091 | D17: 522.1177 | E17: 523.14
B18: 稳定塔(C-204)顶温度℃ | C18: 0.1185762 | D18: 0.1199141 | E18: 0.1219955
B19: 稳定塔(C-204)顶压力Mpa | C19: 145.8097 | D19: 143.8167 | E19: 144.3297
A20: 20万吨/年苯抽提装置 | B20: 抽提塔(C-101)顶温度℃ | C20: 80.1851 | D20: 80.88347 | E20: 79.3567
B21: 抽提塔(C-101)底温度℃ | C21: 168.4544 | D21: 168.6084 | E21: 168.2898
B22: 抽提塔(C-101)顶压力Mpa | C22: 0.06589691 | D22: 0.06800033 | E22: 0.06085174
B23: 溶剂回收塔(C-102)顶温度℃ | C23: 62.81561 | D23: 62.40968 | E23: 62.33079
B24: 溶剂回收塔(C-102)底温度℃ | C24: 165.8763 | D24: 166.1332 | E24: 165.4944
B25: 溶剂回收塔(C-102)顶压力Mpa | C25: -41.69657 | D25: -42.53204 | E25: -42.72856
A26: 60万吨/年气体分馏装置 | B26: 脱丙烷塔(C-101)顶温度℃ | C26: 48.47912 | D26: 48.35229 | E26: 48.62885
B27: 脱丙烷塔(C-101)顶压力Mpa | C27: 1.879918 | D27: 1.880965 | E27: 1.880938
B28: 脱乙烷塔(C-102)顶温度℃ | C28: 57.01244 | D28: 55.95622 | E28: 55.67295
B29: 脱乙烷塔(C-102)顶压力Mpa | C29: 2.853419 | D29: 2.850089 | E29: 2.84925
B30: 丙烯塔(C-104)顶温度℃ | C30: 27.90551 | D30: 26.925 | E30: 27.59036
A31: 20万吨/年聚丙烯装置 | B31: 预聚合反应器（R-200）温度℃ | C31: 18.9928 | D31: 19.01192 | E31: 19.0054
B32: 预聚合反应器（R-200）压力Mpa | C32: 3.546564 | D32: 3.541105 | E32: 3.538326
B33: 第一环管反应器（R-201）温度℃ | C33: 70.00957 | D33: 69.99118 | E33: 70.0092
B34: 第一环管反应器（R-201）压力Mpa | C34: 3.562305 | D34: 3.537084 | E34: 3.531636
B35: 第二环管反应器（R-202）温度℃ | C35: 70.01047 | D35: 70.00228 | E35: 69.97826
B36: 第二环管反应器（R-202）压力mpa | C36: 3.508369 | D36: 3.503385 | E36: 3.502784
B37: 预接触罐（D-201)压力Mpa | C37: 3.582441 | D37: 3.570594 | E37: 3.564552
A38: 12万吨/年MTBE装置 | B38: 反应器床层温度℃ | C38: 0 | D38: 0 | E38: 0
B39: 反应器操作压力Mpa | C39: 0.5605221 | D39: 0.5465196 | E39: 0.5579426
B40: 催化蒸馏塔顶温度℃ | C40: 51.85713 | D40: 52.61676 | E40: 51.62971
B41: 催化蒸馏塔底温度℃ | C41: 126.0645 | D41: 126.4014 | E41: 126.3348
...
