Workbook

Sheet 调运月报
A2: 陕西延长石油集团公司原料油(气)调拨统计报表
A3: 填报单位: 永坪炼油厂 | C3: 统计日期： | E3: 2025-12 | I3: =取值!B1 -> 报表生成时间： | L3: =_xlfn.IFERROR(取值!C1,"") -> 46022
A4: 油品名称 | B4: 调运单位 | C4: 调入 | I4: 调出
C5: 调运量 | F5: 车次 | I5: 调运量 | L5: 车次
C6: 单位 | D6: 月累计 | E6: 年累计 | F6: 单位 | G6: 月累计 | H6: 年累计 | I6: 单位 | J6: 月累计 | K6: 年累计 | L6: 单位 | M6: 月累计 | N6: 年累计
A7: 1.1#渣油 | B7: 榆能化一销售 | C7: 吨 | F7: 辆 | I7: 吨 | J7: 37838.24 | K7: =_xlfn.IFERROR(取值!K7+IF(调运月报!J7="",0,J7),"") -> 513611.1 | L7: 辆 | M7: 1179 | N7: =_xlfn.IFERROR(取值!N7+IF(调运月报!M7="",0,M7),"") -> 15987
B8: 榆能化公司（榆炼） | C8: 吨 | F8: 辆 | I8: 吨 | J8: =IF(SUM(取值!J8)=0,"",SUM(取值!J8)) | K8: =_xlfn.IFERROR(取值!K8+IF(调运月报!J8="",0,J8),"") -> 113316.6 | L8: 辆 | M8: 0 | N8: =_xlfn.IFERROR(取值!N8+IF(调运月报!M8="",0,M8),"") -> 3529
B9: 延安炼油厂 | C9: 吨 | F9: 辆 | I9: 吨 | J9: =IF(SUM(取值!J9)=0,"",SUM(取值!J9)) | K9: =_xlfn.IFERROR(取值!K9+IF(调运月报!J9="",0,J9),"") -> 25700.48 | L9: 辆 | M9: 0 | N9: =_xlfn.IFERROR(取值!N9+IF(调运月报!M9="",0,M9),"") -> 801
A10: 2.常压石脑油 | B10: 延安石化厂 | C10: 吨 | F10: 辆 | I10: 吨 | J10: 15554.72 | K10: =_xlfn.IFERROR(取值!K10+IF(调运月报!J10="",0,J10),"") -> 296494.24 | L10: 辆 | M10: 495 | N10: =_xlfn.IFERROR(取值!N10+IF(调运月报!M10="",0,M10),"") -> 9348
B11: 榆林炼油厂 | C11: 吨 | F11: 辆 | I11: 吨 | J11: =IF(SUM(取值!J11)=0,"",SUM(取值!J11)) | K11: =_xlfn.IFERROR(取值!K11+IF(调运月报!J11="",0,J11),"") -> 0 | L11: 辆 | M11: 0 | N11: =_xlfn.IFERROR(取值!N11+IF(调运月报!M11="",0,M11),"") -> 0
B12: 延能化 | C12: 吨 | F12: 辆 | I12: 吨 | J12: 385.16 | K12: =_xlfn.IFERROR(取值!K12+IF(调运月报!J12="",0,J12),"") -> 13195.9 | L12: 辆 | M12: 12 | N12: =_xlfn.IFERROR(取值!N12+IF(调运月报!M12="",0,M12),"") -> 414
A13: 3.催化柴油 | C13: 吨 | F13: 辆 | I13: 吨 | J13: =IF(SUM(取值!J13)=0,"",SUM(取值!J13)) | K13: =_xlfn.IFERROR(取值!K13+IF(调运月报!J13="",0,J13),"") -> 0 | L13: 辆 | M13: 0 | N13: =_xlfn.IFERROR(取值!N13+IF(调运月报!M13="",0,M13),"") -> 0
A14: 4.原料液化气 | B14: 延安石化厂 | C14: 吨 | F14: 辆 | I14: 吨 | J14: 18441 | K14: =_xlfn.IFERROR(取值!K14+IF(调运月报!J14="",0,J14),"") -> 228858 | L14: 辆 | M14: 729 | N14: =_xlfn.IFERROR(取值!N14+IF(调运月报!M14="",0,M14),"") -> 9105
A15: 5.石脑油Ⅱ | B15: 延能化 | C15: 吨 | F15: 辆 | I15: 吨 | J15: 6836 | K15: =_xlfn.IFERROR(取值!K15+IF(调运月报!J15="",0,J15),"") -> 75702.94 | L15: 辆 | M15: 274 | N15: =_xlfn.IFERROR(取值!N15+IF(调运月报!M15="",0,M15),"") -> 2964
A16: 6.2#渣油 | B16: 榆林炼油厂 | C16: 吨 | F16: 辆 | I16: 吨 | J16: =IF(SUM(取值!J16)=0,"",SUM(取值!J16)) | K16: =_xlfn.IFERROR(取值!K16+IF(调运月报!J16="",0,J16),"") -> 0 | L16: 辆 | M16: 0 | N16: =_xlfn.IFERROR(取值!N16+IF(调运月报!M16="",0,M16),"") -> 0
B17: 榆能化一销售 | C17: 吨 | F17: 辆 | I17: 吨 | J17: 639.48 | K17: =_xlfn.IFERROR(取值!K17+IF(调运月报!J17="",0,J17),"") -> 6796.96 | L17: 辆 | M17: 21 | N17: =_xlfn.IFERROR(取值!N17+IF(调运月报!M17="",0,M17),"") -> 221
B18: 延能化一销售 | C18: 吨 | F18: 辆 | I18: 吨 | J18: =IF(SUM(取值!J18)=0,"",SUM(取值!J18)) | K18: =_xlfn.IFERROR(取值!K18+IF(调运月报!J18="",0,J18),"") -> 306 | L18: 辆 | M18: 0 | N18: =_xlfn.IFERROR(取值!N18+IF(调运月报!M18="",0,M18),"") -> 10
A19: 7、粗硫磺 | B19: 销售 | C19: 吨 | F19: 辆 | I19: 吨 | J19: 70.62 | K19: =_xlfn.IFERROR(取值!K19+IF(调运月报!J19="",0,J19),"") -> 3004.4 | L19: 辆 | M19: 2 | N19: =_xlfn.IFERROR(取值!N19+IF(调运月报!M19="",0,M19),"") -> 88
B20: 延能化 | C20: 吨 | F20: 辆 | I20: 吨 | J20: 194.24 | K20: =_xlfn.IFERROR(取值!K20+IF(调运月报!J20="",0,J20),"") -> 553.92 | L20: 辆 | M20: 6 | N20: =_xlfn.IFERROR(取值!N20+IF(调运月报!M20="",0,M20),"") -> 17
B21: 榆能化 | C21: 吨 | F21: 辆 | I21: 吨 | J21: =IF(SUM(取值!J21)=0,"",SUM(取值!J21)) | K21: =_xlfn.IFERROR(取值!K21+IF(调运月报!J21="",0,J21),"") -> 0 | L21: 辆 | M21: 0 | N21: =_xlfn.IFERROR(取值!N21+IF(调运月报!M21="",0,M21),"") -> 0
A22: 8、常压柴油 | B22: 延安石化厂 | C22: 吨 | F22: 辆 | I22: 吨 | J22: =IF(SUM(取值!J22)=0,"",SUM(取值!J22)) | K22: =_xlfn.IFERROR(取值!K22+IF(调运月报!J22="",0,J22),"") -> 0 | L22: 辆 | M22: 0 | N22: =_xlfn.IFERROR(取值!N22+IF(调运月报!M22="",0,M22),"") -> 0
A23: 9、-20#柴油 | B23: 延安石化厂 | C23: 吨 | F23: 辆 | I23: 吨 | J23: 19.96 | K23: =_xlfn.IFERROR(取值!K23+IF(调运月报!J23="",0,J23),"") -> 49.82 | L23: 辆 | M23: 1 | N23: =_xlfn.IFERROR(取值!N23+IF(调运月报!M23="",0,M23),"") -> 2
A24: 10、烷基化 | B24: 延安石化厂 | C24: 吨 | D24: 2286.72 | E24: =_xlfn.IFERROR(取值!E24+IF(调运月报!D24="",0,D24),"") -> 43210.6 | F24: 辆 | G24: 73 | H24: =_xlfn.IFERROR(取值!H24+IF(调运月报!G24="",0,G24),"") -> 1383
B25: 外购 | C25: 吨 | D25: =IF(SUM(取值!D25)=0,"",SUM(取值!D25)) | E25: =_xlfn.IFERROR(取值!E25+IF(调运月报!D25="",0,D25),"") -> 0 | F25: 辆 | G25: 0 | H25: =_xlfn.IFERROR(取值!H25+IF(调运月报!G25="",0,G25),"") -> 0
A26: 11、MTBE内调 | B26: 延安石化厂 | C26: 吨 | D26: 7872.78 | E26: =_xlfn.IFERROR(取值!E26+IF(调运月报!D26="",0,D26),"") -> 48534.2 | F26: 辆 | G26: 251 | H26: =_xlfn.IFERROR(取值!H26+IF(调运月报!G26="",0,G26),"") -> 1546
A27: 12、MTBE外购 | B27: 榆能化 | C27: 吨 | D27: =IF(SUM(取值!D27)=0,"",SUM(取值!D27)) | E27: =_xlfn.IFERROR(取值!E27+IF(调运月报!D27="",0,D27),"") -> 0 | F27: 辆 | G27: 0 | H27: =_xlfn.IFERROR(取值!H27+IF(调运月报!G27="",0,G27),"") -> 0
B28: 恒百瑞（外购） | C28: 吨 | D28: =IF(SUM(取值!D28)=0,"",SUM(取值!D28)) | E28: =_xlfn.IFERROR(取值!E28+IF(调运月报!D28="",0,D28),"") -> 0 | F28: 辆 | G28: 0 | H28: =_xlfn.IFERROR(取值!H28+IF(调运月报!G28="",0,G28),"") -> 0
B29: 陕西圣仁石化 | C29: 吨 | D29: =IF(SUM(取值!D29)=0,"",SUM(取值!D29)) | E29: =_xlfn.IFERROR(取值!E29+IF(调运月报!D29="",0,D29),"") -> 0 | F29: 辆 | G29: 0 | H29: =_xlfn.IFERROR(取值!H29+IF(调运月报!G29="",0,G29),"") -> 0
B30: 榆林市洪宇石化 | C30: 吨 | D30: =IF(SUM(取值!D30)=0,"",SUM(取值!D30)) | E30: =_xlfn.IFERROR(取值!E30+IF(调运月报!D30="",0,D30),"") -> 0 | F30: 辆 | G30: 0 | H30: =_xlfn.IFERROR(取值!H30+IF(调运月报!G30="",0,G30),"") -> 0
B31: 中煤榆能化 | C31: 吨 | D31: =IF(SUM(取值!D31)=0,"",SUM(取值!D31)) | E31: =_xlfn.IFERROR(取值!E31+IF(调运月报!D31="",0,D31),"") -> 0 | F31: 辆 | G31: 0 | H31: =_xlfn.IFERROR(取值!H31+IF(调运月报!G31="",0,G31),"") -> 0
B32: 榆林新瑞能源 | C32: 吨 | D32: =IF(SUM(取值!D32)=0,"",SUM(取值!D32)) | E32: =_xlfn.IFERROR(取值!E32+IF(调运月报!D32="",0,D32),"") -> 0 | F32: 辆 | G32: 0 | H32: =_xlfn.IFERROR(取值!H32+IF(调运月报!G32="",0,G32),"") -> 0
B33: 延安能源化工 | C33: 吨 | D33: 454.46 | E33: =_xlfn.IFERROR(取值!E33+IF(调运月报!D33="",0,D33),"") -> 4946.82 | F33: 辆 | G33: 14 | H33: =_xlfn.IFERROR(取值!H33+IF(调运月报!G33="",0,G33),"") -> 152
B34: 陕西亿鑫寰宇石油化工 | C34: 吨 | D34: =IF(SUM(取值!D34)=0,"",SUM(取值!D34)) | E34: =_xlfn.IFERROR(取值!E34+IF(调运月报!D34="",0,D34),"") -> 1892.52 | F34: 辆 | G34: 0 | H34: =_xlfn.IFERROR(取值!H34+IF(调运月报!G34="",0,G34),"") -> 58
B35: 陕西延长石油能源科技有限公司 | C35: 吨 | D35: =IF(SUM(取值!D35)=0,"",SUM(取值!D35)) | E35: =_xlfn.IFERROR(取值!E35+IF(调运月报!D35="",0,D35),"") -> 3466.22 | F35: 辆 | G35: 0 | H35: =_xlfn.IFERROR(取值!H35+IF(调运月报!G35="",0,G35),"") -> 106
B36: 陕西中钻投 | C36: 吨 | D36: =IF(SUM(取值!D36)=0,"",SUM(取值!D36)) | E36: =_xlfn.IFERROR(取值!E36+IF(调运月报!D36="",0,D36),"") -> 553.36 | F36: 辆 | G36: 0 | H36: =_xlfn.IFERROR(取值!H36+IF(调运月报!G36="",0,G36),"") -> 17
B37: 西安劲雨实业有限公司 | C37: 吨 | D37: =IF(SUM(取值!D37)=0,"",SUM(取值!D37)) | E37: =_xlfn.IFERROR(取值!E37+IF(调运月报!D37="",0,D37),"") -> 2967.5 | F37: 辆 | G37: 0 | H37: =_xlfn.IFERROR(取值!H37+IF(调运月报!G37="",0,G37),"") -> 91
B38: 黄陵顺达工贸有限责任公司 | C38: 吨 | D38: =IF(SUM(取值!D38)=0,"",SUM(取值!D38)) | E38: =_xlfn.IFERROR(取值!E38+IF(调运月报!D38="",0,D38),"") -> 1993.7 | F38: 辆 | G38: 0 | H38: =_xlfn.IFERROR(取值!H38+IF(调运月报!G38="",0,G38),"") -> 62
B39: =_xlfn.IFERROR(取值!B39,"") -> 陕西长恒实业有限公司外购MTBE | C39: 吨 | D39: =IF(SUM(取值!D39)=0,"",SUM(取值!D39)) | E39: =_xlfn.IFERROR(取值!E39+IF(调运月报!D39="",0,D39),"") -> 1489.5 | F39: 辆 | G39: 0 | H39: =_xlfn.IFERROR(取值!H39+IF(调运月报!G39="",0,G39),"") -> 45
B40: =_xlfn.IFERROR(取值!B40,"") -> 江苏延长国际物流有限公司外购MTBE | C40: 吨 | D40: =IF(SUM(取值!D40)=0,"",SUM(取值!D40)) | E40: =_xlfn.IFERROR(取值!E40+IF(调运月报!D40="",0,D40),"") -> 2558.42 | F40: 辆 | G40: 0 | H40: =_xlfn.IFERROR(取值!H40+IF(调运月报!G40="",0,G40),"") -> 79
B41: =_xlfn.IFERROR(取值!B41,"") -> 榆林市新瑞能源化工有限公司外购MTBE | C41: 吨 | D41: =IF(SUM(取值!D41)=0,"",SUM(取值!D41)) | E41: =_xlfn.IFERROR(取值!E41+IF(调运月报!D41="",0,D41),"") -> 1976.28 | F41: 辆 | G41: 0 | H41: =_xlfn.IFERROR(取值!H41+IF(调运月报!G41="",0,G41),"") -> 60
...

Sheet 取值
A1: 2025-12 | B1: 报表生成时间： | C1: =DATE(YEAR(A1),MONTH(A1)+1,1)-1 -> 46022 | D1: 8:00:00 | N1: 报表生成时间： | O1: 2025-12 | P1: 8:00:00
A2: 陕西延长石油集团公司原料油(气)调拨统计报表
A3: 填报单位: 永坪炼油厂 | C3: 统计日期： | E3: 2025-12 | I3: =取值!B1 -> 报表生成时间： | L3: =_xlfn.IFERROR(取值!C1,"") -> 46022
A4: 油品名称 | B4: 调运单位 | C4: 调入 | I4: 调出
C5: 调运量 | F5: 车次 | I5: 调运量 | L5: 车次
C6: 单位 | D6: 月累计 | E6: 年累计 | F6: 单位 | G6: 月累计 | H6: 年累计 | I6: 单位 | J6: 月累计 | K6: 年累计 | L6: 单位 | M6: 月累计 | N6: 年累计
A7: 1.1#渣油 | B7: 榆能化一销售 | C7: 吨 | I7: 吨 | J7: 37838.24 | K7: 475772.86 | L7: 辆 | M7: 1179 | N7: 14808
B8: 榆能化公司（榆炼） | C8: 吨 | I8: 吨 | J8: 0 | K8: 113316.6 | L8: 辆 | M8: 0 | N8: 3529
B9: 延安炼油厂 | C9: 吨 | I9: 吨 | J9: 0 | K9: 25700.48 | L9: 辆 | M9: 0 | N9: 801
A10: 2.常压石脑油 | B10: 延安石化厂 | C10: 吨 | I10: 吨 | J10: 15554.72 | K10: 280939.52 | L10: 辆 | M10: 495 | N10: 8853
B11: 榆林炼油厂 | C11: 吨 | I11: 吨 | J11: 0 | L11: 辆 | M11: 0 | N11: 0
B12: 延能化 | C12: 吨 | I12: 吨 | J12: 385.16 | K12: 12810.74 | L12: 辆 | M12: 12 | N12: 402
A13: 3.催化柴油 | C13: 吨 | I13: 吨 | J13: 0 | L13: 辆 | M13: 0 | N13: 0
A14: 4.原料液化气 | B14: 延安石化厂 | C14: 吨 | I14: 吨 | J14: =SUM(J57:J59) -> 18441 | K14: 210417 | L14: 辆 | M14: =SUM(M57:M59) -> 729 | N14: 8376
A15: 5.石脑油Ⅱ | B15: 延能化 | C15: 吨 | I15: 吨 | J15: 6836 | K15: 68866.94 | L15: 辆 | M15: 274 | N15: 2690
A16: 6.2#渣油 | B16: 榆林炼油厂 | C16: 吨 | I16: 吨 | J16: 0 | L16: 辆 | M16: 0 | N16: 0
B17: 榆能化一销售 | I17: 吨 | J17: 517.46 | K17: 6157.48 | L17: 辆 | M17: 17 | N17: 200
B18: 延能化一销售 | I18: 吨 | J18: 0 | K18: 306 | L18: 辆 | M18: 0 | N18: 10
A19: 7、粗硫磺 | B19: 销售 | C19: 吨 | I19: 吨 | J19: 70.62 | K19: 2933.78 | L19: 辆 | M19: 2 | N19: 86
B20: 延能化 | C20: 吨 | I20: 吨 | J20: 194.24 | K20: 359.68 | L20: 辆 | M20: 6 | N20: 11
B21: 榆能化 | C21: 吨 | I21: 吨 | J21: 0 | L21: 辆 | M21: 0 | N21: 0
A22: 8、常压柴油 | B22: 延安石化厂 | C22: 吨 | I22: 吨 | J22: =SUM(D54:D55) -> 0 | L22: 辆 | M22: =SUM(G54:G55) -> 0 | N22: 0
A23: 9、-20#柴油 | B23: 延安石化厂 | C23: 吨 | J23: 19.96 | K23: 29.86 | L23: 辆 | M23: 1 | N23: 1
A24: 10、烷基化 | B24: 延安石化厂 | C24: 吨 | D24: 2286.72 | E24: 40923.88 | F24: 辆 | G24: 73 | H24: 1310
B25: 外购 | C25: 吨 | D25: 0 | F25: 辆 | G25: 0 | H25: 0
A26: 11、MTBE内调 | B26: 延安石化厂 | C26: 吨 | D26: 7872.78 | E26: 40661.42 | F26: 辆 | G26: 251 | H26: 1295
A27: 12、MTBE外购 | B27: 榆能化 | C27: 吨 | D27: 0 | F27: 辆 | G27: 0 | H27: 0
B28: 恒百瑞（外购） | C28: 吨 | D28: 0 | F28: 辆 | G28: 0 | H28: 0
B29: 陕西圣仁石化 | C29: 吨 | D29: 0 | F29: 辆 | G29: 0 | H29: 0
B30: 榆林市洪宇石化 | C30: 吨 | D30: 0 | F30: 辆 | G30: 0 | H30: 0
B31: 中煤榆能化 | C31: 吨 | F31: 辆 | H31: 0
B32: 榆林新瑞能源 | C32: 吨 | D32: 0 | F32: 辆 | G32: 0 | H32: 0
B33: 延安能源化工 | C33: 吨 | D33: 454.46 | E33: 4492.36 | F33: 辆 | G33: 14 | H33: 138
B34: 陕西亿鑫寰宇石油化工 | C34: 吨 | D34: 0 | E34: 1892.52 | F34: 辆 | G34: 0 | H34: 58
B35: 陕西延长石油能源科技有限公司 | C35: 吨 | D35: 0 | E35: 3466.22 | F35: 辆 | G35: 0 | H35: 106
B36: 陕西中钻投 | C36: 吨 | D36: 0 | E36: 553.36 | F36: 辆 | G36: 0 | H36: 17
B37: 西安劲雨实业有限公司 | C37: 吨 | D37: 0 | E37: 2967.5 | F37: 辆 | G37: 0 | H37: 91
B38: 黄陵顺达工贸有限责任公司 | C38: 吨 | D38: 0 | E38: 1993.7 | F38: 辆 | G38: 0 | H38: 62
B39: 陕西长恒实业有限公司外购MTBE | C39: 吨 | D39: 0 | E39: 1489.5 | F39: 辆 | G39: 0 | H39: 45
B40: 江苏延长国际物流有限公司外购MTBE | C40: 吨 | D40: 0 | E40: 2558.42 | F40: 辆 | G40: 0 | H40: 79
...
