Workbook

Sheet 油品动态
B2: =取值!A1&取值!B1 -> 2026-01-07油品动态
B3: 原 油 | H3: 1# 渣 油
B4: 罐号 | C4: 容积(m3) | D4: 安全高度(米) | E4: 油尺 | F4: 油量(吨) | G4: 空量(吨) | H4: 罐号 | I4: 容积(m3) | J4: 安全高度(米) | K4: 油尺 | L4: 油量(吨) | M4: 空量(吨)
B5: 6101 | C5: 10000 | D5: 14.2 | E5: 3.58 | F5: 1897.4 | G5: =IF(E5=0,0,(14.2-E5)*530) -> 5628.6 | H5: 6201 | I5: 10000 | J5: 16.03 | K5: 4.6 | L5: =K5*522 -> 2401.2 | M5: =IF(K5=0,0,(16.03-K5)*522) -> 5966.46
B6: 6102 | C6: 10000 | D6: 14.2 | E6: 9.66 | F6: =E6*530 -> 5119.8 | G6: =IF(E6=0,0,(14.2-E6)*530) -> 2406.2 | H6: 6202 | I6: 5000 | J6: 10.8 | K6: 2.75 | L6: =K6*388 -> 1067 | M6: =IF(K6=0,0,(10.8-K6)*388) -> 3123.4
B7: 6105 | C7: 10000 | D7: 14.2 | E7: 4.45 | F7: =E7*530 -> 2358.5 | G7: =IF(E7=0,0,(14.2-E7)*530) -> 5167.5 | H7: 6204 | I7: 20000 | J7: 16.03 | K7: 7.06 | L7: =K7*997 -> 7038.82 | M7: =IF(K7=0,0,(16.03-K7)*997) -> 8943.09
B8: 6106 | C8: 10000 | D8: 14.2 | E8: 10.53 | F8: =E8*530 -> 5580.9 | G8: =IF(E8=0,0,(14.2-E8)*530) -> 1945.1 | H8: 6205 | I8: 20000 | J8: 16.03 | K8: 6.9 | L8: =K8*996 -> 6872.4 | M8: =IF(K8=0,0,(16.03-K8)*996) -> 9093.48
B9: 9501 | C9: 10000 | D9: 13.6 | E9: 11.85 | F9: =E9*530 -> 6280.5 | G9: =IF(E9=0,0,(13.6-E9)*530) -> 927.5 | H9: 9505 | I9: 5000 | J9: 8.5 | K9: 7.71 | L9: =K9*282 -> 2174.22 | M9: =IF(K9=0,0,(8.5-K9)*278) -> 219.62
B10: 9502 | C10: 10000 | D10: 13.6 | E10: 11.68 | F10: =E10*530 -> 6190.4 | G10: =IF(E10=0,0,(13.6-E10)*530) -> 1017.6 | H10: 9506 | I10: 5000 | J10: 13.67 | K10: 11.06 | L10: =K10*282 -> 3118.92 | M10: =IF(K10=0,0,(13.67-K10)*278) -> 725.58
B11: 9503 | C11: 10000 | D11: 13.6 | E11: 11.2 | F11: =E11*530 -> 5936 | G11: =IF(E11=0,0,(13.6-E11)*530) -> 1272 | H11: 9507 | I11: 5000 | J11: 13.67 | K11: 7.21 | L11: =K11*280 -> 2018.8 | M11: =IF(K11=0,0,(13.67-K11)*278) -> 1795.88
B12: 9510 | C12: 20000 | D12: 13.4 | E12: 8.91 | F12: =E12*1045 -> 9310.95 | G12: =IF(E12=0,0,(13.4-E12)*1045) -> 4692.05 | H12: 9508 | I12: 5000 | J12: 13.67 | K12: 6.73 | L12: =K12*280 -> 1884.4 | M12: =IF(K12=0,0,(13.67-K12)*278) -> 1929.32
B13: 合计 | F13: =SUM(F5:F12) -> 42674.45 | G13: =SUM(G5:G12) -> 23056.55 | H13: 23601 | I13: 5000 | J13: 15.38 | K13: 14.82 | L13: =K13*277 -> 4105.14 | M13: =IF(K13=0,0,(15.38-K13)*278) -> 155.68
B14: 航煤原油掺炼污油专罐 | H14: 23602 | I14: 5000 | J14: 15.38 | K14: 10.8 | L14: =K14*277 -> 2991.6 | M14: =IF(K14=0,0,(15.38-K14)*278) -> 1273.24
B15: 6104 | C15: 5000 | D15: 12.8 | E15: 2.62 | F15: =E15*319 -> 835.78 | G15: =IF(E15=0,0,(12.8-E15)*319) -> 3247.42 | H15: 23603 | I15: 5000 | J15: 15.38 | K15: 11.15 | L15: =K15*277 -> 3088.55 | M15: =IF(K15=0,0,(15.38-K15)*278) -> 1175.94
B16: 环 保 应 急 罐 | H16: 23604 | I16: 5000 | J16: 15.38 | K16: 11.18 | L16: =K16*277 -> 3096.86 | M16: =IF(K16=0,0,(15.38-K16)*278) -> 1167.6
B17: 6103 | C17: 5000 | D17: 12.8 | E17: 3.43 | F17: =E17*319 -> 1094.17 | G17: =IF(E17=0,0,(12.8-E17)*319) -> 2989.03 | H17: 合计 | L17: =SUM(L5:L16) -> 39857.91 | M17: =SUM(M5:M16) -> 35569.29
B18: 9504 | C18: 10000 | D18: 13.6 | E18: 3.39 | F18: =E18*530 -> 1796.7 | G18: =IF(E18=0,0,(13.6-E18)*530) -> 5411.3 | H18: 6203 | K18: 0 | L18: =K18*388 -> 0 | M18: =取值!C1 -> 0
B19: 9509 | C19: 20000 | D19: 13 | E19: 2.88 | F19: =E19*1244 -> 3582.72 | G19: =IF(E19=0,0,(13-E19)*1244) -> 12589.28 | H19: 催 化 柴 油
B20: 合计 | F20: =SUM(F17:F19) -> 6473.59 | G20: =SUM(G17:G19) -> 20989.61 | H20: 罐号 | I20: 容积(m3) | J20: 安全高度(米) | K20: 油尺 | L20: 油量(吨) | M20: 空量(吨)
B21: 常 压 石 脑 油 | H21: 6801 | I21: 10000 | J21: 16.03 | K21: 7.17 | L21: =K21*492 -> 3527.64 | M21: =IF(K21=0,0,(16.03-K21)*492) -> 4359.12
B22: 罐号 | C22: 容积(m3) | D22: 安全高度(米) | E22: 油尺 | F22: 油量(吨) | G22: 空量(吨) | H22: 6802 | I22: 10000 | J22: 16.03 | K22: 2.96 | L22: =K22*492 -> 1456.32 | M22: =IF(K22=0,0,(16.03-K22)*492) -> 6430.44
B23: 6803 | C23: 10000 | D23: 16.03 | E23: 15.08 | F23: =E23*439 -> 6620.12 | G23: =IF(E23=0,0,(16.03-E23)*439) -> 417.05 | H23: 合计 | L23: =SUM(L21:L22) -> 4983.96 | M23: =SUM(M21:M22) -> 10789.56
B24: 6804 | C24: 10000 | D24: 16.03 | E24: 11.91 | F24: =E24*439 -> 5228.49 | G24: =IF(E24=0,0,(16.03-E24)*439) -> 1808.68 | H24: 常 压 直 馏 柴 油
B25: 合计 | F25: =SUM(F23:F24) -> 11848.61 | G25: =SUM(G23:G24) -> 2225.73 | H25: 罐号 | I25: 容积(m3) | J25: 安全高度(米) | K25: 油尺 | L25: 油量(吨) | M25: 空量(吨)
B26: 过 剩 精 制 汽 油 | H26: 9527 | I26: 10000 | J26: 15.5 | K26: 7.33 | L26: =K26*478 -> 3503.74 | M26: =IF(K26=0,0,(15.5-K26)*478) -> 3905.26
B27: 罐号 | C27: 容积(m3) | D27: 安全高度(米) | E27: 油尺 | F27: 油量(吨) | G27: 空量(吨) | H27: 9528 | I27: 10000 | J27: 10 | K27: 5.95 | L27: =K27*478 -> 2844.1 | M27: =IF(K27=0,0,(10-K27)*478) -> 1935.9
B28: 9511 | C28: 5000 | D28: 13 | E28: 10.02 | F28: =E28*225 -> 2254.5 | G28: =IF(E28=0,0,(13-E28)*225) -> 670.5 | H28: 合计 | L28: =SUM(L26:L27) -> 6347.84 | M28: =SUM(M26:M27) -> 5841.16
B29: =IFERROR(IF(取值!C157=0,"",取值!C157),"") | C29: 5000 | D29: 13 | E29: =IFERROR(IF(B29=9529,ROUND(取值!B73,2),IF(B29=9530,ROUND(取值!B74,2),IF(B29=823,ROUND(取值!B99,2),IF(B29=824,ROUND(取值!B86,2),"")))),"") | F29: =IFERROR(IF(E29="","",E29*218),"") | G29: =IF(E29=0,0,IFERROR(IF(E29="","",(13-E29)*225),""))
B30: =IFERROR(IF(取值!C158=0,"",取值!C158),"") | C30: 5000 | D30: 13 | E30: =IFERROR(IF(B30=9529,ROUND(取值!B73,2),IF(B30=9530,ROUND(取值!B74,2),IF(B30=823,ROUND(取值!B99,2),IF(B30=824,ROUND(取值!B86,2),"")))),"") | F30: =IFERROR(IF(E30="","",E30*218),"") | G30: =IF(E30=0,0,IFERROR(IF(E30="","",(13-E30)*215),""))
B31: 合计 | F31: =SUM(F28:F30) -> 2254.5 | G31: =SUM(G28:G30) -> 670.5 | H31: 0# 柴 油
B32: 催 化 汽 油（原料） | H32: 罐号 | I32: 容积(m3) | J32: 安全高度(米) | K32: 油尺 | L32: 油量(吨) | M32: 空量(吨)
B33: 罐号 | C33: 容积(m3) | D33: 安全高度(米) | E33: 油尺 | F33: 油量(吨) | G33: 空量(吨) | H33: 801 | I33: 10000 | J33: 13.4 | K33: 13.09 | L33: =K33*515 -> 6741.35 | M33: =IF(K33=0,0,(13.4-K33)*515) -> 159.65
B34: 9512 | C34: 5000 | D34: 13 | E34: 9.92 | F34: =E34*232.5 -> 2306.4 | G34: =IF(E34=0,0,(13-E34)*228) -> 702.24 | H34: 802 | I34: 10000 | J34: 13.4 | K34: 13.09 | L34: =K34*515 -> 6741.35 | M34: =IF(K34=0,0,(13.4-K34)*515) -> 159.65
B35: 9513 | C35: 5000 | D35: 13 | E35: 7.62 | F35: =E35*223 -> 1699.26 | G35: =IF(E35=0,0,(13-E35)*225) -> 1210.5 | H35: 803 | I35: 10000 | J35: 13.4 | K35: 9.54 | L35: =K35*515 -> 4913.1 | M35: =IF(K35=0,0,(13.4-K35)*515) -> 1987.9
B36: 合计 | F36: =SUM(F35) -> 1699.26 | G36: =SUM(G35) -> 1210.5 | H36: 804 | I36: 10000 | J36: 13.4 | K36: 9.15 | L36: =K36*515 -> 4712.25 | M36: =IF(K36=0,0,(13.4-K36)*515) -> 2188.75
B37: MTBE | H37: 810 | I37: 5000 | J37: 10.2 | K37: 2.61 | L37: =K37*365 -> 952.65 | M37: =IF(K37=0,0,(10.2-K37)*365) -> 2770.35
B38: 罐号 | C38: 容积(m3) | D38: 安全高度(米) | E38: 油尺 | F38: 油量(吨) | G38: 空量(吨) | H38: 811 | I38: 5000 | J38: 10.2 | K38: 3.41 | L38: =K38*365 -> 1244.65 | M38: =IF(K38=0,0,(10.2-K38)*365) -> 2478.35
B39: 24903 | C39: 1000 | D39: 7.6 | E39: 3.16 | F39: =E39*68 -> 214.88 | G39: =IF(E39=0,0,(7.6-E39)*68) -> 301.92 | H39: 812 | I39: 10000 | J39: 13.4 | K39: 2.7 | L39: =K39*575 -> 1552.5 | M39: 6152.5
B40: 24904 | C40: 1000 | D40: 7.6 | E40: 4.91 | F40: =E40*68 -> 333.88 | G40: =IF(E40=0,0,(7.6-E40)*68) -> 182.92 | H40: 813 | I40: 10000 | J40: 13.4 | K40: 10.92 | L40: =K40*575 -> 6279 | M40: =IF(K40=0,0,(13.4-K40)*575) -> 1426
B41: 24905 | C41: 1000 | D41: 7.6 | E41: 3.31 | F41: =E41*81 -> 268.11 | G41: =IF(E41=0,0,(7.6-E41)*81) -> 347.49 | H41: 818 | I41: 5000 | J41: 12.5 | K41: 12.11 | L41: =K41*305 -> 3693.55 | M41: =IF(K41=0,0,(12.5-K41)*305) -> 118.95
...

Sheet 取值
A1: 2026-01-07 | B1: 油品动态 | C1: 0 | L1: 20230914更新
A3: 6101 | B3: 3.589725 | M3: 王静
A4: 6102 | B4: 9.667504
A5: 6105 | B5: 4.456197
A6: 6106 | B6: 10.55229
A7: 9501 | B7: 11.81396
A8: 9502 | B8: 11.72607
A9: 9503 | B9: 10.78818
A10: 9510 | B10: 8.879654
A12: 6104 | B12: 2.622185
A14: 6201 | B14: 4.613108
A15: 6202 | B15: 2.754536
A16: 6204 | B16: 7.067131
A17: 6205 | B17: 6.905524
... A35: 6804 | B35: 11.9147
A37: 9527 | B37: 7.330278 | N37: 米系数
A38: 9528 | B38: 5.947126
A40: 9511 | B40: 10.02477
A41: 9514 | B41: 12.29096
A42: 9516 | B42: 8.457937
A45: 801 | B45: 13.09319
A46: 802 | B46: 13.091
A47: 803 | B47: 9.645005
A48: 804 | B48: 9.155269
A49: 810 | B49: 2.611139
A50: 811 | B50: 3.416842
A51: 812 | B51: 2.679999
A52: 813 | B52: 10.88624
... A111: 2117 | B111: 3.278337
A112: 2118
A114: TK3001A | B114: 6826.804
A115: TK3001B | B115: 7837.337
B116: 7837.337
A117: 3002A | B117: 6394.378
A118: 3002B | B118: 3508.785
A120: 24901 | B120: 6.80173
A121: 24902 | B121: 6.312459
J124: 原油入库 | K124: =IFERROR(SUM(L124:R124),0) -> 14688 | L124: 0 | M124: 14688 | N124: 0 | O124: 0 | P124: 0 | Q124: 0 | R124: 0
J125: 末站原油 | K125: =IFERROR(ROUND(M124,0),0) -> 14688
J126: 长庆原油 | K126: =IFERROR(ROUND(L124,0),0) -> 0
...
