Workbook

Sheet 半成品收拨平衡表（本年累计）
B2: 半成品收拨平衡表（本年累计）
B3: 填报单位：延安炼油厂 | H3: 日期： | J3: 2025-12 | P3: 陕油炼计统B206表 | Q3: 陕油炼计统B206表 | R3: 陕油炼计统B206表
B4: 指标名称 | C4: 单位 | D4: 期初 | E4: 外购量 | F4: 生产量 | G4: 成品 | H4: 装置 | I4: 销售 | J4: 油品 | K4: 生产 | L4: 内部调拨量 | N4: 内移量 | O4: 内移量 | P4: 盈（+） | Q4: 期末 | R4: 备 注
B5: 指标名称 | C5: 单位 | D5: 库存 | E5: 外购量 | F5: 生产量 | G5: 交库 | H5: 加工量 | I5: 销售 | J5: 调合 | K5: 自用 | L5: 调入 | M5: 调出 | N5: 移进 | O5: 移出 | P5: 亏（-） | Q5: 库存 | R5: 备 注
B6: 一、汽油 | C6: 吨 | D6: =IF(_xlfn.IFERROR(SUM(D7:D26),0)=0,"",_xlfn.IFERROR(SUM(D7:D26),0)) -> 27148 | E6: =IF(_xlfn.IFERROR(SUM(E7:E26),0)=0,"",_xlfn.IFERROR(SUM(E7:E26),0)) -> 23126.66 | F6: =IF(_xlfn.IFERROR(SUM(F7:F26),0)=0,"",_xlfn.IFERROR(SUM(F7:F26),0)) -> 2535501 | G6: =IF(_xlfn.IFERROR(SUM(G7:G26),0)=0,"",_xlfn.IFERROR(SUM(G7:G26),0)) | H6: =IF(_xlfn.IFERROR(SUM(H7:H26),0)=0,"",_xlfn.IFERROR(SUM(H7:H26),0)) -> 12140 | I6: =IF(_xlfn.IFERROR(SUM(I7:I26),0)=0,"",_xlfn.IFERROR(SUM(I7:I26),0)) | J6: =IF(_xlfn.IFERROR(SUM(J7:J26),0)=0,"",_xlfn.IFERROR(SUM(J7:J26),0)) -> 3187045 | K6: =IF(_xlfn.IFERROR(SUM(K7:K26),0)=0,"",_xlfn.IFERROR(SUM(K7:K26),0)) | ... O6: =IF(_xlfn.IFERROR(SUM(O7:O26),0)=0,"",_xlfn.IFERROR(SUM(O7:O26),0)) -> 19884 | P6: =_xlfn.IFERROR(SUM(P7:P26),0) -> -1772.18 | Q6: =IF(_xlfn.IFERROR(SUM(Q7:Q26),0)=0,"",_xlfn.IFERROR(SUM(Q7:Q26),0)) -> 31418.4
B7: 常压石脑油 | C7: 吨 | D7: =取值!D7 -> 1492 | E7: =取值!E7 -> 0 | F7: =取值!F7 -> 950698 | G7: =取值!G7 -> 0 | H7: =取值!H7 -> 0 | I7: =取值!I7 -> 0 | J7: =取值!J7 -> 0 | K7: =取值!K7 -> 0 | ... O7: =取值!O7 -> 0 | P7: =-_xlfn.IFERROR(SUM(IF(D7="",0,D7),IF(E7="",0,E7),IF(F7="",0,F7),IF(G7="",0,G7),IF(L7="",0,L7),IF(N7="",0,N7))-SUM(IF(H7="",0,H7),IF(I7="",0,I7),IF(J7="",0,J7),IF(K7="",0,K7),IF(M7="",0,M7),IF(O7="",0,O7),IF(Q7="",0,Q7)),"") -> -95 | Q7: =取值!Q7 -> 7375 | R7: =IF(取值!R7=0,"",取值!R7)
B8: 重整精制油 | C8: 吨
B9: MTBE | C9: 吨 | D9: =取值!D14 -> 6222 | E9: =取值!E14 -> 9400.16 | F9: =取值!F14 -> 40319 | G9: =取值!G14 -> 0 | H9: =取值!H14 -> 0 | I9: =取值!I14 -> 0 | J9: =取值!J14 -> 266399 | K9: =取值!K14 -> 0 | ... O9: =取值!O14 -> 767 | P9: =-_xlfn.IFERROR(SUM(IF(D9="",0,D9),IF(E9="",0,E9),IF(F9="",0,F9),IF(G9="",0,G9),IF(L9="",0,L9),IF(N9="",0,N9))-SUM(IF(H9="",0,H9),IF(I9="",0,I9),IF(J9="",0,J9),IF(K9="",0,K9),IF(M9="",0,M9),IF(O9="",0,O9),IF(Q9="",0,Q9)),"") -> 0.24 | Q9: =取值!Q14 -> 3440 | R9: =IF(取值!R14=0,"",取值!R14)
B10: 二甲苯 | C10: 吨 | D10: =取值!D20 -> 2078 | E10: =取值!E20 -> 13726.5 | F10: =取值!F20 -> 0 | G10: =取值!G20 -> 0 | H10: =取值!H20 -> 0 | I10: =取值!I20 -> 0 | J10: =取值!J20 -> 27570 | K10: =取值!K20 -> 0 | ... O10: =取值!O20 -> 0 | P10: =-_xlfn.IFERROR(SUM(IF(D10="",0,D10),IF(E10="",0,E10),IF(F10="",0,F10),IF(G10="",0,G10),IF(L10="",0,L10),IF(N10="",0,N10))-SUM(IF(H10="",0,H10),IF(I10="",0,I10),IF(J10="",0,J10),IF(K10="",0,K10),IF(M10="",0,M10),IF(O10="",0,O10),IF(Q10="",0,Q10)),"") -> -0.42 | Q10: =取值!Q20 -> 3645.4 | R10: =IF(取值!R20=0,"",取值!R20)
B11: 催化汽油 | C11: 吨 | D11: =取值!D8 -> 1217 | E11: =取值!E8 -> 0 | F11: =取值!F8 -> 1523017 | G11: =取值!G8 -> 0 | H11: =取值!H8 -> 0 | I11: =取值!I8 -> 0 | J11: =取值!J8 -> 0 | K11: =取值!K8 -> 0 | ... O11: =取值!O8 -> 0 | P11: =-_xlfn.IFERROR(SUM(IF(D11="",0,D11),IF(E11="",0,E11),IF(F11="",0,F11),IF(G11="",0,G11),IF(L11="",0,L11),IF(N11="",0,N11))-SUM(IF(H11="",0,H11),IF(I11="",0,I11),IF(J11="",0,J11),IF(K11="",0,K11),IF(M11="",0,M11),IF(O11="",0,O11),IF(Q11="",0,Q11)),"") -> -130 | Q11: =取值!Q8 -> 1663 | R11: =IF(取值!R8=0,"",取值!R8)
B12: 重整汽油 | C12: 吨 | D12: =取值!D9 -> 4214 | E12: =取值!E9 -> 0 | F12: =取值!F9 -> 0 | G12: =取值!G9 -> 0 | H12: =取值!H9 -> 0 | I12: =取值!I9 -> 0 | J12: =取值!J9 -> 992028 | K12: =取值!K9 -> 0 | ... O12: =取值!O9 -> 0 | P12: =-_xlfn.IFERROR(SUM(IF(D12="",0,D12),IF(E12="",0,E12),IF(F12="",0,F12),IF(G12="",0,G12),IF(L12="",0,L12),IF(N12="",0,N12))-SUM(IF(H12="",0,H12),IF(I12="",0,I12),IF(J12="",0,J12),IF(K12="",0,K12),IF(M12="",0,M12),IF(O12="",0,O12),IF(Q12="",0,Q12)),"") -> -609 | Q12: =取值!Q9 -> 3642 | R12: =IF(取值!R9=0,"",取值!R9)
B13: 加氢粗汽油 | C13: 吨
B14: 航煤粗汽油 | C14: 吨 | D14: =取值!D10 -> 0 | E14: =取值!E10 -> 0 | F14: =取值!F10 -> 4472 | G14: =取值!G10 -> 0 | H14: =取值!H10 -> 0 | I14: =取值!I10 -> 0 | J14: =取值!J10 -> 0 | K14: =取值!K10 -> 0 | ... O14: =取值!O10 -> 4472 | P14: =-_xlfn.IFERROR(SUM(IF(D14="",0,D14),IF(E14="",0,E14),IF(F14="",0,F14),IF(G14="",0,G14),IF(L14="",0,L14),IF(N14="",0,N14))-SUM(IF(H14="",0,H14),IF(I14="",0,I14),IF(J14="",0,J14),IF(K14="",0,K14),IF(M14="",0,M14),IF(O14="",0,O14),IF(Q14="",0,Q14)),"") -> 0 | Q14: =取值!Q10 -> 0 | R14: =IF(取值!R10=0,"",取值!R10)
B15: 抽提汽油（非芳烃） | C15: 吨
B16: C6馏分 | C16: 吨
B17: 二甲苯塔底油 | C17: 吨
B18: 石脑油号Ⅱ（拔头油） | C18: 吨 | D18: =取值!D11 -> 0 | E18: =取值!E11 -> 0 | F18: =取值!F11 -> 0 | G18: =取值!G11 -> 0 | H18: =取值!H11 -> 0 | I18: =取值!I11 -> 0 | J18: =取值!J11 -> 259307 | K18: =取值!K11 -> 0 | ... O18: =取值!O11 -> 0 | P18: =-_xlfn.IFERROR(SUM(IF(D18="",0,D18),IF(E18="",0,E18),IF(F18="",0,F18),IF(G18="",0,G18),IF(L18="",0,L18),IF(N18="",0,N18))-SUM(IF(H18="",0,H18),IF(I18="",0,I18),IF(J18="",0,J18),IF(K18="",0,K18),IF(M18="",0,M18),IF(O18="",0,O18),IF(Q18="",0,Q18)),"") -> 0 | Q18: =取值!Q11 -> 0 | R18: =IF(取值!R11=0,"",取值!R11)
B19: 戊烷 | C19: 吨 | D19: =取值!D13 -> 0 | E19: =取值!E13 -> 0 | F19: =取值!F13 -> 12140 | G19: =取值!G13 -> 0 | H19: =取值!H13 -> 12140 | I19: =取值!I13 -> 0 | J19: =取值!J13 -> 0 | K19: =取值!K13 -> 0 | ... O19: =取值!O13 -> 0 | P19: =-_xlfn.IFERROR(SUM(IF(D19="",0,D19),IF(E19="",0,E19),IF(F19="",0,F19),IF(G19="",0,G19),IF(L19="",0,L19),IF(N19="",0,N19))-SUM(IF(H19="",0,H19),IF(I19="",0,I19),IF(J19="",0,J19),IF(K19="",0,K19),IF(M19="",0,M19),IF(O19="",0,O19),IF(Q19="",0,Q19)),"") -> 0 | Q19: =取值!Q13 -> 0 | R19: =IF(取值!R13=0,"",取值!R13)
B20: 甲苯 | C20: 吨 | D20: =取值!D15 -> 0 | E20: =取值!E15 -> 0 | F20: =取值!F15 -> 1725 | G20: =取值!G15 -> 0 | H20: =取值!H15 -> 0 | I20: =取值!I15 -> 0 | J20: =取值!J15 -> 0 | K20: =取值!K15 -> 0 | ... O20: =取值!O15 -> 1725 | P20: =-_xlfn.IFERROR(SUM(IF(D20="",0,D20),IF(E20="",0,E20),IF(F20="",0,F20),IF(G20="",0,G20),IF(L20="",0,L20),IF(N20="",0,N20))-SUM(IF(H20="",0,H20),IF(I20="",0,I20),IF(J20="",0,J20),IF(K20="",0,K20),IF(M20="",0,M20),IF(O20="",0,O20),IF(Q20="",0,Q20)),"") -> 0 | Q20: =取值!Q15 -> 0 | R20: =IF(取值!R15=0,"",取值!R15)
B21: 丙苯 | C21: 吨 | D21: =取值!D16 -> 0 | E21: =取值!E16 -> 0 | F21: =取值!F16 -> 2430 | G21: =取值!G16 -> 0 | H21: =取值!H16 -> 0 | I21: =取值!I16 -> 0 | J21: =取值!J16 -> 0 | K21: =取值!K16 -> 0 | ... O21: =取值!O16 -> 2430 | P21: =-_xlfn.IFERROR(SUM(IF(D21="",0,D21),IF(E21="",0,E21),IF(F21="",0,F21),IF(G21="",0,G21),IF(L21="",0,L21),IF(N21="",0,N21))-SUM(IF(H21="",0,H21),IF(I21="",0,I21),IF(J21="",0,J21),IF(K21="",0,K21),IF(M21="",0,M21),IF(O21="",0,O21),IF(Q21="",0,Q21)),"") -> 0 | Q21: =取值!Q16 -> 0 | R21: =IF(取值!R16=0,"",取值!R16)
B22: 高沸物 | C22: 吨 | D22: =取值!D17 -> 0 | E22: =取值!E17 -> 0 | F22: =取值!F17 -> 700 | G22: =取值!G17 -> 0 | H22: =取值!H17 -> 0 | I22: =取值!I17 -> 0 | J22: =取值!J17 -> 0 | K22: =取值!K17 -> 0 | ... O22: =取值!O17 -> 700 | P22: =-_xlfn.IFERROR(SUM(IF(D22="",0,D22),IF(E22="",0,E22),IF(F22="",0,F22),IF(G22="",0,G22),IF(L22="",0,L22),IF(N22="",0,N22))-SUM(IF(H22="",0,H22),IF(I22="",0,I22),IF(J22="",0,J22),IF(K22="",0,K22),IF(M22="",0,M22),IF(O22="",0,O22),IF(Q22="",0,Q22)),"") -> 0 | Q22: =取值!Q17 -> 0 | R22: =IF(取值!R17=0,"",取值!R17)
B23: 精制汽油 | C23: 吨 | D23: =取值!D12 -> 9226 | E23: =取值!E12 -> 0 | F23: =取值!F12 -> 0 | G23: =取值!G12 -> 0 | H23: =取值!H12 -> 0 | I23: =取值!I12 -> 0 | J23: =取值!J12 -> 1508263 | K23: =取值!K12 -> 0 | ... O23: =取值!O12 -> 9790 | P23: =-_xlfn.IFERROR(SUM(IF(D23="",0,D23),IF(E23="",0,E23),IF(F23="",0,F23),IF(G23="",0,G23),IF(L23="",0,L23),IF(N23="",0,N23))-SUM(IF(H23="",0,H23),IF(I23="",0,I23),IF(J23="",0,J23),IF(K23="",0,K23),IF(M23="",0,M23),IF(O23="",0,O23),IF(Q23="",0,Q23)),"") -> -938 | Q23: =取值!Q12 -> 7284 | R23: =IF(取值!R12=0,"",取值!R12)
B24: DCC脱戊烷油 | C24: 吨
B25: 油煤石脑油 | C25: 吨 | D25: =取值!D19 -> 0 | E25: =取值!E19 -> 0 | F25: =取值!F19 -> 0 | G25: =取值!G19 -> 0 | H25: =取值!H19 -> 0 | I25: =取值!I19 -> 0 | J25: =取值!J19 -> 0 | K25: =取值!K19 -> 0 | ... O25: =取值!O19 -> 0 | P25: =-_xlfn.IFERROR(SUM(IF(D25="",0,D25),IF(E25="",0,E25),IF(F25="",0,F25),IF(G25="",0,G25),IF(L25="",0,L25),IF(N25="",0,N25))-SUM(IF(H25="",0,H25),IF(I25="",0,I25),IF(J25="",0,J25),IF(K25="",0,K25),IF(M25="",0,M25),IF(O25="",0,O25),IF(Q25="",0,Q25)),"") -> 0 | Q25: =取值!Q19 -> 0 | R25: =IF(取值!R19=0,"",取值!R19)
B26: 异辛烷组分 | C26: 吨 | D26: =取值!D18 -> 2699 | E26: =取值!E18 -> 0 | F26: =取值!F18 -> 0 | G26: =取值!G18 -> 0 | H26: =取值!H18 -> 0 | I26: =取值!I18 -> 0 | J26: =取值!J18 -> 133478 | K26: =取值!K18 -> 0 | ... O26: =取值!O18 -> 0 | P26: =-_xlfn.IFERROR(SUM(IF(D26="",0,D26),IF(E26="",0,E26),IF(F26="",0,F26),IF(G26="",0,G26),IF(L26="",0,L26),IF(N26="",0,N26))-SUM(IF(H26="",0,H26),IF(I26="",0,I26),IF(J26="",0,J26),IF(K26="",0,K26),IF(M26="",0,M26),IF(O26="",0,O26),IF(Q26="",0,Q26)),"") -> 0 | Q26: =取值!Q18 -> 4369 | R26: =IF(取值!R18=0,"",取值!R18)
B27: 二、柴油 | C27: 吨 | D27: =IF(_xlfn.IFERROR(SUM(D28:D36),0)=0,"",_xlfn.IFERROR(SUM(D28:D36),0)) -> 22067 | E27: =IF(_xlfn.IFERROR(SUM(E28:E36),0)=0,"",_xlfn.IFERROR(SUM(E28:E36),0)) | F27: =IF(_xlfn.IFERROR(SUM(F28:F36),0)=0,"",_xlfn.IFERROR(SUM(F28:F36),0)) -> 3172441 | G27: =IF(_xlfn.IFERROR(SUM(G28:G36),0)=0,"",_xlfn.IFERROR(SUM(G28:G36),0)) | H27: =IF(_xlfn.IFERROR(SUM(H28:H36),0)=0,"",_xlfn.IFERROR(SUM(H28:H36),0)) -> 223400 | I27: =IF(_xlfn.IFERROR(SUM(I28:I36),0)=0,"",_xlfn.IFERROR(SUM(I28:I36),0)) | J27: =IF(_xlfn.IFERROR(SUM(J28:J36),0)=0,"",_xlfn.IFERROR(SUM(J28:J36),0)) -> 2749834 | K27: =IF(_xlfn.IFERROR(SUM(K28:K36),0)=0,"",_xlfn.IFERROR(SUM(K28:K36),0)) | ... O27: =IF(_xlfn.IFERROR(SUM(O28:O36),0)=0,"",_xlfn.IFERROR(SUM(O28:O36),0)) -> 587461 | P27: =_xlfn.IFERROR(SUM(P28:P36),0) -> -1025 | Q27: =IF(_xlfn.IFERROR(SUM(Q28:Q36),0)=0,"",_xlfn.IFERROR(SUM(Q28:Q36),0)) -> 20694
B28: 常压柴油 | C28: 吨 | D28: =取值!D22 -> 4053 | E28: =取值!E22 -> 0 | F28: =取值!F22 -> 1681854 | G28: =取值!G22 -> 0 | H28: =取值!H22 -> 0 | I28: =取值!I22 -> 0 | J28: =取值!J22 -> 0 | K28: =取值!K22 -> 0 | ... O28: =取值!O22 -> 172147 | P28: =-_xlfn.IFERROR(SUM(IF(D28="",0,D28),IF(E28="",0,E28),IF(F28="",0,F28),IF(G28="",0,G28),IF(L28="",0,L28),IF(N28="",0,N28))-SUM(IF(H28="",0,H28),IF(I28="",0,I28),IF(J28="",0,J28),IF(K28="",0,K28),IF(M28="",0,M28),IF(O28="",0,O28),IF(Q28="",0,Q28)),"") -> -164 | Q28: =取值!Q22 -> 3284 | R28: =IF(取值!R22=0,"",取值!R22)
B29: 催化柴油 | C29: 吨 | D29: =取值!D25 -> 5921 | E29: =取值!E25 -> 0 | F29: =取值!F25 -> 791281 | G29: =取值!G25 -> 0 | H29: =取值!H25 -> 0 | I29: =取值!I25 -> 0 | J29: =取值!J25 -> 0 | K29: =取值!K25 -> 0 | ... O29: =取值!O25 -> 0 | P29: =-_xlfn.IFERROR(SUM(IF(D29="",0,D29),IF(E29="",0,E29),IF(F29="",0,F29),IF(G29="",0,G29),IF(L29="",0,L29),IF(N29="",0,N29))-SUM(IF(H29="",0,H29),IF(I29="",0,I29),IF(J29="",0,J29),IF(K29="",0,K29),IF(M29="",0,M29),IF(O29="",0,O29),IF(Q29="",0,Q29)),"") -> -91 | Q29: =取值!Q25 -> 5653 | R29: =IF(取值!R25=0,"",取值!R25)
B30: 加氢柴油 | C30: 吨 | D30: =取值!D26 -> 0 | E30: =取值!E26 -> 0 | F30: =取值!F26 -> 0 | G30: =取值!G26 -> 0 | H30: =取值!H26 -> 0 | I30: =取值!I26 -> 0 | J30: =取值!J26 -> 872747 | K30: =取值!K26 -> 0 | ... O30: =取值!O26 -> 21877 | P30: =-_xlfn.IFERROR(SUM(IF(D30="",0,D30),IF(E30="",0,E30),IF(F30="",0,F30),IF(G30="",0,G30),IF(L30="",0,L30),IF(N30="",0,N30))-SUM(IF(H30="",0,H30),IF(I30="",0,I30),IF(J30="",0,J30),IF(K30="",0,K30),IF(M30="",0,M30),IF(O30="",0,O30),IF(Q30="",0,Q30)),"") -> -190 | Q30: =取值!Q26 -> 0 | R30: =IF(取值!R26=0,"",取值!R26)
B31: 精制柴油 | C31: 吨 | D31: =取值!D27 -> 4468 | E31: =取值!E27 -> 0 | F31: =取值!F27 -> 0 | G31: =取值!G27 -> 0 | H31: =取值!H27 -> 0 | I31: =取值!I27 -> 0 | J31: =取值!J27 -> 1749755 | K31: =取值!K27 -> 0 | ... O31: =取值!O27 -> 4155 | P31: =-_xlfn.IFERROR(SUM(IF(D31="",0,D31),IF(E31="",0,E31),IF(F31="",0,F31),IF(G31="",0,G31),IF(L31="",0,L31),IF(N31="",0,N31))-SUM(IF(H31="",0,H31),IF(I31="",0,I31),IF(J31="",0,J31),IF(K31="",0,K31),IF(M31="",0,M31),IF(O31="",0,O31),IF(Q31="",0,Q31)),"") -> -580 | Q31: =取值!Q27 -> 10460 | R31: =IF(取值!R27=0,"",取值!R27)
B32: 油煤柴油 | C32: 吨
B33: （航煤原料）常一线 | C33: 吨 | D33: =取值!D23 -> 7625 | E33: =取值!E23 -> 0 | F33: =取值!F23 -> 481048 | G33: =取值!G23 -> 0 | H33: =取值!H23 -> 223400 | I33: =取值!I23 -> 0 | J33: =取值!J23 -> 0 | K33: =取值!K23 -> 0 | ... O33: =取值!O23 -> 298356 | P33: =-_xlfn.IFERROR(SUM(IF(D33="",0,D33),IF(E33="",0,E33),IF(F33="",0,F33),IF(G33="",0,G33),IF(L33="",0,L33),IF(N33="",0,N33))-SUM(IF(H33="",0,H33),IF(I33="",0,I33),IF(J33="",0,J33),IF(K33="",0,K33),IF(M33="",0,M33),IF(O33="",0,O33),IF(Q33="",0,Q33)),"") -> 0 | Q33: =取值!Q23 -> 1297 | R33: =IF(取值!R23=0,"",取值!R23)
B34: 军柴原料 | C34: 吨
B35: 常三线 | C35: 吨
B36: 半成品航煤 | C36: 吨 | D36: =取值!D24 -> 0 | E36: =取值!E24 -> 0 | F36: =取值!F24 -> 218258 | G36: =取值!G24 -> 0 | H36: =取值!H24 -> 0 | I36: =取值!I24 -> 0 | J36: =取值!J24 -> 127332 | K36: =取值!K24 -> 0 | ... O36: =取值!O24 -> 90926 | P36: =-_xlfn.IFERROR(SUM(IF(D36="",0,D36),IF(E36="",0,E36),IF(F36="",0,F36),IF(G36="",0,G36),IF(L36="",0,L36),IF(N36="",0,N36))-SUM(IF(H36="",0,H36),IF(I36="",0,I36),IF(J36="",0,J36),IF(K36="",0,K36),IF(M36="",0,M36),IF(O36="",0,O36),IF(Q36="",0,Q36)),"") -> 0 | Q36: =取值!Q24 -> 0 | R36: =IF(取值!R24=0,"",取值!R24)
B37: 三、液化气 | C37: 吨 | D37: =IF(_xlfn.IFERROR(SUM(D38:D56),0)=0,"",_xlfn.IFERROR(SUM(D38:D56),0)) -> 8977 | E37: =IF(_xlfn.IFERROR(SUM(E38:E56),0)=0,"",_xlfn.IFERROR(SUM(E38:E56),0)) | F37: =IF(_xlfn.IFERROR(SUM(F38:F56),0)=0,"",_xlfn.IFERROR(SUM(F38:F56),0)) -> 1441652 | G37: =IF(_xlfn.IFERROR(SUM(G38:G56),0)=0,"",_xlfn.IFERROR(SUM(G38:G56),0)) -> 15368 | H37: =IF(_xlfn.IFERROR(SUM(H38:H56),0)=0,"",_xlfn.IFERROR(SUM(H38:H56),0)) -> 1081279 | I37: =IF(_xlfn.IFERROR(SUM(I38:I56),0)=0,"",_xlfn.IFERROR(SUM(I38:I56),0)) -> 321442.8 | J37: =IF(_xlfn.IFERROR(SUM(J38:J56),0)=0,"",_xlfn.IFERROR(SUM(J38:J56),0)) | K37: =IF(_xlfn.IFERROR(SUM(K38:K56),0)=0,"",_xlfn.IFERROR(SUM(K38:K56),0)) | ... O37: =IF(_xlfn.IFERROR(SUM(O38:O56),0)=0,"",_xlfn.IFERROR(SUM(O38:O56),0)) -> 191372 | P37: =_xlfn.IFERROR(SUM(P38:P56),0) -> 957.48 | Q37: =IF(_xlfn.IFERROR(SUM(Q38:Q56),0)=0,"",_xlfn.IFERROR(SUM(Q38:Q56),0)) -> 7332
B38: 常压液化气 | C38: 吨
B39: 催化液化气 | C39: 吨 | D39: =取值!D29 -> 3659 | E39: =取值!E29 -> 0 | F39: =取值!F29 -> 539226 | G39: =取值!G29 -> 0 | H39: =取值!H29 -> 333212 | I39: =取值!I29 -> 0 | J39: =取值!J29 -> 0 | K39: =取值!K29 -> 0 | ... O39: =取值!O29 -> 0 | P39: =-_xlfn.IFERROR(SUM(IF(D39="",0,D39),IF(E39="",0,E39),IF(F39="",0,F39),IF(G39="",0,G39),IF(L39="",0,L39),IF(N39="",0,N39))-SUM(IF(H39="",0,H39),IF(I39="",0,I39),IF(J39="",0,J39),IF(K39="",0,K39),IF(M39="",0,M39),IF(O39="",0,O39),IF(Q39="",0,Q39)),"") -> 950.68 | Q39: =取值!Q29 -> 3354.5 | R39: =IF(取值!R29=0,"",取值!R29)
B40: 苯乙烯液化气 | C40: 吨 | D40: =取值!D30 -> 0 | E40: =取值!E30 -> 0 | F40: =取值!F30 -> 0 | G40: =取值!G30 -> 0 | H40: =取值!H30 -> 0 | I40: =取值!I30 -> 0 | J40: =取值!J30 -> 0 | K40: =取值!K30 -> 0 | ... O40: =取值!O30 -> 0 | P40: =-_xlfn.IFERROR(SUM(IF(D40="",0,D40),IF(E40="",0,E40),IF(F40="",0,F40),IF(G40="",0,G40),IF(L40="",0,L40),IF(N40="",0,N40))-SUM(IF(H40="",0,H40),IF(I40="",0,I40),IF(J40="",0,J40),IF(K40="",0,K40),IF(M40="",0,M40),IF(O40="",0,O40),IF(Q40="",0,Q40)),"") -> 0 | Q40: =取值!Q30 -> 0 | R40: =IF(取值!R30=0,"",取值!R30)
B41: 重整液化气 | C41: 吨
...

Sheet 取值
B1: 报表生成时间： | C1: 2025-12 | D1: 8:00:00
C2: =EDATE(C1,1) -> 46023
C3: =C2-1 -> 46022
D7: 1492 | E7: 0 | F7: 950698 | G7: 0 | H7: 0 | I7: 0 | J7: 0 | K7: 0 | L7: 0 | M7: 953346 | N7: 8626 | O7: 0 | Q7: 7375
D8: 1217 | E8: 0 | F8: 1523017 | G8: 0 | H8: 0 | I8: 0 | J8: 0 | K8: 0 | L8: 0 | M8: 1532231 | N8: 9790 | O8: 0 | Q8: 1663
D9: 4214 | E9: 0 | F9: 0 | G9: 0 | H9: 0 | I9: 0 | J9: 992028 | K9: 0 | L9: 992065 | M9: 0 | N9: 0 | O9: 0 | Q9: 3642
E10: 0 | F10: 4472 | G10: 0 | H10: 0 | I10: 0 | J10: 0 | K10: 0 | L10: 0 | O10: 4472
D11: 0 | E11: 0 | F11: 0 | G11: 0 | H11: 0 | I11: 0 | J11: 259307 | K11: 0 | L11: 259307 | M11: 0 | N11: 0 | O11: 0 | Q11: 0
D12: 9226 | E12: 0 | F12: 0 | G12: 0 | H12: 0 | I12: 0 | J12: 1508263 | K12: 0 | L12: 1517049 | M12: 0 | N12: 0 | O12: 9790 | Q12: 7284
D13: 0 | E13: 0 | F13: 12140 | G13: 0 | H13: 12140 | I13: 0 | J13: 0 | K13: 0 | L13: 0 | M13: 0 | N13: 0 | O13: 0 | Q13: 0
D14: 6222 | E14: 9400.16 | F14: 40319 | G14: 0 | H14: 0 | I14: 0 | J14: 266399 | K14: 0 | L14: 214664.6 | M14: 0 | N14: 0 | O14: 767 | Q14: 3440
D15: 0 | E15: 0 | F15: 1725 | G15: 0 | H15: 0 | I15: 0 | J15: 0 | K15: 0 | L15: 0 | M15: 0 | N15: 0 | O15: 1725 | Q15: 0
D16: 0 | E16: 0 | F16: 2430 | G16: 0 | H16: 0 | I16: 0 | J16: 0 | K16: 0 | L16: 0 | M16: 0 | N16: 0 | O16: 2430 | Q16: 0
D17: 0 | E17: 0 | F17: 700 | G17: 0 | H17: 0 | I17: 0 | J17: 0 | K17: 0 | L17: 0 | M17: 0 | N17: 0 | O17: 700 | Q17: 0
D18: 2699 | E18: 0 | F18: 0 | G18: 0 | H18: 0 | I18: 0 | J18: 133478 | K18: 0 | L18: 135148 | M18: 0 | N18: 0 | O18: 0 | Q18: 4369
D19: 0 | E19: 0 | F19: 0 | G19: 0 | H19: 0 | I19: 0 | J19: 0 | K19: 0 | L19: 0 | M19: 0 | N19: 0 | O19: 0 | Q19: 0
D20: 2078 | E20: 13726.5 | F20: 0 | G20: 0 | H20: 0 | I20: 0 | J20: 27570 | K20: 0 | L20: 14644.32 | M20: 0 | N20: 767 | O20: 0 | Q20: 3645.4
D22: 4053 | E22: 0 | F22: 1681854 | G22: 0 | H22: 0 | I22: 0 | J22: 0 | K22: 0 | L22: 0 | M22: 1866906 | N22: 356594 | O22: 172147 | Q22: 3284
D23: 7625 | E23: 0 | F23: 481048 | G23: 0 | H23: 223400 | I23: 0 | J23: 0 | K23: 0 | L23: 0 | M23: 0 | N23: 34380 | O23: 298356 | Q23: 1297
... D33: 715 | E33: 0 | F33: 31882 | G33: 0 | H33: 0 | I33: 0 | J33: 0 | K33: 0 | L33: 20852 | M33: 30403 | N33: 0 | O33: 22779 | Q33: 267
D34: 694 | E34: 0 | F34: 166720 | H34: 113631 | I34: 95198.64 | J34: 0 | K34: 0 | L34: 74310 | M34: 0 | N34: 267 | O34: 32686 | Q34: 477
D35: 487 | E35: 0 | F35: 84872 | G35: 0 | H35: 0 | I35: 0 | J35: 0 | K35: 0 | L35: 509 | M35: 74611 | N35: 168 | O35: 10984 | Q35: 441
D36: 1587 | L36: 52806.5 | M36: 54059 | Q36: 335
D37: 592 | E37: 0 | F37: 0 | G37: 0 | H37: 0 | I37: 0 | J37: 0 | K37: 0 | L37: 109406 | M37: 0 | N37: 0 | O37: 109761 | Q37: 243
D38: 492 | G38: 15368 | I38: 189305.4 | N38: 174694 | O38: 0 | Q38: 1247
D39: 491 | E39: 0 | F39: 92386 | G39: 0 | H39: 107779 | I39: 36938.76 | J39: 0 | K39: 0 | L39: 53588 | M39: 0 | N39: 0 | O39: 875 | Q39: 872.5
D40: 2369 | E40: 0 | F40: 0 | G40: 0 | H40: 51293 | I40: 8687.74 | J40: 0 | K40: 0 | L40: 59327 | M40: 0 | N40: 0 | O40: 0 | Q40: 1715
D41: 0 | E41: 0 | F41: 0 | G41: 0 | H41: 0 | I41: 0 | J41: 0 | K41: 0 | L41: 0 | M41: 0 | N41: 0 | O41: 0 | Q41: 0
D42: 2368 | E42: 0 | F42: 65411 | G42: 0 | H42: 64164 | I42: 0 | J42: 0 | K42: 0 | L42: 0 | M42: 0 | N42: 0 | O42: 0 | Q42: 3615
D43: 565 | E43: 0 | F43: 62340 | G43: 0 | H43: 62252 | I43: 0 | J43: 0 | K43: 0 | L43: 0 | M43: 0 | N43: 0 | O43: 0 | Q43: 653
D45: 535 | E45: 0 | F45: 25371 | G45: 0 | H45: 0 | I45: 24882.5 | J45: 0 | K45: 0 | L45: 0 | M45: 0 | N45: 0 | O45: 0
D46: 0 | E46: 0 | F46: 1109 | G46: 0 | H46: 0 | I46: 0 | J46: 0 | K46: 0 | L46: 0 | M46: 0 | N46: 0 | O46: 1109 | Q46: 0
D48: 0 | E48: 75.73 | F48: 0 | G48: 0 | H48: 0 | I48: 0 | J48: 0 | K48: 0 | L48: 0 | M48: 0 | N48: 0 | O48: 75.17 | Q48: 0.4
D51: 王静
D52: 黄宏飞
