Workbook

Sheet 半成品收拨平衡表（本年累计）
B2: 半成品收拨平衡表（本年累计）
B3: 填报单位：榆林炼油厂 | I3: 日期： | J3: 2025-12 | L3: =取值!A1&取值!B1&取值!C1 -> 报表生成时间：2026-01-01 8:00:00 | Q3: 陕油炼计统B206表
B4: 指标名称 | C4: 单位 | D4: 期初 库存 | E4: 外购量 | F4: 生产量 | G4: 成品 交库 | H4: 装置 加工量 | I4: 销售 | J4: 油品 调合 | K4: 生产 自用 | L4: 内部调拨量 | N4: 内移量 | P4: 盈(+) 亏(-) | Q4: 期末 库存 | R4: 备 注
L5: 调入 | M5: 调出 | N5: 移进 | O5: 移出
B6: 一、汽油
B7: 石脑油Ⅰ（常压石脑油） | C7: 吨 | D7: =取值!D7 -> 6249 | E7: =取值!E7 -> 0 | F7: =取值!F7 -> 842970 | G7: =取值!G7 -> 0 | H7: =取值!H7 -> 1002315 | I7: =取值!I7 -> 0 | J7: =取值!J7 -> 0 | K7: =取值!K7 -> 0 | L7: =取值!M7 -> 0 | M7: =取值!L7 -> 49520 | N7: =取值!N7 -> 226554 | O7: =取值!O7 -> 1366 | P7: =取值!AB7 -> 0 | Q7: =取值!Q7 -> 22572
B8: 精制石脑油 | C8: 吨 | D8: =取值!D33 -> 5189 | E8: =取值!E33 -> 0 | F8: =取值!F33 -> 0 | G8: =取值!G33 -> 0 | H8: =取值!H33 -> 0 | I8: =取值!I33 -> 0 | J8: =取值!J33 -> 0 | K8: =取值!K33 -> 0 | L8: =取值!M33 -> 0 | M8: =取值!L33 -> 0 | N8: =取值!N33 -> 1366 | O8: =取值!O33 -> 774 | P8: =取值!AB33 -> 0 | Q8: =取值!Q33 -> 5781
B9: MTBE | C9: 吨 | D9: =取值!D8 -> 1924 | E9: =取值!E8 -> 79331 | F9: =取值!F8 -> 0 | G9: =取值!G8 -> 0 | H9: =取值!H8 -> 0 | I9: =取值!I8 -> 0 | J9: =取值!J8 -> 90377 | K9: =取值!K8 -> 0 | L9: =取值!M8 -> 12184 | M9: =取值!L8 -> 0 | N9: =取值!N8 -> 0 | O9: =取值!O8 -> 0 | P9: =取值!AB8 -> 0 | Q9: =取值!Q8 -> 3062
B10: 二甲苯 | C10: 吨 | D10: =取值!D10 -> 3871 | E10: =取值!E10 -> 0 | F10: =取值!F10 -> 95326 | G10: =取值!G10 -> 0 | H10: =取值!H10 -> 0 | I10: =取值!I10 -> 15295 | J10: =取值!J10 -> 34744 | K10: =取值!K10 -> 0 | L10: =取值!M10 -> 0 | M10: =取值!L10 -> 44840 | N10: =取值!N10 -> 0 | O10: =取值!O10 -> 0 | P10: =取值!AB10 -> 1 | Q10: =取值!Q10 -> 4318
B11: 催化汽油 | C11: 吨 | D11: =取值!D12 -> 3839 | E11: =取值!E12 -> 0 | F11: =取值!F12 -> 841354 | G11: =取值!G12 -> 0 | H11: =取值!H12 -> 840052 | I11: =取值!I12 -> 0 | J11: =取值!J12 -> 0 | K11: =取值!K12 -> 0 | L11: =取值!M12 -> 0 | M11: =取值!L12 -> 0 | N11: =取值!N12 -> 0 | O11: =取值!O12 -> 0 | P11: =取值!AB12 -> 0 | Q11: =取值!Q12 -> 5141
B12: 重整汽油 | C12: 吨 | D12: =取值!D13 -> 0 | E12: =取值!E13 -> 0 | F12: =取值!F13 -> 634833 | G12: =取值!G13 -> 0 | H12: =取值!H13 -> 0 | I12: =取值!I13 -> 0 | J12: =_xlfn.IFERROR(F12-H12,"") -> 634833 | K12: =取值!K13 -> 0 | L12: =取值!M13 -> 0 | M12: =取值!L13 -> 0 | N12: =取值!N13 -> 0 | O12: =取值!O13 -> 0 | P12: =取值!AB13 -> 0 | Q12: =取值!Q13 -> 0
B13: 加氢粗汽油 | C13: 吨 | D13: =取值!D14 -> 0 | E13: =取值!E14 -> 0 | F13: =取值!F14 -> 221398 | G13: =取值!G14 -> 0 | H13: =取值!H14 -> 0 | I13: =取值!I14 -> 0 | J13: =取值!J14 -> 0 | K13: =取值!K14 -> 0 | L13: =取值!M14 -> 0 | M13: =取值!L14 -> 0 | N13: =取值!N14 -> 0 | O13: =取值!O14 -> 221398 | P13: =取值!P14 -> 0 | Q13: =取值!Q14 -> 0
B14: 航煤粗汽油 | C14: 吨 | D14: =取值!D35 -> 0 | E14: =取值!E35 -> 0 | F14: =取值!F35 -> 4382 | G14: =取值!G35 -> 0 | H14: =取值!H35 -> 0 | I14: =取值!I35 -> 0 | J14: =取值!J35 -> 0 | K14: =取值!K35 -> 0 | L14: =取值!M35 -> 0 | M14: =取值!L35 -> 0 | N14: =取值!N35 -> 0 | O14: =取值!O35 -> 4382 | P14: =取值!AB35 -> 0 | Q14: =取值!Q35 -> 0
B15: 抽提汽油（非芳烃） | C15: 吨 | D15: =取值!D15 -> 0 | E15: =取值!E15 -> 0 | F15: =取值!F15 -> 80598 | G15: =取值!G15 -> 0 | H15: =取值!H15 -> 0 | I15: =取值!I15 -> 0 | J15: =F15 -> 80598 | K15: =取值!K15 -> 0 | L15: =取值!M15 -> 0 | M15: =取值!L15 -> 0 | N15: =取值!N15 -> 0 | O15: =取值!O15 -> 0 | P15: =取值!AB15 -> 0 | Q15: =取值!Q15 -> 0
B16: C6馏分油 | C16: 吨 | D16: =取值!D16 -> 0 | E16: =取值!E16 -> 0 | F16: =取值!F16 -> 136054 | G16: =取值!G16 -> 0 | H16: =取值!H16 -> 132304 | I16: =取值!I16 -> 0 | J16: =取值!J16 -> 3750 | K16: =取值!K16 -> 0 | L16: =取值!M16 -> 0 | M16: =取值!L16 -> 0 | N16: =取值!N16 -> 0 | O16: =取值!O16 -> 0 | P16: =取值!AB16 -> 0 | Q16: =取值!Q16 -> 0
B17: 二甲苯塔底油 | C17: 吨 | D17: =取值!D32 -> 0 | E17: =取值!E32 -> 0 | F17: =取值!F32 -> 21166 | G17: =取值!G32 -> 0 | H17: =F17 -> 21166 | I17: =取值!I32 -> 0 | J17: =取值!J32 -> 0 | K17: =取值!K32 -> 0 | L17: =取值!M32 -> 0 | M17: =取值!L32 -> 0 | N17: =取值!N32 -> 0 | O17: =取值!O32 -> 0 | P17: =取值!AB32 -> 0 | Q17: =取值!Q32 -> 0
B18: 石脑油号Ⅱ（拔头油）
B19: 戊烷
B20: 甲苯
B21: 丙苯
B22: 高沸物
B23: 精制汽油 | C23: 吨 | D23: =取值!D17 -> 0 | E23: =取值!E17 -> 0 | F23: =取值!F17 -> 756695 | G23: =取值!G17 -> 0 | H23: =取值!H17 -> 0 | I23: =取值!I17 -> 0 | J23: =F23 -> 756695 | K23: =取值!K17 -> 0 | L23: =取值!M17 -> 0 | M23: =取值!L17 -> 0 | N23: =取值!N17 -> 0 | O23: =取值!O17 -> 0 | P23: =取值!AB17 -> 0 | Q23: =取值!Q17 -> 0
B24: 裂解汽油 | C24: 吨 | D24: =取值!D11 -> 0 | E24: =取值!E11 -> 2472 | F24: =取值!F11 -> 0 | G24: =取值!G11 -> 0 | H24: =取值!H11 -> 0 | I24: =取值!I11 -> 0 | J24: =_xlfn.IFERROR(F24-H24+E24,"") -> 2472 | K24: =取值!K11 -> 0 | L24: =取值!M11 -> 0 | M24: =取值!L11 -> 0 | N24: =取值!N11 -> 0 | O24: =取值!O11 -> 0 | P24: =取值!AB11 -> 0 | Q24: =取值!Q11 -> 0
B25: 油煤石脑油
B26: 异辛烷组分 | D26: =取值!D9 -> 2670 | E26: =取值!E9 -> 0 | F26: =取值!F9 -> 0 | G26: =取值!G9 -> 0 | H26: =取值!H9 -> 0 | I26: =取值!I9 -> 0 | J26: =取值!J9 -> 55587 | K26: =取值!K9 -> 0 | L26: =取值!M9 -> 55620 | M26: =取值!L9 -> 0 | N26: =取值!N9 -> 0 | O26: =取值!O9 -> 0 | P26: =取值!AB9 -> 0 | Q26: =取值!Q9 -> 2703
B27: 二、柴油
B28: 常压柴油 | C28: 吨 | D28: =取值!D22 -> 0 | E28: =取值!E22 -> 0 | F28: =取值!F22 -> 1526606 | G28: =取值!G22 -> 0 | H28: 1526606 | I28: =取值!I22 -> 0 | J28: =取值!J22 -> 0 | K28: =取值!K22 -> 0 | L28: =取值!M22 -> 0 | M28: =取值!L22 -> 0 | N28: =取值!N22 -> 0 | O28: =取值!O22 -> 2074 | P28: =取值!AB22 -> 0 | Q28: =取值!Q22 -> 0
B29: 催化柴油 | C29: 吨 | D29: =取值!D23 -> 3502 | E29: =取值!E23 -> 0 | F29: =取值!F23 -> 389517 | G29: =取值!G23 -> 0 | H29: =取值!H23 -> 375285 | I29: =取值!I23 -> 0 | J29: =取值!J23 -> 0 | K29: =取值!K23 -> 0 | L29: =取值!M23 -> 0 | M29: =取值!L23 -> 20988 | N29: =取值!N23 -> 21051 | O29: =取值!O23 -> 74 | P29: =取值!AB23 -> 0 | Q29: =取值!Q23 -> 17723
B30: 加氢柴油 | C30: 吨
B31: 精制柴油 | C31: 吨 | D31: =取值!D24 -> 0 | E31: =取值!E24 -> 0 | F31: =取值!F24 -> 1674381 | G31: =取值!G24 -> 0 | H31: =取值!H24 -> 0 | I31: =取值!I24 -> 0 | J31: =F31 -> 1674381 | K31: =取值!K24 -> 0 | L31: =取值!M24 -> 0 | M31: =取值!L24 -> 0 | N31: =取值!N24 -> 0 | O31: =取值!O24 -> 0 | P31: =取值!AB24 -> 0 | Q31: =取值!Q24 -> 0
B32: 油煤柴油 | C32: 吨
B33: 航煤原料 | C33: 吨 | D33: =取值!D36 -> 0 | E33: =取值!E36 -> 0 | F33: =取值!F36 -> 281248 | G33: =取值!G36 -> 0 | H33: =取值!H36 -> 281248 | I33: =取值!I36 -> 0 | J33: =取值!J36 -> 0 | K33: =取值!K36 -> 0 | L33: =取值!M36 -> 0 | M33: =取值!L36 -> 0 | N33: =取值!N36 -> 0 | O33: =取值!O36 -> 0 | P33: =取值!AB36 -> 0 | Q33: =取值!Q36 -> 0
B34: 军柴原料 | C34: 吨 | D34: =取值!D26 -> 5484 | E34: =取值!E26 -> 0 | F34: =取值!F26 -> 0 | G34: =取值!G26 -> 0 | H34: =取值!H26 -> 0 | I34: =取值!I26 -> 0 | J34: =取值!J26 -> 0 | K34: =取值!K26 -> 0 | L34: =取值!M26 -> 0 | M34: =取值!L26 -> 0 | N34: =取值!N26 -> 74 | O34: =取值!O26 -> 0 | P34: =取值!AB26 -> 0 | Q34: =取值!Q26 -> 5558
B35: 常三线油 | C35: 吨 | D35: =取值!D37 -> 0 | E35: =取值!E37 -> 0 | F35: =取值!F37 -> 0 | G35: =取值!G37 -> 0 | H35: =取值!H37 -> 0 | I35: =取值!I37 -> 0 | J35: =取值!J37 -> 0 | K35: =取值!K37 -> 0 | L35: =取值!M37 -> 0 | M35: =取值!L37 -> 0 | N35: =取值!N37 -> 0 | O35: =取值!O37 -> 0 | P35: =取值!AB37 -> 0 | Q35: =取值!Q37 -> 0
B36: 半成品航煤 | C36: 吨
B37: 三、液化气
B38: 常压液化气 | C38: 吨 | D38: =取值!D30 -> 0 | E38: =取值!E30 -> 0 | F38: =取值!F30 -> 44852 | G38: =取值!G30 -> 0 | H38: =取值!H30 -> 0 | I38: =取值!I30 -> 0 | J38: =取值!J30 -> 0 | K38: =取值!K30 -> 0 | L38: =取值!M30 -> 0 | M38: =取值!L30 -> 0 | N38: =取值!N27 -> 0 | O38: =取值!O30 -> 44852 | P38: =取值!AB30 -> 0 | Q38: =取值!Q30 -> 0
B39: 催化原料液化气 | C39: 吨 | D39: =取值!D28 -> 1086 | E39: =取值!E28 -> 0 | F39: =取值!F28 -> 226776 | G39: =取值!G28 -> 0 | H39: =取值!H28 -> 0 | I39: =取值!I28 -> 41361 | J39: =取值!J28 -> 0 | K39: =取值!K28 -> 0 | L39: =取值!M28 -> 0 | M39: =取值!L28 -> 184967 | N39: =取值!N28 -> 0 | O39: =取值!O28 -> 0 | P39: =取值!AB28 -> -10 | Q39: =取值!Q28 -> 1524
B40: 苯乙烯液化气 | C40: 吨
B41: 重整液化气 | C41: 吨 | D41: =取值!D31 -> 0 | E41: =取值!E31 -> 0 | F41: =取值!F31 -> 47162 | G41: =取值!G31 -> 0 | H41: =取值!H31 -> 0 | I41: =取值!I31 -> 0 | J41: =取值!J31 -> 0 | K41: =取值!K31 -> 0 | L41: =取值!M31 -> 0 | M41: =取值!L31 -> 0 | N41: =取值!N31 -> 0 | O41: =F41 -> 47162 | P41: =取值!AB31 -> 0 | Q41: =取值!Q31 -> 0
...

Sheet 取值
A1: 报表生成时间： | B1: 2026-01-01 | C1: 8:00:00
B4: 指标名称 | C4: 单位 | D4: 期初 库存 | E4: 外购量 | F4: 生产量 | G4: 成品 交库 | H4: 装置 加工量 | I4: 销售 | J4: 油品 调合 | K4: 生产 自用 | L4: 内部调拨量 | N4: 内移量 | P4: 装置 加工量 | Q4: 期末 库存 | AB4: 装置 加工量
L5: 调出 | M5: 调入 | N5: 移进 | O5: 移出
B6: 一、汽油
B7: 石脑油Ⅰ（常压石脑油） | C7: 吨 | D7: 6249 | E7: 0 | F7: 842970 | H7: 1002315 | I7: 0 | J7: 0 | K7: 0 | L7: 49520 | M7: 0 | N7: 226554 | O7: 1366 | P7: 0 | Q7: 22572 | AB7: 0
B8: MTBE | C8: 吨 | D8: 1924 | E8: 79331 | F8: 0 | H8: 0 | I8: 0 | J8: 90377 | K8: 0 | L8: 0 | M8: 12184 | P8: 0 | Q8: 3062 | AB8: 0
B9: 烷基化油 | D9: 2670 | F9: 0 | H9: 0 | I9: 0 | J9: 55587 | K9: 0 | L9: 0 | M9: 55620 | P9: 0 | Q9: 2703 | AB9: 0
B10: 二甲苯 | C10: 吨 | D10: 3871 | E10: 0 | F10: 95326 | H10: 0 | I10: 15295 | J10: 34744 | K10: 0 | L10: 44840 | M10: 0 | P10: 1 | Q10: 4318 | AB10: 1
B11: DCC脱戊烷油 | C11: 吨 | D11: 0 | E11: 2472 | F11: 0 | H11: 0 | I11: 0 | J11: 2472 | L11: 0 | M11: 0 | P11: 0 | AB11: 0
B12: 催化汽油 | C12: 吨 | D12: 3839 | E12: 0 | F12: 841354 | H12: 840052 | I12: 0 | J12: 0 | K12: 0 | L12: 0 | M12: 0 | P12: 0 | Q12: 5141 | AB12: 0
B13: 重整汽油 | C13: 吨 | D13: 0 | E13: 0 | F13: 634833 | H13: 0 | I13: 0 | J13: 634833 | L13: 0 | M13: 0 | P13: 0 | Q13: 0 | AB13: 0
B14: 加氢粗汽油 | C14: 吨 | D14: 0 | E14: 0 | F14: 221398 | H14: 0 | I14: 0 | J14: 0 | L14: 0 | M14: 0 | O14: 221398 | P14: 0 | Q14: 0 | AB14: 0
B15: 非芳烃 | C15: 吨 | D15: 0 | E15: 0 | F15: 80598 | H15: 0 | I15: 0 | L15: 0 | M15: 0 | P15: 0 | Q15: 0 | AB15: 0
B16: C6馏分油 | C16: 吨 | D16: 0 | E16: 0 | F16: 136054 | H16: 132304 | I16: 0 | J16: 3750 | K16: 0 | L16: 0 | M16: 0 | P16: 0 | Q16: 0 | AB16: 0
B17: 精制汽油 | C17: 吨 | D17: 0 | E17: 0 | F17: 756695 | H17: 0 | I17: 0 | L17: 0 | M17: 0 | P17: 0 | Q17: 0 | AB17: 0
B18: 轻烃液（近似石脑油） | C18: 吨
B19: DCC石脑油C5 | C19: 吨 | D19: 0 | E19: 0 | F19: 0 | I19: 0 | J19: 0 | L19: 0 | M19: 0 | P19: 0 | Q19: 0 | AB19: 0
B20: 石脑油Ⅰ（加氢石脑油） | C20: 吨
B21: 二、柴油 | C21: 吨 | D21: 0 | E21: 0 | F21: 0 | H21: 0 | I21: 0 | J21: 0 | L21: 0 | M21: 0 | P21: 0 | Q21: 0 | AB21: 0
B22: 常压柴油 | C22: 吨 | D22: 0 | E22: 0 | F22: 1526606 | I22: 0 | J22: 0 | L22: 0 | M22: 0 | O22: 2074 | P22: 0 | Q22: 0 | AB22: 0
B23: 催化柴油 | C23: 吨 | D23: 3502 | E23: 0 | F23: 389517 | H23: 375285 | I23: 0 | J23: 0 | K23: 0 | L23: 20988 | M23: 0 | N23: 21051 | O23: 74 | P23: 0 | Q23: 17723 | AB23: 0
B24: 精制柴油 | C24: 吨 | D24: 0 | E24: 0 | F24: 1674381 | H24: 0 | I24: 0 | K24: 0 | L24: 0 | M24: 0 | P24: 0 | Q24: 0 | AB24: 0
B25: 油煤柴油 | C25: 吨 | D25: 0 | E25: 0 | F25: 0 | H25: 0 | I25: 0 | J25: 0 | L25: 0 | M25: 0 | P25: 0 | Q25: 0 | AB25: 0
B26: 军用柴油（原常二线） | C26: 吨 | D26: 5484 | E26: 0 | F26: 0 | H26: 0 | I26: 0 | J26: 0 | K26: 0 | L26: 0 | M26: 0 | N26: 74 | P26: 0 | Q26: 5558 | AB26: 0
B27: 四、液化气 | C27: 吨 | D27: 0 | E27: 0 | F27: 0 | H27: 0 | I27: 0 | L27: 0 | P27: 0 | Q27: 0 | AB27: 0
B28: 催化原料液化气 | C28: 吨 | D28: 1086 | E28: 0 | F28: 226776 | H28: 0 | I28: 41361 | K28: 0 | L28: 184967 | M28: 0 | P28: -10 | Q28: 1524 | AB28: -10
B29: 加氢原料液化气 | C29: 吨 | D29: 0 | E29: 0 | F29: 0 | H29: 0 | I29: 0 | J29: 0 | K29: 0 | L29: 0 | M29: 0 | P29: 0 | Q29: 0 | AB29: 0
B30: 常压液化气 | C30: 吨 | E30: 0 | F30: 44852 | H30: 0 | K30: 0 | O30: 44852 | P30: 0 | Q30: 0 | AB30: 0
B31: 重整液化气 | C31: 吨 | D31: 0 | E31: 0 | F31: 47162 | H31: 0 | I31: 0 | L31: 0 | M31: 0 | P31: 0 | Q31: 0 | AB31: 0
B32: 二甲苯塔底油 | C32: 吨 | D32: 0 | E32: 0 | F32: 21166 | I32: 0 | J32: 0 | K32: 0 | L32: 0 | M32: 0 | P32: 0 | Q32: 0 | AB32: 0
B33: 五、精制石脑油 | C33: 吨 | D33: 5189 | E33: 0 | F33: 0 | H33: 0 | I33: 0 | J33: 0 | K33: 0 | L33: 0 | M33: 0 | N33: 1366 | O33: 774 | P33: 0 | Q33: 5781 | AB33: 0
B34: 液氨 | C34: 吨 | D34: 576 | E34: 0 | F34: 5024 | L34: 1867 | Q34: 619
B35: 航煤粗汽油 | C35: 吨 | D35: 0 | E35: 0 | F35: 4382 | H35: 0 | I35: 0 | J35: 0 | L35: 0 | M35: 0 | O35: 4382 | P35: 0 | Q35: 0 | AB35: 0
B36: 常一线油 | C36: 吨 | D36: 0 | E36: 0 | F36: 281248 | H36: 281248 | I36: 0 | J36: 0 | K36: 0 | L36: 0 | M36: 0 | N36: 0 | P36: 0 | Q36: 0 | AB36: 0
B37: 常三线 | C37: 吨 | D37: 0 | F37: 0 | L37: 0 | Q37: 0
D39: 891 | I39: 39540 | M39: 0 | N39: 52639 | O39: 92014 | Q39: 726
D40: 951 | F40: 41528 | I40: 41467 | Q40: 1012
E41: 19131 | F41: 19131
