Workbook

Sheet 原料油、成品收拨平衡表（本年累计）
B2: 原料油、成品收拨平衡表（本年累计）
B3: 填报单位：榆林炼油厂 | I3: 日期： | J3: 日期： | L3: 2025-12 | N3: =取值!A1&取值!B1&取值!C1 -> 报表生成时间：2026-01-01 8:00:00 | S3: 陕油炼计统B205表
B4: 指标名称 | C4: 单位 | D4: 期初 库存 | E4: 外购量 | F4: 生产量 | G4: 成品 交库 | H4: 装置 加工量 | I4: 销售 | J4: 销售 | L4: 油品 调合 | M4: 生产 自用 | N4: 内部调拨量 | P4: 内移量 | R4: 盈(+) 亏(-) | S4: 期末 库存 | T4: 备 注
J5: 公路、铁路 | K5: 管道 | N5: 调入 | O5: 调出 | P5: 移进 | Q5: 移出
B6: 一、原油及原料油
B7: 原油 | C7: 吨 | D7: =取值!D7 -> 113371 | E7: =取值!E7 -> 5180465 | F7: =取值!F7 -> 0 | G7: =取值!G7 -> 0 | H7: =取值!H7 -> 5055169 | I7: =_xlfn.IFERROR(J7+K7,"") -> 0 | J7: =取值!I7 -> 0 | K7: =取值!U7 -> 0 | L7: =取值!J7 -> 0 | M7: =取值!K7 -> 0 | N7: =取值!M7 -> 0 | O7: =取值!L7 -> 0 | P7: =取值!N7 -> 7765 | Q7: =取值!O7 -> 0 | R7: =取值!W7 -> 2 | S7: =取值!Q7 -> 246434
B8: 1#渣油 | C8: 吨 | D8: =取值!D8 -> 10071 | E8: =取值!E8 -> 0 | F8: =取值!F8 -> 2393921 | G8: =取值!G8 -> 0 | H8: =取值!H8 -> 1699985 | I8: =_xlfn.IFERROR(J8+K8,"") -> 746254 | J8: =取值!I8 -> 0 | K8: =取值!U8 -> 746254 | L8: =取值!J8 -> 0 | M8: =取值!K8 -> 0 | N8: =取值!M8 -> 82461 | O8: =取值!L8 -> 0 | P8: =取值!N8 -> 0 | Q8: =取值!O8 -> 8300 | R8: =取值!W8 -> 0 | S8: =取值!Q8 -> 31914
B9: 甲醇 | C9: 吨 | I9: =_xlfn.IFERROR(J9+K9,"") -> 0
B10: 醋酸 | C10: 吨 | I10: =_xlfn.IFERROR(J10+K10,"") -> 0
B11: DCC裂解石脑油 | C11: 吨 | D11: =取值!D11 -> 0 | E11: =取值!E11 -> 481 | F11: =取值!F11 -> 0 | G11: =取值!G11 -> 0 | H11: =取值!H11 -> 0 | I11: =_xlfn.IFERROR(J11+K11,"") -> 0 | J11: =取值!I11 -> 0 | K11: =取值!U11 -> 0 | L11: =取值!J11 -> 0 | M11: =取值!K11 -> 0 | N11: =取值!M11 -> 0 | O11: =取值!L11 -> 0 | P11: =取值!N11 -> 0 | Q11: =取值!O11 -> 0 | R11: =取值!W11 -> -481 | S11: =取值!Q11 -> 0
B12: DCC裂解轻油 | C12: 吨 | I12: =_xlfn.IFERROR(J12+K12,"") -> 0
B13: VGO（减压蜡油） | C13: 吨
B14: 沥青 | C14: 吨 | I14: =_xlfn.IFERROR(J14+K14,"") -> 0
B15: 罚没油 | C15: 吨 | E15: =取值!E13 -> 9 | I15: =_xlfn.IFERROR(J15+K15,"") -> 0 | Q15: =取值!O13 -> 9
B16: 二、成品油 | C16: 吨 | D16: =取值!D15 -> 0 | E16: =_xlfn.IFERROR(E17+E21,"") -> 0 | F16: =_xlfn.IFERROR(F17+F21,"") -> 3342820 | G16: =_xlfn.IFERROR(G17+G21,"") -> 0 | H16: =_xlfn.IFERROR(H17+H21,"") -> 0 | I16: =_xlfn.IFERROR(I17+I21,"") -> 3268210 | J16: =_xlfn.IFERROR(J17+J21,"") -> 0 | K16: =_xlfn.IFERROR(K17+K21,"") -> 0 | L16: =_xlfn.IFERROR(L17+L21,"") -> 0 | ... S16: =_xlfn.IFERROR(S17+S21,"") -> 168233
B17: 汽油 | C17: 吨 | D17: =取值!D16 -> 38500 | E17: =_xlfn.IFERROR(E18+E19,"") -> 0 | F17: =_xlfn.IFERROR(F18+F19,"") -> 1659056 | G17: =_xlfn.IFERROR(G18+G19,"") -> 0 | H17: =_xlfn.IFERROR(H18+H19,"") -> 0 | I17: =_xlfn.IFERROR(I18+I19,"") -> 1619985 | L17: =_xlfn.IFERROR(L18+L19,"") -> 0 | M17: =_xlfn.IFERROR(M18+M19,"") -> 0 | N17: =_xlfn.IFERROR(N18+N19,"") -> 0 | O17: =_xlfn.IFERROR(O18+O19,"") -> 0 | P17: =_xlfn.IFERROR(P18+P19,"") -> 16000 | Q17: =_xlfn.IFERROR(Q18+Q19,"") -> 16000 | R17: =_xlfn.IFERROR(R18+R19,"") -> -231 | S17: =_xlfn.IFERROR(S18+S19,"") -> 77340
B18: 92# | C18: 吨 | D18: =取值!D17 -> 32323 | E18: =取值!E17 -> 0 | F18: =取值!F17 -> 1479584 | G18: =取值!G17 -> 0 | H18: =取值!H17 -> 0 | I18: =_xlfn.IFERROR(J18+K18,"") -> 1420862 | J18: =取值!I17 -> 996117 | K18: =取值!U17 -> 424745 | L18: =取值!J17 -> 0 | M18: =取值!K17 -> 0 | N18: =取值!M17 -> 0 | O18: =取值!L17 -> 0 | P18: =取值!N17 -> 0 | Q18: =取值!O17 -> 16000 | R18: =取值!W17 -> -231 | S18: =取值!Q17 -> 74814
B19: 95# | C19: 吨 | D19: =取值!D18 -> 6177 | E19: =取值!E18 -> 0 | F19: =取值!F18 -> 179472 | G19: =取值!G18 -> 0 | H19: =取值!H18 -> 0 | I19: =_xlfn.IFERROR(J19+K19,"") -> 199123 | J19: =取值!I18 -> 199123 | K19: =取值!U18 -> 0 | L19: =取值!J18 -> 0 | M19: =取值!K18 -> 0 | N19: =取值!M18 -> 0 | O19: =取值!L18 -> 0 | P19: =取值!N18 -> 16000 | Q19: =取值!O18 -> 0 | R19: =取值!W18 -> 0 | S19: =取值!Q18 -> 2526
B20: 98# | C20: 吨 | I20: =_xlfn.IFERROR(J20+K20,"") -> 0
B21: 柴油 | C21: 吨 | D21: =取值!D19 -> 55584 | E21: =_xlfn.IFERROR(E22+E23+E24,"") -> 0 | F21: =_xlfn.IFERROR(F22+F23+F24,"") -> 1683764 | G21: =_xlfn.IFERROR(G22+G23+G24,"") -> 0 | H21: =_xlfn.IFERROR(H22+H23+H24,"") -> 0 | I21: =_xlfn.IFERROR(I22+I23+I24,"") -> 1648225 | L21: =_xlfn.IFERROR(L22+L23+L24,"") -> 0 | M21: =_xlfn.IFERROR(M22+M23+M24,"") -> 0 | N21: =_xlfn.IFERROR(N22+N23+N24,"") -> 0 | O21: =_xlfn.IFERROR(O22+O23+O24,"") -> 0 | P21: =_xlfn.IFERROR(P22+P23+P24,"") -> 4809 | Q21: =_xlfn.IFERROR(Q22+Q23+Q24,"") -> 4809 | R21: =_xlfn.IFERROR(R22+R23+R24,"") -> -230 | S21: =_xlfn.IFERROR(S22+S23+S24,"") -> 90893
B22: 0# | C22: 吨 | D22: =取值!D20 -> 48949 | E22: =取值!E20 -> 0 | F22: =取值!F20 -> 1559802 | G22: =取值!G20 -> 0 | H22: =取值!H20 -> 0 | I22: =_xlfn.IFERROR(J22+K22,"") -> 1530660 | J22: =取值!I20 -> 1130907 | K22: =取值!U20 -> 399753 | L22: =取值!J20 -> 0 | M22: =取值!K20 -> 0 | N22: =取值!M20 -> 0 | O22: =取值!L20 -> 0 | P22: =取值!N20 -> 4809 | Q22: =取值!O20 -> 0 | R22: =取值!W20 -> -230 | S22: =取值!Q20 -> 82670
B23: -10# | C23: 吨 | D23: =取值!D21 -> 6635 | E23: =取值!E21 -> 0 | F23: =取值!F21 -> 109351 | G23: =取值!G21 -> 0 | H23: =取值!H21 -> 0 | I23: =_xlfn.IFERROR(J23+K23,"") -> 106752 | J23: =取值!I21 -> 76648 | K23: =取值!U21 -> 30104 | L23: =取值!J21 -> 0 | M23: =取值!K21 -> 0 | N23: =取值!M21 -> 0 | O23: =取值!L21 -> 0 | P23: =取值!N21 -> 0 | Q23: =取值!O21 -> 4809 | R23: =取值!W21 -> 0 | S23: =取值!Q21 -> 4425
B24: -20# | C24: 吨 | D24: =取值!D22 -> 0 | E24: =取值!E22 -> 0 | F24: =取值!F22 -> 14611 | G24: =取值!G22 -> 0 | H24: =取值!H22 -> 0 | I24: =_xlfn.IFERROR(J24+K24,"") -> 10813 | J24: =取值!I22 -> 10813 | K24: =取值!U22 -> 0 | L24: =取值!J22 -> 0 | M24: =取值!K22 -> 0 | N24: =取值!M22 -> 0 | O24: =取值!L22 -> 0 | P24: =取值!N22 -> 0 | Q24: =取值!O22 -> 0 | R24: =取值!W22 -> 0 | S24: =取值!Q22 -> 3798
B25: -35# | C25: 吨 | I25: =_xlfn.IFERROR(J25+K25,"") -> 0
B26: 聚丙烯 | C26: 吨 | I26: =_xlfn.IFERROR(J26+K26,"") -> 0
B27: 苯乙烯焦油 | C27: 吨 | I27: =_xlfn.IFERROR(J27+K27,"") -> 0
B28: 苯乙烯 | C28: 吨 | I28: =_xlfn.IFERROR(J28+K28,"") -> 0
B29: 3#喷气燃料 | C29: 吨 | D29: =取值!D31 -> 7106 | E29: =取值!E31 -> 0 | F29: =取值!F31 -> 272723 | G29: =取值!G31 -> 0 | H29: =取值!H31 -> 0 | I29: =_xlfn.IFERROR(J29+K29,"") -> 257518 | J29: =取值!I31 -> 0 | K29: =取值!U31 -> 257518 | L29: =取值!J31 -> 9383 | M29: =取值!K31 -> 0 | N29: =取值!M31 -> 0 | O29: =取值!L31 -> 0 | P29: =取值!N31 -> 0 | Q29: =取值!O31 -> 7596 | R29: =取值!W31 -> 0 | S29: =取值!Q31 -> 5332
B30: 粗硫磺 | C30: 吨 | I30: =_xlfn.IFERROR(J30+K30,"") -> 0
B31: 精制硫磺 | C31: 吨 | D31: =取值!D26 -> 136.18 | E31: =取值!E26 -> 0 | F31: =取值!F26 -> 5775 | G31: =取值!G26 -> 0 | H31: =取值!H26 -> 0 | I31: =_xlfn.IFERROR(J31+K31,"") -> 5814 | J31: =取值!I26 -> 5814 | K31: =取值!U26 -> 0 | L31: =取值!J26 -> 0 | M31: =取值!K26 -> 0 | N31: =取值!M26 -> 0 | O31: =取值!L26 -> 0 | P31: =取值!N26 -> 0 | Q31: =取值!O26 -> 0 | R31: =取值!W26 -> -1 | S31: =取值!Q26 -> 95.88
B32: 醋酸仲丁酯 | C32: 吨 | I32: =_xlfn.IFERROR(J32+K32,"") -> 0
B33: 石脑油III | C33: 吨 | I33: =_xlfn.IFERROR(J33+K33,"") -> 0
B34: 2#渣油 | C34: 吨 | D34: =取值!D27 -> 2159 | E34: =取值!E27 -> 0 | F34: =取值!F27 -> 55349 | G34: =取值!G27 -> 0 | H34: =取值!H27 -> 0 | I34: =_xlfn.IFERROR(J34+K34,"") -> 61449 | J34: =取值!I27 -> 61449 | K34: =取值!U27 -> 0 | L34: =取值!J27 -> 0 | M34: =取值!K27 -> 0 | N34: =取值!M27 -> 0 | O34: =取值!L27 -> 0 | P34: =取值!N27 -> 8300 | Q34: =取值!O27 -> 0 | R34: =取值!W27 -> 0 | S34: =取值!Q27 -> 4359
B35: 硫酸铵 | C35: 吨 | I35: =_xlfn.IFERROR(J35+K35,"") -> 0
B36: 液氮 | C36: 吨 | D36: =取值!D39 -> 0 | E36: =取值!E39 -> 776 | F36: =取值!F39 -> 0 | G36: =取值!G39 -> 0 | H36: =取值!H39 -> 0 | I36: =_xlfn.IFERROR(J36+K36,"") -> 0 | J36: =取值!I39 -> 0 | K36: =取值!U39 -> 0 | L36: =取值!J39 -> 0 | M36: =取值!K39 -> 776 | N36: =取值!L39 -> 0 | O36: =取值!M39 -> 0 | P36: =取值!N39 -> 0 | Q36: =取值!O39 -> 0 | R36: =取值!P39 -> 0 | S36: =取值!Q39 -> 0
B37: 粗白油 | C37: 吨 | I37: =_xlfn.IFERROR(J37+K37,"") -> 0 | N37: =取值!G35 -> 0 | O37: =取值!H35 -> 0 | P37: =取值!G36 -> 0 | Q37: =取值!H36 -> 0
B38: 液氨 | C38: 吨 | D38: =取值!D33 -> 576 | F38: =取值!F33 -> 5024 | I38: =_xlfn.IFERROR(J38+K38,"") -> 3113 | J38: =取值!D35 -> 3113 | K38: =取值!D36 -> 0 | O38: =取值!M38 -> 1867 | S38: =取值!D37 -> 619
B39: 煤液化沥青 | C39: 吨 | I39: =_xlfn.IFERROR(J39+K39,"") -> 0
B40: 含固渣油 | C40: 吨 | I40: =_xlfn.IFERROR(J40+K40,"") -> 0
B41: 三、LNG | C41: 吨 | I41: =_xlfn.IFERROR(J41+K41,"") -> 0
...

Sheet 取值
A1: 报表生成时间： | B1: 2026-01-01 | C1: 8:00:00
B4: 指标名称 | C4: 单位 | D4: 期初 库存 | E4: 外购量 | F4: 生产量 | G4: 成品 交库 | H4: 装置 加工量 | I4: 销售_公路 | J4: 油品 调合 | K4: 生产 自用 | L4: 内部调拨量 | N4: 内移量 | P4: 盈(+) 亏(-) | Q4: 期末 库存 | U4: 销售_管道
L5: 调出 | M5: 调入 | N5: 移进 | O5: 移出 | W5: 盈亏
B6: 一、原油及原料油
B7: 原油 | D7: 113371 | E7: 5180465 | F7: 0 | G7: 0 | H7: 5055169 | I7: 0 | J7: 0 | K7: 0 | L7: 0 | M7: 0 | N7: 7765 | O7: 0 | P7: 2 | Q7: 246434 | W7: 2
B8: 1#渣油 | D8: 10071 | E8: 0 | F8: 2393921 | G8: 0 | H8: 1699985 | I8: 0 | J8: 0 | K8: 0 | L8: 0 | M8: 82461 | N8: 0 | O8: 8300 | P8: 0 | Q8: 31914 | U8: 746254 | W8: 0
B9: 天燃气
B11: DCC裂解石脑油 | D11: 0 | E11: 481 | F11: 0 | G11: 0 | H11: 0 | I11: 0 | J11: 0 | K11: 0 | L11: 0 | M11: 0 | N11: 0 | O11: 0 | P11: -481 | Q11: 0 | U11: 0 | W11: -481
B12: VCC粗汽油
E13: 9 | O13: 9
B14: VCC石脑油
B15: 二、成品油
B16: 汽油 | D16: 38500 | J16: 0 | K16: 0 | L16: 0 | M16: 0 | N16: 0 | O16: 0 | P16: -227 | Q16: 77340 | W16: -227
B17: 92# | D17: 32323 | E17: 0 | F17: 1479584 | G17: 0 | H17: 0 | I17: 996117 | J17: 0 | K17: 0 | L17: 0 | M17: 0 | N17: 0 | O17: 16000 | P17: -231 | Q17: 74814 | U17: 424745 | W17: -231
B18: 95# | D18: 6177 | E18: 0 | F18: 179472 | G18: 0 | H18: 0 | I18: 199123 | J18: 0 | K18: 0 | L18: 0 | M18: 0 | N18: 16000 | O18: 0 | P18: 0 | Q18: 2526 | U18: 0 | W18: 0
B19: 柴油 | D19: 55584 | F19: 1683764 | J19: 0 | K19: 0 | L19: 0 | M19: 0 | N19: 0 | O19: 0 | P19: -230 | Q19: 90893 | W19: -230
B20: 0# | D20: 48949 | E20: 0 | F20: 1559802 | G20: 0 | H20: 0 | I20: 1130907 | J20: 0 | K20: 0 | L20: 0 | M20: 0 | N20: 4809 | O20: 0 | P20: -230 | Q20: 82670 | U20: 399753 | W20: -230
B21: -10# | D21: 6635 | E21: 0 | F21: 109351 | G21: 0 | H21: 0 | I21: 76648 | J21: 0 | K21: 0 | L21: 0 | M21: 0 | N21: 0 | O21: 4809 | P21: 0 | Q21: 4425 | U21: 30104 | W21: 0
B22: -20# | D22: 0 | E22: 0 | F22: 14611 | G22: 0 | H22: 0 | I22: 10813 | J22: 0 | K22: 0 | L22: 0 | M22: 0 | N22: 0 | O22: 0 | P22: 0 | Q22: 3798 | U22: 0 | W22: 0
B23: 苯 | D23: 951 | E23: 0 | F23: 41528 | G23: 0 | H23: 0 | J23: 0 | K23: 0 | L23: 0 | M23: 0 | N23: 0 | O23: 0 | P23: 0 | Q23: 1012 | W23: 0
B25: 干气
B26: 精制硫磺 | D26: 136.18 | E26: 0 | F26: 5775 | G26: 0 | H26: 0 | I26: 5814 | J26: 0 | K26: 0 | L26: 0 | M26: 0 | N26: 0 | O26: 0 | P26: -1 | Q26: 95.88 | U26: 0 | W26: -1
B27: 2#渣油 | D27: 2159 | E27: 0 | F27: 55349 | G27: 0 | H27: 0 | I27: 61449 | J27: 0 | K27: 0 | L27: 0 | M27: 0 | N27: 8300 | O27: 0 | P27: 0 | Q27: 4359 | U27: 0 | W27: 0
B28: 除盐水
B29: 罚没油 | D29: 0 | E29: 9 | F29: 0 | G29: 0 | H29: 0 | I29: 0 | J29: 0 | K29: 0 | L29: 0 | M29: 0 | N29: 0 | O29: 9 | P29: 0 | U29: 0 | W29: 0
B30: 混油
B31: 3#喷气燃料 | D31: 7106 | E31: 0 | F31: 272723 | G31: 0 | H31: 0 | I31: 0 | J31: 9383 | K31: 0 | L31: 0 | M31: 0 | N31: 0 | O31: 7596 | P31: 0 | Q31: 5332 | U31: 257518 | W31: 0
D33: 576 | F33: 5024
D35: 3113 | G35: 0 | H35: 0
D36: 0 | G36: 0 | H36: 0
D37: 619 | M37: 82461
M38: 1867
B39: 液氮 | E39: 776 | F39: 0 | G39: 0 | I39: 0 | J39: 0 | K39: 776 | L39: 0 | M39: 0 | N39: 0 | O39: 0 | P39: 0 | U39: 0 | W39: 0

Sheet Sheet4
A5: 盈亏
A7: 2
A8: 0
A11: -481
A16: -227
A17: -231
A18: 0
A19: -230
A20: -230
A21: 0
A22: 0
A23: 0
A26: -1
... A31: 0

Sheet Sheet2
A1: 113371
A2: 10071
A5: 0
A10: 38500
A11: 32323
A12: 6177
A13: 55584
A14: 48949
A15: 6635
A16: 0
A17: 951
A20: 136.18
... A25: 7106

Sheet Sheet1
A1: 0
A2: 0
A5: 0
A11: 0
A12: 0
A14: 0
A15: 0
A16: 0
A17: 0
A20: 0
A21: 0
A23: 0
... A260: 0
