Workbook

Sheet 原料产品收拨平衡月报
A1: 原料、产品收拨平衡月报表
A2: 填报单位：油田气化工科技公司 | F2: 日期： | G2: 2025-05 | J2: =取值!P1&取值!Q1&取值!R1 -> 报表生成时间：2025-06-01 8:00:00
A3: 指标名称 | C3: 单位 | D3: 期初库存 | E3: 外购量 | F3: 生产量 | G3: 装置加工量 | H3: 成品交库 | I3: 销售量 | J3: 生产自用 | K3: 移入 | L3: 移出 | M3: 盈亏 | N3: 期末库存
A4: 天然气 | C4: Nm3 | E4: =取值!E4 -> 21743000
A5: 原料天然气 | C5: Nm3 | G5: =取值!G5 -> 19990403
A6: 燃料天然气 | C6: Nm3 | J6: =取值!J6 -> 1752597
A7: 甲醇 | C7: t | D7: =取值!D7 -> 3351.29 | E7: =取值!E7 -> 7060.22 | G7: =取值!G7 -> 7189 | I7: =取值!I7 -> 0 | K7: =_xlfn.IFERROR(IF(取值!K7=0,"",取值!K7),"") | L7: =_xlfn.IFERROR(IF(取值!L7=0,"",取值!L7),"") | M7: =_xlfn.IFERROR(IF(取值!M7=0,"",取值!M7),"") | N7: =_xlfn.IFERROR(SUM(D7,E7,F7,H7,K7,M7)-SUM(G7,I7,J7,L7),"") -> 3222.51
A8: 醋酐 | C8: t | D8: =取值!D8 -> 144.38 | E8: =取值!E8 -> 0 | G8: =取值!G8 -> 0 | I8: =取值!I8 -> 0 | K8: =_xlfn.IFERROR(IF(取值!K8=0,"",取值!K8),"") | L8: =_xlfn.IFERROR(IF(取值!L8=0,"",取值!L8),"") | M8: =_xlfn.IFERROR(IF(取值!M8=0,"",取值!M8),"") | N8: =_xlfn.IFERROR(SUM(D8,E8,F8,H8,K8,M8)-SUM(G8,I8,J8,L8),"") -> 144.38
A9: BDO | C9: t | D9: =取值!D9 -> 326.39 | G9: =取值!G9 -> 0 | H9: 8004.69 | I9: =取值!I9 -> 4794.78 | K9: =_xlfn.IFERROR(IF(取值!K9=0,"",取值!K9),"") | L9: =_xlfn.IFERROR(IF(取值!L9=0,"",取值!L9),"") | M9: =_xlfn.IFERROR(IF(取值!M9=0,"",取值!M9),"") | N9: =_xlfn.IFERROR(SUM(D9,E9,F9,H9,K9,M9)-SUM(G9,I9,J9,L9),"") -> 3536.3
A10: THF | C10: t | D10: =取值!D10 -> 25.88 | G10: =取值!G10 -> 0 | H10: =取值!H10 -> 0 | I10: =取值!I10 -> 0 | K10: =_xlfn.IFERROR(IF(取值!K10=0,"",取值!K10),"") | L10: =_xlfn.IFERROR(IF(取值!L10=0,"",取值!L10),"") | M10: =_xlfn.IFERROR(IF(取值!M10=0,"",取值!M10),"") | N10: =_xlfn.IFERROR(SUM(D10,E10,F10,H10,K10,M10)-SUM(G10,I10,J10,L10),"") -> 25.88
A11: PTMEG | C11: t | D11: =取值!D11 -> 7138.61 | E11: =取值!E11 -> 0 | F11: =取值!F11 -> 0 | G11: =取值!G11 -> 0 | H11: =取值!H11 -> 0 | I11: =取值!I11 -> 90.18 | J11: =取值!J11 -> 0 | K11: =_xlfn.IFERROR(IF(取值!K11=0,"",取值!K11),"") | L11: =_xlfn.IFERROR(IF(取值!L11=0,"",取值!L11),"") | M11: =_xlfn.IFERROR(IF(取值!M11=0,"",取值!M11),"") | N11: =_xlfn.IFERROR(SUM(D11,E11,F11,H11,K11,M11)-SUM(G11,I11,J11,L11),"") -> 7048.43
A12: PTMEG1800 | B12: 国标 | C12: t | D12: =取值!D12 -> 7138.61 | G12: =取值!G12 -> 0 | H12: =取值!H12 -> 0 | I12: =取值!I12 -> 90.18 | K12: =_xlfn.IFERROR(IF(取值!K12=0,"",取值!K12),"") | L12: =_xlfn.IFERROR(IF(取值!L12=0,"",取值!L12),"") | M12: =_xlfn.IFERROR(IF(取值!M12=0,"",取值!M12),"") | N12: =_xlfn.IFERROR(SUM(D12,E12,F12,H12,K12,M12)-SUM(G12,I12,J12,L12),"") -> 7048.43
B13: 行标 | C13: t | D13: =取值!D13 -> 0 | G13: =取值!G13 -> 0 | H13: =取值!H13 -> 0 | I13: =取值!I13 -> 0 | K13: =_xlfn.IFERROR(IF(取值!K13=0,"",取值!K13),"") | L13: =_xlfn.IFERROR(IF(取值!L13=0,"",取值!L13),"") | M13: =_xlfn.IFERROR(IF(取值!M13=0,"",取值!M13),"") | N13: =_xlfn.IFERROR(SUM(D13,E13,F13,H13,K13,M13)-SUM(G13,I13,J13,L13),"") -> 0
A14: PTMEG2000 | B14: 国标 | C14: t | D14: =取值!D14 -> 0 | G14: =取值!G14 -> 0 | H14: =取值!H14 -> 0 | I14: =取值!I14 -> 0 | K14: =_xlfn.IFERROR(IF(取值!K14=0,"",取值!K14),"") | L14: =_xlfn.IFERROR(IF(取值!L14=0,"",取值!L14),"") | M14: =_xlfn.IFERROR(IF(取值!M14=0,"",取值!M14),"") | N14: =_xlfn.IFERROR(SUM(D14,E14,F14,H14,K14,M14)-SUM(G14,I14,J14,L14),"") -> 0
B15: 行标 | C15: t | D15: =取值!D15 -> 0 | G15: =取值!G15 -> 0 | H15: =取值!H15 -> 0 | I15: =取值!I15 -> 0 | K15: =_xlfn.IFERROR(IF(取值!K15=0,"",取值!K15),"") | L15: =_xlfn.IFERROR(IF(取值!L15=0,"",取值!L15),"") | M15: =_xlfn.IFERROR(IF(取值!M15=0,"",取值!M15),"") | N15: =_xlfn.IFERROR(SUM(D15,E15,F15,H15,K15,M15)-SUM(G15,I15,J15,L15),"") -> 0
A16: 副产油 | C16: t | D16: =取值!D16 -> 177.04 | H16: =取值!H16 -> 0 | I16: =取值!I16 -> 0 | K16: =_xlfn.IFERROR(IF(取值!K16=0,"",取值!K16),"") | L16: =_xlfn.IFERROR(IF(取值!L16=0,"",取值!L16),"") | M16: =_xlfn.IFERROR(IF(取值!M16=0,"",取值!M16),"") | N16: =_xlfn.IFERROR(SUM(D16,E16,F16,H16,K16,M16)-SUM(G16,I16,J16,L16),"") -> 177.04
A17: PTMEG过渡料 | C17: t | D17: =取值!D17 -> 0 | H17: =取值!H17 -> 0 | I17: =取值!I17 -> 0 | K17: =_xlfn.IFERROR(IF(取值!K17=0,"",取值!K17),"") | L17: =_xlfn.IFERROR(IF(取值!L17=0,"",取值!L17),"") | M17: =_xlfn.IFERROR(IF(取值!M17=0,"",取值!M17),"") | N17: =_xlfn.IFERROR(SUM(D17,E17,F17,H17,K17,M17)-SUM(G17,I17,J17,L17),"") -> 0
A18: 聚酯级乙二醇 | C18: t | D18: =取值!D18 -> 1472.5 | G18: =取值!G18 -> 0 | H18: =取值!H18 -> 4642 | I18: =取值!I18 -> 2329.92 | K18: =_xlfn.IFERROR(IF(取值!K18=0,"",取值!K18),"") | L18: =_xlfn.IFERROR(IF(取值!L18=0,"",取值!L18),"") | M18: =_xlfn.IFERROR(IF(取值!M18=0,"",取值!M18),"") | N18: =_xlfn.IFERROR(SUM(D18,E18,F18,H18,K18,M18)-SUM(G18,I18,J18,L18),"") -> 3784.58
A19: 工业级乙二醇 | C19: t | D19: =取值!D19 -> 0 | G19: =取值!G19 -> 0 | H19: =取值!H19 -> 0 | I19: =取值!I19 -> 0 | K19: =_xlfn.IFERROR(IF(取值!K19=0,"",取值!K19),"") | L19: =_xlfn.IFERROR(IF(取值!L19=0,"",取值!L19),"") | M19: =_xlfn.IFERROR(IF(取值!M19=0,"",取值!M19),"") | N19: =_xlfn.IFERROR(SUM(D19,E19,F19,H19,K19,M19)-SUM(G19,I19,J19,L19),"") -> 0
A20: 轻质多元醇 | C20: t | D20: =取值!D20 -> 42.61 | H20: =取值!H20 -> 1663.24 | I20: =取值!I20 -> 1388.44 | K20: =_xlfn.IFERROR(IF(取值!K20=0,"",取值!K20),"") | L20: =_xlfn.IFERROR(IF(取值!L20=0,"",取值!L20),"") | M20: =_xlfn.IFERROR(IF(取值!M20=0,"",取值!M20),"") | N20: =_xlfn.IFERROR(SUM(D20,E20,F20,H20,K20,M20)-SUM(G20,I20,J20,L20),"") -> 317.41
A21: 重质多元醇 | C21: t | D21: =取值!D21 -> 247.14 | H21: =取值!H21 -> 731.7 | I21: =取值!I21 -> 683.44 | K21: =_xlfn.IFERROR(IF(取值!K21=0,"",取值!K21),"") | L21: =_xlfn.IFERROR(IF(取值!L21=0,"",取值!L21),"") | M21: =_xlfn.IFERROR(IF(取值!M21=0,"",取值!M21),"") | N21: =_xlfn.IFERROR(SUM(D21,E21,F21,H21,K21,M21)-SUM(G21,I21,J21,L21),"") -> 295.4
A22: 混合醇 | C22: t | D22: =取值!D22 -> 37.84 | H22: =取值!H22 -> 197.8 | I22: =取值!I22 -> 196.14 | K22: =_xlfn.IFERROR(IF(取值!K22=0,"",取值!K22),"") | L22: =_xlfn.IFERROR(IF(取值!L22=0,"",取值!L22),"") | M22: =_xlfn.IFERROR(IF(取值!M22=0,"",取值!M22),"") | N22: =_xlfn.IFERROR(SUM(D22,E22,F22,H22,K22,M22)-SUM(G22,I22,J22,L22),"") -> 39.5
A23: 粗乙醇 | C23: t | D23: =取值!D23 -> 0 | H23: =取值!H23 -> 0 | I23: =取值!I23 -> 0 | K23: =_xlfn.IFERROR(IF(取值!K23=0,"",取值!K23),"") | L23: =_xlfn.IFERROR(IF(取值!L23=0,"",取值!L23),"") | M23: =_xlfn.IFERROR(IF(取值!M23=0,"",取值!M23),"") | N23: =_xlfn.IFERROR(SUM(D23,E23,F23,H23,K23,M23)-SUM(G23,I23,J23,L23),"") -> 0
A24: 碳酸二甲脂 | C24: t | D24: =取值!D24 -> 166.64 | H24: =取值!H24 -> 238.4 | I24: =取值!I24 -> 227.02 | K24: =_xlfn.IFERROR(IF(取值!K24=0,"",取值!K24),"") | L24: =_xlfn.IFERROR(IF(取值!L24=0,"",取值!L24),"") | M24: =_xlfn.IFERROR(IF(取值!M24=0,"",取值!M24),"") | N24: =_xlfn.IFERROR(SUM(D24,E24,F24,H24,K24,M24)-SUM(G24,I24,J24,L24),"") -> 178.02
A25: 正丁醇 | C25: t | D25: =取值!D25 -> 204.05 | H25: =取值!H25 -> 25.6 | I25: =取值!I25 -> 0 | K25: =_xlfn.IFERROR(IF(取值!K25=0,"",取值!K25),"") | L25: =_xlfn.IFERROR(IF(取值!L25=0,"",取值!L25),"") | M25: =_xlfn.IFERROR(IF(取值!M25=0,"",取值!M25),"") | N25: =_xlfn.IFERROR(SUM(D25,E25,F25,H25,K25,M25)-SUM(G25,I25,J25,L25),"") -> 229.65
A26: 焦油 | C26: t | D26: =取值!D26 -> 48.44 | H26: =取值!H26 -> 0 | I26: =取值!I26 -> 0 | K26: =_xlfn.IFERROR(IF(取值!K26=0,"",取值!K26),"") | L26: =_xlfn.IFERROR(IF(取值!L26=0,"",取值!L26),"") | M26: =_xlfn.IFERROR(IF(取值!M26=0,"",取值!M26),"") | N26: =_xlfn.IFERROR(SUM(D26,E26,F26,H26,K26,M26)-SUM(G26,I26,J26,L26),"") -> 48.44
A27: THF过渡料 | C27: t | D27: =取值!D27 -> 0 | H27: =取值!H27 -> 0 | I27: =取值!I27 -> 0 | K27: =_xlfn.IFERROR(IF(取值!K27=0,"",取值!K27),"") | L27: =_xlfn.IFERROR(IF(取值!L27=0,"",取值!L27),"") | M27: =_xlfn.IFERROR(IF(取值!M27=0,"",取值!M27),"") | N27: =_xlfn.IFERROR(SUM(D27,E27,F27,H27,K27,M27)-SUM(G27,I27,J27,L27),"") -> 0
A28: 备注：
A30: 单位负责人： | C30: 李刚 | L30: 填报人： | M30: 霍宇

Sheet 取值
A1: 原料、产品收拨平衡月报表 | P1: 报表生成时间： | Q1: 2025-06-01 | R1: 8:00:00
A2: 填报单位：油田气化工科技公司 | F2: 日期： | G2: 2025-05
A3: 指标名称 | C3: 单位 | D3: 期初库存 | E3: 外购量 | F3: 生产量 | G3: 装置加工量 | H3: 成品交库 | I3: 销售量 | J3: 生产自用 | K3: 移入 | L3: 移出 | M3: 盈亏 | N3: 期末库存
A4: 天然气 | C4: Nm3 | E4: =E29 -> 21743000
A5: 原料天然气 | C5: Nm3 | G5: =G30 -> 19990403
A6: 燃料天然气 | C6: Nm3 | J6: =_xlfn.IFERROR(SUM(E4-G5),"") -> 1752597
A7: 甲醇 | C7: t | D7: =D32 -> 3351.29 | E7: =E32 -> 7060.22 | G7: =G32 -> 7189 | I7: =I32 -> 0 | K7: =K32 -> 0 | L7: =L32 -> 0 | M7: 0
A8: 醋酐 | C8: t | D8: =D33 -> 144.38 | E8: =E33 -> 0 | G8: =G33 -> 0 | I8: =I33 -> 0 | K8: =K33 -> 0 | L8: =L33 -> 0 | M8: 0
A9: BDO | C9: t | D9: =D34 -> 326.39 | G9: =G34 -> 0 | H9: =H34 -> 8004.69 | I9: =I34 -> 4794.78 | K9: =K34 -> 0 | L9: =L34 -> 0 | M9: 0
A10: THF | C10: t | D10: =D35 -> 25.88 | G10: =G35 -> 0 | H10: =H35 -> 0 | I10: =I35 -> 0 | K10: =K35 -> 0 | L10: =L35 -> 0 | M10: 0
A11: PTMEG | C11: t | D11: =_xlfn.IFERROR(SUM(D12:D15),"") -> 7138.61 | E11: =_xlfn.IFERROR(SUM(E12:E15),"") -> 0 | F11: =_xlfn.IFERROR(SUM(F12:F15),"") -> 0 | G11: =_xlfn.IFERROR(SUM(G12:G15),"") -> 0 | H11: =_xlfn.IFERROR(SUM(H12:H15),"") -> 0 | I11: =_xlfn.IFERROR(SUM(I12:I15),"") -> 90.18 | J11: =_xlfn.IFERROR(SUM(J12:J15),"") -> 0 | K11: =_xlfn.IFERROR(SUM(K12:K15),"") -> 0 | ... N11: =_xlfn.IFERROR(SUM(N12:N15),"") -> 0
A12: PTMEG1800 | B12: 国标 | C12: t | D12: =D37 -> 7138.61 | G12: =G37 -> 0 | H12: =H37 -> 0 | I12: =I37 -> 90.18 | K12: =K37 -> 0 | L12: =L37 -> 0 | M12: 0
B13: 行标 | C13: t | D13: =D38 -> 0 | G13: =G38 -> 0 | H13: =H38 -> 0 | I13: =I38 -> 0 | K13: =K38 -> 0 | L13: =L38 -> 0 | M13: 0
A14: PTMEG2000 | B14: 国标 | C14: t | D14: =D39 -> 0 | G14: =G39 -> 0 | H14: =H39 -> 0 | I14: =I39 -> 0 | K14: =K39 -> 0 | L14: =L39 -> 0 | M14: 0
B15: 行标 | C15: t | D15: =D40 -> 0 | G15: =G40 -> 0 | H15: =H40 -> 0 | I15: =I40 -> 0 | K15: =K40 -> 0 | L15: =L40 -> 0 | M15: 0
A16: 副产油 | C16: t | D16: =D41 -> 177.04 | H16: =H41 -> 0 | I16: =I41 -> 0 | K16: =K41 -> 0 | L16: =L41 -> 0 | M16: 0
A17: PTMEG过渡料 | C17: t | D17: =D42 -> 0 | H17: =H42 -> 0 | I17: =I42 -> 0 | K17: =K42 -> 0 | L17: =L42 -> 0 | M17: 0
A18: 聚酯级乙二醇 | C18: t | D18: =D43 -> 1472.5 | G18: =G43 -> 0 | H18: =H43 -> 4642 | I18: =I43 -> 2329.92 | K18: =K43 -> 0 | L18: =L43 -> 0 | M18: 0
A19: 工业级乙二醇 | C19: t | D19: =D44 -> 0 | G19: =G44 -> 0 | H19: =H44 -> 0 | I19: =I44 -> 0 | K19: =K44 -> 0 | L19: =L44 -> 0 | M19: 0
A20: 乙二醇过渡料/轻质多元醇 | C20: t | D20: =D45 -> 42.61 | H20: =H45 -> 1663.24 | I20: =I45 -> 1388.44 | K20: =K45 -> 0 | L20: =L45 -> 0 | M20: 0
A21: 重质多元醇 | C21: t | D21: =D46 -> 247.14 | H21: =H46 -> 731.7 | I21: =I46 -> 683.44 | K21: =K46 -> 0 | L21: =L46 -> 0 | M21: 0
A22: 混合醇 | C22: t | D22: =D47 -> 37.84 | H22: =H47 -> 197.8 | I22: =I47 -> 196.14 | K22: =K47 -> 0 | L22: =L47 -> 0 | M22: 0
A23: 粗乙醇 | C23: t | D23: =D48 -> 0 | H23: =H48 -> 0 | I23: =I48 -> 0 | K23: =K48 -> 0 | L23: =L48 -> 0 | M23: 0
A24: 碳酸二甲脂 | C24: t | D24: =D49 -> 166.64 | H24: =H49 -> 238.4 | I24: =I49 -> 227.02 | K24: =K49 -> 0 | L24: =L49 -> 0 | M24: 0
A25: 正丁醇 | C25: t | D25: =D50 -> 204.05 | H25: =H50 -> 25.6 | I25: =I50 -> 0 | K25: =K50 -> 0 | L25: =L50 -> 0 | M25: 0
A26: 焦油 | C26: t | D26: =D51 -> 48.44 | H26: =H51 -> 0 | I26: =I51 -> 0 | K26: =K51 -> 0 | L26: =L51 -> 0 | M26: 0
A27: THF过渡料 | C27: t | D27: =D52 -> 0 | H27: =H52 -> 0 | I27: =I52 -> 0 | K27: =K52 -> 0 | L27: =L52 -> 0 | M27: 0
A29: 天然气 | C29: Nm3 | E29: 21743000
A30: 原料天然气 | C30: Nm3 | G30: 19990403
A31: 燃料天然气 | C31: Nm3 | G31: 19990403
A32: 甲醇 | C32: t | D32: 3351.29 | E32: 7060.22 | G32: =_xlfn.IFERROR(SUM(G57,G58,G59,G60),"") -> 7189 | I32: 0 | K32: 0 | L32: 0
A33: 醋酐 | C33: t | D33: 144.38 | E33: 0 | G33: 0 | I33: 0 | K33: 0 | L33: 0
A34: BDO | C34: t | D34: 326.39 | G34: =_xlfn.IFERROR(SUM(G63,G64,G65),"") -> 0 | H34: =_xlfn.IFERROR(SUM(H63,G65),"") -> 8004.69 | I34: 4794.78 | K34: 0 | L34: 0
A35: THF | D35: 25.88 | G35: 0 | H35: 0 | I35: 0 | K35: 0 | L35: 0
A36: PTMEG | C36: t
A37: PTMEG1800 | B37: 国标 | C37: t | D37: 7138.61 | G37: 0 | H37: 0 | I37: 90.18 | K37: 0 | L37: 0
B38: 行标 | C38: t | D38: 0 | G38: 0 | H38: 0 | I38: 0 | K38: 0 | L38: 0
A39: PTMEG2000 | B39: 国标 | C39: t | D39: 0 | G39: 0 | H39: 0 | I39: 0 | K39: 0 | L39: 0
B40: 行标 | C40: t | D40: 0 | G40: 0 | H40: 0 | I40: 0 | K40: 0 | L40: 0
A41: 副产油 | C41: t | D41: 177.04 | H41: 0 | I41: 0 | K41: 0 | L41: 0
...

Sheet Sheet3
