Workbook

Sheet 原料产品收拨平衡表
B2: 原料油、产品收拨平衡表(本年累计)
B3: 填报单位：延安石油化工厂 | D3: 日期： | E3: 2025-12 | H3: =原料产品取值!A49&原料产品取值!B49&原料产品取值!C49 -> 报表生成时间：2026-01-01 8:00:00 | M3: 陕延油炼化计统B205表
B4: 指标名称 | C4: 单位 | D4: 期初库存 | E4: 外购量 | F4: 生产量 | G4: 装置加工量 | H4: 销 售 | I4: 生产自用 | J4: 内部调拨量 | L4: 内移量 | N4: 盈（+） | O4: 期末库存
J5: 调入 | K5: 调出 | L5: 移入 | M5: 移出 | N5: 亏（-）
B6: 一、原料油（气）
B7: 1、常压石脑油 （石脑油Ⅰ） | C7: 吨 | D7: =原料产品取值!B3 -> 7587 | E7: =原料产品取值!C3 -> 0 | F7: =原料产品取值!D3 -> 0 | G7: =原料产品取值!F3 -> 1491491 | H7: =原料产品取值!G3 -> 0 | I7: =原料产品取值!I3 -> 0 | J7: =原料产品取值!J3 -> 1301027.6 | K7: =原料产品取值!K3 -> 0 | L7: =原料产品取值!L3 -> 197058 | M7: =原料产品取值!M3 -> 0 | N7: =_xlfn.IFERROR(SUM(IF(G7="",0,G7),IF(H7="",0,H7),IF(I7="",0,I7),IF(K7="",0,K7),IF(M7="",0,M7),IF(O7="",0,O7))-SUM(IF(D7="",0,D7),IF(E7="",0,E7),IF(F7="",0,F7),IF(J7="",0,J7),IF(L7="",0,L7)),0) -> -3892.58 | O7: =原料产品取值!O3 -> 10289 | P7: =_xlfn.IFERROR(SUM(D7,E7,F7,J7,L7,N7)-SUM(G7,H7,I7,K7,M7),0) -> 10289 | Q7: =_xlfn.IFERROR(P7-O7,"0") -> 0
B8: 其中：延炼 | C8: 吨 | D8: =原料产品取值!B4 -> 0 | E8: =原料产品取值!C4 -> 0 | F8: =原料产品取值!D4 -> 0 | G8: =原料产品取值!F4 -> 0 | H8: =原料产品取值!G4 -> 0 | I8: =原料产品取值!I4 -> 0 | J8: =原料产品取值!J4 -> 955826 | K8: =原料产品取值!K4 -> 0 | L8: =原料产品取值!L4 -> 0 | M8: =原料产品取值!M4 -> 0 | O8: =原料产品取值!O4 -> 0
B9: 永炼 | C9: 吨 | D9: =原料产品取值!B5 -> 0 | E9: =原料产品取值!C5 -> 0 | F9: =原料产品取值!D5 -> 0 | G9: =原料产品取值!F5 -> 0 | H9: =原料产品取值!G5 -> 0 | I9: =原料产品取值!I5 -> 0 | J9: =原料产品取值!J5 -> 296258.06 | K9: =原料产品取值!K5 -> 0 | L9: =原料产品取值!L5 -> 0 | M9: =原料产品取值!M5 -> 0 | O9: =原料产品取值!O5 -> 0
B10: 榆炼 | C10: 吨 | D10: =原料产品取值!B6 -> 0 | E10: =原料产品取值!C6 -> 0 | F10: =原料产品取值!D6 -> 0 | G10: =原料产品取值!F6 -> 0 | H10: =原料产品取值!G6 -> 0 | I10: =原料产品取值!I6 -> 0 | J10: =原料产品取值!J6 -> 48943.52 | K10: =原料产品取值!K6 -> 0 | L10: =原料产品取值!L6 -> 0 | M10: =原料产品取值!M6 -> 0 | O10: =原料产品取值!O6 -> 0
B11: 2、催化柴油 | C11: 吨 | D11: =原料产品取值!B7 -> 11515 | E11: =原料产品取值!C7 -> 0 | F11: =原料产品取值!D7 -> 0 | G11: =原料产品取值!F7 -> 1018725 | H11: =原料产品取值!G7 -> 0 | I11: =原料产品取值!I7 -> 0 | J11: =原料产品取值!J7 -> 987289.68 | K11: =原料产品取值!K7 -> 0 | L11: =原料产品取值!L7 -> 30745 | M11: =原料产品取值!M7 -> 518 | N11: =_xlfn.IFERROR(SUM(IF(G11="",0,G11),IF(H11="",0,H11),IF(I11="",0,I11),IF(K11="",0,K11),IF(M11="",0,M11),IF(O11="",0,O11))-SUM(IF(D11="",0,D11),IF(E11="",0,E11),IF(F11="",0,F11),IF(J11="",0,J11),IF(L11="",0,L11)),0) -> 231.32 | O11: =原料产品取值!O7 -> 10538 | P11: =_xlfn.IFERROR(SUM(D11,E11,F11,J11,L11,N11)-SUM(G11,H11,I11,K11,M11),0) -> 10538 | Q11: =_xlfn.IFERROR(P11-O11,"0") -> 0
B12: 其中：延炼 | C12: 吨 | D12: =原料产品取值!B8 -> 0 | E12: =原料产品取值!C8 -> 0 | F12: =原料产品取值!D8 -> 0 | G12: =原料产品取值!F8 -> 0 | H12: =原料产品取值!G8 -> 0 | I12: =原料产品取值!I8 -> 0 | J12: =原料产品取值!J8 -> 966625 | K12: =原料产品取值!K8 -> 0 | L12: =原料产品取值!L8 -> 0 | M12: =原料产品取值!M8 -> 0 | O12: =原料产品取值!O8 -> 0
B13: 永炼 | C13: 吨 | D13: =原料产品取值!B9 -> 0 | E13: =原料产品取值!C9 -> 0 | F13: =原料产品取值!D9 -> 0 | G13: =原料产品取值!F9 -> 0 | H13: =原料产品取值!G9 -> 0 | I13: =原料产品取值!I9 -> 0 | J13: =原料产品取值!J9 -> 0 | K13: =原料产品取值!K9 -> 0 | L13: =原料产品取值!L9 -> 0 | M13: =原料产品取值!M9 -> 0 | O13: =原料产品取值!O9 -> 0
B14: 榆炼 | C14: 吨 | D14: =原料产品取值!B10 -> 0 | E14: =原料产品取值!C10 -> 0 | F14: =原料产品取值!D10 -> 0 | G14: =原料产品取值!F10 -> 0 | H14: =原料产品取值!G10 -> 0 | I14: =原料产品取值!I10 -> 0 | J14: =原料产品取值!J10 -> 20664.68 | K14: =原料产品取值!K10 -> 0 | L14: =原料产品取值!L10 -> 0 | M14: =原料产品取值!M10 -> 0 | O14: =原料产品取值!O10 -> 0
B15: 3、催化汽油 | C15: 吨 | D15: =原料产品取值!B11 -> 1293 | E15: =原料产品取值!C11 -> 0 | F15: =原料产品取值!D11 -> 0 | G15: =原料产品取值!F11 -> 1533158 | H15: =原料产品取值!G11 -> 0 | I15: =原料产品取值!I11 -> 0 | J15: =原料产品取值!J11 -> 1537211 | K15: =原料产品取值!K11 -> 0 | L15: =原料产品取值!L11 -> 0 | M15: =原料产品取值!M11 -> 0 | N15: =_xlfn.IFERROR(SUM(IF(G15="",0,G15),IF(H15="",0,H15),IF(I15="",0,I15),IF(K15="",0,K15),IF(M15="",0,M15),IF(O15="",0,O15))-SUM(IF(D15="",0,D15),IF(E15="",0,E15),IF(F15="",0,F15),IF(J15="",0,J15),IF(L15="",0,L15)),0) -> -3782 | O15: =原料产品取值!O11 -> 1564 | P15: =_xlfn.IFERROR(SUM(D15,E15,F15,J15,L15,N15)-SUM(G15,H15,I15,K15,M15),0) -> 1564 | Q15: =_xlfn.IFERROR(P15-O15,"0") -> 0
B16: 4、常压柴油 | C16: 吨 | D16: =原料产品取值!B12 -> 2174 | E16: =原料产品取值!C12 -> 0 | F16: =原料产品取值!D12 -> 0 | G16: =原料产品取值!F12 -> 1864458 | H16: =原料产品取值!G12 -> 0 | I16: =原料产品取值!I12 -> 0 | J16: =原料产品取值!J12 -> 1872356 | K16: =原料产品取值!K12 -> 0 | L16: =原料产品取值!L12 -> 2007 | M16: =原料产品取值!M12 -> 10897 | N16: =_xlfn.IFERROR(SUM(IF(G16="",0,G16),IF(H16="",0,H16),IF(I16="",0,I16),IF(K16="",0,K16),IF(M16="",0,M16),IF(O16="",0,O16))-SUM(IF(D16="",0,D16),IF(E16="",0,E16),IF(F16="",0,F16),IF(J16="",0,J16),IF(L16="",0,L16)),0) -> 907 | O16: =原料产品取值!O12 -> 2089 | P16: =_xlfn.IFERROR(SUM(D16,E16,F16,J16,L16,N16)-SUM(G16,H16,I16,K16,M16),0) -> 2089 | Q16: =_xlfn.IFERROR(P16-O16,"0") -> 0
B17: 其中：延炼 | C17: 吨 | D17: =原料产品取值!B13 -> 0 | E17: =原料产品取值!C13 -> 0 | F17: =原料产品取值!D13 -> 0 | G17: =原料产品取值!F13 -> 0 | H17: =原料产品取值!G13 -> 0 | I17: =原料产品取值!I13 -> 0 | J17: =原料产品取值!J13 -> 1872356 | K17: =原料产品取值!K13 -> 0 | L17: =原料产品取值!L13 -> 0 | M17: =原料产品取值!M13 -> 0 | O17: =原料产品取值!O13 -> 0
B18: 永炼 | C18: 吨 | D18: =原料产品取值!B14 -> 0 | E18: =原料产品取值!C14 -> 0 | F18: =原料产品取值!D14 -> 0 | G18: =原料产品取值!F14 -> 0 | H18: =原料产品取值!G14 -> 0 | I18: =原料产品取值!I14 -> 0 | J18: =原料产品取值!J14 -> 0 | K18: =原料产品取值!K14 -> 0 | L18: =原料产品取值!L14 -> 0 | M18: =原料产品取值!M14 -> 0 | O18: =原料产品取值!O14 -> 0
B19: 榆炼 | C19: 吨 | D19: =原料产品取值!B15 -> 0 | E19: =原料产品取值!C15 -> 0 | F19: =原料产品取值!D15 -> 0 | G19: =原料产品取值!F15 -> 0 | H19: =原料产品取值!G15 -> 0 | I19: =原料产品取值!I15 -> 0 | J19: =原料产品取值!J15 -> 0 | K19: =原料产品取值!K15 -> 0 | L19: =原料产品取值!L15 -> 0 | M19: =原料产品取值!M15 -> 0 | O19: =原料产品取值!O15 -> 0
B20: 5、催化液化气 | C20: 吨 | D20: =原料产品取值!B16 -> 0 | E20: =原料产品取值!C16 -> 0 | F20: =原料产品取值!D16 -> 0 | G20: =原料产品取值!F16 -> 621089 | H20: =原料产品取值!G16 -> 0 | I20: =原料产品取值!I16 -> 0 | J20: =原料产品取值!J16 -> 621089 | K20: =原料产品取值!K16 -> 0 | L20: =原料产品取值!L16 -> 0 | M20: =原料产品取值!M16 -> 0 | O20: =原料产品取值!O16 -> 0 | P20: =_xlfn.IFERROR(SUM(D20,E20,F20,J20,L20,N20)-SUM(G20,H20,I20,K20,M20),0) -> 0 | Q20: =_xlfn.IFERROR(P20-O20,"0") -> 0
B21: 6、甲醇 | C21: 吨 | D21: =原料产品取值!B17 -> 5540 | E21: =原料产品取值!C17 -> 98470.22 | F21: =原料产品取值!D17 -> 0 | G21: =原料产品取值!F17 -> 98558 | H21: =原料产品取值!G17 -> 0 | I21: =原料产品取值!I17 -> 0 | J21: =原料产品取值!J17 -> 0 | K21: =原料产品取值!K17 -> 0 | L21: =原料产品取值!L17 -> 0 | M21: =原料产品取值!M17 -> 0 | N21: =_xlfn.IFERROR(SUM(IF(G21="",0,G21),IF(H21="",0,H21),IF(I21="",0,I21),IF(K21="",0,K21),IF(M21="",0,M21),IF(O21="",0,O21))-SUM(IF(D21="",0,D21),IF(E21="",0,E21),IF(F21="",0,F21),IF(J21="",0,J21),IF(L21="",0,L21)),0) -> -435.22 | O21: =原料产品取值!O17 -> 5017 | P21: =_xlfn.IFERROR(SUM(D21,E21,F21,J21,L21,N21)-SUM(G21,H21,I21,K21,M21),0) -> 5017 | Q21: =_xlfn.IFERROR(P21-O21,"0") -> 0
B22: 7、DCC | C22: 吨 | D22: =原料产品取值!B18 -> 0 | E22: =原料产品取值!C18 -> 65 | F22: =原料产品取值!D18 -> 0 | G22: =原料产品取值!F18 -> 0 | H22: =原料产品取值!G18 -> 0 | I22: =原料产品取值!I18 -> 0 | J22: =原料产品取值!J18 -> 6305.7 | K22: =原料产品取值!K18 -> 0 | L22: =原料产品取值!L18 -> 0 | M22: =原料产品取值!M18 -> 6370.7 | O22: =原料产品取值!O18 -> 0 | P22: =_xlfn.IFERROR(SUM(D22,E22,F22,J22,L22,N22)-SUM(G22,H22,I22,K22,M22),0) -> 0 | Q22: =_xlfn.IFERROR(P22-O22,"0") -> 0
B23: 8、柴油0# | C23: 吨 | D23: =原料产品取值!B19 -> 39 | E23: =原料产品取值!C19 -> 0 | F23: =原料产品取值!D19 -> 0 | G23: =原料产品取值!F19 -> 0 | H23: =原料产品取值!G19 -> 0 | I23: =原料产品取值!I19 -> 675 | J23: =原料产品取值!J19 -> 691 | K23: =原料产品取值!K19 -> 0 | L23: =原料产品取值!L19 -> 0 | M23: =原料产品取值!M19 -> 0 | O23: =原料产品取值!O19 -> 0 | P23: =_xlfn.IFERROR(SUM(D23,E23,F23,J23,L23,N23)-SUM(G23,H23,I23,K23,M23),0) -> 55 | Q23: =_xlfn.IFERROR(P23-O23,"0") -> 55
B24: 9、柴油-10# | C24: 吨 | D24: =原料产品取值!B20 -> 0 | E24: =原料产品取值!C20 -> 0 | F24: =原料产品取值!D20 -> 0 | G24: =原料产品取值!F20 -> 0 | H24: =原料产品取值!G20 -> 0 | I24: =原料产品取值!I20 -> 0 | J24: =原料产品取值!J20 -> 0 | K24: =原料产品取值!K20 -> 0 | L24: =原料产品取值!L20 -> 0 | M24: =原料产品取值!M20 -> 0 | O24: =原料产品取值!O20 -> 0 | P24: =_xlfn.IFERROR(SUM(D24,E24,F24,J24,L24,N24)-SUM(G24,H24,I24,K24,M24),0) -> 0 | Q24: =_xlfn.IFERROR(P24-O24,"0") -> 0
B25: 10、柴油-20# | C25: 吨 | D25: =原料产品取值!B21 -> 0 | E25: =原料产品取值!C21 -> 0 | F25: =原料产品取值!D21 -> 0 | G25: =原料产品取值!F21 -> 0 | H25: =原料产品取值!G21 -> 0 | I25: =原料产品取值!I21 -> 30 | J25: =原料产品取值!J21 -> 30 | K25: =原料产品取值!K21 -> 0 | L25: =原料产品取值!L21 -> 0 | M25: =原料产品取值!M21 -> 0 | O25: =原料产品取值!O21 -> 0 | P25: =_xlfn.IFERROR(SUM(D25,E25,F25,J25,L25,N25)-SUM(G25,H25,I25,K25,M25),0) -> 0 | Q25: =_xlfn.IFERROR(P25-O25,"0") -> 0
B26: 11、异丁烷 | C26: 吨 | D26: =原料产品取值!B22 -> 0 | E26: =原料产品取值!C22 -> 74490.36 | F26: =原料产品取值!D22 -> 0 | G26: =原料产品取值!F22 -> 0 | H26: =原料产品取值!G22 -> 0 | I26: =原料产品取值!I22 -> 0 | J26: =原料产品取值!J22 -> 0 | K26: =原料产品取值!K22 -> 0 | L26: =原料产品取值!L22 -> 0 | M26: =原料产品取值!M22 -> 74490.36 | O26: =原料产品取值!O22 -> 0 | P26: =_xlfn.IFERROR(SUM(D26,E26,F26,J26,L26,N26)-SUM(G26,H26,I26,K26,M26),0) -> 0 | Q26: =_xlfn.IFERROR(P26-O26,"0") -> 0
B27: 12、其他 | C27: 吨 | D27: =原料产品取值!B23 -> 0 | E27: =原料产品取值!C23 -> 0 | F27: =原料产品取值!D23 -> 0 | G27: =原料产品取值!F23 -> 0 | H27: =原料产品取值!G23 -> 0 | I27: =原料产品取值!I23 -> 0 | J27: =原料产品取值!J23 -> 0 | K27: =原料产品取值!K23 -> 0 | L27: =原料产品取值!L23 -> 0 | M27: =原料产品取值!M23 -> 0 | O27: =原料产品取值!O23 -> 0 | P27: =_xlfn.IFERROR(SUM(D27,E27,F27,J27,L27,N27)-SUM(G27,H27,I27,K27,M27),0) -> 0 | Q27: =_xlfn.IFERROR(P27-O27,"0") -> 0
B28: 二、产品产量 | D28: =原料产品取值!B24 -> 0 | E28: =原料产品取值!C24 -> 0 | F28: =原料产品取值!D24 -> 0 | G28: =原料产品取值!F24 -> 0 | H28: =原料产品取值!G24 -> 0 | I28: =原料产品取值!I24 -> 0 | J28: =原料产品取值!J24 -> 0 | K28: =原料产品取值!K24 -> 0 | L28: =原料产品取值!L24 -> 0 | M28: =原料产品取值!M24 -> 0 | O28: =原料产品取值!O24 -> 0
B29: (一）汽油 | C29: 吨
B30: 1、重整汽油 | C30: 吨 | D30: =原料产品取值!B26 -> 0 | E30: =原料产品取值!C26 -> 0 | F30: =原料产品取值!D26 -> 866531 | G30: =原料产品取值!F26 -> 0 | H30: =原料产品取值!G26 -> 0 | I30: =原料产品取值!I26 -> 0 | J30: =原料产品取值!J26 -> 0 | K30: =原料产品取值!K26 -> 866531 | L30: =原料产品取值!L26 -> 0 | M30: =原料产品取值!M26 -> 0 | O30: =原料产品取值!O26 -> 0 | P30: =_xlfn.IFERROR(SUM(D30,E30,F30,J30,L30,N30)-SUM(G30,H30,I30,K30,M30),0) -> 0 | Q30: =_xlfn.IFERROR(P30-O30,"0") -> 0
B31: 2、重整轻汽油 | C31: 吨 | D31: =原料产品取值!B27 -> 0 | E31: =原料产品取值!C27 -> 0 | F31: =原料产品取值!D27 -> 260107 | G31: =原料产品取值!F27 -> 0 | H31: =原料产品取值!G27 -> 0 | I31: =原料产品取值!I27 -> 0 | J31: =原料产品取值!J27 -> 0 | K31: =原料产品取值!K27 -> 260107 | L31: =原料产品取值!L27 -> 0 | M31: =原料产品取值!M27 -> 0 | O31: =原料产品取值!O27 -> 0 | P31: =_xlfn.IFERROR(SUM(D31,E31,F31,J31,L31,N31)-SUM(G31,H31,I31,K31,M31),0) -> 0 | Q31: =_xlfn.IFERROR(P31-O31,"0") -> 0
B32: 3、非芳烃 | C32: 吨 | D32: =原料产品取值!B28 -> 0 | E32: =原料产品取值!C28 -> 0 | F32: =原料产品取值!D28 -> 126972 | G32: =原料产品取值!F28 -> 0 | H32: =原料产品取值!G28 -> 0 | I32: =原料产品取值!I28 -> 0 | J32: =原料产品取值!J28 -> 0 | K32: =原料产品取值!K28 -> 126972 | L32: =原料产品取值!L28 -> 0 | M32: =原料产品取值!M28 -> 0 | O32: =原料产品取值!O28 -> 0 | P32: =_xlfn.IFERROR(SUM(D32,E32,F32,J32,L32,N32)-SUM(G32,H32,I32,K32,M32),0) -> 0 | Q32: =_xlfn.IFERROR(P32-O32,"0") -> 0
B33: 4、戊烷 | C33: 吨 | D33: =原料产品取值!B29 -> 0 | E33: =原料产品取值!C29 -> 0 | F33: =原料产品取值!D29 -> 5870 | G33: =原料产品取值!F29 -> 1777 | H33: =原料产品取值!G29 -> 0 | I33: =原料产品取值!I29 -> 0 | J33: =原料产品取值!J29 -> 0 | K33: =原料产品取值!K29 -> 4093 | L33: =原料产品取值!L29 -> 0 | M33: =原料产品取值!M29 -> 0 | O33: =原料产品取值!O29 -> 0 | P33: =_xlfn.IFERROR(SUM(D33,E33,F33,J33,L33,N33)-SUM(G33,H33,I33,K33,M33),0) -> 0 | Q33: =_xlfn.IFERROR(P33-O33,"0") -> 0
B34: 5、MTBE | C34: 吨 | D34: =原料产品取值!B30 -> 7131 | E34: =原料产品取值!C30 -> 3135 | F34: =原料产品取值!D30 -> 270854 | G34: =原料产品取值!F30 -> 0 | H34: =原料产品取值!G30 -> 0 | I34: =原料产品取值!I30 -> 0 | J34: =原料产品取值!J30 -> 0 | K34: =原料产品取值!K30 -> 275659.36 | L34: =原料产品取值!L30 -> 0 | M34: =原料产品取值!M30 -> 0 | N34: =_xlfn.IFERROR(SUM(IF(G34="",0,G34),IF(H34="",0,H34),IF(I34="",0,I34),IF(K34="",0,K34),IF(M34="",0,M34),IF(O34="",0,O34))-SUM(IF(D34="",0,D34),IF(E34="",0,E34),IF(F34="",0,F34),IF(J34="",0,J34),IF(L34="",0,L34)),0) -> -483.64 | O34: =原料产品取值!O30 -> 4977 | P34: =_xlfn.IFERROR(SUM(D34,E34,F34,J34,L34,N34)-SUM(G34,H34,I34,K34,M34),0) -> 4977 | Q34: =_xlfn.IFERROR(P34-O34,"0") -> 0
B35: 其中：延炼 | C35: 吨 | D35: =原料产品取值!B31 -> 0 | E35: =原料产品取值!C31 -> 0 | F35: =原料产品取值!D31 -> 0 | G35: =原料产品取值!F31 -> 0 | H35: =原料产品取值!F31 -> 0 | I35: =原料产品取值!I31 -> 0 | J35: =原料产品取值!J31 -> 0 | K35: =原料产品取值!K31 -> 214665 | L35: =原料产品取值!L31 -> 0 | M35: =原料产品取值!M31 -> 0 | O35: =原料产品取值!O31 -> 0
B36: 永炼 | C36: 吨 | D36: =原料产品取值!B32 -> 0 | E36: =原料产品取值!C32 -> 0 | F36: =原料产品取值!D32 -> 0 | G36: =原料产品取值!F32 -> 0 | H36: =原料产品取值!F32 -> 0 | I36: =原料产品取值!I32 -> 0 | J36: =原料产品取值!J32 -> 0 | K36: =原料产品取值!K32 -> 48816.64 | L36: =原料产品取值!L32 -> 0 | M36: =原料产品取值!M32 -> 0 | O36: =原料产品取值!O32 -> 0
B37: 榆炼 | C37: 吨 | D37: =原料产品取值!B33 -> 0 | E37: =原料产品取值!C33 -> 0 | F37: =原料产品取值!D33 -> 0 | G37: =原料产品取值!F33 -> 0 | H37: =原料产品取值!F33 -> 0 | I37: =原料产品取值!I33 -> 0 | J37: =原料产品取值!J33 -> 0 | K37: =原料产品取值!K33 -> 12177.72 | L37: =原料产品取值!L33 -> 0 | M37: =原料产品取值!M33 -> 0 | O37: =原料产品取值!O33 -> 0
B38: 6、精制汽油 | C38: 吨 | D38: =原料产品取值!B34 -> 0 | E38: =原料产品取值!C34 -> 0 | F38: =原料产品取值!D34 -> 1517866 | G38: =原料产品取值!F34 -> 0 | H38: =原料产品取值!G34 -> 0 | I38: =原料产品取值!I34 -> 0 | J38: =原料产品取值!J34 -> 0 | K38: =原料产品取值!K34 -> 1517866 | L38: =原料产品取值!L34 -> 0 | M38: =原料产品取值!M34 -> 0 | N38: =_xlfn.IFERROR(SUM(IF(G38="",0,G38),IF(H38="",0,H38),IF(I38="",0,I38),IF(K38="",0,K38),IF(M38="",0,M38),IF(O38="",0,O38))-SUM(IF(D38="",0,D38),IF(E38="",0,E38),IF(F38="",0,F38),IF(J38="",0,J38),IF(L38="",0,L38)),0) -> 0 | O38: =原料产品取值!O34 -> 0 | P38: =_xlfn.IFERROR(SUM(D38,E38,F38,J38,L38,N38)-SUM(G38,H38,I38,K38,M38),0) -> 0 | Q38: =_xlfn.IFERROR(P38-O38,"0") -> 0
B39: 7、异辛烷组分 | C39: 吨 | D39: =原料产品取值!B35 -> 5550 | E39: =原料产品取值!C35 -> 0 | F39: =原料产品取值!D35 -> 230334 | G39: =原料产品取值!F35 -> 0 | H39: =原料产品取值!G35 -> 0 | I39: =原料产品取值!I35 -> 0 | J39: =原料产品取值!J35 -> 0 | K39: =原料产品取值!K35 -> 234179.16 | L39: =原料产品取值!L35 -> 0 | N39: =_xlfn.IFERROR(SUM(IF(G39="",0,G39),IF(H39="",0,H39),IF(I39="",0,I39),IF(K39="",0,K39),IF(M39="",0,M39),IF(O39="",0,O39))-SUM(IF(D39="",0,D39),IF(E39="",0,E39),IF(F39="",0,F39),IF(J39="",0,J39),IF(L39="",0,L39)),0) -> 3521.16 | O39: =原料产品取值!O35 -> 5226 | P39: =_xlfn.IFERROR(SUM(D39,E39,F39,J39,L39,N39)-SUM(G39,H39,I39,K39,M39),0) -> 5226 | Q39: =_xlfn.IFERROR(P39-O39,"0") -> 0
B40: 其中：延炼 | C40: 吨 | D40: =原料产品取值!B36 -> 0 | E40: =原料产品取值!C36 -> 0 | F40: =原料产品取值!D36 -> 0 | G40: =原料产品取值!F36 -> 0 | H40: =原料产品取值!G36 -> 0 | I40: =原料产品取值!I36 -> 0 | J40: =原料产品取值!J36 -> 0 | K40: =原料产品取值!K36 -> 135148 | L40: =原料产品取值!L36 -> 0 | M40: =原料产品取值!M36 -> 0 | O40: =原料产品取值!O36 -> 0
B41: 榆炼 | C41: 吨 | D41: =原料产品取值!B37 -> 0 | E41: =原料产品取值!C37 -> 0 | F41: =原料产品取值!D37 -> 0 | G41: =原料产品取值!F37 -> 0 | H41: =原料产品取值!G37 -> 0 | I41: =原料产品取值!I37 -> 0 | J41: =原料产品取值!J37 -> 0 | K41: =原料产品取值!K37 -> 55777.62 | L41: =原料产品取值!L37 -> 0 | M41: =原料产品取值!M37 -> 0 | O41: =原料产品取值!O37 -> 0
...

Sheet 原料产品取值
B1: 期初库存 | C1: 外购量 | D1: 生产量 | E1: 成品交库 | F1: 装 置 加工量 | G1: 销 售 | H1: 油品调合 | I1: 生产自用 | J1: 内部调拨量 | L1: 内移量 | N1: 盈（+） | O1: 期末库存
A2: 一、原料油（气） | J2: 调入 | K2: 调出 | L2: 移入 | M2: 移出 | N2: 亏（-）
A3: 1、常压石脑油 | B3: 7587 | F3: 1491491 | J3: 1301027.6 | L3: 197058 | M3: 0 | O3: 10289
A4: 其中：延炼 | J4: 955826
A5: 永炼 | J5: 296258.06
A6: 榆炼 | J6: 48943.52
A7: 2、催化柴油 | B7: 11515 | F7: 1018725 | J7: 987289.68 | L7: 30745 | M7: 518 | O7: 10538
A8: 其中：延炼 | J8: 966625
A9: 永炼 | J9: 0
A10: 榆炼 | J10: 20664.68
A11: 3、催化汽油 | B11: 1293 | F11: 1533158 | J11: 1537211 | L11: 0 | M11: 0 | O11: 1564
A12: 4、常压柴油 | B12: 2174 | F12: 1864458 | J12: 1872356 | L12: 2007 | M12: 10897 | O12: 2089
A13: 其中：延炼 | J13: 1872356 | O13: 0
A14: 永炼 | J14: 0 | O14: 0
A15: 榆炼 | J15: 0
A16: 5、原料液化气 | F16: 621089 | J16: 621089 | L16: 0 | M16: 0 | O16: 0
A17: 6、甲醇 | B17: 5540 | C17: 98470.22 | F17: 98558 | L17: 0 | M17: 0 | O17: 5017
A18: 7、裂解轻油 | C18: 65 | J18: 6305.7 | M18: 6370.7
A19: 8、柴油0# | B19: 39 | I19: 675 | J19: 691 | O19: 0
A20: 9、柴油-10# | B20: 0 | I20: 0 | J20: 0 | O20: 0
A21: 10、柴油-20# | B21: 0 | I21: 30 | J21: 30 | O21: 0
A22: 11、异丁烷 | C22: 74490.36 | M22: 74490.36
A23: 12、其他
A24: 二、产品产量
A25: 1、汽油
A26: 其中：重整汽油 | D26: 866531 | K26: 866531
A27: 重整轻汽油 | D27: 260107 | K27: 260107
A28: 非芳烃 | D28: 126972 | K28: 126972
A29: 戊烷 | D29: 5870 | F29: 1777 | K29: 4093
A30: MTBE | B30: 7131 | C30: 3135 | D30: 270854 | F30: 0 | G30: 0 | I30: 0 | J30: 0 | K30: 275659.36 | L30: 0 | M30: 0 | O30: 4977
K31: 214665
K32: 48816.64
K33: 12177.72
A34: 精制汽油 | D34: 1517866 | K34: 1517866
A35: 烷基化油 | B35: 5550 | D35: 230334 | G35: 0 | K35: 234179.16 | M35: 0 | O35: 5226
A36: 其中：惠家河 | K36: 135148
A37: 榆炼 | K37: 55777.62
A38: 永炼 | K38: 43253.54
A39: 2、柴油 | B39: 0 | C39: 0 | D39: 2636010 | F39: 0 | G39: 0 | I39: 0 | J39: 0 | K39: 2636010
A40: 其中：加氢柴油 | D40: 892459 | K40: 892459
...
