Workbook

Sheet Sheet1
B2: 原材料、燃料、动力购进、库存及价格表
B3: 填报单位：延安石油化工厂生产计划部 | E3: 日期： | F3: 2025-12
B4: 指标名称 | C4: 期初库存 （吨） | D4: 购进量 (吨) | E4: 购进量(吨) | F4: 消费量 (吨) | G4: 消费量(吨) | H4: 期末库存 （吨） | I4: 价格 (元/吨)（元/Nm3） | J4: 当月金额 （千元） | K4: 累计金额 （千元）
B5: 一、原材料 | D5: 本月 | E5: 累计 | F5: 本月 | G5: 累计
B6: 甲 醇 | C6: =SUM(C7,C8) -> 3983 | D6: =SUM(D7,D8) -> 11272.76 | E6: =SUM(E7,E8) -> 98470.22 | F6: =SUM(F7,F8) -> 10195 | G6: =SUM(G7,G8) -> 98558 | H6: =SUM(H7,H8) -> 5017
B7: 其中：石化厂 | C7: 2128 | D7: 2577.28 | E7: =SUM(D7,取值!E5) -> 26666.96 | F7: 2102 | G7: =SUM(F7,取值!G5) -> 26543 | H7: 2603
B8: 轻烃 | C8: 1855 | D8: 8695.48 | E8: =SUM(D8,取值!E6) -> 71803.26 | F8: 8093 | G8: =SUM(F8,取值!G6) -> 72015 | H8: 2414
B9: 二、燃料
B10: 1、原 煤 | C10: =SUM(C11:C12) -> 3115 | D10: =SUM(D11:D12) -> 40561 | E10: =SUM(E11:E12) -> 416119 | F10: =SUM(F11:F12) -> 39896 | G10: =SUM(G11:G12) -> 419265 | H10: =SUM(H11:H12) -> 3780 | I10: 530.97 | J10: =SUM(J11:J12) -> 26969.49 | K10: =SUM(K11:K12) -> 252118.15
B11: 其中：石化厂 | C11: 375 | D11: 19244 | E11: =SUM(D11,取值!E9) -> 182058 | F11: 18900 | G11: =SUM(F11,取值!G9) -> 185273 | H11: 719 | J11: 12795.44 | K11: =SUM(J11,取值!K9) -> 110859.27
B12: 轻烃 | C12: 2740 | D12: 21317 | E12: =SUM(D12,取值!E10) -> 234061 | F12: 20996 | G12: =SUM(F12,取值!G10) -> 233992 | H12: 3061 | J12: 14174.05 | K12: =SUM(J12,取值!K10) -> 141258.87
B13: 2、 柴油0# | C13: 51 | D13: 95 | E13: =SUM(D13,取值!E11) -> 832 | F13: 95 | G13: =SUM(F13,取值!G11) -> 820 | H13: 51
B14: 3、柴油-10# | C14: 0 | D14: 0 | E14: =SUM(D14,取值!E13) -> 0 | F14: 0 | G14: =SUM(F14,取值!G13) -> 0 | H14: 0
B15: 4、 柴油-20# | C15: 0 | D15: 20 | E15: =SUM(D15,取值!E14) -> 50 | F15: 20 | G15: =SUM(F15,取值!G14) -> 50 | H15: 0
B16: 三、半成品 | C16: 期初库存（吨） | D16: 期初库存（吨） | E16: 期初库存（吨） | F16: 期末库存（吨) | G16: 期末库存（吨) | H16: 期末库存（吨)
B17: 1、液化气 | C17: 9509 | F17: 8980
B18: 2、精制油 | C18: 6925 | F18: 7410
B19: 3、粗硫磺 | C19: 0 | F19: 0
B20: 四、成品 | C20: 期初库存（吨） | D20: 期初库存（吨） | E20: 期初库存（吨） | F20: 期末库存（吨) | G20: 期末库存（吨) | H20: 期末库存（吨)
B21: 1、异辛烷 | C21: 4957 | F21: 5226
B22: 2、MTBE | C22: 6309 | F22: 4977
B23: 3、聚丙烯 | C23: 865 | F23: 1112
B24: 4、苯 | C24: 349 | F24: 386
B25: 5、精制硫磺 | C25: 26 | F25: 52
B26: 五、动力 | C26: 购进量(万千瓦时) | D26: 购进量(度) | E26: 工业消费(万千瓦时) | F26: 工业消费(度) | G26: 非工业消费(万千瓦时) | H26: 非工业消费(度) | I26: 价格(元/度) | J26: 当月金额 （千元） | K26: 累计金额 （千元）
B27: 五、动力 | C27: 本月 | D27: 累计 | E27: 本月 | F27: 累计 | G27: 本月 | H27: 累计 | I27: 价格(元/度) | J27: （千元） | K27: （千元）
B28: 电 | C28: 5435 | D28: =F28+H28 -> 62192.1 | E28: 5290.3 | F28: =SUM(取值!F29:F66)/10000+Sheet1!E28 -> 60473.35 | G28: 144.7 | H28: =_xlfn.IFERROR(SUM(取值!H28,Sheet1!G28),"") -> 1718.75 | I28: 0.57 | J28: 30999.94 | K28: =SUM(J28,取值!K28) -> 355928.44
B29: 单位领导：温铜川 | D29: 审核人：高景龙 | F29: 填报人：张艳妮 | I29: 报出日期： | J29: 2026-01-01

Sheet 取值
B2: 指标名称 | C2: 期初库存 （吨） | D2: 购进量 (吨) | E2: 购进量(吨) | F2: 消费量 (吨) | G2: 消费量(吨) | H2: 期末库存 （吨） | I2: 价格 (元/吨)（元/Nm3） | J2: 当月金额 （千元） | K2: 累计金额 （千元）
B3: 一、原材料 | D3: 本月 | E3: 累计 | F3: 本月 | G3: 累计
B4: 甲 醇
B5: 其中：石化厂 | C5: 2128 | D5: 2577.28 | E5: 24089.68 | F5: 2102 | G5: 24441 | H5: 2603
B6: 轻烃 | C6: 1855 | D6: 8695.48 | E6: 63107.78 | F6: 8093 | G6: 63922 | H6: 2414
B7: 二、燃料 | I7: 530.97
B8: 1、原 煤
B9: 其中：石化厂 | C9: 375 | D9: 19244 | E9: 162814 | F9: 18900 | G9: 166373 | K9: 98063.834
B10: 轻烃 | C10: 2740 | D10: 21317 | E10: 212744 | F10: 20996 | G10: 212996 | K10: 127084.82
B11: 2、 柴油0# | C11: 51 | D11: 95 | E11: 737 | F11: 95 | G11: 725
B13: 3、柴油-10# | C13: 0 | D13: 0 | E13: 0 | F13: 0 | G13: 0
B14: 4、 柴油-20# | C14: 0 | D14: 20 | E14: 30 | F14: 20 | G14: 30
B15: 三、半成品 | C15: 期初库存（吨） | D15: 期初库存（吨） | E15: 期初库存（吨） | F15: 期末库存（吨) | G15: 期末库存（吨) | H15: 期末库存（吨)
B16: 1、液化气 | C16: 10793 | F16: 8835
B17: 2、精制油 | C17: 6925 | F17: 7410 | L17: 3、聚丙烯 | M17: 3、聚丙烯 | N17: 1、液化气 | O17: 1、液化气
B18: 3、粗硫磺 | C18: 0 | F18: 0 | L18: 865 | M18: 1112 | N18: 2311 | O18: 721
B19: 四、成品 | C19: 期初库存（吨） | D19: 期初库存（吨） | E19: 期初库存（吨） | F19: 期末库存（吨) | G19: 期末库存（吨) | H19: 期末库存（吨) | L19: 0 | M19: 0 | N19: 766 | O19: 2336
B20: 1、异辛烷 | C20: 4957 | F20: 5226 | L20: 0 | M20: 0 | N20: 864 | O20: 894
B21: 2、MTBE | C21: 2689 | F21: 2514 | L21: 0 | M21: 0 | N21: 506 | O21: 1034
C22: 3620 | F22: 2463 | L22: 0 | M22: 0 | N22: 1048 | O22: 1130
B23: 3、聚丙烯 | L23: 0 | M23: 0 | N23: 593 | O23: 556
B24: 4、苯 | C24: 349 | F24: 386 | L24: 0 | M24: 0 | N24: 467 | O24: 332
B25: 5、精制硫磺 | C25: 26 | F25: 52 | L25: 0 | M25: 0 | N25: 2954 | O25: 1977
B26: 五、动力 | C26: 购进量(万千瓦时) | D26: 购进量(度) | E26: 工业消费(万千瓦时) | F26: 工业消费(度) | G26: 非工业消费(万千瓦时) | H26: 非工业消费(度) | I26: 价格(元/度) | J26: 当月金额 （千元） | K26: 累计金额 （千元）
B27: 五、动力 | C27: 本月 | D27: 累计 | E27: 本月 | F27: 累计 | G27: 本月 | H27: 累计 | I27: 价格(元/度) | J27: （千元） | K27: （千元）
B28: 电 | C28: 54350000 | D28: 567571000 | H28: 1574.05 | I28: 0.57 | K28: 324928.5
E29: 2086100 | F29: 52896200
E30: 3511200 | F30: 38537700
E31: 185900 | F31: 2450400
E32: 3108500 | F32: 13495700
E33: 2431000 | F33: 67479900
E34: 268500 | F34: 244100
E35: 2685000 | F35: 10189200
E36: 516400 | F36: 29883800
E37: 0 | F37: 15053300
E38: 492600 | F38: 1460100
E39: 20000
E40: 20000 | F40: 540200
E41: 5060300 | F41: 706400
E42: 3614500 | F42: 3435500
...
