Workbook

Sheet 榆林炼油厂油品动态明细表
B2: 榆林炼油厂油品动态明细表
B3: 填报部门：生产计划部 | H3: =Sheet2!B54&Sheet2!C54&Sheet2!D54 -> 报表生成时间：2026-01-06
B4: 油品 | C4: 位号 | D4: 油尺 | E4: 油量 | F4: 空量 | G4: 容积,m3 | H4: 安高,m | I4: 油品 | J4: 位号 | K4: 油尺 | L4: 油量 | M4: 空量 | N4: 容积,m3 | O4: 安高,m | P4: 油品 | Q4: 位号 | R4: 油尺 | S4: 油量 | T4: 空量 | U4: 容积,m3 | V4: 安高,m
B5: 原油 | C5: 115 | D5: 7.026 | E5: 7306.629 | F5: =_xlfn.IFERROR(Sheet2!G5-E5,"") -> 6733.371 | G5: 20000 | H5: 13.7 | I5: 厂区汽油 | J5: 301 | K5: 8.526 | L5: 2216.854 | M5: =_xlfn.IFERROR(Sheet2!O4-L5,"") -> 1163.146 | N5: 5000 | O5: 12.9 | P5: 1#渣油 | Q5: 403 | R5: 8.826 | S5: 4765.805 | T5: =_xlfn.IFERROR(Sheet2!W4-S5,"") -> 2254.195 | U5: 10000 | V5: 13.7
C6: 116 | D6: 6.174 | E6: 6421.297 | F6: =_xlfn.IFERROR(Sheet2!G6-E6,"") -> 7618.703 | G6: 20000 | H6: 13.7 | J6: 303 | K6: 11.977 | L6: 3113.968 | M6: =_xlfn.IFERROR(Sheet2!O5-L6,"") -> 266.032 | N6: 5000 | O6: 12.9 | Q6: 404 | R6: 9.195 | S6: 4965.524 | T6: =_xlfn.IFERROR(Sheet2!W5-S6,"") -> 2054.476 | U6: 10000 | V6: 13.7
C7: 合计 | E7: =SUM(E5:E6) -> 13727.926 | F7: =SUM(F5:F6) -> 14352.074 | J7: 307 | K7: 12.897 | L7: 6706.669 | M7: =_xlfn.IFERROR(Sheet2!O6-L7,"") -> 105.331 | N7: 10000 | O7: 13.6 | Q7: 405 | R7: 11.65 | S7: 7164.925 | T7: =_xlfn.IFERROR(Sheet2!W6-S7,"") -> 1322.075 | U7: 10000 | V7: 15.2
B8: 含水 污油 | C8: 104 | D8: 13.29 | E8: 0 | F8: =_xlfn.IFERROR(Sheet2!G8-E8,"") -> 7155 | G8: 10000 | H8: 13.7 | J8: 308 | K8: 6.616 | L8: 3440.198 | M8: =_xlfn.IFERROR(Sheet2!O7-L8,"") -> 3371.802 | N8: 10000 | O8: 13.6 | Q8: 406 | R8: 8.574 | S8: 5272.861 | T8: =_xlfn.IFERROR(Sheet2!W7-S8,"") -> 3214.139 | U8: 10000 | V8: 15.2
C9: 105 | D9: 11.17 | E9: 0 | F9: =_xlfn.IFERROR(Sheet2!G9-E9,"") -> 3776 | G9: 5000 | H9: 12.2 | J9: 309 | K9: 12.69 | L9: 6598.884 | M9: =_xlfn.IFERROR(Sheet2!O8-L9,"") -> 213.116 | N9: 10000 | O9: 13.6 | Q9: 407 | R9: 7.403 | S9: 4552.724 | T9: =_xlfn.IFERROR(Sheet2!W8-S9,"") -> 3934.276 | U9: 10000 | V9: 15.2
C10: 106 | D10: 7.33 | E10: 0 | F10: =_xlfn.IFERROR(Sheet2!G10-E10,"") -> 3776 | G10: 5000 | H10: 12.2 | J10: 310 | K10: 2.49 | L10: 1294.644 | M10: =_xlfn.IFERROR(Sheet2!O9-L10,"") -> 5517.356 | N10: 10000 | O10: 13.6 | Q10: 408 | R10: 7.785 | S10: 4125.908 | T10: =_xlfn.IFERROR(Sheet2!W9-S10,"") -> 3188.092 | U10: 10000 | V10: 15.2
C11: 110 | D11: 9.157 | E11: 9523.488 | F11: =_xlfn.IFERROR(Sheet2!G11-E11,"") -> 4516.512 | G11: 20000 | H11: 14.3 | J11: 合计 | L11: =SUM(L5:L10) -> 23371.217 | M11: =SUM(M5:M10) -> 10636.783 | Q11: 合计 | S11: =SUM(S5:S9) -> 26721.839 | T11: =SUM(T5:T9) -> 12779.161
C12: 合计 | E12: =SUM(E8:E11) -> 9523.488 | F12: =SUM(F8:F11) -> 19223.512 | I12: 集运汽油 | J12: 301 | K12: 13.675 | L12: 16683.05 | M12: =_xlfn.IFERROR(Sheet2!O11-L12,"") -> 3080.95 | N12: 30000 | O12: 16.4 | P12: 2#渣油 | Q12: 401 | R12: 8.548 | S12: 2735.246 | T12: =_xlfn.IFERROR(Sheet2!W11-S12,"") -> 2192.754 | U12: 5000 | V12: 15.4
B13: 进口原油 | C13: 103 | D13: 12.16 | E13: 0 | F13: =_xlfn.IFERROR(Sheet2!G4-E13,"") -> 7155 | G13: 10000 | H13: 13.7 | J13: 302 | K13: 16.098 | L13: 19639.639 | M13: =_xlfn.IFERROR(Sheet2!O12-L13,"") -> 124.361 | N13: 30000 | O13: 16.4 | Q13: 402 | R13: 1.957 | S13: 626.285 | T13: =_xlfn.IFERROR(Sheet2!W12-S13,"") -> 4301.715 | U13: 5000 | V13: 15.4
C14: 109 | D14: 8.977 | E14: 9694.709 | F14: =_xlfn.IFERROR(Sheet2!G13-E14,"") -> 4345.291 | G14: 20000 | H14: 14.3 | J14: 303 | K14: 16.08 | L14: 19617.579 | M14: =_xlfn.IFERROR(Sheet2!O13-L14,"") -> 146.421 | N14: 30000 | O14: 16.4 | Q14: 411 | R14: 3.648 | S14: 1167.266 | T14: =_xlfn.IFERROR(Sheet2!W13-S14,"") -> 3760.734 | U14: 5000 | V14: 15.4
C15: 111 | D15: 9.814 | E15: 10598.972 | F15: =_xlfn.IFERROR(Sheet2!G14-E15,"") -> 3441.028 | G15: 20000 | H15: 14.3 | J15: 合计 | L15: =SUM(L12:L14) -> 55940.268 | M15: =SUM(M12:M14) -> 3351.732 | Q15: 412 | R15: 7.603 | S15: 380.129 | T15: =_xlfn.IFERROR(Sheet2!W14-S15,"") -> 29.871 | U15: 500 | V15: 9.7
C16: 112 | D16: 11.069 | E16: 11954.182 | F16: =_xlfn.IFERROR(Sheet2!G15-E16,"") -> 2085.818 | G16: 20000 | H16: 14.3 | I16: MTBE | J16: 302 | K16: 7.932 | L16: 2022.545 | M16: =_xlfn.IFERROR(Sheet2!O15-L16,"") -> 1190.455 | N16: 5000 | O16: 12.9 | Q16: 413 | R16: 1.343 | S16: 67.152 | T16: =_xlfn.IFERROR(Sheet2!W15-S16,"") -> 342.848 | U16: 500 | V16: 9.7
C17: 113 | D17: 11.068 | E17: 11953.391 | F17: =_xlfn.IFERROR(Sheet2!G16-E17,"") -> 2086.609 | G17: 20000 | H17: 13.7 | I17: 烷基化油 | J17: 304 | K17: 10.157 | L17: 2488.392 | M17: =_xlfn.IFERROR(Sheet2!O16-L17,"") -> 598.608 | N17: 5000 | O17: 12.9 | Q17: 合计 | S17: =SUM(S12:S16) -> 4976.078 | T17: =SUM(T12:T16) -> 10627.922
C18: 114 | D18: 7.148 | E18: 7433.927 | F18: =_xlfn.IFERROR(Sheet2!G17-E18,"") -> 6606.073 | G18: 20000 | H18: 13.7 | I18: 裂解石脑油 | J18: 311 | K18: 4.428 | L18: 2258.221 | M18: =_xlfn.IFERROR(Sheet2!O17-L18,"") -> 4473.779 | N18: 10000 | O18: 13.9 | P18: 饱 和 液化气 | Q18: 501 | R18: 0 | S18: 0 | T18: =_xlfn.IFERROR(Sheet2!W17-S18,"") -> 440 | U18: 1000 | V18: 9.2
C19: 合计 | E19: =SUM(E13:E18) -> 51635.181 | F19: =SUM(F13:F18) -> 25719.819 | J19: 312 | K19: 4.438 | L19: 2263.346 | M19: =_xlfn.IFERROR(Sheet2!O18-L19,"") -> 4468.654 | N19: 10000 | O19: 13.9 | Q19: 502 | R19: 0 | S19: 0 | T19: =_xlfn.IFERROR(Sheet2!W18-S19,"") -> 440 | U19: 1000 | V19: 9.2
B20: 二线油 | C20: 201 | D20: 7.568 | E20: 2724.375 | F20: =_xlfn.IFERROR(Sheet2!G19-E20,"") -> 83.625 | G20: 5000 | H20: 8.2 | J20: 合计 | L20: =SUM(L18:L19) -> 4521.567 | M20: =SUM(M18:M19) -> 8942.433 | Q20: 503 | R20: 0 | S20: 0 | T20: =_xlfn.IFERROR(Sheet2!W19-S20,"") -> 440 | U20: 1000 | V20: 9.2
C21: 202 | D21: 7.82 | E21: 2815.218 | F21: =_xlfn.IFERROR(Sheet2!G20-E21,"") -> -7.218 | G21: 5000 | H21: 8.2 | I21: 催化汽油 | J21: 313 | K21: 7.489 | L21: 3145.425 | M21: =_xlfn.IFERROR(Sheet2!O20-L21,"") -> 2398.575 | N21: 10000 | O21: 13.9 | Q21: 504 | R21: 0 | S21: 0 | T21: =_xlfn.IFERROR(Sheet2!W20-S21,"") -> 440 | U21: 1000 | V21: 9.2
C22: 合计 | E22: =SUM(E20:E21) -> 5539.593 | F22: =SUM(F20:F21) -> 76.407 | J22: 314 | K22: 5.819 | L22: 2443.878 | M22: =_xlfn.IFERROR(Sheet2!O21-L22,"") -> 3100.122 | N22: 10000 | O22: 13.9 | Q22: 511 | R22: 2.579 | S22: 63.717 | T22: =_xlfn.IFERROR(Sheet2!W21-S22,"") -> 376.283 | U22: 1000 | V22: 9.2
B23: 厂区柴油 | C23: 203 | D23: 12.259 | E23: 7110.038 | F23: =_xlfn.IFERROR(Sheet2!G22-E23,"") -> 719.962 | G23: 10000 | H23: 13.5 | J23: 合计 | L23: =SUM(L21:L22) -> 5589.303 | M23: =SUM(M21:M22) -> 5498.697 | Q23: 512 | R23: 5.533 | S23: 212.91 | T23: =_xlfn.IFERROR(Sheet2!W22-S23,"") -> 227.09 | U23: 1000 | V23: 9.2
C24: 204 | D24: 6.141 | E24: 3561.892 | F24: =_xlfn.IFERROR(Sheet2!G23-E24,"") -> 4268.108 | G24: 10000 | H24: 13.5 | I24: 重整汽油 | J24: 315 | K24: 5.739 | L24: 1377.403 | M24: =_xlfn.IFERROR(Sheet2!O23-L24,"") -> 1742.597 | N24: 5000 | O24: 13.9 | Q24: 合计 | S24: =SUM(S18:S23) -> 276.627 | T24: =SUM(T18:T23) -> 2363.373
C25: 205 | D25: 0 | E25: 0 | F25: =_xlfn.IFERROR(Sheet2!G24-E25,"") -> 7830 | G25: 10000 | H25: 13.5 | J25: 316 | K25: 4.73 | L25: 1135.095 | M25: =_xlfn.IFERROR(Sheet2!O24-L25,"") -> 1984.905 | N25: 5000 | O25: 13.9 | P25: 液化气 （饱和） | Q25: 513 | R25: 6.586 | S25: 303.707 | T25: =_xlfn.IFERROR(Sheet2!W24-S25,"") -> 136.293 | U25: 1000 | V25: 9.2
C26: 206 | D26: 5.153 | E26: 2988.616 | F26: =_xlfn.IFERROR(Sheet2!G25-E26,"") -> 4841.384 | G26: 10000 | H26: 13.5 | J26: 合计 | L26: =SUM(L24:L25) -> 2512.498 | M26: =SUM(M24:M25) -> 3727.502 | Q26: 514 | R26: 6.812 | S26: 319.222 | T26: =_xlfn.IFERROR(Sheet2!W25-S26,"") -> 120.778 | U26: 1000 | V26: 9.2
C27: 207 | D27: 2.447 | E27: 1223.5 | F27: =_xlfn.IFERROR(Sheet2!G26-E27,"") -> 5526.5 | G27: 10000 | H27: 13.9 | I27: 二甲苯 | J27: 317 | K27: 7.406 | L27: 2014.565 | M27: =_xlfn.IFERROR(Sheet2!O26-L27,"") -> 1657.435 | N27: 5000 | O27: 13.9 | Q27: 515 | R27: 2.434 | S27: 58.477 | T27: =_xlfn.IFERROR(Sheet2!W26-S27,"") -> 381.523 | U27: 1000 | V27: 9.2
C28: 合计 | E28: =SUM(E23:E27) -> 14884.046 | F28: =SUM(F23:F27) -> 23185.954 | J28: 318 | K28: 6.754 | L28: 1837.064 | M28: =_xlfn.IFERROR(Sheet2!O27-L28,"") -> 1834.936 | N28: 5000 | O28: 13.9 | Q28: 合计 | S28: =SUM(S25:S27)+S36 -> 739.097 | T28: =SUM(T25:T27)+T36 -> 1020.903
B29: 集运军柴 | C29: 201 | D29: .087 | E29: 116.997 | F29: =_xlfn.IFERROR(Sheet2!G28-E29,"") -> 21753.003 | G29: 30000 | H29: 16.4 | J29: 合计 | L29: =SUM(L27:L28) -> 3851.629 | M29: =SUM(M27:M28) -> 3492.371 | P29: 原料 液化气 | Q29: 505 | R29: 4.131 | S29: 215.001 | T29: =_xlfn.IFERROR(Sheet2!W28-S29,"") -> 680.999 | U29: 2000 | V29: 11.1
B30: 集运柴油 | C30: 202 | D30: 16.153 | E30: 21805.958 | F30: =_xlfn.IFERROR(Sheet2!G29-E30,"") -> 64.042 | G30: 30000 | H30: 16.4 | I30: 次品 | J30: 319 | K30: 3.121 | L30: 1092.189 | M30: =_xlfn.IFERROR(Sheet2!O29-L30,"") -> 1637.811 | N30: 5000 | O30: 8.2 | Q30: 506 | R30: 3.15 | S30: 136.216 | T30: =_xlfn.IFERROR(Sheet2!W29-S30,"") -> 759.784 | U30: 2000 | V30: 11.1
C31: 203 | D31: 10.819 | E31: 14605.383 | F31: =_xlfn.IFERROR(Sheet2!G30-E31,"") -> 7264.617 | G31: 30000 | H31: 16.4 | J31: 320 | K31: 2.877 | L31: 1006.807 | M31: =_xlfn.IFERROR(Sheet2!O30-L31,"") -> 1723.193 | N31: 5000 | O31: 8.2 | Q31: 507 | R31: 10.398 | S31: 852.378 | T31: =_xlfn.IFERROR(Sheet2!W30-S31,"") -> 43.622 | U31: 2000 | V31: 11.1
C32: 204 | D32: 16.122 | E32: 21764.349 | F32: =_xlfn.IFERROR(Sheet2!G31-E32,"") -> 105.651 | G32: 30000 | H32: 16.4 | J32: 合计 | L32: =SUM(L30:L31) -> 2098.996 | M32: =SUM(M30:M31) -> 3361.004 | Q32: 508 | R32: 0 | S32: 7.722 | T32: =_xlfn.IFERROR(Sheet2!W31-S32,"") -> 888.278 | U32: 2000 | V32: 11.1
C33: 合计 | E33: =SUM(E29:E32) -> 58292.687 | F33: =SUM(F29:F32) -> 29187.313 | I33: C6馏分油 | J33: 321 | K33: 12.929 | L33: 3232.199 | M33: =_xlfn.IFERROR(Sheet2!O32-L33,"") -> -32.199 | N33: 5000 | O33: 13.9 | Q33: 509 | R33: 0 | S33: 0.646 | T33: =_xlfn.IFERROR(Sheet2!W32-S33,"") -> 895.354 | U33: 2000 | V33: 11.1
B34: 航煤 | C34: 221 | D34: 8.827 | E34: 2427.362 | F34: =_xlfn.IFERROR(Sheet2!G33-E34,"") -> 1147.638 | G34: 5000 | H34: 13.5 | I34: 石脑油 （航煤罐区） | J34: 322 | K34: 2.509 | L34: 627.342 | M34: =_xlfn.IFERROR(Sheet2!O33-L34,"") -> 2572.658 | N34: 5000 | O34: 13.9 | Q34: 510 | R34: 0 | S34: 0.586 | T34: =_xlfn.IFERROR(Sheet2!W33-S34,"") -> 895.414 | U34: 2000 | V34: 11.1
C35: 222 | D35: 6.004 | E35: 1651.014 | F35: =_xlfn.IFERROR(Sheet2!G34-E35,"") -> 1923.986 | G35: 5000 | H35: 13.5 | J35: 323 | K35: 9.04 | L35: 2260.028 | M35: =_xlfn.IFERROR(Sheet2!O34-L35,"") -> 939.972 | N35: 5000 | O35: 13.9 | Q35: 合计 | S35: =SUM(S29:S34) -> 1212.549 | T35: =SUM(T29:T34) -> 4163.451
C36: 223 | D36: 12.911 | E36: 3550.447 | F36: =_xlfn.IFERROR(Sheet2!G35-E36,"") -> 24.553 | G36: 5000 | H36: 13.5 | J36: 合计 | L36: =SUM(L34:L35) -> 2887.37 | M36: =SUM(M34:M35) -> 3512.63 | P36: 液化气 （饱和） | Q36: 516 | R36: 2.414 | S36: 57.691 | T36: =_xlfn.IFERROR(Sheet2!W35-S36,"") -> 382.309 | U36: 1000 | V36: 9.2
C37: 合计 | E37: =SUM(E34:E36) -> 7628.823 | F37: =SUM(F34:F36) -> 3096.177 | I37: 石脑油 （油品罐区） | J37: 324 | K37: 12.593 | L37: 5289.06 | M37: =_xlfn.IFERROR(Sheet2!O36-L37,"") -> 380.94 | N37: 5000 | O37: 13.9 | P37: 原料 液化气 | Q37: 517 | R37: 2.877 | S37: 78.531 | T37: =_xlfn.IFERROR(Sheet2!W36-S37,"") -> 361.469 | U37: 1000 | V37: 9.2
B38: 加氢原料 | C38: 224 | D38: 13.399 | E38: 3617.825 | F38: =_xlfn.IFERROR(Sheet2!G37-E38,"") -> -53.825 | G38: 5000 | H38: 13.9 | J38: 325 | K38: 13.178 | L38: 5534.76 | M38: =_xlfn.IFERROR(Sheet2!O37-L38,"") -> 135.24 | N38: 10000 | O38: 13.9 | Q38: 518 | R38: 2.535 | S38: 62.88 | T38: =_xlfn.IFERROR(Sheet2!W37-S38,"") -> 377.12 | U38: 1000 | V38: 9.2
C39: 225 | D39: 11.711 | E39: 3162.047 | F39: =_xlfn.IFERROR(Sheet2!G38-E39,"") -> 401.953 | G39: 5000 | H39: 13.9 | J39: 327 | K39: 11.522 | L39: 4839.24 | M39: =_xlfn.IFERROR(Sheet2!O38-L39,"") -> 830.76 | N39: 10000 | O39: 13.9 | Q39: 合计 | S39: =SUM(S37:S38) -> 141.411 | T39: =SUM(T37:T38) -> 738.589
C40: 226 | D40: 4.766 | E40: 1286.746 | F40: =_xlfn.IFERROR(Sheet2!G39-E40,"") -> 2277.254 | G40: 5000 | H40: 13.9 | J40: 合计 | L40: =SUM(L37:L39) -> 15663.06 | M40: =SUM(M37:M39) -> 1346.94 | P40: 液氨 | Q40: 701 | R40: 0 | T40: =500-S40 -> 500 | U40: 10000 | V40: 3.9
C41: 227 | D41: 13.417 | E41: 3622.477 | F41: =_xlfn.IFERROR(Sheet2!G40-E41,"") -> -58.477 | G41: 5000 | H41: 13.9 | I41: 精制油 | J41: 326 | K41: 13.191 | L41: 5804.04 | M41: =_xlfn.IFERROR(Sheet2!O40-L41,"") -> 135.96 | N41: 10000 | O41: 13.9
...

Sheet Sheet2
B1: 榆林炼油厂油品动态明细表
B2: 填报部门：生产计划部
B3: 油品 | C3: 位号 | D3: 油尺 | E3: 油量 | F3: 空量 | G3: 总管廊 | H3: 容积,m3 | I3: 安高,m | J3: 油品 | K3: 位号 | L3: 油尺 | M3: 油量 | N3: 空量 | O3: 总管量 | P3: 容积,m3 | Q3: 安高,m | R3: 油品 | S3: 位号 | T3: 油尺 | U3: 油量 | V3: 空量 | X3: 容积,m3 | Y3: 安高,m
B4: 原油 | C4: 103 | D4: 12.16 | E4: 0 | F4: =IF(_xlfn.IFERROR(G4-E4,"")>0,_xlfn.IFERROR(G4-E4,""),0) -> 7155 | G4: 7155 | J4: 厂区汽油 | K4: 301 | L4: 8.526 | M4: 2216.854 | N4: =IF(_xlfn.IFERROR(O4-M4,"")>0,_xlfn.IFERROR(O4-M4,""),0) -> 1163.146 | O4: 3380 | R4: 1#渣油 | S4: 403 | T4: 8.826 | U4: 4765.805 | V4: =IF(_xlfn.IFERROR(W4-U4,"")>0,_xlfn.IFERROR(W4-U4,""),0) -> 2254.195 | W4: 7020
C5: 115 | D5: 7.026 | E5: 7306.629 | F5: =IF(_xlfn.IFERROR(G5-E5,"")>0,_xlfn.IFERROR(G5-E5,""),0) -> 6733.371 | G5: 14040 | K5: 303 | L5: 11.977 | M5: 3113.968 | N5: =IF(_xlfn.IFERROR(O5-M5,"")>0,_xlfn.IFERROR(O5-M5,""),0) -> 266.032 | O5: 3380 | S5: 404 | T5: 9.195 | U5: 4965.524 | V5: =IF(_xlfn.IFERROR(W5-U5,"")>0,_xlfn.IFERROR(W5-U5,""),0) -> 2054.476 | W5: 7020
C6: 116 | D6: 6.174 | E6: 6421.297 | F6: =IF(_xlfn.IFERROR(G6-E6,"")>0,_xlfn.IFERROR(G6-E6,""),0) -> 7618.703 | G6: 14040 | K6: 307 | L6: 12.897 | M6: 6706.669 | N6: =IF(_xlfn.IFERROR(O6-M6,"")>0,_xlfn.IFERROR(O6-M6,""),0) -> 105.331 | O6: 6812 | S6: 405 | T6: 11.65 | U6: 7164.925 | V6: =IF(_xlfn.IFERROR(W6-U6,"")>0,_xlfn.IFERROR(W6-U6,""),0) -> 1322.075 | W6: 8487
C7: 合计 | E7: =SUM(E4:E6) -> 13727.926 | F7: =SUM(F4:F6) -> 21507.074 | K7: 308 | L7: 6.616 | M7: 3440.198 | N7: =IF(_xlfn.IFERROR(O7-M7,"")>0,_xlfn.IFERROR(O7-M7,""),0) -> 3371.802 | O7: 6812 | S7: 406 | T7: 8.574 | U7: 5272.861 | V7: =IF(_xlfn.IFERROR(W7-U7,"")>0,_xlfn.IFERROR(W7-U7,""),0) -> 3214.139 | W7: 8487
B8: 含水 污油 | C8: 104 | D8: 13.29 | E8: 0 | F8: =IF(_xlfn.IFERROR(G8-E8,"")>0,_xlfn.IFERROR(G8-E8,""),0) -> 7155 | G8: 7155 | K8: 309 | L8: 12.69 | M8: 6598.884 | N8: =IF(_xlfn.IFERROR(O8-M8,"")>0,_xlfn.IFERROR(O8-M8,""),0) -> 213.116 | O8: 6812 | S8: 407 | T8: 7.403 | U8: 4552.724 | V8: =IF(_xlfn.IFERROR(W8-U8,"")>0,_xlfn.IFERROR(W8-U8,""),0) -> 3934.276 | W8: 8487
C9: 105 | D9: 11.17 | E9: 0 | F9: =IF(_xlfn.IFERROR(G9-E9,"")>0,_xlfn.IFERROR(G9-E9,""),0) -> 3776 | G9: 3776 | K9: 310 | L9: 2.49 | M9: 1294.644 | N9: =IF(_xlfn.IFERROR(O9-M9,"")>0,_xlfn.IFERROR(O9-M9,""),0) -> 5517.356 | O9: 6812 | S9: 408 | T9: 7.785 | U9: 4125.908 | V9: =IF(_xlfn.IFERROR(W9-U9,"")>0,_xlfn.IFERROR(W9-U9,""),0) -> 3188.092 | W9: 7314
C10: 106 | D10: 7.33 | E10: 0 | F10: =IF(_xlfn.IFERROR(G10-E10,"")>0,_xlfn.IFERROR(G10-E10,""),0) -> 3776 | G10: 3776 | K10: 合计 | M10: =SUM(M4:M9) -> 23371.217 | N10: =SUM(N4:N9) -> 10636.783 | S10: 合计 | U10: =SUM(U4:U9) -> 30847.747 | V10: =SUM(V4:V9) -> 15967.253
C11: 110 | D11: 9.157 | E11: 9523.488 | F11: =IF(_xlfn.IFERROR(G11-E11,"")>0,_xlfn.IFERROR(G11-E11,""),0) -> 4516.512 | G11: 14040 | J11: 集运汽油 | K11: 301 | L11: 13.675 | M11: 16683.05 | N11: =IF(_xlfn.IFERROR(O11-M11,"")>0,_xlfn.IFERROR(O11-M11,""),0) -> 3080.95 | O11: 19764 | R11: 2#渣油 | S11: 401 | T11: 8.548 | U11: 2735.246 | V11: =IF(_xlfn.IFERROR(W11-U11,"")>0,_xlfn.IFERROR(W11-U11,""),0) -> 2192.754 | W11: 4928
C12: 合计 | E12: =SUM(E8:E11) -> 9523.488 | F12: =SUM(F8:F11) -> 19223.512 | K12: 302 | L12: 16.098 | M12: 19639.639 | N12: =IF(_xlfn.IFERROR(O12-M12,"")>0,_xlfn.IFERROR(O12-M12,""),0) -> 124.361 | O12: 19764 | S12: 402 | T12: 1.957 | U12: 626.285 | V12: =IF(_xlfn.IFERROR(W12-U12,"")>0,_xlfn.IFERROR(W12-U12,""),0) -> 4301.715 | W12: 4928
B13: 进口原油 | C13: 109 | D13: 8.977 | E13: 9694.709 | F13: =IF(_xlfn.IFERROR(G13-E13,"")>0,_xlfn.IFERROR(G13-E13,""),0) -> 4345.291 | G13: 14040 | K13: 303 | L13: 16.08 | M13: 19617.579 | N13: =IF(_xlfn.IFERROR(O13-M13,"")>0,_xlfn.IFERROR(O13-M13,""),0) -> 146.421 | O13: 19764 | S13: 411 | T13: 3.648 | U13: 1167.266 | V13: =IF(_xlfn.IFERROR(W13-U13,"")>0,_xlfn.IFERROR(W13-U13,""),0) -> 3760.734 | W13: 4928
C14: 111 | D14: 9.814 | E14: 10598.972 | F14: =IF(_xlfn.IFERROR(G14-E14,"")>0,_xlfn.IFERROR(G14-E14,""),0) -> 3441.028 | G14: 14040 | K14: 合计 | M14: =SUM(M11:M13) -> 55940.268 | N14: =SUM(N11:N13) -> 3351.732 | S14: 412 | T14: 7.603 | U14: 380.129 | V14: =IF(_xlfn.IFERROR(W14-U14,"")>0,_xlfn.IFERROR(W14-U14,""),0) -> 29.871 | W14: 410
C15: 112 | D15: 11.069 | E15: 11954.182 | F15: =IF(_xlfn.IFERROR(G15-E15,"")>0,_xlfn.IFERROR(G15-E15,""),0) -> 2085.818 | G15: 14040 | J15: MTBE | K15: 302 | L15: 7.932 | M15: 2022.545 | N15: =IF(_xlfn.IFERROR(O15-M15,"")>0,_xlfn.IFERROR(O15-M15,""),0) -> 1190.455 | O15: 3213 | S15: 413 | T15: 1.343 | U15: 67.152 | V15: =IF(_xlfn.IFERROR(W15-U15,"")>0,_xlfn.IFERROR(W15-U15,""),0) -> 342.848 | W15: 410
C16: 113 | D16: 11.068 | E16: 11953.391 | F16: =IF(_xlfn.IFERROR(G16-E16,"")>0,_xlfn.IFERROR(G16-E16,""),0) -> 2086.609 | G16: 14040 | J16: 烷基化油 | K16: 304 | L16: 10.157 | M16: 2488.392 | N16: =IF(_xlfn.IFERROR(O16-M16,"")>0,_xlfn.IFERROR(O16-M16,""),0) -> 598.608 | O16: 3087 | S16: 合计 | U16: =SUM(U11:U15) -> 4976.078 | V16: =SUM(V11:V15) -> 10627.922
C17: 114 | D17: 7.148 | E17: 7433.927 | F17: =IF(_xlfn.IFERROR(G17-E17,"")>0,_xlfn.IFERROR(G17-E17,""),0) -> 6606.073 | G17: 14040 | J17: 裂解石脑油 | K17: 311 | L17: 4.428 | M17: 2258.221 | N17: =IF(_xlfn.IFERROR(O17-M17,"")>0,_xlfn.IFERROR(O17-M17,""),0) -> 4473.779 | O17: 6732 | R17: 饱 和 液化气 | S17: 501 | T17: 0 | U17: 0 | V17: =IF(_xlfn.IFERROR(W17-U17,"")>0,_xlfn.IFERROR(W17-U17,""),0) -> 440 | W17: 440
C18: 合计 | E18: =SUM(E13:E17) -> 51635.181 | F18: =SUM(F13:F17) -> 18564.819 | K18: 312 | L18: 4.438 | M18: 2263.346 | N18: =IF(_xlfn.IFERROR(O18-M18,"")>0,_xlfn.IFERROR(O18-M18,""),0) -> 4468.654 | O18: 6732 | S18: 502 | T18: 0 | U18: 0 | V18: =IF(_xlfn.IFERROR(W18-U18,"")>0,_xlfn.IFERROR(W18-U18,""),0) -> 440 | W18: 440
B19: 二线油 | C19: 201 | D19: 7.568 | E19: 2724.375 | F19: =IF(_xlfn.IFERROR(G19-E19,"")>0,_xlfn.IFERROR(G19-E19,""),0) -> 83.625 | G19: 2808 | K19: 合计 | M19: =SUM(M17:M18) -> 4521.567 | N19: =SUM(N17:N18) -> 8942.433 | S19: 503 | T19: 0 | U19: 0 | V19: =IF(_xlfn.IFERROR(W19-U19,"")>0,_xlfn.IFERROR(W19-U19,""),0) -> 440 | W19: 440
C20: 202 | D20: 7.82 | E20: 2815.218 | F20: =IF(_xlfn.IFERROR(G20-E20,"")>0,_xlfn.IFERROR(G20-E20,""),0) -> 0 | G20: 2808 | J20: 催化汽油 | K20: 313 | L20: 7.489 | M20: 3145.425 | N20: =IF(_xlfn.IFERROR(O20-M20,"")>0,_xlfn.IFERROR(O20-M20,""),0) -> 2398.575 | O20: 5544 | S20: 504 | T20: 0 | U20: 0 | V20: =IF(_xlfn.IFERROR(W20-U20,"")>0,_xlfn.IFERROR(W20-U20,""),0) -> 440 | W20: 440
C21: 合计 | E21: =SUM(E19:E20) -> 5539.593 | F21: =SUM(F19:F20) -> 83.625 | K21: 314 | L21: 5.819 | M21: 2443.878 | N21: =IF(_xlfn.IFERROR(O21-M21,"")>0,_xlfn.IFERROR(O21-M21,""),0) -> 3100.122 | O21: 5544 | S21: 511 | T21: 2.579 | U21: 63.717 | V21: =IF(_xlfn.IFERROR(W21-U21,"")>0,_xlfn.IFERROR(W21-U21,""),0) -> 376.283 | W21: 440
B22: 厂区柴油 | C22: 203 | D22: 12.259 | E22: 7110.038 | F22: =IF(_xlfn.IFERROR(G22-E22,"")>0,_xlfn.IFERROR(G22-E22,""),0) -> 719.962 | G22: 7830 | K22: 合计 | M22: =SUM(M20:M21) -> 5589.303 | N22: =SUM(N20:N21) -> 5498.697 | S22: 512 | T22: 5.533 | U22: 212.91 | V22: =IF(_xlfn.IFERROR(W22-U22,"")>0,_xlfn.IFERROR(W22-U22,""),0) -> 227.09 | W22: 440
C23: 204 | D23: 6.141 | E23: 3561.892 | F23: =IF(_xlfn.IFERROR(G23-E23,"")>0,_xlfn.IFERROR(G23-E23,""),0) -> 4268.108 | G23: 7830 | J23: 重整汽油 | K23: 315 | L23: 5.739 | M23: 1377.403 | N23: =IF(_xlfn.IFERROR(O23-M23,"")>0,_xlfn.IFERROR(O23-M23,""),0) -> 1742.597 | O23: 3120 | S23: 合计 | U23: =SUM(U17:U22) -> 276.627 | V23: =SUM(V17:V22) -> 2363.373
C24: 205 | D24: 0 | E24: 0 | F24: =IF(_xlfn.IFERROR(G24-E24,"")>0,_xlfn.IFERROR(G24-E24,""),0) -> 7830 | G24: 7830 | K24: 316 | L24: 4.73 | M24: 1135.095 | N24: =IF(_xlfn.IFERROR(O24-M24,"")>0,_xlfn.IFERROR(O24-M24,""),0) -> 1984.905 | O24: 3120 | R24: 液化气（饱和） | S24: 513 | T24: 6.586 | U24: 303.707 | V24: =IF(_xlfn.IFERROR(W24-U24,"")>0,_xlfn.IFERROR(W24-U24,""),0) -> 136.293 | W24: 440
C25: 206 | D25: 5.153 | E25: 2988.616 | F25: =IF(_xlfn.IFERROR(G25-E25,"")>0,_xlfn.IFERROR(G25-E25,""),0) -> 4841.384 | G25: 7830 | K25: 合计 | M25: =SUM(M23:M24) -> 2512.498 | N25: =SUM(N23:N24) -> 3727.502 | S25: 514 | T25: 6.812 | U25: 319.222 | V25: =IF(_xlfn.IFERROR(W25-U25,"")>0,_xlfn.IFERROR(W25-U25,""),0) -> 120.778 | W25: 440
C26: 207 | D26: 2.447 | E26: 1223.5 | F26: =IF(_xlfn.IFERROR(G26-E26,"")>0,_xlfn.IFERROR(G26-E26,""),0) -> 5526.5 | G26: 6750 | J26: 二甲苯 | K26: 317 | L26: 7.406 | M26: 2014.565 | N26: =IF(_xlfn.IFERROR(O26-M26,"")>0,_xlfn.IFERROR(O26-M26,""),0) -> 1657.435 | O26: 3672 | S26: 515 | T26: 2.434 | U26: 58.477 | V26: =IF(_xlfn.IFERROR(W26-U26,"")>0,_xlfn.IFERROR(W26-U26,""),0) -> 381.523 | W26: 440
C27: 合计 | E27: =SUM(E22:E26) -> 14884.046 | F27: =SUM(F22:F26) -> 23185.954 | K27: 318 | L27: 6.754 | M27: 1837.064 | N27: =IF(_xlfn.IFERROR(O27-M27,"")>0,_xlfn.IFERROR(O27-M27,""),0) -> 1834.936 | O27: 3672 | S27: 合计 | U27: =SUM(U24:U26)+U35 -> 739.097 | V27: =SUM(V24:V26)+V35 -> 1020.903
B28: 集运军柴 | C28: 201 | D28: .087 | E28: 116.997 | F28: =IF(_xlfn.IFERROR(G28-E28,"")>0,_xlfn.IFERROR(G28-E28,""),0) -> 21753.003 | G28: 21870 | K28: 合计 | M28: =SUM(M26:M27) -> 3851.629 | N28: =SUM(N26:N27) -> 3492.371 | R28: 原料 液化气 | S28: 505 | T28: 4.131 | U28: 215.001 | V28: =IF(_xlfn.IFERROR(W28-U28,"")>0,_xlfn.IFERROR(W28-U28,""),0) -> 680.999 | W28: 896
B29: 集运柴油 | C29: 202 | D29: 16.153 | E29: 21805.958 | F29: =IF(_xlfn.IFERROR(G29-E29,"")>0,_xlfn.IFERROR(G29-E29,""),0) -> 64.042 | G29: 21870 | J29: 次品 | K29: 319 | L29: 3.121 | M29: 1092.189 | N29: =IF(_xlfn.IFERROR(O29-M29,"")>0,_xlfn.IFERROR(O29-M29,""),0) -> 1637.811 | O29: 2730 | S29: 506 | T29: 3.15 | U29: 136.216 | V29: =IF(_xlfn.IFERROR(W29-U29,"")>0,_xlfn.IFERROR(W29-U29,""),0) -> 759.784 | W29: 896
C30: 203 | D30: 10.819 | E30: 14605.383 | F30: =IF(_xlfn.IFERROR(G30-E30,"")>0,_xlfn.IFERROR(G30-E30,""),0) -> 7264.617 | G30: 21870 | K30: 320 | L30: 2.877 | M30: 1006.807 | N30: =IF(_xlfn.IFERROR(O30-M30,"")>0,_xlfn.IFERROR(O30-M30,""),0) -> 1723.193 | O30: 2730 | S30: 507 | T30: 10.398 | U30: 852.378 | V30: =IF(_xlfn.IFERROR(W30-U30,"")>0,_xlfn.IFERROR(W30-U30,""),0) -> 43.622 | W30: 896
C31: 204 | D31: 16.122 | E31: 21764.349 | F31: =IF(_xlfn.IFERROR(G31-E31,"")>0,_xlfn.IFERROR(G31-E31,""),0) -> 105.651 | G31: 21870 | K31: 合计 | M31: =SUM(M29:M30) -> 2098.996 | N31: =SUM(N29:N30) -> 3361.004 | S31: 508 | T31: 0 | U31: 7.722 | V31: =IF(_xlfn.IFERROR(W31-U31,"")>0,_xlfn.IFERROR(W31-U31,""),0) -> 888.278 | W31: 896
C32: 合计 | E32: =SUM(E28:E31) -> 58292.687 | F32: =SUM(F28:F31) -> 29187.313 | J32: C6馏分油 | K32: 321 | L32: 12.929 | M32: 3232.199 | N32: =IF(_xlfn.IFERROR(O32-M32,"")>0,_xlfn.IFERROR(O32-M32,""),0) -> 0 | O32: 3200 | S32: 509 | T32: 0 | U32: 0.646 | V32: =IF(_xlfn.IFERROR(W32-U32,"")>0,_xlfn.IFERROR(W32-U32,""),0) -> 895.354 | W32: 896
B33: 航煤 | C33: 221 | D33: 8.827 | E33: 2427.362 | F33: =IF(_xlfn.IFERROR(G33-E33,"")>0,_xlfn.IFERROR(G33-E33,""),0) -> 1147.638 | G33: 3575 | J33: 石脑油 （航煤罐区） | K33: 322 | L33: 2.509 | M33: 627.342 | N33: =IF(_xlfn.IFERROR(O33-M33,"")>0,_xlfn.IFERROR(O33-M33,""),0) -> 2572.658 | O33: 3200 | S33: 510 | T33: 0 | U33: 0.586 | V33: =IF(_xlfn.IFERROR(W33-U33,"")>0,_xlfn.IFERROR(W33-U33,""),0) -> 895.414 | W33: 896
C34: 222 | D34: 6.004 | E34: 1651.014 | F34: =IF(_xlfn.IFERROR(G34-E34,"")>0,_xlfn.IFERROR(G34-E34,""),0) -> 1923.986 | G34: 3575 | K34: 323 | L34: 9.04 | M34: 2260.028 | N34: =IF(_xlfn.IFERROR(O34-M34,"")>0,_xlfn.IFERROR(O34-M34,""),0) -> 939.972 | O34: 3200 | S34: 合计 | U34: =SUM(U28:U33) -> 1212.549 | V34: =SUM(V28:V33) -> 4163.451
C35: 223 | D35: 12.911 | E35: 3550.447 | F35: =IF(_xlfn.IFERROR(G35-E35,"")>0,_xlfn.IFERROR(G35-E35,""),0) -> 24.553 | G35: 3575 | K35: 合计 | M35: =SUM(M33:M34) -> 2887.37 | N35: =SUM(N33:N34) -> 3512.63 | R35: 液化气（饱和） | S35: 516 | T35: 2.414 | U35: 57.691 | V35: =IF(_xlfn.IFERROR(W35-U35,"")>0,_xlfn.IFERROR(W35-U35,""),0) -> 382.309 | W35: 440
C36: 合计 | E36: =SUM(E33:E35) -> 7628.823 | F36: =SUM(F33:F35) -> 3096.177 | J36: 石脑油 （油品罐区） | K36: 324 | L36: 12.593 | M36: 5289.06 | N36: =IF(_xlfn.IFERROR(O36-M36,"")>0,_xlfn.IFERROR(O36-M36,""),0) -> 380.94 | O36: 5670 | R36: 原料液化气 | S36: 517 | T36: 2.877 | U36: 78.531 | V36: =IF(_xlfn.IFERROR(W36-U36,"")>0,_xlfn.IFERROR(W36-U36,""),0) -> 361.469 | W36: 440
B37: 加氢原料 | C37: 224 | D37: 13.399 | E37: 3617.825 | F37: =IF(_xlfn.IFERROR(G37-E37,"")>0,_xlfn.IFERROR(G37-E37,""),0) -> 0 | G37: 3564 | K37: 325 | L37: 13.178 | M37: 5534.76 | N37: =IF(_xlfn.IFERROR(O37-M37,"")>0,_xlfn.IFERROR(O37-M37,""),0) -> 135.24 | O37: 5670 | S37: 518 | T37: 2.535 | U37: 62.88 | V37: =IF(_xlfn.IFERROR(W37-U37,"")>0,_xlfn.IFERROR(W37-U37,""),0) -> 377.12 | W37: 440
C38: 225 | D38: 11.711 | E38: 3162.047 | F38: =IF(_xlfn.IFERROR(G38-E38,"")>0,_xlfn.IFERROR(G38-E38,""),0) -> 401.953 | G38: 3564 | K38: 327 | L38: 11.522 | M38: 4839.24 | N38: =IF(_xlfn.IFERROR(O38-M38,"")>0,_xlfn.IFERROR(O38-M38,""),0) -> 830.76 | O38: 5670 | S38: 合计 | U38: =SUM(U36:U37) -> 141.411 | V38: =SUM(V36:V37) -> 738.589
C39: 226 | D39: 4.766 | E39: 1286.746 | F39: =IF(_xlfn.IFERROR(G39-E39,"")>0,_xlfn.IFERROR(G39-E39,""),0) -> 2277.254 | G39: 3564 | K39: 合计 | M39: =SUM(M36:M38) -> 15663.06 | N39: =SUM(N36:N38) -> 1346.94 | R39: 液氨 | S39: 701 | T39: 0 | V39: =IF(_xlfn.IFERROR(W39-U39,"")>0,_xlfn.IFERROR(W39-U39,""),0) -> 500 | W39: 500
C40: 227 | D40: 13.417 | E40: 3622.477 | F40: =IF(_xlfn.IFERROR(G40-E40,"")>0,_xlfn.IFERROR(G40-E40,""),0) -> 0 | G40: 3564 | J40: 精制油 | K40: 326 | L40: 13.191 | M40: 5804.04 | N40: =IF(_xlfn.IFERROR(O40-M40,"")>0,_xlfn.IFERROR(O40-M40,""),0) -> 135.96 | O40: 5940
...
