Workbook

Sheet 延安石化厂装置生产完成情况（3-4）
B2: 延安石化厂装置生产完成情况（3-4）
B3: 编制单位：延安石油化工厂 | D3: 日期： | E3: 2025-12 | G3: =取值!A2&取值!B2&取值!C2 -> 报表生成时间：2026-01-01 8:00:00 | K3: 附表3-4
B4: 单位名称 | C4: 装置名称 | D4: 指标名称 | E4: 产量（吨） | G4: 收率（%） | I4: 去年同期 | K4: 备注
E5: 本月 | F5: 累计 | G5: 本月 | H5: 累计 | I5: 产量 | J5: 收率
B6: 轻 烃 中 心 | C6: 20 万 吨/ 年 烷 基 化 装 置 | D6: 原料处理量 | E6: 31693.2 | F6: =_xlfn.IFERROR(SUM(F7:F10),"") -> 349590 | G6: / | H6: / | I6: =取值!M5 -> 0 | J6: /
D7: 其中：混合C4 | E7: 31687 | F7: =取值!F7 -> 349517 | G7: / | H7: / | I7: =取值!M6 -> 0 | J7: /
D8: 开工异丁烷 | E8: 0 | F8: =取值!F6 -> 0 | G8: / | H8: / | I8: =取值!M7 -> 0 | J8: /
D9: 氢气 | E9: 6.2 | F9: =取值!F8 -> 73 | G9: / | H9: / | I9: =取值!M8 -> 0 | J9: /
D10: 开工异辛烷组分 | E10: 0 | F10: =取值!F5 -> 0 | G10: / | H10: / | I10: =取值!M9 -> 0 | J10: /
D11: 异辛烷组分 | E11: 19752 | F11: =取值!F9 -> 230334 | G11: =_xlfn.IFERROR(E11/E6*100,0) -> 62.322517 | H11: =_xlfn.IFERROR(F11/F6*100,0) -> 65.886896 | I11: =取值!M10 -> 0 | J11: =_xlfn.IFERROR(I11/I$6*100,0) -> 0
D12: 烷基化碳四 | E12: 6730 | F12: =取值!F10 -> 61856 | G12: =_xlfn.IFERROR(E12/E6*100,0) -> 21.234839 | H12: =_xlfn.IFERROR(F12/F6*100,0) -> 17.69387 | I12: =取值!M11 -> 0 | J12: =_xlfn.IFERROR(I12/I$6*100,0) -> 0
D13: 预处理碳四 | E13: 0 | F13: =取值!F11 -> 0 | G13: =_xlfn.IFERROR(E13/E6*100,0) -> 0 | H13: =_xlfn.IFERROR(F13/F6*100,0) -> 0 | I13: =取值!M12 -> 0 | J13: =_xlfn.IFERROR(I13/I$6*100,0) -> 0
D14: 正丁烷 | E14: 4251 | F14: =取值!F12 -> 46684 | G14: =_xlfn.IFERROR(E14/E6*100,0) -> 13.412972 | H14: =_xlfn.IFERROR(F14/F6*100,0) -> 13.353929 | I14: =取值!M13 -> 0 | J14: =_xlfn.IFERROR(I14/I$6*100,0) -> 0
D15: 干气 | E15: 642 | F15: =取值!F13 -> 7219 | G15: =_xlfn.IFERROR(E15/E6*100,0) -> 2.0256711 | H15: =_xlfn.IFERROR(F15/F6*100,0) -> 2.0649904 | I15: =取值!M14 -> 0 | J15: =_xlfn.IFERROR(I15/I$6*100,0) -> 0
D16: 不合格产品 | E16: 0 | F16: =取值!F14 -> 0 | G16: =_xlfn.IFERROR(E16/E6*100,0) -> 0 | H16: =_xlfn.IFERROR(F16/F6*100,0) -> 0 | I16: =取值!M15 -> 0 | J16: =_xlfn.IFERROR(I16/I$6*100,0) -> 0
D17: 加工损失 | E17: =E6-SUM(E11,E12,E13,E14,E15,E16) -> 318.2 | F17: =F6-SUM(F11,F12,F13,F14,F15,F16) -> 3497 | G17: =_xlfn.IFERROR(E17/E6*100,0) -> 1.0040009 | H17: =_xlfn.IFERROR(F17/F6*100,0) -> 1.0003147 | I17: =_xlfn.IFERROR(I6-SUM(I11,I12,I13,I14,I15,I16),0) -> 0 | J17: =_xlfn.IFERROR(I17/I$6*100,0) -> 0
C18: 30 万 吨/ 年 混 合 脱 氢 装 置 | D18: 原料处理量 | E18: 58392 | F18: =_xlfn.IFERROR(SUM(F19:F22),"") -> 545061 | I18: =取值!M17 -> 0 | J18: /
D19: 其中：丙烷 | E19: 8518 | F19: =取值!F17 -> 85819 | G19: / | H19: / | I19: =取值!M18 -> 0 | J19: /
D20: 饱和液化气 | E20: 13546 | F20: =取值!F18 -> 110180 | G20: / | H20: / | I20: =取值!M19 -> 0 | J20: /
D21: 烷基化碳四 | E21: 14674 | F21: =取值!F19 -> 132805 | G21: / | H21: / | I21: =取值!M20 -> 0 | J21: /
D22: 醚后碳四 | E22: 21654 | F22: =取值!F20 -> 216257 | G22: / | H22: / | I22: =取值!M21 -> 0 | J22: /
D23: 丙烯 | E23: 11369 | F23: =取值!F22 -> 105638 | G23: =_xlfn.IFERROR(E23/E18*100,0) -> 19.470133 | H23: =_xlfn.IFERROR(F23/F18*100,0) -> 19.38095 | I23: =取值!M22 -> 0 | J23: =_xlfn.IFERROR(I23/I$18*100,0) -> 0
D24: 富异丁烯碳四 | E24: 31814 | F24: =取值!F23 -> 288599 | G24: =_xlfn.IFERROR(E24/E18*100,0) -> 54.483491 | H24: =_xlfn.IFERROR(F24/F18*100,0) -> 52.948019 | I24: =取值!M23 -> 0 | J24: =_xlfn.IFERROR(I24/I$18*100,0) -> 0
D25: 再生碳四 | E25: 5702 | F25: =取值!F24 -> 66081 | G25: =_xlfn.IFERROR(E25/E18*100,0) -> 9.7650363 | H25: =_xlfn.IFERROR(F25/F18*100,0) -> 12.123597 | I25: =取值!M24 -> 0 | J25: =_xlfn.IFERROR(I25/I$18*100,0) -> 0
D26: 正丁烷 | E26: 6665 | F26: =取值!F25 -> 58759 | G26: =_xlfn.IFERROR(E26/E18*100,0) -> 11.414235 | H26: =_xlfn.IFERROR(F26/F18*100,0) -> 10.780261 | I26: =取值!M25 -> 0 | J26: =_xlfn.IFERROR(I26/I$18*100,0) -> 0
D27: 轻污油 | E27: 0 | F27: =取值!F26 -> 323 | G27: =_xlfn.IFERROR(E27/E18*100,0) -> 0 | H27: =_xlfn.IFERROR(F27/F18*100,0) -> 0.059259422 | I27: =取值!M26 -> 0 | J27: =_xlfn.IFERROR(I27/I$18*100,0) -> 0
D28: 燃料气 | E28: 1922 | F28: =取值!F27 -> 18725 | G28: =_xlfn.IFERROR(E28/E18*100,0) -> 3.2915468 | H28: =_xlfn.IFERROR(F28/F18*100,0) -> 3.4353953 | I28: =取值!M27 -> 0 | J28: =_xlfn.IFERROR(I28/I$18*100,0) -> 0
D29: 氢气 | E29: 6.2 | F29: =取值!F28 -> 65 | G29: =_xlfn.IFERROR(E29/E18*100,0) -> 0.010617893 | H29: =_xlfn.IFERROR(F29/F18*100,0) -> 0.011925271 | I29: =取值!M28 -> 0 | J29: =_xlfn.IFERROR(I29/I$18*100,0) -> 0
D30: 不合格产品 | E30: 0 | F30: =取值!F29 -> 0 | G30: =_xlfn.IFERROR(E30/E18*100,0) -> 0 | H30: =_xlfn.IFERROR(F30/F18*100,0) -> 0 | I30: =取值!M29 -> 0 | J30: =_xlfn.IFERROR(I30/I$18*100,0) -> 0
D31: 加工损失 | E31: =E18-SUM(E23,E24,E25,E26,E27,E28,E29,E30) -> 913.8 | F31: =F18-SUM(F23,F24,F25,F26,F27,F28,F29,F30) -> 6871 | G31: =_xlfn.IFERROR(E31/E18*100,0) -> 1.5649404 | H31: =_xlfn.IFERROR(F31/F18*100,0) -> 1.2605929 | I31: =_xlfn.IFERROR(I18-SUM(I23,I24,I25,I26,I27,I28,I29,I30),0) -> 0 | J31: =_xlfn.IFERROR(I31/I$18*100,0) -> 0
C32: 25 万 吨/ 年 MTBE 装 置 | D32: 原料处理量 | E32: 45376 | F32: =_xlfn.IFERROR(SUM(F33:F36),"") -> 424328 | I32: =取值!M31 -> 0 | J32: /
D33: 其中：富异丁烯碳四 | E33: 31581 | F33: =取值!F32 -> 286232 | G33: / | H33: / | I33: =取值!M32 -> 0 | J33: /
D34: 预处理碳四 | E34: 0 | F34: =取值!F33 -> 0 | G34: / | H34: / | I34: =取值!M33 -> 0 | J34: /
D35: 再生碳四 | E35: 5702 | F35: =取值!F34 -> 66081 | G35: / | H35: / | I35: =取值!M34 -> 0 | J35: /
D36: 甲醇 | E36: 8093 | F36: =取值!F35 -> 72015 | G36: / | H36: / | I36: =取值!M35 -> 0 | J36: /
D37: MTBE | E37: 22620 | F37: =取值!F36 -> 197239 | G37: =_xlfn.IFERROR(E37/E32*100,0) -> 49.850141 | H37: =_xlfn.IFERROR(F37/F32*100,0) -> 46.482674 | I37: =取值!M36 -> 0 | J37: =_xlfn.IFERROR(I37/I$32*100,0) -> 0
D38: 醚后碳四 | E38: 22395 | F38: =取值!F37 -> 223602 | G38: =_xlfn.IFERROR(E38/E32*100,0) -> 49.354284 | H38: =_xlfn.IFERROR(F38/F32*100,0) -> 52.695556 | I38: =取值!M37 -> 0 | J38: =_xlfn.IFERROR(I38/I$32*100,0) -> 0
D39: 不合格产品 | E39: 0 | F39: =取值!F38 -> 0 | G39: =_xlfn.IFERROR(E39/E32*100,0) -> 0 | H39: =_xlfn.IFERROR(F39/F32*100,0) -> 0 | I39: =取值!M38 -> 0 | J39: =_xlfn.IFERROR(I39/I$32*100,0) -> 0
D40: 加工损失 | E40: =E32-SUM(E37,E38,E39) -> 361 | F40: =F32-SUM(F37,F38,F39) -> 3487 | G40: =_xlfn.IFERROR(E40/E32*100,0) -> 0.79557475 | H40: =_xlfn.IFERROR(F40/F32*100,0) -> 0.82176995 | I40: =_xlfn.IFERROR(I32-SUM(I37,I38,I39),0) -> 0 | J40: =_xlfn.IFERROR(I40/I$32*100,0) -> 0
B41: 备注：
...

Sheet 取值
A2: 报表生成时间： | B2: 2026-01-01 | C2: 8:00:00
E5: 0 | F5: 0 | I5: 0
E6: 0 | F6: 0 | I6: 0
E7: 31687 | F7: 349517 | I7: 344585
E8: 6.2 | F8: 73 | I8: 73.2
E9: 19752 | F9: 230334 | I9: 231019
E10: 6730 | F10: 61856 | I10: 56444
E11: 0 | F11: 0 | I11: 0
E12: 4251 | F12: 46684 | I12: 46666
E13: 642 | F13: 7219 | I13: 7079
E14: 0 | F14: 0 | I14: 0
E17: 8518 | F17: 85819 | I17: 89790
E18: 13546 | F18: 110180 | I18: 136844
... E38: 0 | F38: 0 | I38: 0
